File: data/instron/Sample22_Control.is_tcyclic_RawData/Specimen_RawData_1.csv
Strain : Tensile strain (Extension) gauge length,100,mm,,,,
,,,,,,
Time,Extension,Load,,,,
(s),(mm),(N),Low Start,Low End,High Start ,High End
0,0,0.21512,5,412,467,488
0.01,0,0.21987,,,,
0.02,0.00009,0.22433,,,,
0.03,0.00041,0.22437,,,,
0.04,0.00111,0.22596,,,,
0.05,0.00248,0.22379,,,,
0.06,0.00423,0.21638,,,,
0.07,0.00576,0.2202,,,,
0.08,0.00723,0.23037,,,,
0.09,0.00904,0.23881,,,,
0.1,0.01163,0.24955,,,,
0.11,0.01516,0.26114,,,,
0.12,0.01947,0.27167,,,,
0.13,0.02422,0.28348,,,,
0.14,0.02907,0.30051,,,,
0.15,0.03377,0.3158,,,,
0.16,0.03821,0.33354,,,,
0.17,0.04236,0.34931,,,,
0.18,0.04627,0.3628,,,,
0.19,0.05001,0.37712,,,,
0.2,0.05368,0.38962,,,,
0.21,0.05734,0.40348,,,,
0.22,0.06104,0.41762,,,,
0.23,0.06476,0.42884,,,,
0.24,0.06845,0.44306,,,,
0.25,0.07207,0.45881,,,,
0.26,0.07563,0.47721,,,,
0.27,0.07916,0.50031,,,,
0.28,0.08269,0.521,,,,
0.29,0.08622,0.53599,,,,
0.3,0.08978,0.5545,,,,
0.31,0.0934,0.5729,,,,
0.32,0.09707,0.58884,,,,
0.33,0.10077,0.60824,,,,
0.34,0.10445,0.62835,,,,
0.35,0.10806,0.64645,,,,
0.36,0.1116,0.66748,,,,
0.37,0.11509,0.68982,,,,
0.38,0.11856,0.70789,,,,
0.39,0.12203,0.72831,,,,
0.4,0.12556,0.7525,,,,
0.41,0.12915,0.77816,,,,
0.42,0.13281,0.80108,,,,
0.43,0.13649,0.82777,,,,
0.44,0.14017,0.85351,,,,
0.45,0.14381,0.87549,,,,
0.46,0.14739,0.8994,,,,
0.47,0.15091,0.92545,,,,
0.48,0.15439,0.95375,,,,
0.49,0.15786,0.98309,,,,
0.5,0.16138,1.01684,,,,
0.51,0.16496,1.04881,,,,
0.52,0.16862,1.08095,,,,
0.53,0.17232,1.11647,,,,
0.54,0.17603,1.1547,,,,
0.55,0.17973,1.18664,,,,
0.56,0.1834,1.22119,,,,
0.57,0.18703,1.25672,,,,
0.58,0.19059,1.29185,,,,
0.59,0.1941,1.32384,,,,
0.6,0.19759,1.35704,,,,
0.61,0.2011,1.39375,,,,
0.62,0.20466,1.43249,,,,
0.63,0.20826,1.47382,,,,
0.64,0.21189,1.51512,,,,
0.65,0.2155,1.5537,,,,
0.66,0.2191,1.5965,,,,
0.67,0.22269,1.63784,,,,
0.68,0.22625,1.67689,,,,
0.69,0.22978,1.71814,,,,
0.7,0.2333,1.76359,,,,
0.71,0.23686,1.80929,,,,
0.72,0.24046,1.85813,,,,
0.73,0.24409,1.90381,,,,
0.74,0.24772,1.94758,,,,
0.75,0.25134,1.99217,,,,
0.76,0.25494,2.04127,,,,
0.77,0.25851,2.0888,,,,
0.78,0.26206,2.13539,,,,
0.79,0.2656,2.18341,,,,
0.8,0.26914,2.23471,,,,
0.81,0.27271,2.28839,,,,
0.82,0.27629,2.34175,,,,
0.83,0.27988,2.39372,,,,
0.84,0.28347,2.4471,,,,
0.85,0.28705,2.50182,,,,
0.86,0.29062,2.56304,,,,
0.87,0.29417,2.6169,,,,
0.88,0.2977,2.6702,,,,
0.89,0.30124,2.73147,,,,
0.9,0.30481,2.78737,,,,
0.91,0.30842,2.84745,,,,
0.92,0.31205,2.91515,,,,
0.93,0.31567,2.97551,,,,
0.94,0.31927,3.03274,,,,
0.95,0.32284,3.09623,,,,
0.96,0.32637,3.15753,,,,
0.97,0.32988,3.21446,,,,
0.98,0.33337,3.27902,,,,
0.99,0.33689,3.34484,,,,
1,0.34047,3.40851,,,,
1.01,0.34412,3.47858,,,,
1.02,0.34782,3.55061,,,,
1.03,0.35152,3.61646,,,,
1.04,0.35517,3.6861,,,,
1.05,0.35875,3.75954,,,,
1.06,0.36228,3.82846,,,,
1.07,0.36578,3.89877,,,,
1.08,0.36927,3.97497,,,,
1.09,0.37279,4.04826,,,,
1.1,0.37636,4.12237,,,,
1.11,0.38002,4.1971,,,,
1.12,0.38375,4.27222,,,,
1.13,0.38749,4.35027,,,,
1.14,0.39118,4.42982,,,,
1.15,0.39479,4.5077,,,,
1.16,0.39832,4.58263,,,,
1.17,0.40179,4.6617,,,,
1.18,0.40524,4.7425,,,,
1.19,0.40871,4.81879,,,,
1.2,0.41223,4.89674,,,,
1.21,0.41581,4.98091,,,,
1.22,0.41947,5.06924,,,,
1.23,0.42316,5.15681,,,,
1.24,0.42686,5.24622,,,,
1.25,0.43051,5.334,,,,
1.26,0.43409,5.41856,,,,
1.27,0.43759,5.5027,,,,
1.28,0.44105,5.58896,,,,
1.29,0.44449,5.6723,,,,
1.3,0.44797,5.76086,,,,
1.31,0.45153,5.85355,,,,
1.32,0.45515,5.94978,,,,
1.33,0.45882,6.04878,,,,
1.34,0.46249,6.14761,,,,
1.35,0.46614,6.23976,,,,
1.36,0.46975,6.32952,,,,
1.37,0.47331,6.41869,,,,
1.38,0.47681,6.51131,,,,
1.39,0.48027,6.60789,,,,
1.4,0.48373,6.70514,,,,
1.41,0.48724,6.80489,,,,
1.42,0.49082,6.90863,,,,
1.43,0.49444,7.01243,,,,
1.44,0.49809,7.1179,,,,
1.45,0.50172,7.22166,,,,
1.46,0.50534,7.32373,,,,
1.47,0.50893,7.4252,,,,
1.48,0.51249,7.53036,,,,
1.49,0.51603,7.6345,,,,
1.5,0.51955,7.7408,,,,
1.51,0.5231,7.84985,,,,
1.52,0.52669,7.95817,,,,
1.53,0.53031,8.07125,,,,
1.54,0.53394,8.18474,,,,
1.55,0.53754,8.29746,,,,
1.56,0.54111,8.40936,,,,
1.57,0.54466,8.5219,,,,
1.58,0.54819,8.63203,,,,
1.59,0.55175,8.74324,,,,
1.6,0.55536,8.86121,,,,
1.61,0.55904,8.9839,,,,
1.62,0.56274,9.10598,,,,
1.63,0.56644,9.22762,,,,
1.64,0.57009,9.3523,,,,
1.65,0.5737,9.4769,,,,
1.66,0.57724,9.59835,,,,
1.67,0.58075,9.71953,,,,
1.68,0.58422,9.83766,,,,
1.69,0.58771,9.95417,,,,
1.7,0.59125,10.07392,,,,
1.71,0.59489,10.20045,,,,
1.72,0.59858,10.32863,,,,
1.73,0.60227,10.45782,,,,
1.74,0.60592,10.58959,,,,
1.75,0.60949,10.72125,,,,
1.76,0.61302,10.84983,,,,
1.77,0.6165,10.97447,,,,
1.78,0.61996,11.09908,,,,
1.79,0.62343,11.22543,,,,
1.8,0.62695,11.35418,,,,
1.81,0.63055,11.48665,,,,
1.82,0.63421,11.62376,,,,
1.83,0.6379,11.76358,,,,
1.84,0.64159,11.90239,,,,
1.85,0.6452,12.03866,,,,
1.86,0.64875,12.1765,,,,
1.87,0.65224,12.31269,,,,
1.88,0.65569,12.44735,,,,
1.89,0.65914,12.58848,,,,
1.9,0.66264,12.73195,,,,
1.91,0.66621,12.87629,,,,
1.92,0.66987,13.02097,,,,
1.93,0.67356,13.16782,,,,
1.94,0.67725,13.31715,,,,
1.95,0.68091,13.46419,,,,
1.96,0.68452,13.60669,,,,
1.97,0.68806,13.75055,,,,
1.98,0.69154,13.89643,,,,
1.99,0.695,14.04207,,,,
2,0.69848,14.18896,,,,
2.01,0.70202,14.33963,,,,
2.02,0.70562,14.49927,,,,
2.03,0.70925,14.66306,,,,
2.04,0.7129,14.82189,,,,
2.05,0.71652,14.97163,,,,
2.06,0.72012,15.11665,,,,
2.07,0.72368,15.26432,,,,
2.08,0.72721,15.4142,,,,
2.09,0.73071,15.57129,,,,
2.1,0.73425,15.73418,,,,
2.11,0.73784,15.9012,,,,
2.12,0.7415,16.07303,,,,
2.13,0.74519,16.24349,,,,
2.14,0.74888,16.41548,,,,
2.15,0.75255,16.58483,,,,
2.16,0.75618,16.75053,,,,
2.17,0.75977,16.91132,,,,
2.18,0.76332,17.06959,,,,
2.19,0.76686,17.22732,,,,
2.2,0.77042,17.38895,,,,
2.21,0.774,17.55963,,,,
2.22,0.77761,17.73357,,,,
2.23,0.78122,17.90782,,,,
2.24,0.78482,18.08409,,,,
2.25,0.78839,18.25694,,,,
2.26,0.79193,18.42568,,,,
2.27,0.79546,18.5912,,,,
2.28,0.79898,18.75809,,,,
2.29,0.80252,18.92722,,,,
2.3,0.8061,19.10285,,,,
2.31,0.80972,19.283,,,,
2.32,0.81336,19.46659,,,,
2.33,0.81699,19.65065,,,,
2.34,0.82059,19.8345,,,,
2.35,0.82413,20.01696,,,,
2.36,0.82764,20.19719,,,,
2.37,0.83114,20.37581,,,,
2.38,0.83464,20.55049,,,,
2.39,0.83816,20.72714,,,,
2.4,0.84173,20.90735,,,,
2.41,0.84536,21.09479,,,,
2.42,0.84902,21.29008,,,,
2.43,0.85268,21.48532,,,,
2.44,0.8563,21.67824,,,,
2.45,0.85987,21.87019,,,,
2.46,0.86338,22.06112,,,,
2.47,0.86688,22.24759,,,,
2.48,0.87036,22.43435,,,,
2.49,0.87386,22.61932,,,,
2.5,0.87742,22.80933,,,,
2.51,0.88106,23.0092,,,,
2.52,0.88474,23.21426,,,,
2.53,0.88844,23.41574,,,,
2.54,0.8921,23.6203,,,,
2.55,0.89569,23.81873,,,,
2.56,0.89921,24.01114,,,,
2.57,0.90267,24.20383,,,,
2.58,0.90612,24.3959,,,,
2.59,0.90959,24.58735,,,,
2.6,0.91314,24.78767,,,,
2.61,0.91676,24.9957,,,,
2.62,0.92046,25.20606,,,,
2.63,0.92418,25.41878,,,,
2.64,0.92791,25.63121,,,,
2.65,0.9316,25.84116,,,,
2.66,0.93523,26.0484,,,,
2.67,0.9388,26.25303,,,,
2.68,0.94232,26.45674,,,,
2.69,0.94583,26.6612,,,,
2.7,0.94936,26.8709,,,,
2.71,0.95293,27.08232,,,,
2.72,0.95654,27.29402,,,,
2.73,0.96016,27.50496,,,,
2.74,0.96378,27.71071,,,,
2.75,0.96739,27.91628,,,,
2.76,0.97099,28.12365,,,,
2.77,0.97454,28.32982,,,,
2.78,0.97806,28.53324,,,,
2.79,0.98155,28.73763,,,,
2.8,0.98507,28.94899,,,,
2.81,0.98862,29.16856,,,,
2.82,0.99221,29.39323,,,,
2.83,0.99582,29.62068,,,,
2.84,0.99944,29.84269,,,,
2.85,1.00307,30.06045,,,,
2.86,1.00668,30.27635,,,,
2.87,1.01027,30.48658,,,,
2.88,1.01383,30.69769,,,,
2.89,1.01739,30.91622,,,,
2.9,1.02095,31.14305,,,,
2.91,1.02455,31.37404,,,,
2.92,1.02815,31.60584,,,,
2.93,1.03175,31.8359,,,,
2.94,1.03533,32.06129,,,,
2.95,1.03886,32.27931,,,,
2.96,1.04237,32.49466,,,,
2.97,1.04586,32.70785,,,,
2.98,1.04934,32.91884,,,,
2.99,1.05286,33.13475,,,,
3,1.05644,33.35933,,,,
3.01,1.06006,33.59177,,,,
3.02,1.06371,33.83281,,,,
3.03,1.06734,34.07916,,,,
3.04,1.07095,34.31921,,,,
3.05,1.07451,34.55803,,,,
3.06,1.07806,34.7941,,,,
3.07,1.08157,35.02641,,,,
3.08,1.08509,35.25724,,,,
3.09,1.08864,35.48786,,,,
3.1,1.09225,35.72189,,,,
3.11,1.09593,35.9628,,,,
3.12,1.09964,36.20867,,,,
3.13,1.10334,36.45304,,,,
3.14,1.10697,36.69756,,,,
3.15,1.11054,36.93773,,,,
3.16,1.11406,37.17411,,,,
3.17,1.11756,37.40696,,,,
3.18,1.12106,37.64159,,,,
3.19,1.1246,37.87377,,,,
3.2,1.12822,38.10996,,,,
3.21,1.13192,38.35793,,,,
3.22,1.13566,38.61206,,,,
3.23,1.13939,38.86495,,,,
3.24,1.14304,39.11335,,,,
3.25,1.14659,39.35092,,,,
3.26,1.15007,39.58156,,,,
3.27,1.1535,39.81379,,,,
3.28,1.15692,40.05082,,,,
3.29,1.16039,40.29265,,,,
3.3,1.16394,40.54438,,,,
3.31,1.16756,40.80472,,,,
3.32,1.17124,41.06717,,,,
3.33,1.17495,41.3263,,,,
3.34,1.17864,41.58025,,,,
3.35,1.18226,41.82988,,,,
3.36,1.18582,42.07847,,,,
3.37,1.18931,42.326,,,,
3.38,1.19277,42.57213,,,,
3.39,1.19623,42.8218,,,,
3.4,1.19974,43.07626,,,,
3.41,1.20333,43.34136,,,,
3.42,1.20696,43.61184,,,,
3.43,1.21061,43.88066,,,,
3.44,1.21425,44.13957,,,,
3.45,1.21786,44.3926,,,,
3.46,1.22145,44.64412,,,,
3.47,1.22499,44.89076,,,,
3.48,1.22849,45.13713,,,,
3.49,1.23198,45.38868,,,,
3.5,1.23548,45.64718,,,,
3.51,1.23905,45.91619,,,,
3.52,1.24266,46.19489,,,,
3.53,1.24631,46.47913,,,,
3.54,1.24997,46.75743,,,,
3.55,1.2536,47.02919,,,,
3.56,1.25721,47.29356,,,,
3.57,1.26077,47.54853,,,,
3.58,1.2643,47.801,,,,
3.59,1.26781,48.05809,,,,
3.6,1.27135,48.32138,,,,
3.61,1.27493,48.5928,,,,
3.62,1.27853,48.87118,,,,
3.63,1.28214,49.15007,,,,
3.64,1.28573,49.42705,,,,
3.65,1.28929,49.70139,,,,
3.66,1.29284,49.96995,,,,
3.67,1.29638,50.23386,,,,
3.68,1.29993,50.50173,,,,
3.69,1.30353,50.7739,,,,
3.7,1.30717,51.05555,,,,
3.71,1.31087,51.34636,,,,
3.72,1.31458,51.64355,,,,
3.73,1.31826,51.93817,,,,
3.74,1.32188,52.22641,,,,
3.75,1.32546,52.50412,,,,
3.76,1.32899,52.77393,,,,
3.77,1.33248,53.04052,,,,
3.78,1.33597,53.30742,,,,
3.79,1.33949,53.57585,,,,
3.8,1.34308,53.85236,,,,
3.81,1.34674,54.13708,,,,
3.82,1.35041,54.42566,,,,
3.83,1.35406,54.71511,,,,
3.84,1.35766,55.00181,,,,
3.85,1.36119,55.28426,,,,
3.86,1.36469,55.55917,,,,
3.87,1.36818,55.83205,,,,
3.88,1.37165,56.10439,,,,
3.89,1.37515,56.38088,,,,
3.9,1.37872,56.66585,,,,
3.91,1.38237,56.96007,,,,
3.92,1.38607,57.25713,,,,
3.93,1.38977,57.55437,,,,
3.94,1.39342,57.8491,,,,
3.95,1.39699,58.13622,,,,
3.96,1.40048,58.41629,,,,
3.97,1.40394,58.68856,,,,
3.98,1.40738,58.96004,,,,
3.99,1.41085,59.23806,,,,
4,1.4144,59.52807,,,,
4.01,1.41803,59.82633,,,,
4.02,1.42171,60.12898,,,,
4.03,1.42541,60.43003,,,,
4.04,1.42909,60.72551,,,,
4.049,1.43236,60.98677,,,,
4.05,1.43272,61.01538,,,,
4.051,1.43308,61.04398,,,,
4.151,1.43058,59.23959,,,,
4.227,1.40062,54.19756,,,,
4.317,1.36712,49.19704,,,,
4.417,1.33107,44.33484,,,,
4.517,1.29493,39.897,,,,
4.617,1.25939,35.90745,,,,
4.717,1.22359,32.21988,,,,
4.817,1.18786,28.8429,,,,
4.917,1.15197,25.72327,,,,
5.017,1.116,22.85663,,,,
5.117,1.08029,20.24855,,,,
5.217,1.0445,17.84594,,,,
5.317,1.00878,15.66607,,,,
5.417,0.97284,13.63563,,,,
5.517,0.93721,11.8166,,,,
5.617,0.90138,10.16982,,,,
5.717,0.86574,8.68266,,,,
5.817,0.82983,7.33338,,,,
5.917,0.79385,6.14086,,,,
6.017,0.75801,5.09817,,,,
6.117,0.72217,4.17398,,,,
6.217,0.68679,3.37981,,,,
6.317,0.65095,2.70971,,,,
6.417,0.61516,2.13339,,,,
6.517,0.57904,1.66154,,,,
6.617,0.54309,1.27943,,,,
6.717,0.50754,0.9677,,,,
6.817,0.47183,0.72316,,,,
6.917,0.43599,0.53742,,,,
7.017,0.40018,0.39802,,,,
7.117,0.36422,0.29359,,,,
7.217,0.32849,0.22295,,,,
7.317,0.29276,0.16745,,,,
7.417,0.25695,0.13494,,,,
7.517,0.22107,0.10863,,,,
7.617,0.18538,0.09066,,,,
7.717,0.14961,0.07465,,,,
7.817,0.11388,0.06124,,,,
7.917,0.07807,0.05158,,,,
8.017,0.04209,0.04563,,,,
8.117,0.00626,0.03857,,,,
8.134,0.00021,0.03495,,,,
8.135,-0.00015,0.03455,,,,
8.136,-0.0005,0.03429,,,,
8.236,0.00172,0.05068,,,,
8.336,0.0417,0.05919,,,,
8.436,0.07805,0.07031,,,,
8.536,0.1141,0.09896,,,,
8.636,0.14991,0.12103,,,,
8.736,0.18599,0.15951,,,,
8.836,0.22166,0.20598,,,,
8.936,0.25752,0.26445,,,,
9.036,0.29318,0.36059,,,,
9.136,0.3289,0.49823,,,,
9.138,0.3296,0.5003,,,,
9.139,0.32995,0.50136,,,,
9.14,0.3303,0.50253,,,,
9.145,0.33206,0.51624,,,,
9.15,0.33422,0.58284,,,,
9.155,0.33802,0.69774,,,,
9.16,0.34535,0.86211,,,,
9.165,0.35837,1.09524,,,,
9.17,0.37921,1.44401,,,,
9.175,0.40984,1.99273,,,,
9.18,0.45194,2.88866,,,,
9.185,0.5069,4.3495,,,,
9.19,0.57576,6.65562,,,,
9.195,0.65928,10.16952,,,,
9.2,0.75789,15.27624,,,,
9.205,0.8715,22.34221,,,,
9.21,0.99961,31.63488,,,,
9.215,1.14142,43.23452,,,,
9.22,1.29559,56.90282,,,,
9.225,1.45962,72.18694,,,,
9.23,1.63053,88.42026,,,,
9.235,1.80565,104.75232,,,,
9.24,1.9831,120.7449,,,,
9.245,2.16179,136.06778,,,,
9.25,2.34116,150.20065,,,,
9.255,2.52101,162.85426,,,,
9.26,2.7013,174.47865,,,,
9.265,2.88199,185.55911,,,,
9.27,3.06303,196.27362,,,,
9.275,3.24428,206.71829,,,,
9.28,3.42561,216.93657,,,,
9.285,3.60689,226.9167,,,,
9.29,3.78801,236.57224,,,,
9.295,3.96888,245.80887,,,,
9.3,4.14949,254.5132,,,,
9.305,4.32982,262.11243,,,,
9.31,4.5099,265.03311,,,,
9.315,4.68976,259.07495,,,,
9.32,4.86943,245.68312,,,,
9.325,5.04899,228.17972,,,,
9.33,5.2285,209.19676,,,,
9.335,5.40799,190.70142,,,,
9.34,5.58744,173.94051,,,,
9.345,5.76685,159.58014,,,,
9.35,5.94623,147.74696,,,,
9.355,6.12556,138.16016,,,,
9.36,6.30483,130.46609,,,,
9.365,6.48405,124.37015,,,,
9.37,6.66323,119.66915,,,,
9.375,6.84238,116.17108,,,,
9.38,7.02152,113.61806,,,,
9.385,7.20062,111.71609,,,,
9.39,7.3797,110.13294,,,,
9.395,7.55878,108.63058,,,,
9.4,7.73787,107.14367,,,,
9.405,7.91696,105.69247,,,,
9.41,8.09607,104.27768,,,,
9.415,8.27519,102.91122,,,,
9.42,8.45431,101.5667,,,,
9.425,8.63343,100.19152,,,,
9.43,8.81253,98.76319,,,,
9.435,8.99163,97.28745,,,,
9.44,9.17072,95.80634,,,,
9.445,9.34979,94.40305,,,,
9.45,9.52884,93.09531,,,,
9.455,9.70787,91.84155,,,,
9.46,9.88687,90.58482,,,,
9.465,10.06585,89.32444,,,,
9.47,10.24481,88.09658,,,,
9.475,10.42377,86.95003,,,,
9.48,10.60275,85.91497,,,,
9.485,10.78173,84.94372,,,,
9.49,10.96072,84.00019,,,,
9.495,11.13971,83.06966,,,,
9.5,11.3187,82.11851,,,,
9.505,11.4977,81.12705,,,,
9.51,11.67669,80.10056,,,,
9.515,11.85569,79.06246,,,,
9.52,12.03469,77.9634,,,,
9.525,12.21369,76.76952,,,,
9.53,12.39268,75.50342,,,,
9.535,12.57165,74.2131,,,,
9.54,12.75063,72.91926,,,,
9.545,12.92962,71.62029,,,,
9.55,13.10862,70.30061,,,,
9.555,13.28762,69.00114,,,,
9.56,13.46663,67.7526,,,,
9.565,13.64564,66.56184,,,,
9.57,13.82464,65.41184,,,,
9.575,14.00365,64.24238,,,,
9.58,14.18265,63.00269,,,,
9.585,14.36167,61.71502,,,,
9.59,14.5407,60.34928,,,,
9.595,14.71971,58.84757,,,,
9.6,14.89872,57.22092,,,,
9.605,15.07772,55.46633,,,,
9.61,15.25671,53.57399,,,,
9.615,15.43569,51.51232,,,,
9.62,15.61469,49.27006,,,,
9.625,15.79369,46.88115,,,,
9.63,15.97271,44.40396,,,,
9.635,16.15172,41.87235,,,,
9.64,16.33073,39.2778,,,,
9.645,16.50972,36.56113,,,,
9.65,16.68871,33.73074,,,,
9.655,16.86769,30.81965,,,,
9.66,17.04666,27.86827,,,,
9.665,17.22566,24.90518,,,,
9.67,17.40466,21.94368,,,,
9.675,17.58366,18.97229,,,,
9.68,17.76267,16.06722,,,,
9.685,17.94169,13.33358,,,,
9.69,18.12074,10.86678,,,,
9.694,18.26398,9.11928,,,,