File: data/static/S2/raw_data.csv
Strain : Tensile strain (Extension) gauge length,"100.00000",mm

Time,Extension,Load
(s),(mm),(N)
"0.00000","0.00000","0.24372"
"0.20000","0.05223","0.51249"
"0.40000","0.12549","1.01590"
"0.60000","0.19721","1.74642"
"0.80000","0.26902","2.77399"
"1.00000","0.34120","4.15003"
"1.20000","0.41302","5.88668"
"1.40000","0.48519","8.04382"
"1.60000","0.55683","10.64140"
"1.80000","0.62862","13.72755"
"2.00000","0.70095","17.36188"
"2.20000","0.77255","21.55667"
"2.40000","0.84451","26.36347"
"2.60000","0.91664","31.78990"
"2.80000","0.98842","37.76226"
"3.00000","1.06047","44.29846"
"3.20000","1.13221","51.21955"
"3.40000","1.20426","58.46112"
"3.55200","1.25873","64.19035"
"3.55400","1.25943","64.26610"
"3.75400","1.26953","63.53527"
"3.95400","1.26726","62.18868"
"4.15400","1.26691","61.38618"
"4.35400","1.26684","60.80405"
"4.55400","1.26684","60.32478"
"4.75400","1.26675","59.90931"
"4.95400","1.26681","59.56621"
"5.15400","1.26684","59.25245"
"5.35400","1.26684","58.97027"
"5.55400","1.26684","58.72090"
"5.75400","1.26684","58.48077"
"5.95400","1.26684","58.25147"
"6.15400","1.26684","58.06893"
"6.35400","1.26684","57.87189"
"6.55400","1.26684","57.70121"
"6.75400","1.26684","57.53730"
"6.95400","1.26684","57.37770"
"7.15400","1.26684","57.22235"
"7.35400","1.26684","57.07671"
"7.55400","1.26684","56.93604"
"7.75400","1.26684","56.82335"
"7.95400","1.26684","56.69407"
"8.15400","1.26684","56.56840"
"8.35400","1.26684","56.45959"
"8.55400","1.26684","56.34081"
"8.75400","1.26684","56.24453"
"8.95400","1.26684","56.13530"
"9.15400","1.26684","56.03510"
"9.35400","1.26684","55.93760"
"9.55400","1.26684","55.83714"
"9.75400","1.26684","55.74986"
"9.95400","1.26684","55.66244"
"10.15400","1.26684","55.57481"
"10.35400","1.26684","55.48969"
"10.55400","1.26684","55.41586"
"10.75400","1.26684","55.33452"
"10.95400","1.26684","55.25645"
"11.15400","1.26684","55.18948"
"11.35400","1.26684","55.11035"
"11.55400","1.26684","55.04623"
"11.75400","1.26684","54.96867"
"11.95400","1.26684","54.90050"
"12.15400","1.26684","54.83401"
"12.35400","1.26684","54.76810"
"12.55400","1.26684","54.70362"
"12.75400","1.26681","54.64931"
"12.95400","1.26684","54.58529"
"13.15400","1.26684","54.52023"
"13.35400","1.26684","54.46241"
"13.55400","1.26684","54.40322"
"13.75400","1.26684","54.35054"
"13.95400","1.26684","54.29221"
"14.15400","1.26684","54.24493"
"14.35400","1.26684","54.17538"
"14.55400","1.26684","54.13781"
"14.75400","1.26684","54.08205"
"14.95400","1.26684","54.02539"
"15.15400","1.26684","53.97616"
"15.35400","1.26684","53.93576"
"15.55400","1.26684","53.88047"
"15.75400","1.26684","53.82782"
"15.95400","1.26684","53.77545"
"16.15400","1.26684","53.73112"
"16.35400","1.26684","53.68512"
"16.55400","1.26684","53.64265"
"16.75400","1.26684","53.59910"
"16.95400","1.26684","53.55871"
"17.15400","1.26684","53.51576"
"17.35400","1.26684","53.47092"
"17.55400","1.26684","53.42165"
"17.75400","1.26684","53.38294"
"17.95400","1.26684","53.34420"
"18.15400","1.26684","53.30057"
"18.35400","1.26684","53.26932"
"18.55400","1.26684","53.22751"
"18.75400","1.26684","53.18808"
"18.95400","1.26684","53.14427"
"19.15400","1.26684","53.10608"
"19.35400","1.26684","53.07178"
"19.55400","1.26684","53.03671"
"19.75400","1.26684","52.99906"
"19.95400","1.26684","52.96576"
"20.15400","1.26684","52.92806"
"20.35400","1.26684","52.89160"
"20.55400","1.26684","52.85502"
"20.75400","1.26684","52.81713"
"20.95400","1.26684","52.78348"
"21.15400","1.26684","52.74775"
"21.35400","1.26684","52.71713"
"21.55400","1.26684","52.67628"
"21.75400","1.26684","52.64513"
"21.95400","1.26684","52.61620"
"22.15400","1.26684","52.58471"
"22.35400","1.26684","52.55433"
"22.55400","1.26684","52.52748"
"22.75400","1.26684","52.49292"
"22.95400","1.26684","52.46030"
"23.15400","1.26684","52.42318"
"23.35400","1.26684","52.39725"
"23.55300","1.26684","52.37179"
"23.59000","1.26684","52.36080"
"23.77000","1.21732","45.04121"
"23.97000","1.14494","35.76802"
"24.17000","1.07296","28.15522"
"24.37000","1.00105","21.87577"
"24.57000","0.92916","16.67337"
"24.77000","0.85709","12.42665"
"24.97000","0.78551","9.03494"
"25.17000","0.71343","6.37791"
"25.37000","0.64122","4.34574"
"25.57000","0.56960","2.83850"
"25.77000","0.49763","1.74370"
"25.97000","0.42570","0.99650"
"26.17000","0.35376","0.52367"
"26.37000","0.28180","0.25151"
"26.57000","0.21009","0.10997"
"26.77000","0.13799","0.05012"
"26.97000","0.06615","0.04359"
"27.13200","0.00791","0.03742"
"27.13400","0.00718","0.03772"
"27.33400","0.04907","0.06483"
"27.53400","0.12224","0.10827"
"27.73400","0.19402","0.22264"
"27.93400","0.26582","0.47515"
"28.13400","0.33804","0.90809"
"28.33400","0.40989","1.62234"
"28.53400","0.48196","2.72354"
"28.73400","0.55368","4.24768"
"28.93400","0.62553","6.29979"
"29.13400","0.69773","8.95774"
"29.33400","0.76935","12.29284"
"29.53400","0.84135","16.39888"
"29.73400","0.91353","21.35320"
"29.93400","0.98523","27.18414"
"30.13400","1.05733","33.87629"
"30.33400","1.12912","41.24418"
"30.53400","1.20110","49.29904"
"30.71700","1.26677","57.13933"
"30.71900","1.26751","57.22984"
"30.91900","1.27755","57.35854"
"31.11900","1.27527","56.50539"
"31.31900","1.27495","56.04367"
"31.51900","1.27491","55.72126"
"31.71900","1.27491","55.47179"
"31.91900","1.27481","55.25079"
"32.11900","1.27487","55.06004"
"32.31900","1.27488","54.90203"
"32.51900","1.27491","54.75118"
"32.71900","1.27491","54.62000"
"32.91900","1.27491","54.50584"
"33.11900","1.27491","54.39108"
"33.31900","1.27491","54.29112"
"33.51900","1.27491","54.19378"
"33.71900","1.27491","54.10671"
"33.91900","1.27491","54.01876"
"34.11900","1.27491","53.93497"
"34.31900","1.27491","53.85864"
"34.51900","1.27491","53.78156"
"34.71900","1.27491","53.70962"
"34.91900","1.27491","53.64660"
"35.11900","1.27491","53.58944"
"35.31900","1.27491","53.52825"
"35.51900","1.27491","53.46786"
"35.71900","1.27491","53.40484"
"35.91900","1.27491","53.34974"
"36.11900","1.27491","53.29657"
"36.31900","1.27491","53.25381"
"36.51900","1.27491","53.20416"
"36.71900","1.27491","53.15046"
"36.91900","1.27491","53.10395"
"37.11900","1.27491","53.04790"
"37.31900","1.27491","53.01664"
"37.51900","1.27491","52.96634"
"37.71900","1.27491","52.92131"
"37.91900","1.27491","52.88045"
"38.11900","1.27491","52.84049"
"38.31900","1.27491","52.79734"
"38.51900","1.27491","52.75843"
"38.71900","1.27491","52.71758"
"38.91900","1.27491","52.67740"
"39.11900","1.27491","52.64776"
"39.31900","1.27491","52.60716"
"39.51900","1.27491","52.56771"
"39.71900","1.27491","52.53432"
"39.91900","1.27491","52.50449"
"40.11900","1.27491","52.47401"
"40.31900","1.27491","52.44228"
"40.51900","1.27491","52.40184"
"40.71900","1.27491","52.37573"
"40.91900","1.27491","52.34317"
"41.11900","1.27491","52.30552"
"41.31900","1.27491","52.28128"
"41.51900","1.27491","52.24438"
"41.71900","1.27491","52.22023"
"41.91900","1.27491","52.19255"
"42.11900","1.27491","52.16368"
"42.31900","1.27491","52.13773"
"42.51900","1.27491","52.10514"
"42.71900","1.27491","52.07764"
"42.91900","1.27491","52.04756"
"43.11900","1.27491","52.01637"
"43.31900","1.27491","51.99461"
"43.51900","1.27491","51.95891"
"43.71900","1.27491","51.94044"
"43.91900","1.27491","51.91540"
"44.11900","1.27491","51.88515"
"44.31900","1.27491","51.85892"
"44.51900","1.27491","51.83664"
"44.71900","1.27491","51.80845"
"44.91900","1.27491","51.78316"
"45.11900","1.27491","51.75740"
"45.31900","1.27491","51.73290"
"45.51900","1.27491","51.71754"
"45.71900","1.27491","51.68985"
"45.91900","1.27491","51.66196"
"46.11900","1.27491","51.63804"
"46.31900","1.27491","51.61452"
"46.51900","1.27491","51.58386"
"46.71900","1.27491","51.56182"
"46.91900","1.27491","51.54789"
"47.11900","1.27491","51.52031"
"47.31900","1.27491","51.49640"
"47.51900","1.27491","51.47576"
"47.71900","1.27491","51.44986"
"47.91900","1.27491","51.43094"
"48.11900","1.27491","51.40693"
"48.31900","1.27491","51.38194"
"48.51900","1.27491","51.35843"
"48.71900","1.27491","51.34539"
"48.91900","1.27491","51.32445"
"49.11900","1.27491","51.30029"
"49.31900","1.27491","51.27759"
"49.51900","1.27491","51.25007"
"49.71900","1.27491","51.24439"
"49.91900","1.27491","51.21945"
"50.11900","1.27491","51.20050"
"50.31900","1.27491","51.18022"
"50.51900","1.27491","51.15908"
"50.71800","1.27491","51.13905"
"50.74700","1.27491","51.13411"
"50.92700","1.22533","43.81510"
"51.12700","1.15301","34.51752"
"51.32700","1.08099","26.92736"
"51.52700","1.00878","20.69994"
"51.72700","0.93705","15.60715"
"51.92700","0.86513","11.48626"
"52.12700","0.79339","8.23726"
"52.32700","0.72131","5.72284"
"52.52700","0.64914","3.83184"
"52.72700","0.57755","2.43788"
"52.92700","0.50547","1.45328"
"53.12700","0.43343","0.80745"
"53.32700","0.36174","0.40583"
"53.52700","0.28975","0.18121"
"53.72700","0.21790","0.08663"
"53.92700","0.14591","0.04509"
"54.12700","0.07390","0.04035"
"54.28800","0.01629","0.03743"
"54.29000","0.01555","0.03695"
"54.49000","0.05712","0.06256"
"54.69000","0.13043","0.09112"
"54.89000","0.20224","0.17930"
"55.09000","0.27408","0.36913"
"55.29000","0.34616","0.72841"
"55.49000","0.41798","1.33761"
"55.69000","0.49027","2.29303"
"55.89000","0.56185","3.70071"
"56.09000","0.63362","5.59887"
"56.29000","0.70592","8.08970"
"56.49000","0.77764","11.25020"
"56.69000","0.84958","15.21647"
"56.89000","0.92154","20.02973"
"57.09000","0.99337","25.78463"
"57.29000","1.06544","32.40290"
"57.49000","1.13711","39.77110"
"57.69000","1.20908","47.84676"
"57.87300","1.27505","55.79792"
"57.87500","1.27578","55.88610"
"58.07500","1.28561","56.08107"
"58.27500","1.28337","55.27154"
"58.47500","1.28297","54.84425"
"58.67500","1.28297","54.54703"
"58.87500","1.28288","54.31788"
"59.07500","1.28288","54.13087"
"59.27500","1.28293","53.95800"
"59.47500","1.28293","53.81720"
"59.67500","1.28293","53.69537"
"59.87500","1.28293","53.57127"
"60.07500","1.28294","53.47098"
"60.27500","1.28294","53.37324"
"60.47500","1.28294","53.28320"
"60.67500","1.28294","53.19366"
"60.87500","1.28295","53.12185"
"61.07500","1.28294","53.04066"
"61.27500","1.28297","52.97573"
"61.47500","1.28297","52.91142"
"61.67500","1.28297","52.85555"
"61.87500","1.28297","52.78863"
"62.07500","1.28297","52.73463"
"62.27500","1.28297","52.67715"
"62.47500","1.28297","52.62494"
"62.67500","1.28297","52.57919"
"62.87500","1.28297","52.52880"
"63.07500","1.28297","52.47807"
"63.27500","1.28297","52.42831"
"63.47500","1.28297","52.39296"
"63.67500","1.28297","52.35028"
"63.87500","1.28297","52.29793"
"64.07500","1.28297","52.27044"
"64.27500","1.28297","52.22688"
"64.47500","1.28297","52.19310"
"64.67500","1.28297","52.15226"
"64.87500","1.28297","52.11748"
"65.07500","1.28297","52.08435"
"65.27500","1.28297","52.04366"
"65.47500","1.28297","52.01499"
"65.67500","1.28297","51.97567"
"65.87500","1.28297","51.94076"
"66.07500","1.28297","51.91300"
"66.27500","1.28297","51.88525"
"66.47500","1.28297","51.84611"
"66.67500","1.28297","51.82101"
"66.87500","1.28297","51.79590"
"67.07500","1.28297","51.76489"
"67.27500","1.28297","51.74082"
"67.47500","1.28297","51.70972"
"67.67500","1.28297","51.68195"
"67.87500","1.28297","51.65662"
"68.07500","1.28297","51.63373"
"68.27500","1.28297","51.60089"
"68.47500","1.28297","51.58052"
"68.67500","1.28297","51.55084"
"68.87500","1.28297","51.52343"
"69.07500","1.28297","51.49783"
"69.27500","1.28297","51.47203"
"69.47500","1.28297","51.45723"
"69.67500","1.28297","51.42588"
"69.87500","1.28297","51.41126"
"70.07500","1.28297","51.38184"
"70.27500","1.28297","51.36274"
"70.47500","1.28297","51.33579"
"70.67500","1.28297","51.32085"
"70.87500","1.28297","51.28950"
"71.07500","1.28297","51.27583"
"71.27500","1.28297","51.25512"
"71.47500","1.28297","51.23337"
"71.67500","1.28297","51.20667"
"71.87500","1.28297","51.19390"
"72.07500","1.28297","51.17364"
"72.27500","1.28297","51.15032"
"72.47500","1.28297","51.13571"
"72.67500","1.28297","51.11162"
"72.87500","1.28297","51.09303"
"73.07500","1.28297","51.07295"
"73.27500","1.28297","51.05661"
"73.47500","1.28297","51.02975"
"73.67500","1.28297","51.01469"
"73.87500","1.28297","50.99448"
"74.07500","1.28297","50.97899"
"74.27500","1.28297","50.95772"
"74.47500","1.28297","50.94411"
"74.67500","1.28297","50.92485"
"74.87500","1.28297","50.90801"
"75.07500","1.28297","50.88451"
"75.27500","1.28297","50.87822"
"75.47500","1.28297","50.84742"
"75.67500","1.28297","50.83213"
"75.87500","1.28297","50.81532"
"76.07500","1.28297","50.80220"
"76.27500","1.28297","50.77961"
"76.47500","1.28297","50.76327"
"76.67500","1.28297","50.74540"
"76.87500","1.28297","50.73497"
"77.07500","1.28297","50.71914"
"77.27500","1.28297","50.69470"
"77.47500","1.28297","50.68142"
"77.67500","1.28297","50.65833"
"77.87400","1.28297","50.64666"
"77.90100","1.28297","50.64418"
"78.08100","1.23356","43.37096"
"78.28100","1.16131","34.03380"
"78.48100","1.08913","26.44105"
"78.68100","1.01679","20.22649"
"78.88100","0.94531","15.17480"
"79.08100","0.87335","11.08545"
"79.28100","0.80148","7.89894"
"79.48100","0.72947","5.44241"
"79.68100","0.65750","3.60469"
"79.88100","0.58575","2.26537"
"80.08100","0.51357","1.32473"
"80.28100","0.44159","0.72348"
"80.48100","0.36995","0.35740"
"80.68100","0.29780","0.15779"
"80.88100","0.22605","0.07926"
"81.08100","0.15411","0.04592"
"81.28100","0.08192","0.03693"
"81.44300","0.02407","0.04198"
"81.44500","0.02334","0.04248"
"81.64500","0.06495","0.06159"
"81.84500","0.13814","0.08546"
"82.04500","0.21001","0.14700"
"82.24500","0.28201","0.31843"
"82.37500","0.32871","0.50036"
"82.37700","0.32942","0.50435"
"82.39700","0.33595","0.52478"
"82.41700","0.33985","0.56411"
"82.43700","0.34349","0.56850"
"82.45700","0.34646","0.59490"
"82.47700","0.35150","0.62560"
"82.49700","0.35961","0.68002"
"82.51700","0.36872","0.73954"
"82.53700","0.37743","0.79065"
"82.55700","0.38550","0.85545"
"82.57700","0.39306","0.91264"
"82.59700","0.40040","0.96782"
"82.61700","0.40778","1.03009"
"82.63700","0.41516","1.09994"
"82.65700","0.42241","1.16933"
"82.67700","0.42952","1.23971"
"82.69700","0.43662","1.31432"
"82.71700","0.44397","1.39568"
"82.73700","0.45139","1.48151"
"82.75700","0.45859","1.56776"
"82.77700","0.46562","1.66203"
"82.79700","0.47274","1.75042"
"82.81700","0.48013","1.84516"
"82.83700","0.48763","1.94738"
"82.85700","0.49487","2.05518"
"82.87700","0.50182","2.16605"
"82.89700","0.50877","2.28139"
"82.91700","0.51599","2.39804"
"82.93700","0.52341","2.52563"
"82.95700","0.53076","2.65277"
"82.97700","0.53784","2.78706"
"82.99700","0.54479","2.92122"
"83.01700","0.55192","3.05477"
"83.03700","0.55923","3.20337"
"83.05700","0.56652","3.35975"
"83.07700","0.57367","3.51374"
"83.09700","0.58067","3.66987"
"83.11700","0.58780","3.84203"
"83.13700","0.59511","4.02243"
"83.15700","0.60243","4.19854"
"83.17700","0.60961","4.37519"
"83.19700","0.61669","4.55854"
"83.21700","0.62380","4.74819"
"83.23700","0.63103","4.95497"
"83.25700","0.63824","5.15688"
"83.27700","0.64540","5.36217"
"83.29700","0.65261","5.58151"
"83.31700","0.66001","5.81302"
"83.33700","0.66738","6.04703"
"83.35700","0.67454","6.28223"
"83.37700","0.68154","6.51803"
"83.39700","0.68861","6.76212"
"83.41700","0.69596","7.01470"
"83.43700","0.70334","7.28027"
"83.45700","0.71048","7.54943"
"83.47700","0.71745","7.81920"
"83.49700","0.72448","8.09235"
"83.51700","0.73179","8.37992"
"83.53700","0.73924","8.68501"
"83.55700","0.74647","8.98982"
"83.57700","0.75343","9.29061"
"83.59700","0.76036","9.59265"
"83.61700","0.76758","9.91890"
"83.63700","0.77499","10.25553"
"83.65700","0.78231","10.59776"
"83.67700","0.78937","10.94289"
"83.69700","0.79633","11.28645"
"83.71700","0.80349","11.65335"
"83.73700","0.81083","12.03252"
"83.75700","0.81813","12.41216"
"83.77700","0.82528","12.79648"
"83.79700","0.83235","13.18915"
"83.81700","0.83959","13.60739"
"83.83700","0.84697","14.03684"
"83.85700","0.85429","14.46237"
"83.87700","0.86147","14.88630"
"83.89700","0.86860","15.32470"
"83.91700","0.87579","15.78189"
"83.93700","0.88304","16.25337"
"83.95700","0.89021","16.72575"
"83.97700","0.89730","17.18475"
"83.99700","0.90446","17.66307"
"84.01700","0.91176","18.16739"
"84.03700","0.91900","18.68182"
"84.05700","0.92607","19.19750"
"84.07700","0.93309","19.70926"
"84.09700","0.94023","20.23091"
"84.11700","0.94756","20.78028"
"84.13700","0.95486","21.34760"
"84.15700","0.96197","21.91616"
"84.17700","0.96897","22.48315"
"84.19700","0.97611","23.05687"
"84.21700","0.98346","23.65539"
"84.23700","0.99081","24.26368"
"84.25700","0.99794","24.87223"
"84.27700","1.00491","25.47990"
"84.29700","1.01200","26.09646"
"84.31700","1.01935","26.74823"
"84.33700","1.02679","27.40180"
"84.35700","1.03411","28.06006"
"84.37700","1.04124","28.72398"
"84.39700","1.04833","29.39354"
"84.41700","1.05557","30.07517"
"84.43700","1.06286","30.76120"
"84.45700","1.07006","31.43694"
"84.47700","1.07714","32.12566"
"84.49700","1.08421","32.83318"
"84.51700","1.09143","33.56477"
"84.53700","1.09870","34.30582"
"84.55700","1.10594","35.03537"
"84.57700","1.11308","35.75611"
"84.59700","1.12021","36.49744"
"84.61700","1.12740","37.25932"
"84.63700","1.13457","38.03839"
"84.65700","1.14169","38.80246"
"84.67700","1.14878","39.55064"
"84.69700","1.15601","40.32830"
"84.71700","1.16332","41.14510"
"84.73700","1.17056","41.96041"
"84.75700","1.17768","42.77407"
"84.77700","1.18473","43.56776"
"84.79700","1.19196","44.37904"
"84.81700","1.19936","45.21701"
"84.83700","1.20658","46.04907"
"84.85700","1.21357","46.87408"
"84.87700","1.22059","47.70515"
"84.89700","1.22791","48.56899"
"84.91700","1.23545","49.46647"
"84.93700","1.24281","50.34610"
"84.95700","1.24987","51.20246"
"84.97700","1.25682","52.06019"
"84.99700","1.26395","52.93324"
"85.01700","1.27129","53.83158"
"85.03700","1.27863","54.72535"
"85.05700","1.28576","55.59941"
"85.07700","1.29270","56.46978"
"85.09700","1.29977","57.37153"
"85.11700","1.30710","58.29715"
"85.13700","1.31445","59.21807"
"85.15700","1.32166","60.11175"
"85.17700","1.32868","60.98804"
"85.19700","1.33573","61.88872"
"85.21700","1.34297","62.81950"
"85.23700","1.35028","63.75396"
"85.25700","1.35748","64.65697"
"85.27700","1.36456","65.54156"
"85.29700","1.37170","66.45036"
"85.31700","1.37896","67.39844"
"85.33700","1.38618","68.33300"
"85.35700","1.39330","69.23671"
"85.37700","1.40044","70.13513"
"85.39700","1.40781","71.07050"
"85.41700","1.41526","72.03191"
"85.43700","1.42252","72.97108"
"85.45700","1.42957","73.87056"
"85.47700","1.43659","74.74407"
"85.49700","1.44384","75.65732"
"85.51700","1.45124","76.59840"
"85.53700","1.45844","77.51799"
"85.55700","1.46544","78.40250"
"85.57700","1.47243","79.27591"
"85.59700","1.47968","80.17942"
"85.61700","1.48712","81.10293"
"85.63700","1.49438","82.00307"
"85.65700","1.50134","82.87123"
"85.67700","1.50829","83.73180"
"85.69700","1.51551","84.62229"
"85.71700","1.52291","85.53503"
"85.73700","1.53025","86.42844"
"85.75700","1.53739","87.30249"
"85.77700","1.54439","88.16423"
"85.79700","1.55150","89.04569"
"85.81700","1.55879","89.93198"
"85.83700","1.56607","90.79559"
"85.85700","1.57324","91.64668"
"85.87700","1.58029","92.48975"
"85.89700","1.58747","93.36550"
"85.91700","1.59487","94.26810"
"85.93700","1.60223","95.15410"
"85.95700","1.60944","96.00078"
"85.97700","1.61655","96.82816"
"85.99700","1.62375","97.68869"
"86.01700","1.63100","98.56358"
"86.03700","1.63818","99.40872"
"86.05700","1.64526","100.21783"
"86.07700","1.65236","101.02943"
"86.09700","1.65965","101.88601"
"86.11700","1.66695","102.75954"
"86.13700","1.67407","103.60575"
"86.15700","1.68110","104.42970"
"86.17700","1.68819","105.24107"
"86.19700","1.69548","106.08727"
"86.21700","1.70282","106.93867"
"86.23700","1.70998","107.76588"
"86.25700","1.71699","108.56018"
"86.27700","1.72407","109.35089"
"86.29700","1.73138","110.15484"
"86.31700","1.73876","110.96598"
"86.33700","1.74594","111.75530"
"86.35700","1.75291","112.53544"
"86.37700","1.75995","113.33572"
"86.39700","1.76725","114.17382"
"86.39900","1.76799","114.25926"
"86.56300","1.74051","107.50787"
"86.71000","1.68583","97.46075"
"86.87400","1.62700","87.39961"
"87.05000","1.56341","77.30484"
"87.23800","1.49603","67.25545"
"87.43600","1.42463","57.33936"
"87.63600","1.35280","48.12723"
"87.83600","1.28085","39.66906"
"88.03600","1.20867","32.04027"
"88.23600","1.13698","25.41776"
"88.43600","1.06492","19.69467"
"88.63600","0.99327","14.90819"
"88.83600","0.92139","10.97397"
"89.03600","0.84918","7.83456"
"89.23600","0.77752","5.44015"
"89.43600","0.70554","3.60805"
"89.63600","0.63352","2.27593"
"89.83600","0.56161","1.33660"
"90.03600","0.48971","0.72777"
"90.23600","0.41794","0.35568"
"90.43600","0.34587","0.16723"
"90.48500","0.32829","0.13170"
"90.58600","0.32925","0.17076"
"90.78100","0.40411","0.50120"
"90.78300","0.40484","0.50554"
"90.78500","0.40557","0.50975"
"90.78700","0.40631","0.51665"
"90.78900","0.40709","0.53266"
"90.79100","0.40794","0.55976"
"90.79300","0.40894","0.59476"
"90.79500","0.41020","0.63616"
"90.79700","0.41183","0.68608"
"90.79900","0.41396","0.74489"
"90.80100","0.41671","0.81096"
"90.80300","0.42022","0.88632"
"90.80500","0.42464","0.97314"
"90.80700","0.43010","1.07341"
"90.80900","0.43673","1.18997"
"90.81100","0.44468","1.32732"
"90.81300","0.45407","1.48992"
"90.81500","0.46502","1.68407"
"90.81700","0.47764","1.91888"
"90.81900","0.49203","2.20516"
"90.82100","0.50831","2.55596"
"90.82300","0.52655","2.98742"
"90.82500","0.54683","3.51774"
"90.82700","0.56923","4.16886"
"90.82900","0.59382","4.96667"
"90.83100","0.62065","5.94040"
"90.83300","0.64977","7.12349"
"90.83500","0.68123","8.55390"
"90.83700","0.71506","10.27038"
"90.83900","0.75130","12.31286"
"90.84100","0.78997","14.72038"
"90.84300","0.83109","17.52706"
"90.84500","0.87468","20.76314"
"90.84700","0.92073","24.45703"
"90.84900","0.96926","28.63324"
"90.85100","1.02024","33.30613"
"90.85300","1.07363","38.47876"
"90.85500","1.12937","44.14171"
"90.85700","1.18735","50.27445"
"90.85900","1.24738","56.84736"
"90.86100","1.30930","63.82333"
"90.86300","1.37288","71.15654"
"90.86500","1.43791","78.79427"
"90.86700","1.50419","86.68127"
"90.86900","1.57153","94.76102"
"90.87100","1.63975","102.97664"
"90.87300","1.70871","111.27502"
"90.87500","1.77826","119.60580"
"90.87700","1.84830","127.92422"
"90.87900","1.91875","136.19646"
"90.88100","1.98953","144.39215"
"90.88300","2.06060","152.48068"
"90.88500","2.13191","160.42561"
"90.88700","2.20344","167.59462"
"90.88900","2.27515","172.19781"
"90.89100","2.34705","173.58757"
"90.89300","2.41912","172.14754"
"90.89500","2.49134","168.43118"
"90.89700","2.56371","162.88182"
"90.89900","2.63623","155.88138"
"90.90100","2.70888","147.76752"
"90.90300","2.78166","138.84039"
"90.90500","2.85456","129.36356"
"90.90700","2.92755","119.57112"
"90.90900","3.00063","109.65841"
"90.91100","3.07379","99.78435"
"90.91300","3.14699","90.07809"
"90.91500","3.22023","80.64689"
"90.91700","3.29349","71.58139"
"90.91900","3.36675","62.95142"
"90.92100","3.44000","54.80975"
"90.92300","3.51322","47.19753"
"90.92500","3.58640","40.14489"
"90.92700","3.65953","33.66462"
"90.92900","3.73261","27.75533"
"90.93100","3.80563","22.40759"
"90.93300","3.87859","17.60428"
"90.93500","3.95147","13.32440"
"90.93700","4.02429","9.54271"
"90.93900","4.09703","6.23379"
"90.94100","4.16971","3.37301"
"90.94300","4.24232","0.93563"
"90.94500","4.31487","-1.11048"
"90.94700","4.38735","-2.80247"
"90.94900","4.45978","-4.17790"
"90.95100","4.53216","-5.26781"
"90.95300","4.60448","-6.09954"
"90.95500","4.67676","-6.70193"
"90.95700","4.74899","-7.10418"
"90.95900","4.82119","-7.33564"
"90.96100","4.89334","-7.42193"
"90.96300","4.96547","-7.38780"
"90.96500","5.03756","-7.25595"
"90.96700","5.10963","-7.04321"
"90.96900","5.18169","-6.75992"
"90.97100","5.25373","-6.41969"
"90.97300","5.32576","-6.03946"
"90.97500","5.39778","-5.63185"
"90.97700","5.46979","-5.20346"
"90.97900","5.54180","-4.76491"
"90.98100","5.61380","-4.32994"
"90.98300","5.68579","-3.90626"
"90.98500","5.75779","-3.49431"
"90.98700","5.82978","-3.09272"
"90.98900","5.90177","-2.70488"
"90.99100","5.97376","-2.33726"
"90.99300","6.04576","-1.99690"
"90.99500","6.11775","-1.68676"
"90.99700","6.18974","-1.40453"
"90.99900","6.26174","-1.14637"
"91.00100","6.33373","-0.91126"
"91.00300","6.40571","-0.69917"
"91.00500","6.47770","-0.51184"
"91.00700","6.54968","-0.34957"
"91.00900","6.62166","-0.20881"
"91.01100","6.69364","-0.08583"
"91.01300","6.76562","0.02189"
"91.01500","6.83760","0.11481"
"91.01700","6.90958","0.19247"
"91.01900","6.98156","0.25724"
"91.02100","7.05354","0.31156"
"91.02300","7.12552","0.35527"
"91.02500","7.19749","0.38837"
"91.02700","7.26946","0.40900"
"91.02900","7.34143","0.41556"
"91.03100","7.41340","0.41368"
"91.03300","7.48536","0.40999"
"91.03500","7.55733","0.40520"
"91.03700","7.62930","0.39458"
"91.03900","7.70127","0.37871"
"91.04100","7.77324","0.36304"
"91.04300","7.84522","0.34929"
"91.04500","7.91719","0.33483"
"91.04700","7.98916","0.31900"
"91.04900","8.06113","0.30321"
"91.05100","8.13311","0.29002"
"91.05300","8.20508","0.27956"
"91.05500","8.27706","0.26837"
"91.05700","8.34904","0.25437"
"91.05900","8.42102","0.23799"
"91.06100","8.49299","0.22128"
"91.06300","8.56497","0.20736"
"91.06500","8.63693","0.19621"
"91.06700","8.70890","0.18539"
"91.06900","8.78086","0.17296"
"91.07100","8.85282","0.15875"
"91.07300","8.92477","0.14538"
"91.07500","8.99673","0.13538"
"91.07700","9.06868","0.12872"
"91.07900","9.14063","0.12396"
"91.08100","9.21258","0.11975"
"91.08300","9.28452","0.11573"
"91.08500","9.35646","0.11344"
"91.08700","9.42840","0.11280"
"91.08900","9.50033","0.11074"
"91.09100","9.57227","0.10693"
"91.09300","9.64420","0.10335"
"91.09500","9.71613","0.10022"
"91.09700","9.78806","0.09741"
"91.09900","9.85998","0.09486"
"91.10100","9.93190","0.09074"
"91.10300","10.00382","0.08439"
"91.10500","10.07574","0.07896"
"91.10700","10.14766","0.07725"
"91.10900","10.21957","0.07771"
"91.11100","10.29148","0.07860"
"91.11300","10.36340","0.07895"
"91.11500","10.43532","0.07876"
"91.11700","10.50723","0.07973"
"91.11900","10.57915","0.08288"
"91.12100","10.65108","0.08696"
"91.12300","10.72300","0.08932"
"91.12500","10.79493","0.09020"
"91.12700","10.86685","0.09160"
"91.12900","10.93878","0.09396"
"91.13100","11.01070","0.09516"
"91.13300","11.08263","0.09511"
"91.13500","11.15456","0.09490"
"91.13700","11.22649","0.09506"
"91.13900","11.29842","0.09486"
"91.14100","11.37035","0.09623"
"91.14300","11.44227","0.09998"
"91.14500","11.51420","0.10431"
"91.14700","11.58613","0.10583"
"91.14900","11.65805","0.10500"
"91.15100","11.72997","0.10451"
"91.15300","11.80189","0.10590"
"91.15500","11.87381","0.10669"
"91.15700","11.94573","0.10561"
"91.15900","12.01765","0.10379"
"91.16100","12.08958","0.10252"
"91.16300","12.16150","0.10089"
"91.16500","12.23342","0.09914"
"91.16700","12.30534","0.09822"
"91.16900","12.37726","0.09813"
"91.17100","12.44917","0.09739"
"91.17300","12.52108","0.09550"
"91.17500","12.59298","0.09543"
"91.17700","12.66489","0.09574"
"91.17900","12.73680","0.09408"
"91.18100","12.80870","0.09146"
"91.18300","12.88061","0.09160"
"91.18500","12.95252","0.09385"
"91.18700","13.02443","0.09475"
"91.18900","13.09635","0.09419"
"91.19100","13.16826","0.09333"
"91.19300","13.24017","0.09066"
"91.19500","13.31208","0.08635"
"91.19700","13.38399","0.08286"
"91.19900","13.45590","0.08145"
"91.20100","13.52782","0.08096"
"91.20300","13.59973","0.08171"
"91.20500","13.67165","0.08464"
"91.20700","13.74357","0.08813"
"91.20900","13.81549","0.09049"
"91.21100","13.88741","0.09285"
"91.21300","13.95932","0.09649"
"91.21500","14.03124","0.09985"
"91.21700","14.10316","0.10125"
"91.21900","14.17509","0.10103"
"91.22100","14.24701","0.10016"
"91.22300","14.31894","0.09941"
"91.22500","14.39087","0.09936"
"91.22700","14.46280","0.09948"
"91.22900","14.53474","0.10019"
"91.23100","14.60667","0.10184"
"91.23300","14.67861","0.10333"
"91.23500","14.75054","0.10476"
"91.23700","14.82248","0.10705"
"91.23900","14.89441","0.11119"
"91.24100","14.96634","0.11403"
"91.24300","15.03827","0.11256"
"91.24500","15.11019","0.11044"
"91.24700","15.18211","0.11195"
"91.24900","15.25403","0.11348"
"91.25100","15.32595","0.10962"
"91.25300","15.39787","0.10192"
"91.25500","15.46979","0.09620"
"91.25700","15.54171","0.09284"
"91.25900","15.61363","0.08876"
"91.26100","15.68555","0.08354"
"91.26300","15.75748","0.07978"
"91.26500","15.82940","0.07909"
"91.26700","15.90133","0.07995"
"91.26900","15.97326","0.08069"
"91.27100","16.04518","0.08147"
"91.27300","16.11710","0.08232"
"91.27500","16.18902","0.08361"
"91.27700","16.26094","0.08590"
"91.27900","16.33286","0.08775"
"91.28100","16.40477","0.08856"
"91.28300","16.47668","0.08887"
"91.28500","16.54859","0.08786"
"91.28700","16.62050","0.08560"
"91.28900","16.69241","0.08397"
"91.29100","16.76431","0.08434"
"91.29300","16.83621","0.08555"
"91.29500","16.90811","0.08562"
"91.29700","16.98001","0.08507"
"91.29900","17.05191","0.08712"
"91.30100","17.12381","0.09067"
"91.30300","17.19571","0.09396"
"91.30500","17.26762","0.09772"
"91.30700","17.33953","0.10258"
"91.30900","17.41145","0.10827"
"91.31100","17.48336","0.11339"
"91.31300","17.55528","0.11624"
"91.31500","17.62720","0.11508"
"91.31700","17.69911","0.11134"
"91.31900","17.77103","0.10827"
"91.32100","17.84295","0.10550"
"91.32300","17.91488","0.10228"
"91.32500","17.98681","0.09977"
"91.32700","18.05874","0.09742"
"91.32900","18.13068","0.09494"
"91.33100","18.20262","0.09277"
"91.33300","18.27456","0.09103"
"91.33500","18.34650","0.08944"
"91.33700","18.41845","0.08841"