File: data/instron/Sample20_Dynamic.is_tcyclic_RawData/Specimen_RawData_1.csv
Strain : Tensile strain (Extension) gauge length,"100.00000",mm

Time,Extension,Load
(s),(mm),(N)
"0.00000","0.00000","0.29314"
"0.20000","0.13526","1.96573"
"0.40000","0.30624","6.67702"
"0.60000","0.47657","14.99900"
"0.78300","0.63256","25.02642"
"0.94800","0.77313","35.10945"
"1.04100","0.85204","40.91943"
"1.04300","0.85373","41.04495"
"1.18800","0.79469","31.15866"
"1.30000","0.69702","21.11549"
"1.45300","0.56676","11.05689"
"1.65300","0.39649","3.31660"
"1.85300","0.22622","0.54941"
"2.05300","0.05605","0.09203"
"2.12000","-0.00121","0.07075"
"2.22100","0.01459","0.12125"
"2.42100","0.19150","0.90012"
"2.62100","0.36175","4.84329"
"2.82100","0.53183","13.66785"
"2.98400","0.67073","23.71943"
"3.12700","0.79276","33.80944"
"3.19700","0.85212","38.90289"
"3.19900","0.85381","39.04970"
"3.34400","0.79472","29.86223"
"3.45800","0.69534","19.80041"
"3.61700","0.55998","9.75529"
"3.81700","0.38966","2.65327"
"4.01700","0.21941","0.37980"
"4.21700","0.04927","0.08677"
"4.27600","-0.00117","0.06425"
"4.37700","0.01452","0.10573"
"4.57700","0.19147","0.67592"
"4.77700","0.36172","4.16659"
"4.97700","0.53181","12.61577"
"5.14100","0.67154","22.64977"
"5.28300","0.79273","32.77416"
"5.35300","0.85208","37.98112"
"5.35500","0.85377","38.13270"
"5.50000","0.79470","29.15956"
"5.61500","0.69448","19.11107"
"5.77700","0.55654","9.06956"
"5.97700","0.38620","2.32358"
"6.17700","0.21596","0.29938"
"6.37700","0.04583","0.07461"
"6.43200","-0.00120","0.06694"
"6.53300","0.01441","0.09910"
"6.73300","0.19139","0.56171"
"6.93300","0.36163","3.79119"
"7.13300","0.53171","11.99809"
"7.29900","0.67313","22.08988"
"7.43900","0.79262","32.10725"
"7.50900","0.85199","37.36578"
"7.51100","0.85368","37.51954"
"7.65700","0.79371","28.56673"
"7.77400","0.69185","18.45003"
"7.94100","0.54962","8.36287"
"8.14100","0.37924","2.01731"
"8.34100","0.20902","0.24217"
"8.54100","0.03889","0.06408"
"8.58800","-0.00129","0.06475"
"8.68900","0.01429","0.08478"
"8.88900","0.19125","0.49374"
"9.08900","0.36150","3.52100"
"9.28900","0.53158","11.56300"
"9.45600","0.67384","21.66103"
"9.59600","0.79335","31.69223"
"9.66500","0.85185","36.91239"
"9.66700","0.85355","37.06680"
"9.81300","0.79359","28.17829"
"9.93000","0.69175","18.12218"
"10.09800","0.54866","8.07400"
"10.29800","0.37829","1.88050"
"10.49800","0.20806","0.21825"
"10.69800","0.03792","0.06863"
"10.74400","-0.00140","0.05909"
"10.84500","0.01418","0.09108"
"11.04500","0.19114","0.45261"
"11.24500","0.36137","3.33196"
"11.44500","0.53146","11.23565"
"11.61200","0.67373","21.28618"
"11.75200","0.79323","31.31105"
"11.82100","0.85174","36.55943"
"11.82300","0.85344","36.71519"
"11.96900","0.79347","27.87446"
"12.08600","0.69166","17.85553"
"12.25600","0.54684","7.79925"
"12.45600","0.37648","1.75914"
"12.65600","0.20624","0.21184"
"12.85600","0.03610","0.06340"
"12.90000","-0.00150","0.05586"
"13.00100","0.01416","0.08156"
"13.20100","0.19101","0.41040"
"13.40100","0.36124","3.17132"
"13.60100","0.53134","10.96761"
"13.76900","0.67446","21.03181"
"13.90900","0.79396","31.06457"
"13.97700","0.85162","36.25173"
"13.97900","0.85331","36.40781"
"14.12500","0.79340","27.61338"
"14.24400","0.68986","17.49012"
"14.41600","0.54330","7.44527"
"14.61600","0.37298","1.61521"
"14.81600","0.20275","0.19293"
"15.01600","0.03259","0.06776"
"15.05600","-0.00159","0.05591"
"15.15700","0.01389","0.07999"
"15.35700","0.19086","0.38241"
"15.55700","0.36110","3.04961"
"15.75700","0.53120","10.73286"
"15.92500","0.67432","20.77109"
"16.06600","0.79468","30.86680"
"16.13400","0.85232","36.06268"
"16.13600","0.85402","36.21839"
"16.28200","0.79409","27.45763"
"16.40100","0.69054","17.34385"
"16.57500","0.54230","7.25325"
"16.77500","0.37196","1.54653"
"16.97500","0.20174","0.17867"
"17.17500","0.03160","0.06910"
"17.21300","-0.00091","0.05735"
"17.31400","0.01459","0.08073"
"17.51400","0.19158","0.36694"
"17.71400","0.36181","2.96047"
"17.91400","0.53189","10.58200"
"18.08200","0.67502","20.59897"
"18.22300","0.79538","30.69468"
"18.29000","0.85218","35.82771"
"18.29200","0.85387","35.98381"
"18.43800","0.79404","27.25127"
"18.55800","0.68959","17.10802"
"18.73200","0.54134","7.07964"
"18.93200","0.37100","1.46419"
"19.13200","0.20078","0.17288"
"19.33200","0.03065","0.05547"
"19.36900","-0.00101","0.05135"
"19.47000","0.01442","0.08276"
"19.67000","0.19148","0.34866"
"19.87000","0.36170","2.85670"
"20.07000","0.53179","10.40287"
"20.23900","0.67576","20.45072"
"20.38000","0.79614","30.55210"
"20.44700","0.85292","35.69727"
"20.54800","0.83682","32.12642"
"20.64900","0.74545","22.01353"
"20.79000","0.62500","11.99893"
"20.98800","0.45621","3.48282"
"21.18800","0.28590","0.47081"
"21.38800","0.11548","0.09184"
"21.52400","-0.00026","0.06510"
"21.52600","-0.00197","0.06423"
"21.72600","0.10525","0.12579"
"21.92600","0.27646","1.06464"
"22.12600","0.44686","5.82765"
"22.31600","0.60871","15.27840"
"22.46900","0.73890","25.39918"
"22.60200","0.85196","35.42752"
"22.60400","0.85365","35.58469"
"22.75000","0.79383","26.90712"
"22.87000","0.68940","16.79536"
"23.04700","0.53857","6.74643"
"23.24700","0.36828","1.34525"
"23.44700","0.19804","0.16792"
"23.64700","0.02789","0.05748"
"23.68100","-0.00120","0.05341"
"23.78200","0.01417","0.08470"
"23.98200","0.19123","0.32055"
"24.18200","0.36143","2.69997"
"24.38200","0.53153","10.11249"
"24.55200","0.67635","20.17525"
"24.69300","0.79675","30.27062"
"24.75900","0.85265","35.33535"
"24.86000","0.83638","31.77854"
"24.96100","0.74525","21.71635"
"25.10400","0.62308","11.65080"
"25.30400","0.45263","3.23597"
"25.50400","0.28227","0.42372"
"25.70400","0.11193","0.08483"
"25.83600","-0.00048","0.06050"
"25.83800","-0.00219","0.06028"
"26.03800","0.10498","0.13347"
"26.23800","0.27619","0.98504"
"26.43800","0.44660","5.61100"
"26.62900","0.60930","15.04423"
"26.78200","0.73950","25.14041"
"26.91400","0.85170","35.09702"
"26.91600","0.85340","35.25404"
"27.06200","0.79356","26.60751"
"27.18200","0.68917","16.54047"
"27.36000","0.53746","6.52220"
"27.56000","0.36719","1.25278"
"27.76000","0.19695","0.14166"
"27.96000","0.02679","0.05976"
"27.99300","-0.00145","0.05266"
"28.09400","0.01414","0.07651"
"28.29400","0.19100","0.29349"
"28.49400","0.36120","2.56877"
"28.69400","0.53132","9.86591"
"28.86500","0.67699","19.94053"
"29.00600","0.79737","30.02290"
"29.07100","0.85242","35.02151"
"29.17200","0.83622","31.48922"
"29.27300","0.74504","21.45579"
"29.41700","0.62198","11.38449"
"29.61700","0.45157","3.10622"
"29.81700","0.28123","0.39357"
"30.01700","0.11087","0.07534"
"30.14800","-0.00069","0.04950"
"30.15000","-0.00240","0.04882"
"30.35000","0.10470","0.11748"
"30.55000","0.27592","0.92556"
"30.75000","0.44632","5.43268"
"30.94100","0.60902","14.77169"
"31.09400","0.73921","24.83374"
"31.22700","0.85225","34.86637"
"31.22900","0.85394","35.02293"
"31.37500","0.79415","26.41203"
"31.49500","0.68973","16.36550"
"31.67400","0.53717","6.36562"
"31.87400","0.36688","1.20092"
"32.07400","0.19665","0.14042"
"32.27400","0.02652","0.05703"
"32.30600","-0.00086","0.05183"
"32.40700","0.01441","0.07511"
"32.60700","0.19153","0.28106"
"32.80700","0.36170","2.47445"
"33.00700","0.53183","9.69185"
"33.17800","0.67748","19.72213"
"33.31900","0.79788","29.80277"
"33.38400","0.85291","34.79520"
"33.48500","0.83676","31.28760"
"33.58700","0.74471","21.19028"
"33.73100","0.62169","11.17360"
"33.93100","0.45128","2.99687"
"34.13100","0.28099","0.36923"
"34.33100","0.11056","0.07426"
"34.46100","-0.00015","0.04966"
"34.46300","-0.00186","0.04992"
"34.66300","0.10524","0.11535"
"34.86300","0.27645","0.87782"
"35.06300","0.44686","5.29654"
"35.25500","0.61039","14.63852"
"35.40800","0.74062","24.69962"
"35.53900","0.85194","34.57825"
"35.54100","0.85363","34.73573"
"35.68800","0.79298","26.07227"
"35.81000","0.68686","15.95565"
"35.99000","0.53342","6.05942"
"36.19000","0.36314","1.09624"
"36.39000","0.19294","0.12753"
"36.59000","0.02281","0.05154"
"36.61800","-0.00116","0.05783"
"36.71900","0.01432","0.07727"
"36.91900","0.19121","0.26558"
"37.11900","0.36141","2.37431"
"37.31900","0.53153","9.48662"
"37.49100","0.67802","19.54210"
"37.63200","0.79841","29.60349"
"37.69600","0.85262","34.53332"
"37.79700","0.83645","31.03842"
"37.90000","0.74353","20.88882"
"38.04600","0.61883","10.83718"
"38.24600","0.44846","2.84312"
"38.44600","0.27814","0.33931"
"38.64600","0.10774","0.07265"
"38.77300","-0.00043","0.05443"
"38.77500","-0.00214","0.05463"
"38.97500","0.10487","0.12075"
"39.17500","0.27611","0.84776"
"39.37500","0.44653","5.15747"
"39.56700","0.61005","14.43577"
"39.72100","0.74112","24.53408"
"39.85100","0.85159","34.32568"
"39.85300","0.85328","34.48248"
"40.00000","0.79269","25.85496"
"40.12200","0.68655","15.75788"
"40.30300","0.53226","5.89806"
"40.50300","0.36198","1.03928"
"40.70300","0.19178","0.12185"
"40.90300","0.02165","0.05548"
"40.93000","-0.00146","0.04661"
"41.03100","0.01395","0.07495"
"41.23100","0.19085","0.25481"
"41.43100","0.36105","2.29501"
"41.63100","0.53118","9.32120"
"41.80400","0.67849","19.39154"
"41.94500","0.79889","29.45138"
"42.00900","0.85310","34.38218"
"42.11000","0.83704","30.91560"
"42.21300","0.74402","20.76085"
"42.36000","0.61845","10.68357"
"42.56000","0.44808","2.75990"
"42.76000","0.27775","0.31810"
"42.96000","0.10737","0.08070"
"43.08700","-0.00080","0.05453"
"43.08900","-0.00251","0.05415"
"43.28900","0.10449","0.11659"
"43.48900","0.27575","0.79791"
"43.68900","0.44615","5.03205"
"43.88200","0.61051","14.29742"
"44.03600","0.74159","24.38738"
"44.16600","0.85206","34.18519"
"44.16800","0.85375","34.34259"
"44.31500","0.79317","25.72097"
"44.43700","0.68700","15.65182"
"44.61800","0.53274","5.81910"
"44.81800","0.36242","1.00678"
"45.01800","0.19232","0.12000"
"45.21800","0.02212","0.05462"
"45.24500","-0.00100","0.05196"
"45.34600","0.01414","0.07281"
"45.54600","0.19132","0.24560"
"45.74600","0.36153","2.23913"
"45.94600","0.53166","9.20062"
"46.11900","0.67898","19.24351"
"46.26000","0.79937","29.29757"
"46.32300","0.85274","34.14512"
"46.42400","0.83668","30.69486"
"46.52700","0.74365","20.57648"
"46.67400","0.61806","10.53397"
"46.87400","0.44771","2.68102"
"47.07400","0.27739","0.30383"
"47.27400","0.10698","0.07405"
"47.40000","-0.00033","0.04498"
"47.40200","-0.00204","0.04457"
"47.60200","0.10501","0.11109"
"47.80200","0.27625","0.76892"
"48.00200","0.44663","4.94080"
"48.19500","0.61099","14.17335"
"48.34900","0.74209","24.24906"
"48.47800","0.85171","33.96816"
"48.48000","0.85340","34.12647"
"48.62700","0.79281","25.52349"
"48.74900","0.68665","15.48389"
"48.93000","0.53239","5.71146"
"49.13000","0.36207","0.97286"
"49.33000","0.19193","0.11286"
"49.53000","0.02175","0.06332"
"49.55700","-0.00138","0.04880"
"49.65800","0.01407","0.07037"
"49.85800","0.19101","0.23470"
"50.05800","0.36120","2.16564"
"50.25800","0.53133","9.06000"
"50.43200","0.67948","19.11751"
"50.57300","0.79989","29.16958"
"50.63500","0.85239","33.93639"
"50.73600","0.83619","30.48300"
"50.83900","0.74330","20.40087"
"50.98700","0.61688","10.33948"
"51.18700","0.44651","2.58890"
"51.38700","0.27622","0.29292"
"51.58700","0.10583","0.06667"
"51.71200","-0.00069","0.06134"
"51.71400","-0.00240","0.06227"
"51.91400","0.10462","0.10827"
"52.11400","0.27589","0.73237"
"52.31400","0.44625","4.83516"
"52.50700","0.61062","14.00140"
"52.66100","0.74171","24.05826"
"52.79100","0.85217","33.83478"
"52.79300","0.85386","33.99300"
"52.94000","0.79328","25.41508"
"53.06300","0.68628","15.33246"
"53.24500","0.53117","5.57576"
"53.44500","0.36086","0.92758"
"53.64500","0.19070","0.11937"
"53.84500","0.02053","0.05712"
"53.87000","-0.00090","0.05640"
"53.97100","0.01419","0.07038"
"54.17100","0.19144","0.22875"
"54.37100","0.36166","2.11990"
"54.57100","0.53176","8.96100"
"54.74500","0.67991","19.02208"
"54.88600","0.80031","29.05758"
"54.94800","0.85283","33.82407"
"55.04900","0.83672","30.38238"
"55.15200","0.74375","20.31349"
"55.30100","0.61648","10.21837"
"55.50100","0.44612","2.52569"
"55.70100","0.27581","0.27586"
"55.90100","0.10544","0.06200"
"56.02500","-0.00022","0.04507"
"56.02700","-0.00193","0.04583"
"56.22700","0.10506","0.10993"
"56.42700","0.27632","0.72043"
"56.62700","0.44670","4.76909"
"56.82000","0.61105","13.90710"
"56.97400","0.74216","23.94090"
"57.10300","0.85178","33.65065"
"57.10500","0.85347","33.80822"
"57.25200","0.79290","25.23850"
"57.37500","0.68590","15.19212"
"57.55700","0.53076","5.48468"
"57.75700","0.36049","0.89435"
"57.95700","0.19030","0.11380"
"58.15700","0.02015","0.04378"
"58.18200","-0.00128","0.04061"
"58.28300","0.01406","0.07031"
"58.48300","0.19105","0.22501"
"58.68300","0.36126","2.05984"
"58.88300","0.53136","8.83658"
"59.05800","0.68038","18.91315"
"59.19900","0.80076","28.93524"
"59.26000","0.85236","33.62073"
"59.36100","0.83649","30.22786"
"59.46400","0.74348","20.16243"
"59.61300","0.61616","10.10612"
"59.81300","0.44580","2.47260"
"60.01300","0.27552","0.26207"
"60.21300","0.10513","0.06919"
"60.33700","-0.00053","0.04578"
"60.33900","-0.00224","0.04599"
"60.53900","0.10480","0.10737"
"60.73900","0.27602","0.68504"
"60.93900","0.44639","4.67572"
"61.13300","0.61160","13.81139"
"61.28700","0.74272","23.85031"
"61.41600","0.85229","33.54663"
"61.41800","0.85399","33.70568"
"61.56500","0.79355","25.16162"
"61.68800","0.68655","15.11377"
"61.87000","0.53141","5.43935"
"62.07000","0.36114","0.87394"
"62.27000","0.19096","0.10591"
"62.47000","0.02078","0.04455"
"62.49600","-0.00148","0.04042"
"62.59700","0.01355","0.06948"
"62.79700","0.19078","0.21645"
"62.99700","0.36101","2.00623"
"63.19700","0.53108","8.71255"
"63.37200","0.68011","18.75556"
"63.51500","0.80208","28.89529"
"63.57500","0.85308","33.53938"
"63.67600","0.83710","30.13417"
"63.78000","0.74324","19.99785"
"63.92900","0.61594","9.98143"
"64.12900","0.44560","2.41525"
"64.32900","0.27531","0.25531"
"64.52900","0.10495","0.06835"
"64.65300","-0.00075","0.05006"
"64.65500","-0.00246","0.04996"
"64.85500","0.10455","0.10041"
"65.05500","0.27577","0.66047"
"65.25500","0.44614","4.59212"
"65.44900","0.61133","13.67636"
"65.60400","0.74330","23.74590"
"65.73200","0.85214","33.38567"
"65.73400","0.85383","33.54304"
"65.88100","0.79329","25.01101"
"66.00400","0.68630","14.98698"
"66.18700","0.53028","5.32400"
"66.38700","0.36002","0.84507"
"66.58700","0.18984","0.11032"
"66.78700","0.01966","0.05476"
"66.81100","-0.00089","0.05138"
"66.91200","0.01435","0.07651"
"67.11200","0.19139","0.20764"
"67.31200","0.36162","1.98024"
"67.51200","0.53168","8.63844"
"67.68700","0.68070","18.67357"
"67.82900","0.80192","28.74121"
"67.88900","0.85278","33.36272"
"67.99000","0.83690","29.98138"
"68.09400","0.74301","19.86512"
"68.24500","0.61400","9.77265"
"68.44500","0.44367","2.33145"
"68.64500","0.27339","0.24154"
"68.84500","0.10303","0.06326"
"68.96600","-0.00013","0.04257"
"68.96800","-0.00184","0.04333"
"69.16800","0.10515","0.10575"
"69.36800","0.27638","0.65033"
"69.56800","0.44673","4.54158"
"69.76200","0.61193","13.60420"
"69.91700","0.74385","23.65550"
"70.04400","0.85181","33.21230"
"70.04600","0.85350","33.37096"
"70.19300","0.79302","24.85636"
"70.31800","0.68437","14.73551"
"70.50100","0.52833","5.16856"
"70.70100","0.35810","0.80335"
"70.90100","0.18792","0.11234"
"71.10100","0.01775","0.04164"
"71.12300","-0.00110","0.04871"
"71.22400","0.01401","0.07803"
"71.42400","0.19111","0.20895"
"71.62400","0.36133","1.92087"
"71.82400","0.53143","8.54079"
"72.00000","0.68129","18.59593"
"72.14200","0.80259","28.67838"
"72.20100","0.85250","33.20522"
"72.30200","0.83662","29.83515"
"72.40600","0.74272","19.73637"
"72.55700","0.61371","9.67164"
"72.75700","0.44340","2.28330"
"72.95700","0.27314","0.23529"
"73.15700","0.10274","0.06616"
"73.27800","-0.00041","0.04734"
"73.28000","-0.00212","0.04661"
"73.48000","0.10482","0.10329"
"73.68000","0.27607","0.62686"
"73.88000","0.44641","4.45838"
"74.07500","0.61245","13.53398"
"74.23100","0.74522","23.65268"
"74.35700","0.85232","33.12027"
"74.35900","0.85401","33.27890"
"74.50600","0.79354","24.79338"
"74.63100","0.68485","14.67590"
"74.81400","0.52882","5.13543"
"75.01400","0.35858","0.78442"
"75.21400","0.18841","0.09964"
"75.41400","0.01828","0.04964"
"75.43700","-0.00146","0.04851"
"75.53800","0.01368","0.06866"
"75.73800","0.19075","0.19645"
"75.93800","0.36095","1.87635"
"76.13800","0.53105","8.43019"
"76.31500","0.68174","18.51606"
"76.45700","0.80306","28.59286"
"76.51600","0.85294","33.12912"
"76.61700","0.83709","29.75884"
"76.72100","0.74321","19.66894"
"76.87300","0.61333","9.56218"
"77.07300","0.44301","2.23611"
"77.27300","0.27274","0.23455"
"77.47300","0.10234","0.06304"
"77.59400","-0.00078","0.04587"
"77.59600","-0.00249","0.04556"
"77.79600","0.10440","0.10165"
"77.99600","0.27567","0.61832"
"78.19600","0.44604","4.38863"
"78.39100","0.61209","13.41095"
"78.54700","0.74487","23.50216"
"78.67300","0.85195","32.96432"
"78.67500","0.85364","33.12167"
"78.82200","0.79318","24.65080"
"78.94700","0.68448","14.55965"
"79.13100","0.52760","5.02505"
"79.33100","0.35738","0.75196"
"79.53100","0.18722","0.10418"
"79.73100","0.01705","0.04820"
"79.75200","-0.00096","0.05199"
"79.85300","0.01416","0.06289"
"80.05300","0.19127","0.19961"
"80.25300","0.36143","1.84211"
"80.45300","0.53153","8.38181"
"80.63000","0.68223","18.44943"
"80.77200","0.80352","28.51718"
"80.83000","0.85262","32.97734"
"80.93100","0.83668","29.60829"
"81.03500","0.74284","19.54608"
"81.18700","0.61295","9.47649"
"81.38700","0.44265","2.19473"
"81.58700","0.27238","0.22730"
"81.78700","0.10197","0.06465"
"81.90700","-0.00027","0.04629"
"81.90900","-0.00198","0.04686"
"82.10900","0.10488","0.10719"
"82.30900","0.27612","0.59919"
"82.50900","0.44650","4.34615"
"82.70400","0.61256","13.35567"
"82.86000","0.74539","23.45375"
"82.98500","0.85157","32.82367"
"82.98700","0.85326","32.98135"
"83.13400","0.79280","24.53023"
"83.25900","0.68412","14.45459"
"83.44300","0.52724","4.95545"
"83.64300","0.35700","0.73646"
"83.84300","0.18685","0.09609"
"84.04300","0.01671","0.05468"
"84.06400","-0.00130","0.05295"
"84.16500","0.01373","0.07494"
"84.36500","0.19087","0.19896"
"84.56500","0.36105","1.80494"
"84.76500","0.53114","8.28383"
"84.94200","0.68181","18.31901"
"85.08400","0.80316","28.38895"
"85.14300","0.85306","32.90372"
"85.24400","0.83698","29.52784"
"85.34800","0.74322","19.48796"
"85.50000","0.61333","9.43060"
"85.70000","0.44301","2.16619"
"85.90000","0.27275","0.22583"
"86.10000","0.10235","0.06549"
"86.22100","-0.00073","0.05131"
"86.22300","-0.00244","0.05200"
"86.42300","0.10432","0.10185"
"86.62300","0.27563","0.57818"
"86.82300","0.44599","4.28203"
"87.01800","0.61207","13.24300"
"87.17400","0.74492","23.30775"
"87.30000","0.85201","32.75743"
"87.30200","0.85371","32.91449"
"87.44900","0.79305","24.44752"
"87.57400","0.68441","14.38798"
"87.75800","0.52755","4.92797"
"87.95800","0.35731","0.72696"
"88.15800","0.18714","0.10551"
"88.35800","0.01696","0.04357"
"88.37900","-0.00103","0.04353"
"88.48000","0.01401","0.06721"
"88.68000","0.19119","0.19605"
"88.88000","0.36135","1.78225"
"89.08000","0.53146","8.23130"
"89.25800","0.68295","18.32001"
"89.40100","0.80517","28.45722"
"89.45700","0.85260","32.76173"
"89.55800","0.83658","29.39966"
"89.66200","0.74273","19.36290"
"89.81400","0.61284","9.33555"
"90.01400","0.44250","2.13355"
"90.21400","0.27227","0.21486"
"90.41400","0.10186","0.06559"
"90.53400","-0.00041","0.04371"
"90.53600","-0.00212","0.04344"
"90.73600","0.10471","0.10158"
"90.93600","0.27598","0.57409"
"91.13600","0.44637","4.23554"
"91.33200","0.61325","13.23298"
"91.48800","0.74607","23.30288"
"91.61200","0.85176","32.63048"
"91.61400","0.85344","32.78753"
"91.76100","0.79266","24.32108"
"91.88700","0.68319","14.23690"
"92.07200","0.52552","4.80061"
"92.27200","0.35523","0.68842"
"92.47200","0.18506","0.09422"
"92.67200","0.01487","0.04042"
"92.69100","-0.00142","0.04285"
"92.79200","0.01362","0.06768"
"92.99200","0.19081","0.18718"
"93.19200","0.36099","1.74792"
"93.39200","0.53109","8.15261"
"93.57000","0.68256","18.19922"
"93.71300","0.80481","28.32054"
"93.77000","0.85306","32.70565"
"93.87100","0.83703","29.33761"
"93.97500","0.74320","19.32042"
"94.12700","0.61331","9.30591"
"94.32700","0.44295","2.10730"
"94.52700","0.27272","0.20279"
"94.72700","0.10236","0.06786"
"94.84800","-0.00077","0.03554"
"94.85000","-0.00248","0.03640"
"95.05000","0.10435","0.09572"
"95.25000","0.27557","0.55699"
"95.45000","0.44597","4.17465"
"95.64600","0.61285","13.13596"
"95.80300","0.74643","23.23324"
"95.92700","0.85205","32.54672"
"95.92900","0.85374","32.70343"
"96.07700","0.79223","24.17319"
"96.20300","0.68277","14.11511"
"96.38800","0.52504","4.72757"
"96.58800","0.35480","0.67204"
"96.78800","0.18463","0.09835"
"96.98800","0.01444","0.04976"
"97.00600","-0.00099","0.04835"
"97.10700","-0.01685","0.05729"
"97.30700","0.05645","0.07542"
"97.50700","0.12466","0.10832"
"97.70700","0.19305","0.19843"
"97.90700","0.26090","0.45171"
"97.92600","0.26752","0.50263"
"97.93700","0.27131","0.53222"
"97.95700","0.27803","0.58923"
"97.97700","0.28464","0.65386"
"97.99700","0.28996","0.69005"
"98.01700","0.29332","0.72845"
"98.03700","0.29869","0.78817"
"98.05700","0.30691","0.88496"
"98.07700","0.31558","0.99319"
"98.09700","0.32346","1.10542"
"98.11700","0.33087","1.20981"
"98.13700","0.33819","1.33486"
"98.15700","0.34541","1.45701"
"98.17700","0.35244","1.58375"
"98.19700","0.35927","1.71383"
"98.21700","0.36607","1.84739"
"98.23700","0.37298","2.00716"
"98.25700","0.37990","2.16962"
"98.27700","0.38675","2.32626"
"98.29700","0.39347","2.50449"
"98.31700","0.40019","2.68717"
"98.33700","0.40704","2.88577"
"98.35700","0.41395","3.09057"
"98.37700","0.42083","3.29920"
"98.39700","0.42761","3.51102"
"98.41700","0.43438","3.73838"
"98.43700","0.44121","3.98868"
"98.45700","0.44803","4.24477"
"98.47700","0.45479","4.50543"
"98.49700","0.46151","4.76831"
"98.51700","0.46825","5.04139"
"98.53700","0.47514","5.32918"
"98.55700","0.48207","5.63030"
"98.57700","0.48888","5.93648"
"98.59700","0.49555","6.24713"
"98.61700","0.50220","6.56458"
"98.63700","0.50906","6.90222"
"98.65700","0.51609","7.26068"
"98.67700","0.52298","7.61667"
"98.69700","0.52967","7.97101"
"98.71700","0.53635","8.33663"
"98.73700","0.54322","8.71443"
"98.75700","0.55033","9.10800"
"98.77700","0.55737","9.50380"
"98.79700","0.56409","9.90166"
"98.81700","0.57062","10.29348"
"98.83700","0.57723","10.69711"
"98.85700","0.58411","11.12302"
"98.87700","0.59114","11.56350"
"98.89700","0.59807","11.98887"
"98.91700","0.60477","12.41536"
"98.93700","0.61136","12.84947"
"98.95700","0.61812","13.31101"
"98.97700","0.62506","13.78157"
"98.99700","0.63198","14.24600"
"99.01700","0.63877","14.70626"
"99.03700","0.64542","15.16585"
"99.05700","0.65210","15.65134"
"99.07700","0.65896","16.15451"
"99.09700","0.66587","16.65471"
"99.11700","0.67270","17.14268"
"99.13700","0.67943","17.63043"
"99.15700","0.68619","18.14707"
"99.17700","0.69304","18.67484"
"99.19700","0.69990","19.19954"
"99.21700","0.70671","19.71287"
"99.23700","0.71350","20.22395"
"99.25700","0.72039","20.75156"
"99.27700","0.72741","21.29983"
"99.29700","0.73436","21.85078"
"99.31700","0.74112","22.39131"
"99.33700","0.74774","22.92863"
"99.35700","0.75439","23.47073"
"99.37700","0.76132","24.04390"
"99.39700","0.76838","24.63559"
"99.41700","0.77523","25.20821"
"99.43700","0.78188","25.77065"
"99.45700","0.78849","26.32843"
"99.47700","0.79532","26.90700"
"99.49700","0.80234","27.50479"
"99.51700","0.80928","28.09465"
"99.53700","0.81595","28.67482"
"99.55700","0.82248","29.25147"
"99.57700","0.82913","29.84307"
"99.59700","0.83609","30.45661"
"99.61700","0.84312","31.07392"
"99.63700","0.84999","31.69075"
"99.65700","0.85665","32.28718"
"99.67700","0.86323","32.89364"
"99.69700","0.87002","33.52315"
"99.71700","0.87698","34.15829"
"99.73700","0.88388","34.78234"
"99.75700","0.89066","35.39339"
"99.77700","0.89732","36.00510"
"99.79700","0.90412","36.65386"
"99.81700","0.91113","37.31313"
"99.83700","0.91811","37.95124"
"99.85700","0.92498","38.55600"
"99.87700","0.93176","39.15022"
"99.89700","0.93857","39.75468"
"99.91700","0.94543","40.37653"
"99.93700","0.95222","40.98671"
"99.95700","0.95894","41.56252"
"99.97700","0.96565","42.13527"
"99.99700","0.97247","42.72044"
"100.01700","0.97942","43.33029"
"100.03700","0.98626","43.93203"
"100.05700","0.99294","44.50007"
"100.07700","0.99961","45.05909"
"100.09700","1.00641","45.62957"
"100.11700","1.01338","46.20634"
"100.13700","1.02032","46.79438"
"100.15700","1.02702","47.35096"
"100.17700","1.03358","47.89920"
"100.19700","1.04022","48.44712"
"100.21700","1.04713","49.01130"
"100.23700","1.05420","49.59228"
"100.25700","1.06112","50.15292"
"100.27700","1.06778","50.69540"
"100.29700","1.07436","51.23051"
"100.31700","1.08117","51.77652"
"100.33700","1.08821","52.34509"
"100.35700","1.09528","52.89914"
"100.37700","1.10216","53.42842"
"100.39700","1.10882","53.95213"
"100.41700","1.11550","54.48178"
"100.43700","1.12235","55.02141"
"100.45700","1.12929","55.55183"
"100.47700","1.13616","56.05373"
"100.49700","1.14290","56.54871"
"100.51700","1.14958","57.04898"
"100.53700","1.15636","57.57389"
"100.55700","1.16324","58.09669"
"100.57700","1.17010","58.60410"
"100.59700","1.17688","59.08474"
"100.61700","1.18364","59.56303"
"100.63700","1.19042","60.06010"
"100.65700","1.19720","60.56311"
"100.67700","1.20392","61.04876"
"100.69700","1.21064","61.52888"
"100.71700","1.21746","62.00216"
"100.73700","1.22446","62.49714"
"100.75700","1.23143","63.00001"
"100.77700","1.23822","63.47973"
"100.79700","1.24492","63.94268"
"100.81700","1.25160","64.38604"
"100.83700","1.25843","64.83946"
"100.85700","1.26546","65.31477"
"100.87700","1.27242","65.79144"
"100.89700","1.27912","66.23444"
"100.91700","1.28573","66.65348"
"100.93700","1.29252","67.09674"
"100.95700","1.29958","67.55882"
"100.97700","1.30666","68.00013"
"100.99700","1.31348","68.41014"
"101.01700","1.32003","68.78535"
"101.03700","1.32660","69.12433"
"101.05700","1.33344","69.36023"
"101.07700","1.34046","69.42499"
"101.09700","1.34741","69.42870"
"101.11700","1.35415","69.49896"
"101.13700","1.36074","69.66874"
"101.15700","1.36748","69.94579"
"101.17700","1.37439","70.29134"
"101.19700","1.38130","70.64603"
"101.21700","1.38808","70.99390"
"101.23700","1.39478","71.35651"
"101.25700","1.40150","71.74910"
"101.27700","1.40833","72.17657"
"101.29700","1.41523","72.59043"
"101.31700","1.42206","72.98314"
"101.33700","1.42878","73.35572"
"101.35700","1.43554","73.74139"
"101.37700","1.44244","74.15791"
"101.39700","1.44933","74.57019"
"101.41700","1.45610","74.95495"
"101.43700","1.46282","75.32804"
"101.45700","1.46965","75.72022"
"101.47700","1.47670","76.15124"
"101.49700","1.48374","76.57146"
"101.51700","1.49052","76.94261"
"101.53700","1.49710","77.28779"
"101.55700","1.50372","77.63396"
"101.57700","1.51061","78.01820"
"101.59700","1.51767","78.42146"
"101.61700","1.52458","78.79480"
"101.63700","1.53124","79.11648"
"101.65700","1.53781","79.41425"
"101.67700","1.54456","79.72469"
"101.69700","1.55155","80.05452"
"101.71700","1.55855","80.36944"
"101.73700","1.56531","80.63943"
"101.75700","1.57188","80.88056"
"101.77700","1.57850","81.12953"
"101.79700","1.58535","81.39680"
"101.81700","1.59233","81.67400"
"101.83700","1.59922","81.93938"
"101.85700","1.60598","82.19694"
"101.87700","1.61262","82.46329"
"101.89700","1.61940","82.75356"
"101.91700","1.62635","83.07909"
"101.92800","1.63017","83.25718"
"102.02900","1.62815","80.51360"
"102.18500","1.57131","70.45023"
"102.38100","1.50414","60.68486"
"102.58100","1.43616","52.15621"
"102.78100","1.36815","44.61663"
"102.98100","1.29986","37.82828"
"103.18100","1.23201","31.66558"
"103.38100","1.16364","26.10902"
"103.58100","1.09534","21.04841"
"103.78100","1.02772","16.54438"
"103.98100","0.95902","12.49137"
"104.18100","0.89084","8.97076"
"104.38100","0.82308","6.07343"
"104.58100","0.75466","3.76368"
"104.78100","0.68692","2.08523"
"104.98100","0.61878","1.00755"
"105.18100","0.55053","0.42164"
"105.38100","0.48266","0.20859"
"105.58100","0.41426","0.11768"
"105.78100","0.34601","0.08194"
"105.98100","0.27817","0.07107"
"106.01400","0.26702","0.06147"
"106.11500","0.26747","0.08073"
"106.31500","0.34008","0.12415"
"106.51500","0.40861","0.20837"
"106.70500","0.47320","0.50173"
"106.70700","0.47390","0.50730"
"106.70900","0.47459","0.51287"
"106.71100","0.47530","0.52117"
"106.71300","0.47603","0.53822"
"106.71500","0.47683","0.56585"
"106.71700","0.47778","0.60165"
"106.71900","0.47898","0.64539"
"106.72100","0.48054","0.69977"
"106.72300","0.48259","0.76583"
"106.72500","0.48525","0.84348"
"106.72700","0.48866","0.93686"
"106.72900","0.49296","1.05074"
"106.73100","0.49830","1.19081"
"106.73300","0.50480","1.36465"
"106.73500","0.51261","1.58154"
"106.73700","0.52184","1.85113"
"106.73900","0.53263","2.18772"
"106.74100","0.54508","2.60718"
"106.74300","0.55930","3.12479"
"106.74500","0.57540","3.75968"
"106.74700","0.59345","4.53075"
"106.74900","0.61355","5.45462"
"106.75100","0.63576","6.54959"
"106.75300","0.66015","7.83475"
"106.75500","0.68678","9.32615"
"106.75700","0.71571","11.03866"
"106.75900","0.74696","12.98720"
"106.76100","0.78059","15.18697"
"106.76300","0.81662","17.65138"
"106.76500","0.85509","20.39613"
"106.76700","0.89600","23.43744"
"106.76900","0.93937","26.79169"
"106.77100","0.98522","30.47160"
"106.77300","1.03354","34.47839"
"106.77500","1.08428","38.80086"
"106.77700","1.13735","43.42142"
"106.77900","1.19261","48.31079"
"106.78100","1.24988","53.42913"
"106.78300","1.30894","58.73598"
"106.78500","1.36957","64.18958"
"106.78700","1.43157","69.74196"
"106.78900","1.49472","75.34051"
"106.79100","1.55883","80.93248"
"106.79300","1.62374","86.46851"
"106.79500","1.68930","91.90443"
"106.79700","1.75539","97.20088"
"106.79900","1.82190","102.32392"
"106.80100","1.88877","107.24541"
"106.80300","1.95593","111.94503"
"106.80500","2.02334","116.41119"
"106.80700","2.09096","120.63718"
"106.80900","2.15876","124.62353"
"106.81100","2.22673","128.37277"
"106.81300","2.29487","131.88737"
"106.81500","2.36315","135.16898"
"106.81700","2.43158","138.21982"
"106.81900","2.50014","141.04485"
"106.82100","2.56882","143.65060"
"106.82300","2.63762","146.04855"
"106.82500","2.70652","148.25533"
"106.82700","2.77551","150.28981"
"106.82900","2.84458","152.17134"
"106.83100","2.91371","153.91951"
"106.83300","2.98290","155.55299"
"106.83500","3.05213","157.08835"
"106.83700","3.12139","158.53963"
"106.83900","3.19065","159.91559"
"106.84100","3.25992","161.22029"
"106.84300","3.32918","162.44339"
"106.84500","3.39841","163.56056"
"106.84700","3.46761","164.55898"
"106.84900","3.53677","165.43924"
"106.85100","3.60588","166.18773"
"106.85300","3.67494","166.75951"
"106.85500","3.74395","167.09956"
"106.85700","3.81291","167.14278"
"106.85900","3.88181","166.71432"
"106.86100","3.95065","165.38390"
"106.86300","4.01944","162.84187"
"106.86500","4.08819","159.17284"
"106.86700","4.15688","154.61060"
"106.86900","4.22554","149.38155"
"106.87100","4.29415","143.67482"
"106.87300","4.36273","137.64769"
"106.87500","4.43127","131.43216"
"106.87700","4.49979","125.13802"
"106.87900","4.56828","118.85339"
"106.88100","4.63675","112.65305"
"106.88300","4.70519","106.60226"
"106.88500","4.77362","100.75411"
"106.88700","4.84203","95.14983"
"106.88900","4.91042","89.81743"
"106.89100","4.97879","84.77611"
"106.89300","5.04713","80.03916"
"106.89500","5.11547","75.61316"
"106.89700","5.18378","71.49998"
"106.89900","5.25208","67.69986"
"106.90100","5.32037","64.21108"
"106.90300","5.38864","61.02680"
"106.90500","5.45690","58.13624"
"106.90700","5.52515","55.52632"
"106.90900","5.59339","53.17902"
"106.91100","5.66161","51.07477"
"106.91300","5.72983","49.19589"
"106.91500","5.79804","47.52478"
"106.91700","5.86623","46.04243"
"106.91900","5.93442","44.73118"
"106.92100","6.00261","43.57446"
"106.92300","6.07079","42.55382"
"106.92500","6.13896","41.65118"
"106.92700","6.20713","40.84956"
"106.92900","6.27529","40.13303"
"106.93100","6.34344","39.48663"
"106.93300","6.41159","38.89533"
"106.93500","6.47973","38.34595"
"106.93700","6.54786","37.83096"
"106.93900","6.61599","37.34420"
"106.94100","6.68411","36.88067"
"106.94300","6.75224","36.43692"
"106.94500","6.82037","36.01163"
"106.94700","6.88850","35.60108"
"106.94900","6.95664","35.20196"
"106.95100","7.02478","34.81205"
"106.95300","7.09293","34.42767"
"106.95500","7.16107","34.04467"
"106.95700","7.22922","33.66251"
"106.95900","7.29737","33.28184"
"106.96100","7.36552","32.90031"
"106.96300","7.43367","32.51407"
"106.96500","7.50183","32.12237"
"106.96700","7.56998","31.72393"
"106.96900","7.63814","31.31600"
"106.97100","7.70629","30.89610"
"106.97300","7.77445","30.46372"
"106.97500","7.84259","30.01723"
"106.97700","7.91074","29.55357"
"106.97900","7.97888","29.07312"
"106.98100","8.04701","28.58074"
"106.98300","8.11514","28.07927"
"106.98500","8.18327","27.56804"
"106.98700","8.25140","27.04739"
"106.98900","8.31952","26.51922"
"106.99100","8.38765","25.98629"
"106.99300","8.45578","25.44921"
"106.99500","8.52391","24.90734"
"106.99700","8.59204","24.36049"
"106.99900","8.66017","23.80918"
"107.00100","8.72829","23.25233"
"107.00300","8.79642","22.68918"
"107.00500","8.86455","22.11981"
"107.00700","8.93268","21.54082"
"107.00900","9.00080","20.95100"
"107.01100","9.06893","20.35301"
"107.01300","9.13707","19.74764"
"107.01500","9.20520","19.13475"
"107.01700","9.27335","18.51787"
"107.01900","9.34149","17.90145"
"107.02100","9.40964","17.28863"
"107.02300","9.47779","16.68106"
"107.02500","9.54594","16.08048"
"107.02700","9.61410","15.48802"
"107.02900","9.68226","14.90578"
"107.03100","9.75042","14.33364"
"107.03300","9.81859","13.77298"
"107.03500","9.88676","13.22522"
"107.03700","9.95493","12.69043"
"107.03900","10.02310","12.16787"
"107.04100","10.09127","11.65985"
"107.04300","10.15945","11.16984"
"107.04500","10.22761","10.69802"
"107.04700","10.29578","10.24366"
"107.04900","10.36394","9.80944"
"107.05100","10.43210","9.39612"
"107.05300","10.50025","9.00090"
"107.05500","10.56841","8.62295"
"107.05700","10.63656","8.26419"
"107.05900","10.70471","7.92474"
"107.06100","10.77285","7.60233"
"107.06300","10.84099","7.29458"
"107.06500","10.90913","7.00128"
"107.06700","10.97726","6.72219"
"107.06900","11.04539","6.45614"
"107.07100","11.11351","6.20019"
"107.07300","11.18163","5.95416"
"107.07500","11.24975","5.71971"
"107.07700","11.31786","5.49713"
"107.07900","11.38596","5.28443"
"107.08100","11.45407","5.07982"
"107.08300","11.52217","4.88136"
"107.08500","11.59026","4.68843"
"107.08700","11.65835","4.50347"
"107.08900","11.72645","4.32793"
"107.09100","11.79454","4.15886"
"107.09300","11.86263","3.99554"
"107.09500","11.93072","3.83918"
"107.09700","11.99881","3.68791"
"107.09900","12.06691","3.53956"
"107.10100","12.13501","3.39368"
"107.10300","12.20312","3.25225"
"107.10500","12.27122","3.11484"
"107.10700","12.33933","2.97995"
"107.10900","12.40745","2.84723"
"107.11100","12.47556","2.71784"
"107.11300","12.54367","2.59178"
"107.11500","12.61179","2.46768"
"107.11700","12.67990","2.34658"
"107.11900","12.74802","2.22976"
"107.12100","12.81613","2.11691"
"107.12300","12.88425","2.00693"
"107.12500","12.95236","1.89961"
"107.12700","13.02048","1.79549"
"107.12900","13.08860","1.69431"
"107.13100","13.15671","1.59614"
"107.13300","13.22483","1.50081"
"107.13500","13.29294","1.40832"
"107.13700","13.36106","1.31983"
"107.13900","13.42917","1.23723"
"107.14100","13.49729","1.16053"
"107.14300","13.56542","1.08820"
"107.14500","13.63354","1.01986"
"107.14700","13.70167","0.95596"
"107.14900","13.76980","0.89716"
"107.15100","13.83792","0.84366"
"107.15300","13.90605","0.79638"
"107.15500","13.97417","0.75335"
"107.15700","14.04230","0.71204"
"107.15900","14.11041","0.67202"
"107.16100","14.17853","0.63591"
"107.16300","14.24665","0.60250"
"107.16500","14.31476","0.56952"
"107.16700","14.38288","0.53717"
"107.16900","14.45100","0.50799"
"107.17100","14.51913","0.48310"
"107.17300","14.58725","0.46034"
"107.17500","14.65538","0.43868"
"107.17700","14.72350","0.42006"
"107.17900","14.79163","0.40373"
"107.18100","14.85975","0.38799"
"107.18300","14.92788","0.37193"
"107.18500","14.99600","0.35770"
"107.18700","15.06413","0.34489"
"107.18900","15.13226","0.33097"
"107.19100","15.20039","0.31707"
"107.19300","15.26852","0.30459"
"107.19500","15.33665","0.29105"
"107.19700","15.40477","0.27619"
"107.19900","15.47289","0.26323"
"107.20100","15.54101","0.25227"
"107.20300","15.60913","0.24047"
"107.20500","15.67724","0.22806"
"107.20700","15.74536","0.21667"
"107.20900","15.81347","0.20586"
"107.21100","15.88158","0.19538"
"107.21300","15.94970","0.18566"
"107.21500","16.01781","0.17743"
"107.21700","16.08592","0.17117"
"107.21900","16.15404","0.16606"
"107.22100","16.22215","0.16183"
"107.22300","16.29025","0.15869"
"107.22500","16.35836","0.15655"
"107.22700","16.42647","0.15475"
"107.22900","16.49457","0.15418"
"107.23100","16.56267","0.15226"
"107.23300","16.63077","0.14657"
"107.23500","16.69887","0.14105"
"107.23700","16.76697","0.13905"
"107.23900","16.83506","0.13707"
"107.24100","16.90316","0.13234"
"107.24300","16.97126","0.12788"
"107.24500","17.03936","0.12750"
"107.24700","17.10747","0.12915"
"107.24900","17.17558","0.13014"
"107.25100","17.24369","0.12989"
"107.25300","17.31180","0.12912"
"107.25500","17.37992","0.12901"
"107.25700","17.44805","0.12954"
"107.25900","17.51618","0.13035"