File: data/instron/Sample24_Static.is_tcyclic_RawData/Specimen_RawData_1.csv
Strain : Tensile strain (Extension) gauge length,100,mm,,,,
,,,,,,
Time,Extension,Load,,,,
(s),(mm),(N),Low Start,Low End,High Start,High End
0,0,0.18186,856,1164,1314,1404
0.2,0.05425,0.30318,,,,
0.4,0.12882,0.5045,,,,
0.6,0.20274,0.78762,,,,
0.8,0.27606,1.22018,,,,
1,0.34951,1.83097,,,,
1.2,0.42346,2.70414,,,,
1.4,0.49688,3.85544,,,,
1.6,0.57043,5.34776,,,,
1.8,0.64387,7.1889,,,,
2,0.7173,9.45035,,,,
2.2,0.7911,12.12565,,,,
2.4,0.86429,15.2191,,,,
2.6,0.93796,18.74465,,,,
2.8,1.01155,22.67597,,,,
3,1.08502,26.99811,,,,
3.2,1.15873,31.75834,,,,
3.4,1.23204,36.8098,,,,
3.55,1.2875,40.81127,,,,
3.552,1.28824,40.86437,,,,
3.752,1.29819,39.55972,,,,
3.952,1.29612,38.29017,,,,
4.152,1.29581,37.5416,,,,
4.352,1.29572,36.98078,,,,
4.552,1.29572,36.54723,,,,
4.752,1.29571,36.15725,,,,
4.952,1.29562,35.84451,,,,
5.152,1.29568,35.57001,,,,
5.352,1.2957,35.32294,,,,
5.552,1.29572,35.08762,,,,
5.752,1.29572,34.88716,,,,
5.952,1.29572,34.69232,,,,
6.152,1.29572,34.52299,,,,
6.352,1.29572,34.35041,,,,
6.552,1.29572,34.19178,,,,
6.752,1.29572,34.0529,,,,
6.952,1.29572,33.92241,,,,
7.152,1.29572,33.79144,,,,
7.352,1.29572,33.6722,,,,
7.552,1.29572,33.55006,,,,
7.752,1.29572,33.4344,,,,
7.952,1.29572,33.33086,,,,
8.152,1.29572,33.23029,,,,
8.352,1.29572,33.12946,,,,
8.552,1.29572,33.02124,,,,
8.752,1.29572,32.93686,,,,
8.952,1.29572,32.85186,,,,
9.152,1.29572,32.77258,,,,
9.352,1.29572,32.69524,,,,
9.552,1.29572,32.60621,,,,
9.752,1.29572,32.52947,,,,
9.952,1.29572,32.4603,,,,
10.152,1.29572,32.38097,,,,
10.352,1.29572,32.31436,,,,
10.552,1.29572,32.24593,,,,
10.752,1.29572,32.18492,,,,
10.952,1.29572,32.11576,,,,
11.152,1.29572,32.0545,,,,
11.352,1.29572,31.99474,,,,
11.552,1.29572,31.92932,,,,
11.752,1.29572,31.88042,,,,
11.952,1.29572,31.81596,,,,
12.152,1.29572,31.75389,,,,
12.352,1.29572,31.70198,,,,
12.552,1.29572,31.651,,,,
12.752,1.29572,31.59852,,,,
12.952,1.29572,31.54739,,,,
13.152,1.29572,31.4897,,,,
13.352,1.29572,31.44142,,,,
13.552,1.29572,31.39312,,,,
13.752,1.29572,31.34829,,,,
13.952,1.29572,31.30129,,,,
14.152,1.29572,31.26604,,,,
14.352,1.29572,31.21569,,,,
14.552,1.29572,31.16868,,,,
14.752,1.29572,31.12233,,,,
14.952,1.29572,31.07949,,,,
15.152,1.29572,31.04449,,,,
15.352,1.29572,30.99658,,,,
15.552,1.29572,30.95774,,,,
15.752,1.29572,30.91603,,,,
15.952,1.29572,30.87781,,,,
16.152,1.29572,30.83812,,,,
16.352,1.29572,30.80334,,,,
16.552,1.29572,30.76653,,,,
16.752,1.29572,30.72612,,,,
16.952,1.29572,30.69871,,,,
17.152,1.29572,30.66089,,,,
17.352,1.29572,30.61356,,,,
17.552,1.29567,30.58699,,,,
17.752,1.29569,30.55818,,,,
17.952,1.29572,30.52295,,,,
18.152,1.29572,30.47965,,,,
18.352,1.29572,30.45426,,,,
18.552,1.29572,30.41843,,,,
18.752,1.29572,30.38821,,,,
18.952,1.29572,30.35691,,,,
19.152,1.29572,30.31625,,,,
19.352,1.29572,30.29065,,,,
19.552,1.29572,30.26545,,,,
19.752,1.29572,30.23314,,,,
19.952,1.29572,30.20204,,,,
20.152,1.29572,30.16916,,,,
20.352,1.29572,30.14292,,,,
20.552,1.29572,30.11836,,,,
20.752,1.29572,30.09033,,,,
20.952,1.29572,30.05558,,,,
21.152,1.29572,30.02876,,,,
21.352,1.29572,30.00314,,,,
21.552,1.29572,29.97333,,,,
21.752,1.29572,29.95494,,,,
21.952,1.29572,29.92357,,,,
22.152,1.29572,29.90098,,,,
22.352,1.29572,29.87392,,,,
22.552,1.29572,29.84482,,,,
22.752,1.29572,29.82125,,,,
22.952,1.29572,29.79925,,,,
23.152,1.29572,29.76708,,,,
23.352,1.29572,29.7421,,,,
23.551,1.29572,29.72635,,,,
23.581,1.29572,29.71637,,,,
23.781,1.23789,22.93976,,,,
23.981,1.16397,16.21288,,,,
24.181,1.09035,11.29503,,,,
24.381,1.01681,7.62267,,,,
24.581,0.94304,4.93466,,,,
24.781,0.86944,3.06153,,,,
24.981,0.79591,1.81584,,,,
25.181,0.72226,1.04144,,,,
25.381,0.64878,0.59283,,,,
25.581,0.57516,0.33691,,,,
25.781,0.50192,0.19524,,,,
25.981,0.42825,0.10979,,,,
26.181,0.35443,0.07157,,,,
26.381,0.2811,0.05473,,,,
26.581,0.20757,0.03944,,,,
26.781,0.13414,0.01881,,,,
26.981,0.06038,0.01464,,,,
27.122,0.00841,0.01643,,,,
27.124,0.00767,0.01595,,,,
27.324,0.05082,0.02728,,,,
27.524,0.12517,0.04601,,,,
27.724,0.199,0.08207,,,,
27.924,0.27241,0.10797,,,,
28.124,0.34591,0.16045,,,,
28.324,0.41985,0.2669,,,,
28.524,0.49324,0.45838,,,,
28.724,0.56681,0.79311,,,,
28.924,0.64036,1.35,,,,
29.124,0.71384,2.26399,,,,
29.324,0.7876,3.68931,,,,
29.524,0.86082,5.74799,,,,
29.724,0.93447,8.55486,,,,
29.924,1.00809,12.1702,,,,
30.124,1.08154,16.59911,,,,
30.324,1.15514,21.85747,,,,
30.524,1.22846,27.83028,,,,
30.707,1.29591,33.88762,,,,
30.709,1.29663,33.95548,,,,
30.909,1.30685,33.81436,,,,
31.109,1.30468,33.06802,,,,
31.309,1.30434,32.68272,,,,
31.509,1.30425,32.40366,,,,
31.709,1.30425,32.18712,,,,
31.909,1.30425,31.99511,,,,
32.109,1.30416,31.8503,,,,
32.309,1.30422,31.70909,,,,
32.509,1.30425,31.58651,,,,
32.709,1.30425,31.48508,,,,
32.909,1.30425,31.37678,,,,
33.109,1.30425,31.29533,,,,
33.309,1.30425,31.20134,,,,
33.509,1.30425,31.11827,,,,
33.709,1.30425,31.04723,,,,
33.909,1.30425,30.97105,,,,
34.109,1.30425,30.90278,,,,
34.309,1.30425,30.84511,,,,
34.509,1.30425,30.79156,,,,
34.709,1.30425,30.7244,,,,
34.909,1.30425,30.67079,,,,
35.109,1.30425,30.61141,,,,
35.309,1.30425,30.56404,,,,
35.509,1.30425,30.51637,,,,
35.709,1.30425,30.46643,,,,
35.909,1.30425,30.42474,,,,
36.109,1.30425,30.38187,,,,
36.309,1.30425,30.33426,,,,
36.509,1.30425,30.2912,,,,
36.709,1.30425,30.25763,,,,
36.909,1.30425,30.2146,,,,
37.109,1.30425,30.17482,,,,
37.309,1.30425,30.14392,,,,
37.509,1.30425,30.10557,,,,
37.709,1.30425,30.06849,,,,
37.909,1.30425,30.03814,,,,
38.109,1.30425,29.99636,,,,
38.309,1.30425,29.96536,,,,
38.509,1.30425,29.93165,,,,
38.709,1.30425,29.90202,,,,
38.909,1.30425,29.87135,,,,
39.109,1.30425,29.84106,,,,
39.309,1.30425,29.81653,,,,
39.509,1.30425,29.77621,,,,
39.709,1.30425,29.74454,,,,
39.909,1.30425,29.72377,,,,
40.109,1.30425,29.70077,,,,
40.309,1.30425,29.66717,,,,
40.509,1.30425,29.63457,,,,
40.709,1.30425,29.60968,,,,
40.909,1.30425,29.58411,,,,
41.109,1.30425,29.56265,,,,
41.309,1.30425,29.53548,,,,
41.509,1.30425,29.50979,,,,
41.709,1.30425,29.48536,,,,
41.909,1.30425,29.46405,,,,
42.109,1.30425,29.43567,,,,
42.309,1.30425,29.40629,,,,
42.509,1.30425,29.38967,,,,
42.709,1.30425,29.35966,,,,
42.909,1.30425,29.33738,,,,
43.109,1.30425,29.32224,,,,
43.309,1.30425,29.29179,,,,
43.509,1.30425,29.2687,,,,
43.709,1.30425,29.25117,,,,
43.909,1.30425,29.23238,,,,
44.109,1.30425,29.20564,,,,
44.309,1.30425,29.18106,,,,
44.509,1.30425,29.1722,,,,
44.709,1.30425,29.15413,,,,
44.909,1.30425,29.12998,,,,
45.109,1.30425,29.09831,,,,
45.309,1.30422,29.08518,,,,
45.509,1.30424,29.06828,,,,
45.709,1.30425,29.05062,,,,
45.909,1.30425,29.02658,,,,
46.109,1.30425,29.0094,,,,
46.309,1.30425,28.99182,,,,
46.509,1.30425,28.97507,,,,
46.709,1.30425,28.95765,,,,
46.909,1.30425,28.93599,,,,
47.109,1.30425,28.91967,,,,
47.309,1.30425,28.89773,,,,
47.509,1.30425,28.88142,,,,
47.709,1.30425,28.86615,,,,
47.909,1.30425,28.84487,,,,
48.109,1.30425,28.83362,,,,
48.309,1.30425,28.81822,,,,
48.509,1.30425,28.79952,,,,
48.709,1.30425,28.77775,,,,
48.909,1.30425,28.76831,,,,
49.109,1.30425,28.74722,,,,
49.309,1.30425,28.72435,,,,
49.509,1.30425,28.71344,,,,
49.709,1.30425,28.6919,,,,
49.909,1.30425,28.68522,,,,
50.109,1.30425,28.67238,,,,
50.309,1.30425,28.65626,,,,
50.509,1.30425,28.63729,,,,
50.708,1.30425,28.61687,,,,
50.73,1.30425,28.62223,,,,
50.93,1.2465,21.79798,,,,
51.13,1.17254,15.11962,,,,
51.33,1.09879,10.27975,,,,
51.53,1.02531,6.74585,,,,
51.73,0.95164,4.21877,,,,
51.93,0.87823,2.50439,,,,
52.13,0.80454,1.41951,,,,
52.33,0.73068,0.79004,,,,
52.53,0.65741,0.43034,,,,
52.73,0.58385,0.23446,,,,
52.93,0.51045,0.13973,,,,
53.13,0.43668,0.08157,,,,
53.33,0.36276,0.05575,,,,
53.53,0.28965,0.04329,,,,
53.73,0.21605,0.03934,,,,
53.93,0.14244,0.02516,,,,
54.13,0.06886,0.02607,,,,
54.271,0.01692,0.01267,,,,
54.273,0.01618,0.01267,,,,
54.473,0.05899,0.03046,,,,
54.673,0.13349,0.03645,,,,
54.873,0.2075,0.05166,,,,
55.073,0.2808,0.08596,,,,
55.273,0.35419,0.12875,,,,
55.473,0.42805,0.19016,,,,
55.673,0.5015,0.32514,,,,
55.873,0.57512,0.57241,,,,
56.073,0.6484,1.00851,,,,
56.273,0.72182,1.74228,,,,
56.473,0.79564,2.94703,,,,
56.673,0.86888,4.78685,,,,
56.873,0.94262,7.41307,,,,
57.073,1.01613,10.85502,,,,
57.273,1.08967,15.16809,,,,
57.473,1.16347,20.38745,,,,
57.673,1.23682,26.39428,,,,
57.857,1.3044,32.59824,,,,
57.859,1.30515,32.67132,,,,
58.059,1.31544,32.64568,,,,
58.259,1.31325,31.96131,,,,
58.459,1.31292,31.62024,,,,
58.659,1.31288,31.37243,,,,
58.859,1.31288,31.17615,,,,
59.059,1.31278,31.02288,,,,
59.259,1.31283,30.88452,,,,
59.459,1.31284,30.76873,,,,
59.659,1.31285,30.6655,,,,
59.859,1.31287,30.56551,,,,
60.059,1.31288,30.48389,,,,
60.259,1.31288,30.40403,,,,
60.459,1.31288,30.33264,,,,
60.659,1.31288,30.26225,,,,
60.859,1.31288,30.19221,,,,
61.059,1.31288,30.14134,,,,
61.259,1.31288,30.08929,,,,
61.459,1.31288,30.03512,,,,
61.659,1.31288,29.98484,,,,
61.859,1.31288,29.93564,,,,
62.059,1.31288,29.8893,,,,
62.259,1.31288,29.84868,,,,
62.459,1.31288,29.80355,,,,
62.659,1.31288,29.76478,,,,
62.859,1.31288,29.7256,,,,
63.059,1.31288,29.68159,,,,
63.259,1.31288,29.65576,,,,
63.459,1.31288,29.61062,,,,
63.659,1.31288,29.57879,,,,
63.859,1.31288,29.54994,,,,
64.059,1.31288,29.51557,,,,
64.259,1.31288,29.47969,,,,
64.459,1.31288,29.45411,,,,
64.659,1.31288,29.42491,,,,
64.859,1.31288,29.39293,,,,
65.059,1.31288,29.36827,,,,
65.259,1.31288,29.33651,,,,
65.459,1.31288,29.31329,,,,
65.659,1.31288,29.28463,,,,
65.859,1.31288,29.26639,,,,
66.059,1.31288,29.23042,,,,
66.259,1.31288,29.21808,,,,
66.459,1.31288,29.18936,,,,
66.659,1.31288,29.15791,,,,
66.859,1.31288,29.13715,,,,
67.059,1.31288,29.11671,,,,
67.259,1.31288,29.09061,,,,
67.459,1.31288,29.06613,,,,
67.659,1.31288,29.04631,,,,
67.859,1.31288,29.02247,,,,
68.059,1.31288,29.0046,,,,
68.259,1.31288,28.99159,,,,
68.459,1.31288,28.96956,,,,
68.659,1.31288,28.94546,,,,
68.859,1.31288,28.93353,,,,
69.059,1.31288,28.90811,,,,
69.259,1.31288,28.89237,,,,
69.459,1.31288,28.86839,,,,
69.659,1.31288,28.85587,,,,
69.859,1.31288,28.83492,,,,
70.059,1.31288,28.81472,,,,
70.259,1.31288,28.8016,,,,
70.459,1.31288,28.77884,,,,
70.659,1.31288,28.75656,,,,
70.859,1.31288,28.74519,,,,
71.059,1.31288,28.72674,,,,
71.259,1.31288,28.70883,,,,
71.459,1.31288,28.6933,,,,
71.659,1.31288,28.68001,,,,
71.859,1.31288,28.66184,,,,
72.059,1.31288,28.64484,,,,
72.259,1.31288,28.62998,,,,
72.459,1.31288,28.61698,,,,
72.659,1.31288,28.59702,,,,
72.859,1.31288,28.58445,,,,
73.059,1.31288,28.56617,,,,
73.259,1.31288,28.54727,,,,
73.459,1.31288,28.5369,,,,
73.659,1.31288,28.52317,,,,
73.859,1.31288,28.51043,,,,
74.059,1.31288,28.48863,,,,
74.259,1.31288,28.47999,,,,
74.459,1.31288,28.46724,,,,
74.659,1.31288,28.45341,,,,
74.859,1.31288,28.43631,,,,
75.059,1.31288,28.41608,,,,
75.259,1.31288,28.41349,,,,
75.459,1.31288,28.39729,,,,
75.659,1.31288,28.38188,,,,
75.859,1.31288,28.36333,,,,
76.059,1.31288,28.34982,,,,
76.259,1.31288,28.33926,,,,
76.459,1.31288,28.3312,,,,
76.659,1.31288,28.31057,,,,
76.859,1.31288,28.29216,,,,
77.059,1.31288,28.27906,,,,
77.259,1.31288,28.27408,,,,
77.459,1.31288,28.24943,,,,
77.659,1.31288,28.2464,,,,
77.858,1.31288,28.23336,,,,
77.879,1.31288,28.23267,,,,
78.079,1.25501,21.32104,,,,
78.279,1.18097,14.65175,,,,
78.479,1.10698,9.82374,,,,
78.679,1.03372,6.35762,,,,
78.879,0.96017,3.88398,,,,
79.079,0.88672,2.25205,,,,
79.279,0.81304,1.2475,,,,
79.479,0.73921,0.67036,,,,
79.679,0.66613,0.36046,,,,
79.879,0.59247,0.18867,,,,
80.079,0.51893,0.11648,,,,
80.279,0.44523,0.06929,,,,
80.479,0.37149,0.05613,,,,
80.679,0.29825,0.04154,,,,
80.879,0.22447,0.01953,,,,
81.079,0.15069,0.01975,,,,
81.279,0.07741,0.01244,,,,
81.42,0.02541,0.00275,,,,
81.422,0.02468,0.00267,,,,
81.622,0.06742,0.01846,,,,
81.822,0.14182,0.03063,,,,
82.022,0.21582,0.0493,,,,
82.222,0.28917,0.07841,,,,
82.422,0.36249,0.09901,,,,
82.622,0.43618,0.16265,,,,
82.822,0.50963,0.27286,,,,
83.022,0.58345,0.48455,,,,
83.034,0.58785,0.50236,,,,
83.045,0.59189,0.51086,,,,
83.065,0.59737,0.53016,,,,
83.085,0.60133,0.54868,,,,
83.105,0.60447,0.56114,,,,
83.125,0.60861,0.59124,,,,
83.145,0.61607,0.63146,,,,
83.165,0.62535,0.67775,,,,
83.185,0.63449,0.72774,,,,
83.205,0.64279,0.77226,,,,
83.225,0.6505,0.8237,,,,
83.245,0.65806,0.87897,,,,
83.265,0.6657,0.92442,,,,
83.285,0.67323,0.97507,,,,
83.305,0.68054,1.03656,,,,
83.325,0.68777,1.09265,,,,
83.345,0.69517,1.15384,,,,
83.365,0.70273,1.22985,,,,
83.385,0.71021,1.30051,,,,
83.405,0.71744,1.37364,,,,
83.425,0.72459,1.45657,,,,
83.445,0.73197,1.54151,,,,
83.465,0.73956,1.62925,,,,
83.485,0.74715,1.72044,,,,
83.505,0.75452,1.82543,,,,
83.525,0.76174,1.92805,,,,
83.545,0.76907,2.03707,,,,
83.565,0.77654,2.15352,,,,
83.585,0.78397,2.26775,,,,
83.605,0.79126,2.38897,,,,
83.625,0.79844,2.5243,,,,
83.645,0.80575,2.66143,,,,
83.665,0.81321,2.81195,,,,
83.685,0.82067,2.96418,,,,
83.705,0.82805,3.11743,,,,
83.725,0.83536,3.28138,,,,
83.745,0.84271,3.45607,,,,
83.765,0.85004,3.63541,,,,
83.785,0.85727,3.81676,,,,
83.805,0.86443,4.00039,,,,
83.825,0.87175,4.19798,,,,
83.845,0.87923,4.41168,,,,
83.865,0.88669,4.62782,,,,
83.885,0.89399,4.86071,,,,
83.905,0.90122,5.09504,,,,
83.925,0.9086,5.33049,,,,
83.945,0.9162,5.58354,,,,
83.965,0.92368,5.84558,,,,
83.985,0.93092,6.10718,,,,
84.005,0.93813,6.37734,,,,
84.025,0.94555,6.65687,,,,
84.045,0.95318,6.95592,,,,
84.065,0.96064,7.26318,,,,
84.085,0.96783,7.56414,,,,
84.105,0.97493,7.87187,,,,
84.125,0.98223,8.19884,,,,
84.145,0.98976,8.54113,,,,
84.165,0.9973,8.89527,,,,
84.185,1.00459,9.23851,,,,
84.205,1.01172,9.59558,,,,
84.225,1.01902,9.97626,,,,
84.245,1.0265,10.362,,,,
84.265,1.03395,10.75391,,,,
84.285,1.04125,11.13842,,,,
84.305,1.04842,11.53078,,,,
84.325,1.05573,11.95613,,,,
84.345,1.06319,12.3991,,,,
84.365,1.07062,12.83878,,,,
84.385,1.07792,13.2626,,,,
84.405,1.08519,13.70592,,,,
84.425,1.09255,14.1732,,,,
84.445,1.09996,14.65687,,,,
84.465,1.1073,15.13744,,,,
84.485,1.11458,15.6175,,,,
84.505,1.122,16.1155,,,,
84.525,1.12958,16.63882,,,,
84.545,1.13709,17.17901,,,,
84.565,1.1444,17.71155,,,,
84.585,1.15155,18.22798,,,,
84.605,1.15887,18.75857,,,,
84.625,1.16642,19.32402,,,,
84.645,1.17389,19.89658,,,,
84.665,1.1811,20.46049,,,,
84.685,1.18822,21.01996,,,,
84.705,1.19556,21.60255,,,,
84.725,1.20313,22.20814,,,,
84.745,1.21059,22.82604,,,,
84.765,1.21779,23.42405,,,,
84.785,1.22489,24.0255,,,,
84.805,1.2322,24.65025,,,,
84.825,1.23976,25.30149,,,,
84.845,1.24727,25.94736,,,,
84.865,1.25458,26.59175,,,,
84.885,1.26171,27.23779,,,,
84.905,1.26897,27.90954,,,,
84.925,1.27647,28.61118,,,,
84.945,1.28397,29.3081,,,,
84.965,1.2913,29.99103,,,,
84.985,1.29849,30.67661,,,,
85.005,1.30581,31.39203,,,,
85.025,1.31335,32.13363,,,,
85.045,1.32085,32.868,,,,
85.065,1.32821,33.58127,,,,
85.085,1.33553,34.30366,,,,
85.105,1.34292,35.05474,,,,
85.125,1.35032,35.80178,,,,
85.145,1.35763,36.53682,,,,
85.165,1.36488,37.27023,,,,
85.185,1.37223,38.00529,,,,
85.205,1.37971,38.76549,,,,
85.225,1.38709,39.53546,,,,
85.245,1.3943,40.28101,,,,
85.265,1.40147,41.01669,,,,
85.285,1.4088,41.77356,,,,
85.305,1.41633,42.5633,,,,
85.325,1.42378,43.34071,,,,
85.345,1.43102,44.09813,,,,
85.365,1.43822,44.84776,,,,
85.385,1.44558,45.60616,,,,
85.405,1.4531,46.3687,,,,
85.425,1.46055,47.12825,,,,
85.445,1.46776,47.87536,,,,
85.465,1.47489,48.61771,,,,
85.485,1.48227,49.38305,,,,
85.505,1.48987,50.16666,,,,
85.525,1.49744,50.93946,,,,
85.545,1.50481,51.70107,,,,
85.565,1.51203,52.44864,,,,
85.585,1.51938,53.20657,,,,
85.605,1.52686,53.96803,,,,
85.625,1.53427,54.70776,,,,
85.645,1.54155,55.43193,,,,
85.665,1.54872,56.14907,,,,
85.685,1.55606,56.90898,,,,
85.705,1.56354,57.67874,,,,
85.725,1.57098,58.42601,,,,
85.745,1.5783,59.13792,,,,
85.765,1.58558,59.85595,,,,
85.785,1.59293,60.60014,,,,
85.805,1.6003,61.34429,,,,
85.825,1.60759,62.05735,,,,
85.845,1.61483,62.74632,,,,
85.865,1.62217,63.44939,,,,
85.885,1.62964,64.18556,,,,
85.905,1.63705,64.91914,,,,
85.925,1.64432,65.63039,,,,
85.945,1.65153,66.31599,,,,
85.965,1.65891,67.01569,,,,
85.985,1.66651,67.7467,,,,
86.005,1.674,68.46992,,,,
86.025,1.68124,69.16338,,,,
86.045,1.68845,69.84296,,,,
86.065,1.69587,70.54694,,,,
86.085,1.70346,71.26562,,,,
86.105,1.71091,71.96458,,,,
86.125,1.71809,72.63384,,,,
86.145,1.7252,73.29684,,,,
86.165,1.73258,73.99632,,,,
86.185,1.74018,74.71005,,,,
86.205,1.74769,75.39709,,,,
86.225,1.75495,76.0497,,,,
86.245,1.76204,76.69941,,,,
86.265,1.76933,77.38615,,,,
86.285,1.77682,78.08893,,,,
86.305,1.78426,78.76247,,,,
86.325,1.79154,79.40857,,,,
86.345,1.79871,80.0444,,,,
86.365,1.80601,80.72656,,,,
86.385,1.81345,81.41682,,,,
86.405,1.82088,82.08852,,,,
86.425,1.82819,82.72312,,,,
86.445,1.83548,83.36234,,,,
86.465,1.84288,84.04295,,,,
86.485,1.85026,84.71926,,,,
86.505,1.85756,85.3727,,,,
86.525,1.86486,86.00998,,,,
86.545,1.87232,86.67136,,,,
86.565,1.87995,87.36941,,,,
86.585,1.88744,88.0554,,,,
86.605,1.89471,88.69918,,,,
86.625,1.90188,89.30834,,,,
86.645,1.9092,89.9326,,,,
86.665,1.91674,90.6014,,,,
86.685,1.92418,91.27331,,,,
86.705,1.93139,91.89738,,,,
86.725,1.93853,92.50657,,,,
86.745,1.94587,93.14207,,,,
86.765,1.95342,93.80433,,,,
86.785,1.9609,94.46001,,,,
86.805,1.96812,95.06856,,,,
86.825,1.97521,95.65549,,,,
86.845,1.98252,96.27214,,,,
86.865,1.99005,96.92805,,,,
86.885,1.9975,97.56323,,,,
86.905,2.0048,98.16532,,,,
86.925,2.01201,98.76318,,,,
86.945,2.01934,99.38319,,,,
86.965,2.02683,100.01671,,,,
86.985,2.03425,100.63518,,,,
87.005,2.0415,101.22714,,,,
87.025,2.04873,101.82307,,,,
87.045,2.05617,102.45702,,,,
87.053,2.05921,102.71619,,,,
87.154,2.05653,99.95439,,,,
87.273,2.00918,89.89381,,,,
87.42,1.95496,79.85976,,,,
87.582,1.89483,69.81489,,,,
87.762,1.82868,59.77358,,,,
87.959,1.75632,49.79651,,,,
88.159,1.68256,40.73913,,,,
88.359,1.60902,32.71386,,,,
88.559,1.53542,25.66887,,,,
88.759,1.46208,19.5967,,,,
88.959,1.3886,14.49624,,,,
89.159,1.31477,10.32744,,,,
89.359,1.24141,7.07799,,,,
89.559,1.16784,4.59899,,,,
89.759,1.09426,2.83541,,,,
89.959,1.02078,1.65417,,,,
90.159,0.94703,0.92233,,,,
90.359,0.87356,0.50736,,,,
90.559,0.79995,0.27198,,,,
90.759,0.72618,0.16141,,,,
90.959,0.65277,0.10028,,,,
91.137,0.58743,0.07687,,,,
91.139,0.58668,0.07612,,,,
91.339,0.62939,0.1253,,,,
91.539,0.70378,0.25962,,,,
91.739,0.77758,0.49922,,,,
91.741,0.77832,0.50246,,,,
91.743,0.77907,0.50563,,,,
91.745,0.77981,0.50943,,,,
91.747,0.78057,0.51888,,,,
91.749,0.78138,0.53994,,,,
91.751,0.7823,0.57078,,,,
91.753,0.78342,0.60805,,,,
91.755,0.78486,0.65206,,,,
91.757,0.78672,0.70402,,,,
91.759,0.78915,0.76402,,,,
91.761,0.79228,0.83123,,,,
91.763,0.79624,0.90798,,,,
91.765,0.80119,0.99635,,,,
91.767,0.80725,1.09874,,,,
91.769,0.81457,1.2196,,,,
91.771,0.82328,1.36404,,,,
91.773,0.8335,1.5378,,,,
91.775,0.84534,1.75023,,,,
91.777,0.85892,2.01431,,,,
91.779,0.87435,2.34527,,,,
91.781,0.89171,2.76017,,,,
91.783,0.9111,3.28045,,,,
91.785,0.93258,3.93224,,,,
91.787,0.95623,4.74231,,,,
91.789,0.98212,5.73932,,,,
91.791,1.01028,6.9564,,,,
91.793,1.04078,8.42737,,,,
91.795,1.07365,10.18501,,,,
91.797,1.10892,12.26167,,,,
91.799,1.14662,14.68966,,,,
91.801,1.18678,17.49739,,,,
91.803,1.22939,20.70837,,,,
91.805,1.27446,24.34371,,,,
91.807,1.32198,28.41953,,,,
91.809,1.37194,32.94009,,,,
91.811,1.42431,37.90565,,,,
91.813,1.47905,43.31148,,,,
91.815,1.53611,49.12966,,,,
91.817,1.59538,55.31631,,,,
91.819,1.65674,61.8254,,,,
91.821,1.72,68.60522,,,,
91.823,1.78498,75.59634,,,,
91.825,1.85146,82.73618,,,,
91.827,1.91924,89.96902,,,,
91.829,1.98812,97.24418,,,,
91.831,2.05794,104.51347,,,,
91.833,2.12853,111.73167,,,,
91.835,2.19975,118.86018,,,,
91.837,2.27148,125.86795,,,,
91.839,2.34364,132.72643,,,,
91.841,2.41615,139.40935,,,,
91.843,2.48895,145.89478,,,,
91.845,2.56199,152.16446,,,,
91.847,2.63524,158.20459,,,,
91.849,2.70868,164.00703,,,,
91.851,2.78229,169.56619,,,,
91.853,2.85605,174.87601,,,,
91.855,2.92995,179.93346,,,,
91.857,3.00398,184.74245,,,,
91.859,3.07813,189.3119,,,,
91.861,3.15239,193.65234,,,,
91.863,3.22674,197.77652,,,,
91.865,3.3012,201.69759,,,,
91.867,3.37573,205.42853,,,,
91.869,3.45032,208.98103,,,,
91.871,3.52498,212.3665,,,,
91.873,3.59967,215.5997,,,,
91.875,3.67439,218.69563,,,,
91.877,3.74913,221.66502,,,,
91.879,3.82386,224.51501,,,,
91.881,3.89859,227.2527,,,,
91.883,3.9733,229.8795,,,,
91.885,4.04798,232.36766,,,,
91.887,4.12262,234.47229,,,,
91.889,4.19722,234.66684,,,,
91.891,4.27177,231.71303,,,,
91.893,4.34626,225.78282,,,,
91.895,4.42071,217.50151,,,,
91.897,4.49509,207.42371,,,,
91.899,4.56943,195.99681,,,,
91.901,4.64371,183.59912,,,,
91.903,4.71795,170.56143,,,,
91.905,4.79215,157.17061,,,,
91.907,4.86631,143.68578,,,,
91.909,4.94044,130.32643,,,,
91.911,5.01454,117.27023,,,,
91.913,5.08861,104.65856,,,,
91.915,5.16265,92.5971,,,,
91.917,5.23666,81.16869,,,,
91.919,5.31065,70.43316,,,,
91.921,5.3846,60.4278,,,,
91.923,5.45853,51.17632,,,,
91.925,5.53243,42.68825,,,,
91.927,5.60631,34.96095,,,,
91.929,5.68016,27.98854,,,,
91.931,5.75399,21.75312,,,,
91.933,5.8278,16.2246,,,,
91.935,5.90158,11.36532,,,,
91.937,5.97534,7.13001,,,,
91.939,6.04909,3.47732,,,,
91.941,6.12281,0.36928,,,,
91.943,6.19651,-2.23834,,,,
91.945,6.2702,-4.39056,,,,
91.947,6.34387,-6.13076,,,,
91.949,6.41752,-7.50008,,,,
91.951,6.49117,-8.5345,,,,
91.953,6.56481,-9.27131,,,,
91.955,6.63844,-9.75075,,,,
91.957,6.71206,-10.0117,,,,
91.959,6.78567,-10.0881,,,,
91.961,6.85927,-10.00533,,,,
91.963,6.93286,-9.78665,,,,
91.965,7.00645,-9.46076,,,,
91.967,7.08003,-9.05599,,,,
91.969,7.15361,-8.59075,,,,
91.971,7.22719,-8.07509,,,,
91.973,7.30077,-7.5218,,,,
91.975,7.37436,-6.94711,,,,
91.977,7.44794,-6.36213,,,,
91.979,7.52153,-5.77744,,,,
91.981,7.59513,-5.20488,,,,
91.983,7.66872,-4.65197,,,,
91.985,7.74232,-4.12151,,,,
91.987,7.81593,-3.61399,,,,
91.989,7.88954,-3.13431,,,,
91.991,7.96315,-2.68796,,,,
91.993,8.03677,-2.27541,,,,
91.995,8.11039,-1.8948,,,,
91.997,8.18402,-1.54629,,,,
91.999,8.25764,-1.23171,,,,
92.001,8.33126,-0.95182,,,,
92.003,8.40488,-0.70504,,,,
92.005,8.4785,-0.4871,,,,
92.007,8.55212,-0.29506,,,,
92.009,8.62574,-0.12813,,,,
92.011,8.69935,0.01439,,,,
92.013,8.77296,0.13329,,,,
92.015,8.84657,0.23134,,,,
92.017,8.92018,0.31233,,,,
92.019,8.99378,0.37858,,,,
92.021,9.06738,0.43077,,,,
92.023,9.14098,0.46838,,,,
92.025,9.21457,0.49132,,,,
92.027,9.28816,0.50367,,,,
92.029,9.36174,0.50798,,,,
92.031,9.43532,0.50499,,,,
92.033,9.5089,0.49457,,,,
92.035,9.58247,0.47801,,,,
92.037,9.65604,0.45679,,,,
92.039,9.7296,0.4337,,,,
92.041,9.80315,0.41152,,,,
92.043,9.8767,0.38938,,,,
92.045,9.95025,0.365,,,,
92.047,10.0238,0.33888,,,,
92.049,10.09735,0.3128,,,,
92.051,10.1709,0.2887,,,,
92.053,10.24445,0.26674,,,,
92.055,10.31801,0.24522,,,,
92.057,10.39156,0.22257,,,,
92.059,10.46512,0.19992,,,,
92.061,10.53868,0.1795,,,,
92.063,10.61224,0.16192,,,,
92.065,10.6858,0.1443,,,,
92.067,10.75936,0.12605,,,,
92.069,10.83292,0.10946,,,,
92.071,10.90649,0.09596,,,,
92.073,10.98005,0.08533,,,,
92.075,11.05362,0.07535,,,,
92.077,11.12718,0.06649,,,,
92.079,11.20075,0.0594,,,,
92.081,11.27431,0.05314,,,,
92.083,11.34787,0.04744,,,,
92.085,11.42143,0.04345,,,,
92.087,11.49499,0.04169,,,,
92.089,11.56855,0.03925,,,,
92.091,11.64212,0.03439,,,,
92.093,11.71568,0.02966,,,,
92.095,11.78924,0.02792,,,,
92.097,11.86281,0.0277,,,,
92.099,11.93637,0.02733,,,,
92.101,12.00993,0.02765,,,,
92.103,12.08349,0.02913,,,,
92.105,12.15704,0.03039,,,,
92.107,12.23059,0.03149,,,,
92.109,12.30414,0.03337,,,,
92.111,12.3777,0.03334,,,,
92.113,12.45125,0.03244,,,,
92.115,12.5248,0.03419,,,,
92.117,12.59836,0.04083,,,,
92.119,12.67192,0.04672,,,,
92.121,12.74548,0.04766,,,,
92.123,12.81904,0.0469,,,,
92.125,12.89259,0.04795,,,,
92.127,12.96615,0.04974,,,,
92.129,13.03971,0.0506,,,,
92.131,13.11327,0.05145,,,,
92.133,13.18683,0.05264,,,,
92.135,13.26039,0.05333,,,,
92.137,13.33396,0.05389,,,,
92.139,13.40752,0.0549,,,,
92.141,13.48109,0.05508,,,,
92.143,13.55465,0.05439,,,,
92.145,13.62821,0.0545,,,,
92.147,13.70178,0.05646,,,,
92.149,13.77534,0.05903,,,,
92.151,13.8489,0.05967,,,,
92.153,13.92247,0.056,,,,
92.155,13.99604,0.04986,,,,
92.157,14.06961,0.04477,,,,
92.159,14.14318,0.04318,,,,
92.161,14.21675,0.04349,,,,
92.163,14.29032,0.0437,,,,
92.165,14.36389,0.04318,,,,
92.167,14.43746,0.04227,,,,
92.169,14.51103,0.04168,,,,
92.171,14.5846,0.04374,,,,
92.173,14.65817,0.04643,,,,
92.175,14.73173,0.04528,,,,
92.177,14.80529,0.04219,,,,
92.179,14.87885,0.04222,,,,
92.181,14.95241,0.04362,,,,
92.183,15.02597,0.0414,,,,
92.185,15.09953,0.03666,,,,
92.187,15.17309,0.03347,,,,
92.189,15.24664,0.03301,,,,
92.191,15.3202,0.0339,,,,
92.193,15.39377,0.03451,,,,
92.195,15.46733,0.03515,,,,
92.197,15.54089,0.0359,,,,
92.199,15.61446,0.03586,,,,
92.201,15.68803,0.03491,,,,
92.203,15.76159,0.03442,,,,
92.205,15.83516,0.03494,,,,
92.207,15.90872,0.03727,,,,
92.209,15.98228,0.04035,,,,
92.211,16.05584,0.04255,,,,
92.213,16.1294,0.04294,,,,
92.215,16.20295,0.0425,,,,
92.217,16.27651,0.04195,,,,
92.219,16.35006,0.04219,,,,
92.221,16.42361,0.04248,,,,
92.223,16.49716,0.04394,,,,
92.225,16.57071,0.04602,,,,
92.227,16.64425,0.04704,,,,
92.229,16.71779,0.0468,,,,
92.231,16.79134,0.04693,,,,
92.233,16.86489,0.04588,,,,
92.235,16.93843,0.04545,,,,
92.237,17.01198,0.04772,,,,
92.239,17.08553,0.05107,,,,
92.241,17.15908,0.05258,,,,
92.243,17.23264,0.05214,,,,
92.245,17.30619,0.04997,,,,
92.247,17.37974,0.04673,,,,
92.249,17.45329,0.04465,,,,
92.251,17.52684,0.04396,,,,
92.253,17.6004,0.04303,,,,
92.255,17.67396,0.0421,,,,
92.257,17.74753,0.04104,,,,
92.259,17.8211,0.03905,,,,
92.261,17.89467,0.03626,,,,
92.263,17.96825,0.03331,,,,
92.265,18.04182,0.03028,,,,
92.267,18.1154,0.02864,,,,
92.269,18.18898,0.02976,,,,
92.271,18.26256,0.03259,,,,
92.273,18.33615,0.03343,,,,
92.275,18.40973,0.03141,,,,
92.277,18.48331,0.0299,,,,
92.279,18.5569,0.03095,,,,
92.281,18.63048,0.03297,,,,
92.283,18.70406,0.03352,,,,
92.285,18.77765,0.03356,,,,
92.287,18.85122,0.03491,,,,
92.289,18.9248,0.03576,,,,
92.291,18.99837,0.03411,,,,
92.293,19.07195,0.03099,,,,
92.295,19.14552,0.02919,,,,
92.296,19.18231,0.02923,,,,