File: data/instron/Sample9_Static.is_tcyclic_RawData/Specimen_RawData_1.csv
Strain : Tensile strain (Extension) gauge length,"100.00000",mm

Time,Extension,Load
(s),(mm),(N)
"0.00000","0.00000","0.27949"
"0.20000","0.05241","0.43774"
"0.40000","0.12243","0.63921"
"0.60000","0.19229","0.90419"
"0.80000","0.26221","1.23982"
"1.00000","0.33167","1.68372"
"1.20000","0.40162","2.24833"
"1.40000","0.47119","2.96138"
"1.60000","0.54090","3.80591"
"1.80000","0.61065","4.91331"
"2.00000","0.68039","6.23460"
"2.20000","0.75021","7.82751"
"2.40000","0.81998","9.67556"
"2.60000","0.88977","11.90047"
"2.80000","0.95976","14.50039"
"3.00000","1.02927","17.49093"
"3.20000","1.09903","20.90379"
"3.40000","1.16909","24.68897"
"3.54900","1.22086","27.78256"
"3.55100","1.22156","27.82582"
"3.75100","1.23134","27.12310"
"3.95100","1.22912","26.29504"
"4.15100","1.22871","25.81560"
"4.35100","1.22869","25.46418"
"4.55100","1.22859","25.18545"
"4.75100","1.22862","24.95635"
"4.95100","1.22865","24.75241"
"5.15100","1.22869","24.57279"
"5.35100","1.22869","24.41221"
"5.55100","1.22869","24.26291"
"5.75100","1.22869","24.13278"
"5.95100","1.22869","24.00444"
"6.15100","1.22869","23.89732"
"6.35100","1.22869","23.78930"
"6.55100","1.22869","23.68046"
"6.75100","1.22869","23.58827"
"6.95100","1.22869","23.50069"
"7.15100","1.22869","23.41535"
"7.35100","1.22869","23.33364"
"7.55100","1.22869","23.25554"
"7.75100","1.22869","23.18592"
"7.95100","1.22869","23.12164"
"8.15100","1.22869","23.04786"
"8.35100","1.22869","22.98701"
"8.55100","1.22869","22.91973"
"8.75100","1.22869","22.86156"
"8.95100","1.22869","22.80303"
"9.15100","1.22869","22.75306"
"9.35100","1.22869","22.68985"
"9.55100","1.22869","22.64260"
"9.75100","1.22869","22.58694"
"9.95100","1.22864","22.54111"
"10.15100","1.22865","22.49813"
"10.35100","1.22869","22.44847"
"10.55100","1.22869","22.40540"
"10.75100","1.22869","22.36090"
"10.95100","1.22869","22.32556"
"11.15100","1.22869","22.28056"
"11.35100","1.22869","22.24081"
"11.55100","1.22869","22.19981"
"11.75100","1.22869","22.16489"
"11.95100","1.22869","22.11989"
"12.15100","1.22869","22.07972"
"12.35100","1.22869","22.04459"
"12.55100","1.22869","22.00142"
"12.75100","1.22869","21.97777"
"12.95100","1.22869","21.94872"
"13.15100","1.22869","21.91055"
"13.35100","1.22869","21.88150"
"13.55100","1.22869","21.84853"
"13.75100","1.22869","21.81342"
"13.95100","1.22869","21.78105"
"14.15100","1.22869","21.75099"
"14.35100","1.22869","21.72527"
"14.55100","1.22869","21.69819"
"14.75100","1.22869","21.66612"
"14.95100","1.22869","21.63334"
"15.15100","1.22869","21.60936"
"15.35100","1.22869","21.58801"
"15.55100","1.22869","21.55513"
"15.75100","1.22869","21.52504"
"15.95100","1.22869","21.50370"
"16.15100","1.22869","21.47450"
"16.35100","1.22869","21.44680"
"16.55100","1.22869","21.42521"
"16.75100","1.22869","21.39024"
"16.95100","1.22869","21.37180"
"17.15100","1.22869","21.34138"
"17.35100","1.22869","21.32769"
"17.55100","1.22869","21.29956"
"17.75100","1.22869","21.27845"
"17.95100","1.22869","21.25950"
"18.15100","1.22869","21.23273"
"18.35100","1.22869","21.21093"
"18.55100","1.22869","21.18270"
"18.75100","1.22869","21.17090"
"18.95100","1.22869","21.15124"
"19.15100","1.22869","21.13006"
"19.35100","1.22869","21.10342"
"19.55100","1.22869","21.09137"
"19.75100","1.22869","21.07019"
"19.95100","1.22869","21.04935"
"20.15100","1.22869","21.03451"
"20.35100","1.22869","21.00472"
"20.55100","1.22869","20.98950"
"20.75100","1.22869","20.96550"
"20.95100","1.22869","20.94566"
"21.15100","1.22869","20.92912"
"21.35100","1.22869","20.91514"
"21.55100","1.22869","20.88769"
"21.75100","1.22869","20.88172"
"21.95100","1.22869","20.85815"
"22.15100","1.22869","20.83355"
"22.35100","1.22869","20.81897"
"22.55100","1.22869","20.81091"
"22.75100","1.22869","20.78823"
"22.95100","1.22869","20.76151"
"23.15100","1.22869","20.74523"
"23.35100","1.22869","20.73173"
"23.55000","1.22869","20.71029"
"23.58100","1.22869","20.71484"
"23.78100","1.17376","15.71767"
"23.98100","1.10354","11.11707"
"24.18100","1.03370","7.82541"
"24.38100","0.96395","5.42662"
"24.58100","0.89436","3.69435"
"24.78100","0.82448","2.44588"
"24.98100","0.75471","1.59734"
"25.18100","0.68518","1.02946"
"25.38100","0.61517","0.65810"
"25.58100","0.54541","0.42566"
"25.78100","0.47587","0.28355"
"25.98100","0.40585","0.19929"
"26.18100","0.33644","0.13280"
"26.38100","0.26656","0.10652"
"26.58100","0.19659","0.08631"
"26.78100","0.12712","0.07763"
"26.98100","0.05718","0.06398"
"27.12300","0.00766","0.06768"
"27.12500","0.00695","0.06809"
"27.32500","0.04700","0.08428"
"27.52500","0.11748","0.10532"
"27.72500","0.18742","0.13729"
"27.92500","0.25726","0.18178"
"28.12500","0.32676","0.25232"
"28.32500","0.39682","0.37433"
"28.52500","0.46643","0.55664"
"28.72500","0.53605","0.82837"
"28.92500","0.60593","1.26223"
"29.12500","0.67575","1.91923"
"29.32500","0.74538","2.87379"
"29.52500","0.81533","4.20652"
"29.72500","0.88515","5.98665"
"29.92500","0.95503","8.29380"
"30.12500","1.02462","11.18605"
"30.32500","1.09439","14.73838"
"30.52500","1.16432","18.98309"
"30.71000","1.22863","23.49073"
"30.71200","1.22933","23.54337"
"30.91200","1.23904","23.51700"
"31.11200","1.23693","23.00179"
"31.31200","1.23656","22.74767"
"31.51200","1.23647","22.56649"
"31.71200","1.23647","22.42155"
"31.91200","1.23637","22.30069"
"32.11200","1.23638","22.19561"
"32.31200","1.23643","22.10372"
"32.51200","1.23644","22.02519"
"32.71200","1.23647","21.95217"
"32.91200","1.23647","21.88544"
"33.11200","1.23647","21.82598"
"33.31200","1.23647","21.76942"
"33.51200","1.23647","21.71292"
"33.71200","1.23647","21.69065"
"33.91200","1.23647","21.66354"
"34.11200","1.23647","21.55732"
"34.31200","1.23647","21.55252"
"34.51200","1.23647","21.46566"
"34.71200","1.23647","21.48325"
"34.91200","1.23647","21.39428"
"35.11200","1.23647","21.33584"
"35.31200","1.23647","21.35538"
"35.51200","1.23647","21.26180"
"35.71200","1.23647","21.22763"
"35.91200","1.23647","21.20154"
"36.11200","1.23647","21.16077"
"36.31200","1.23647","20.99126"
"36.51200","1.23647","21.10119"
"36.71200","1.23647","21.00044"
"36.91200","1.23647","20.90239"
"37.11200","1.23647","20.70733"
"37.31200","1.23647","20.57049"
"37.51200","1.23647","20.89690"
"37.71200","1.23647","20.89744"
"37.91200","1.23647","20.52474"
"38.11200","1.23647","20.82850"
"38.31200","1.23647","20.38185"
"38.51200","1.23647","20.42126"
"38.71200","1.23647","20.25181"
"38.91200","1.23647","20.66796"
"39.11200","1.23647","20.71939"
"39.31200","1.23647","20.70314"
"39.51200","1.23647","20.68464"
"39.71200","1.23647","20.65833"
"39.91200","1.23647","20.63923"
"40.11200","1.23647","20.64512"
"40.31200","1.23647","20.65157"
"40.51200","1.23647","20.57895"
"40.71200","1.23647","20.58328"
"40.91200","1.23647","20.53411"
"41.11200","1.23647","20.52590"
"41.31200","1.23647","20.50325"
"41.51200","1.23647","20.48496"
"41.71200","1.23647","20.51449"
"41.91200","1.23647","20.56645"
"42.11200","1.23647","20.41923"
"42.31200","1.23647","20.39289"
"42.51200","1.23647","20.37416"
"42.71200","1.23647","20.36196"
"42.91200","1.23647","20.34016"
"43.11200","1.23647","20.32952"
"43.31200","1.23647","20.32228"
"43.51200","1.23647","20.30184"
"43.71200","1.23647","20.28626"
"43.91200","1.23647","20.27156"
"44.11200","1.23647","20.25075"
"44.31200","1.23647","20.24811"
"44.51200","1.23647","20.22823"
"44.71200","1.23647","20.21337"
"44.91200","1.23647","20.20778"
"45.11200","1.23647","20.20219"
"45.31200","1.23647","20.18727"
"45.51200","1.23647","20.17488"
"45.71200","1.23647","20.15894"
"45.91200","1.23647","20.14733"
"46.11200","1.23647","20.13787"
"46.31200","1.23647","20.12944"
"46.51200","1.23647","20.10810"
"46.71200","1.23647","20.10777"
"46.91200","1.23647","20.09305"
"47.11200","1.23647","20.07588"
"47.31200","1.23647","20.06099"
"47.51200","1.23647","20.06149"
"47.71200","1.23647","20.04884"
"47.91200","1.23647","20.03143"
"48.11200","1.23647","20.02344"
"48.31200","1.23647","20.00961"
"48.51200","1.23647","20.00139"
"48.71200","1.23647","19.98378"
"48.91200","1.23647","19.97344"
"49.11200","1.23647","19.96685"
"49.31200","1.23647","19.95315"
"49.51200","1.23647","19.94712"
"49.71200","1.23647","19.93153"
"49.91200","1.23647","19.92435"
"50.11200","1.23647","19.90502"
"50.31200","1.23647","19.90282"
"50.51200","1.23647","19.89116"
"50.71100","1.23647","19.88622"
"50.73100","1.23647","19.88726"
"50.93100","1.18174","14.93141"
"51.13100","1.11120","10.37801"
"51.33100","1.04166","7.17434"
"51.53100","0.97189","4.87285"
"51.73100","0.90213","3.21991"
"51.93100","0.83239","2.07241"
"52.13100","0.76264","1.30852"
"52.33100","0.69295","0.81007"
"52.53100","0.62302","0.50309"
"52.73100","0.55320","0.32499"
"52.93100","0.48358","0.21627"
"53.13100","0.41364","0.15341"
"53.33100","0.34411","0.10624"
"53.53100","0.27425","0.09618"
"53.73100","0.20432","0.07408"
"53.93100","0.13481","0.06344"
"54.13100","0.06483","0.06723"
"54.27300","0.01547","0.06033"
"54.27500","0.01478","0.05898"
"54.47500","0.05504","0.06538"
"54.67500","0.12558","0.09221"
"54.87500","0.19547","0.11151"
"55.07500","0.26535","0.14605"
"55.27500","0.33487","0.20290"
"55.47500","0.40476","0.28267"
"55.67500","0.47434","0.42140"
"55.87500","0.54416","0.65100"
"56.07500","0.61383","1.00019"
"56.27500","0.68349","1.55364"
"56.47500","0.75339","2.39581"
"56.67500","0.82307","3.60922"
"56.87500","0.89279","5.26553"
"57.07500","0.96285","7.47835"
"57.27500","1.03236","10.28922"
"57.47500","1.10206","13.78024"
"57.67500","1.17217","18.00320"
"57.86000","1.23653","22.59370"
"57.86200","1.23722","22.64469"
"58.06200","1.24686","22.68542"
"58.26200","1.24483","22.21503"
"58.46200","1.24444","21.98339"
"58.66200","1.24434","21.82723"
"58.86200","1.24434","21.69702"
"59.06200","1.24434","21.59153"
"59.26200","1.24425","21.49879"
"59.46200","1.24430","21.42683"
"59.66200","1.24431","21.35036"
"59.86200","1.24434","21.29431"
"60.06200","1.24434","21.24455"
"60.26200","1.24434","21.18600"
"60.46200","1.24434","21.13946"
"60.66200","1.24434","21.09164"
"60.86200","1.24434","21.06374"
"61.06200","1.24434","21.01141"
"61.26200","1.24434","20.97882"
"61.46200","1.24434","20.94663"
"61.66200","1.24434","20.91012"
"61.86200","1.24434","20.87352"
"62.06200","1.24434","20.84946"
"62.26200","1.24434","20.81830"
"62.46200","1.24434","20.78633"
"62.66200","1.24434","20.76561"
"62.86200","1.24434","20.73778"
"63.06200","1.24434","20.71843"
"63.26200","1.24434","20.68940"
"63.46200","1.24434","20.67172"
"63.66200","1.24434","20.65134"
"63.86200","1.24434","20.62347"
"64.06200","1.24434","20.60761"
"64.26200","1.24434","20.58396"
"64.46200","1.24434","20.56320"
"64.66200","1.24434","20.54595"
"64.86200","1.24434","20.52663"
"65.06200","1.24434","20.50862"
"65.26200","1.24434","20.49137"
"65.46200","1.24434","20.46641"
"65.66200","1.24434","20.46002"
"65.86200","1.24434","20.43913"
"66.06200","1.24434","20.42120"
"66.26200","1.24434","20.40614"
"66.46200","1.24434","20.38974"
"66.66200","1.24434","20.37394"
"66.86200","1.24434","20.36185"
"67.06200","1.24434","20.34711"
"67.26200","1.24434","20.33154"
"67.46200","1.24434","20.30836"
"67.66200","1.24434","20.29649"
"67.86200","1.24434","20.28804"
"68.06200","1.24434","20.26730"
"68.26200","1.24434","20.25397"
"68.46200","1.24434","20.24444"
"68.66200","1.24434","20.22221"
"68.86200","1.24434","20.20554"
"69.06200","1.24434","20.19840"
"69.26200","1.24434","20.18953"
"69.46200","1.24434","20.17523"
"69.66200","1.24434","20.16805"
"69.86200","1.24434","20.14938"
"70.06200","1.24434","20.14053"
"70.26200","1.24434","20.12610"
"70.46200","1.24434","20.10957"
"70.66200","1.24434","20.09920"
"70.86200","1.24434","20.08549"
"71.06200","1.24434","20.08019"
"71.26200","1.24434","20.06072"
"71.46200","1.24434","20.04809"
"71.66200","1.24434","20.04474"
"71.86200","1.24434","20.03475"
"72.06200","1.24434","20.02470"
"72.26200","1.24434","20.00709"
"72.46200","1.24434","20.00708"
"72.66200","1.24434","19.99046"
"72.86200","1.24434","19.97787"
"73.06200","1.24434","19.96169"
"73.26200","1.24434","19.96246"
"73.46200","1.24434","19.93583"
"73.66200","1.24434","19.93376"
"73.86200","1.24434","19.92109"
"74.06200","1.24434","19.92365"
"74.26200","1.24434","19.90145"
"74.46200","1.24434","19.89282"
"74.66200","1.24434","19.88654"
"74.86200","1.24434","19.87753"
"75.06200","1.24434","19.86603"
"75.26200","1.24434","19.85500"
"75.46200","1.24434","19.83890"
"75.66200","1.24434","19.83810"
"75.86200","1.24434","19.82765"
"76.06200","1.24434","19.81258"
"76.26200","1.24434","19.80854"
"76.46200","1.24434","19.79861"
"76.66200","1.24434","19.79150"
"76.86200","1.24434","19.77580"
"77.06200","1.24434","19.77829"
"77.26200","1.24434","19.76291"
"77.46200","1.24434","19.75879"
"77.66200","1.24434","19.74343"
"77.86100","1.24434","19.74003"
"77.88600","1.24434","19.73582"
"78.08600","1.18974","14.76647"
"78.28600","1.11922","10.17724"
"78.48600","1.04977","6.97358"
"78.68600","0.97982","4.67151"
"78.88600","0.90994","3.04002"
"79.08600","0.84045","1.92714"
"79.28600","0.77051","1.19013"
"79.48600","0.70079","0.73220"
"79.68600","0.63103","0.44885"
"79.88600","0.56108","0.28593"
"80.08600","0.49140","0.18954"
"80.28600","0.42165","0.12661"
"80.48600","0.35179","0.10037"
"80.68600","0.28212","0.09050"
"80.88600","0.21236","0.07034"
"81.08600","0.14274","0.05953"
"81.28600","0.07288","0.06734"
"81.42800","0.02332","0.05463"
"81.43000","0.02263","0.05505"
"81.63000","0.01190","0.06062"
"81.83000","0.01204","0.07106"
"82.03000","0.01309","0.06981"
"82.23000","0.01455","0.07130"
"82.43000","0.01588","0.07634"
"82.63000","0.01713","0.07017"
"82.83000","0.01827","0.07339"
"83.03000","0.01944","0.07095"
"83.23000","0.02067","0.07403"
"83.43000","0.02184","0.07102"
"83.63000","0.02301","0.07538"
"83.83000","0.02420","0.07053"
"84.03000","0.02535","0.07499"
"84.23000","0.02651","0.07677"
"84.43000","0.02768","0.07647"
"84.63000","0.02884","0.07856"
"84.83000","0.03001","0.08032"
"85.03000","0.03117","0.08034"
"85.23000","0.03234","0.07451"
"85.43000","0.03352","0.07496"
"85.63000","0.03469","0.06981"
"85.83000","0.03584","0.07576"
"86.03000","0.03699","0.08228"
"86.23000","0.03817","0.07773"
"86.43000","0.03935","0.08208"
"86.63000","0.04051","0.07690"
"86.83000","0.04168","0.07783"
"87.03000","0.04285","0.07907"
"87.23000","0.04404","0.07659"
"87.43000","0.04522","0.07635"
"87.63000","0.04633","0.08559"
"87.83000","0.04749","0.07923"
"88.03000","0.04864","0.08155"
"88.23000","0.04983","0.08591"
"88.43000","0.05102","0.08304"
"88.63000","0.05217","0.07934"
"88.83000","0.05334","0.08291"
"89.03000","0.05446","0.08493"
"89.23000","0.05560","0.07969"
"89.43000","0.05677","0.08121"
"89.63000","0.05795","0.08913"
"89.83000","0.05910","0.08592"
"90.03000","0.06026","0.08856"
"90.23000","0.06143","0.09139"
"90.43000","0.06259","0.08725"
"90.63000","0.06375","0.09099"
"90.83000","0.06489","0.08336"
"91.03000","0.06606","0.08523"
"91.23000","0.06723","0.09226"
"91.43000","0.06841","0.09364"
"91.63000","0.06959","0.08420"
"91.83000","0.07080","0.08340"
"92.03000","0.07198","0.08642"
"92.23000","0.07310","0.08749"
"92.43000","0.07425","0.09648"
"92.63000","0.07544","0.08932"
"92.83000","0.07666","0.08780"
"93.03000","0.07783","0.08459"
"93.23000","0.07898","0.08785"
"93.43000","0.08016","0.09575"
"93.63000","0.08129","0.09207"
"93.83000","0.08241","0.08485"
"94.03000","0.08360","0.08879"
"94.23000","0.08476","0.09096"
"94.43000","0.08596","0.09114"
"94.63000","0.08711","0.08716"
"94.83000","0.08829","0.09312"
"95.03000","0.08944","0.09059"
"95.23000","0.09051","0.09133"
"95.43000","0.09166","0.09492"
"95.63000","0.09283","0.09505"
"95.83000","0.09399","0.09766"
"96.03000","0.09515","0.09594"
"96.23000","0.09632","0.09096"
"96.43000","0.09746","0.08277"
"96.63000","0.09863","0.09753"
"96.83000","0.09975","0.10176"
"97.03000","0.10095","0.09338"
"97.23000","0.10211","0.09549"
"97.43000","0.10328","0.09244"
"97.63000","0.10443","0.10394"
"97.83000","0.10563","0.09197"
"98.03000","0.10682","0.09838"
"98.23000","0.10796","0.10066"
"98.43000","0.10909","0.08882"
"98.63000","0.11030","0.10183"
"98.83000","0.11149","0.10141"
"99.03000","0.11271","0.10186"
"99.23000","0.11388","0.09937"
"99.43000","0.11504","0.09399"
"99.63000","0.11620","0.08994"
"99.83000","0.11728","0.09993"
"100.03000","0.11845","0.10800"
"100.23000","0.11962","0.10197"
"100.43000","0.12081","0.10970"
"100.63000","0.12202","0.10488"
"100.83000","0.12317","0.10068"
"101.03000","0.12433","0.09265"
"101.23000","0.12550","0.10232"
"101.43000","0.12656","0.10217"
"101.63000","0.12769","0.10129"
"101.83000","0.12892","0.09657"
"102.03000","0.13007","0.10719"
"102.23000","0.13127","0.10663"
"102.43000","0.13244","0.10151"
"102.63000","0.13359","0.10134"
"102.83000","0.13472","0.09925"
"103.03000","0.13579","0.10289"
"103.23000","0.13701","0.10318"
"103.43000","0.13815","0.10655"
"103.63000","0.13932","0.10551"
"103.83000","0.14049","0.10424"
"104.03000","0.14168","0.10694"
"104.23000","0.14287","0.11298"
"104.43000","0.14398","0.11255"
"104.63000","0.14513","0.11102"
"104.83000","0.14633","0.11022"
"105.03000","0.14752","0.10536"
"105.23000","0.14871","0.11256"
"105.43000","0.14991","0.11362"
"105.63000","0.15106","0.10899"
"105.83000","0.15224","0.11579"
"106.03000","0.15333","0.11377"
"106.23000","0.15448","0.11644"
"106.43000","0.15565","0.11396"
"106.63000","0.15685","0.11592"
"106.83000","0.15803","0.11774"
"107.03000","0.15920","0.11281"
"107.23000","0.16038","0.11345"
"107.43000","0.16152","0.11680"
"107.63000","0.16261","0.11145"
"107.83000","0.16377","0.11649"
"108.03000","0.16494","0.11692"
"108.23000","0.16609","0.11874"
"108.43000","0.16727","0.11902"
"108.63000","0.16843","0.11880"
"108.83000","0.16958","0.12559"
"109.03000","0.17073","0.11355"
"109.23000","0.17188","0.11759"
"109.43000","0.17305","0.12133"
"109.63000","0.17419","0.12236"
"109.83000","0.17538","0.11227"
"110.03000","0.17654","0.12751"
"110.23000","0.17773","0.12382"
"110.43000","0.17889","0.12087"
"110.63000","0.18002","0.12202"
"110.83000","0.18119","0.12186"
"111.03000","0.18238","0.12071"
"111.23000","0.18358","0.11576"
"111.43000","0.18480","0.12920"
"111.63000","0.18595","0.12653"
"111.83000","0.18712","0.12117"
"112.03000","0.18828","0.12223"
"112.23000","0.18936","0.11583"
"112.43000","0.19054","0.13001"
"112.63000","0.19172","0.13284"
"112.83000","0.19293","0.13134"
"113.03000","0.19408","0.12731"
"113.23000","0.19526","0.12552"
"113.43000","0.19642","0.12559"
"113.63000","0.19754","0.13304"
"113.83000","0.19865","0.12965"
"114.03000","0.19978","0.13227"
"114.23000","0.20099","0.13408"
"114.43000","0.20217","0.12849"
"114.63000","0.20335","0.12779"
"114.83000","0.20450","0.13728"
"115.03000","0.20568","0.13489"
"115.23000","0.20679","0.13182"
"115.43000","0.20791","0.13806"
"115.63000","0.20910","0.13813"
"115.83000","0.21026","0.12889"
"116.03000","0.21143","0.13894"
"116.23000","0.21264","0.13303"
"116.43000","0.21386","0.13731"
"116.63000","0.21500","0.14637"
"116.83000","0.21616","0.14233"
"117.03000","0.21732","0.14713"
"117.23000","0.21849","0.14089"
"117.43000","0.21968","0.13634"
"117.63000","0.22084","0.14789"
"117.83000","0.22199","0.14043"
"118.03000","0.22316","0.14248"
"118.23000","0.22428","0.13934"
"118.43000","0.22541","0.14208"
"118.63000","0.22659","0.14685"
"118.83000","0.22778","0.14918"
"119.03000","0.22895","0.14109"
"119.23000","0.23014","0.14392"
"119.43000","0.23129","0.14590"
"119.63000","0.23246","0.14764"
"119.83000","0.23359","0.14908"
"120.03000","0.23466","0.14628"
"120.23000","0.23584","0.15136"
"120.43000","0.23698","0.14502"
"120.63000","0.23817","0.14603"
"120.83000","0.23934","0.14992"
"121.03000","0.24050","0.15401"
"121.23000","0.24166","0.15001"
"121.43000","0.24279","0.15641"
"121.63000","0.24396","0.15484"
"121.83000","0.24513","0.15101"
"122.03000","0.24630","0.16123"
"122.23000","0.24748","0.14787"
"122.43000","0.24868","0.15894"
"122.63000","0.24990","0.16112"
"122.83000","0.25104","0.15368"
"123.03000","0.25221","0.16311"
"123.23000","0.25340","0.16155"
"123.43000","0.25457","0.15829"
"123.63000","0.25572","0.16311"
"123.83000","0.25688","0.16714"
"124.03000","0.25804","0.16085"
"124.23000","0.25920","0.16165"
"124.43000","0.26033","0.16451"
"124.63000","0.26144","0.17144"
"124.83000","0.26261","0.16780"
"125.03000","0.26378","0.16408"
"125.23000","0.26496","0.16773"
"125.43000","0.26609","0.17097"
"125.63000","0.26725","0.16877"
"125.83000","0.26841","0.16505"
"126.03000","0.26953","0.16837"
"126.23000","0.27071","0.17454"
"126.43000","0.27187","0.16911"
"126.63000","0.27303","0.17115"
"126.83000","0.27420","0.17176"
"127.03000","0.27536","0.17693"
"127.23000","0.27654","0.16960"
"127.43000","0.27766","0.17703"
"127.63000","0.27886","0.17967"
"127.83000","0.28004","0.18316"
"128.03000","0.28116","0.17887"
"128.23000","0.28233","0.18910"
"128.43000","0.28352","0.17361"
"128.63000","0.28472","0.18265"
"128.83000","0.28589","0.18178"
"129.03000","0.28700","0.18239"
"129.23000","0.28816","0.18786"
"129.43000","0.28937","0.18546"
"129.63000","0.29059","0.18402"
"129.83000","0.29176","0.19458"
"130.03000","0.29292","0.18615"
"130.23000","0.29409","0.19275"
"130.43000","0.29522","0.19145"
"130.63000","0.29634","0.18332"
"130.83000","0.29750","0.19859"
"131.03000","0.29867","0.18534"
"131.23000","0.29986","0.19543"
"131.43000","0.30102","0.18859"
"131.63000","0.30217","0.18958"
"131.83000","0.30333","0.19456"
"132.03000","0.30449","0.19677"
"132.23000","0.30556","0.20034"
"132.43000","0.30676","0.20218"
"132.63000","0.30791","0.19643"
"132.83000","0.30907","0.20211"
"133.03000","0.31026","0.20458"
"133.23000","0.31140","0.21127"
"133.43000","0.31256","0.21090"
"133.63000","0.31370","0.20564"
"133.83000","0.31489","0.20035"
"134.03000","0.31605","0.21280"
"134.23000","0.31721","0.20847"
"134.43000","0.31838","0.21965"
"134.63000","0.31955","0.20852"
"134.83000","0.32074","0.21967"
"135.03000","0.32194","0.22616"
"135.23000","0.32309","0.21573"
"135.43000","0.32422","0.22402"
"135.63000","0.32541","0.22715"
"135.83000","0.32662","0.22176"
"136.03000","0.32780","0.22308"
"136.23000","0.32896","0.22587"
"136.43000","0.33014","0.22391"
"136.63000","0.33128","0.21874"
"136.83000","0.33242","0.23089"
"137.03000","0.33359","0.22518"
"137.23000","0.33478","0.23087"
"137.43000","0.33594","0.23220"
"137.63000","0.33710","0.23368"
"137.83000","0.33826","0.24040"
"138.03000","0.33941","0.23525"
"138.23000","0.34052","0.24462"
"138.43000","0.34160","0.23503"
"138.63000","0.34280","0.23280"
"138.83000","0.34395","0.24504"
"139.03000","0.34512","0.23642"
"139.23000","0.34627","0.24122"
"139.43000","0.34745","0.24731"
"139.63000","0.34861","0.24954"
"139.83000","0.34974","0.24190"
"140.03000","0.35093","0.24593"
"140.23000","0.35208","0.24803"
"140.43000","0.35325","0.25266"
"140.63000","0.35442","0.24188"
"140.83000","0.35560","0.25300"
"141.03000","0.35681","0.25323"
"141.23000","0.35793","0.25375"
"141.43000","0.35907","0.25287"
"141.63000","0.36027","0.25886"
"141.83000","0.36148","0.26432"
"142.03000","0.36268","0.26929"
"142.23000","0.36384","0.26517"
"142.43000","0.36501","0.26760"
"142.63000","0.36618","0.27062"
"142.83000","0.36727","0.26777"
"143.03000","0.36842","0.27270"
"143.23000","0.36961","0.27465"
"143.43000","0.37082","0.27283"
"143.63000","0.37199","0.27345"
"143.83000","0.37314","0.27430"
"144.03000","0.37432","0.27573"
"144.23000","0.37546","0.28284"
"144.43000","0.37658","0.28212"
"144.63000","0.37771","0.29245"
"144.83000","0.37893","0.27880"
"145.03000","0.38013","0.28394"
"145.23000","0.38128","0.28653"
"145.43000","0.38244","0.28745"
"145.63000","0.38357","0.28729"
"145.83000","0.38475","0.30373"
"146.03000","0.38584","0.29452"
"146.23000","0.38696","0.29971"
"146.43000","0.38813","0.29680"
"146.63000","0.38931","0.30100"
"146.83000","0.39048","0.30021"
"147.03000","0.39168","0.30447"
"147.23000","0.39286","0.30469"
"147.43000","0.39399","0.30930"
"147.63000","0.39515","0.30324"
"147.83000","0.39632","0.30918"
"148.03000","0.39753","0.31343"
"148.23000","0.39873","0.31069"
"148.43000","0.39988","0.31846"
"148.63000","0.40105","0.31677"
"148.83000","0.40219","0.32711"
"149.03000","0.40329","0.32166"
"149.23000","0.40448","0.32958"
"149.43000","0.40568","0.32306"
"149.63000","0.40687","0.33448"
"149.83000","0.40803","0.32730"
"150.03000","0.40918","0.33022"
"150.23000","0.41034","0.33369"
"150.43000","0.41149","0.33409"
"150.63000","0.41258","0.34025"
"150.83000","0.41372","0.34049"
"151.03000","0.41492","0.34281"
"151.23000","0.41611","0.34935"
"151.43000","0.41730","0.35146"
"151.63000","0.41849","0.34927"
"151.83000","0.41964","0.35654"
"152.03000","0.42080","0.35169"
"152.23000","0.42189","0.36128"
"152.43000","0.42300","0.36113"
"152.63000","0.42418","0.35598"
"152.83000","0.42534","0.35740"
"153.03000","0.42652","0.36670"
"153.23000","0.42771","0.37739"
"153.43000","0.42890","0.37458"
"153.63000","0.43003","0.37334"
"153.83000","0.43118","0.37507"
"154.03000","0.43238","0.37888"
"154.23000","0.43361","0.38192"
"154.43000","0.43477","0.38416"
"154.63000","0.43593","0.39007"
"154.83000","0.43710","0.39258"
"155.03000","0.43820","0.39534"
"155.23000","0.43937","0.39827"
"155.43000","0.44055","0.40088"
"155.63000","0.44170","0.40040"
"155.83000","0.44288","0.40025"
"156.03000","0.44406","0.39633"
"156.23000","0.44523","0.41632"
"156.43000","0.44639","0.41632"
"156.63000","0.44756","0.41154"
"156.83000","0.44865","0.41500"
"157.03000","0.44977","0.41027"
"157.23000","0.45096","0.42291"
"157.43000","0.45215","0.42207"
"157.63000","0.45331","0.43004"
"157.83000","0.45446","0.42024"
"158.03000","0.45562","0.43358"
"158.23000","0.45671","0.43415"
"158.43000","0.45792","0.43295"
"158.63000","0.45909","0.43785"
"158.83000","0.46023","0.44986"
"159.03000","0.46138","0.44536"
"159.23000","0.46255","0.44646"
"159.43000","0.46373","0.45582"
"159.63000","0.46488","0.45228"
"159.83000","0.46603","0.45925"
"160.03000","0.46722","0.46866"
"160.23000","0.46839","0.46551"
"160.43000","0.46957","0.47078"
"160.63000","0.47076","0.47040"
"160.83000","0.47195","0.48306"
"161.03000","0.47314","0.47906"
"161.23000","0.47422","0.48569"
"161.43000","0.47535","0.48913"
"161.63000","0.47652","0.48854"
"161.83000","0.47769","0.49057"
"161.94800","0.47840","0.50004"
"161.95000","0.47841","0.50047"
"161.97000","0.47867","0.50125"
"161.99000","0.48071","0.50378"
"162.01000","0.48310","0.52742"
"162.03000","0.48651","0.55648"
"162.05000","0.49366","0.58563"
"162.07000","0.50330","0.62298"
"162.09000","0.51271","0.66566"
"162.11000","0.52086","0.70980"
"162.13000","0.52810","0.74901"
"162.15000","0.53507","0.78309"
"162.17000","0.54224","0.82461"
"162.19000","0.54949","0.86138"
"162.21000","0.55651","0.90184"
"162.23000","0.56336","0.94221"
"162.25000","0.57030","0.98320"
"162.27000","0.57747","1.02742"
"162.29000","0.58477","1.07785"
"162.31000","0.59184","1.11947"
"162.33000","0.59862","1.16795"
"162.35000","0.60534","1.21806"
"162.37000","0.61226","1.27608"
"162.39000","0.61946","1.33648"
"162.41000","0.62665","1.39777"
"162.43000","0.63358","1.45870"
"162.45000","0.64031","1.51036"
"162.47000","0.64716","1.57860"
"162.49000","0.65423","1.65504"
"162.51000","0.66134","1.72037"
"162.53000","0.66832","1.79313"
"162.55000","0.67513","1.86287"
"162.57000","0.68196","1.94524"
"162.59000","0.68898","2.03367"
"162.61000","0.69611","2.12319"
"162.63000","0.70317","2.20883"
"162.65000","0.71010","2.29616"
"162.67000","0.71696","2.39617"
"162.69000","0.72389","2.49455"
"162.71000","0.73090","2.59459"
"162.73000","0.73785","2.69907"
"162.75000","0.74479","2.80891"
"162.77000","0.75184","2.92511"
"162.79000","0.75905","3.04382"
"162.81000","0.76617","3.16271"
"162.83000","0.77307","3.27975"
"162.85000","0.77985","3.40731"
"162.87000","0.78673","3.54101"
"162.89000","0.79389","3.67616"
"162.91000","0.80108","3.81877"
"162.93000","0.80799","3.96853"
"162.95000","0.81474","4.11184"
"162.97000","0.82153","4.26688"
"162.99000","0.82860","4.42565"
"163.01000","0.83583","4.58712"
"163.03000","0.84289","4.75891"
"163.05000","0.84966","4.92826"
"163.07000","0.85635","5.09447"
"163.09000","0.86329","5.27563"
"163.11000","0.87049","5.46151"
"163.13000","0.87764","5.65585"
"163.15000","0.88457","5.85036"
"163.17000","0.89130","6.05082"
"163.19000","0.89813","6.25873"
"163.21000","0.90516","6.47254"
"163.23000","0.91228","6.69177"
"163.25000","0.91932","6.91011"
"163.27000","0.92621","7.12973"
"163.29000","0.93312","7.36140"
"163.31000","0.94021","7.60888"
"163.33000","0.94736","7.85897"
"163.35000","0.95441","8.11154"
"163.37000","0.96134","8.36173"
"163.39000","0.96825","8.62340"
"163.41000","0.97523","8.89535"
"163.43000","0.98225","9.16840"
"163.45000","0.98920","9.44262"
"163.47000","0.99609","9.71713"
"163.49000","1.00308","10.00304"
"163.51000","1.01020","10.31124"
"163.53000","1.01721","10.62368"
"163.55000","1.02404","10.93002"
"163.57000","1.03084","11.23855"
"163.59000","1.03777","11.55005"
"163.61000","1.04488","11.87608"
"163.63000","1.05198","12.21923"
"163.65000","1.05886","12.56382"
"163.67000","1.06565","12.90188"
"163.69000","1.07255","13.25454"
"163.71000","1.07965","13.62027"
"163.73000","1.08682","13.99763"
"163.75000","1.09379","14.37400"
"163.77000","1.10057","14.74460"
"163.79000","1.10737","15.13274"
"163.81000","1.11441","15.52566"
"163.83000","1.12163","15.93358"
"163.85000","1.12879","16.35056"
"163.87000","1.13578","16.76392"
"163.89000","1.14265","17.19186"
"163.91000","1.14960","17.62474"
"163.93000","1.15667","18.06639"
"163.95000","1.16371","18.50416"
"163.97000","1.17067","18.94050"
"163.99000","1.17750","19.38296"
"164.01000","1.18439","19.84824"
"164.03000","1.19142","20.32633"
"164.05000","1.19848","20.80638"
"164.07000","1.20547","21.28181"
"164.09000","1.21237","21.75837"
"164.11000","1.21930","22.24771"
"164.13000","1.22629","22.76787"
"164.15000","1.23328","23.28799"
"164.17000","1.24018","23.79489"
"164.19000","1.24705","24.29379"
"164.21000","1.25404","24.81273"
"164.23000","1.26112","25.35662"
"164.25000","1.26813","25.90276"
"164.27000","1.27503","26.45273"
"164.29000","1.28188","26.98429"
"164.31000","1.28889","27.53442"
"164.33000","1.29609","28.09937"
"164.35000","1.30316","28.66367"
"164.37000","1.30997","29.21425"
"164.39000","1.31673","29.76567"
"164.41000","1.32371","30.33283"
"164.43000","1.33097","30.93381"
"164.45000","1.33823","31.52734"
"164.47000","1.34515","32.10535"
"164.49000","1.35188","32.66288"
"164.51000","1.35870","33.24964"
"164.53000","1.36577","33.86652"
"164.55000","1.37295","34.47856"
"164.57000","1.38001","35.07951"
"164.59000","1.38681","35.66693"
"164.61000","1.39357","36.27115"
"164.63000","1.40056","36.90165"
"164.65000","1.40769","37.53193"
"164.67000","1.41474","38.14898"
"164.69000","1.42163","38.75006"
"164.71000","1.42843","39.36150"
"164.73000","1.43532","39.99674"
"164.75000","1.44239","40.65267"
"164.77000","1.44947","41.29481"
"164.79000","1.45643","41.91496"
"164.81000","1.46330","42.53332"
"164.83000","1.47024","43.18413"
"164.85000","1.47729","43.85528"
"164.87000","1.48428","44.51950"
"164.89000","1.49119","45.15638"
"164.91000","1.49811","45.78964"
"164.93000","1.50523","46.45156"
"164.95000","1.51247","47.15068"
"164.97000","1.51954","47.83810"
"164.99000","1.52640","48.49838"
"165.01000","1.53318","49.13701"
"165.03000","1.54017","49.80342"
"165.05000","1.54738","50.49902"
"165.07000","1.55444","51.19110"
"165.09000","1.56126","51.86192"
"165.11000","1.56800","52.52011"
"165.13000","1.57491","53.19994"
"165.15000","1.58209","53.90571"
"165.17000","1.58928","54.61216"
"165.19000","1.59616","55.29605"
"165.21000","1.60285","55.96063"
"165.23000","1.60966","56.64346"
"165.25000","1.61677","57.36128"
"165.27000","1.62398","58.08511"
"165.29000","1.63102","58.78196"
"165.31000","1.63783","59.46358"
"165.33000","1.64461","60.16132"
"165.35000","1.65158","60.89198"
"165.37000","1.65868","61.63198"
"165.39000","1.66573","62.34845"
"165.41000","1.67266","63.04760"
"165.43000","1.67951","63.75703"
"165.45000","1.68652","64.51440"
"165.47000","1.69369","65.28474"
"165.49000","1.70080","66.03169"
"165.51000","1.70776","66.74986"
"165.53000","1.71468","67.47140"
"165.55000","1.72167","68.22327"
"165.57000","1.72873","68.98492"
"165.59000","1.73571","69.72720"
"165.61000","1.74258","70.44686"
"165.63000","1.74943","71.15293"
"165.65000","1.75647","71.90589"
"165.67000","1.76358","72.69540"
"165.69000","1.77052","73.46598"
"165.71000","1.77735","74.20940"
"165.73000","1.78419","74.94524"
"165.75000","1.79120","75.71483"
"165.77000","1.79835","76.51653"
"165.79000","1.80537","77.29774"
"165.81000","1.81220","78.05758"
"165.83000","1.81899","78.80901"
"165.85000","1.82597","79.57784"
"165.87000","1.83311","80.36385"
"165.89000","1.84020","81.14685"
"165.91000","1.84710","81.91606"
"165.93000","1.85388","82.67472"
"165.95000","1.86081","83.46173"
"165.97000","1.86797","84.27637"
"165.98600","1.87372","84.92817"
"165.98800","1.87444","85.00912"
"166.15100","1.84811","78.08444"
"166.30200","1.79383","67.97870"
"166.47600","1.73286","57.94273"
"166.67200","1.66432","48.03741"
"166.87200","1.59482","39.26646"
"167.07200","1.52477","31.59047"
"167.27200","1.45505","25.04928"
"167.47200","1.38537","19.46632"
"167.67200","1.31525","14.81145"
"167.87200","1.24567","11.04501"
"168.07200","1.17600","7.98691"
"168.27200","1.10605","5.61619"
"168.47200","1.03648","3.82370"
"168.67200","0.96676","2.49716"
"168.87200","0.89712","1.59321"
"169.07200","0.82727","0.98544"
"169.27200","0.75751","0.60102"
"169.47200","0.68791","0.38128"
"169.67200","0.61794","0.25616"
"169.87200","0.54818","0.16619"
"170.07200","0.47856","0.12393"
"170.07400","0.47787","0.12326"
"170.17500","0.46650","0.12443"
"170.37500","0.46656","0.14913"
"170.57500","0.46710","0.14602"
"170.77500","0.46852","0.15235"
"170.97500","0.46987","0.16244"
"171.17500","0.47114","0.16477"
"171.37500","0.47239","0.17255"
"171.57500","0.47357","0.17903"
"171.77500","0.47475","0.18235"
"171.97500","0.47593","0.17629"
"172.17500","0.47711","0.19058"
"172.37500","0.47829","0.18583"
"172.57500","0.47945","0.19082"
"172.77500","0.48060","0.19049"
"172.97500","0.48178","0.19810"
"173.17500","0.48295","0.20170"
"173.37500","0.48408","0.21100"
"173.57500","0.48528","0.20812"
"173.77500","0.48644","0.21102"
"173.97500","0.48760","0.20579"
"174.17500","0.48877","0.21307"
"174.37500","0.48992","0.21856"
"174.57500","0.49108","0.22271"
"174.77500","0.49224","0.22290"
"174.97500","0.49341","0.21663"
"175.17500","0.49457","0.22545"
"175.37500","0.49574","0.22661"
"175.57500","0.49691","0.23679"
"175.77500","0.49809","0.24401"
"175.97500","0.49926","0.23777"
"176.17500","0.50041","0.23818"
"176.37500","0.50154","0.23886"
"176.57500","0.50272","0.24662"
"176.77500","0.50390","0.24656"
"176.97500","0.50510","0.25104"
"177.17500","0.50627","0.25172"
"177.37500","0.50743","0.25518"
"177.57500","0.50859","0.25769"
"177.77500","0.50977","0.26240"
"177.97500","0.51087","0.25461"
"178.17500","0.51201","0.26355"
"178.37500","0.51321","0.27461"
"178.57500","0.51439","0.27503"
"178.77500","0.51554","0.26898"
"178.97500","0.51667","0.27771"
"179.17500","0.51785","0.27962"
"179.37500","0.51900","0.28765"
"179.57500","0.52014","0.28535"
"179.77500","0.52135","0.28929"
"179.97500","0.52251","0.28714"
"180.17500","0.52365","0.29303"
"180.37500","0.52481","0.30144"
"180.57500","0.52598","0.29711"
"180.77500","0.52714","0.29683"
"180.97500","0.52827","0.30502"
"181.17500","0.52945","0.30070"
"181.37500","0.53063","0.30575"
"181.57500","0.53179","0.30340"
"181.77500","0.53298","0.31620"
"181.97500","0.53417","0.31298"
"182.17500","0.53541","0.31483"
"182.37500","0.53652","0.32038"
"182.57500","0.53765","0.32209"
"182.77500","0.53885","0.32953"
"182.97500","0.54007","0.32300"
"183.17500","0.54122","0.33214"
"183.37500","0.54238","0.32983"
"183.57500","0.54355","0.33457"
"183.77500","0.54470","0.33961"
"183.97500","0.54580","0.33959"
"184.17500","0.54695","0.33997"
"184.37500","0.54808","0.34749"
"184.57500","0.54924","0.35275"
"184.77500","0.55043","0.35120"
"184.97500","0.55157","0.35925"
"185.17500","0.55272","0.35551"
"185.37500","0.55388","0.35478"
"185.57500","0.55501","0.35860"
"185.77500","0.55621","0.36846"
"185.97500","0.55737","0.36584"
"186.17500","0.55853","0.37755"
"186.37500","0.55971","0.37438"
"186.57500","0.56089","0.38266"
"186.77500","0.56206","0.38286"
"186.97500","0.56321","0.38868"
"187.17500","0.56432","0.38873"
"187.37500","0.56551","0.39037"
"187.57500","0.56667","0.39974"
"187.77500","0.56785","0.40031"
"187.97500","0.56907","0.40366"
"188.17500","0.57031","0.41057"
"188.37500","0.57144","0.40334"
"188.57500","0.57257","0.40855"
"188.77500","0.57377","0.41477"
"188.97500","0.57495","0.42065"
"189.17500","0.57611","0.41996"
"189.37500","0.57727","0.42572"
"189.57500","0.57843","0.43114"
"189.77500","0.57960","0.43247"
"189.97500","0.58073","0.43311"
"190.17500","0.58188","0.44209"
"190.37500","0.58308","0.44343"
"190.57500","0.58425","0.44761"
"190.77500","0.58539","0.44363"
"190.97500","0.58657","0.45554"
"191.17500","0.58769","0.45826"
"191.37500","0.58883","0.45915"
"191.57500","0.58998","0.46410"
"191.77500","0.59106","0.46713"
"191.97500","0.59225","0.47196"
"192.17500","0.59344","0.47658"
"192.37500","0.59459","0.48175"
"192.57500","0.59576","0.48249"
"192.77500","0.59690","0.49372"
"192.93900","0.59786","0.50019"
"192.94100","0.59787","0.50036"
"192.94300","0.59788","0.50035"
"192.94500","0.59790","0.50275"
"192.94700","0.59794","0.51383"
"192.94900","0.59806","0.53553"
"192.95100","0.59833","0.56486"
"192.95300","0.59885","0.60067"
"192.95500","0.59971","0.64362"
"192.95700","0.60106","0.69355"
"192.95900","0.60301","0.74908"
"192.96100","0.60571","0.81133"
"192.96300","0.60928","0.88145"
"192.96500","0.61388","0.95933"
"192.96700","0.61963","1.04676"
"192.96900","0.62668","1.14642"
"192.97100","0.63513","1.26124"
"192.97300","0.64513","1.39482"
"192.97500","0.65677","1.55262"
"192.97700","0.67017","1.74309"
"192.97900","0.68543","1.97526"
"192.98100","0.70263","2.26005"
"192.98300","0.72186","2.61093"
"192.98500","0.74319","3.04255"
"192.98700","0.76670","3.57257"
"192.98900","0.79243","4.22311"
"192.99100","0.82043","5.01972"
"192.99300","0.85077","5.98935"
"192.99500","0.88347","7.16261"
"192.99700","0.91856","8.57447"
"192.99900","0.95608","10.26013"
"193.00100","0.99604","12.25577"
"193.00300","1.03844","14.59786"
"193.00500","1.08327","17.32484"
"193.00700","1.13049","20.47300"
"193.00900","1.18008","24.07428"
"193.01100","1.23199","28.15585"
"193.01300","1.28615","32.73325"
"193.01500","1.34245","37.80773"
"193.01700","1.40077","43.37212"
"193.01900","1.46093","49.40987"
"193.02100","1.52273","55.89400"
"193.02300","1.58598","62.78774"
"193.02500","1.65048","70.04980"
"193.02700","1.71604","77.63998"
"193.02900","1.78249","85.51707"
"193.03100","1.84967","93.63772"
"193.03300","1.91745","101.96008"
"193.03500","1.98571","110.44698"
"193.03700","2.05437","119.06074"
"193.03900","2.12335","127.76126"
"193.04100","2.19258","136.50691"
"193.04300","2.26204","145.25494"
"193.04500","2.33168","153.96144"
"193.04700","2.40147","162.58171"
"193.04900","2.47141","171.07944"
"193.05100","2.54148","179.43137"
"193.05300","2.61166","187.62875"
"193.05500","2.68195","195.67198"
"193.05700","2.75235","203.56277"
"193.05900","2.82283","211.29799"
"193.06100","2.89340","218.86960"
"193.06300","2.96404","226.26808"
"193.06500","3.03475","233.48280"
"193.06700","3.10552","240.50381"
"193.06900","3.17633","247.32805"
"193.07100","3.24717","253.95685"
"193.07300","3.31804","260.38824"
"193.07500","3.38891","266.59277"
"193.07700","3.45978","271.69086"
"193.07900","3.53063","273.34702"
"193.08100","3.60146","270.79874"
"193.08300","3.67227","264.62250"
"193.08500","3.74304","255.59804"
"193.08700","3.81379","244.35347"
"193.08900","3.88450","231.41232"
"193.09100","3.95517","217.23109"
"193.09300","4.02581","202.21841"
"193.09500","4.09641","186.72841"
"193.09700","4.16698","171.07068"
"193.09900","4.23751","155.50525"
"193.10100","4.30800","140.24310"
"193.10300","4.37844","125.45343"
"193.10500","4.44885","111.26692"
"193.10700","4.51921","97.78703"
"193.10900","4.58954","85.08735"
"193.11100","4.65982","73.22250"
"193.11300","4.73006","62.22839"
"193.11500","4.80025","52.12263"
"193.11700","4.87040","42.90560"
"193.11900","4.94051","34.56847"
"193.12100","5.01057","27.09673"
"193.12300","5.08060","20.45816"
"193.12500","5.15059","14.60549"
"193.12700","5.22054","9.48823"
"193.12900","5.29048","5.06214"
"193.13100","5.36039","1.28309"
"193.13300","5.43028","-1.90023"
"193.13500","5.50015","-4.54019"
"193.13700","5.57001","-6.68346"
"193.13900","5.63985","-8.37700"
"193.14100","5.70969","-9.66893"
"193.14300","5.77951","-10.60665"
"193.14500","5.84932","-11.23537"
"193.14700","5.91913","-11.59608"
"193.14900","5.98894","-11.72762"
"193.15100","6.05874","-11.66571"
"193.15300","6.12855","-11.44352"
"193.15500","6.19835","-11.09213"
"193.15700","6.26815","-10.63816"
"193.15900","6.33795","-10.10440"
"193.16100","6.40774","-9.51284"
"193.16300","6.47754","-8.88014"
"193.16500","6.54733","-8.21803"
"193.16700","6.61712","-7.53878"
"193.16900","6.68691","-6.85680"
"193.17100","6.75670","-6.18526"
"193.17300","6.82649","-5.53135"
"193.17500","6.89628","-4.90039"
"193.17700","6.96607","-4.29854"
"193.17900","7.03587","-3.73123"
"193.18100","7.10567","-3.20043"
"193.18300","7.17546","-2.70782"
"193.18500","7.24525","-2.25360"
"193.18700","7.31505","-1.83783"
"193.18900","7.38484","-1.46154"
"193.19100","7.45462","-1.12770"
"193.19300","7.52441","-0.83555"
"193.19500","7.59420","-0.57823"
"193.19700","7.66399","-0.35237"
"193.19900","7.73378","-0.15853"
"193.20100","7.80357","0.00643"
"193.20300","7.87337","0.14843"
"193.20500","7.94316","0.26881"
"193.20700","8.01296","0.36659"
"193.20900","8.08275","0.44368"
"193.21100","8.15255","0.50300"
"193.21300","8.22234","0.54840"
"193.21500","8.29214","0.58056"
"193.21700","8.36194","0.60055"
"193.21900","8.43174","0.60905"
"193.22100","8.50154","0.60652"
"193.22300","8.57135","0.59326"
"193.22500","8.64115","0.57325"
"193.22700","8.71095","0.55023"
"193.22900","8.78074","0.52532"
"193.23100","8.85054","0.49870"
"193.23300","8.92033","0.47198"
"193.23500","8.99012","0.44524"
"193.23700","9.05991","0.41792"
"193.23900","9.12970","0.39056"
"193.24100","9.19948","0.36389"
"193.24300","9.26927","0.33804"
"193.24500","9.33905","0.31293"
"193.24700","9.40884","0.28984"
"193.24900","9.47861","0.26908"
"193.25100","9.54839","0.25108"
"193.25300","9.61817","0.23221"
"193.25500","9.68794","0.21187"
"193.25700","9.75770","0.19234"
"193.25900","9.82747","0.17526"
"193.26100","9.89724","0.16068"
"193.26300","9.96700","0.14849"
"193.26500","10.03676","0.13729"
"193.26700","10.10652","0.12564"
"193.26900","10.17627","0.11481"
"193.27100","10.24602","0.10696"
"193.27300","10.31577","0.10109"
"193.27500","10.38552","0.09632"
"193.27700","10.45527","0.09362"
"193.27900","10.52502","0.09262"
"193.28100","10.59477","0.09096"
"193.28300","10.66452","0.08813"
"193.28500","10.73428","0.08524"
"193.28700","10.80404","0.08143"
"193.28900","10.87380","0.07680"
"193.29100","10.94356","0.07299"
"193.29300","11.01332","0.07223"
"193.29500","11.08308","0.07362"
"193.29700","11.15284","0.07419"
"193.29900","11.22261","0.07476"
"193.30100","11.29237","0.07641"
"193.30300","11.36213","0.07865"
"193.30500","11.43190","0.08142"
"193.30700","11.50167","0.08587"
"193.30900","11.57143","0.09172"
"193.31100","11.64119","0.09667"
"193.31300","11.71095","0.09981"
"193.31500","11.78071","0.10091"
"193.31700","11.85046","0.10066"
"193.31900","11.92022","0.10011"
"193.32100","11.98998","0.09999"
"193.32300","12.05973","0.10029"
"193.32500","12.12949","0.10068"
"193.32700","12.19925","0.10115"
"193.32900","12.26901","0.10086"
"193.33100","12.33877","0.10018"
"193.33300","12.40853","0.10072"
"193.33500","12.47828","0.10278"
"193.33700","12.54803","0.10445"
"193.33900","12.61778","0.10451"
"193.34100","12.68753","0.10629"
"193.34300","12.75727","0.10784"
"193.34500","12.82702","0.10556"
"193.34700","12.89677","0.09975"
"193.34900","12.96652","0.09461"
"193.35100","13.03627","0.09161"
"193.35300","13.10603","0.08771"
"193.35500","13.17578","0.08227"
"193.35700","13.24553","0.07827"
"193.35900","13.31529","0.07595"
"193.36100","13.38504","0.07323"
"193.36300","13.45479","0.07031"
"193.36500","13.52455","0.06992"
"193.36700","13.59430","0.07130"
"193.36900","13.66406","0.07218"
"193.37100","13.73382","0.07279"
"193.37300","13.80358","0.07436"
"193.37500","13.87334","0.07462"
"193.37700","13.94310","0.07372"
"193.37900","14.01286","0.07432"
"193.38100","14.08262","0.07600"
"193.38300","14.15238","0.07639"
"193.38500","14.22214","0.07620"
"193.38700","14.29190","0.07576"
"193.38900","14.36166","0.07501"
"193.39100","14.43143","0.07425"
"193.39300","14.50120","0.07384"
"193.39500","14.57097","0.07535"
"193.39700","14.64074","0.07915"
"193.39900","14.71052","0.08431"
"193.40100","14.78029","0.08983"
"193.40300","14.85006","0.09516"
"193.40500","14.91983","0.10020"
"193.40700","14.98959","0.10620"
"193.40900","15.05936","0.11134"
"193.41100","15.12912","0.11179"
"193.41300","15.19888","0.10926"
"193.41500","15.26865","0.10869"
"193.41700","15.33841","0.10939"
"193.41900","15.40817","0.10607"
"193.42100","15.47792","0.09973"
"193.42300","15.54768","0.09603"
"193.42500","15.61744","0.09573"
"193.42700","15.68720","0.09480"
"193.42900","15.75696","0.09248"
"193.43100","15.82672","0.09052"
"193.43300","15.89648","0.08968"
"193.43500","15.96624","0.08926"
"193.43700","16.03601","0.08903"
"193.43900","16.10577","0.08822"
"193.44100","16.17553","0.08643"
"193.44300","16.24529","0.08337"
"193.44500","16.31505","0.08144"
"193.44700","16.38481","0.07959"
"193.44900","16.45456","0.07707"
"193.45100","16.52431","0.07430"
"193.45300","16.59406","0.07216"
"193.45500","16.66381","0.06992"
"193.45700","16.73356","0.06776"
"193.45900","16.80330","0.06690"
"193.46100","16.87305","0.06805"
"193.46300","16.94279","0.06971"
"193.46500","17.01253","0.07004"
"193.46700","17.08227","0.07094"
"193.46900","17.15201","0.07437"
"193.47100","17.22175","0.07910"
"193.47300","17.29150","0.08187"
"193.47500","17.36124","0.08372"
"193.47700","17.43099","0.08669"
"193.47900","17.50075","0.09063"
"193.48100","17.57050","0.09364"
"193.48300","17.64026","0.09531"
"193.48500","17.71001","0.09438"
"193.48700","17.77977","0.09186"
"193.48900","17.84953","0.09086"
"193.49100","17.91928","0.09159"
"193.49300","17.98905","0.09264"
"193.49500","18.05882","0.09354"