File: data/instron/Sample19_Static.is_tcyclic_RawData/Specimen_RawData_1.csv
Strain : Tensile strain (Extension) gauge length,100,mm,Sample 24,,,
,,,,,,
Time,Extension,Load,,,,
(s),(mm),(N),Low Start,Low End,High Start,High End
0,0,0.21669,853,1116,1309,1392
0.2,0.05797,0.34451,,,,
0.4,0.13575,0.67654,,,,
0.6,0.21323,1.33151,,,,
0.8,0.29037,2.41763,,,,
1,0.36772,4.02136,,,,
1.2,0.44521,6.21269,,,,
1.4,0.52232,9.00781,,,,
1.6,0.59979,12.40842,,,,
1.8,0.67686,16.3386,,,,
2,0.75435,20.80752,,,,
2.2,0.8317,25.75628,,,,
2.4,0.90891,30.9798,,,,
2.6,0.98644,36.6052,,,,
2.8,1.06342,42.40112,,,,
3,1.14104,48.45519,,,,
3.2,1.21829,54.52356,,,,
3.4,1.29554,60.58387,,,,
3.549,1.35314,65.02096,,,,
3.551,1.3539,65.07907,,,,
3.751,1.36433,63.28901,,,,
3.951,1.36224,61.59132,,,,
4.151,1.3619,60.54046,,,,
4.351,1.36182,59.76407,,,,
4.551,1.36181,59.1389,,,,
4.751,1.36181,58.61075,,,,
4.951,1.36181,58.1539,,,,
5.151,1.36181,57.75598,,,,
5.351,1.36181,57.3945,,,,
5.551,1.36181,57.06696,,,,
5.751,1.36181,56.77018,,,,
5.951,1.36181,56.50099,,,,
6.151,1.36181,56.24038,,,,
6.351,1.36181,56.00405,,,,
6.551,1.36181,55.78362,,,,
6.751,1.36181,55.57393,,,,
6.951,1.36172,55.37328,,,,
7.151,1.36178,55.1883,,,,
7.351,1.36181,55.0113,,,,
7.551,1.36181,54.8439,,,,
7.751,1.36181,54.68988,,,,
7.951,1.36181,54.51934,,,,
8.151,1.36181,54.38282,,,,
8.351,1.36181,54.24723,,,,
8.551,1.36181,54.1095,,,,
8.751,1.36181,53.98551,,,,
8.951,1.36181,53.85692,,,,
9.151,1.36181,53.73029,,,,
9.351,1.36181,53.60226,,,,
9.551,1.36181,53.49587,,,,
9.751,1.36181,53.3872,,,,
9.951,1.36181,53.27378,,,,
10.151,1.36181,53.17681,,,,
10.351,1.36181,53.0749,,,,
10.551,1.36181,52.97871,,,,
10.751,1.36181,52.88087,,,,
10.951,1.36181,52.78948,,,,
11.151,1.36181,52.69719,,,,
11.351,1.36181,52.61012,,,,
11.551,1.36181,52.51938,,,,
11.751,1.36181,52.43862,,,,
11.951,1.36181,52.34732,,,,
12.151,1.36181,52.27202,,,,
12.351,1.36181,52.2024,,,,
12.551,1.36181,52.1305,,,,
12.751,1.36181,52.04797,,,,
12.951,1.36181,51.97046,,,,
13.151,1.36181,51.90287,,,,
13.351,1.36181,51.82882,,,,
13.551,1.36181,51.76089,,,,
13.751,1.36181,51.69136,,,,
13.951,1.36181,51.62809,,,,
14.151,1.36181,51.56106,,,,
14.351,1.36181,51.49796,,,,
14.551,1.36181,51.44079,,,,
14.751,1.36181,51.37201,,,,
14.951,1.36181,51.30737,,,,
15.151,1.36181,51.24922,,,,
15.351,1.36181,51.20047,,,,
15.551,1.36181,51.13639,,,,
15.751,1.36181,51.06989,,,,
15.951,1.36181,51.02318,,,,
16.151,1.36181,50.96331,,,,
16.351,1.36181,50.91046,,,,
16.551,1.36181,50.85902,,,,
16.751,1.36181,50.8102,,,,
16.951,1.36181,50.75295,,,,
17.151,1.36181,50.70065,,,,
17.351,1.36181,50.65295,,,,
17.551,1.36181,50.60088,,,,
17.751,1.36181,50.55436,,,,
17.951,1.36181,50.51224,,,,
18.151,1.36181,50.46404,,,,
18.351,1.36181,50.41124,,,,
18.551,1.36181,50.3612,,,,
18.751,1.36181,50.31952,,,,
18.951,1.36181,50.27,,,,
19.151,1.36181,50.2327,,,,
19.351,1.36181,50.18467,,,,
19.551,1.36181,50.14173,,,,
19.751,1.36181,50.10555,,,,
19.951,1.36181,50.05954,,,,
20.151,1.36181,50.01939,,,,
20.351,1.36181,49.98642,,,,
20.551,1.36181,49.94364,,,,
20.751,1.36181,49.89411,,,,
20.951,1.36181,49.85017,,,,
21.151,1.36181,49.82061,,,,
21.351,1.36181,49.77485,,,,
21.551,1.36181,49.73751,,,,
21.751,1.36181,49.70141,,,,
21.951,1.36181,49.65966,,,,
22.151,1.36181,49.61834,,,,
22.351,1.36181,49.58311,,,,
22.551,1.36181,49.54768,,,,
22.751,1.36181,49.5065,,,,
22.951,1.36181,49.47258,,,,
23.151,1.36181,49.44398,,,,
23.351,1.36181,49.40262,,,,
23.55,1.36181,49.37219,,,,
23.586,1.36181,49.36649,,,,
23.768,1.30732,41.88135,,,,
23.968,1.22984,32.83153,,,,
24.168,1.15219,25.27575,,,,
24.368,1.07514,18.94263,,,,
24.568,0.99767,13.60292,,,,
24.768,0.92008,9.26028,,,,
24.968,0.84314,5.95159,,,,
25.168,0.76568,3.55651,,,,
25.368,0.68849,1.96514,,,,
25.568,0.61092,0.98559,,,,
25.768,0.53343,0.4735,,,,
25.968,0.45641,0.24969,,,,
26.168,0.37896,0.18057,,,,
26.368,0.30194,0.14798,,,,
26.568,0.22448,0.13087,,,,
26.768,0.14721,0.12886,,,,
26.968,0.06976,0.12083,,,,
27.127,0.00842,0.10976,,,,
27.129,0.00764,0.10942,,,,
27.329,0.05279,0.12583,,,,
27.529,0.13089,0.13912,,,,
27.729,0.20833,0.16858,,,,
27.929,0.28537,0.20555,,,,
28.129,0.36266,0.2901,,,,
28.329,0.44029,0.54701,,,,
28.529,0.51753,1.18281,,,,
28.729,0.59512,2.39532,,,,
28.929,0.67209,4.36345,,,,
29.129,0.74931,7.23487,,,,
29.329,0.82671,11.07542,,,,
29.529,0.90398,15.7475,,,,
29.729,0.98163,21.20645,,,,
29.929,1.05873,27.27851,,,,
30.129,1.13621,33.94099,,,,
30.329,1.21335,40.94646,,,,
30.529,1.29049,48.27048,,,,
30.713,1.36179,55.18726,,,,
30.715,1.36258,55.26469,,,,
30.915,1.37306,54.77537,,,,
31.115,1.37089,53.77557,,,,
31.315,1.37056,53.23263,,,,
31.515,1.37053,52.83273,,,,
31.715,1.37053,52.52623,,,,
31.915,1.37053,52.25909,,,,
32.115,1.37053,52.03991,,,,
32.315,1.37044,51.84184,,,,
32.515,1.37049,51.66717,,,,
32.715,1.3705,51.51392,,,,
32.915,1.3705,51.36995,,,,
33.115,1.37051,51.23419,,,,
33.315,1.37051,51.10824,,,,
33.515,1.37053,50.99812,,,,
33.715,1.37053,50.89917,,,,
33.915,1.37053,50.79628,,,,
34.115,1.37053,50.69556,,,,
34.315,1.37053,50.61095,,,,
34.515,1.37053,50.51378,,,,
34.715,1.37053,50.44604,,,,
34.915,1.37053,50.36414,,,,
35.115,1.37053,50.28388,,,,
35.315,1.37053,50.21729,,,,
35.515,1.37053,50.1443,,,,
35.715,1.37053,50.07609,,,,
35.915,1.37053,50.01475,,,,
36.115,1.37053,49.94952,,,,
36.315,1.37053,49.882,,,,
36.515,1.37053,49.82674,,,,
36.715,1.37053,49.77027,,,,
36.915,1.37053,49.71574,,,,
37.115,1.37053,49.66291,,,,
37.315,1.37053,49.60724,,,,
37.515,1.37053,49.54395,,,,
37.715,1.37053,49.50315,,,,
37.915,1.37053,49.45555,,,,
38.115,1.37053,49.40535,,,,
38.315,1.37053,49.3619,,,,
38.515,1.37053,49.30266,,,,
38.715,1.37053,49.2622,,,,
38.915,1.37053,49.21516,,,,
39.115,1.37053,49.18235,,,,
39.315,1.37053,49.14197,,,,
39.515,1.37053,49.09762,,,,
39.715,1.37053,49.05304,,,,
39.915,1.37053,49.01237,,,,
40.115,1.37053,48.96907,,,,
40.315,1.37053,48.93081,,,,
40.515,1.37053,48.89092,,,,
40.715,1.37053,48.84971,,,,
40.915,1.37053,48.81913,,,,
41.115,1.37053,48.77729,,,,
41.315,1.37053,48.74409,,,,
41.515,1.37053,48.70628,,,,
41.715,1.37053,48.66805,,,,
41.915,1.37053,48.63468,,,,
42.115,1.37053,48.5986,,,,
42.315,1.37053,48.56791,,,,
42.515,1.37053,48.54111,,,,
42.715,1.37053,48.50704,,,,
42.915,1.37053,48.47635,,,,
43.115,1.37053,48.44622,,,,
43.315,1.37053,48.41188,,,,
43.515,1.37053,48.38433,,,,
43.715,1.37053,48.35266,,,,
43.915,1.37053,48.32811,,,,
44.115,1.37053,48.29531,,,,
44.315,1.37053,48.27112,,,,
44.515,1.37053,48.23169,,,,
44.715,1.37053,48.20926,,,,
44.915,1.37053,48.1743,,,,
45.115,1.37053,48.15303,,,,
45.315,1.37053,48.12167,,,,
45.515,1.37053,48.09943,,,,
45.715,1.37053,48.07504,,,,
45.915,1.37053,48.0485,,,,
46.115,1.37053,48.02401,,,,
46.315,1.37053,47.99313,,,,
46.515,1.37053,47.96415,,,,
46.715,1.37053,47.9415,,,,
46.915,1.37053,47.91643,,,,
47.115,1.37053,47.8822,,,,
47.315,1.37053,47.86102,,,,
47.515,1.37053,47.84128,,,,
47.715,1.37053,47.81225,,,,
47.915,1.37053,47.78489,,,,
48.115,1.37053,47.7677,,,,
48.315,1.37053,47.73675,,,,
48.515,1.37053,47.71364,,,,
48.715,1.37053,47.69667,,,,
48.915,1.37053,47.66631,,,,
49.115,1.37053,47.65681,,,,
49.315,1.37053,47.6272,,,,
49.515,1.37053,47.60537,,,,
49.715,1.37053,47.58782,,,,
49.915,1.37053,47.56079,,,,
50.115,1.37053,47.5359,,,,
50.315,1.37053,47.5168,,,,
50.515,1.37053,47.4978,,,,
50.714,1.37053,47.47063,,,,
50.75,1.37053,47.46998,,,,
50.931,1.31641,40.00292,,,,
51.131,1.2388,30.97023,,,,
51.331,1.16122,23.48456,,,,
51.531,1.08415,17.29515,,,,
51.731,1.00683,12.12812,,,,
51.931,0.92915,8.01034,,,,
52.131,0.85209,4.95612,,,,
52.331,0.77456,2.81179,,,,
52.531,0.6974,1.46459,,,,
52.731,0.62001,0.70693,,,,
52.931,0.54258,0.33867,,,,
53.131,0.46561,0.21004,,,,
53.331,0.38804,0.16247,,,,
53.531,0.31081,0.14379,,,,
53.731,0.23335,0.13478,,,,
53.931,0.15607,0.12871,,,,
54.131,0.07897,0.11656,,,,
54.29,0.01736,0.1239,,,,
54.292,0.0166,0.12394,,,,
54.492,0.06173,0.12566,,,,
54.692,0.13976,0.1457,,,,
54.892,0.21747,0.15201,,,,
55.092,0.29466,0.18829,,,,
55.292,0.37208,0.246,,,,
55.492,0.44942,0.3974,,,,
55.692,0.52643,0.8274,,,,
55.892,0.60385,1.75633,,,,
56.092,0.68107,3.40762,,,,
56.292,0.75875,5.96316,,,,
56.492,0.83601,9.51205,,,,
56.692,0.91314,13.9373,,,,
56.892,0.9906,19.20588,,,,
57.092,1.06761,25.13507,,,,
57.292,1.1453,31.71219,,,,
57.492,1.22253,38.68198,,,,
57.692,1.29985,46.01352,,,,
57.875,1.37072,52.97855,,,,
57.877,1.3715,53.05668,,,,
58.077,1.3818,52.67148,,,,
58.277,1.37966,51.76733,,,,
58.477,1.37934,51.27175,,,,
58.677,1.37925,50.92276,,,,
58.877,1.37925,50.65149,,,,
59.077,1.37925,50.4295,,,,
59.277,1.37925,50.2338,,,,
59.477,1.37925,50.06428,,,,
59.677,1.37925,49.9192,,,,
59.877,1.37925,49.77888,,,,
60.077,1.37917,49.65619,,,,
60.277,1.37916,49.54128,,,,
60.477,1.37921,49.43505,,,,
60.677,1.37922,49.34618,,,,
60.877,1.37923,49.26448,,,,
61.077,1.37925,49.17537,,,,
61.277,1.37925,49.09513,,,,
61.477,1.37925,49.0205,,,,
61.677,1.37925,48.95243,,,,
61.877,1.37925,48.88124,,,,
62.077,1.37925,48.81523,,,,
62.277,1.37925,48.7489,,,,
62.477,1.37925,48.69231,,,,
62.677,1.37925,48.63411,,,,
62.877,1.37925,48.58432,,,,
63.077,1.37925,48.52617,,,,
63.277,1.37925,48.47142,,,,
63.477,1.37925,48.42622,,,,
63.677,1.37925,48.37461,,,,
63.877,1.37925,48.33025,,,,
64.077,1.37925,48.28154,,,,
64.277,1.37925,48.23853,,,,
64.477,1.37925,48.19776,,,,
64.677,1.37925,48.15676,,,,
64.877,1.37925,48.1048,,,,
65.077,1.37925,48.06598,,,,
65.277,1.37925,48.03925,,,,
65.477,1.37925,47.99234,,,,
65.677,1.37925,47.95972,,,,
65.877,1.37925,47.92213,,,,
66.077,1.37925,47.8895,,,,
66.277,1.37925,47.8539,,,,
66.477,1.37925,47.81939,,,,
66.677,1.37925,47.78621,,,,
66.877,1.37925,47.75782,,,,
67.077,1.37925,47.71723,,,,
67.277,1.37925,47.69696,,,,
67.477,1.37925,47.66194,,,,
67.677,1.37925,47.63304,,,,
67.877,1.37925,47.60504,,,,
68.077,1.37925,47.57215,,,,
68.277,1.37925,47.54099,,,,
68.477,1.37925,47.5156,,,,
68.677,1.37925,47.49447,,,,
68.877,1.37925,47.45692,,,,
69.077,1.37925,47.43096,,,,
69.277,1.37925,47.4088,,,,
69.477,1.37925,47.38402,,,,
69.677,1.37925,47.35065,,,,
69.877,1.37925,47.33538,,,,
70.077,1.37925,47.30825,,,,
70.277,1.37925,47.28564,,,,
70.477,1.37925,47.25384,,,,
70.677,1.37925,47.22709,,,,
70.877,1.37925,47.20372,,,,
71.077,1.37925,47.18014,,,,
71.277,1.37925,47.15388,,,,
71.477,1.37925,47.13184,,,,
71.677,1.37925,47.10678,,,,
71.877,1.37925,47.09593,,,,
72.077,1.37925,47.07006,,,,
72.277,1.37925,47.04645,,,,
72.477,1.37925,47.0228,,,,
72.677,1.37925,46.99634,,,,
72.877,1.37925,46.97166,,,,
73.077,1.37925,46.94667,,,,
73.277,1.37925,46.9331,,,,
73.477,1.37925,46.91201,,,,
73.677,1.37925,46.8876,,,,
73.877,1.37925,46.86955,,,,
74.077,1.37925,46.84571,,,,
74.277,1.37925,46.81854,,,,
74.477,1.37925,46.80313,,,,
74.677,1.37925,46.7846,,,,
74.877,1.37925,46.76168,,,,
75.077,1.37925,46.74597,,,,
75.277,1.37925,46.73115,,,,
75.477,1.37925,46.70962,,,,
75.677,1.37925,46.68823,,,,
75.877,1.37925,46.66964,,,,
76.077,1.37925,46.65292,,,,
76.277,1.37925,46.63406,,,,
76.477,1.37925,46.61061,,,,
76.677,1.37925,46.60048,,,,
76.877,1.37925,46.57774,,,,
77.077,1.37925,46.5615,,,,
77.277,1.37925,46.53659,,,,
77.477,1.37925,46.52345,,,,
77.677,1.37925,46.50388,,,,
77.876,1.37925,46.48985,,,,
77.903,1.37925,46.48037,,,,
78.085,1.32491,39.0168,,,,
78.285,1.24723,30.03278,,,,
78.485,1.16956,22.59854,,,,
78.685,1.09225,16.46737,,,,
78.885,1.01513,11.43248,,,,
79.085,0.93751,7.42999,,,,
79.285,0.86053,4.50203,,,,
79.485,0.7829,2.47709,,,,
79.685,0.7057,1.25356,,,,
79.885,0.62839,0.59631,,,,
80.085,0.55095,0.30224,,,,
80.285,0.47394,0.19605,,,,
80.485,0.39636,0.16072,,,,
80.685,0.31913,0.14068,,,,
80.885,0.24163,0.13707,,,,
81.085,0.16427,0.13258,,,,
81.285,0.08735,0.13014,,,,
81.443,0.0259,0.12334,,,,
81.445,0.02513,0.12131,,,,
81.645,0.07023,0.13201,,,,
81.845,0.14831,0.14555,,,,
82.045,0.22619,0.15861,,,,
82.245,0.30337,0.17798,,,,
82.445,0.38082,0.22536,,,,
82.645,0.45798,0.35102,,,,
82.755,0.5003,0.50081,,,,
82.757,0.50108,0.50516,,,,
82.777,0.50856,0.52386,,,,
82.797,0.5133,0.55695,,,,
82.817,0.51739,0.56916,,,,
82.837,0.5207,0.60285,,,,
82.857,0.52645,0.64971,,,,
82.877,0.53535,0.70667,,,,
82.897,0.54524,0.76882,,,,
82.917,0.55446,0.83947,,,,
82.937,0.56282,0.91917,,,,
82.957,0.57089,0.9953,,,,
82.977,0.57904,1.07814,,,,
82.997,0.5871,1.17068,,,,
83.017,0.59482,1.26209,,,,
83.037,0.60233,1.36027,,,,
83.057,0.61003,1.46444,,,,
83.077,0.61797,1.57845,,,,
83.097,0.62589,1.6974,,,,
83.117,0.6336,1.82519,,,,
83.137,0.64116,1.95737,,,,
83.157,0.64888,2.10333,,,,
83.177,0.6567,2.25414,,,,
83.197,0.66445,2.40611,,,,
83.217,0.67207,2.55871,,,,
83.237,0.67966,2.74048,,,,
83.257,0.68741,2.92848,,,,
83.277,0.69527,3.1213,,,,
83.297,0.70302,3.31772,,,,
83.317,0.71066,3.5245,,,,
83.337,0.71838,3.73954,,,,
83.357,0.72615,3.97534,,,,
83.377,0.73385,4.21402,,,,
83.397,0.7415,4.45426,,,,
83.417,0.74928,4.70903,,,,
83.437,0.75729,4.99184,,,,
83.457,0.76519,5.28212,,,,
83.477,0.77282,5.57146,,,,
83.497,0.78036,5.86635,,,,
83.517,0.78809,6.17118,,,,
83.537,0.79601,6.50008,,,,
83.557,0.80379,6.83182,,,,
83.577,0.81136,7.16626,,,,
83.597,0.8189,7.51914,,,,
83.617,0.82668,7.88092,,,,
83.637,0.83457,8.26565,,,,
83.657,0.84233,8.64866,,,,
83.677,0.84988,9.02367,,,,
83.697,0.85745,9.41596,,,,
83.717,0.86528,9.82664,,,,
83.737,0.87315,10.25022,,,,
83.757,0.88085,10.6756,,,,
83.777,0.88843,11.09995,,,,
83.797,0.89611,11.54353,,,,
83.817,0.90394,12.0064,,,,
83.837,0.91172,12.46544,,,,
83.857,0.91937,12.92515,,,,
83.877,0.92703,13.39759,,,,
83.897,0.93489,13.89627,,,,
83.917,0.94283,14.40789,,,,
83.937,0.95062,14.90806,,,,
83.957,0.95828,15.40102,,,,
83.977,0.96601,15.91848,,,,
83.997,0.97385,16.46361,,,,
84.017,0.9816,17.00464,,,,
84.037,0.9892,17.53211,,,,
84.057,0.99679,18.06231,,,,
84.077,1.00461,18.619,,,,
84.097,1.01251,19.19321,,,,
84.117,1.02019,19.7576,,,,
84.137,1.02776,20.32585,,,,
84.157,1.0354,20.89889,,,,
84.177,1.04323,21.49569,,,,
84.197,1.05107,22.09749,,,,
84.217,1.05868,22.69571,,,,
84.237,1.06621,23.30075,,,,
84.257,1.07394,23.9231,,,,
84.277,1.08183,24.56071,,,,
84.297,1.08964,25.19422,,,,
84.317,1.09726,25.81211,,,,
84.337,1.1048,26.43449,,,,
84.357,1.11258,27.09232,,,,
84.377,1.12052,27.76502,,,,
84.397,1.12841,28.42952,,,,
84.417,1.13615,29.08298,,,,
84.437,1.14387,29.74917,,,,
84.457,1.15167,30.43192,,,,
84.477,1.15944,31.10868,,,,
84.497,1.16709,31.7773,,,,
84.517,1.17472,32.44818,,,,
84.537,1.18248,33.13341,,,,
84.557,1.19031,33.83772,,,,
84.577,1.19807,34.53683,,,,
84.597,1.20568,35.22095,,,,
84.617,1.2133,35.90882,,,,
84.637,1.22107,36.62455,,,,
84.657,1.22884,37.34845,,,,
84.677,1.2365,38.06177,,,,
84.697,1.24408,38.76249,,,,
84.717,1.25182,39.48816,,,,
84.737,1.2597,40.23591,,,,
84.757,1.26745,40.9674,,,,
84.777,1.27504,41.67941,,,,
84.797,1.28261,42.39075,,,,
84.817,1.29044,43.13256,,,,
84.837,1.29841,43.90335,,,,
84.857,1.30616,44.64473,,,,
84.877,1.31375,45.36945,,,,
84.897,1.3215,46.12702,,,,
84.917,1.32948,46.90432,,,,
84.937,1.33738,47.67505,,,,
84.957,1.345,48.42033,,,,
84.977,1.35249,49.16002,,,,
84.997,1.3602,49.92933,,,,
85.017,1.3681,50.72932,,,,
85.037,1.37593,51.51593,,,,
85.057,1.38353,52.27496,,,,
85.077,1.39104,53.0239,,,,
85.097,1.39879,53.81094,,,,
85.117,1.40667,54.6163,,,,
85.137,1.41446,55.39593,,,,
85.157,1.42212,56.15462,,,,
85.177,1.42973,56.90941,,,,
85.197,1.43746,57.68443,,,,
85.217,1.44526,58.45854,,,,
85.237,1.45293,59.20433,,,,
85.257,1.46054,59.94394,,,,
85.277,1.4683,60.71761,,,,
85.297,1.47614,61.49913,,,,
85.317,1.48389,62.25461,,,,
85.337,1.49154,62.99056,,,,
85.357,1.49929,63.73306,,,,
85.377,1.50725,64.51553,,,,
85.397,1.51516,65.28419,,,,
85.417,1.52284,66.01132,,,,
85.437,1.53037,66.71139,,,,
85.457,1.53811,67.43301,,,,
85.477,1.54603,68.17037,,,,
85.497,1.55379,68.89969,,,,
85.517,1.56136,69.5963,,,,
85.537,1.56893,70.26905,,,,
85.557,1.57673,70.96642,,,,
85.577,1.58466,71.67408,,,,
85.597,1.59239,72.35944,,,,
85.617,1.5999,73.01643,,,,
85.637,1.60746,73.67197,,,,
85.657,1.61531,74.34573,,,,
85.677,1.62324,75.00799,,,,
85.697,1.63094,75.65109,,,,
85.717,1.6384,76.27966,,,,
85.737,1.64602,76.91801,,,,
85.757,1.65389,77.57164,,,,
85.777,1.66177,78.20295,,,,
85.797,1.66948,78.80861,,,,
85.817,1.67707,79.40241,,,,
85.837,1.68486,80.02351,,,,
85.857,1.6928,80.66734,,,,
85.877,1.70066,81.27299,,,,
85.897,1.70834,81.83772,,,,
85.917,1.716,82.41643,,,,
85.937,1.7238,83.00805,,,,
85.957,1.73158,83.5838,,,,
85.977,1.73923,84.13084,,,,
85.997,1.74686,84.67587,,,,
86.017,1.75467,85.25799,,,,
86.037,1.76249,85.84296,,,,
86.057,1.77012,86.39092,,,,
86.077,1.77767,86.90884,,,,
86.097,1.78534,87.44003,,,,
86.117,1.79324,88.00307,,,,
86.137,1.80109,88.55847,,,,
86.157,1.80867,89.07139,,,,
86.177,1.81618,89.56053,,,,
86.197,1.82393,90.07886,,,,
86.217,1.83186,90.61252,,,,
86.237,1.83969,91.13511,,,,
86.257,1.84727,91.62755,,,,
86.277,1.85479,92.10264,,,,
86.297,1.86259,92.61147,,,,
86.317,1.87059,93.14082,,,,
86.337,1.8785,93.64101,,,,
86.357,1.88616,94.11819,,,,
86.377,1.8938,94.60026,,,,
86.397,1.90159,95.08659,,,,
86.417,1.90942,95.56092,,,,
86.437,1.91714,96.01561,,,,
86.457,1.92472,96.46143,,,,
86.477,1.93238,96.92541,,,,
86.497,1.94015,97.39101,,,,
86.517,1.94793,97.854,,,,
86.537,1.95562,98.28709,,,,
86.557,1.9633,98.72021,,,,
86.577,1.97105,99.17199,,,,
86.597,1.97878,99.61283,,,,
86.617,1.98644,100.01655,,,,
86.637,1.99408,100.40406,,,,
86.657,2.00187,100.81267,,,,
86.677,2.00971,101.23629,,,,
86.697,2.01743,101.64956,,,,
86.717,2.02502,102.02855,,,,
86.737,2.03263,102.38957,,,,
86.757,2.04052,102.77859,,,,
86.773,2.0469,103.10018,,,,
86.775,2.04769,103.13883,,,,
86.936,2.01865,94.46618,,,,
87.092,1.95682,84.41805,,,,
87.273,1.88645,74.35823,,,,
87.472,1.80965,64.45193,,,,
87.672,1.73214,55.35973,,,,
87.872,1.65493,47.08988,,,,
88.072,1.57784,39.50302,,,,
88.272,1.50019,32.48851,,,,
88.472,1.42313,26.14599,,,,
88.672,1.34561,20.38071,,,,
88.872,1.26838,15.32576,,,,
89.072,1.19105,10.99454,,,,
89.272,1.11346,7.43517,,,,
89.472,1.03651,4.71106,,,,
89.672,0.95902,2.72634,,,,
89.872,0.88186,1.46775,,,,
90.072,0.80444,0.72992,,,,
90.272,0.72707,0.3823,,,,
90.472,0.64994,0.2347,,,,
90.672,0.57245,0.18513,,,,
90.859,0.50029,0.16305,,,,
90.861,0.4995,0.16269,,,,
91.061,0.54432,0.20954,,,,
91.261,0.62267,0.32305,,,,
91.39,0.67246,0.50053,,,,
91.392,0.67322,0.50566,,,,
91.394,0.67398,0.51091,,,,
91.396,0.67474,0.51876,,,,
91.398,0.67553,0.53541,,,,
91.4,0.67641,0.56269,,,,
91.402,0.67745,0.59797,,,,
91.404,0.67875,0.6401,,,,
91.406,0.68043,0.6908,,,,
91.408,0.68262,0.74997,,,,
91.41,0.68545,0.81705,,,,
91.412,0.68905,0.89603,,,,
91.414,0.69358,0.9898,,,,
91.416,0.69916,1.10072,,,,
91.418,0.70594,1.23322,,,,
91.42,0.71406,1.39578,,,,
91.422,0.72363,1.59679,,,,
91.424,0.73478,1.846,,,,
91.426,0.74762,2.15707,,,,
91.428,0.76226,2.54746,,,,
91.43,0.77879,3.03524,,,,
91.432,0.79731,3.64014,,,,
91.434,0.8179,4.38494,,,,
91.436,0.84062,5.29326,,,,
91.438,0.86554,6.38757,,,,
91.44,0.89272,7.68975,,,,
91.442,0.92221,9.22266,,,,
91.444,0.95405,11.00682,,,,
91.446,0.98828,13.06003,,,,
91.448,1.02492,15.39765,,,,
91.45,1.06399,18.03129,,,,
91.452,1.10547,20.9716,,,,
91.454,1.14934,24.22701,,,,
91.456,1.19559,27.80199,,,,
91.458,1.24416,31.69864,,,,
91.46,1.29501,35.91908,,,,
91.462,1.34809,40.46125,,,,
91.464,1.40335,45.31648,,,,
91.466,1.46076,50.46693,,,,
91.468,1.52028,55.8875,,,,
91.47,1.58187,61.5401,,,,
91.472,1.6455,67.36622,,,,
91.474,1.7111,73.29006,,,,
91.476,1.77856,79.23083,,,,
91.478,1.84771,85.11568,,,,
91.48,1.91837,90.88662,,,,
91.482,1.99033,96.4985,,,,
91.484,2.0634,101.91496,,,,
91.486,2.13737,107.10704,,,,
91.488,2.21207,112.05214,,,,
91.49,2.28734,116.73081,,,,
91.492,2.36305,121.12323,,,,
91.494,2.43909,125.2217,,,,
91.496,2.51538,129.04865,,,,
91.498,2.59185,132.64438,,,,
91.5,2.66846,136.04503,,,,
91.502,2.74518,139.27617,,,,
91.504,2.82199,142.35732,,,,
91.506,2.89889,145.30646,,,,
91.508,2.97587,148.13728,,,,
91.51,3.05295,150.85861,,,,
91.512,3.13012,153.48064,,,,
91.514,3.20739,156.01472,,,,
91.516,3.28477,158.47098,,,,
91.518,3.36225,160.85841,,,,
91.52,3.43983,163.18874,,,,
91.522,3.51753,165.47096,,,,
91.524,3.59532,167.71027,,,,
91.526,3.67322,169.91333,,,,
91.528,3.75121,172.09001,,,,
91.53,3.82927,174.24243,,,,
91.532,3.90741,176.3658,,,,
91.534,3.98561,178.45761,,,,
91.536,4.06385,180.51672,,,,
91.538,4.14213,182.54057,,,,
91.54,4.22042,184.52834,,,,
91.542,4.29872,186.47914,,,,
91.544,4.37702,188.3887,,,,
91.546,4.4553,190.25226,,,,
91.548,4.53357,192.06543,,,,
91.55,4.61181,193.82271,,,,
91.552,4.69001,195.51833,,,,
91.554,4.76818,197.14124,,,,
91.556,4.84631,198.67841,,,,
91.558,4.92439,199.91115,,,,
91.56,5.00243,199.51164,,,,
91.562,5.08042,196.49187,,,,
91.564,5.15836,191.03326,,,,
91.566,5.23627,183.6649,,,,
91.568,5.31415,174.84129,,,,
91.57,5.392,164.93277,,,,
91.572,5.46982,154.25232,,,,
91.574,5.54762,143.07906,,,,
91.576,5.62539,131.65692,,,,
91.578,5.70315,120.19518,,,,
91.58,5.78088,108.87029,,,,
91.582,5.85859,97.82186,,,,
91.584,5.93629,87.1618,,,,
91.586,6.01397,76.98071,,,,
91.588,6.09163,67.34817,,,,
91.59,6.16928,58.3101,,,,
91.592,6.24692,49.8987,,,,
91.594,6.32454,42.13739,,,,
91.596,6.40215,35.0374,,,,
91.598,6.47974,28.59349,,,,
91.6,6.55732,22.78994,,,,
91.602,6.63488,17.60773,,,,
91.604,6.71243,13.02229,,,,
91.606,6.78997,9.00162,,,,
91.608,6.86749,5.50679,,,,
91.61,6.945,2.49913,,,,
91.612,7.02249,-0.05709,,,,
91.614,7.09997,-2.19558,,,,
91.616,7.17743,-3.95144,,,,
91.618,7.25488,-5.36121,,,,
91.62,7.33232,-6.46149,,,,
91.622,7.40974,-7.28874,,,,
91.624,7.48716,-7.87459,,,,
91.626,7.56456,-8.24771,,,,
91.628,7.64196,-8.4362,,,,
91.63,7.71935,-8.46819,,,,
91.632,7.79674,-8.36975,,,,
91.634,7.87411,-8.16371,,,,
91.636,7.95148,-7.86831,,,,
91.638,8.02885,-7.5043,,,,
91.64,8.1062,-7.08775,,,,
91.642,8.18355,-6.63276,,,,
91.644,8.2609,-6.15289,,,,
91.646,8.33824,-5.66101,,,,
91.648,8.41558,-5.16625,,,,
91.65,8.49291,-4.67608,,,,
91.652,8.57024,-4.19652,,,,
91.654,8.64757,-3.73359,,,,
91.656,8.72489,-3.29252,,,,
91.658,8.80221,-2.87305,,,,
91.66,8.87953,-2.47469,,,,
91.662,8.95685,-2.10161,,,,
91.664,9.03417,-1.75673,,,,
91.666,9.1115,-1.43944,,,,
91.668,9.18883,-1.1482,,,,
91.67,9.26616,-0.88407,,,,
91.672,9.34349,-0.64795,,,,
91.674,9.42082,-0.43832,,,,
91.676,9.49816,-0.25433,,,,
91.678,9.57549,-0.09615,,,,
91.68,9.65283,0.03709,,,,
91.682,9.73017,0.14894,,,,
91.684,9.80751,0.24298,,,,
91.686,9.88485,0.32019,,,,
91.688,9.96219,0.38297,,,,
91.69,10.03953,0.43265,,,,
91.692,10.11687,0.47039,,,,
91.694,10.1942,0.49676,,,,
91.696,10.27153,0.51374,,,,
91.698,10.34887,0.52458,,,,
91.7,10.4262,0.52999,,,,
91.702,10.50354,0.52984,,,,
91.704,10.58087,0.52551,,,,
91.706,10.6582,0.51792,,,,
91.708,10.73554,0.50685,,,,
91.71,10.81287,0.49252,,,,
91.712,10.8902,0.47579,,,,
91.714,10.96752,0.45562,,,,
91.716,11.04484,0.43192,,,,
91.718,11.12217,0.40952,,,,
91.72,11.19949,0.38845,,,,
91.722,11.27681,0.36513,,,,
91.724,11.35413,0.34048,,,,
91.726,11.43146,0.32048,,,,
91.728,11.50879,0.30523,,,,
91.73,11.58612,0.29042,,,,
91.732,11.66345,0.27678,,,,
91.734,11.74078,0.26515,,,,
91.736,11.81811,0.25418,,,,
91.738,11.89544,0.24192,,,,
91.74,11.97278,0.22857,,,,
91.742,12.05012,0.21538,,,,
91.744,12.12746,0.20405,,,,
91.746,12.20479,0.19495,,,,
91.748,12.28213,0.18612,,,,
91.75,12.35947,0.17699,,,,
91.752,12.43681,0.16848,,,,
91.754,12.51414,0.16114,,,,
91.756,12.59147,0.15528,,,,
91.758,12.6688,0.15091,,,,
91.76,12.74613,0.14659,,,,
91.762,12.82345,0.14356,,,,
91.764,12.90078,0.14224,,,,
91.766,12.97811,0.14276,,,,
91.768,13.05543,0.14387,,,,
91.77,13.13275,0.14446,,,,
91.772,13.21007,0.14561,,,,
91.774,13.28739,0.14709,,,,
91.776,13.3647,0.14862,,,,
91.778,13.44201,0.15132,,,,
91.78,13.51932,0.15156,,,,
91.782,13.59663,0.1479,,,,
91.784,13.67393,0.1438,,,,
91.786,13.75124,0.14277,,,,
91.788,13.82854,0.14308,,,,
91.79,13.90584,0.14273,,,,
91.792,13.98315,0.14438,,,,
91.794,14.06046,0.14905,,,,
91.796,14.13776,0.15393,,,,
91.798,14.21508,0.15581,,,,
91.8,14.2924,0.15605,,,,
91.802,14.36972,0.15792,,,,
91.804,14.44705,0.16223,,,,
91.806,14.52437,0.16616,,,,
91.808,14.6017,0.16648,,,,
91.81,14.67903,0.16397,,,,
91.812,14.75636,0.16185,,,,
91.814,14.83369,0.16116,,,,
91.816,14.91102,0.1603,,,,
91.818,14.98835,0.15855,,,,
91.82,15.06568,0.1567,,,,
91.822,15.14301,0.15631,,,,
91.824,15.22034,0.15755,,,,
91.826,15.29766,0.15879,,,,
91.828,15.37498,0.15798,,,,
91.83,15.45231,0.15571,,,,
91.832,15.52963,0.15573,,,,
91.834,15.60695,0.15952,,,,
91.836,15.68427,0.16218,,,,
91.838,15.76159,0.16116,,,,
91.84,15.83891,0.15945,,,,
91.842,15.91624,0.15908,,,,
91.844,15.99356,0.15897,,,,
91.846,16.07088,0.15779,,,,
91.848,16.1482,0.1551,,,,
91.85,16.22552,0.15239,,,,
91.852,16.30284,0.15092,,,,
91.854,16.38016,0.14863,,,,
91.856,16.45748,0.14648,,,,
91.858,16.5348,0.14748,,,,
91.86,16.61213,0.15042,,,,
91.862,16.68946,0.15222,,,,
91.864,16.76679,0.15361,,,,
91.866,16.84413,0.15627,,,,
91.868,16.92146,0.15813,,,,
91.87,16.99879,0.15817,,,,
91.872,17.07613,0.15658,,,,
91.874,17.15346,0.15629,,,,
91.876,17.23079,0.15705,,,,
91.878,17.30813,0.15798,,,,
91.88,17.38546,0.15935,,,,
91.882,17.4628,0.16083,,,,
91.884,17.54013,0.16188,,,,
91.886,17.61747,0.16251,,,,
91.888,17.6948,0.16277,,,,
91.89,17.77212,0.16251,,,,
91.892,17.84945,0.161,,,,
91.894,17.92677,0.15911,,,,
91.896,18.0041,0.15835,,,,
91.898,18.08143,0.15892,,,,
91.9,18.15876,0.16046,,,,
91.902,18.23609,0.16157,,,,
91.904,18.31342,0.16133,,,,
91.906,18.39074,0.1597,,,,
91.908,18.46806,0.15933,,,,
91.91,18.54537,0.16095,,,,
91.912,18.62268,0.16168,,,,
91.914,18.7,0.15996,,,,
91.916,18.7773,0.15811,,,,
91.918,18.8546,0.15759,,,,
91.92,18.93191,0.15602,,,,
91.922,19.00921,0.15262,,,,
91.924,19.08652,0.15103,,,,
91.926,19.16382,0.15158,,,,
91.928,19.24113,0.15156,,,,
91.93,19.31844,0.15005,,,,
91.932,19.39574,0.1485,,,,
91.934,19.47306,0.14719,,,,
91.936,19.55037,0.14538,,,,
91.938,19.62769,0.14481,,,,
91.94,19.70501,0.14558,,,,
91.942,19.78233,0.14697,,,,
91.944,19.85965,0.14837,,,,
91.946,19.93697,0.14851,,,,
91.948,20.01428,0.14864,,,,