File: data/control/S1/raw_data.csv
Strain : Tensile strain (Extension) gauge length,100,mm,,,,
,,,,,,
Time,Extension,Load,,,,
(s),(mm),(N),Low Start,Low End,High Start,High End
0,0,0.23581,5,400,462,483
0.01,0,0.23727,,,,
0.02,0.00008,0.24146,,,,
0.03,0.00036,0.24508,,,,
0.04,0.00108,0.25528,,,,
0.05,0.00245,0.25473,,,,
0.06,0.00383,0.26011,,,,
0.07,0.00509,0.26842,,,,
0.08,0.00645,0.284,,,,
0.09,0.00836,0.29888,,,,
0.1,0.01119,0.31535,,,,
0.11,0.01497,0.33798,,,,
0.12,0.01947,0.36514,,,,
0.13,0.0243,0.39461,,,,
0.14,0.02913,0.42958,,,,
0.15,0.03372,0.46241,,,,
0.16,0.03799,0.49211,,,,
0.17,0.04194,0.51963,,,,
0.18,0.04565,0.54575,,,,
0.19,0.0492,0.57094,,,,
0.2,0.05269,0.59988,,,,
0.21,0.05621,0.62933,,,,
0.22,0.05977,0.6583,,,,
0.23,0.06337,0.6893,,,,
0.24,0.06697,0.72163,,,,
0.25,0.07054,0.75193,,,,
0.26,0.07404,0.78719,,,,
0.27,0.07748,0.81879,,,,
0.28,0.08088,0.84851,,,,
0.29,0.08425,0.88382,,,,
0.3,0.08763,0.91801,,,,
0.31,0.09107,0.95462,,,,
0.32,0.09458,0.98939,,,,
0.33,0.09814,1.02656,,,,
0.34,0.10171,1.06339,,,,
0.35,0.10527,1.10146,,,,
0.36,0.10877,1.14403,,,,
0.37,0.1122,1.18565,,,,
0.38,0.11559,1.22853,,,,
0.39,0.11893,1.26908,,,,
0.4,0.12228,1.30928,,,,
0.41,0.12567,1.35004,,,,
0.42,0.12913,1.39322,,,,
0.43,0.13265,1.44191,,,,
0.44,0.13619,1.49164,,,,
0.45,0.13973,1.54439,,,,
0.46,0.14324,1.59781,,,,
0.47,0.14672,1.64944,,,,
0.48,0.15017,1.69699,,,,
0.49,0.15359,1.74363,,,,
0.5,0.15699,1.79302,,,,
0.51,0.16038,1.8437,,,,
0.52,0.16381,1.89728,,,,
0.53,0.1673,1.95489,,,,
0.54,0.17082,2.01345,,,,
0.55,0.17436,2.07539,,,,
0.56,0.17787,2.13884,,,,
0.57,0.18135,2.19753,,,,
0.58,0.1848,2.25624,,,,
0.59,0.18821,2.31763,,,,
0.6,0.1916,2.38048,,,,
0.61,0.19498,2.44619,,,,
0.62,0.19839,2.51559,,,,
0.63,0.20187,2.58279,,,,
0.64,0.2054,2.65049,,,,
0.65,0.20894,2.72043,,,,
0.66,0.21248,2.79134,,,,
0.67,0.21599,2.86415,,,,
0.68,0.21948,2.93669,,,,
0.69,0.22293,3.00807,,,,
0.7,0.22637,3.08257,,,,
0.71,0.22981,3.15584,,,,
0.72,0.23328,3.22852,,,,
0.73,0.23679,3.30884,,,,
0.74,0.24032,3.39058,,,,
0.75,0.24385,3.47189,,,,
0.76,0.24735,3.55683,,,,
0.77,0.2508,3.64678,,,,
0.78,0.25421,3.73123,,,,
0.79,0.2576,3.81535,,,,
0.8,0.26098,3.90148,,,,
0.81,0.26438,3.98454,,,,
0.82,0.26782,4.07013,,,,
0.83,0.27131,4.16163,,,,
0.84,0.27485,4.25574,,,,
0.85,0.27839,4.34972,,,,
0.86,0.2819,4.44633,,,,
0.87,0.28535,4.54405,,,,
0.88,0.28874,4.63979,,,,
0.89,0.29212,4.73518,,,,
0.9,0.2955,4.83206,,,,
0.91,0.29888,4.92541,,,,
0.92,0.3023,5.02174,,,,
0.93,0.30578,5.12563,,,,
0.94,0.30931,5.23153,,,,
0.95,0.31285,5.34011,,,,
0.96,0.31637,5.45222,,,,
0.97,0.31985,5.56398,,,,
0.98,0.32327,5.676,,,,
0.99,0.32665,5.78779,,,,
1,0.33001,5.90264,,,,
1.01,0.33337,6.01825,,,,
1.02,0.33676,6.13167,,,,
1.03,0.34023,6.25174,,,,
1.04,0.34376,6.37331,,,,
1.05,0.34733,6.49496,,,,
1.06,0.35092,6.61706,,,,
1.07,0.3545,6.74222,,,,
1.08,0.35801,6.86881,,,,
1.09,0.36145,6.99505,,,,
1.1,0.36482,7.11971,,,,
1.11,0.36815,7.24451,,,,
1.12,0.37148,7.37046,,,,
1.13,0.37486,7.50158,,,,
1.14,0.37832,7.63594,,,,
1.15,0.38185,7.77181,,,,
1.16,0.38542,7.9103,,,,
1.17,0.389,8.05219,,,,
1.18,0.39256,8.19343,,,,
1.19,0.39608,8.33329,,,,
1.2,0.39956,8.47317,,,,
1.21,0.40298,8.61002,,,,
1.22,0.40637,8.74702,,,,
1.23,0.40975,8.88887,,,,
1.24,0.41318,9.03415,,,,
1.25,0.41666,9.1867,,,,
1.26,0.42018,9.33997,,,,
1.27,0.42371,9.49363,,,,
1.28,0.42723,9.64655,,,,
1.29,0.43073,9.79652,,,,
1.3,0.4342,9.94384,,,,
1.31,0.43763,10.09384,,,,
1.32,0.44102,10.24842,,,,
1.33,0.44442,10.4064,,,,
1.34,0.44784,10.56709,,,,
1.35,0.4513,10.72806,,,,
1.36,0.45478,10.89417,,,,
1.37,0.45829,11.06233,,,,
1.38,0.4618,11.23275,,,,
1.39,0.4653,11.39862,,,,
1.4,0.46879,11.55896,,,,
1.41,0.47225,11.72026,,,,
1.42,0.47567,11.8863,,,,
1.43,0.4791,12.05546,,,,
1.44,0.48254,12.2277,,,,
1.45,0.486,12.40403,,,,
1.46,0.48948,12.58325,,,,
1.47,0.49295,12.76188,,,,
1.48,0.49641,12.94056,,,,
1.49,0.49984,13.11796,,,,
1.5,0.50325,13.29331,,,,
1.51,0.50665,13.47077,,,,
1.52,0.51005,13.64904,,,,
1.53,0.51347,13.82713,,,,
1.54,0.51693,14.00658,,,,
1.55,0.52044,14.19411,,,,
1.56,0.52398,14.3828,,,,
1.57,0.52751,14.57099,,,,
1.58,0.53101,14.76211,,,,
1.59,0.53447,14.95285,,,,
1.6,0.53789,15.14142,,,,
1.61,0.54129,15.33131,,,,
1.62,0.54467,15.51871,,,,
1.63,0.54805,15.70107,,,,
1.64,0.55147,15.88841,,,,
1.65,0.55497,16.08714,,,,
1.66,0.55854,16.29309,,,,
1.67,0.56214,16.49776,,,,
1.68,0.56571,16.70409,,,,
1.69,0.56921,16.90502,,,,
1.7,0.57264,17.10452,,,,
1.71,0.57604,17.30414,,,,
1.72,0.57943,17.50469,,,,
1.73,0.58281,17.7057,,,,
1.74,0.58622,17.90956,,,,
1.75,0.58968,18.11835,,,,
1.76,0.59321,18.33135,,,,
1.77,0.59678,18.54989,,,,
1.78,0.60036,18.76737,,,,
1.79,0.60391,18.98364,,,,
1.8,0.6074,19.19719,,,,
1.81,0.61083,19.41119,,,,
1.82,0.61421,19.62499,,,,
1.83,0.61756,19.83901,,,,
1.84,0.6209,20.05123,,,,
1.85,0.62427,20.26891,,,,
1.86,0.62772,20.48988,,,,
1.87,0.63124,20.71723,,,,
1.88,0.63481,20.95115,,,,
1.89,0.6384,21.18765,,,,
1.9,0.64197,21.41893,,,,
1.91,0.64548,21.64727,,,,
1.92,0.64892,21.87164,,,,
1.93,0.6523,22.09481,,,,
1.94,0.65563,22.3163,,,,
1.95,0.65897,22.53968,,,,
1.96,0.66234,22.76867,,,,
1.97,0.66579,23.00507,,,,
1.98,0.6693,23.24725,,,,
1.99,0.67283,23.49076,,,,
2,0.67635,23.73204,,,,
2.01,0.67986,23.97126,,,,
2.02,0.68334,24.21312,,,,
2.03,0.68678,24.45344,,,,
2.04,0.69019,24.68759,,,,
2.05,0.69358,24.92586,,,,
2.06,0.69697,25.16966,,,,
2.07,0.70041,25.41911,,,,
2.08,0.7039,25.67516,,,,
2.09,0.7074,25.93431,,,,
2.1,0.7109,26.19183,,,,
2.11,0.71439,26.44663,,,,
2.12,0.71786,26.69791,,,,
2.13,0.7213,26.94499,,,,
2.14,0.72471,27.18914,,,,
2.15,0.72812,27.43479,,,,
2.16,0.73155,27.68579,,,,
2.17,0.73501,27.94425,,,,
2.18,0.7385,28.20692,,,,
2.19,0.742,28.47091,,,,
2.2,0.7455,28.73856,,,,
2.21,0.74898,29.00902,,,,
2.22,0.75242,29.2673,,,,
2.23,0.75586,29.52182,,,,
2.24,0.75928,29.77555,,,,
2.25,0.76271,30.02548,,,,
2.26,0.76617,30.27839,,,,
2.27,0.7697,30.54554,,,,
2.28,0.7733,30.82231,,,,
2.29,0.7769,31.10906,,,,
2.3,0.78048,31.39311,,,,
2.31,0.78398,31.67007,,,,
2.32,0.78742,31.93883,,,,
2.33,0.7908,32.20946,,,,
2.34,0.79415,32.47058,,,,
2.35,0.7975,32.72501,,,,
2.36,0.80089,32.98497,,,,
2.37,0.80435,33.25759,,,,
2.38,0.80788,33.53337,,,,
2.39,0.81147,33.81796,,,,
2.4,0.81504,34.10966,,,,
2.41,0.81856,34.39498,,,,
2.42,0.82201,34.67135,,,,
2.43,0.8254,34.94889,,,,
2.44,0.82877,35.22453,,,,
2.45,0.83212,35.49697,,,,
2.46,0.83549,35.77086,,,,
2.47,0.83891,36.0455,,,,
2.48,0.8424,36.32533,,,,
2.49,0.84595,36.61349,,,,
2.5,0.84953,36.90876,,,,
2.51,0.85309,37.20397,,,,
2.52,0.8566,37.49627,,,,
2.53,0.86003,37.78267,,,,
2.54,0.8634,38.06384,,,,
2.55,0.86673,38.33966,,,,
2.56,0.87005,38.61569,,,,
2.57,0.87341,38.89345,,,,
2.58,0.87683,39.1753,,,,
2.59,0.88035,39.46487,,,,
2.6,0.88392,39.75941,,,,
2.61,0.8875,40.05313,,,,
2.62,0.89106,40.34616,,,,
2.63,0.89457,40.63859,,,,
2.64,0.89803,40.92783,,,,
2.65,0.90143,41.21768,,,,
2.66,0.90478,41.50203,,,,
2.67,0.90813,41.78857,,,,
2.68,0.9115,42.08057,,,,
2.69,0.91493,42.37701,,,,
2.7,0.91842,42.67934,,,,
2.71,0.92196,42.98535,,,,
2.72,0.92549,43.2896,,,,
2.73,0.92901,43.59081,,,,
2.74,0.93249,43.88948,,,,
2.75,0.93593,44.18242,,,,
2.76,0.93934,44.47178,,,,
2.77,0.94273,44.76958,,,,
2.78,0.94614,45.07813,,,,
2.79,0.9496,45.38681,,,,
2.8,0.95312,45.69854,,,,
2.81,0.95668,46.01773,,,,
2.82,0.96024,46.33501,,,,
2.83,0.96377,46.64552,,,,
2.84,0.96727,46.95421,,,,
2.85,0.97075,47.25658,,,,
2.86,0.9742,47.55165,,,,
2.87,0.97764,47.85394,,,,
2.88,0.98108,48.1573,,,,
2.89,0.98456,48.46508,,,,
2.9,0.98806,48.78384,,,,
2.91,0.99158,49.11146,,,,
2.92,0.99509,49.42865,,,,
2.93,0.99857,49.73904,,,,
2.94,1.002,50.04106,,,,
2.95,1.0054,50.34045,,,,
2.96,1.00879,50.63469,,,,
2.97,1.01217,50.9306,,,,
2.98,1.01557,51.23093,,,,
2.99,1.01902,51.53768,,,,
3,1.02252,51.85606,,,,
3.01,1.02605,52.18082,,,,
3.02,1.02955,52.50669,,,,
3.03,1.03302,52.82914,,,,
3.04,1.03645,53.14548,,,,
3.05,1.03986,53.45805,,,,
3.06,1.04326,53.76789,,,,
3.07,1.04666,54.07291,,,,
3.08,1.05008,54.37546,,,,
3.09,1.05352,54.68283,,,,
3.1,1.05702,54.99783,,,,
3.11,1.06057,55.32053,,,,
3.12,1.06412,55.64643,,,,
3.13,1.06765,55.9715,,,,
3.14,1.07111,56.29164,,,,
3.15,1.07452,56.60517,,,,
3.16,1.07789,56.91456,,,,
3.17,1.08125,57.2241,,,,
3.18,1.08462,57.5323,,,,
3.19,1.08803,57.84611,,,,
3.2,1.09151,58.16626,,,,
3.21,1.09505,58.48861,,,,
3.22,1.09862,58.81395,,,,
3.23,1.10219,59.13621,,,,
3.24,1.10573,59.4613,,,,
3.25,1.10921,59.78363,,,,
3.26,1.11262,60.09809,,,,
3.27,1.11597,60.40462,,,,
3.28,1.1193,60.70597,,,,
3.29,1.12266,61.00999,,,,
3.3,1.1261,61.32121,,,,
3.31,1.1296,61.64293,,,,
3.32,1.13316,61.96769,,,,
3.33,1.13674,62.29304,,,,
3.34,1.14032,62.61317,,,,
3.35,1.14387,62.93332,,,,
3.36,1.14738,63.25205,,,,
3.37,1.15083,63.5659,,,,
3.38,1.15422,63.87424,,,,
3.39,1.1576,64.18622,,,,
3.4,1.161,64.50243,,,,
3.41,1.16445,64.82117,,,,
3.42,1.16794,65.14381,,,,
3.43,1.17147,65.46852,,,,
3.44,1.175,65.78872,,,,
3.45,1.17851,66.10856,,,,
3.46,1.18201,66.42403,,,,
3.47,1.18547,66.73829,,,,
3.48,1.18888,67.04787,,,,
3.49,1.19225,67.35802,,,,
3.5,1.19562,67.67134,,,,
3.51,1.19902,67.99002,,,,
3.52,1.20247,68.31772,,,,
3.53,1.20595,68.65305,,,,
3.54,1.20945,68.98536,,,,
3.55,1.21296,69.30684,,,,
3.56,1.21646,69.63025,,,,
3.57,1.21994,69.95026,,,,
3.58,1.2234,70.26311,,,,
3.59,1.22684,70.572,,,,
3.6,1.23028,70.88813,,,,
3.61,1.23373,71.20784,,,,
3.62,1.2372,71.53153,,,,
3.63,1.24067,71.85908,,,,
3.64,1.24414,72.1813,,,,
3.65,1.24758,72.49915,,,,
3.66,1.251,72.81576,,,,
3.67,1.25442,73.12656,,,,
3.68,1.25783,73.43104,,,,
3.69,1.26125,73.73316,,,,
3.7,1.26469,74.0364,,,,
3.71,1.26817,74.34564,,,,
3.72,1.27171,74.66194,,,,
3.73,1.27525,74.98466,,,,
3.74,1.27877,75.30803,,,,
3.75,1.28225,75.63029,,,,
3.76,1.28568,75.94862,,,,
3.77,1.28907,76.26322,,,,
3.78,1.29245,76.57215,,,,
3.79,1.29582,76.87481,,,,
3.8,1.29922,77.18052,,,,
3.81,1.30266,77.49259,,,,
3.82,1.30618,77.81924,,,,
3.83,1.30977,78.15444,,,,
3.84,1.31337,78.48986,,,,
3.85,1.31692,78.8213,,,,
3.86,1.3204,79.14344,,,,
3.87,1.32382,79.46507,,,,
3.88,1.32721,79.78411,,,,
3.89,1.33059,80.09839,,,,
3.9,1.33398,80.40993,,,,
3.91,1.33741,80.72198,,,,
3.92,1.34092,81.04021,,,,
3.93,1.34451,81.3682,,,,
3.94,1.34813,81.69897,,,,
3.95,1.35173,82.02831,,,,
3.96,1.35528,82.35548,,,,
3.97,1.35873,82.67701,,,,
3.98,1.36212,82.98875,,,,
3.99,1.36546,83.29266,,,,
4,1.36878,83.60282,,,,
4.01,1.37214,83.91807,,,,
4.02,1.37554,84.23621,,,,
4.03,1.37901,84.5589,,,,
4.04,1.38254,84.88101,,,,
4.047,1.38504,85.10606,,,,
4.048,1.3854,85.13831,,,,
4.049,1.38575,85.17058,,,,
4.149,1.38397,83.89145,,,,
4.236,1.35073,78.83888,,,,
4.335,1.31566,73.83829,,,,
4.435,1.28099,69.20659,,,,
4.535,1.24628,64.71734,,,,
4.635,1.21154,60.36562,,,,
4.735,1.17678,56.16208,,,,
4.835,1.14205,52.09782,,,,
4.935,1.10775,48.23473,,,,
5.035,1.0732,44.46391,,,,
5.135,1.03848,40.83311,,,,
5.235,1.00368,37.31499,,,,
5.335,0.96887,33.95756,,,,
5.435,0.93438,30.76912,,,,
5.535,0.90003,27.7439,,,,
5.635,0.86539,24.85328,,,,
5.735,0.83058,22.1251,,,,
5.835,0.79575,19.56906,,,,
5.935,0.76098,17.19942,,,,
6.035,0.72669,15.04153,,,,
6.135,0.6922,13.04856,,,,
6.235,0.65764,11.22145,,,,
6.335,0.62281,9.56503,,,,
6.435,0.58813,8.08002,,,,
6.535,0.55342,6.76781,,,,
6.635,0.51916,5.62287,,,,
6.735,0.48463,4.59804,,,,
6.835,0.44986,3.69195,,,,
6.935,0.41512,2.91425,,,,
7.035,0.38032,2.25136,,,,
7.135,0.34609,1.71231,,,,
7.235,0.31151,1.25999,,,,
7.335,0.27689,0.90567,,,,
7.435,0.24214,0.62464,,,,
7.535,0.20736,0.40454,,,,
7.635,0.17298,0.24333,,,,
7.735,0.13833,0.13147,,,,
7.835,0.10382,0.07032,,,,
7.935,0.06908,0.03865,,,,
8.035,0.03442,0.01666,,,,
8.134,0.00004,0.01815,,,,
8.135,-0.00029,0.01772,,,,
8.136,-0.00062,0.01731,,,,
8.236,0.00084,0.03524,,,,
8.336,0.0396,0.05389,,,,
8.436,0.07505,0.09865,,,,
8.536,0.10981,0.17171,,,,
8.636,0.14437,0.30504,,,,
8.736,0.179,0.48806,,,,
8.742,0.18107,0.50136,,,,
8.743,0.18142,0.50369,,,,
8.744,0.18177,0.50606,,,,
8.749,0.18351,0.52435,,,,
8.754,0.18561,0.59406,,,,
8.759,0.1893,0.71477,,,,
8.764,0.19644,0.8954,,,,
8.769,0.20917,1.16326,,,,
8.774,0.22963,1.57568,,,,
8.779,0.2598,2.25012,,,,
8.784,0.30138,3.36978,,,,
8.789,0.35576,5.21914,,,,
8.794,0.42403,8.16001,,,,
8.799,0.5069,12.59241,,,,
8.804,0.60459,18.87008,,,,
8.809,0.71679,27.21736,,,,
8.814,0.84289,37.71754,,,,
8.819,0.98202,50.28814,,,,
8.824,1.13264,64.62376,,,,
8.829,1.29218,80.30856,,,,
8.834,1.45781,96.84029,,,,
8.839,1.62718,113.73188,,,,
8.844,1.79867,130.55353,,,,
8.849,1.97134,145.17995,,,,
8.854,2.14473,146.07014,,,,
8.859,2.31871,134.96126,,,,
8.864,2.49327,117.18364,,,,
8.869,2.66835,96.53217,,,,
8.874,2.84383,75.69035,,,,
8.879,3.01955,56.3992,,,,
8.884,3.19533,39.56578,,,,
8.889,3.37101,25.63889,,,,
8.894,3.54644,14.67858,,,,
8.899,3.72155,6.49664,,,,
8.904,3.89633,0.71151,,,,
8.909,4.07078,-3.05952,,,,
8.914,4.24495,-5.22441,,,,
8.919,4.41888,-6.18742,,,,
8.924,4.59261,-6.30665,,,,
8.929,4.7662,-5.8953,,,,
8.934,4.93971,-5.16435,,,,
8.939,5.11315,-4.28135,,,,
8.944,5.28654,-3.3575,,,,
8.949,5.45991,-2.49908,,,,
8.954,5.63326,-1.73531,,,,
8.959,5.80659,-1.10881,,,,
8.964,5.97988,-0.61786,,,,
8.969,6.15315,-0.26297,,,,
8.974,6.3264,-0.00916,,,,
8.979,6.49963,0.15624,,,,
8.984,6.67283,0.26398,,,,
8.989,6.846,0.31527,,,,
8.994,7.01917,0.31956,,,,
8.999,7.1923,0.29802,,,,
9.004,7.3654,0.26154,,,,
9.009,7.53849,0.22428,,,,
9.014,7.7116,0.18624,,,,
9.019,7.88472,0.16228,,,,
9.024,8.05785,0.12934,,,,
9.029,8.231,0.10253,,,,
9.034,8.40417,0.07702,,,,
9.039,8.57735,0.06161,,,,
9.044,8.75053,0.05,,,,
9.049,8.9237,0.04879,,,,
9.054,9.09685,0.04497,,,,
9.059,9.27002,0.03348,,,,
9.064,9.44318,0.02751,,,,
9.069,9.61633,0.02836,,,,
9.074,9.78947,0.03009,,,,
9.079,9.9626,0.03358,,,,
9.084,10.13574,0.04108,,,,
9.089,10.30889,0.04412,,,,
9.094,10.48205,0.04478,,,,
9.099,10.65522,0.04406,,,,
9.104,10.82841,0.04539,,,,
9.109,11.0016,0.0464,,,,
9.114,11.17478,0.05168,,,,
9.119,11.34795,0.04854,,,,
9.124,11.52111,0.04227,,,,
9.129,11.69425,0.03223,,,,
9.134,11.86736,0.02751,,,,
9.139,12.04046,0.02877,,,,
9.144,12.21353,0.03362,,,,
9.149,12.38658,0.03623,,,,
9.154,12.55962,0.0315,,,,
9.159,12.73265,0.03345,,,,
9.164,12.9057,0.0284,,,,
9.169,13.07877,0.0334,,,,
9.174,13.25185,0.03852,,,,
9.179,13.42495,0.04491,,,,
9.184,13.59805,0.04699,,,,
9.189,13.77116,0.04812,,,,
9.194,13.94427,0.04696,,,,
9.199,14.11737,0.0384,,,,
9.204,14.29047,0.04301,,,,
9.209,14.46358,0.04488,,,,
9.214,14.6367,0.04695,,,,
9.219,14.8098,0.04712,,,,
9.224,14.98289,0.04172,,,,
9.229,15.15597,0.03142,,,,
9.234,15.32907,0.03072,,,,
9.239,15.50217,0.02733,,,,
9.244,15.67527,0.03071,,,,
9.249,15.84836,0.03418,,,,
9.254,16.02147,0.03435,,,,
9.259,16.19457,0.03159,,,,
9.264,16.36767,0.03505,,,,
9.269,16.54075,0.03807,,,,
9.274,16.71384,0.03696,,,,
9.279,16.88693,0.03882,,,,
9.284,17.06001,0.03757,,,,
9.289,17.23308,0.03848,,,,
9.294,17.40614,0.03843,,,,
9.297,17.50997,0.0335,,,,