File: data/control/S1/raw_data.csv
Strain : Tensile strain (Extension) gauge length,100,mm,,,,
,,,,,,
Time,Extension,Load,,,,
(s),(mm),(N),Slow Start,Slow Max,High Start,High Max
0,0,0.1875,5,413,467,488
0.01,0,0.19208,,,,
0.02,0.00007,0.19516,,,,
0.03,0.00033,0.19641,,,,
0.04,0.00093,0.19621,,,,
0.05,0.00203,0.20172,,,,
0.06,0.00374,0.21273,,,,
0.07,0.00578,0.20844,,,,
0.08,0.00748,0.21581,,,,
0.09,0.00893,0.22087,,,,
0.1,0.01049,0.22881,,,,
0.11,0.01267,0.24483,,,,
0.12,0.01575,0.26209,,,,
0.13,0.01962,0.2784,,,,
0.14,0.02397,0.29716,,,,
0.15,0.02848,0.31919,,,,
0.16,0.03293,0.33788,,,,
0.17,0.03717,0.36188,,,,
0.18,0.04119,0.38322,,,,
0.19,0.04498,0.40462,,,,
0.2,0.04861,0.42652,,,,
0.21,0.05211,0.45102,,,,
0.22,0.05554,0.47153,,,,
0.23,0.05896,0.48968,,,,
0.24,0.06241,0.51033,,,,
0.25,0.06588,0.53231,,,,
0.26,0.06935,0.55317,,,,
0.27,0.07278,0.57497,,,,
0.28,0.07616,0.60109,,,,
0.29,0.07948,0.62272,,,,
0.3,0.08277,0.64241,,,,
0.31,0.08605,0.66585,,,,
0.32,0.08932,0.6907,,,,
0.33,0.09262,0.71627,,,,
0.34,0.09595,0.74536,,,,
0.35,0.09934,0.77595,,,,
0.36,0.10278,0.80701,,,,
0.37,0.10622,0.83611,,,,
0.38,0.10964,0.86632,,,,
0.39,0.11301,0.8972,,,,
0.4,0.11634,0.92729,,,,
0.41,0.11962,0.95697,,,,
0.42,0.12288,0.9882,,,,
0.43,0.12614,1.02179,,,,
0.44,0.12943,1.05676,,,,
0.45,0.13279,1.09253,,,,
0.46,0.1362,1.12837,,,,
0.47,0.13966,1.16752,,,,
0.48,0.14312,1.20458,,,,
0.49,0.14655,1.24031,,,,
0.5,0.14992,1.2773,,,,
0.51,0.15323,1.3186,,,,
0.52,0.15649,1.36286,,,,
0.53,0.15973,1.40613,,,,
0.54,0.16297,1.44853,,,,
0.55,0.16626,1.49081,,,,
0.56,0.16961,1.53741,,,,
0.57,0.17302,1.58315,,,,
0.58,0.17648,1.63398,,,,
0.59,0.17994,1.68365,,,,
0.6,0.18339,1.73176,,,,
0.61,0.18681,1.77913,,,,
0.62,0.19019,1.82965,,,,
0.63,0.19353,1.88187,,,,
0.64,0.19683,1.93597,,,,
0.65,0.20011,1.98819,,,,
0.66,0.20341,2.03983,,,,
0.67,0.20675,2.09715,,,,
0.68,0.21012,2.15418,,,,
0.69,0.21352,2.2057,,,,
0.7,0.21691,2.26191,,,,
0.71,0.22029,2.32203,,,,
0.72,0.22364,2.38312,,,,
0.73,0.22699,2.44116,,,,
0.74,0.2303,2.5017,,,,
0.75,0.23358,2.55939,,,,
0.76,0.23685,2.61721,,,,
0.77,0.24013,2.68271,,,,
0.78,0.24347,2.74739,,,,
0.79,0.24684,2.8116,,,,
0.8,0.25023,2.87794,,,,
0.81,0.25363,2.94533,,,,
0.82,0.25701,3.0103,,,,
0.83,0.26038,3.07574,,,,
0.84,0.26372,3.14369,,,,
0.85,0.26705,3.2086,,,,
0.86,0.27037,3.27641,,,,
0.87,0.27371,3.34917,,,,
0.88,0.27706,3.41979,,,,
0.89,0.28043,3.49026,,,,
0.9,0.28379,3.5685,,,,
0.91,0.28715,3.64519,,,,
0.92,0.29048,3.72122,,,,
0.93,0.2938,3.80069,,,,
0.94,0.29711,3.87505,,,,
0.95,0.30041,3.94501,,,,
0.96,0.30371,4.02514,,,,
0.97,0.30702,4.10753,,,,
0.98,0.31038,4.18792,,,,
0.99,0.31378,4.27502,,,,
1,0.31721,4.3642,,,,
1.01,0.32061,4.44556,,,,
1.02,0.32399,4.52537,,,,
1.03,0.32732,4.60935,,,,
1.04,0.33062,4.69306,,,,
1.05,0.3339,4.77994,,,,
1.06,0.33716,4.87152,,,,
1.07,0.34042,4.9621,,,,
1.08,0.34372,5.05337,,,,
1.09,0.34709,5.15081,,,,
1.1,0.35053,5.24813,,,,
1.11,0.354,5.34683,,,,
1.12,0.35744,5.4547,,,,
1.13,0.36083,5.56055,,,,
1.14,0.36415,5.65752,,,,
1.15,0.36743,5.75609,,,,
1.16,0.3707,5.86039,,,,
1.17,0.37397,5.96411,,,,
1.18,0.37727,6.0733,,,,
1.19,0.38062,6.18468,,,,
1.2,0.38405,6.29567,,,,
1.21,0.38753,6.40688,,,,
1.22,0.39103,6.5231,,,,
1.23,0.3945,6.64,,,,
1.24,0.39791,6.75793,,,,
1.25,0.40125,6.87605,,,,
1.26,0.40453,6.98919,,,,
1.27,0.40776,7.10297,,,,
1.28,0.41097,7.22043,,,,
1.29,0.41422,7.33846,,,,
1.3,0.41753,7.46159,,,,
1.31,0.4209,7.59212,,,,
1.32,0.42431,7.72316,,,,
1.33,0.42775,7.85006,,,,
1.34,0.4312,7.97838,,,,
1.35,0.43462,8.10696,,,,
1.36,0.43799,8.23395,,,,
1.37,0.4413,8.36584,,,,
1.38,0.44456,8.50018,,,,
1.39,0.44778,8.63164,,,,
1.4,0.45101,8.76744,,,,
1.41,0.4543,8.9108,,,,
1.42,0.45767,9.05823,,,,
1.43,0.46108,9.20816,,,,
1.44,0.46452,9.36246,,,,
1.45,0.46796,9.51302,,,,
1.46,0.47136,9.65823,,,,
1.47,0.47472,9.80344,,,,
1.48,0.47804,9.94944,,,,
1.49,0.4813,10.09276,,,,
1.5,0.48454,10.23721,,,,
1.51,0.48778,10.38662,,,,
1.52,0.49106,10.54329,,,,
1.53,0.4944,10.7054,,,,
1.54,0.49778,10.87886,,,,
1.55,0.50118,11.05257,,,,
1.56,0.50459,11.2231,,,,
1.57,0.50798,11.39131,,,,
1.58,0.51134,11.55426,,,,
1.59,0.51466,11.7114,,,,
1.6,0.51796,11.87197,,,,
1.61,0.52125,12.03703,,,,
1.62,0.52456,12.2067,,,,
1.63,0.52791,12.3838,,,,
1.64,0.53129,12.56564,,,,
1.65,0.53469,12.75025,,,,
1.66,0.53809,12.93805,,,,
1.67,0.54147,13.12187,,,,
1.68,0.54482,13.29872,,,,
1.69,0.54816,13.47263,,,,
1.7,0.55148,13.64474,,,,
1.71,0.5548,13.81238,,,,
1.72,0.55814,13.98604,,,,
1.73,0.56155,14.17157,,,,
1.74,0.565,14.36723,,,,
1.75,0.56846,14.56428,,,,
1.76,0.57189,14.75996,,,,
1.77,0.57528,14.95448,,,,
1.78,0.57861,15.14514,,,,
1.79,0.58189,15.33742,,,,
1.8,0.58515,15.5309,,,,
1.81,0.58839,15.72113,,,,
1.82,0.59165,15.91291,,,,
1.83,0.59494,16.10763,,,,
1.84,0.59831,16.30817,,,,
1.85,0.60175,16.51418,,,,
1.86,0.60522,16.7249,,,,
1.87,0.60867,16.94092,,,,
1.88,0.61207,17.15198,,,,
1.89,0.61539,17.35906,,,,
1.9,0.61867,17.56779,,,,
1.91,0.62192,17.77483,,,,
1.92,0.62516,17.97621,,,,
1.93,0.62843,18.18124,,,,
1.94,0.63176,18.38913,,,,
1.95,0.63516,18.60509,,,,
1.96,0.63861,18.82606,,,,
1.97,0.64209,19.0499,,,,
1.98,0.64555,19.27253,,,,
1.99,0.64894,19.4947,,,,
2,0.65225,19.71062,,,,
2.01,0.65548,19.92124,,,,
2.02,0.65867,20.13183,,,,
2.03,0.66186,20.34722,,,,
2.04,0.66508,20.56436,,,,
2.05,0.66837,20.78839,,,,
2.06,0.67176,21.02309,,,,
2.07,0.67521,21.26252,,,,
2.08,0.67869,21.50194,,,,
2.09,0.68216,21.73962,,,,
2.1,0.68559,21.97406,,,,
2.11,0.68896,22.20782,,,,
2.12,0.69227,22.43886,,,,
2.13,0.69553,22.66371,,,,
2.14,0.69876,22.8925,,,,
2.15,0.70201,23.1281,,,,
2.16,0.70531,23.36797,,,,
2.17,0.70867,23.60882,,,,
2.18,0.71208,23.85492,,,,
2.19,0.7155,24.10116,,,,
2.2,0.7189,24.34536,,,,
2.21,0.72228,24.58648,,,,
2.22,0.72563,24.82562,,,,
2.23,0.72893,25.0599,,,,
2.24,0.73218,25.29296,,,,
2.25,0.73541,25.53465,,,,
2.26,0.73866,25.78303,,,,
2.27,0.74197,26.03929,,,,
2.28,0.74537,26.30553,,,,
2.29,0.74882,26.57853,,,,
2.3,0.75231,26.84912,,,,
2.31,0.75579,27.11679,,,,
2.32,0.75924,27.38088,,,,
2.33,0.76267,27.63952,,,,
2.34,0.76605,27.89192,,,,
2.35,0.7694,28.14149,,,,
2.36,0.77274,28.39615,,,,
2.37,0.77609,28.65344,,,,
2.38,0.77945,28.91311,,,,
2.39,0.78281,29.17786,,,,
2.4,0.78616,29.44534,,,,
2.41,0.78949,29.71327,,,,
2.42,0.79281,29.97565,,,,
2.43,0.7961,30.23401,,,,
2.44,0.79938,30.48853,,,,
2.45,0.80267,30.7405,,,,
2.46,0.80596,30.99445,,,,
2.47,0.80928,31.25201,,,,
2.48,0.81266,31.51975,,,,
2.49,0.81608,31.79408,,,,
2.5,0.81948,32.0726,,,,
2.51,0.82284,32.35044,,,,
2.52,0.82615,32.62475,,,,
2.53,0.82943,32.8918,,,,
2.54,0.8327,33.15681,,,,
2.55,0.83598,33.42221,,,,
2.56,0.83928,33.69157,,,,
2.57,0.84261,33.96577,,,,
2.58,0.84597,34.24115,,,,
2.59,0.84939,34.52095,,,,
2.6,0.85284,34.80679,,,,
2.61,0.85628,35.09338,,,,
2.62,0.85968,35.37607,,,,
2.63,0.86301,35.65789,,,,
2.64,0.8663,35.93526,,,,
2.65,0.86955,36.21197,,,,
2.66,0.8728,36.48851,,,,
2.67,0.87606,36.76456,,,,
2.68,0.87938,37.04332,,,,
2.69,0.88276,37.33347,,,,
2.7,0.88622,37.63195,,,,
2.71,0.88971,37.92774,,,,
2.72,0.89318,38.22278,,,,
2.73,0.8966,38.51408,,,,
2.74,0.89995,38.7975,,,,
2.75,0.90323,39.07959,,,,
2.76,0.90646,39.36403,,,,
2.77,0.90967,39.64782,,,,
2.78,0.9129,39.93035,,,,
2.79,0.91616,40.2152,,,,
2.8,0.91949,40.50472,,,,
2.81,0.9229,40.79948,,,,
2.82,0.92635,41.10301,,,,
2.83,0.92981,41.40523,,,,
2.84,0.93327,41.70507,,,,
2.85,0.9367,42.00607,,,,
2.86,0.9401,42.30416,,,,
2.87,0.94345,42.59833,,,,
2.88,0.94675,42.89405,,,,
2.89,0.95004,43.19246,,,,
2.9,0.95334,43.49054,,,,
2.91,0.95667,43.792,,,,
2.92,0.96005,44.10084,,,,
2.93,0.96345,44.4103,,,,
2.94,0.96685,44.71247,,,,
2.95,0.97024,45.0089,,,,
2.96,0.9736,45.30041,,,,
2.97,0.97695,45.58905,,,,
2.98,0.98027,45.8803,,,,
2.99,0.98357,46.16871,,,,
3,0.98685,46.45936,,,,
3.01,0.99014,46.75983,,,,
3.02,0.99347,47.06985,,,,
3.03,0.99683,47.38467,,,,
3.04,1.0002,47.69894,,,,
3.05,1.00358,48.00908,,,,
3.06,1.00695,48.312,,,,
3.07,1.01031,48.61179,,,,
3.08,1.01367,48.90702,,,,
3.09,1.017,49.19796,,,,
3.1,1.02033,49.49109,,,,
3.11,1.02368,49.79176,,,,
3.12,1.02703,50.10123,,,,
3.13,1.0304,50.41992,,,,
3.14,1.03376,50.74065,,,,
3.15,1.03711,51.05706,,,,
3.16,1.04044,51.37099,,,,
3.17,1.04373,51.68171,,,,
3.18,1.04702,51.98502,,,,
3.19,1.05032,52.28366,,,,
3.2,1.05361,52.57984,,,,
3.21,1.05693,52.87225,,,,
3.22,1.0603,53.17315,,,,
3.23,1.06372,53.48425,,,,
3.24,1.06715,53.80361,,,,
3.25,1.07056,54.12444,,,,
3.26,1.07392,54.44571,,,,
3.27,1.07723,54.75824,,,,
3.28,1.0805,55.06606,,,,
3.29,1.08376,55.3734,,,,
3.3,1.08702,55.67748,,,,
3.31,1.09029,55.97703,,,,
3.32,1.09361,56.27966,,,,
3.33,1.09699,56.59512,,,,
3.34,1.10044,56.91632,,,,
3.35,1.10392,57.23773,,,,
3.36,1.1074,57.55957,,,,
3.37,1.11082,57.88109,,,,
3.38,1.11416,58.19659,,,,
3.39,1.11743,58.50266,,,,
3.4,1.12068,58.80865,,,,
3.41,1.12393,59.11647,,,,
3.42,1.1272,59.4264,,,,
3.43,1.13053,59.74099,,,,
3.44,1.13394,60.0636,,,,
3.45,1.1374,60.39342,,,,
3.46,1.14088,60.72196,,,,
3.47,1.14434,61.04896,,,,
3.48,1.14777,61.37128,,,,
3.49,1.15114,61.69339,,,,
3.5,1.15445,62.0093,,,,
3.51,1.15771,62.31601,,,,
3.52,1.16093,62.62066,,,,
3.53,1.16418,62.93066,,,,
3.54,1.16747,63.244,,,,
3.55,1.17083,63.56339,,,,
3.56,1.17425,63.88383,,,,
3.57,1.17769,64.20537,,,,
3.58,1.18113,64.52589,,,,
3.59,1.18454,64.84351,,,,
3.6,1.18791,65.15615,,,,
3.61,1.19123,65.465,,,,
3.62,1.19449,65.77124,,,,
3.63,1.19772,66.07529,,,,
3.64,1.20095,66.38369,,,,
3.65,1.20423,66.70175,,,,
3.66,1.20757,67.02667,,,,
3.67,1.21096,67.35222,,,,
3.68,1.21437,67.67755,,,,
3.69,1.21779,68.0033,,,,
3.7,1.22119,68.32403,,,,
3.71,1.22456,68.63888,,,,
3.72,1.2279,68.94975,,,,
3.73,1.2312,69.26046,,,,
3.74,1.2345,69.5753,,,,
3.75,1.23781,69.89286,,,,
3.76,1.24114,70.21212,,,,
3.77,1.2445,70.54027,,,,
3.78,1.24789,70.87186,,,,
3.79,1.25128,71.20189,,,,
3.8,1.25466,71.5287,,,,
3.81,1.25802,71.84875,,,,
3.82,1.26136,72.15845,,,,
3.83,1.26467,72.4637,,,,
3.84,1.26795,72.77047,,,,
3.85,1.27124,73.07912,,,,
3.86,1.27457,73.39529,,,,
3.87,1.27794,73.71976,,,,
3.88,1.28134,74.04692,,,,
3.89,1.28474,74.37953,,,,
3.9,1.28813,74.71381,,,,
3.91,1.29149,75.0364,,,,
3.92,1.29481,75.3523,,,,
3.93,1.29812,75.66673,,,,
3.94,1.30142,75.97588,,,,
3.95,1.30472,76.28695,,,,
3.96,1.30806,76.60296,,,,
3.97,1.31145,76.925,,,,
3.98,1.31489,77.25845,,,,
3.99,1.31837,77.60046,,,,
4,1.32183,77.93816,,,,
4.01,1.32523,78.26876,,,,
4.02,1.32857,78.58864,,,,
4.03,1.33185,78.89938,,,,
4.04,1.3351,79.20464,,,,
4.05,1.33833,79.50777,,,,
4.053,1.3393,79.59896,,,,
4.054,1.33963,79.62939,,,,
4.055,1.33995,79.65987,,,,
4.155,1.33753,78.38635,,,,
4.231,1.30953,73.35817,,,,
4.318,1.27949,68.35383,,,,
4.414,1.24724,63.32063,,,,
4.514,1.21357,58.38704,,,,
4.614,1.17997,53.71708,,,,
4.714,1.14649,49.2846,,,,
4.814,1.11291,45.07063,,,,
4.914,1.0796,41.09861,,,,
5.014,1.04596,37.29645,,,,
5.114,1.01238,33.7344,,,,
5.214,0.97889,30.33045,,,,
5.314,0.94542,27.11238,,,,
5.414,0.91193,24.08274,,,,
5.514,0.87858,21.25489,,,,
5.614,0.845,18.58215,,,,
5.714,0.81163,16.10012,,,,
5.814,0.77823,13.78044,,,,
5.914,0.74462,11.65895,,,,
6.014,0.71127,9.74119,,,,
6.114,0.67778,7.99785,,,,
6.214,0.64444,6.4391,,,,
6.314,0.61082,5.06981,,,,
6.414,0.57734,3.89189,,,,
6.514,0.54366,2.90581,,,,
6.614,0.51052,2.11705,,,,
6.714,0.47682,1.46472,,,,
6.814,0.44313,0.99813,,,,
6.914,0.40979,0.66864,,,,
7.014,0.37607,0.44437,,,,
7.114,0.34268,0.29786,,,,
7.214,0.3094,0.20416,,,,
7.314,0.27611,0.14697,,,,
7.414,0.24253,0.11317,,,,
7.514,0.20894,0.10421,,,,
7.614,0.1752,0.08881,,,,
7.714,0.14215,0.08744,,,,
7.814,0.10873,0.07149,,,,
7.914,0.07535,0.07043,,,,
8.014,0.04156,0.06661,,,,
8.114,0.00794,0.0523,,,,
8.138,-0.00002,0.05471,,,,
8.139,-0.00035,0.05457,,,,
8.14,-0.00068,0.05443,,,,
8.24,0.00012,0.08319,,,,
8.34,0.03751,0.086,,,,
8.44,0.07196,0.10717,,,,
8.54,0.1054,0.1145,,,,
8.64,0.13886,0.12876,,,,
8.74,0.17225,0.15766,,,,
8.84,0.20599,0.20822,,,,
8.94,0.23942,0.28246,,,,
9.04,0.273,0.43223,,,,
9.073,0.28409,0.50132,,,,
9.074,0.28442,0.50356,,,,
9.075,0.28476,0.50577,,,,
9.08,0.28645,0.52326,,,,
9.085,0.2885,0.592,,,,
9.09,0.29212,0.71927,,,,
9.095,0.29917,0.91125,,,,
9.1,0.31177,1.214,,,,
9.105,0.33207,1.7185,,,,
9.11,0.36204,2.57611,,,,
9.115,0.40338,4.03253,,,,
9.12,0.45749,6.41538,,,,
9.125,0.52543,10.109,,,,
9.13,0.60796,15.51028,,,,
9.135,0.7054,22.95483,,,,
9.14,0.81753,32.64299,,,,
9.145,0.94376,44.58319,,,,
9.15,1.08272,58.53605,,,,
9.155,1.23198,74.08221,,,,
9.16,1.38863,90.74494,,,,
9.165,1.55014,108.05416,,,,
9.17,1.71464,125.60385,,,,
9.175,1.88096,143.07381,,,,
9.18,2.04846,160.18513,,,,
9.185,2.21682,176.28688,,,,
9.19,2.38586,184.82178,,,,
9.195,2.55543,176.21339,,,,
9.2,2.72541,156.705,,,,
9.205,2.89565,131.81754,,,,
9.21,3.066,105.50069,,,,
9.215,3.23629,80.32363,,,,
9.22,3.40635,57.79177,,,,
9.225,3.57609,38.75633,,,,
9.23,3.74546,23.49606,,,,
9.235,3.91446,11.85343,,,,
9.24,4.08312,3.43487,,,,
9.245,4.25148,-2.22935,,,,
9.25,4.41961,-5.66275,,,,
9.255,4.58756,-7.39756,,,,
9.26,4.75539,-7.90951,,,,
9.265,4.92311,-7.60053,,,,
9.27,5.09075,-6.79569,,,,
9.275,5.25834,-5.72087,,,,
9.28,5.4259,-4.57447,,,,
9.285,5.59343,-3.47698,,,,
9.29,5.76095,-2.47414,,,,
9.295,5.92846,-1.63393,,,,
9.3,6.09596,-0.95892,,,,
9.305,6.26342,-0.43873,,,,
9.31,6.43086,-0.06983,,,,
9.315,6.59828,0.17959,,,,
9.32,6.76572,0.341,,,,
9.325,6.93317,0.42401,,,,
9.33,7.10064,0.44636,,,,
9.335,7.26812,0.43573,,,,
9.34,7.43562,0.40064,,,,
9.345,7.60313,0.3549,,,,
9.35,7.77063,0.30906,,,,
9.355,7.9381,0.26432,,,,
9.36,8.10556,0.22479,,,,
9.365,8.27302,0.19222,,,,
9.37,8.44047,0.16521,,,,
9.375,8.60793,0.14313,,,,
9.38,8.77536,0.13567,,,,
9.385,8.94279,0.12061,,,,
9.39,9.11023,0.10742,,,,
9.395,9.27768,0.09906,,,,
9.4,9.44514,0.09217,,,,
9.405,9.61261,0.08496,,,,
9.41,9.7801,0.08236,,,,
9.415,9.94759,0.08132,,,,
9.42,10.11506,0.08304,,,,
9.425,10.28252,0.08938,,,,
9.43,10.44995,0.09083,,,,
9.435,10.61738,0.09066,,,,
9.44,10.78479,0.09026,,,,
9.445,10.95218,0.09988,,,,
9.45,11.11956,0.10631,,,,
9.455,11.28693,0.11015,,,,
9.46,11.45429,0.10678,,,,
9.465,11.62165,0.10124,,,,
9.47,11.789,0.09571,,,,
9.475,11.95638,0.09032,,,,
9.48,12.12377,0.08519,,,,
9.485,12.29118,0.08329,,,,
9.49,12.45859,0.08738,,,,
9.495,12.626,0.08542,,,,
9.5,12.79341,0.08443,,,,
9.505,12.96082,0.08801,,,,
9.51,13.12822,0.09036,,,,
9.515,13.29561,0.09811,,,,
9.52,13.46301,0.10675,,,,
9.525,13.63042,0.10884,,,,
9.53,13.79783,0.11455,,,,
9.535,13.96522,0.11597,,,,
9.54,14.1326,0.11342,,,,
9.545,14.3,0.10397,,,,
9.55,14.46741,0.10434,,,,
9.555,14.63482,0.10326,,,,
9.56,14.80224,0.09714,,,,
9.565,14.96966,0.09258,,,,
9.57,15.13708,0.09046,,,,
9.575,15.30449,0.08813,,,,
9.58,15.47189,0.09182,,,,
9.585,15.63928,0.09501,,,,
9.59,15.80667,0.09172,,,,
9.595,15.97407,0.09558,,,,
9.6,16.14147,0.09729,,,,
9.605,16.30885,0.10226,,,,
9.61,16.47622,0.10353,,,,
9.615,16.64358,0.10259,,,,
9.62,16.81094,0.09545,,,,
9.625,16.9783,0.0925,,,,
9.627,17.04525,0.09161,,,,