File: data/instron/Sample15_Dynamic.is_tcyclic_RawData/Specimen_RawData_1.csv
Strain : Tensile strain (Extension) gauge length,"100.00000",mm

Time,Extension,Load
(s),(mm),(N)
"0.00000","0.00000","0.24969"
"0.20000","0.13997","1.55956"
"0.40000","0.31706","5.46740"
"0.60000","0.49342","12.63152"
"0.79300","0.66375","22.43647"
"0.95700","0.80858","32.53247"
"1.04100","0.88228","38.17234"
"1.04300","0.88404","38.30900"
"1.18800","0.82219","28.84971"
"1.30400","0.71796","18.82847"
"1.47500","0.56705","8.74618"
"1.67500","0.39074","2.39159"
"1.87500","0.21433","0.31183"
"2.07500","0.03799","0.03500"
"2.11900","-0.00099","0.02729"
"2.22000","0.01529","0.06835"
"2.42000","0.19859","0.62869"
"2.62000","0.37499","3.82751"
"2.82000","0.55132","11.44695"
"2.99300","0.70371","21.50373"
"3.13300","0.82736","31.53275"
"3.19700","0.88356","36.47430"
"3.29800","0.86598","32.68550"
"3.39800","0.77303","22.64319"
"3.54000","0.64697","12.56327"
"3.74000","0.47049","4.00586"
"3.94000","0.29402","0.63437"
"4.14000","0.11748","0.05321"
"4.27400","-0.00053","0.02776"
"4.27600","-0.00229","0.02759"
"4.47600","0.10881","0.14213"
"4.67600","0.28618","1.34196"
"4.87600","0.46256","6.21542"
"5.07000","0.63380","15.50889"
"5.22300","0.76882","25.61903"
"5.35200","0.88222","35.51910"
"5.35400","0.88398","35.67892"
"5.50000","0.82129","26.90204"
"5.62100","0.71260","16.77628"
"5.80100","0.55376","6.87814"
"6.00100","0.37748","1.50315"
"6.20100","0.20108","0.13249"
"6.40100","0.02471","0.01916"
"6.43000","-0.00101","0.02024"
"6.53100","0.01545","0.04977"
"6.73100","0.19855","0.36143"
"6.93100","0.37493","2.88241"
"7.13100","0.55127","9.95144"
"7.30700","0.70629","20.03217"
"7.44500","0.82818","30.07015"
"7.50800","0.88352","35.09414"
"7.60900","0.86605","31.55560"
"7.71100","0.77124","21.42879"
"7.85700","0.64169","11.35946"
"8.05700","0.46525","3.30852"
"8.25700","0.28881","0.41843"
"8.45700","0.11221","0.04286"
"8.58500","-0.00055","0.01078"
"8.58700","-0.00231","0.01042"
"8.78700","0.10871","0.09989"
"8.98700","0.28608","1.00329"
"9.18700","0.46246","5.44395"
"9.38200","0.63456","14.52820"
"9.53500","0.76960","24.60933"
"9.66300","0.88212","34.54379"
"9.66500","0.88388","34.70662"
"9.81100","0.82125","26.09681"
"9.93200","0.71255","16.05473"
"10.11300","0.55280","6.31029"
"10.31300","0.37655","1.24271"
"10.51300","0.20014","0.09041"
"10.71300","0.02376","0.01287"
"10.74100","-0.00106","0.00523"
"10.84200","0.01516","0.04004"
"11.04200","0.19840","0.25886"
"11.24200","0.37479","2.47027"
"11.44200","0.55111","9.26257"
"11.61900","0.70700","19.28521"
"11.75700","0.82890","29.35681"
"11.81900","0.88335","34.33476"
"11.92000","0.86572","30.86712"
"12.02200","0.77107","20.82760"
"12.17000","0.63979","10.74619"
"12.37000","0.46335","2.95888"
"12.57000","0.28690","0.31623"
"12.77000","0.11035","0.02494"
"12.89600","-0.00068","0.01502"
"12.89800","-0.00245","0.01565"
"13.09800","0.10847","0.08296"
"13.29800","0.28579","0.83267"
"13.49800","0.46218","4.99245"
"13.69500","0.63603","14.01327"
"13.84800","0.77110","24.09254"
"13.97500","0.88271","34.01250"
"13.97700","0.88447","34.17572"
"14.12300","0.82190","25.63478"
"14.24500","0.71231","15.57432"
"14.42700","0.55166","5.93935"
"14.62700","0.37541","1.08117"
"14.82700","0.19900","0.07649"
"15.02700","0.02261","0.00428"
"15.05400","-0.00130","0.00680"
"15.15500","0.01490","0.03414"
"15.35500","0.19805","0.21509"
"15.55500","0.37446","2.20142"
"15.75500","0.55076","8.78620"
"15.93400","0.70844","18.86435"
"16.07100","0.82942","28.88258"
"16.13200","0.88302","33.81617"
"16.23300","0.86561","30.40796"
"16.33500","0.77076","20.38005"
"16.48400","0.63858","10.32526"
"16.68400","0.46217","2.73523"
"16.88400","0.28571","0.26149"
"17.08400","0.10918","0.03127"
"17.20800","-0.00013","0.00801"
"17.21000","-0.00189","0.00756"
"17.41000","0.10902","0.07268"
"17.61000","0.28636","0.70631"
"17.81000","0.46274","4.70669"
"18.00800","0.63746","13.67500"
"18.16100","0.77254","23.74190"
"18.28600","0.88240","33.54134"
"18.28800","0.88416","33.70746"
"18.43400","0.82162","25.22133"
"18.55800","0.71025","15.08705"
"18.74100","0.54869","5.56674"
"18.94100","0.37243","0.93169"
"19.14100","0.19602","0.06380"
"19.34100","0.01964","0.01337"
"19.36500","-0.00161","0.01228"
"19.46600","0.01444","0.03372"
"19.66600","0.19770","0.18535"
"19.86600","0.37412","2.02451"
"20.06600","0.55041","8.43478"
"20.24600","0.70900","18.50798"
"20.38300","0.82999","28.52804"
"20.44400","0.88355","33.48453"
"20.54500","0.86596","30.09090"
"20.64900","0.76951","19.93878"
"20.80000","0.63565","9.86838"
"21.00000","0.45924","2.51263"
"21.20000","0.28277","0.21670"
"21.40000","0.10623","0.02978"
"21.52100","-0.00045","0.00906"
"21.52300","-0.00222","0.00890"
"21.72300","0.10871","0.07045"
"21.92300","0.28606","0.62810"
"22.12300","0.46242","4.47495"
"22.32100","0.63715","13.32788"
"22.47400","0.77222","23.37955"
"22.59900","0.88206","33.18485"
"22.60100","0.88382","33.35043"
"22.74800","0.82035","24.80288"
"22.87200","0.70902","14.73704"
"23.05700","0.54571","5.26456"
"23.25700","0.36945","0.82216"
"23.45700","0.19303","0.06119"
"23.65700","0.01664","0.00375"
"23.67700","-0.00107","0.00782"
"23.77800","0.01502","0.03367"
"23.97800","0.19827","0.17387"
"24.17800","0.37470","1.90079"
"24.37800","0.55097","8.20983"
"24.55900","0.71045","18.31442"
"24.69600","0.83144","28.36102"
"24.75500","0.88323","33.15298"
"24.85600","0.86594","29.81908"
"24.95900","0.77014","19.74579"
"25.11000","0.63624","9.70018"
"25.31000","0.45982","2.40558"
"25.51000","0.28336","0.20048"
"25.71000","0.10684","0.02305"
"25.83200","-0.00074","0.00714"
"25.83400","-0.00250","0.00763"
"26.03400","0.10842","0.06651"
"26.23400","0.28578","0.57630"
"26.43400","0.46212","4.28209"
"26.63300","0.63776","13.10159"
"26.78600","0.77281","23.14839"
"26.91100","0.88265","32.96946"
"26.91300","0.88441","33.13544"
"27.06000","0.82099","24.61660"
"27.18400","0.70965","14.55958"
"27.36900","0.54633","5.13485"
"27.56900","0.37008","0.77350"
"27.76900","0.19366","0.04974"
"27.96900","0.01725","0.00773"
"27.99000","-0.00132","0.00542"
"28.09100","0.01477","0.03271"
"28.29100","0.19800","0.15540"
"28.49100","0.37441","1.78897"
"28.69100","0.55068","7.97069"
"28.87200","0.71015","18.03267"
"29.00900","0.83114","28.06941"
"29.06800","0.88293","32.85898"
"29.16900","0.86535","29.51669"
"29.27300","0.76888","19.41050"
"29.42700","0.63243","9.30231"
"29.62700","0.45599","2.21545"
"29.82700","0.27955","0.16920"
"30.02700","0.10302","0.01878"
"30.14400","-0.00018","0.00545"
"30.14600","-0.00194","0.00422"
"30.34600","0.10895","0.05426"
"30.54600","0.28634","0.52176"
"30.74600","0.46267","4.14418"
"30.94500","0.63832","12.91032"
"31.09900","0.77426","23.00426"
"31.22200","0.88232","32.68626"
"31.22400","0.88408","32.85261"
"31.37100","0.82073","24.38135"
"31.49500","0.70936","14.34218"
"31.68000","0.54603","4.99539"
"31.88000","0.36979","0.71171"
"32.08000","0.19337","0.05276"
"32.28000","0.01696","0.00919"
"32.30100","-0.00162","0.00313"
"32.40200","0.01452","0.02070"
"32.60200","0.19774","0.14040"
"32.80200","0.37411","1.67846"
"33.00200","0.55040","7.77904"
"33.18400","0.71074","17.84595"
"33.32100","0.83172","27.88941"
"33.38000","0.88353","32.69334"
"33.48100","0.86603","29.36208"
"33.58500","0.76952","19.27065"
"33.73800","0.63392","9.22448"
"33.93800","0.45749","2.15432"
"34.13800","0.28106","0.15143"
"34.33800","0.10450","0.02454"
"34.45700","-0.00043","0.00387"
"34.45900","-0.00219","0.00323"
"34.65900","0.10866","0.05054"
"34.85900","0.28606","0.48990"
"35.05900","0.46239","4.00311"
"35.25900","0.63893","12.74162"
"35.41200","0.77399","22.77190"
"35.53500","0.88206","32.44342"
"35.53700","0.88382","32.61056"
"35.68400","0.82046","24.15882"
"35.80900","0.70819","14.07693"
"35.99500","0.54401","4.79318"
"36.19500","0.36773","0.65104"
"36.39500","0.19132","0.04302"
"36.59500","0.01490","0.00412"
"36.61300","-0.00101","0.00570"
"36.71400","0.01493","0.02286"
"36.91400","0.19837","0.13158"
"37.11400","0.37472","1.61528"
"37.31400","0.55103","7.66190"
"37.49600","0.71137","17.70506"
"37.63400","0.83320","27.81585"
"37.69100","0.88326","32.46372"
"37.79200","0.86577","29.15566"
"37.89600","0.76924","19.07103"
"38.05000","0.63280","9.02079"
"38.25000","0.45634","2.05492"
"38.45000","0.27992","0.12815"
"38.65000","0.10337","0.01481"
"38.76800","-0.00071","-0.00053"
"38.77000","-0.00247","-0.00059"
"38.97000","0.10839","0.04748"
"39.17000","0.28578","0.44174"
"39.37000","0.46213","3.87259"
"39.57000","0.63865","12.55328"
"39.72400","0.77461","22.64022"
"39.84700","0.88267","32.33001"
"39.84900","0.88443","32.49664"
"39.99600","0.82111","24.05249"
"40.12100","0.70883","13.97934"
"40.30700","0.54468","4.71804"
"40.50700","0.36838","0.61681"
"40.70700","0.19196","0.04173"
"40.90700","0.01554","0.00543"
"40.92600","-0.00126","0.00191"
"41.02700","0.01492","0.02910"
"41.22700","0.19812","0.12744"
"41.42700","0.37447","1.54235"
"41.62700","0.55079","7.50313"
"41.80900","0.71113","17.50333"
"41.94600","0.83208","27.53897"
"42.00400","0.88302","32.26816"
"42.10500","0.86578","28.99579"
"42.20900","0.76902","18.89986"
"42.36400","0.63170","8.83578"
"42.56400","0.45525","1.96368"
"42.76400","0.27881","0.12937"
"42.96400","0.10228","0.01405"
"43.08000","-0.00005","0.00345"
"43.08200","-0.00181","0.00300"
"43.28200","0.10902","0.04894"
"43.48200","0.28644","0.42730"
"43.68200","0.46278","3.79873"
"43.88200","0.63933","12.44850"
"44.03600","0.77525","22.51705"
"44.15800","0.88246","32.12945"
"44.16000","0.88422","32.29538"
"44.30700","0.82083","23.87487"
"44.43200","0.70860","13.82755"
"44.61900","0.54357","4.58505"
"44.81900","0.36727","0.58751"
"45.01900","0.19085","0.04216"
"45.21900","0.01444","0.00245"
"45.23700","-0.00148","-0.00363"
"45.33800","0.01449","0.03016"
"45.53800","0.19784","0.12538"
"45.73800","0.37422","1.47813"
"45.93800","0.55053","7.36230"
"46.12000","0.71086","17.33776"
"46.25800","0.83269","27.43585"
"46.31600","0.88365","32.15371"
"46.41700","0.86631","28.88666"
"46.52100","0.76970","18.81218"
"46.67600","0.63240","8.76126"
"46.87600","0.45593","1.91573"
"47.07600","0.27951","0.11855"
"47.27600","0.10299","0.01287"
"47.39300","-0.00024","-0.00051"
"47.39500","-0.00200","-0.00062"
"47.59500","0.10882","0.04655"
"47.79500","0.28624","0.40573"
"47.99500","0.46258","3.69974"
"48.19500","0.63912","12.29249"
"48.35000","0.77591","22.40964"
"48.47100","0.88226","31.95645"
"48.47300","0.88402","32.12238"
"48.62000","0.82065","23.71450"
"48.74500","0.70840","13.69460"
"48.93200","0.54338","4.49828"
"49.13200","0.36709","0.55086"
"49.33200","0.19066","0.03315"
"49.53200","0.01426","-0.00014"
"49.55000","-0.00166","0.00191"
"49.65100","0.01442","0.02412"
"49.85100","0.19761","0.11625"
"50.05100","0.37400","1.41405"
"50.25100","0.55029","7.23656"
"50.43400","0.71153","17.23725"
"50.57200","0.83334","27.33378"
"50.62900","0.88345","31.99422"
"50.73000","0.86620","28.74286"
"50.83400","0.76951","18.67422"
"50.98900","0.63220","8.64805"
"51.18900","0.45577","1.86631"
"51.38900","0.27932","0.10564"
"51.58900","0.10280","0.01399"
"51.70600","-0.00042","-0.00402"
"51.70800","-0.00218","-0.00460"
"51.90800","0.10860","0.05001"
"52.10800","0.28600","0.37729"
"52.30800","0.46235","3.61338"
"52.50800","0.63889","12.15680"
"52.66300","0.77569","22.25432"
"52.78400","0.88203","31.78964"
"52.78600","0.88378","31.95592"
"52.93300","0.82047","23.58068"
"53.05800","0.70819","13.56157"
"53.24600","0.54227","4.37513"
"53.44600","0.36600","0.52193"
"53.64600","0.18957","0.02696"
"53.84600","0.01316","0.00018"
"53.86200","-0.00100","-0.00134"
"53.96300","0.01505","0.02226"
"54.16300","0.19827","0.11454"
"54.36300","0.37464","1.37812"
"54.56300","0.55094","7.16789"
"54.74600","0.71217","17.15216"
"54.88400","0.83399","27.25836"
"54.94000","0.88322","31.83862"
"55.04100","0.86585","28.58568"
"55.14500","0.76923","18.53393"
"55.30100","0.63106","8.49220"
"55.50100","0.45462","1.78871"
"55.70100","0.27818","0.09932"
"55.90100","0.10164","0.01265"
"56.01700","-0.00068","0.00069"
"56.01900","-0.00245","0.00025"
"56.21900","0.10826","0.04754"
"56.41900","0.28568","0.35411"
"56.61900","0.46204","3.52815"
"56.81900","0.63858","12.01726"
"56.97400","0.77535","22.10056"
"57.09600","0.88260","31.72055"
"57.09800","0.88436","31.88639"
"57.24500","0.82104","23.50528"
"57.37100","0.70787","13.42907"
"57.55900","0.54195","4.27377"
"57.75900","0.36567","0.48546"
"57.95900","0.18927","0.02798"
"58.15900","0.01286","0.00068"
"58.17500","-0.00129","0.00140"
"58.27600","0.01456","0.02297"
"58.47600","0.19791","0.09939"
"58.67600","0.37427","1.32050"
"58.87600","0.55059","7.05132"
"59.05900","0.71181","17.00464"
"59.19700","0.83365","27.09997"
"59.25400","0.88374","31.75761"
"59.35500","0.86647","28.52738"
"59.45900","0.76980","18.46930"
"59.61500","0.63161","8.42363"
"59.81500","0.45520","1.76186"
"60.01500","0.27874","0.09624"
"60.21500","0.10222","0.00635"
"60.33100","-0.00014","0.00161"
"60.33300","-0.00190","0.00073"
"60.53300","0.10884","0.04563"
"60.73300","0.28626","0.33883"
"60.93300","0.46261","3.46283"
"61.13300","0.63915","11.93860"
"61.28800","0.77592","22.01137"
"61.40900","0.88228","31.55728"
"61.41100","0.88403","31.72375"
"61.55800","0.82064","23.35102"
"61.68500","0.70660","13.22762"
"61.87400","0.53982","4.14232"
"62.07400","0.36350","0.44580"
"62.27400","0.18711","0.02144"
"62.47400","0.01071","-0.00205"
"62.48800","-0.00167","0.00133"
"62.58900","0.01425","0.02961"
"62.78900","0.19752","0.09637"
"62.98900","0.37389","1.26972"
"63.18900","0.55023","6.94089"
"63.37200","0.71142","16.85764"
"63.51000","0.83327","26.93547"
"63.56700","0.88336","31.59091"
"63.66800","0.86605","28.36317"
"63.77300","0.76849","18.23681"
"63.93100","0.62858","8.16923"
"64.13100","0.45214","1.64408"
"64.33100","0.27570","0.08632"
"64.53100","0.09918","0.00976"
"64.64400","-0.00053","0.00420"
"64.64600","-0.00230","0.00370"
"64.84600","0.10847","0.04285"
"65.04600","0.28586","0.32615"
"65.24600","0.46220","3.38723"
"65.44600","0.63874","11.80411"
"65.60100","0.77556","21.86633"
"65.72300","0.88275","31.47617"
"65.72500","0.88451","31.64359"
"65.87200","0.82118","23.28749"
"65.99800","0.70803","13.23341"
"66.18700","0.54124","4.12458"
"66.38700","0.36491","0.43700"
"66.58700","0.18852","0.02852"
"66.78700","0.01213","0.00127"
"66.80200","-0.00114","-0.00703"
"66.90300","0.01472","0.02037"
"67.10300","0.19805","0.08744"
"67.30300","0.37442","1.23704"
"67.50300","0.55075","6.86382"
"67.68700","0.71282","16.83242"
"67.82500","0.83465","26.94107"
"67.88000","0.88301","31.44242"
"67.98100","0.86587","28.23216"
"68.08600","0.76811","18.10440"
"68.24400","0.62818","8.07031"
"68.44400","0.45174","1.59746"
"68.64400","0.27530","0.07594"
"68.84400","0.09880","0.00408"
"68.95600","-0.00003","-0.00945"
"68.95800","-0.00180","-0.00978"
"69.15800","0.10891","0.04653"
"69.35800","0.28629","0.30183"
"69.55800","0.46266","3.33220"
"69.75800","0.63922","11.73742"
"69.91400","0.77691","21.86071"
"70.03400","0.88236","31.31289"
"70.03600","0.88412","31.47921"
"70.18300","0.82073","23.14270"
"70.31000","0.70672","13.04544"
"70.50000","0.53902","3.98082"
"70.70000","0.36269","0.41089"
"70.90000","0.18632","0.02486"
"71.10000","0.00994","-0.00194"
"71.11300","-0.00155","-0.00347"
"71.21400","0.01439","0.02518"
"71.41400","0.19762","0.09680"
"71.61400","0.37399","1.19753"
"71.81400","0.55033","6.76528"
"71.99800","0.71239","16.69956"
"72.13600","0.83421","26.79385"
"72.19200","0.88345","31.37292"
"72.29300","0.86637","28.16098"
"72.39800","0.76857","18.04128"
"72.55700","0.62778","7.97507"
"72.75700","0.45132","1.55515"
"72.95700","0.27490","0.08097"
"73.15700","0.09838","0.00945"
"73.26900","-0.00045","-0.00245"
"73.27100","-0.00222","-0.00316"
"73.47100","0.10846","0.04674"
"73.67100","0.28585","0.29673"
"73.87100","0.46220","3.26420"
"74.07100","0.63874","11.61393"
"74.22700","0.77642","21.71116"
"74.34800","0.88276","31.24647"
"74.35000","0.88452","31.41326"
"74.49700","0.82121","23.08309"
"74.62400","0.70718","12.98893"
"74.81400","0.53949","3.95060"
"75.01400","0.36314","0.38807"
"75.21400","0.18676","0.02266"
"75.41400","0.01037","-0.00726"
"75.42700","-0.00112","-0.01081"
"75.52800","0.01491","0.01931"
"75.72800","0.19807","0.09261"
"75.92800","0.37446","1.16444"
"76.12800","0.55079","6.71378"
"76.31200","0.71286","16.62472"
"76.45000","0.83469","26.72561"
"76.50500","0.88303","31.21725"
"76.60600","0.86566","27.99319"
"76.71100","0.76813","17.91521"
"76.87000","0.62737","7.88160"
"77.07000","0.45092","1.51746"
"77.27000","0.27449","0.08035"
"77.47000","0.09798","0.00733"
"77.58200","-0.00086","0.00252"
"77.58400","-0.00263","0.00254"
"77.78400","0.10807","0.04138"
"77.98400","0.28548","0.28705"
"78.18400","0.46183","3.18604"
"78.38400","0.63835","11.48864"
"78.54000","0.77602","21.57284"
"78.66100","0.88237","31.09344"
"78.66300","0.88414","31.26102"
"78.81000","0.82081","22.95324"
"78.93700","0.70679","12.87890"
"79.12700","0.53910","3.88520"
"79.32700","0.36276","0.37644"
"79.52700","0.18636","0.02772"
"79.72700","0.01000","-0.00204"
"79.74000","-0.00150","-0.00634"
"79.84100","0.01423","0.02152"
"80.04100","0.19759","0.08819"
"80.24100","0.37398","1.12696"
"80.44100","0.55034","6.62003"
"80.62500","0.71243","16.51431"
"80.76300","0.83422","26.56988"
"80.81900","0.88347","31.15218"
"80.92000","0.86619","27.93760"
"81.02500","0.76860","17.85205"
"81.18400","0.62783","7.83830"
"81.38400","0.45137","1.49108"
"81.58400","0.27494","0.07328"
"81.78400","0.09845","-0.00013"
"81.89600","-0.00043","-0.00475"
"81.89800","-0.00219","-0.00522"
"82.09800","0.10845","0.03816"
"82.29800","0.28588","0.27402"
"82.49800","0.46223","3.15445"
"82.69800","0.63873","11.44439"
"82.85400","0.77642","21.51018"
"82.97500","0.88277","31.03881"
"82.97700","0.88453","31.20576"
"83.12400","0.82129","22.89149"
"83.25200","0.70635","12.76315"
"83.44200","0.53867","3.81623"
"83.64200","0.36230","0.36181"
"83.84200","0.18594","0.02927"
"84.04200","0.00954","-0.00341"
"84.05400","-0.00108","-0.00133"
"84.15500","0.01476","0.02906"
"84.35500","0.19807","0.08081"
"84.55500","0.37446","1.10978"
"84.75500","0.55081","6.56175"
"84.93900","0.71289","16.44372"
"85.07700","0.83468","26.50652"
"85.13200","0.88302","31.00696"
"85.23300","0.86590","27.81681"
"85.33800","0.76820","17.73790"
"85.49900","0.62570","7.65264"
"85.69900","0.44922","1.42221"
"85.89900","0.27281","0.07623"
"86.09900","0.09632","0.00296"
"86.20900","-0.00082","-0.00121"
"86.21100","-0.00259","-0.00160"
"86.41100","0.10807","0.04003"
"86.61100","0.28548","0.26410"
"86.81100","0.46183","3.08021"
"87.01100","0.63840","11.32362"
"87.16700","0.77602","21.36705"
"87.28800","0.88238","30.89530"
"87.29000","0.88414","31.06277"
"87.43700","0.82086","22.76530"
"87.56500","0.70595","12.65866"
"87.75600","0.53739","3.72676"
"87.95600","0.36101","0.34157"
"88.15600","0.18464","0.02801"
"88.35600","0.00826","0.00041"
"88.36700","-0.00147","-0.00359"
"88.46800","0.01428","0.01695"
"88.66800","0.19763","0.08050"
"88.86800","0.37405","1.06255"
"89.06800","0.55041","6.48167"
"89.25200","0.71247","16.31149"
"89.39000","0.83429","26.37772"
"89.44600","0.88349","30.94787"
"89.54700","0.86631","27.76378"
"89.65200","0.76868","17.69491"
"89.81300","0.62618","7.60916"
"90.01300","0.44971","1.39828"
"90.21300","0.27328","0.06608"
"90.41300","0.09682","0.00627"
"90.52300","-0.00035","-0.00713"
"90.52500","-0.00211","-0.00722"
"90.72500","0.10856","0.03750"
"90.92500","0.28596","0.26043"
"91.12500","0.46233","3.04814"
"91.32500","0.63888","11.27262"
"91.48100","0.77653","21.31252"
"91.60200","0.88284","30.84562"
"91.60400","0.88460","31.01276"
"91.75100","0.82142","22.72153"
"91.87900","0.70648","12.61367"
"92.07000","0.53792","3.69388"
"92.27000","0.36156","0.32243"
"92.47000","0.18519","0.02413"
"92.67000","0.00879","-0.00601"
"92.68100","-0.00094","-0.01022"
"92.78200","0.01463","0.01475"
"92.98200","0.19817","0.08467"
"93.18200","0.37459","1.04428"
"93.38200","0.55093","6.44331"
"93.56600","0.71299","16.27518"
"93.70400","0.83482","26.32345"
"93.75900","0.88312","30.82774"
"93.86000","0.86607","27.67187"
"93.96500","0.76840","17.58322"
"94.12600","0.62589","7.52862"
"94.32600","0.44944","1.36042"
"94.52600","0.27298","0.06338"
"94.72600","0.09652","0.00623"
"94.83600","-0.00063","-0.00375"
"94.83800","-0.00240","-0.00393"
"95.03800","0.10825","0.03615"
"95.23800","0.28566","0.24192"
"95.43800","0.46203","2.99925"
"95.63800","0.63855","11.19056"
"95.79500","0.77709","21.27816"
"95.91500","0.88253","30.72654"
"95.91700","0.88429","30.89338"
"96.06400","0.82113","22.62385"
"96.19200","0.70620","12.53626"
"96.38300","0.53764","3.64748"
"96.58300","0.36130","0.31947"
"96.78300","0.18490","0.02740"
"96.98300","0.00851","-0.00546"
"96.99400","-0.00122","-0.00504"
"97.09500","-0.01763","0.00741"
"97.29500","0.05802","0.01942"
"97.49500","0.12902","0.03755"
"97.69500","0.19969","0.08488"
"97.89500","0.26992","0.19101"
"98.05600","0.32695","0.50200"
"98.05800","0.32764","0.50802"
"98.07800","0.33449","0.56553"
"98.09800","0.33915","0.60528"
"98.11800","0.34271","0.64098"
"98.13800","0.34571","0.67285"
"98.15800","0.34936","0.72448"
"98.17800","0.35628","0.80980"
"98.19800","0.36519","0.92979"
"98.21800","0.37407","1.05462"
"98.23800","0.38232","1.18490"
"98.25800","0.38996","1.31475"
"98.27800","0.39720","1.44089"
"98.29800","0.40433","1.57692"
"98.31800","0.41159","1.72693"
"98.33800","0.41884","1.89034"
"98.35800","0.42585","2.04989"
"98.37800","0.43276","2.21013"
"98.39800","0.43973","2.39274"
"98.41800","0.44689","2.57959"
"98.43800","0.45416","2.77197"
"98.45800","0.46125","2.97653"
"98.47800","0.46814","3.19193"
"98.49800","0.47504","3.41371"
"98.51800","0.48215","3.64614"
"98.53800","0.48939","3.88775"
"98.55800","0.49656","4.14212"
"98.57800","0.50350","4.39477"
"98.59800","0.51035","4.65723"
"98.61800","0.51740","4.92985"
"98.63800","0.52466","5.22366"
"98.65800","0.53192","5.51777"
"98.67800","0.53901","5.81771"
"98.69800","0.54594","6.12826"
"98.71800","0.55292","6.45777"
"98.73800","0.56005","6.78832"
"98.75800","0.56721","7.12657"
"98.77800","0.57428","7.47471"
"98.79800","0.58121","7.82217"
"98.81800","0.58816","8.18733"
"98.83800","0.59524","8.56495"
"98.85800","0.60236","8.95165"
"98.87800","0.60944","9.34618"
"98.89800","0.61646","9.73395"
"98.91800","0.62352","10.14036"
"98.93800","0.63062","10.56109"
"98.95800","0.63764","10.98732"
"98.97800","0.64461","11.41934"
"98.99800","0.65157","11.83807"
"99.01800","0.65868","12.27635"
"99.03800","0.66588","12.73701"
"99.05800","0.67293","13.19896"
"99.07800","0.67985","13.66748"
"99.09800","0.68672","14.13027"
"99.11800","0.69379","14.61858"
"99.13800","0.70106","15.12866"
"99.15800","0.70823","15.64072"
"99.17800","0.71518","16.14689"
"99.19800","0.72210","16.65080"
"99.21800","0.72920","17.17565"
"99.23800","0.73652","17.72374"
"99.25800","0.74377","18.26585"
"99.27800","0.75073","18.80562"
"99.29800","0.75753","19.33941"
"99.31800","0.76444","19.89653"
"99.33800","0.77163","20.47897"
"99.35800","0.77892","21.05824"
"99.37800","0.78604","21.63249"
"99.39800","0.79292","22.20341"
"99.41800","0.79980","22.78535"
"99.43800","0.80689","23.39342"
"99.45800","0.81407","23.99879"
"99.47800","0.82114","24.59058"
"99.49800","0.82807","25.19227"
"99.51800","0.83494","25.79856"
"99.53800","0.84195","26.42737"
"99.55800","0.84910","27.07595"
"99.57800","0.85624","27.71750"
"99.59800","0.86327","28.34554"
"99.61800","0.87028","28.98223"
"99.63800","0.87734","29.63634"
"99.65800","0.88443","30.30350"
"99.67800","0.89146","30.95989"
"99.69800","0.89848","31.60509"
"99.71800","0.90562","32.25961"
"99.73800","0.91290","32.93303"
"99.75800","0.92013","33.61968"
"99.77800","0.92713","34.29112"
"99.79800","0.93398","34.93810"
"99.81800","0.94091","35.59042"
"99.83800","0.94813","36.27160"
"99.85800","0.95543","36.96141"
"99.87800","0.96245","37.63863"
"99.89800","0.96927","38.28687"
"99.91800","0.97613","38.92393"
"99.93800","0.98327","39.58370"
"99.95800","0.99059","40.26236"
"99.97800","0.99772","40.92364"
"99.99800","1.00457","41.56441"
"100.01800","1.01137","42.19901"
"100.03800","1.01840","42.86066"
"100.05800","1.02565","43.52773"
"100.07800","1.03281","44.18317"
"100.09800","1.03979","44.82610"
"100.11800","1.04665","45.46438"
"100.13800","1.05363","46.11457"
"100.15800","1.06082","46.78000"
"100.17800","1.06801","47.43216"
"100.19800","1.07508","48.06285"
"100.21800","1.08197","48.68697"
"100.23800","1.08894","49.34140"
"100.25800","1.09616","50.01174"
"100.27800","1.10339","50.67184"
"100.29800","1.11051","51.30503"
"100.31800","1.11754","51.92109"
"100.33800","1.12459","52.56393"
"100.35800","1.13172","53.21410"
"100.37800","1.13877","53.85134"
"100.39800","1.14572","54.46490"
"100.41800","1.15268","55.06630"
"100.43800","1.15982","55.69511"
"100.45800","1.16703","56.34947"
"100.47800","1.17402","56.98721"
"100.49800","1.18087","57.59696"
"100.51800","1.18778","58.19831"
"100.53800","1.19486","58.81461"
"100.55800","1.20208","59.45551"
"100.57800","1.20922","60.10350"
"100.59800","1.21616","60.72922"
"100.61800","1.22303","61.33577"
"100.63800","1.23010","61.95812"
"100.65800","1.23733","62.60170"
"100.67800","1.24448","63.23066"
"100.69800","1.25138","63.83139"
"100.71800","1.25817","64.43198"
"100.73800","1.26516","65.05405"
"100.75800","1.27243","65.70301"
"100.77800","1.27978","66.34619"
"100.79800","1.28696","66.97588"
"100.81800","1.29392","67.58707"
"100.83800","1.30086","68.19951"
"100.85800","1.30796","68.83541"
"100.87800","1.31512","69.45847"
"100.89800","1.32221","70.05804"
"100.91800","1.32920","70.65488"
"100.93800","1.33615","71.27160"
"100.95800","1.34321","71.90737"
"100.97800","1.35033","72.54478"
"100.99800","1.35741","73.15636"
"101.01800","1.36442","73.74588"
"101.03800","1.37145","74.35895"
"101.05800","1.37854","74.99850"
"101.07800","1.38559","75.62925"
"101.09800","1.39254","76.22818"
"101.11800","1.39950","76.81799"
"101.13800","1.40658","77.42248"
"101.15800","1.41378","78.05744"
"101.17800","1.42088","78.68371"
"101.19800","1.42781","79.28455"
"101.21800","1.43466","79.87920"
"101.23800","1.44165","80.47929"
"101.25800","1.44892","81.10470"
"101.27800","1.45619","81.74157"
"101.29800","1.46318","82.35359"
"101.31800","1.47006","82.95402"
"101.33800","1.47709","83.56420"
"101.35800","1.48438","84.20385"
"101.37800","1.49172","84.83102"
"101.39800","1.49881","85.43343"
"101.41800","1.50562","86.01247"
"101.43800","1.51243","86.59176"
"101.45800","1.51951","87.20699"
"101.47800","1.52679","87.82880"
"101.49800","1.53397","88.43589"
"101.51800","1.54092","89.01570"
"101.53800","1.54776","89.59516"
"101.55800","1.55476","90.20251"
"101.57800","1.56192","90.81671"
"101.59800","1.56905","91.41509"
"101.61800","1.57606","91.99316"
"101.63800","1.58300","92.56788"
"101.65800","1.59001","93.17209"
"101.67800","1.59714","93.79365"
"101.69800","1.60425","94.39738"
"101.71800","1.61126","94.97270"
"101.73800","1.61821","95.54258"
"101.75800","1.62530","96.14276"
"101.77800","1.63247","96.75974"
"101.79800","1.63952","97.34674"
"101.81800","1.64649","97.91640"
"101.83800","1.65349","98.48484"
"101.85800","1.66071","99.09048"
"101.87800","1.66804","99.71860"
"101.89800","1.67515","100.31716"
"101.91800","1.68204","100.88173"
"101.93800","1.68891","101.43356"
"101.95800","1.69602","102.01328"
"101.97800","1.70328","102.61555"
"101.99800","1.71037","103.20103"
"102.01800","1.71724","103.74792"
"102.03800","1.72406","104.29290"
"102.05800","1.73112","104.85679"
"102.07800","1.73840","105.46197"
"102.08000","1.73913","105.52195"
"102.25500","1.70789","98.88770"
"102.43400","1.64300","88.83517"
"102.63300","1.57291","78.90002"
"102.83300","1.50226","69.58765"
"103.03300","1.43165","60.89931"
"103.23300","1.36112","52.82140"
"103.43300","1.29055","45.25418"
"103.63300","1.22020","38.24616"
"103.83300","1.14932","31.68869"
"104.03300","1.07875","25.63774"
"104.23300","1.00852","20.16274"
"104.43300","0.93756","15.23269"
"104.63300","0.86736","11.01158"
"104.83300","0.79686","7.48191"
"105.03300","0.72592","4.69012"
"105.23300","0.65568","2.66311"
"105.43300","0.58508","1.27171"
"105.63300","0.51421","0.47840"
"105.83300","0.44397","0.15130"
"106.03300","0.37340","0.06028"
"106.16400","0.32696","0.05788"
"106.16600","0.32626","0.05722"
"106.36600","0.36691","0.11779"
"106.56600","0.43822","0.38930"
"106.60500","0.45236","0.50364"
"106.60700","0.45310","0.50957"
"106.60900","0.45383","0.51652"
"106.61100","0.45457","0.52950"
"106.61300","0.45537","0.55262"
"106.61500","0.45627","0.58594"
"106.61700","0.45736","0.62959"
"106.61900","0.45877","0.68324"
"106.62100","0.46059","0.74870"
"106.62300","0.46297","0.82781"
"106.62500","0.46604","0.92248"
"106.62700","0.46993","1.03770"
"106.62900","0.47479","1.17944"
"106.63100","0.48075","1.35428"
"106.63300","0.48795","1.57017"
"106.63500","0.49652","1.83768"
"106.63700","0.50659","2.16893"
"106.63900","0.51827","2.57744"
"106.64100","0.53166","3.07978"
"106.64300","0.54688","3.69502"
"106.64500","0.56402","4.44229"
"106.64700","0.58317","5.34119"
"106.64900","0.60439","6.41540"
"106.65100","0.62777","7.68645"
"106.65300","0.65336","9.17480"
"106.65500","0.68121","10.90076"
"106.65700","0.71138","12.88434"
"106.65900","0.74391","15.14288"
"106.66100","0.77882","17.69021"
"106.66300","0.81613","20.53763"
"106.66500","0.85584","23.69546"
"106.66700","0.89795","27.17138"
"106.66900","0.94242","30.96830"
"106.67100","0.98924","35.08781"
"106.67300","1.03835","39.52809"
"106.67500","1.08971","44.28378"
"106.67700","1.14327","49.34557"
"106.67900","1.19897","54.69489"
"106.68100","1.25671","60.30472"
"106.68300","1.31637","66.14560"
"106.68500","1.37779","72.18185"
"106.68700","1.44079","78.32884"
"106.68900","1.50519","83.78794"
"106.69100","1.57080","87.47853"
"106.69300","1.63743","89.24091"
"106.69500","1.70492","89.36345"
"106.69700","1.77313","88.15919"
"106.69900","1.84191","85.87811"
"106.70100","1.91116","82.73107"
"106.70300","1.98080","78.90777"
"106.70500","2.05074","74.57414"
"106.70700","2.12092","69.87342"
"106.70900","2.19131","64.92719"
"106.71100","2.26187","59.84534"
"106.71300","2.33257","54.72232"
"106.71500","2.40341","49.63783"
"106.71700","2.47435","44.66072"
"106.71900","2.54541","39.84549"
"106.72100","2.61656","35.23702"
"106.72300","2.68779","30.87140"
"106.72500","2.75911","26.77369"
"106.72700","2.83050","22.95991"
"106.72900","2.90195","19.43523"
"106.73100","2.97345","16.19952"
"106.73300","3.04500","13.25444"
"106.73500","3.11658","10.59945"
"106.73700","3.18819","8.22502"
"106.73900","3.25981","6.11716"
"106.74100","3.33144","4.26293"
"106.74300","3.40307","2.64952"
"106.74500","3.47468","1.26524"
"106.74700","3.54627","0.09372"
"106.74900","3.61783","-0.88496"
"106.75100","3.68935","-1.68776"
"106.75300","3.76083","-2.33311"
"106.75500","3.83226","-2.83995"
"106.75700","3.90364","-3.22399"
"106.75900","3.97498","-3.49921"
"106.76100","4.04626","-3.68108"
"106.76300","4.11750","-3.78197"
"106.76500","4.18868","-3.81135"
"106.76700","4.25982","-3.77903"
"106.76900","4.33091","-3.69570"
"106.77100","4.40196","-3.57075"
"106.77300","4.47297","-3.41552"
"106.77500","4.54394","-3.23776"
"106.77700","4.61487","-3.04215"
"106.77900","4.68577","-2.83158"
"106.78100","4.75664","-2.61088"
"106.78300","4.82748","-2.38750"
"106.78500","4.89830","-2.16701"
"106.78700","4.96910","-1.95167"
"106.78900","5.03987","-1.74247"
"106.79100","5.11062","-1.54127"
"106.79300","5.18136","-1.34947"
"106.79500","5.25207","-1.16832"
"106.79700","5.32278","-1.00017"
"106.79900","5.39347","-0.84591"
"106.80100","5.46414","-0.70350"
"106.80300","5.53481","-0.57280"
"106.80500","5.60547","-0.45608"
"106.80700","5.67613","-0.35442"
"106.80900","5.74677","-0.26476"
"106.81100","5.81741","-0.18349"
"106.81300","5.88805","-0.10820"
"106.81500","5.95868","-0.03991"
"106.81700","6.02931","0.01860"
"106.81900","6.09993","0.06618"
"106.82100","6.17055","0.10497"
"106.82300","6.24117","0.13710"
"106.82500","6.31179","0.16435"
"106.82700","6.38240","0.18672"
"106.82900","6.45301","0.20275"
"106.83100","6.52362","0.21221"
"106.83300","6.59421","0.21653"
"106.83500","6.66481","0.21901"
"106.83700","6.73540","0.22010"
"106.83900","6.80598","0.21717"
"106.84100","6.87657","0.21066"
"106.84300","6.94716","0.20614"
"106.84500","7.01775","0.20452"
"106.84700","7.08834","0.20156"
"106.84900","7.15894","0.19523"
"106.85100","7.22954","0.18680"
"106.85300","7.30014","0.17794"
"106.85500","7.37074","0.16954"
"106.85700","7.44134","0.16217"
"106.85900","7.51194","0.15484"
"106.86100","7.58255","0.14479"
"106.86300","7.65315","0.13262"
"106.86500","7.72376","0.12104"
"106.86700","7.79437","0.11070"
"106.86900","7.86497","0.10067"
"106.87100","7.93558","0.09103"
"106.87300","8.00618","0.08253"
"106.87500","8.07678","0.07527"
"106.87700","8.14737","0.06980"
"106.87900","8.21796","0.06521"
"106.88100","8.28854","0.05907"
"106.88300","8.35912","0.05101"
"106.88500","8.42970","0.04290"
"106.88700","8.50028","0.03708"
"106.88900","8.57086","0.03516"
"106.89100","8.64144","0.03459"
"106.89300","8.71202","0.03194"
"106.89500","8.78261","0.02740"
"106.89700","8.85319","0.02259"
"106.89900","8.92377","0.02038"
"106.90100","8.99434","0.02200"
"106.90300","9.06492","0.02407"
"106.90500","9.13550","0.02312"
"106.90700","9.20608","0.02210"
"106.90900","9.27666","0.02446"
"106.91100","9.34725","0.02735"
"106.91300","9.41784","0.02603"
"106.91500","9.48843","0.02281"
"106.91700","9.55903","0.02295"
"106.91900","9.62963","0.02671"
"106.92100","9.70023","0.03144"
"106.92300","9.77083","0.03481"
"106.92500","9.84144","0.03654"
"106.92700","9.91205","0.03766"
"106.92900","9.98266","0.03868"
"106.93100","10.05327","0.04069"
"106.93300","10.12389","0.04462"
"106.93500","10.19450","0.04864"
"106.93700","10.26512","0.05188"
"106.93900","10.33573","0.05448"
"106.94100","10.40634","0.05621"
"106.94300","10.47694","0.05705"
"106.94500","10.54754","0.05788"
"106.94700","10.61813","0.05890"
"106.94900","10.68872","0.05926"
"106.95100","10.75931","0.05967"
"106.95300","10.82990","0.06111"
"106.95500","10.90048","0.06209"
"106.95700","10.97106","0.05947"
"106.95900","11.04163","0.05346"
"106.96100","11.11220","0.04825"
"106.96300","11.18277","0.04737"
"106.96500","11.25333","0.04897"
"106.96700","11.32388","0.05074"
"106.96900","11.39444","0.05128"
"106.97100","11.46498","0.05090"
"106.97300","11.53553","0.05051"
"106.97500","11.60607","0.05145"
"106.97700","11.67661","0.05239"
"106.97900","11.74715","0.05088"
"106.98100","11.81768","0.04844"
"106.98300","11.88821","0.04766"
"106.98500","11.95875","0.04802"
"106.98700","12.02928","0.04719"
"106.98900","12.09982","0.04488"
"106.99100","12.17036","0.04159"
"106.99300","12.24090","0.03832"
"106.99500","12.31145","0.03655"
"106.99700","12.38200","0.03784"
"106.99900","12.45255","0.04056"
"107.00100","12.52311","0.04244"
"107.00300","12.59367","0.04229"
"107.00500","12.66423","0.04211"
"107.00700","12.73479","0.04336"
"107.00900","12.80534","0.04539"
"107.01100","12.87590","0.04787"
"107.01300","12.94646","0.05058"
"107.01500","13.01702","0.05293"
"107.01700","13.08758","0.05472"
"107.01900","13.15815","0.05648"
"107.02100","13.22871","0.05694"
"107.02300","13.29927","0.05458"
"107.02500","13.36982","0.05046"
"107.02700","13.44038","0.04762"
"107.02900","13.51094","0.04756"
"107.03100","13.58149","0.04866"
"107.03300","13.65205","0.04988"
"107.03500","13.72262","0.05028"
"107.03700","13.79318","0.05015"
"107.03900","13.86374","0.04987"
"107.04100","13.93431","0.05004"
"107.04300","14.00488","0.05084"
"107.04500","14.07544","0.05196"
"107.04700","14.14601","0.05233"
"107.04900","14.21656","0.05036"
"107.05100","14.28712","0.04690"
"107.05300","14.35768","0.04569"
"107.05500","14.42824","0.04427"
"107.05700","14.49880","0.04019"
"107.05900","14.56936","0.03533"
"107.06100","14.63993","0.03446"
"107.06300","14.71049","0.03582"
"107.06500","14.78106","0.03537"
"107.06700","14.85163","0.03315"
"107.06900","14.92220","0.03277"
"107.07100","14.99276","0.03433"
"107.07300","15.06333","0.03525"
"107.07500","15.13390","0.03565"
"107.07700","15.20447","0.03729"
"107.07900","15.27503","0.03872"
"107.08100","15.34560","0.04037"
"107.08300","15.41617","0.04238"
"107.08500","15.48674","0.04349"
"107.08700","15.55731","0.04337"
"107.08900","15.62787","0.04377"
"107.09100","15.69843","0.04541"
"107.09300","15.76899","0.04655"
"107.09500","15.83955","0.04690"
"107.09700","15.91010","0.04781"
"107.09900","15.98066","0.04767"
"107.10100","16.05121","0.04629"
"107.10300","16.12177","0.04525"
"107.10500","16.19232","0.04602"
"107.10700","16.26288","0.04744"
"107.10900","16.33343","0.04799"
"107.11100","16.40398","0.04720"
"107.11300","16.47453","0.04664"
"107.11500","16.54508","0.04755"
"107.11700","16.61562","0.05018"
"107.11900","16.68616","0.05310"
"107.12100","16.75670","0.05234"
"107.12300","16.82724","0.04800"
"107.12500","16.89777","0.04523"
"107.12700","16.96830","0.04501"
"107.12900","17.03884","0.04286"
"107.13100","17.10937","0.03764"
"107.13300","17.17991","0.03358"
"107.13500","17.25045","0.03332"
"107.13700","17.32099","0.03440"
"107.13900","17.39153","0.03403"
"107.14100","17.46208","0.03241"
"107.14300","17.53263","0.03170"
"107.14500","17.60319","0.03190"
"107.14700","17.67375","0.03337"
"107.14900","17.74432","0.03480"
"107.15100","17.81488","0.03556"
"107.15300","17.88545","0.03484"
"107.15500","17.95601","0.03461"
"107.15700","18.02658","0.03635"
"107.15900","18.09715","0.03843"