File: data/instron/Sample28_Static.is_tcyclic_RawData/Specimen_RawData_1.csv
Strain : Tensile strain (Extension) gauge length,"100.00000",mm

Time,Extension,Load
(s),(mm),(N)
"0.00000","0.00000","0.08832"
"0.20000","0.04354","0.17706"
"0.40000","0.10540","0.34458"
"0.60000","0.16625","0.58842"
"0.80000","0.22697","0.95987"
"1.00000","0.28789","1.49254"
"1.20000","0.34881","2.24059"
"1.40000","0.40966","3.26912"
"1.60000","0.47026","4.66719"
"1.80000","0.53133","6.46688"
"2.00000","0.59206","8.74954"
"2.20000","0.65284","11.51520"
"2.40000","0.71357","14.81175"
"2.60000","0.77463","18.55941"
"2.80000","0.83534","22.66885"
"3.00000","0.89609","27.14377"
"3.20000","0.95724","31.79649"
"3.40000","1.01787","36.67248"
"3.55400","1.06487","40.52814"
"3.55600","1.06547","40.57724"
"3.75600","1.07402","39.79595"
"3.95600","1.07211","38.77728"
"4.15600","1.07165","38.17836"
"4.35600","1.07156","37.73345"
"4.55600","1.07156","37.37707"
"4.75600","1.07156","37.08998"
"4.95600","1.07156","36.81667"
"5.15600","1.07156","36.58894"
"5.35600","1.07156","36.38724"
"5.55600","1.07156","36.19885"
"5.75600","1.07148","36.02920"
"5.95600","1.07153","35.89227"
"6.15600","1.07156","35.73631"
"6.35600","1.07156","35.60043"
"6.55600","1.07156","35.47247"
"6.75600","1.07156","35.36375"
"6.95600","1.07156","35.23626"
"7.15600","1.07156","35.14106"
"7.35600","1.07156","35.04070"
"7.55600","1.07156","34.94424"
"7.75600","1.07156","34.85123"
"7.95600","1.07156","34.76495"
"8.15600","1.07156","34.67973"
"8.35600","1.07156","34.59279"
"8.55600","1.07156","34.51683"
"8.75600","1.07156","34.44738"
"8.95600","1.07156","34.37362"
"9.15600","1.07156","34.30512"
"9.35600","1.07156","34.24113"
"9.55600","1.07156","34.17491"
"9.75600","1.07156","34.11116"
"9.95600","1.07156","34.04050"
"10.15600","1.07156","33.98202"
"10.35600","1.07156","33.92836"
"10.55600","1.07156","33.87648"
"10.75600","1.07156","33.82644"
"10.95600","1.07156","33.75998"
"11.15600","1.07156","33.72041"
"11.35600","1.07156","33.65929"
"11.55600","1.07156","33.61824"
"11.75600","1.07156","33.56022"
"11.95600","1.07156","33.51714"
"12.15600","1.07156","33.47694"
"12.35600","1.07156","33.42983"
"12.55600","1.07156","33.38214"
"12.75600","1.07156","33.34149"
"12.95600","1.07156","33.30296"
"13.15600","1.07156","33.26030"
"13.35600","1.07156","33.22469"
"13.55600","1.07156","33.18779"
"13.75600","1.07156","33.14725"
"13.95600","1.07156","33.10719"
"14.15600","1.07156","33.07129"
"14.35600","1.07156","33.03377"
"14.55600","1.07156","32.99794"
"14.75600","1.07156","32.96633"
"14.95600","1.07156","32.92863"
"15.15600","1.07156","32.89739"
"15.35600","1.07156","32.86641"
"15.55600","1.07156","32.82990"
"15.75600","1.07156","32.80004"
"15.95600","1.07156","32.76954"
"16.15600","1.07156","32.73888"
"16.35600","1.07156","32.71136"
"16.55600","1.07156","32.68317"
"16.75600","1.07156","32.64891"
"16.95600","1.07156","32.62055"
"17.15600","1.07156","32.59212"
"17.35600","1.07156","32.56018"
"17.55600","1.07156","32.53622"
"17.75600","1.07156","32.50252"
"17.95600","1.07156","32.47913"
"18.15600","1.07156","32.45404"
"18.35600","1.07156","32.42995"
"18.55600","1.07156","32.40399"
"18.75600","1.07156","32.37483"
"18.95600","1.07156","32.35123"
"19.15600","1.07156","32.32917"
"19.35600","1.07156","32.29869"
"19.55600","1.07156","32.27225"
"19.75600","1.07156","32.25373"
"19.95600","1.07156","32.22412"
"20.15600","1.07156","32.20224"
"20.35600","1.07156","32.18154"
"20.55600","1.07156","32.15435"
"20.75600","1.07156","32.14053"
"20.95600","1.07156","32.11214"
"21.15600","1.07156","32.09820"
"21.35600","1.07156","32.07589"
"21.55600","1.07156","32.04389"
"21.75600","1.07156","32.02676"
"21.95600","1.07156","32.00111"
"22.15600","1.07156","31.99490"
"22.35600","1.07156","31.97452"
"22.55600","1.07156","31.94380"
"22.75600","1.07156","31.93130"
"22.95600","1.07156","31.90792"
"23.15600","1.07156","31.88956"
"23.35600","1.07156","31.87441"
"23.55500","1.07156","31.85298"
"23.58800","1.07156","31.85353"
"23.78800","1.02388","25.90247"
"23.98800","0.96252","19.40613"
"24.18800","0.90175","14.30622"
"24.38800","0.84092","10.18959"
"24.58800","0.77984","6.96071"
"24.78800","0.71918","4.56176"
"24.98800","0.65847","2.86975"
"25.18800","0.59740","1.72878"
"25.38800","0.53675","1.01792"
"25.58800","0.47584","0.59116"
"25.78800","0.41511","0.33957"
"25.98800","0.35415","0.17669"
"26.18800","0.29333","0.09010"
"26.38800","0.23247","0.04809"
"26.58800","0.17170","0.02960"
"26.78800","0.11080","0.01073"
"26.98800","0.04989","0.00217"
"27.13000","0.00661","0.00304"
"27.13200","0.00601","0.00378"
"27.33200","0.04018","0.01327"
"27.53200","0.10211","0.03292"
"27.73200","0.16303","0.06479"
"27.93200","0.22374","0.12642"
"28.13200","0.28485","0.22541"
"28.33200","0.34555","0.41641"
"28.53200","0.40637","0.72295"
"28.73200","0.46718","1.21337"
"28.93200","0.52818","2.01264"
"29.13200","0.58880","3.23907"
"29.33200","0.64970","5.04940"
"29.53200","0.71050","7.57691"
"29.73200","0.77140","10.86974"
"29.93200","0.83221","14.88531"
"30.13200","0.89299","19.54684"
"30.33200","0.95415","24.70259"
"30.53200","1.01460","30.27922"
"30.71800","1.07139","35.75190"
"30.72000","1.07199","35.80925"
"30.92000","1.08060","35.73160"
"31.12000","1.07874","35.06342"
"31.32000","1.07822","34.70380"
"31.52000","1.07819","34.45807"
"31.72000","1.07812","34.26363"
"31.92000","1.07813","34.09904"
"32.12000","1.07813","33.97236"
"32.32000","1.07813","33.83854"
"32.52000","1.07813","33.73535"
"32.72000","1.07803","33.64043"
"32.92000","1.07809","33.55487"
"33.12000","1.07813","33.47777"
"33.32000","1.07813","33.40420"
"33.52000","1.07813","33.32683"
"33.72000","1.07813","33.26567"
"33.92000","1.07813","33.19985"
"34.12000","1.07813","33.13782"
"34.32000","1.07813","33.09312"
"34.52000","1.07813","33.03726"
"34.72000","1.07813","32.98783"
"34.92000","1.07813","32.93360"
"35.12000","1.07813","32.88465"
"35.32000","1.07813","32.85096"
"35.52000","1.07813","32.80458"
"35.72000","1.07813","32.76537"
"35.92000","1.07813","32.72736"
"36.12000","1.07813","32.68854"
"36.32000","1.07813","32.65421"
"36.52000","1.07813","32.61565"
"36.72000","1.07813","32.57666"
"36.92000","1.07813","32.55271"
"37.12000","1.07813","32.52280"
"37.32000","1.07813","32.48717"
"37.52000","1.07813","32.45220"
"37.72000","1.07813","32.42284"
"37.92000","1.07813","32.39757"
"38.12000","1.07813","32.36112"
"38.32000","1.07813","32.33364"
"38.52000","1.07813","32.30809"
"38.72000","1.07813","32.27016"
"38.92000","1.07813","32.25578"
"39.12000","1.07813","32.22792"
"39.32000","1.07813","32.20486"
"39.52000","1.07813","32.18254"
"39.72000","1.07813","32.15444"
"39.92000","1.07813","32.12913"
"40.12000","1.07813","32.11144"
"40.32000","1.07813","32.08384"
"40.52000","1.07813","32.06431"
"40.72000","1.07813","32.03940"
"40.92000","1.07813","32.02285"
"41.12000","1.07813","31.99475"
"41.32000","1.07813","31.97939"
"41.52000","1.07813","31.95315"
"41.72000","1.07813","31.94776"
"41.92000","1.07813","31.92128"
"42.12000","1.07813","31.90159"
"42.32000","1.07813","31.88002"
"42.52000","1.07813","31.86611"
"42.72000","1.07813","31.85624"
"42.92000","1.07813","31.82625"
"43.12000","1.07813","31.81192"
"43.32000","1.07813","31.79243"
"43.52000","1.07813","31.77260"
"43.72000","1.07813","31.75646"
"43.92000","1.07813","31.73660"
"44.12000","1.07813","31.73183"
"44.32000","1.07813","31.70505"
"44.52000","1.07813","31.69393"
"44.72000","1.07813","31.67387"
"44.92000","1.07813","31.66433"
"45.12000","1.07813","31.64570"
"45.32000","1.07813","31.62235"
"45.52000","1.07813","31.61510"
"45.72000","1.07813","31.59648"
"45.92000","1.07813","31.58289"
"46.12000","1.07813","31.57568"
"46.32000","1.07813","31.55579"
"46.52000","1.07813","31.54044"
"46.72000","1.07813","31.52407"
"46.92000","1.07813","31.50397"
"47.12000","1.07813","31.50179"
"47.32000","1.07813","31.48924"
"47.52000","1.07813","31.47280"
"47.72000","1.07813","31.45839"
"47.92000","1.07813","31.44349"
"48.12000","1.07813","31.42557"
"48.32000","1.07813","31.41216"
"48.52000","1.07813","31.40718"
"48.72000","1.07813","31.39132"
"48.92000","1.07813","31.37869"
"49.12000","1.07813","31.36690"
"49.32000","1.07813","31.35027"
"49.52000","1.07813","31.34295"
"49.72000","1.07813","31.32559"
"49.92000","1.07813","31.31479"
"50.12000","1.07813","31.30557"
"50.32000","1.07813","31.29644"
"50.52000","1.07813","31.28197"
"50.71900","1.07813","31.26750"
"50.75200","1.07813","31.26949"
"50.95200","1.03061","25.30884"
"51.15200","0.96920","18.79961"
"51.35200","0.90859","13.69012"
"51.55200","0.84748","9.60490"
"51.75200","0.78658","6.43163"
"51.95200","0.72585","4.12567"
"52.15200","0.66521","2.52414"
"52.35200","0.60399","1.47262"
"52.55200","0.54338","0.83484"
"52.75200","0.48273","0.47461"
"52.95200","0.42166","0.25277"
"53.15200","0.36077","0.13811"
"53.35200","0.30010","0.05982"
"53.55200","0.23916","0.03656"
"53.75200","0.17820","0.01788"
"53.95200","0.11761","0.00541"
"54.15200","0.05654","-0.00089"
"54.29400","0.01319","-0.00278"
"54.29600","0.01258","-0.00246"
"54.49600","0.04676","0.00416"
"54.69600","0.10852","0.02391"
"54.89600","0.16965","0.04635"
"55.09600","0.23050","0.08843"
"55.29600","0.29120","0.17088"
"55.49600","0.35214","0.31729"
"55.69600","0.41319","0.57587"
"55.89600","0.47361","0.99412"
"56.09600","0.53465","1.67957"
"56.29600","0.59559","2.80365"
"56.49600","0.65634","4.48456"
"56.69600","0.71685","6.88546"
"56.89600","0.77811","10.10194"
"57.09600","0.83878","14.06129"
"57.29600","0.89947","18.67127"
"57.49600","0.96054","23.84584"
"57.69600","1.02142","29.48959"
"57.88300","1.07807","35.04593"
"57.88500","1.07866","35.10583"
"58.08500","1.08752","35.13658"
"58.28500","1.08557","34.48835"
"58.48500","1.08515","34.15980"
"58.68500","1.08506","33.94047"
"58.88500","1.08506","33.75718"
"59.08500","1.08497","33.62072"
"59.28500","1.08497","33.50169"
"59.48500","1.08502","33.39571"
"59.68500","1.08502","33.28841"
"59.88500","1.08502","33.20549"
"60.08500","1.08502","33.13131"
"60.28500","1.08503","33.06247"
"60.48500","1.08503","33.00290"
"60.68500","1.08503","32.92870"
"60.88500","1.08503","32.88528"
"61.08500","1.08504","32.83114"
"61.28500","1.08506","32.77615"
"61.48500","1.08506","32.73594"
"61.68500","1.08506","32.67903"
"61.88500","1.08506","32.64416"
"62.08500","1.08506","32.59678"
"62.28500","1.08506","32.56401"
"62.48500","1.08506","32.52439"
"62.68500","1.08506","32.49002"
"62.88500","1.08506","32.44426"
"63.08500","1.08506","32.42029"
"63.28500","1.08506","32.39143"
"63.48500","1.08506","32.35748"
"63.68500","1.08506","32.32522"
"63.88500","1.08506","32.30071"
"64.08500","1.08506","32.27045"
"64.28500","1.08506","32.23938"
"64.48500","1.08506","32.20975"
"64.68500","1.08506","32.18990"
"64.88500","1.08506","32.16363"
"65.08500","1.08506","32.13339"
"65.28500","1.08506","32.10900"
"65.48500","1.08506","32.09232"
"65.68500","1.08506","32.06394"
"65.88500","1.08506","32.03755"
"66.08500","1.08506","32.02567"
"66.28500","1.08506","32.00442"
"66.48500","1.08506","31.98383"
"66.68500","1.08506","31.95516"
"66.88500","1.08506","31.94073"
"67.08500","1.08506","31.92097"
"67.28500","1.08506","31.90559"
"67.48500","1.08506","31.87778"
"67.68500","1.08506","31.86843"
"67.88500","1.08506","31.84555"
"68.08500","1.08506","31.82656"
"68.28500","1.08506","31.81300"
"68.48500","1.08506","31.78685"
"68.68500","1.08506","31.77272"
"68.88500","1.08506","31.76320"
"69.08500","1.08506","31.74726"
"69.28500","1.08506","31.72355"
"69.48500","1.08506","31.70542"
"69.68500","1.08506","31.68863"
"69.88500","1.08506","31.68425"
"70.08500","1.08506","31.67462"
"70.28500","1.08506","31.64829"
"70.48500","1.08506","31.63924"
"70.68500","1.08506","31.62401"
"70.88500","1.08506","31.60241"
"71.08500","1.08506","31.59324"
"71.28500","1.08506","31.58217"
"71.48500","1.08506","31.56170"
"71.68500","1.08506","31.54897"
"71.88500","1.08506","31.54091"
"72.08500","1.08506","31.52784"
"72.28500","1.08506","31.51691"
"72.48500","1.08506","31.49910"
"72.68500","1.08506","31.48505"
"72.88500","1.08506","31.47754"
"73.08500","1.08506","31.46731"
"73.28500","1.08506","31.46012"
"73.48500","1.08506","31.43322"
"73.68500","1.08506","31.42231"
"73.88500","1.08506","31.41651"
"74.08500","1.08506","31.40634"
"74.28500","1.08506","31.39191"
"74.48500","1.08506","31.38152"
"74.68500","1.08506","31.37124"
"74.88500","1.08506","31.36396"
"75.08500","1.08506","31.34342"
"75.28500","1.08506","31.33569"
"75.48500","1.08506","31.32388"
"75.68500","1.08506","31.31333"
"75.88500","1.08506","31.30550"
"76.08500","1.08506","31.29470"
"76.28500","1.08506","31.29004"
"76.48500","1.08506","31.27262"
"76.68500","1.08506","31.26713"
"76.88500","1.08506","31.25281"
"77.08500","1.08506","31.24004"
"77.28500","1.08506","31.23227"
"77.48500","1.08506","31.22330"
"77.68500","1.08506","31.20422"
"77.88400","1.08506","31.20308"
"77.91500","1.08506","31.20271"
"78.11500","1.03771","25.20057"
"78.31500","0.97638","18.69689"
"78.51500","0.91566","13.53718"
"78.71500","0.85449","9.43395"
"78.91500","0.79369","6.27207"
"79.11500","0.73304","3.98715"
"79.31500","0.67221","2.39538"
"79.51500","0.61108","1.38312"
"79.71500","0.55045","0.77635"
"79.91500","0.48976","0.42407"
"80.11500","0.42857","0.22756"
"80.31500","0.36792","0.10935"
"80.51500","0.30710","0.05345"
"80.71500","0.24615","0.02154"
"80.91500","0.18521","0.01560"
"81.11500","0.12474","0.00001"
"81.31500","0.06359","-0.00783"
"81.45700","0.02027","-0.00743"
"81.45900","0.01966","-0.00761"
"81.65900","0.05386","0.00872"
"81.85900","0.11549","0.02619"
"82.05900","0.17658","0.04539"
"82.25900","0.23781","0.08107"
"82.45900","0.29823","0.13794"
"82.65900","0.35907","0.27536"
"82.84800","0.41698","0.50090"
"82.85000","0.41759","0.50408"
"82.87000","0.42359","0.52983"
"82.89000","0.42948","0.56089"
"82.91000","0.43481","0.57902"
"82.93000","0.43786","0.59974"
"82.95000","0.44156","0.62699"
"82.97000","0.44828","0.67265"
"82.99000","0.45629","0.73146"
"83.01000","0.46379","0.78238"
"83.03000","0.47055","0.82561"
"83.05000","0.47708","0.87452"
"83.07000","0.48360","0.93420"
"83.09000","0.48997","0.99512"
"83.11000","0.49609","1.04052"
"83.13000","0.50204","1.09113"
"83.15000","0.50799","1.15085"
"83.17000","0.51415","1.22091"
"83.19000","0.52045","1.29562"
"83.21000","0.52665","1.36989"
"83.23000","0.53272","1.44050"
"83.25000","0.53865","1.51349"
"83.27000","0.54456","1.59665"
"83.29000","0.55062","1.68572"
"83.31000","0.55684","1.78073"
"83.33000","0.56303","1.87940"
"83.35000","0.56912","1.98133"
"83.37000","0.57511","2.08533"
"83.39000","0.58112","2.19760"
"83.41000","0.58731","2.31496"
"83.43000","0.59361","2.43642"
"83.45000","0.59981","2.56663"
"83.47000","0.60588","2.70562"
"83.49000","0.61189","2.84346"
"83.51000","0.61796","2.98609"
"83.53000","0.62412","3.14242"
"83.55000","0.63025","3.29702"
"83.57000","0.63627","3.46654"
"83.59000","0.64224","3.63059"
"83.61000","0.64822","3.80256"
"83.63000","0.65434","3.98847"
"83.65000","0.66060","4.17869"
"83.67000","0.66673","4.38109"
"83.69000","0.67268","4.59042"
"83.71000","0.67861","4.79553"
"83.73000","0.68458","5.01254"
"83.75000","0.69072","5.23869"
"83.77000","0.69697","5.48681"
"83.79000","0.70312","5.74275"
"83.81000","0.70908","5.98920"
"83.83000","0.71498","6.24692"
"83.85000","0.72095","6.52054"
"83.87000","0.72712","6.79841"
"83.89000","0.73340","7.09222"
"83.91000","0.73964","7.38564"
"83.93000","0.74569","7.68122"
"83.95000","0.75158","7.99027"
"83.97000","0.75748","8.29856"
"83.99000","0.76359","8.63398"
"84.01000","0.76987","8.98059"
"84.03000","0.77615","9.32778"
"84.05000","0.78231","9.67714"
"84.07000","0.78832","10.03522"
"84.09000","0.79431","10.39947"
"84.11000","0.80041","10.78269"
"84.13000","0.80659","11.17023"
"84.15000","0.81274","11.55173"
"84.17000","0.81883","11.94530"
"84.19000","0.82479","12.34184"
"84.21000","0.83074","12.74694"
"84.23000","0.83684","13.16880"
"84.25000","0.84302","13.61193"
"84.27000","0.84916","14.05276"
"84.29000","0.85523","14.48236"
"84.31000","0.86125","14.91479"
"84.33000","0.86729","15.35961"
"84.35000","0.87340","15.83466"
"84.37000","0.87952","16.31455"
"84.39000","0.88557","16.79391"
"84.41000","0.89155","17.25372"
"84.43000","0.89754","17.71654"
"84.45000","0.90367","18.20596"
"84.47000","0.90988","18.71137"
"84.49000","0.91601","19.21821"
"84.51000","0.92202","19.72428"
"84.53000","0.92797","20.21839"
"84.55000","0.93397","20.71800"
"84.57000","0.94017","21.23758"
"84.59000","0.94650","21.77671"
"84.61000","0.95268","22.30810"
"84.63000","0.95865","22.83923"
"84.65000","0.96457","23.36612"
"84.67000","0.97058","23.91190"
"84.69000","0.97680","24.47419"
"84.71000","0.98311","25.04293"
"84.73000","0.98931","25.60846"
"84.75000","0.99527","26.15554"
"84.77000","1.00110","26.70306"
"84.79000","1.00698","27.26801"
"84.81000","1.01309","27.85402"
"84.83000","1.01939","28.45876"
"84.85000","1.02569","29.05755"
"84.87000","1.03180","29.63402"
"84.89000","1.03769","30.20319"
"84.91000","1.04359","30.79092"
"84.93000","1.04969","31.40808"
"84.95000","1.05590","32.02916"
"84.97000","1.06209","32.63499"
"84.99000","1.06818","33.23625"
"85.01000","1.07414","33.82371"
"85.03000","1.08006","34.41750"
"85.05000","1.08610","35.04437"
"85.07000","1.09225","35.68434"
"85.09000","1.09842","36.31375"
"85.11000","1.10450","36.92653"
"85.13000","1.11048","37.52441"
"85.15000","1.11649","38.13553"
"85.17000","1.12262","38.77745"
"85.19000","1.12880","39.43041"
"85.21000","1.13492","40.06817"
"85.23000","1.14093","40.68697"
"85.25000","1.14694","41.29376"
"85.27000","1.15312","41.91364"
"85.29000","1.15945","42.57117"
"85.31000","1.16569","43.23344"
"85.33000","1.17174","43.87396"
"85.35000","1.17767","44.48775"
"85.37000","1.18359","45.08381"
"85.39000","1.18968","45.70399"
"85.41000","1.19597","46.34904"
"85.43000","1.20217","46.98823"
"85.45000","1.20817","47.60399"
"85.47000","1.21407","48.21548"
"85.49000","1.21997","48.82247"
"85.51000","1.22611","49.44421"
"85.53000","1.23244","50.09230"
"85.55000","1.23869","50.72336"
"85.57000","1.24469","51.32449"
"85.59000","1.25054","51.91800"
"85.61000","1.25640","52.51269"
"85.63000","1.26247","53.12703"
"85.65000","1.26875","53.76209"
"85.67000","1.27501","54.38089"
"85.69000","1.28111","54.97488"
"85.71000","1.28703","55.55586"
"85.73000","1.29292","56.14921"
"85.75000","1.29898","56.76802"
"85.77000","1.30520","57.39289"
"85.79000","1.31140","58.00261"
"85.81000","1.31749","58.59286"
"85.83000","1.32348","59.17908"
"85.85000","1.32943","59.77482"
"85.87000","1.33556","60.40480"
"85.89000","1.34186","61.04085"
"85.91000","1.34811","61.66404"
"85.93000","1.35424","62.25629"
"85.95000","1.36027","62.83301"
"85.97000","1.36627","63.41086"
"85.99000","1.37235","64.02141"
"86.01000","1.37849","64.64067"
"86.03000","1.38458","65.24078"
"86.05000","1.39060","65.82340"
"86.07000","1.39658","66.39178"
"86.09000","1.40266","66.98882"
"86.11000","1.40888","67.61792"
"86.13000","1.41502","68.23810"
"86.15000","1.42103","68.82764"
"86.17000","1.42699","69.41447"
"86.19000","1.43297","69.98980"
"86.21000","1.43905","70.57037"
"86.23000","1.44526","71.17281"
"86.25000","1.45143","71.77866"
"86.27000","1.45743","72.37730"
"86.29000","1.46334","72.95998"
"86.31000","1.46927","73.54133"
"86.33000","1.47541","74.14224"
"86.35000","1.48169","74.76064"
"86.37000","1.48792","75.37199"
"86.39000","1.49399","75.96210"
"86.41000","1.49992","76.53912"
"86.43000","1.50583","77.11770"
"86.45000","1.51194","77.71727"
"86.47000","1.51822","78.32804"
"86.49000","1.52451","78.93450"
"86.51000","1.53068","79.52512"
"86.53000","1.53670","80.10444"
"86.55000","1.54264","80.67107"
"86.57000","1.54869","81.25987"
"86.59000","1.55487","81.86906"
"86.61000","1.56106","82.46188"
"86.63000","1.56715","83.03505"
"86.65000","1.57311","83.58323"
"86.67000","1.57901","84.13766"
"86.69000","1.58505","84.73052"
"86.71000","1.59123","85.34165"
"86.73000","1.59740","85.94360"
"86.75000","1.60352","86.52704"
"86.77000","1.60956","87.08553"
"86.79000","1.61560","87.65424"
"86.81000","1.62168","88.24536"
"86.83000","1.62779","88.84743"
"86.85000","1.63383","89.43189"
"86.85200","1.63443","89.48848"
"87.03800","1.60503","82.97802"
"87.23400","1.54426","73.18027"
"87.43400","1.48332","64.22736"
"87.63400","1.42265","55.94436"
"87.83400","1.36141","48.19613"
"88.03400","1.30079","41.11158"
"88.23400","1.24018","34.55633"
"88.43400","1.17882","28.45583"
"88.63400","1.11833","22.95228"
"88.83400","1.05751","17.98787"
"89.03400","0.99662","13.60595"
"89.23400","0.93537","9.89332"
"89.43400","0.87508","6.89888"
"89.63400","0.81392","4.56781"
"89.83400","0.75310","2.87659"
"90.03400","0.69240","1.73575"
"90.23400","0.63151","1.00701"
"90.43400","0.57049","0.56303"
"90.63400","0.50984","0.31353"
"90.83400","0.44910","0.16255"
"90.94000","0.41686","0.11821"
"90.94200","0.41625","0.11742"
"91.14200","0.45048","0.24944"
"91.31000","0.50234","0.50021"
"91.31200","0.50292","0.50426"
"91.31400","0.50351","0.50843"
"91.31600","0.50410","0.51472"
"91.31800","0.50472","0.52891"
"91.32000","0.50542","0.55422"
"91.32200","0.50626","0.58811"
"91.32400","0.50735","0.62866"
"91.32600","0.50880","0.67762"
"91.32800","0.51072","0.73496"
"91.33000","0.51327","0.80040"
"91.33200","0.51656","0.87663"
"91.33400","0.52075","0.96507"
"91.33600","0.52597","1.06863"
"91.33800","0.53236","1.19288"
"91.34000","0.54005","1.34542"
"91.34200","0.54917","1.53276"
"91.34400","0.55984","1.76503"
"91.34600","0.57218","2.05874"
"91.34800","0.58628","2.43297"
"91.35000","0.60226","2.90741"
"91.35200","0.62019","3.50570"
"91.35400","0.64017","4.25744"
"91.35600","0.66227","5.19184"
"91.35800","0.68655","6.33396"
"91.36000","0.71308","7.71231"
"91.36200","0.74190","9.35590"
"91.36400","0.77306","11.28895"
"91.36600","0.80658","13.53153"
"91.36800","0.84246","16.10247"
"91.37000","0.88070","19.01826"
"91.37200","0.92129","22.29015"
"91.37400","0.96419","25.91907"
"91.37600","1.00931","29.89907"
"91.37800","1.05656","34.22074"
"91.38000","1.10577","38.87114"
"91.38200","1.15677","43.83053"
"91.38400","1.20937","49.07155"
"91.38600","1.26337","54.56352"
"91.38800","1.31859","60.27854"
"91.39000","1.37486","66.18854"
"91.39200","1.43200","72.26008"
"91.39400","1.48989","78.46083"
"91.39600","1.54841","84.76364"
"91.39800","1.60744","91.14169"
"91.40000","1.66690","97.56525"
"91.40200","1.72672","104.00648"
"91.40400","1.78686","110.43994"
"91.40600","1.84725","116.83952"
"91.40800","1.90787","123.17820"
"91.41000","1.96870","129.41100"
"91.41200","2.02971","134.90273"
"91.41400","2.09088","138.24583"
"91.41600","2.15219","139.03526"
"91.41800","2.21364","137.61533"
"91.42000","2.27521","134.42557"
"91.42200","2.33689","129.81956"
"91.42400","2.39867","124.09722"
"91.42600","2.46053","117.51937"
"91.42800","2.52246","110.31529"
"91.43000","2.58444","102.69270"
"91.43200","2.64648","94.83820"
"91.43400","2.70855","86.90635"
"91.43600","2.77063","79.02072"
"91.43800","2.83273","71.28741"
"91.44000","2.89482","63.79241"
"91.44200","2.95689","56.60260"
"91.44400","3.01894","49.76665"
"91.44600","3.08095","43.32314"
"91.44800","3.14291","37.30082"
"91.45000","3.20482","31.71647"
"91.45200","3.26667","26.58052"
"91.45400","3.32846","21.89709"
"91.45600","3.39018","17.66190"
"91.45800","3.45184","13.86446"
"91.46000","3.51344","10.48741"
"91.46200","3.57498","7.50785"
"91.46400","3.63645","4.90237"
"91.46600","3.69787","2.64754"
"91.46800","3.75924","0.72020"
"91.47000","3.82055","-0.90321"
"91.47200","3.88181","-2.24744"
"91.47400","3.94303","-3.33762"
"91.47600","4.00420","-4.19873"
"91.47800","4.06534","-4.85639"
"91.48000","4.12644","-5.33672"
"91.48200","4.18751","-5.66108"
"91.48400","4.24856","-5.85049"
"91.48600","4.30959","-5.92485"
"91.48800","4.37059","-5.90248"
"91.49000","4.43159","-5.79948"
"91.49200","4.49256","-5.62881"
"91.49400","4.55353","-5.40172"
"91.49600","4.61448","-5.12951"
"91.49800","4.67542","-4.82586"
"91.50000","4.73635","-4.50087"
"91.50200","4.79727","-4.16029"
"91.50400","4.85818","-3.81237"
"91.50600","4.91909","-3.46480"
"91.50800","4.97999","-3.12383"
"91.51000","5.04088","-2.79541"
"91.51200","5.10178","-2.48285"
"91.51400","5.16267","-2.18637"
"91.51600","5.22356","-1.90577"
"91.51800","5.28445","-1.64270"
"91.52000","5.34535","-1.39896"
"91.52200","5.40624","-1.17506"
"91.52400","5.46713","-0.96933"
"91.52600","5.52803","-0.78139"
"91.52800","5.58892","-0.61363"
"91.53000","5.64981","-0.46629"
"91.53200","5.71071","-0.33619"
"91.53400","5.77160","-0.22126"
"91.53600","5.83250","-0.12070"
"91.53800","5.89340","-0.03375"
"91.54000","5.95430","0.04071"
"91.54200","6.01520","0.10214"
"91.54400","6.07610","0.15091"
"91.54600","6.13699","0.18918"
"91.54800","6.19789","0.21774"
"91.55000","6.25878","0.23843"
"91.55200","6.31966","0.25228"
"91.55400","6.38054","0.25914"
"91.55600","6.44142","0.26011"
"91.55800","6.50230","0.25666"
"91.56000","6.56318","0.25039"
"91.56200","6.62405","0.24224"
"91.56400","6.68492","0.23298"
"91.56600","6.74579","0.22290"
"91.56800","6.80666","0.21196"
"91.57000","6.86752","0.20036"
"91.57200","6.92838","0.18805"
"91.57400","6.98924","0.17478"
"91.57600","7.05009","0.16087"
"91.57800","7.11095","0.14730"
"91.58000","7.17180","0.13442"
"91.58200","7.23266","0.12240"
"91.58400","7.29351","0.11068"
"91.58600","7.35436","0.09906"
"91.58800","7.41521","0.08807"
"91.59000","7.47606","0.07876"
"91.59200","7.53691","0.07096"
"91.59400","7.59775","0.06477"
"91.59600","7.65858","0.05848"
"91.59800","7.71941","0.05188"
"91.60000","7.78024","0.04780"
"91.60200","7.84107","0.04527"
"91.60400","7.90190","0.04215"
"91.60600","7.96272","0.03693"
"91.60800","8.02355","0.03072"
"91.61000","8.08438","0.02673"
"91.61200","8.14522","0.02341"
"91.61400","8.20606","0.01890"
"91.61600","8.26690","0.01373"
"91.61800","8.32775","0.00959"
"91.62000","8.38860","0.00576"
"91.62200","8.44944","0.00164"
"91.62400","8.51029","-0.00125"
"91.62600","8.57115","-0.00234"
"91.62800","8.63200","-0.00273"
"91.63000","8.69285","-0.00288"
"91.63200","8.75371","-0.00223"
"91.63400","8.81457","-0.00076"
"91.63600","8.87543","0.00028"
"91.63800","8.93629","0.00031"
"91.64000","8.99716","0.00048"
"91.64200","9.05802","0.00112"
"91.64400","9.11888","0.00179"
"91.64600","9.17974","0.00214"
"91.64800","9.24059","0.00294"
"91.65000","9.30144","0.00345"
"91.65200","9.36229","0.00261"
"91.65400","9.42314","0.00158"
"91.65600","9.48399","0.00259"
"91.65800","9.54484","0.00434"
"91.66000","9.60569","0.00525"
"91.66200","9.66654","0.00632"
"91.66400","9.72739","0.00958"
"91.66600","9.78824","0.01348"
"91.66800","9.84908","0.01677"
"91.67000","9.90993","0.01964"
"91.67200","9.97077","0.02289"
"91.67400","10.03161","0.02659"
"91.67600","10.09245","0.03097"
"91.67800","10.15329","0.03271"
"91.68000","10.21412","0.02877"
"91.68200","10.27495","0.02344"
"91.68400","10.33578","0.02069"
"91.68600","10.39661","0.01860"
"91.68800","10.45745","0.01554"
"91.69000","10.51829","0.01266"
"91.69200","10.57913","0.01139"
"91.69400","10.63997","0.01063"
"91.69600","10.70082","0.01002"
"91.69800","10.76167","0.00950"
"91.70000","10.82252","0.00833"
"91.70200","10.88337","0.00617"
"91.70400","10.94423","0.00430"
"91.70600","11.00508","0.00286"
"91.70800","11.06594","0.00204"
"91.71000","11.12681","0.00080"
"91.71200","11.18767","-0.00125"
"91.71400","11.24854","-0.00331"
"91.71600","11.30941","-0.00510"
"91.71800","11.37027","-0.00608"
"91.72000","11.43113","-0.00502"
"91.72200","11.49199","-0.00268"
"91.72400","11.55285","-0.00084"
"91.72600","11.61371","0.00091"
"91.72800","11.67457","0.00290"
"91.73000","11.73542","0.00441"
"91.73200","11.79628","0.00532"
"91.73400","11.85713","0.00672"
"91.73600","11.91799","0.00807"
"91.73800","11.97884","0.00888"
"91.74000","12.03970","0.00971"
"91.74200","12.10055","0.00969"
"91.74400","12.16140","0.00913"
"91.74600","12.22225","0.00833"
"91.74800","12.28309","0.00924"
"91.75000","12.34394","0.01025"
"91.75200","12.40478","0.01101"
"91.75400","12.46562","0.01233"
"91.75600","12.52645","0.01375"
"91.75800","12.58729","0.01508"
"91.76000","12.64812","0.01656"
"91.76200","12.70895","0.01823"
"91.76400","12.76978","0.01891"
"91.76600","12.83060","0.01725"
"91.76800","12.89143","0.01606"
"91.77000","12.95224","0.01593"
"91.77200","13.01306","0.01469"
"91.77400","13.07388","0.01226"
"91.77600","13.13470","0.01082"
"91.77800","13.19552","0.01038"
"91.78000","13.25634","0.00863"
"91.78200","13.31717","0.00558"
"91.78400","13.37800","0.00279"
"91.78600","13.43884","0.00077"
"91.78800","13.49968","-0.00060"
"91.79000","13.56052","-0.00199"
"91.79200","13.62136","-0.00245"
"91.79400","13.68220","-0.00156"
"91.79600","13.74304","-0.00002"
"91.79800","13.80388","0.00097"
"91.80000","13.86472","0.00171"
"91.80200","13.92557","0.00240"
"91.80400","13.98641","0.00252"
"91.80600","14.04725","0.00227"
"91.80800","14.10810","0.00235"
"91.81000","14.16894","0.00202"
"91.81200","14.22979","0.00223"
"91.81400","14.29063","0.00312"
"91.81600","14.35148","0.00440"
"91.81800","14.41232","0.00508"
"91.82000","14.47316","0.00593"
"91.82200","14.53400","0.00628"
"91.82400","14.59484","0.00737"
"91.82600","14.65568","0.00922"
"91.82800","14.71653","0.01128"
"91.83000","14.77737","0.01292"
"91.83200","14.83822","0.01432"
"91.83400","14.89906","0.01500"
"91.83600","14.95991","0.01467"
"91.83800","15.02076","0.01404"
"91.84000","15.08160","0.01361"
"91.84200","15.14245","0.01420"
"91.84400","15.20329","0.01521"
"91.84600","15.26413","0.01514"
"91.84800","15.32496","0.01315"
"91.85000","15.38580","0.01120"
"91.85200","15.44663","0.01183"
"91.85400","15.50746","0.01160"
"91.85600","15.56829","0.00957"
"91.85800","15.62913","0.00642"
"91.86000","15.68997","0.00437"
"91.86100","15.72039","0.00449"