File: data/dynamic/S1/raw_data.csv
Strain : Tensile strain (Extension) gauge length,100,mm,,,,
,,,,,,
Time,Extension,Load,,,,
(s),(mm),(N),Low Start,Low End,High Start,High End
0,0,0.29286,1278,1610,1735,1835
0.2,0.1648,1.69836,,,,
0.4,0.37283,5.87323,,,,
0.6,0.58017,12.71685,,,,
0.8,0.78747,22.0944,,,,
0.98,0.97412,32.15114,,,,
1.042,1.03817,35.89289,,,,
1.142,1.01679,30.83755,,,,
1.242,0.90811,20.71093,,,,
1.395,0.74877,10.695,,,,
1.595,0.54131,3.55983,,,,
1.795,0.33376,0.74767,,,,
1.995,0.12623,0.12182,,,,
2.117,-0.00002,0.05785,,,,
2.119,-0.00209,0.05727,,,,
2.319,0.13026,0.22413,,,,
2.519,0.33867,1.58782,,,,
2.719,0.54615,6.16635,,,,
2.919,0.75357,15.06602,,,,
3.078,0.91845,25.10676,,,,
3.193,1.03731,33.56446,,,,
3.195,1.03937,33.71547,,,,
3.34,0.96574,24.27304,,,,
3.467,0.83191,14.17933,,,,
3.66,0.63168,5.29043,,,,
3.86,0.42444,1.27621,,,,
4.06,0.21707,0.19089,,,,
4.26,0.00972,0.05032,,,,
4.271,-0.00169,0.04706,,,,
4.372,0.02023,0.0836,,,,
4.572,0.23411,0.47148,,,,
4.772,0.44156,2.74949,,,,
4.972,0.64883,8.9997,,,,
5.158,0.84164,18.86459,,,,
5.3,0.98912,28.91762,,,,
5.348,1.0387,32.66163,,,,
5.449,1.01656,28.56138,,,,
5.553,0.90369,18.42884,,,,
5.72,0.7298,8.40749,,,,
5.92,0.52231,2.42824,,,,
6.12,0.3148,0.40429,,,,
6.32,0.1072,0.07599,,,,
6.424,-0.00025,0.05143,,,,
6.426,-0.00232,0.05203,,,,
6.626,0.12994,0.13911,,,,
6.826,0.33836,1.07785,,,,
7.026,0.54587,4.89547,,,,
7.226,0.75327,13.24127,,,,
7.387,0.92022,23.29149,,,,
7.5,1.03702,31.90889,,,,
7.502,1.03909,32.07047,,,,
7.648,0.96443,22.98341,,,,
7.779,0.82652,12.89078,,,,
7.978,0.62014,4.38594,,,,
8.178,0.41281,0.92968,,,,
8.378,0.20546,0.12987,,,,
8.577,-0.00089,0.04742,,,,
8.579,-0.00296,0.04718,,,,
8.779,0.12924,0.13055,,,,
8.979,0.33767,0.96842,,,,
9.179,0.54517,4.60692,,,,
9.379,0.75259,12.77921,,,,
9.541,0.92058,22.83946,,,,
9.654,1.03737,31.49251,,,,
9.656,1.03944,31.65482,,,,
9.802,0.9648,22.63627,,,,
9.933,0.82687,12.62442,,,,
10.133,0.61946,4.19082,,,,
10.333,0.41213,0.86074,,,,
10.533,0.20479,0.11958,,,,
10.731,-0.00054,0.04603,,,,
10.733,-0.00262,0.04482,,,,
10.933,0.12959,0.12664,,,,
11.133,0.33801,0.89539,,,,
11.333,0.54551,4.39288,,,,
11.533,0.75293,12.44911,,,,
11.696,0.92197,22.53746,,,,
11.808,1.03771,31.14116,,,,
11.81,1.03977,31.30406,,,,
11.957,0.96406,22.26145,,,,
12.09,0.82415,12.21023,,,,
12.29,0.61673,3.98552,,,,
12.49,0.40937,0.78259,,,,
12.69,0.20205,0.11006,,,,
12.885,-0.00018,0.04328,,,,
12.887,-0.00225,0.04327,,,,
13.087,0.1299,0.12071,,,,
13.287,0.33832,0.84006,,,,
13.487,0.54582,4.22678,,,,
13.687,0.75324,12.17858,,,,
13.85,0.92228,22.24097,,,,
13.962,1.03801,30.85656,,,,
13.964,1.04008,31.02093,,,,
14.11,0.9655,22.12477,,,,
14.243,0.82551,12.08339,,,,
14.443,0.61809,3.90952,,,,
14.643,0.41075,0.75772,,,,
14.843,0.20342,0.09651,,,,
15.04,-0.00088,0.04612,,,,
15.042,-0.00296,0.04646,,,,
15.242,0.12918,0.1103,,,,
15.442,0.33757,0.7837,,,,
15.642,0.5451,4.06421,,,,
15.842,0.75252,11.90436,,,,
16.006,0.92259,21.99238,,,,
16.117,1.03727,30.52963,,,,
16.119,1.03934,30.69401,,,,
16.266,0.96365,21.75536,,,,
16.402,0.82066,11.64193,,,,
16.602,0.61325,3.69226,,,,
16.802,0.40589,0.69094,,,,
17.002,0.19854,0.10154,,,,
17.194,-0.00059,0.03972,,,,
17.196,-0.00266,0.039,,,,
17.396,0.12943,0.11542,,,,
17.596,0.33782,0.74677,,,,
17.796,0.54535,3.94739,,,,
17.996,0.75276,11.72508,,,,
18.16,0.92285,21.77495,,,,
18.271,1.03751,30.32038,,,,
18.273,1.03958,30.48474,,,,
18.42,0.96395,21.58376,,,,
18.556,0.82094,11.50784,,,,
18.756,0.61351,3.6118,,,,
18.956,0.40618,0.66254,,,,
19.156,0.19881,0.08979,,,,
19.348,-0.0003,0.03847,,,,
19.35,-0.00237,0.03717,,,,
19.55,0.12968,0.10212,,,,
19.75,0.33804,0.72595,,,,
19.95,0.54559,3.84931,,,,
20.15,0.75301,11.56026,,,,
20.314,0.92308,21.57937,,,,
20.425,1.03774,30.12621,,,,
20.427,1.03981,30.2912,,,,
20.574,0.96427,21.43025,,,,
20.71,0.82119,11.38272,,,,
20.91,0.61378,3.54101,,,,
21.11,0.40647,0.6447,,,,
21.31,0.19909,0.08765,,,,
21.502,-0.00001,0.03782,,,,
21.504,-0.00208,0.03811,,,,
21.704,0.12999,0.09953,,,,
21.904,0.33833,0.69637,,,,
22.104,0.5459,3.76818,,,,
22.304,0.75331,11.42063,,,,
22.469,0.92442,21.48309,,,,
22.579,1.03802,29.94877,,,,
22.581,1.04009,30.11338,,,,
22.728,0.96452,21.27927,,,,
22.865,0.82046,11.21602,,,,
23.065,0.61306,3.45771,,,,
23.265,0.40575,0.62391,,,,
23.465,0.19836,0.08404,,,,
23.657,-0.00075,0.03775,,,,
23.659,-0.00283,0.0366,,,,
23.859,0.12924,0.09173,,,,
24.059,0.3376,0.65798,,,,
24.259,0.54515,3.66806,,,,
24.459,0.75257,11.23412,,,,
24.624,0.92368,21.26302,,,,
24.734,1.03729,29.71168,,,,
24.736,1.03936,29.87708,,,,
24.883,0.96378,21.07348,,,,
25.02,0.81971,11.06172,,,,
25.22,0.61231,3.37509,,,,
25.42,0.405,0.58853,,,,
25.62,0.19759,0.08518,,,,
25.811,-0.00048,0.04181,,,,
25.813,-0.00255,0.04172,,,,
26.013,0.1295,0.09987,,,,
26.213,0.33787,0.64557,,,,
26.413,0.54543,3.59666,,,,
26.613,0.75283,11.12381,,,,
26.779,0.92497,21.19166,,,,
26.888,1.03755,29.57726,,,,
26.89,1.03962,29.74165,,,,
27.037,0.96408,20.95723,,,,
27.176,0.81791,10.86144,,,,
27.376,0.61052,3.28613,,,,
27.576,0.40321,0.56421,,,,
27.776,0.19579,0.08249,,,,
27.965,-0.00021,0.04076,,,,
27.967,-0.00228,0.04044,,,,
28.167,0.12976,0.09965,,,,
28.367,0.3381,0.62527,,,,
28.567,0.54567,3.53372,,,,
28.767,0.75308,11.00891,,,,
28.934,0.92625,21.13535,,,,
29.042,1.03779,29.44719,,,,
29.044,1.03986,29.61269,,,,
29.191,0.96428,20.85445,,,,
29.33,0.81814,10.77642,,,,
29.53,0.61075,3.23559,,,,
29.73,0.40346,0.55627,,,,
29.93,0.19601,0.07961,,,,
30.12,-0.001,0.03487,,,,
30.122,-0.00308,0.03369,,,,
30.322,0.12895,0.09984,,,,
30.522,0.3373,0.59346,,,,
30.722,0.54486,3.4559,,,,
30.922,0.75228,10.8614,,,,
31.089,0.92546,20.94067,,,,
31.197,1.037,29.24459,,,,
31.199,1.03907,29.40908,,,,
31.346,0.96349,20.68145,,,,
31.486,0.81631,10.5956,,,,
31.686,0.60892,3.14607,,,,
31.886,0.40161,0.52787,,,,
32.086,0.19416,0.07773,,,,
32.274,-0.00077,0.03966,,,,
32.276,-0.00285,0.03923,,,,
32.476,0.12917,0.08779,,,,
32.676,0.33751,0.58936,,,,
32.876,0.54507,3.40762,,,,
33.076,0.75249,10.77148,,,,
33.243,0.92566,20.84134,,,,
33.351,1.03722,29.13865,,,,
33.353,1.03929,29.3041,,,,
33.5,0.96367,20.58976,,,,
33.64,0.81652,10.53266,,,,
33.84,0.60913,3.11791,,,,
34.04,0.40183,0.51241,,,,
34.24,0.19435,0.08043,,,,
34.428,-0.00055,0.0443,,,,
34.43,-0.00262,0.04384,,,,
34.63,0.12939,0.09881,,,,
34.83,0.33771,0.57626,,,,
35.03,0.54527,3.3529,,,,
35.23,0.75271,10.68991,,,,
35.397,0.92587,20.74426,,,,
35.505,1.03744,29.04714,,,,
35.507,1.0395,29.21205,,,,
35.655,0.96287,20.41945,,,,
35.795,0.81573,10.41211,,,,
35.995,0.60834,3.0534,,,,
36.195,0.40104,0.49781,,,,
36.395,0.19354,0.07389,,,,
36.582,-0.00032,0.03853,,,,
36.584,-0.0024,0.0385,,,,
36.784,0.12963,0.08517,,,,
36.984,0.33797,0.56189,,,,
37.184,0.54553,3.31419,,,,
37.384,0.75295,10.6187,,,,
37.551,0.92611,20.65925,,,,
37.659,1.03768,28.95717,,,,
37.661,1.03975,29.12272,,,,
37.81,0.96133,20.19674,,,,
37.953,0.81148,10.12508,,,,
38.153,0.60413,2.93309,,,,
38.353,0.39682,0.46654,,,,
38.553,0.1893,0.07166,,,,
38.736,-0.00041,0.03943,,,,
38.738,-0.00249,0.04001,,,,
38.938,0.12954,0.08408,,,,
39.138,0.33787,0.54902,,,,
39.338,0.54543,3.2652,,,,
39.538,0.75286,10.5294,,,,
39.706,0.92705,20.61645,,,,
39.813,1.03759,28.84211,,,,
39.815,1.03966,29.00722,,,,
39.963,0.96301,20.24395,,,,
40.105,0.81382,10.16461,,,,
40.305,0.60643,2.94537,,,,
40.505,0.39914,0.47483,,,,
40.705,0.19162,0.07123,,,,
40.89,-0.00016,0.04372,,,,
40.892,-0.00224,0.04447,,,,
41.092,0.12979,0.08985,,,,
41.292,0.33812,0.53734,,,,
41.492,0.54568,3.21834,,,,
41.692,0.7531,10.46161,,,,
41.86,0.9273,20.53347,,,,
41.967,1.03784,28.76537,,,,
41.969,1.0399,28.93176,,,,
42.117,0.9633,20.16842,,,,
42.259,0.81408,10.11629,,,,
42.459,0.60671,2.91618,,,,
42.659,0.3994,0.46418,,,,
42.859,0.1919,0.07577,,,,
43.045,-0.00093,0.04078,,,,
43.047,-0.003,0.04058,,,,
43.247,0.12904,0.08592,,,,
43.447,0.33737,0.51842,,,,
43.647,0.54493,3.16906,,,,
43.847,0.75233,10.35397,,,,
44.015,0.92655,20.38745,,,,
44.122,1.03708,28.59533,,,,
44.124,1.03914,28.76027,,,,
44.272,0.96256,20.03539,,,,
44.415,0.8123,9.96014,,,,
44.615,0.60492,2.85467,,,,
44.815,0.39761,0.44362,,,,
45.015,0.1901,0.07533,,,,
45.199,-0.00065,0.04235,,,,
45.201,-0.00272,0.04198,,,,
45.401,0.12931,0.07999,,,,
45.601,0.33765,0.51876,,,,
45.801,0.54518,3.14299,,,,
46.001,0.7526,10.30008,,,,
46.169,0.92682,20.31997,,,,
46.276,1.03735,28.53162,,,,
46.278,1.03942,28.69754,,,,
46.426,0.96284,19.97928,,,,
46.569,0.81254,9.9235,,,,
46.769,0.60517,2.81948,,,,
46.969,0.39787,0.44015,,,,
47.169,0.19036,0.07142,,,,
47.353,-0.00039,0.03783,,,,
47.355,-0.00246,0.03735,,,,
47.555,0.12953,0.08655,,,,
47.755,0.33786,0.51474,,,,
47.955,0.54541,3.10526,,,,
48.155,0.75282,10.23173,,,,
48.324,0.92807,20.31844,,,,
48.43,1.03758,28.45908,,,,
48.432,1.03965,28.62421,,,,
48.58,0.96308,19.91313,,,,
48.723,0.81281,9.87576,,,,
48.923,0.60543,2.80369,,,,
49.123,0.39813,0.42782,,,,
49.323,0.19064,0.06689,,,,
49.507,-0.00012,0.03847,,,,
49.509,-0.00219,0.03874,,,,
49.709,0.1298,0.08615,,,,
49.909,0.33812,0.50017,,,,
50.109,0.54566,3.07952,,,,
50.309,0.75308,10.18831,,,,
50.478,0.92833,20.25065,,,,
50.584,1.03782,28.39235,,,,
50.586,1.03988,28.55764,,,,
50.734,0.96337,19.86366,,,,
50.877,0.81307,9.82223,,,,
51.077,0.60571,2.78068,,,,
51.277,0.3984,0.42878,,,,
51.477,0.19091,0.06903,,,,
51.662,-0.00089,0.03547,,,,
51.664,-0.00297,0.03404,,,,
51.864,0.12901,0.08075,,,,
52.064,0.33735,0.48854,,,,
52.264,0.54489,3.02755,,,,
52.464,0.75231,10.09143,,,,
52.634,0.92859,20.18528,,,,
52.739,1.03703,28.2318,,,,
52.741,1.0391,28.39624,,,,
52.889,0.9626,19.73759,,,,
53.033,0.81129,9.68944,,,,
53.233,0.6039,2.72501,,,,
53.433,0.3966,0.41424,,,,
53.633,0.18911,0.07447,,,,
53.816,-0.00062,0.0378,,,,
53.818,-0.0027,0.03792,,,,
54.018,0.12928,0.07656,,,,
54.218,0.33763,0.47557,,,,
54.418,0.54517,3.0114,,,,
54.618,0.75259,10.04745,,,,
54.788,0.92886,20.13917,,,,
54.893,1.03731,28.18202,,,,
54.895,1.03938,28.34623,,,,
55.043,0.96291,19.69418,,,,
55.187,0.81159,9.65365,,,,
55.387,0.60419,2.6997,,,,
55.587,0.3969,0.40845,,,,
55.787,0.18941,0.06879,,,,
55.97,-0.00031,0.0399,,,,
55.972,-0.00239,0.03889,,,,
56.172,0.12956,0.07619,,,,
56.372,0.33792,0.48059,,,,
56.572,0.54546,2.98292,,,,
56.772,0.75287,10.00286,,,,
56.942,0.92913,20.08481,,,,
57.047,1.03759,28.13747,,,,
57.049,1.03966,28.30313,,,,
57.197,0.96317,19.64513,,,,
57.341,0.81188,9.61807,,,,
57.541,0.60448,2.6765,,,,
57.741,0.39717,0.39708,,,,
57.941,0.18969,0.06863,,,,
58.124,-0.00004,0.03611,,,,
58.126,-0.00211,0.03653,,,,
58.326,0.12986,0.07604,,,,
58.526,0.33823,0.46118,,,,
58.726,0.54575,2.96274,,,,
58.926,0.75316,9.95892,,,,
59.096,0.92942,20.0326,,,,
59.201,1.03788,28.07251,,,,
59.203,1.03995,28.23726,,,,
59.351,0.96351,19.60865,,,,
59.495,0.8122,9.58474,,,,
59.695,0.60479,2.66003,,,,
59.895,0.3975,0.40013,,,,
60.095,0.18998,0.06964,,,,
60.279,-0.00076,0.03423,,,,
60.281,-0.00284,0.03468,,,,
60.481,0.12912,0.07934,,,,
60.681,0.33747,0.45457,,,,
60.881,0.54501,2.91589,,,,
61.081,0.75243,9.87529,,,,
61.251,0.92866,19.90787,,,,
61.356,1.03715,27.93543,,,,
61.358,1.03922,28.10174,,,,
61.506,0.96272,19.48385,,,,
61.652,0.80937,9.40907,,,,
61.852,0.60197,2.58724,,,,
62.052,0.39466,0.37737,,,,
62.252,0.18712,0.06943,,,,
62.433,-0.00051,0.04211,,,,
62.435,-0.00258,0.04253,,,,
62.635,0.12936,0.08128,,,,
62.835,0.33767,0.44817,,,,
63.035,0.54524,2.89444,,,,
63.235,0.75265,9.82861,,,,
63.405,0.92889,19.87362,,,,
63.51,1.03737,27.89953,,,,
63.512,1.03944,28.06394,,,,
63.66,0.96296,19.44341,,,,
63.806,0.80961,9.36569,,,,
64.006,0.60222,2.5752,,,,
64.206,0.3949,0.37054,,,,
64.406,0.18739,0.05902,,,,
64.587,-0.00025,0.03995,,,,
64.589,-0.00233,0.04009,,,,
64.789,0.12958,0.07201,,,,
64.989,0.33791,0.44566,,,,
65.189,0.54547,2.8728,,,,
65.389,0.75289,9.79541,,,,
65.56,0.93015,19.89085,,,,
65.664,1.0376,27.84901,,,,
65.666,1.03967,28.01477,,,,
65.814,0.96324,19.40781,,,,
65.96,0.80985,9.33696,,,,
66.16,0.60248,2.55577,,,,
66.36,0.39515,0.36549,,,,
66.56,0.18768,0.06232,,,,
66.741,-0.00002,0.03725,,,,
66.743,-0.00209,0.0372,,,,
66.943,0.12985,0.07994,,,,
67.143,0.33815,0.4422,,,,
67.343,0.54574,2.85984,,,,
67.543,0.75315,9.76291,,,,
67.714,0.93044,19.8465,,,,
67.818,1.03786,27.80267,,,,
67.82,1.03993,27.96826,,,,
67.968,0.96353,19.37981,,,,
68.113,0.81115,9.35979,,,,
68.313,0.6038,2.55744,,,,
68.513,0.39647,0.36205,,,,
68.713,0.189,0.0628,,,,
68.896,-0.00077,0.03505,,,,
68.898,-0.00285,0.03476,,,,
69.098,0.12909,0.07799,,,,
69.298,0.33741,0.43276,,,,
69.498,0.54498,2.81186,,,,
69.698,0.75242,9.68089,,,,
69.869,0.92971,19.73935,,,,
69.973,1.0371,27.68357,,,,
69.975,1.03917,27.84906,,,,
70.123,0.96272,19.25706,,,,
70.27,0.80831,9.18759,,,,
70.47,0.60095,2.4782,,,,
70.67,0.39361,0.35728,,,,
70.87,0.18615,0.06658,,,,
71.05,-0.00053,0.03987,,,,
71.052,-0.00261,0.03968,,,,
71.252,0.12936,0.08088,,,,
71.452,0.33769,0.42445,,,,
71.652,0.54526,2.80234,,,,
71.852,0.75268,9.64725,,,,
72.023,0.92997,19.70129,,,,
72.127,1.03736,27.64597,,,,
72.129,1.03943,27.81152,,,,
72.277,0.96298,19.22727,,,,
72.424,0.80857,9.15758,,,,
72.624,0.6012,2.46795,,,,
72.824,0.39386,0.35821,,,,
73.024,0.18643,0.05391,,,,
73.204,-0.00027,0.04066,,,,
73.206,-0.00234,0.04065,,,,
73.406,0.12958,0.06952,,,,
73.606,0.33795,0.42478,,,,
73.806,0.54548,2.77623,,,,
74.006,0.75291,9.61169,,,,
74.177,0.93022,19.65689,,,,
74.281,1.03759,27.61197,,,,
74.283,1.03966,27.77718,,,,
74.432,0.96213,19.09339,,,,
74.579,0.80776,9.082,,,,
74.779,0.6004,2.43729,,,,
74.979,0.39305,0.34825,,,,
75.179,0.1856,0.06864,,,,
75.358,-0.00003,0.04221,,,,
75.36,-0.00211,0.04135,,,,
75.56,0.12982,0.07264,,,,
75.76,0.33818,0.41621,,,,
75.96,0.54571,2.76076,,,,
76.16,0.75313,9.58086,,,,
76.331,0.93044,19.62783,,,,
76.435,1.03783,27.55982,,,,
76.437,1.0399,27.72413,,,,
76.585,0.96346,19.16015,,,,
76.732,0.80904,9.10597,,,,
76.932,0.60168,2.44041,,,,
77.132,0.39434,0.34218,,,,
77.332,0.18687,0.06437,,,,
77.513,-0.00081,0.03654,,,,
77.515,-0.00289,0.03607,,,,
77.715,0.12901,0.07181,,,,
77.915,0.33736,0.40939,,,,
78.115,0.54491,2.7233,,,,
78.315,0.75232,9.49922,,,,
78.486,0.92963,19.50669,,,,
78.59,1.03703,27.44566,,,,
78.592,1.0391,27.61101,,,,
78.741,0.96154,18.9576,,,,
78.89,0.80511,8.88982,,,,
79.09,0.59774,2.34966,,,,
79.29,0.39039,0.32725,,,,
79.49,0.18292,0.0644,,,,
79.667,-0.00063,0.03402,,,,
79.669,-0.0027,0.03307,,,,
79.869,0.1292,0.06987,,,,
80.069,0.33755,0.40944,,,,
80.269,0.54509,2.70359,,,,
80.469,0.75251,9.46458,,,,
80.641,0.93085,19.53844,,,,
80.744,1.03724,27.40822,,,,
80.746,1.0393,27.57324,,,,
80.895,0.96173,18.92602,,,,
81.044,0.80531,8.85531,,,,
81.244,0.59793,2.34229,,,,
81.444,0.3906,0.32073,,,,
81.644,0.18311,0.05899,,,,
81.821,-0.00044,0.03949,,,,
81.823,-0.00252,0.0399,,,,
82.023,0.12939,0.06722,,,,
82.223,0.33773,0.40194,,,,
82.423,0.54528,2.68961,,,,
82.623,0.7527,9.42953,,,,
82.795,0.93103,19.49475,,,,
82.898,1.03742,27.35511,,,,
82.9,1.03948,27.52039,,,,
83.049,0.96192,18.87926,,,,
83.199,0.80446,8.78628,,,,
83.399,0.59709,2.30636,,,,
83.599,0.38973,0.31346,,,,
83.799,0.18225,0.06233,,,,
83.975,-0.00026,0.0394,,,,
83.977,-0.00233,0.03951,,,,
84.177,0.12956,0.07141,,,,
84.377,0.3379,0.39571,,,,
84.577,0.54544,2.67834,,,,
84.777,0.75286,9.4021,,,,
84.949,0.93119,19.45328,,,,
85.052,1.03757,27.31079,,,,
85.054,1.03964,27.47629,,,,
85.203,0.96208,18.84109,,,,
85.353,0.80463,8.75222,,,,
85.553,0.59727,2.29209,,,,
85.753,0.38991,0.30817,,,,
85.953,0.18243,0.05427,,,,
86.129,-0.00008,0.03275,,,,
86.131,-0.00215,0.03202,,,,
86.331,0.12971,0.07005,,,,
86.531,0.33805,0.38879,,,,
86.731,0.54558,2.66077,,,,
86.931,0.75302,9.36222,,,,
87.103,0.93134,19.40952,,,,
87.206,1.03773,27.25633,,,,
87.208,1.03979,27.42208,,,,
87.357,0.96219,18.80845,,,,
87.507,0.80475,8.72837,,,,
87.707,0.5974,2.28153,,,,
87.907,0.39004,0.30872,,,,
88.107,0.18258,0.06103,,,,
88.284,-0.00099,0.0361,,,,
88.286,-0.00307,0.03583,,,,
88.486,0.12881,0.07421,,,,
88.686,0.33714,0.38456,,,,
88.886,0.54469,2.62905,,,,
89.086,0.75212,9.286,,,,
89.259,0.93149,19.36995,,,,
89.362,1.03786,27.22046,,,,
89.364,1.03993,27.38569,,,,
89.513,0.96245,18.766,,,,
89.663,0.80497,8.70534,,,,
89.863,0.59759,2.27421,,,,
90.063,0.39023,0.30341,,,,
90.263,0.18277,0.05462,,,,
90.44,-0.00078,0.04087,,,,
90.442,-0.00285,0.04023,,,,
90.642,0.12901,0.06946,,,,
90.842,0.33733,0.37808,,,,
91.042,0.54488,2.60921,,,,
91.242,0.75232,9.26775,,,,
91.415,0.93168,19.33801,,,,
91.517,1.03703,27.10203,,,,
91.519,1.0391,27.26733,,,,
91.668,0.96153,18.66683,,,,
91.818,0.80409,8.6324,,,,
92.018,0.59669,2.2364,,,,
92.218,0.38934,0.29914,,,,
92.418,0.18188,0.04879,,,,
92.594,-0.00061,0.03521,,,,
92.596,-0.00269,0.03516,,,,
92.796,0.12915,0.0658,,,,
92.996,0.33746,0.38104,,,,
93.196,0.54502,2.60134,,,,
93.396,0.75245,9.23414,,,,
93.569,0.9318,19.29993,,,,
93.671,1.03715,27.06363,,,,
93.673,1.03922,27.22956,,,,
93.822,0.96162,18.62462,,,,
93.973,0.80316,8.56224,,,,
94.173,0.59578,2.21658,,,,
94.373,0.38842,0.29181,,,,
94.573,0.18094,0.05188,,,,
94.748,-0.00049,0.04301,,,,
94.75,-0.00257,0.04333,,,,
94.95,0.12931,0.07332,,,,
95.15,0.33762,0.37929,,,,
95.35,0.54518,2.58739,,,,
95.55,0.7526,9.20606,,,,
95.724,0.93299,19.33108,,,,
95.825,1.03729,27.02523,,,,
95.827,1.03936,27.19047,,,,
95.976,0.96182,18.58784,,,,
96.128,0.80231,8.48538,,,,
96.328,0.59491,2.18267,,,,
96.528,0.38755,0.28919,,,,
96.728,0.18008,0.06982,,,,
96.902,-0.00032,0.03665,,,,
96.904,-0.0024,0.03706,,,,
97.104,0.02747,0.04425,,,,
97.304,0.11151,0.07037,,,,
97.504,0.19453,0.10397,,,,
97.704,0.27726,0.19798,,,,
97.904,0.36062,0.48048,,,,
97.917,0.36595,0.50285,,,,
97.928,0.37038,0.52887,,,,
97.948,0.37761,0.5547,,,,
97.968,0.38215,0.59523,,,,
97.988,0.38631,0.61092,,,,
98.008,0.39029,0.64963,,,,
98.028,0.39754,0.707,,,,
98.048,0.40732,0.77104,,,,
98.068,0.41737,0.84985,,,,
98.088,0.42702,0.93313,,,,
98.108,0.43609,1.01931,,,,
98.128,0.4446,1.10526,,,,
98.148,0.45293,1.19155,,,,
98.168,0.46141,1.29192,,,,
98.188,0.46992,1.39234,,,,
98.208,0.47826,1.49367,,,,
98.228,0.48648,1.60346,,,,
98.248,0.4949,1.7207,,,,
98.268,0.50346,1.84271,,,,
98.288,0.51187,1.97705,,,,
98.308,0.52008,2.11573,,,,
98.328,0.52834,2.2563,,,,
98.348,0.5367,2.41133,,,,
98.368,0.54499,2.56174,,,,
98.388,0.55318,2.72149,,,,
98.408,0.56149,2.89458,,,,
98.428,0.56991,3.08061,,,,
98.448,0.57814,3.26299,,,,
98.468,0.58626,3.44572,,,,
98.488,0.59446,3.64496,,,,
98.508,0.60288,3.86311,,,,
98.528,0.61128,4.0853,,,,
98.548,0.61942,4.31081,,,,
98.568,0.62753,4.54234,,,,
98.588,0.63592,4.7922,,,,
98.608,0.64441,5.04316,,,,
98.628,0.65267,5.29301,,,,
98.648,0.66075,5.55041,,,,
98.668,0.669,5.82685,,,,
98.688,0.6775,6.11697,,,,
98.708,0.68599,6.41808,,,,
98.728,0.69429,6.71814,,,,
98.748,0.70253,7.03024,,,,
98.768,0.71089,7.34937,,,,
98.788,0.71927,7.67601,,,,
98.808,0.72756,8.01253,,,,
98.828,0.73575,8.3527,,,,
98.848,0.74401,8.70545,,,,
98.868,0.75236,9.07141,,,,
98.888,0.76067,9.43163,,,,
98.908,0.76887,9.7994,,,,
98.928,0.77711,10.18472,,,,
98.948,0.78538,10.58136,,,,
98.968,0.79362,10.97958,,,,
98.988,0.80183,11.38235,,,,
99.008,0.81017,11.80072,,,,
99.028,0.81861,12.24036,,,,
99.048,0.8269,12.68459,,,,
99.068,0.835,13.11953,,,,
99.088,0.84317,13.56092,,,,
99.108,0.85167,14.02507,,,,
99.128,0.86014,14.49884,,,,
99.148,0.86833,14.97295,,,,
99.168,0.87652,15.45718,,,,
99.188,0.88501,15.9684,,,,
99.208,0.89362,16.486,,,,
99.228,0.90196,16.99517,,,,
99.248,0.91001,17.49671,,,,
99.268,0.91813,18.02166,,,,
99.288,0.92648,18.55807,,,,
99.308,0.93486,19.1012,,,,
99.328,0.94306,19.63098,,,,
99.348,0.95121,20.19048,,,,
99.368,0.95958,20.7819,,,,
99.388,0.96799,21.37084,,,,
99.408,0.97625,21.94562,,,,
99.428,0.9844,22.52153,,,,
99.448,0.99264,23.12113,,,,
99.468,1.00103,23.74385,,,,
99.488,1.00939,24.35594,,,,
99.508,1.0176,24.96428,,,,
99.528,1.02585,25.60303,,,,
99.548,1.03419,26.25934,,,,
99.568,1.04248,26.90182,,,,
99.588,1.0507,27.54223,,,,
99.608,1.05906,28.20038,,,,
99.628,1.06762,28.89231,,,,
99.648,1.07605,29.58245,,,,
99.668,1.08421,30.24547,,,,
99.688,1.09233,30.90393,,,,
99.708,1.10075,31.58963,,,,
99.728,1.10925,32.28481,,,,
99.748,1.11747,32.94883,,,,
99.768,1.12552,33.59595,,,,
99.788,1.13377,34.27143,,,,
99.808,1.14226,34.96068,,,,
99.828,1.15062,35.62129,,,,
99.848,1.15873,36.25718,,,,
99.868,1.16685,36.89865,,,,
99.888,1.17525,37.57062,,,,
99.908,1.18368,38.23352,,,,
99.928,1.19192,38.87431,,,,
99.948,1.20008,39.49683,,,,
99.968,1.20837,40.1281,,,,
99.988,1.21675,40.76199,,,,
100.008,1.22501,41.3861,,,,
100.028,1.23317,41.99619,,,,
100.048,1.24151,42.61978,,,,
100.068,1.25004,43.26235,,,,
100.088,1.25848,43.8884,,,,
100.108,1.26672,44.48406,,,,
100.128,1.27497,45.08483,,,,
100.148,1.28334,45.70277,,,,
100.168,1.29164,46.30314,,,,
100.188,1.2998,46.87413,,,,
100.208,1.30802,47.45386,,,,
100.228,1.31647,48.06952,,,,
100.248,1.32485,48.67574,,,,
100.268,1.33301,49.25789,,,,
100.288,1.34113,49.84181,,,,
100.308,1.34946,50.44606,,,,
100.328,1.35792,51.05061,,,,
100.348,1.36618,51.64307,,,,
100.368,1.37425,52.21388,,,,
100.388,1.38244,52.80075,,,,
100.408,1.39085,53.40019,,,,
100.428,1.39925,53.98589,,,,
100.448,1.40747,54.55041,,,,
100.468,1.41566,55.12397,,,,
100.488,1.42405,55.7227,,,,
100.508,1.43252,56.31616,,,,
100.528,1.44093,56.89526,,,,
100.548,1.44922,57.46178,,,,
100.568,1.45754,58.03947,,,,
100.588,1.4659,58.62577,,,,
100.608,1.47419,59.19838,,,,
100.628,1.48238,59.74911,,,,
100.648,1.49064,60.31487,,,,
100.668,1.49899,60.90457,,,,
100.688,1.50728,61.48075,,,,
100.708,1.51548,62.0396,,,,
100.728,1.52374,62.608,,,,
100.748,1.53208,63.18638,,,,
100.768,1.54032,63.76121,,,,
100.788,1.54845,64.31958,,,,
100.808,1.55668,64.8741,,,,
100.828,1.56514,65.44846,,,,
100.848,1.57356,66.0312,,,,
100.868,1.58177,66.58961,,,,
100.888,1.58987,67.13905,,,,
100.908,1.59822,67.71468,,,,
100.928,1.60675,68.31638,,,,
100.948,1.61506,68.8924,,,,
100.968,1.62325,69.45304,,,,
100.988,1.63164,70.04881,,,,
101.008,1.64024,70.6632,,,,
101.028,1.64867,71.23382,,,,
101.048,1.65677,71.7663,,,,
101.068,1.66482,72.29218,,,,
101.088,1.67314,72.85357,,,,
101.108,1.68159,73.42484,,,,
101.128,1.68987,73.96008,,,,
101.148,1.69796,74.48579,,,,
101.168,1.70621,75.04158,,,,
101.188,1.71462,75.61625,,,,
101.208,1.72294,76.17487,,,,
101.228,1.73115,76.70327,,,,
101.248,1.73939,77.23372,,,,
101.268,1.74777,77.77345,,,,
101.288,1.75615,78.30482,,,,
101.308,1.7643,78.81167,,,,
101.328,1.77242,79.31585,,,,
101.348,1.78073,79.85799,,,,
101.368,1.7891,80.42253,,,,
101.388,1.7974,80.95634,,,,
101.408,1.80568,81.48158,,,,
101.428,1.81418,82.04087,,,,
101.448,1.82271,82.60523,,,,
101.468,1.83095,83.13371,,,,
101.488,1.83903,83.63696,,,,
101.508,1.84731,84.16257,,,,
101.528,1.8558,84.70901,,,,
101.548,1.86413,85.23983,,,,
101.568,1.87224,85.73271,,,,
101.588,1.88041,86.22849,,,,
101.608,1.88882,86.74558,,,,
101.628,1.89723,87.26383,,,,
101.648,1.9054,87.75066,,,,
101.668,1.91346,88.22686,,,,
101.688,1.92176,88.72172,,,,
101.708,1.93024,89.22835,,,,
101.728,1.93858,89.71811,,,,
101.748,1.94671,90.19202,,,,
101.768,1.95488,90.66935,,,,
101.788,1.96328,91.16779,,,,
101.808,1.97169,91.64114,,,,
101.828,1.97994,92.08192,,,,
101.848,1.98811,92.52608,,,,
101.868,1.99655,93.00592,,,,
101.888,2.00507,93.46954,,,,
101.908,2.0134,93.88432,,,,
101.928,2.02164,94.28487,,,,
101.937,2.02538,94.47115,,,,
102.038,2.022,91.18346,,,,
102.178,1.95982,81.08424,,,,
102.349,1.88876,71.04512,,,,
102.538,1.80999,60.98777,,,,
102.738,1.7272,51.40231,,,,
102.938,1.64418,42.7514,,,,
103.138,1.56137,34.95898,,,,
103.338,1.4781,28.01735,,,,
103.538,1.39535,21.993,,,,
103.738,1.3124,16.8168,,,,
103.938,1.22901,12.45988,,,,
104.138,1.14649,8.9903,,,,
104.338,1.06338,6.20778,,,,
104.538,0.9805,4.05561,,,,
104.738,0.8975,2.48948,,,,
104.938,0.81472,1.39347,,,,
105.138,0.73163,0.69326,,,,
105.338,0.64863,0.32261,,,,
105.538,0.56582,0.14277,,,,
105.738,0.48245,0.0811,,,,
105.938,0.39984,0.06127,,,,
106.021,0.36531,0.06273,,,,
106.122,0.36754,0.07311,,,,
106.322,0.4555,0.11407,,,,
106.522,0.53917,0.25875,,,,
106.671,0.60073,0.50131,,,,
106.673,0.60158,0.50515,,,,
106.675,0.60243,0.5093,,,,
106.677,0.60328,0.51633,,,,
106.679,0.60416,0.53257,,,,
106.681,0.60512,0.56054,,,,
106.683,0.60624,0.59672,,,,
106.685,0.60762,0.63914,,,,
106.687,0.60936,0.68994,,,,
106.689,0.6116,0.74988,,,,
106.691,0.61447,0.81717,,,,
106.693,0.6181,0.89433,,,,
106.695,0.62263,0.984,,,,
106.697,0.62821,1.08847,,,,
106.699,0.63497,1.21143,,,,
106.701,0.64303,1.35742,,,,
106.703,0.65254,1.53067,,,,
106.705,0.66361,1.73779,,,,
106.707,0.67635,1.98806,,,,
106.709,0.69087,2.29217,,,,
106.711,0.70727,2.66197,,,,
106.713,0.72564,3.11049,,,,
106.715,0.74606,3.65317,,,,
106.717,0.7686,4.3074,,,,
106.719,0.79333,5.09029,,,,
106.721,0.82031,6.02208,,,,
106.723,0.84958,7.12447,,,,
106.725,0.8812,8.42019,,,,
106.727,0.91519,9.93071,,,,
106.729,0.95159,11.67733,,,,
106.731,0.99042,13.68199,,,,
106.733,1.03167,15.96359,,,,
106.735,1.07535,18.54003,,,,
106.737,1.12141,21.4276,,,,
106.739,1.16984,24.63667,,,,
106.741,1.22058,28.17644,,,,
106.743,1.27359,32.05256,,,,
106.745,1.32881,36.26467,,,,
106.747,1.3862,40.80165,,,,
106.749,1.44568,45.64134,,,,
106.751,1.50721,50.75591,,,,
106.753,1.57073,56.11314,,,,
106.755,1.63618,61.68171,,,,
106.757,1.7035,67.43335,,,,
106.759,1.77267,73.34058,,,,
106.761,1.84363,79.37502,,,,
106.763,1.91632,85.50591,,,,
106.765,1.99066,91.70363,,,,
106.767,2.06653,97.93742,,,,
106.769,2.14377,104.1826,,,,
106.771,2.2222,110.41481,,,,
106.773,2.30165,116.60948,,,,
106.775,2.38194,122.74513,,,,
106.777,2.4629,128.80115,,,,
106.779,2.54438,134.75789,,,,
106.781,2.62626,140.59451,,,,
106.783,2.70842,146.28711,,,,
106.785,2.79079,151.80988,,,,
106.787,2.8733,157.1412,,,,
106.789,2.9559,161.9404,,,,
106.791,3.03856,164.74915,,,,
106.793,3.12127,164.80128,,,,
106.795,3.20401,162.36302,,,,
106.797,3.2868,157.94531,,,,
106.799,3.36963,151.96797,,,,
106.801,3.45252,144.77679,,,,
106.803,3.53547,136.6665,,,,
106.805,3.6185,127.89662,,,,
106.807,3.7016,118.70179,,,,
106.809,3.78479,109.28364,,,,
106.811,3.86807,99.81256,,,,
106.813,3.95143,90.43737,,,,
106.815,4.03489,81.28448,,,,
106.817,4.11842,72.4519,,,,
106.819,4.20203,64.01383,,,,
106.821,4.2857,56.02889,,,,
106.823,4.36942,48.53881,,,,
106.825,4.45317,41.56931,,,,
106.827,4.53695,35.13427,,,,
106.829,4.62075,29.2383,,,,
106.831,4.70455,23.8813,,,,
106.833,4.78835,19.05643,,,,
106.835,4.87213,14.7465,,,,
106.837,4.9559,10.92788,,,,
106.839,5.03963,7.57266,,,,
106.841,5.12333,4.65003,,,,
106.843,5.20698,2.13293,,,,
106.845,5.2906,-0.00692,,,,
106.847,5.37417,-1.79996,,,,
106.849,5.45771,-3.27525,,,,
106.851,5.5412,-4.4584,,,,
106.853,5.62465,-5.3757,,,,
106.855,5.70807,-6.05957,,,,
106.857,5.79146,-6.54149,,,,
106.859,5.87481,-6.84819,,,,
106.861,5.95813,-7.00291,,,,
106.863,6.04142,-7.02785,,,,
106.865,6.12469,-6.94719,,,,
106.867,6.20793,-6.78177,,,,
106.869,6.29116,-6.54524,,,,
106.871,6.37438,-6.25095,,,,
106.873,6.45758,-5.9169,,,,
106.875,6.54077,-5.55463,,,,
106.877,6.62396,-5.17026,,,,
106.879,6.70714,-4.77078,,,,
106.881,6.79032,-4.36747,,,,
106.883,6.87349,-3.9667,,,,
106.885,6.95667,-3.56954,,,,
106.887,7.03984,-3.17996,,,,
106.889,7.12301,-2.80465,,,,
106.891,7.20618,-2.44965,,,,
106.893,7.28934,-2.11489,,,,
106.895,7.37251,-1.80007,,,,
106.897,7.45566,-1.50738,,,,
106.899,7.53882,-1.23949,,,,
106.901,7.62196,-0.99796,,,,
106.903,7.7051,-0.78409,,,,
106.905,7.78824,-0.59678,,,,
106.907,7.87137,-0.43187,,,,
106.909,7.95449,-0.28705,,,,
106.911,8.03761,-0.16227,,,,
106.913,8.12071,-0.05407,,,,
106.915,8.20381,0.04299,,,,
106.917,8.28689,0.12652,,,,
106.919,8.36997,0.19486,,,,
106.921,8.45303,0.25167,,,,
106.923,8.53609,0.30036,,,,
106.925,8.61913,0.34057,,,,
106.927,8.70216,0.37123,,,,
106.929,8.78518,0.39226,,,,
106.931,8.8682,0.40492,,,,
106.933,8.9512,0.41009,,,,
106.935,9.03419,0.40734,,,,
106.937,9.11718,0.39735,,,,
106.939,9.20016,0.38142,,,,
106.941,9.28314,0.36196,,,,
106.943,9.36612,0.34209,,,,
106.945,9.4491,0.32397,,,,
106.947,9.53208,0.30774,,,,
106.949,9.61505,0.29233,,,,
106.951,9.69803,0.27771,,,,
106.953,9.781,0.26421,,,,
106.955,9.86397,0.25054,,,,
106.957,9.94694,0.23748,,,,
106.959,10.02991,0.2261,,,,
106.961,10.11288,0.21651,,,,
106.963,10.19585,0.20792,,,,
106.965,10.27881,0.19828,,,,
106.967,10.36178,0.18473,,,,
106.969,10.44474,0.166,,,,
106.971,10.52771,0.14528,,,,
106.973,10.61067,0.12687,,,,
106.975,10.69363,0.1118,,,,
106.977,10.77659,0.09876,,,,
106.979,10.85956,0.08767,,,,
106.981,10.94252,0.07952,,,,
106.983,11.02549,0.0738,,,,
106.985,11.10845,0.07073,,,,
106.987,11.19141,0.06989,,,,
106.989,11.27437,0.06851,,,,
106.991,11.35732,0.06713,,,,
106.993,11.44028,0.06798,,,,
106.995,11.52324,0.06712,,,,
106.997,11.60619,0.0618,,,,
106.999,11.68915,0.05616,,,,
107.001,11.77211,0.05096,,,,
107.003,11.85508,0.04379,,,,
107.005,11.93804,0.03736,,,,
107.007,12.021,0.03412,,,,
107.009,12.10397,0.03087,,,,
107.011,12.18693,0.02677,,,,
107.013,12.2699,0.02307,,,,
107.015,12.35287,0.0223,,,,
107.017,12.43584,0.02559,,,,
107.019,12.51881,0.03136,,,,
107.021,12.60178,0.03876,,,,
107.023,12.68475,0.04773,,,,
107.025,12.76772,0.05621,,,,
107.027,12.85069,0.06119,,,,
107.029,12.93365,0.0631,,,,
107.031,13.01662,0.06259,,,,
107.033,13.09959,0.05986,,,,
107.035,13.18257,0.05667,,,,
107.037,13.26554,0.05568,,,,
107.039,13.34851,0.05601,,,,
107.041,13.43149,0.05495,,,,
107.043,13.51446,0.05345,,,,
107.045,13.59743,0.05394,,,,
107.047,13.68039,0.05787,,,,
107.049,13.76336,0.06201,,,,
107.051,13.84632,0.06355,,,,
107.053,13.92928,0.06634,,,,
107.055,14.01224,0.07284,,,,
107.057,14.09519,0.07799,,,,
107.059,14.17815,0.07697,,,,
107.061,14.26111,0.07399,,,,
107.063,14.34406,0.07243,,,,
107.065,14.42702,0.06879,,,,
107.067,14.50998,0.0613,,,,
107.069,14.59295,0.05455,,,,
107.071,14.67591,0.05219,,,,
107.073,14.75888,0.05079,,,,
107.075,14.84184,0.04735,,,,
107.077,14.92481,0.04319,,,,
107.079,15.00777,0.04153,,,,
107.081,15.09073,0.04293,,,,
107.083,15.17368,0.0449,,,,
107.085,15.25663,0.04672,,,,
107.087,15.33958,0.04868,,,,
107.089,15.42253,0.05121,,,,
107.091,15.50547,0.0545,,,,
107.093,15.58841,0.05742,,,,
107.095,15.67135,0.05599,,,,
107.097,15.75428,0.05118,,,,
107.099,15.83721,0.04863,,,,
107.101,15.92014,0.04887,,,,
107.103,16.00307,0.0471,,,,
107.105,16.08601,0.04341,,,,
107.107,16.16895,0.0427,,,,
107.109,16.25188,0.04529,,,,
107.111,16.33482,0.04918,,,,
107.113,16.41777,0.05149,,,,
107.115,16.50071,0.05419,,,,
107.117,16.58366,0.05928,,,,
107.119,16.66661,0.06392,,,,
107.121,16.74957,0.06642,,,,
107.123,16.83253,0.06711,,,,
107.125,16.9155,0.06731,,,,
107.127,16.99848,0.06775,,,,
107.129,17.08146,0.06828,,,,
107.131,17.16444,0.06728,,,,
107.133,17.24743,0.06412,,,,
107.135,17.33042,0.06085,,,,
107.137,17.41341,0.05751,,,,
107.139,17.49641,0.05306,,,,
107.141,17.57942,0.04881,,,,
107.143,17.66242,0.04836,,,,
107.145,17.74543,0.0518,,,,
107.147,17.82843,0.05597,,,,
107.149,17.91144,0.05886,,,,
107.151,17.99444,0.06022,,,,
107.153,18.07744,0.05929,,,,
107.155,18.16044,0.05634,,,,
107.157,18.24344,0.05353,,,,
107.159,18.32644,0.05216,,,,
107.161,18.40944,0.05179,,,,
107.163,18.49243,0.0514,,,,
107.165,18.57542,0.05021,,,,
107.167,18.65841,0.04861,,,,
107.169,18.74139,0.04863,,,,
107.171,18.82436,0.04989,,,,
107.173,18.90732,0.04883,,,,
107.175,18.99028,0.0454,,,,
107.177,19.07324,0.04529,,,,
107.179,19.15619,0.04931,,,,
107.181,19.23914,0.05304,,,,
107.183,19.32209,0.05587,,,,
107.185,19.40503,0.05879,,,,
107.187,19.48798,0.06028,,,,
107.189,19.57092,0.06077,,,,
107.191,19.65386,0.06142,,,,
107.193,19.73681,0.06139,,,,
107.195,19.81976,0.05966,,,,
107.197,19.90271,0.05777,,,,
107.199,19.98566,0.05665,,,,
107.201,20.06861,0.0561,,,,
107.203,20.15157,0.05561,,,,
107.205,20.23451,0.05498,,,,
107.207,20.31746,0.05621,,,,
107.209,20.40041,0.05856,,,,
107.211,20.48336,0.05888,,,,
107.213,20.5663,0.05827,,,,
107.215,20.64925,0.05971,,,,
107.217,20.73219,0.06229,,,,
107.219,20.81514,0.0622,,,,
107.221,20.89808,0.06079,,,,
107.223,20.98103,0.06128,,,,
107.225,21.06397,0.06092,,,,
107.227,21.14691,0.05768,,,,
107.229,21.22986,0.05298,,,,
107.231,21.31281,0.05018,,,,
107.232,21.35428,0.05006,,,,