File: data/dynamic/S1/raw_data.csv
Strain : Tensile strain (Extension) gauge length,"100.00000",mm

Time,Extension,Load
(s),(mm),(N)
"0.00000","0.00000","0.33694"
"0.20000","0.13790","1.30076"
"0.40000","0.31166","2.89619"
"0.60000","0.48482","5.24263"
"0.80000","0.65794","8.52869"
"1.00000","0.83101","12.82194"
"1.04100","0.86638","13.82028"
"1.14200","0.84923","12.31272"
"1.34200","0.67063","6.28625"
"1.54200","0.49718","2.91095"
"1.74200","0.32413","1.06158"
"1.94200","0.15092","0.23112"
"2.11700","-0.00074","0.02553"
"2.11900","-0.00247","0.02589"
"2.31900","0.10711","0.33735"
"2.51900","0.28115","1.39523"
"2.71900","0.45428","3.41669"
"2.91900","0.62729","6.64163"
"3.11900","0.80032","11.16428"
"3.19600","0.86692","13.24326"
"3.29700","0.84994","11.88394"
"3.49700","0.67127","5.96006"
"3.69700","0.49782","2.67251"
"3.89700","0.32478","0.93237"
"4.09700","0.15157","0.17843"
"4.27200","-0.00011","0.02791"
"4.27400","-0.00184","0.02646"
"4.47400","0.10770","0.27313"
"4.67400","0.28174","1.22287"
"4.87400","0.45487","3.14689"
"5.07400","0.62786","6.32090"
"5.27400","0.80091","10.85242"
"5.35000","0.86663","12.93328"
"5.45100","0.84965","11.63945"
"5.65100","0.67099","5.78047"
"5.85100","0.49755","2.54102"
"6.05100","0.32452","0.84721"
"6.25100","0.15131","0.14486"
"6.42600","-0.00039","0.02403"
"6.42800","-0.00211","0.02428"
"6.62800","0.10736","0.23584"
"6.82800","0.28138","1.11529"
"7.02800","0.45451","2.98603"
"7.22800","0.62750","6.10760"
"7.42800","0.80056","10.63246"
"7.50500","0.86712","12.75431"
"7.60600","0.85022","11.49046"
"7.80600","0.67153","5.65190"
"8.00600","0.49808","2.45527"
"8.20600","0.32506","0.80618"
"8.40600","0.15186","0.13147"
"8.58200","-0.00070","0.02415"
"8.58400","-0.00243","0.02348"
"8.78400","0.10705","0.20663"
"8.98400","0.28105","1.05810"
"9.18400","0.45419","2.87071"
"9.38400","0.62717","5.96444"
"9.58400","0.80024","10.48500"
"9.66100","0.86680","12.62281"
"9.76200","0.84977","11.37519"
"9.96200","0.67118","5.56845"
"10.16200","0.49773","2.39737"
"10.36200","0.32472","0.75821"
"10.56200","0.15150","0.11953"
"10.73700","-0.00018","0.02395"
"10.73900","-0.00191","0.02394"
"10.93900","0.10748","0.18529"
"11.13900","0.28148","1.00407"
"11.33900","0.45463","2.79437"
"11.53900","0.62761","5.86558"
"11.73900","0.80068","10.39251"
"11.81500","0.86637","12.50761"
"11.91600","0.84949","11.27597"
"12.11600","0.67079","5.48815"
"12.31600","0.49737","2.33807"
"12.51600","0.32435","0.72811"
"12.71600","0.15112","0.10005"
"12.89100","-0.00056","0.01537"
"12.89300","-0.00229","0.01506"
"13.09300","0.10707","0.17598"
"13.29300","0.28105","0.96625"
"13.49300","0.45420","2.71529"
"13.69300","0.62721","5.76817"
"13.89300","0.80026","10.27453"
"13.97000","0.86678","12.42924"
"14.07100","0.85001","11.20736"
"14.27100","0.67122","5.43325"
"14.47100","0.49782","2.28760"
"14.67100","0.32480","0.71345"
"14.87100","0.15153","0.09571"
"15.04600","-0.00011","0.02222"
"15.04800","-0.00184","0.02258"
"15.24800","0.10747","0.16707"
"15.44800","0.28145","0.93014"
"15.64800","0.45458","2.66861"
"15.84800","0.62761","5.70687"
"16.04800","0.80064","10.21308"
"16.12500","0.86718","12.36392"
"16.22600","0.85024","11.14423"
"16.42600","0.67163","5.37957"
"16.62600","0.49821","2.26682"
"16.82600","0.32525","0.68721"
"17.02600","0.15194","0.08351"
"17.20200","-0.00058","0.01761"
"17.20400","-0.00230","0.01741"
"17.40400","0.10698","0.15374"
"17.60400","0.28096","0.89725"
"17.80400","0.45406","2.60708"
"18.00400","0.62712","5.61815"
"18.20400","0.80015","10.11759"
"18.28100","0.86671","12.27043"
"18.38200","0.84992","11.06827"
"18.58200","0.67121","5.31677"
"18.78200","0.49778","2.22014"
"18.98200","0.32477","0.66235"
"19.18200","0.15151","0.08211"
"19.35700","-0.00014","0.02086"
"19.35900","-0.00187","0.02116"
"19.55900","0.10736","0.14614"
"19.75900","0.28136","0.87845"
"19.95900","0.45446","2.57634"
"20.15900","0.62751","5.56821"
"20.35900","0.80053","10.06106"
"20.43600","0.86711","12.21710"
"20.53700","0.85033","11.01476"
"20.73700","0.67158","5.29092"
"20.93700","0.49816","2.20157"
"21.13700","0.32517","0.65345"
"21.33700","0.15188","0.08844"
"21.51300","-0.00063","0.01910"
"21.51500","-0.00235","0.01796"
"21.71500","0.10689","0.13951"
"21.91500","0.28086","0.86091"
"22.11500","0.45399","2.52893"
"22.31500","0.62700","5.50653"
"22.51500","0.80002","9.98308"
"22.59200","0.86662","12.13265"
"22.69300","0.84993","10.94935"
"22.89300","0.67113","5.23565"
"23.09300","0.49769","2.16861"
"23.29300","0.32471","0.64437"
"23.49300","0.15141","0.07528"
"23.66800","-0.00022","0.01764"
"23.67000","-0.00195","0.01753"
"23.87000","0.10729","0.13829"
"24.07000","0.28127","0.83690"
"24.27000","0.45439","2.49143"
"24.47000","0.62739","5.45794"
"24.67000","0.80042","9.93638"
"24.74700","0.86701","12.09495"
"24.84800","0.85034","10.91752"
"25.04800","0.67152","5.19865"
"25.24800","0.49808","2.13986"
"25.44800","0.32510","0.62517"
"25.64800","0.15181","0.07892"
"25.82400","-0.00068","0.02144"
"25.82600","-0.00241","0.02182"
"26.02600","0.10683","0.13980"
"26.22600","0.28080","0.82240"
"26.42600","0.45391","2.46363"
"26.62600","0.62691","5.40835"
"26.82600","0.79995","9.88091"
"26.90300","0.86654","12.03309"
"27.00400","0.84969","10.85565"
"27.20400","0.67105","5.15604"
"27.40400","0.49763","2.11292"
"27.60400","0.32463","0.61270"
"27.80400","0.15136","0.07401"
"27.97900","-0.00029","0.00871"
"27.98100","-0.00202","0.00807"
"28.18100","0.10719","0.12589"
"28.38100","0.28116","0.81394"
"28.58100","0.45435","2.43504"
"28.78100","0.62729","5.37010"
"28.98100","0.80033","9.84084"
"29.05800","0.86693","11.99692"
"29.15900","0.85026","10.82723"
"29.35900","0.67144","5.13133"
"29.55900","0.49801","2.09789"
"29.75900","0.32502","0.59847"
"29.95900","0.15176","0.07189"
"30.13500","-0.00077","0.00789"
"30.13700","-0.00249","0.00814"
"30.33700","0.10672","0.12174"
"30.53700","0.28069","0.79019"
"30.73700","0.45386","2.40037"
"30.93700","0.62681","5.32993"
"31.13700","0.79984","9.78228"
"31.21400","0.86644","11.93702"
"31.31500","0.84984","10.77125"
"31.51500","0.67095","5.09049"
"31.71500","0.49751","2.06902"
"31.91500","0.32452","0.58897"
"32.11500","0.15126","0.06987"
"32.29000","-0.00039","0.01622"
"32.29200","-0.00212","0.01617"
"32.49200","0.10709","0.11671"
"32.69200","0.28105","0.78049"
"32.89200","0.45423","2.38208"
"33.09200","0.62718","5.29897"
"33.29200","0.80022","9.76732"
"33.36900","0.86679","11.91567"
"33.47000","0.85021","10.75009"
"33.67000","0.67134","5.07079"
"33.87000","0.49791","2.06713"
"34.07000","0.32490","0.58843"
"34.27000","0.15166","0.06690"
"34.44600","-0.00086","0.01527"
"34.44800","-0.00258","0.01540"
"34.64800","0.10656","0.11805"
"34.84800","0.28050","0.76416"
"35.04800","0.45367","2.35084"
"35.24800","0.62664","5.26956"
"35.44800","0.79967","9.71045"
"35.52600","0.86711","11.88960"
"35.62700","0.85053","10.72979"
"35.82700","0.67169","5.05997"
"36.02700","0.49827","2.05138"
"36.22700","0.32526","0.58186"
"36.42700","0.15202","0.06470"
"36.60300","-0.00049","0.01312"
"36.60500","-0.00222","0.01348"
"36.80500","0.10691","0.11653"
"37.00500","0.28087","0.75005"
"37.20500","0.45402","2.33743"
"37.40500","0.62699","5.23177"
"37.60500","0.80004","9.69030"
"37.68200","0.86660","11.83429"
"37.78300","0.84987","10.67321"
"37.98300","0.67117","5.02212"
"38.18300","0.49775","2.02515"
"38.38300","0.32476","0.56685"
"38.58300","0.15153","0.05898"
"38.75800","-0.00017","0.01684"
"38.76000","-0.00189","0.01720"
"38.96000","0.10727","0.12088"
"39.16000","0.28121","0.74927"
"39.36000","0.45436","2.31932"
"39.56000","0.62735","5.21654"
"39.76000","0.80039","9.66932"
"39.83700","0.86696","11.82226"
"39.93800","0.85026","10.66186"
"40.13800","0.67154","5.00347"
"40.33800","0.49811","2.00334"
"40.53800","0.32513","0.56289"
"40.73800","0.15188","0.05699"
"40.91400","-0.00073","0.01354"
"40.91600","-0.00246","0.01252"
"41.11600","0.10670","0.10809"
"41.31600","0.28067","0.73357"
"41.51600","0.45380","2.29107"
"41.71600","0.62679","5.17536"
"41.91600","0.79985","9.62176"
"41.99300","0.86644","11.77058"
"42.09400","0.84969","10.61211"
"42.29400","0.67097","4.97246"
"42.49400","0.49756","1.98717"
"42.69400","0.32456","0.54726"
"42.89400","0.15131","0.05691"
"43.06900","-0.00040","0.01174"
"43.07100","-0.00213","0.01151"
"43.27100","0.10697","0.10513"
"43.47100","0.28095","0.72582"
"43.67100","0.45407","2.27900"
"43.87100","0.62708","5.16043"
"44.07100","0.80011","9.61067"
"44.14800","0.86671","11.76328"
"44.24900","0.84997","10.60378"
"44.44900","0.67126","4.96178"
"44.64900","0.49784","1.97367"
"44.84900","0.32485","0.54660"
"45.04900","0.15159","0.05359"
"45.22400","-0.00005","0.01452"
"45.22600","-0.00179","0.01453"
"45.42600","0.10718","0.10166"
"45.62600","0.28117","0.71804"
"45.82600","0.45431","2.26852"
"46.02600","0.62729","5.14511"
"46.22600","0.80034","9.58016"
"46.30300","0.86694","11.73393"
"46.40400","0.85035","10.57806"
"46.60400","0.67148","4.93695"
"46.80400","0.49807","1.96046"
"47.00400","0.32507","0.54296"
"47.20400","0.15183","0.05174"
"47.38000","-0.00062","0.01335"
"47.38200","-0.00236","0.01376"
"47.58200","0.10653","0.10210"
"47.78200","0.28051","0.70223"
"47.98200","0.45364","2.23857"
"48.18200","0.62665","5.09516"
"48.38200","0.79966","9.53057"
"48.46000","0.86713","11.70903"
"48.56100","0.85058","10.56748"
"48.76100","0.67169","4.92476"
"48.96100","0.49827","1.95772"
"49.16100","0.32526","0.52842"
"49.36100","0.15203","0.05640"
"49.53700","-0.00045","0.01034"
"49.53900","-0.00217","0.00968"
"49.73900","0.10669","0.09556"
"49.93900","0.28069","0.69587"
"50.13900","0.45381","2.21990"
"50.33900","0.62681","5.07710"
"50.53900","0.79984","9.51759"
"50.61600","0.86645","11.66402"
"50.71700","0.84970","10.51096"
"50.91700","0.67098","4.88500"
"51.11700","0.49755","1.93038"
"51.31700","0.32455","0.51950"
"51.51700","0.15132","0.04442"
"51.69200","-0.00031","0.00814"
"51.69400","-0.00203","0.00791"
"51.89400","0.10685","0.10338"
"52.09400","0.28086","0.69151"
"52.29400","0.45395","2.21154"
"52.49400","0.62698","5.06370"
"52.69400","0.80001","9.49307"
"52.77100","0.86662","11.65975"
"52.87200","0.85006","10.50969"
"53.07200","0.67114","4.86811"
"53.27200","0.49768","1.91616"
"53.47200","0.32472","0.51133"
"53.67200","0.15149","0.04884"
"53.84700","-0.00008","0.01737"
"53.84900","-0.00181","0.01652"
"54.04900","0.10694","0.10180"
"54.24900","0.28099","0.68200"
"54.44900","0.45406","2.19309"
"54.64900","0.62708","5.04169"
"54.84900","0.80012","9.48158"
"54.92600","0.86671","11.63340"
"55.02700","0.84998","10.48031"
"55.22700","0.67125","4.85701"
"55.42700","0.49781","1.91116"
"55.62700","0.32483","0.51140"
"55.82700","0.15161","0.05065"
"56.00300","-0.00084","0.00562"
"56.00500","-0.00257","0.00589"
"56.20500","0.10620","0.09451"
"56.40500","0.28025","0.67062"
"56.60500","0.45331","2.15823"
"56.80500","0.62632","5.00908"
"57.00500","0.79936","9.44061"
"57.08300","0.86683","11.61397"
"57.18400","0.85034","10.48551"
"57.38400","0.67140","4.84859"
"57.58400","0.49799","1.90101"
"57.78400","0.32497","0.50657"
"57.98400","0.15176","0.05258"
"58.16000","-0.00069","0.00745"
"58.16200","-0.00241","0.00816"
"58.36200","0.10638","0.08541"
"58.56200","0.28042","0.66809"
"58.76200","0.45350","2.16901"
"58.96200","0.62649","4.98682"
"59.16200","0.79953","9.41186"
"59.24000","0.86701","11.60235"
"59.34100","0.85024","10.44545"
"59.54100","0.67155","4.83588"
"59.74100","0.49815","1.89592"
"59.94100","0.32511","0.49713"
"60.14100","0.15188","0.04890"
"60.31700","-0.00054","0.01432"
"60.31900","-0.00226","0.01310"
"60.51900","0.10649","0.08628"
"60.71900","0.28052","0.65904"
"60.91900","0.45362","2.15459"
"61.11900","0.62661","4.98027"
"61.31900","0.79964","9.39872"
"61.39700","0.86713","11.59600"
"61.49800","0.85057","10.44663"
"61.69800","0.67168","4.82427"
"61.89800","0.49831","1.87878"
"62.09800","0.32524","0.49214"
"62.29800","0.15201","0.04138"
"62.47400","-0.00040","0.00707"
"62.47600","-0.00212","0.00751"
"62.67600","0.10666","0.08640"
"62.87600","0.28070","0.66415"
"63.07600","0.45377","2.14359"
"63.27600","0.62678","4.97238"
"63.47600","0.79980","9.38733"
"63.55300","0.86645","11.54853"
"63.65400","0.84970","10.39758"
"63.85400","0.67097","4.78946"
"64.05400","0.49763","1.86302"
"64.25400","0.32455","0.48653"
"64.45400","0.15130","0.04087"
"64.62900","-0.00028","0.00512"
"64.63100","-0.00200","0.00498"
"64.83100","0.10676","0.08947"
"65.03100","0.28080","0.65170"
"65.23100","0.45391","2.12979"
"65.43100","0.62691","4.95510"
"65.63100","0.79991","9.36323"
"65.70800","0.86657","11.52124"
"65.80900","0.84979","10.37391"
"66.00900","0.67107","4.77778"
"66.20900","0.49772","1.85545"
"66.40900","0.32467","0.48269"
"66.60900","0.15139","0.04617"
"66.78400","-0.00019","0.02002"
"66.78600","-0.00192","0.01904"
"66.98600","0.10687","0.07492"
"67.18600","0.28092","0.63926"
"67.38600","0.45402","2.12712"
"67.58600","0.62703","4.92687"
"67.78600","0.80003","9.35110"
"67.86300","0.86668","11.50508"
"67.96400","0.85015","10.37428"
"68.16400","0.67122","4.75784"
"68.36400","0.49786","1.84978"
"68.56400","0.32480","0.47578"
"68.76400","0.15154","0.03631"
"68.93900","-0.00007","0.00258"
"68.94100","-0.00180","0.00194"
"69.14100","0.10703","0.07516"
"69.34100","0.28108","0.63545"
"69.54100","0.45419","2.11303"
"69.74100","0.62718","4.92811"
"69.94100","0.80021","9.35240"
"70.01800","0.86683","11.51429"
"70.11900","0.85036","10.37108"
"70.31900","0.67141","4.75935"
"70.51900","0.49800","1.83660"
"70.71900","0.32500","0.47037"
"70.91900","0.15175","0.03548"
"71.09500","-0.00074","0.00903"
"71.09700","-0.00246","0.00911"
"71.29700","0.10635","0.07802"
"71.49700","0.28043","0.63485"
"71.69700","0.45352","2.09841"
"71.89700","0.62652","4.90705"
"72.09700","0.79956","9.31790"
"72.17500","0.86703","11.51816"
"72.27600","0.85050","10.37392"
"72.47600","0.67159","4.75533"
"72.67600","0.49818","1.82958"
"72.87600","0.32518","0.46485"
"73.07600","0.15192","0.03582"
"73.25200","-0.00057","0.00178"
"73.25400","-0.00229","0.00258"
"73.45400","0.10655","0.08313"
"73.65400","0.28060","0.62161"
"73.85400","0.45370","2.09237"
"74.05400","0.62670","4.89979"
"74.25400","0.79974","9.32107"
"74.33100","0.86638","11.48532"
"74.43200","0.84962","10.33259"
"74.63200","0.67088","4.72849"
"74.83200","0.49748","1.82026"
"75.03200","0.32446","0.46125"
"75.23200","0.15121","0.04156"
"75.40700","-0.00042","0.00815"
"75.40900","-0.00215","0.00769"
"75.60900","0.10673","0.07868"
"75.80900","0.28079","0.61899"
"76.00900","0.45388","2.08199"
"76.20900","0.62688","4.88816"
"76.40900","0.79993","9.30620"
"76.48600","0.86655","11.47372"
"76.58700","0.84983","10.32704"
"76.78700","0.67108","4.70697"
"76.98700","0.49766","1.81135"
"77.18700","0.32464","0.46199"
"77.38700","0.15138","0.04070"
"77.56200","-0.00023","0.00590"
"77.56400","-0.00196","0.00582"
"77.76400","0.10686","0.08112"
"77.96400","0.28093","0.61916"
"78.16400","0.45402","2.07133"
"78.36400","0.62702","4.86476"
"78.56400","0.80009","9.29339"
"78.64100","0.86666","11.44551"
"78.74200","0.85002","10.30386"
"78.94200","0.67127","4.70513"
"79.14200","0.49784","1.79961"
"79.34200","0.32482","0.44946"
"79.54200","0.15156","0.03650"
"79.71700","-0.00006","0.00927"
"79.71900","-0.00178","0.00814"
"79.91900","0.10703","0.08141"
"80.11900","0.28108","0.61890"
"80.31900","0.45417","2.05985"
"80.51900","0.62717","4.86237"
"80.71900","0.80023","9.28616"
"80.79600","0.86682","11.44310"
"80.89700","0.85036","10.31099"
"81.09700","0.67141","4.69628"
"81.29700","0.49798","1.79481"
"81.49700","0.32495","0.45292"
"81.69700","0.15171","0.04775"
"81.87300","-0.00076","0.00181"
"81.87500","-0.00249","0.00134"
"82.07500","0.10631","0.07660"
"82.27500","0.28036","0.60896"
"82.47500","0.45345","2.05296"
"82.67500","0.62645","4.83323"
"82.87500","0.79952","9.25132"
"82.95300","0.86696","11.44325"
"83.05400","0.85031","10.29757"
"83.25400","0.67154","4.69709"
"83.45400","0.49813","1.79614"
"83.65400","0.32507","0.45268"
"83.85400","0.15185","0.03982"
"84.03000","-0.00062","0.00338"
"84.03200","-0.00234","0.00411"
"84.23200","0.10648","0.07666"
"84.43200","0.28050","0.60557"
"84.63200","0.45359","2.04015"
"84.83200","0.62659","4.82569"
"85.03200","0.79967","9.23680"
"85.11000","0.86708","11.41332"
"85.21100","0.85053","10.29103"
"85.41100","0.67171","4.68762"
"85.61100","0.49838","1.78924"
"85.81100","0.32525","0.44587"
"86.01100","0.15205","0.03474"
"86.18700","-0.00043","0.00807"
"86.18900","-0.00215","0.00779"
"86.38900","0.10660","0.07635"
"86.58900","0.28064","0.59639"
"86.78900","0.45373","2.02531"
"86.98900","0.62672","4.80058"
"87.18900","0.79981","9.21760"
"87.26700","0.86720","11.40460"
"87.36800","0.85090","10.27822"
"87.56800","0.67189","4.66296"
"87.76800","0.49856","1.77656"
"87.96800","0.32542","0.44458"
"88.16800","0.15224","0.03384"
"88.34400","-0.00023","0.00602"
"88.34600","-0.00195","0.00574"
"88.54600","0.10676","0.07216"
"88.74600","0.28079","0.59196"
"88.94600","0.45389","2.02585"
"89.14600","0.62687","4.80130"
"89.34600","0.79996","9.21131"
"89.42300","0.86641","11.36721"
"89.52400","0.85013","10.25077"
"89.72400","0.67128","4.64714"
"89.92400","0.49794","1.76144"
"90.12400","0.32480","0.43681"
"90.32400","0.15162","0.03084"
"90.49900","-0.00002","0.01203"
"90.50100","-0.00175","0.01191"
"90.70100","0.10699","0.06536"
"90.90100","0.28102","0.58676"
"91.10100","0.45412","2.01550"
"91.30100","0.62711","4.80032"
"91.50100","0.80017","9.21009"
"91.57800","0.86662","11.34714"
"91.67900","0.85047","10.24379"
"91.87900","0.67155","4.63755"
"92.07900","0.49823","1.76213"
"92.27900","0.32511","0.43640"
"92.47900","0.15195","0.03410"
"92.65500","-0.00064","0.00920"
"92.65700","-0.00236","0.00980"
"92.85700","0.10642","0.07405"
"93.05700","0.28042","0.58106"
"93.25700","0.45347","2.00245"
"93.45700","0.62651","4.76532"
"93.65700","0.79956","9.15828"
"93.73500","0.86684","11.33183"
"93.83600","0.85076","10.22578"
"94.03600","0.67183","4.62012"
"94.23600","0.49846","1.75703"
"94.43600","0.32543","0.43030"
"94.63600","0.15224","0.03410"
"94.81200","-0.00036","-0.00418"
"94.81400","-0.00209","-0.00425"
"95.01400","0.10669","0.07057"
"95.21400","0.28070","0.57256"
"95.41400","0.45375","1.99667"
"95.61400","0.62676","4.75096"
"95.81400","0.79982","9.14777"
"95.89200","0.86707","11.32538"
"95.99300","0.85100","10.21434"
"96.19300","0.67212","4.62363"
"96.39300","0.49871","1.75264"
"96.59300","0.32572","0.43349"
"96.79300","0.15253","0.02910"
"96.96900","-0.00008","0.00356"
"96.97100","-0.00181","0.00351"
"97.17100","-0.02784","0.01821"
"97.37100","-0.02005","0.02860"
"97.57100","-0.01284","0.02894"
"97.77100","-0.00609","0.03855"
"97.97100","0.00059","0.03834"
"98.17100","0.00724","0.04615"
"98.37100","0.01403","0.04523"
"98.57100","0.02077","0.05560"
"98.77100","0.02732","0.05210"
"98.97100","0.03390","0.05628"
"99.17100","0.04054","0.05636"
"99.37100","0.04733","0.05999"
"99.57100","0.05414","0.05647"
"99.77100","0.06071","0.06396"
"99.97100","0.06731","0.06511"
"100.17100","0.07399","0.06222"
"100.37100","0.08061","0.07529"
"100.57100","0.08742","0.08480"
"100.77100","0.09411","0.08998"
"100.97100","0.10077","0.09400"
"101.17100","0.10726","0.10286"
"101.37100","0.11387","0.11348"
"101.57100","0.12062","0.12359"
"101.77100","0.12746","0.13227"
"101.97100","0.13410","0.15388"
"102.17100","0.14064","0.15927"
"102.37100","0.14726","0.17096"
"102.57100","0.15397","0.19028"
"102.77100","0.16068","0.21040"
"102.97100","0.16736","0.22956"
"103.17100","0.17410","0.24311"
"103.37100","0.18070","0.26441"
"103.57100","0.18724","0.28194"
"103.77100","0.19395","0.29635"
"103.97100","0.20079","0.31577"
"104.17100","0.20745","0.35213"
"104.37100","0.21398","0.36796"
"104.57100","0.22065","0.39727"
"104.77100","0.22740","0.42587"
"104.97100","0.23412","0.44594"
"105.17100","0.24074","0.48177"
"105.33600","0.24625","0.50007"
"105.33800","0.24631","0.49986"
"105.35800","0.24708","0.51398"
"105.37800","0.24954","0.52606"
"105.39800","0.25217","0.55058"
"105.41800","0.25593","0.57822"
"105.43800","0.26324","0.62400"
"105.45800","0.27275","0.67044"
"105.47800","0.28180","0.72053"
"105.49800","0.28963","0.76814"
"105.51800","0.29681","0.81769"
"105.53800","0.30391","0.86733"
"105.55800","0.31107","0.91815"
"105.57800","0.31809","0.95940"
"105.59800","0.32490","1.00856"
"105.61800","0.33170","1.06489"
"105.63800","0.33871","1.11583"
"105.65800","0.34584","1.16775"
"105.67800","0.35291","1.22329"
"105.69800","0.35976","1.27604"
"105.71800","0.36647","1.32917"
"105.73800","0.37332","1.38398"
"105.75800","0.38040","1.45399"
"105.77800","0.38757","1.52124"
"105.79800","0.39461","1.58001"
"105.81800","0.40147","1.64548"
"105.83800","0.40828","1.72058"
"105.85800","0.41525","1.79526"
"105.87800","0.42228","1.86694"
"105.89800","0.42923","1.93205"
"105.91800","0.43607","1.99902"
"105.93800","0.44285","2.07955"
"105.95800","0.44976","2.16026"
"105.97800","0.45677","2.23518"
"105.99800","0.46376","2.31648"
"106.01800","0.47065","2.40157"
"106.03800","0.47749","2.48770"
"106.05800","0.48440","2.58315"
"106.07800","0.49136","2.67751"
"106.09800","0.49826","2.76784"
"106.11800","0.50509","2.86261"
"106.13800","0.51193","2.96015"
"106.15800","0.51892","3.06122"
"106.17800","0.52594","3.16583"
"106.19800","0.53288","3.27227"
"106.21800","0.53970","3.37950"
"106.23800","0.54649","3.48331"
"106.25800","0.55352","3.59559"
"106.27800","0.56069","3.70790"
"106.29800","0.56766","3.82432"
"106.31800","0.57439","3.94335"
"106.33800","0.58110","4.06261"
"106.35800","0.58806","4.18875"
"106.37800","0.59529","4.32194"
"106.39800","0.60242","4.44956"
"106.41800","0.60923","4.57574"
"106.43800","0.61591","4.69928"
"106.45800","0.62275","4.83829"
"106.47800","0.62982","4.98316"
"106.49800","0.63693","5.12569"
"106.51800","0.64391","5.26172"
"106.53800","0.65065","5.40584"
"106.55800","0.65739","5.55451"
"106.57800","0.66436","5.70644"
"106.59800","0.67144","5.86211"
"106.61800","0.67839","6.01811"
"106.63800","0.68522","6.16954"
"106.65800","0.69200","6.32207"
"106.67800","0.69890","6.48400"
"106.69800","0.70593","6.65468"
"106.71800","0.71291","6.83193"
"106.73800","0.71978","6.99739"
"106.75800","0.72657","7.16139"
"106.77800","0.73347","7.33279"
"106.79800","0.74048","7.51556"
"106.81800","0.74742","7.69814"
"106.83800","0.75425","7.87934"
"106.85800","0.76112","8.05696"
"106.87800","0.76821","8.25149"
"106.89800","0.77539","8.45056"
"106.91800","0.78239","8.64877"
"106.93800","0.78919","8.84567"
"106.95800","0.79592","9.03467"
"106.97800","0.80285","9.22903"
"106.99800","0.81001","9.44060"
"107.01800","0.81704","9.64691"
"107.03800","0.82382","9.85033"
"107.05800","0.83050","10.06117"
"107.07800","0.83730","10.27257"
"107.09800","0.84438","10.49597"
"107.11800","0.85147","10.71806"
"107.13800","0.85829","10.92986"
"107.15800","0.86495","11.14833"
"107.17800","0.87172","11.37878"
"107.19800","0.87879","11.61045"
"107.21800","0.88601","11.85271"
"107.23800","0.89307","12.08653"
"107.25800","0.89988","12.32184"
"107.27800","0.90662","12.56641"
"107.29800","0.91353","12.81170"
"107.31800","0.92058","13.06357"
"107.33800","0.92762","13.30732"
"107.35800","0.93453","13.55038"
"107.37800","0.94131","13.78536"
"107.39800","0.94822","14.04296"
"107.41800","0.95530","14.30793"
"107.43800","0.96237","14.56998"
"107.45800","0.96929","14.82496"
"107.47800","0.97615","15.06904"
"107.49800","0.98306","15.32239"
"107.51800","0.99003","15.59081"
"107.53800","0.99696","15.84978"
"107.55800","1.00378","16.10347"
"107.57800","1.01060","16.35970"
"107.59800","1.01757","16.62461"
"107.61800","1.02464","16.89835"
"107.63800","1.03155","17.16700"
"107.65800","1.03833","17.43391"
"107.67800","1.04511","17.69814"
"107.69800","1.05200","17.96337"
"107.71800","1.05908","18.24686"
"107.73800","1.06612","18.53357"
"107.75800","1.07295","18.80982"
"107.77800","1.07967","19.07867"
"107.79800","1.08652","19.34862"
"107.81800","1.09357","19.63515"
"107.83800","1.10066","19.92226"
"107.85800","1.10755","20.20577"
"107.87800","1.11431","20.48999"
"107.89800","1.12112","20.77586"
"107.91800","1.12815","21.07322"
"107.93800","1.13530","21.36657"
"107.95800","1.14236","21.66256"
"107.97800","1.14925","21.96075"
"107.99800","1.15606","22.25413"
"108.01800","1.16300","22.55603"
"108.03800","1.17005","22.85933"
"108.05800","1.17702","23.15311"
"108.07800","1.18392","23.44628"
"108.09800","1.19072","23.74013"
"108.11800","1.19757","24.04951"
"108.13800","1.20454","24.36831"
"108.15800","1.21152","24.67804"
"108.17800","1.21842","24.97536"
"108.19800","1.22527","25.27894"
"108.21800","1.23218","25.59168"
"108.23800","1.23914","25.91144"
"108.25800","1.24606","26.23292"
"108.27800","1.25289","26.53661"
"108.29800","1.25973","26.84573"
"108.31800","1.26669","27.16776"
"108.33800","1.27374","27.49923"
"108.35800","1.28070","27.83099"
"108.37800","1.28751","28.14819"
"108.39800","1.29427","28.46465"
"108.41800","1.30120","28.78755"
"108.43800","1.30836","29.12486"
"108.45800","1.31544","29.45991"
"108.47800","1.32224","29.78703"
"108.49800","1.32898","30.11227"
"108.51800","1.33588","30.44405"
"108.53800","1.34305","30.79340"
"108.55800","1.35023","31.14482"
"108.57800","1.35717","31.47946"
"108.59800","1.36385","31.80632"
"108.61800","1.37055","32.13335"
"108.63800","1.37754","32.49460"
"108.65800","1.38472","32.86223"
"108.67800","1.39179","33.19989"
"108.69800","1.39861","33.53360"
"108.71800","1.40530","33.86539"
"108.73800","1.41213","34.22081"
"108.75800","1.41910","34.58447"
"108.77800","1.42606","34.93712"
"108.79800","1.43293","35.28400"
"108.81800","1.43975","35.63314"
"108.83800","1.44663","36.00343"
"108.85800","1.45363","36.38224"
"108.87800","1.46067","36.74519"
"108.89800","1.46760","37.10350"
"108.91800","1.47442","37.45608"
"108.93800","1.48128","37.81670"
"108.95800","1.48824","38.19442"
"108.97800","1.49521","38.57437"
"108.99800","1.50208","38.94274"
"109.01800","1.50893","39.30978"
"109.03800","1.51598","39.69111"
"109.05800","1.52320","40.09265"
"109.07800","1.53026","40.48849"
"109.09800","1.53706","40.86195"
"109.11800","1.54376","41.22721"
"109.13800","1.55060","41.59995"
"109.15800","1.55772","41.99093"
"109.17800","1.56483","42.39597"
"109.19800","1.57169","42.78407"
"109.21800","1.57840","43.16010"
"109.23800","1.58516","43.54863"
"109.25800","1.59216","43.95460"
"109.27800","1.59931","44.36880"
"109.29800","1.60632","44.77129"
"109.31800","1.61310","45.15051"
"109.33800","1.61978","45.52721"
"109.35800","1.62666","45.92334"
"109.37100","1.63126","46.19015"
"109.37300","1.63197","46.23162"
"109.57300","1.59226","41.17372"
"109.77300","1.52225","34.77335"
"109.97300","1.45296","29.38548"
"110.17300","1.38353","24.73488"
"110.37300","1.31421","20.67956"
"110.57300","1.24515","17.16821"
"110.77300","1.17575","14.10167"
"110.97300","1.10648","11.43676"
"111.17300","1.03732","9.17137"
"111.37300","0.96787","7.25133"
"111.57300","0.89891","5.62903"
"111.77300","0.82951","4.26807"
"111.97300","0.75996","3.15132"
"112.17300","0.69124","2.25862"
"112.37300","0.62176","1.54119"
"112.57300","0.55260","1.00732"
"112.77300","0.48359","0.60294"
"112.97300","0.41410","0.34101"
"113.17300","0.34506","0.16256"
"113.37300","0.27587","0.06562"
"113.45900","0.24588","0.03875"
"113.56000","0.23559","0.05406"
"113.76000","0.24081","0.08340"
"113.96000","0.24860","0.11495"
"114.16000","0.25550","0.13648"
"114.36000","0.26229","0.15152"
"114.56000","0.26902","0.17978"
"114.76000","0.27559","0.19973"
"114.96000","0.28221","0.23188"
"115.16000","0.28893","0.25306"
"115.36000","0.29560","0.28397"
"115.56000","0.30232","0.30696"
"115.76000","0.30901","0.32586"
"115.96000","0.31559","0.35479"
"116.16000","0.32227","0.38782"
"116.36000","0.32893","0.42176"
"116.56000","0.33570","0.44916"
"116.76000","0.34244","0.48479"
"116.89200","0.34682","0.50010"
"116.89400","0.34689","0.50051"
"116.89600","0.34696","0.50111"
"116.89800","0.34703","0.50423"
"116.90000","0.34714","0.51546"
"116.90200","0.34731","0.53712"
"116.90400","0.34764","0.56741"
"116.90600","0.34821","0.60475"
"116.90800","0.34914","0.64911"
"116.91000","0.35054","0.70074"
"116.91200","0.35254","0.75988"
"116.91400","0.35529","0.82577"
"116.91600","0.35892","0.89942"
"116.91800","0.36357","0.98245"
"116.92000","0.36937","1.07611"
"116.92200","0.37646","1.18105"
"116.92400","0.38496","1.29855"
"116.92600","0.39500","1.43142"
"116.92800","0.40668","1.58475"
"116.93000","0.42013","1.76159"
"116.93200","0.43543","1.96516"
"116.93400","0.45267","2.20256"
"116.93600","0.47194","2.48165"
"116.93800","0.49332","2.80796"
"116.94000","0.51687","3.18929"
"116.94200","0.54264","3.63696"
"116.94400","0.57070","4.16278"
"116.94600","0.60108","4.77801"
"116.94800","0.63383","5.49594"
"116.95000","0.66897","6.33247"
"116.95200","0.70652","7.30320"
"116.95400","0.74652","8.42456"
"116.95600","0.78898","9.71532"
"116.95800","0.83390","11.19550"
"116.96000","0.88128","12.88644"
"116.96200","0.93112","14.80477"
"116.96400","0.98336","16.95872"
"116.96600","1.03793","19.35813"
"116.96800","1.09467","22.01274"
"116.97000","1.15340","24.92753"
"116.97200","1.21392","28.09771"
"116.97400","1.27601","31.51490"
"116.97600","1.33943","35.17160"
"116.97800","1.40400","39.05613"
"116.98000","1.46952","43.15166"
"116.98200","1.53581","47.44102"
"116.98400","1.60274","51.90719"
"116.98600","1.67018","56.53194"
"116.98800","1.73803","61.29618"
"116.99000","1.80622","66.17917"
"116.99200","1.87468","71.15939"
"116.99400","1.94336","76.21639"
"116.99600","2.01224","81.33054"
"116.99800","2.08128","86.48049"
"117.00000","2.15047","91.64693"
"117.00200","2.21980","96.81386"
"117.00400","2.28926","101.96826"
"117.00600","2.35884","107.09753"
"117.00800","2.42855","112.18875"
"117.01000","2.49836","117.23035"
"117.01200","2.56827","122.20982"
"117.01400","2.63827","127.11258"
"117.01600","2.70835","131.92549"
"117.01800","2.77850","136.64064"
"117.02000","2.84871","141.25298"
"117.02200","2.91896","145.75824"
"117.02400","2.98925","150.15570"
"117.02600","3.05956","154.44676"
"117.02800","3.12987","158.63354"
"117.03000","3.20019","162.71712"
"117.03200","3.27049","166.69969"
"117.03400","3.34077","170.58815"
"117.03600","3.41102","174.38928"
"117.03800","3.48123","178.11128"
"117.04000","3.55139","181.76350"
"117.04200","3.62151","185.35301"
"117.04400","3.69158","188.88339"
"117.04600","3.76159","192.35472"
"117.04800","3.83155","195.76479"
"117.05000","3.90146","199.10962"
"117.05200","3.97131","202.38364"
"117.05400","4.04110","205.57817"
"117.05600","4.11085","208.68773"
"117.05800","4.18054","211.71657"
"117.06000","4.25019","214.67276"
"117.06200","4.31979","217.56110"
"117.06400","4.38935","220.38084"
"117.06600","4.45888","223.12370"
"117.06800","4.52838","225.63651"
"117.07000","4.59785","227.47105"
"117.07200","4.66729","228.45384"
"117.07400","4.73672","228.69148"
"117.07600","4.80614","228.34225"
"117.07800","4.87553","227.52966"
"117.08000","4.94492","226.35347"
"117.08200","5.01429","224.89970"
"117.08400","5.08366","223.22899"
"117.08600","5.15302","220.87509"
"117.08800","5.22237","216.50171"
"117.09000","5.29173","209.72047"
"117.09200","5.36108","200.94185"
"117.09400","5.43044","190.67358"
"117.09600","5.49979","179.32663"
"117.09800","5.56916","167.24092"
"117.10000","5.63852","154.70473"
"117.10200","5.70789","141.96819"
"117.10400","5.77727","129.24991"
"117.10600","5.84665","116.73653"
"117.10800","5.91603","104.57964"
"117.11000","5.98542","92.89851"
"117.11200","6.05481","81.78751"
"117.11400","6.12420","71.31370"
"117.11600","6.19359","61.52264"
"117.11800","6.26299","52.44062"
"117.12000","6.33238","44.08088"
"117.12200","6.40176","36.44577"
"117.12400","6.47114","29.52739"
"117.12600","6.54051","23.31060"
"117.12800","6.60987","17.77465"
"117.13000","6.67922","12.88658"
"117.13200","6.74856","8.60633"
"117.13400","6.81790","4.89900"
"117.13600","6.88722","1.72852"
"117.13800","6.95654","-0.94763"
"117.14000","7.02586","-3.17525"
"117.14200","7.09517","-4.99431"
"117.14400","7.16448","-6.44282"
"117.14600","7.23379","-7.56058"
"117.14800","7.30309","-8.38743"
"117.15000","7.37240","-8.95836"
"117.15200","7.44170","-9.30430"
"117.15400","7.51100","-9.45428"
"117.15600","7.58030","-9.43723"
"117.15800","7.64960","-9.28234"
"117.16000","7.71891","-9.01663"
"117.16200","7.78821","-8.66365"
"117.16400","7.85751","-8.24417"
"117.16600","7.92680","-7.77513"
"117.16800","7.99610","-7.26773"
"117.17000","8.06539","-6.73500"
"117.17200","8.13467","-6.18911"
"117.17400","8.20395","-5.64053"
"117.17600","8.27323","-5.09843"
"117.17800","8.34251","-4.56967"
"117.18000","8.41178","-4.05930"
"117.18200","8.48105","-3.57110"
"117.18400","8.55032","-3.10722"
"117.18600","8.61959","-2.67054"
"117.18800","8.68885","-2.26316"
"117.19000","8.75811","-1.88510"
"117.19200","8.82736","-1.53786"
"117.19400","8.89662","-1.22500"
"117.19600","8.96587","-0.94516"
"117.19800","9.03511","-0.69501"
"117.20000","9.10435","-0.47254"
"117.20200","9.17359","-0.27785"
"117.20400","9.24283","-0.11028"
"117.20600","9.31206","0.03102"
"117.20800","9.38129","0.14745"
"117.21000","9.45052","0.24432"
"117.21200","9.51974","0.32563"
"117.21400","9.58896","0.39199"
"117.21600","9.65818","0.44428"
"117.21800","9.72740","0.48568"
"117.22000","9.79663","0.51711"
"117.22200","9.86585","0.53746"
"117.22400","9.93508","0.54695"
"117.22600","10.00431","0.54880"
"117.22800","10.07355","0.54432"
"117.23000","10.14278","0.53442"
"117.23200","10.21201","0.52038"
"117.23400","10.28125","0.50394"
"117.23600","10.35048","0.48456"
"117.23800","10.41972","0.46154"
"117.24000","10.48895","0.43710"
"117.24200","10.55818","0.41283"
"117.24400","10.62742","0.38916"
"117.24600","10.69665","0.36635"
"117.24800","10.76588","0.34592"
"117.25000","10.83512","0.32739"
"117.25200","10.90435","0.30881"
"117.25400","10.97357","0.29007"
"117.25600","11.04280","0.27142"
"117.25800","11.11202","0.25310"
"117.26000","11.18124","0.23648"
"117.26200","11.25046","0.22273"
"117.26400","11.31969","0.21117"
"117.26600","11.38891","0.19988"
"117.26800","11.45814","0.18795"
"117.27000","11.52737","0.17513"
"117.27200","11.59660","0.16278"
"117.27400","11.66583","0.15303"
"117.27600","11.73505","0.14625"
"117.27800","11.80428","0.14067"
"117.28000","11.87350","0.13477"
"117.28200","11.94272","0.13122"
"117.28400","12.01194","0.13051"
"117.28600","12.08117","0.12827"
"117.28800","12.15040","0.12269"
"117.29000","12.21963","0.11736"
"117.29200","12.28886","0.11537"
"117.29400","12.35810","0.11319"
"117.29600","12.42733","0.10852"
"117.29800","12.49657","0.10437"
"117.30000","12.56580","0.10285"
"117.30200","12.63504","0.10142"
"117.30400","12.70427","0.09888"
"117.30600","12.77351","0.09771"
"117.30800","12.84275","0.09922"
"117.31000","12.91199","0.10074"
"117.31200","12.98123","0.10213"
"117.31400","13.05047","0.10495"
"117.31600","13.11971","0.10734"
"117.31800","13.18895","0.10858"
"117.32000","13.25819","0.11171"
"117.32200","13.32743","0.11639"
"117.32400","13.39667","0.11992"
"117.32600","13.46591","0.12229"
"117.32800","13.53515","0.12489"
"117.33000","13.60440","0.12690"
"117.33200","13.67365","0.12682"
"117.33400","13.74290","0.12522"
"117.33600","13.81215","0.12355"
"117.33800","13.88140","0.12318"
"117.34000","13.95065","0.12353"
"117.34200","14.01991","0.12471"
"117.34400","14.08916","0.12763"
"117.34600","14.15841","0.13149"
"117.34800","14.22765","0.13591"
"117.35000","14.29690","0.14025"
"117.35200","14.36614","0.14116"
"117.35400","14.43538","0.13818"
"117.35600","14.50462","0.13537"
"117.35800","14.57386","0.13471"
"117.36000","14.64309","0.13275"
"117.36200","14.71233","0.12708"
"117.36400","14.78156","0.12150"
"117.36600","14.85079","0.11930"
"117.36800","14.92003","0.11813"
"117.37000","14.98926","0.11651"
"117.37200","15.05850","0.11463"
"117.37400","15.12774","0.11355"
"117.37600","15.19698","0.11320"
"117.37800","15.26622","0.11418"
"117.38000","15.33546","0.11601"
"117.38200","15.40470","0.11737"
"117.38400","15.47394","0.11741"
"117.38600","15.54317","0.11816"
"117.38800","15.61239","0.12016"
"117.39000","15.68161","0.12208"
"117.39200","15.75083","0.12343"
"117.39400","15.82005","0.12489"
"117.39600","15.88927","0.12610"
"117.39800","15.95848","0.12624"
"117.40000","16.02768","0.12540"
"117.40200","16.09689","0.12463"
"117.40400","16.16610","0.12478"
"117.40600","16.23530","0.12441"
"117.40800","16.30450","0.12373"
"117.41000","16.37370","0.12410"
"117.41200","16.44291","0.12720"
"117.41400","16.51212","0.13106"
"117.41600","16.58133","0.13290"
"117.41800","16.65055","0.13363"
"117.42000","16.71976","0.13378"
"117.42200","16.78899","0.13420"
"117.42400","16.85822","0.13423"
"117.42600","16.92745","0.13388"
"117.42800","16.99668","0.13205"
"117.43000","17.06591","0.12972"
"117.43200","17.13515","0.12875"
"117.43400","17.20440","0.12800"
"117.43600","17.27364","0.12580"
"117.43800","17.34290","0.12356"
"117.44000","17.41216","0.12263"
"117.44200","17.48143","0.12207"
"117.44400","17.55070","0.12055"
"117.44600","17.61997","0.11917"
"117.44800","17.68925","0.11873"