File: data/instron/Sample23_Static.is_tcyclic_RawData/Specimen_RawData_1.csv
Strain : Tensile strain (Extension) gauge length,"100.00000",mm

Time,Extension,Load
(s),(mm),(N)
"0.00000","0.81206","0.05855"
"0.20000","0.86665","0.07581"
"0.40000","0.94153","0.09554"
"0.60000","1.01548","0.11021"
"0.80000","1.08913","0.12767"
"1.00000","1.16329","0.15847"
"1.20000","1.23713","0.20591"
"1.40000","1.31141","0.26562"
"1.60000","1.38537","0.38993"
"1.80000","1.45921","0.61428"
"2.00000","1.53360","0.94503"
"2.20000","1.60747","1.34733"
"2.40000","1.68151","1.67030"
"2.60000","1.75549","1.84181"
"2.80000","1.82932","1.97813"
"3.00000","1.90350","2.14255"
"3.20000","1.97740","2.22952"
"3.40000","2.05121","2.36750"
"3.55000","2.10713","2.43305"
"3.55200","2.10787","2.43312"
"3.75200","2.11760","1.98063"
"3.95200","2.11561","1.84290"
"4.15200","2.11528","1.77372"
"4.35200","2.11519","1.72323"
"4.55200","2.11519","1.68407"
"4.75200","2.11519","1.65034"
"4.95200","2.11510","1.62584"
"5.15200","2.11509","1.60683"
"5.35200","2.11514","1.58724"
"5.55200","2.11515","1.56958"
"5.75200","2.11516","1.54991"
"5.95200","2.11516","1.53144"
"6.15200","2.11516","1.52588"
"6.35200","2.11519","1.51515"
"6.55200","2.11519","1.50208"
"6.75200","2.11519","1.48797"
"6.95200","2.11519","1.48918"
"7.15200","2.11519","1.47008"
"7.35200","2.11519","1.47223"
"7.55200","2.11519","1.45518"
"7.75200","2.11519","1.44873"
"7.95200","2.11519","1.44619"
"8.15200","2.11519","1.43800"
"8.35200","2.11519","1.42868"
"8.55200","2.11519","1.42206"
"8.75200","2.11519","1.42180"
"8.95200","2.11519","1.41856"
"9.15200","2.11519","1.41370"
"9.35200","2.11519","1.40561"
"9.55200","2.11519","1.39785"
"9.75200","2.11519","1.40089"
"9.95200","2.11519","1.38353"
"10.15200","2.11519","1.38504"
"10.35200","2.11519","1.38033"
"10.55200","2.11519","1.38728"
"10.75200","2.11519","1.38239"
"10.95200","2.11519","1.37506"
"11.15200","2.11519","1.36937"
"11.35200","2.11519","1.35781"
"11.55200","2.11519","1.35810"
"11.75200","2.11519","1.35586"
"11.95200","2.11519","1.34895"
"12.15200","2.11519","1.34775"
"12.35200","2.11519","1.34962"
"12.55200","2.11519","1.34469"
"12.75200","2.11519","1.34482"
"12.95200","2.11519","1.33807"
"13.15200","2.11519","1.33614"
"13.35200","2.11519","1.33919"
"13.55200","2.11519","1.32886"
"13.75200","2.11519","1.32820"
"13.95200","2.11519","1.32387"
"14.15200","2.11519","1.31964"
"14.35200","2.11519","1.31347"
"14.55200","2.11519","1.31685"
"14.75200","2.11519","1.31603"
"14.95200","2.11519","1.31360"
"15.15200","2.11519","1.30615"
"15.35200","2.11519","1.30592"
"15.55200","2.11519","1.30557"
"15.75200","2.11519","1.30573"
"15.95200","2.11519","1.30014"
"16.15200","2.11519","1.29907"
"16.35200","2.11519","1.30178"
"16.55200","2.11519","1.29895"
"16.75200","2.11519","1.29238"
"16.95200","2.11519","1.29152"
"17.15200","2.11519","1.29071"
"17.35200","2.11519","1.28898"
"17.55200","2.11519","1.28612"
"17.75200","2.11519","1.29058"
"17.95200","2.11519","1.28371"
"18.15200","2.11519","1.27989"
"18.35200","2.11519","1.28029"
"18.55200","2.11519","1.27245"
"18.75200","2.11519","1.27145"
"18.95200","2.11519","1.27052"
"19.15200","2.11519","1.27032"
"19.35200","2.11519","1.26756"
"19.55200","2.11519","1.26694"
"19.75200","2.11519","1.26196"
"19.95200","2.11519","1.26833"
"20.15200","2.11519","1.26982"
"20.35200","2.11519","1.26376"
"20.55200","2.11519","1.25687"
"20.75200","2.11519","1.25688"
"20.95200","2.11519","1.25864"
"21.15200","2.11519","1.25682"
"21.35200","2.11519","1.25413"
"21.55200","2.11519","1.25478"
"21.75200","2.11519","1.25025"
"21.95200","2.11519","1.25076"
"22.15200","2.11519","1.24787"
"22.35200","2.11519","1.25165"
"22.55200","2.11519","1.24173"
"22.75200","2.11519","1.25084"
"22.95200","2.11519","1.24705"
"23.15200","2.11519","1.23915"
"23.35200","2.11519","1.23385"
"23.55100","2.11519","1.24253"
"23.58400","2.11519","1.23746"
"23.78400","2.05667","0.62385"
"23.98400","1.98256","0.33028"
"24.18400","1.90817","0.20505"
"24.38400","1.83408","0.14642"
"24.58400","1.76026","0.10641"
"24.78400","1.68625","0.08434"
"24.98400","1.61250","0.07474"
"25.18400","1.53829","0.06682"
"25.38400","1.46441","0.06261"
"25.58400","1.39037","0.04972"
"25.78400","1.31640","0.04882"
"25.98400","1.24252","0.04386"
"26.18400","1.16827","0.04064"
"26.38400","1.09414","0.03614"
"26.58400","1.02059","0.03426"
"26.78400","0.94632","0.03354"
"26.98400","0.87240","0.03350"
"27.12600","0.81996","0.02423"
"27.12800","0.81923","0.02375"
"27.32800","0.86215","0.02658"
"27.52800","0.93732","0.04225"
"27.72800","1.01129","0.04698"
"27.92800","1.08495","0.04353"
"28.12800","1.15911","0.05874"
"28.32800","1.23298","0.06897"
"28.52800","1.30707","0.07054"
"28.72800","1.38101","0.08657"
"28.92800","1.45491","0.09342"
"29.12800","1.52934","0.10711"
"29.32800","1.60317","0.12452"
"29.52800","1.67718","0.16194"
"29.72800","1.75123","0.21840"
"29.92800","1.82520","0.30126"
"30.12800","1.89939","0.47100"
"30.32800","1.97323","0.75515"
"30.52800","2.04702","1.13784"
"30.71100","2.11501","1.60270"
"30.71300","2.11573","1.60751"
"30.91300","2.12559","1.50812"
"31.11300","2.12356","1.43290"
"31.31300","2.12325","1.40963"
"31.51300","2.12316","1.38131"
"31.71300","2.12316","1.36381"
"31.91300","2.12309","1.35974"
"32.11300","2.12306","1.34132"
"32.31300","2.12313","1.33197"
"32.51300","2.12316","1.31771"
"32.71300","2.12316","1.31881"
"32.91300","2.12316","1.31490"
"33.11300","2.12316","1.29963"
"33.31300","2.12316","1.30132"
"33.51300","2.12316","1.29370"
"33.71300","2.12316","1.28251"
"33.91300","2.12316","1.28410"
"34.11300","2.12316","1.27937"
"34.31300","2.12316","1.26967"
"34.51300","2.12316","1.26937"
"34.71300","2.12316","1.26069"
"34.91300","2.12316","1.26157"
"35.11300","2.12316","1.25455"
"35.31300","2.12316","1.25133"
"35.51300","2.12316","1.24533"
"35.71300","2.12316","1.24326"
"35.91300","2.12316","1.24914"
"36.11300","2.12316","1.24131"
"36.31300","2.12316","1.23748"
"36.51300","2.12316","1.23326"
"36.71300","2.12316","1.22983"
"36.91300","2.12316","1.23307"
"37.11300","2.12316","1.22592"
"37.31300","2.12316","1.23004"
"37.51300","2.12316","1.22510"
"37.71300","2.12316","1.22977"
"37.91300","2.12316","1.22289"
"38.11300","2.12316","1.21885"
"38.31300","2.12316","1.21647"
"38.51300","2.12316","1.21581"
"38.71300","2.12316","1.20562"
"38.91300","2.12316","1.20517"
"39.11300","2.12316","1.20810"
"39.31300","2.12316","1.20042"
"39.51300","2.12316","1.20567"
"39.71300","2.12316","1.20090"
"39.91300","2.12316","1.19628"
"40.11300","2.12316","1.19965"
"40.31300","2.12316","1.20241"
"40.51300","2.12316","1.20597"
"40.71300","2.12316","1.19739"
"40.91300","2.12316","1.19581"
"41.11300","2.12316","1.19177"
"41.31300","2.12316","1.19284"
"41.51300","2.12316","1.19908"
"41.71300","2.12316","1.18473"
"41.91300","2.12316","1.18604"
"42.11300","2.12316","1.18733"
"42.31300","2.12316","1.18061"
"42.51300","2.12316","1.18246"
"42.71300","2.12316","1.18177"
"42.91300","2.12316","1.18097"
"43.11300","2.12316","1.17985"
"43.31300","2.12316","1.17164"
"43.51300","2.12316","1.17547"
"43.71300","2.12316","1.17519"
"43.91300","2.12316","1.17644"
"44.11300","2.12316","1.17072"
"44.31300","2.12316","1.17556"
"44.51300","2.12316","1.16927"
"44.71300","2.12316","1.17023"
"44.91300","2.12316","1.17144"
"45.11300","2.12316","1.17238"
"45.31300","2.12316","1.16345"
"45.51300","2.12316","1.16273"
"45.71300","2.12316","1.16162"
"45.91300","2.12316","1.16374"
"46.11300","2.12316","1.16301"
"46.31300","2.12316","1.15914"
"46.51300","2.12316","1.15537"
"46.71300","2.12316","1.16439"
"46.91300","2.12316","1.15602"
"47.11300","2.12316","1.15348"
"47.31300","2.12316","1.16062"
"47.51300","2.12316","1.15803"
"47.71300","2.12316","1.15437"
"47.91300","2.12316","1.14892"
"48.11300","2.12316","1.15064"
"48.31300","2.12316","1.14745"
"48.51300","2.12316","1.15130"
"48.71300","2.12316","1.15087"
"48.91300","2.12316","1.14839"
"49.11300","2.12316","1.14811"
"49.31300","2.12316","1.15191"
"49.51300","2.12316","1.14272"
"49.71300","2.12316","1.14903"
"49.91300","2.12316","1.15077"
"50.11300","2.12316","1.14279"
"50.31300","2.12316","1.13457"
"50.51300","2.12316","1.15076"
"50.71200","2.12316","1.13417"
"50.73400","2.12316","1.13271"
"50.93400","2.06492","0.55552"
"51.13400","1.99060","0.28446"
"51.33400","1.91620","0.17855"
"51.53400","1.84206","0.12356"
"51.73400","1.76838","0.09865"
"51.93400","1.69431","0.08382"
"52.13400","1.62036","0.06671"
"52.33400","1.54614","0.06332"
"52.53400","1.47215","0.05768"
"52.73400","1.39847","0.05012"
"52.93400","1.32436","0.04407"
"53.13400","1.25034","0.04670"
"53.33400","1.17628","0.03949"
"53.53400","1.10220","0.03445"
"53.73400","1.02863","0.03003"
"53.93400","0.95429","0.02702"
"54.13400","0.88039","0.03221"
"54.27600","0.82785","0.01741"
"54.27800","0.82712","0.01763"
"54.47800","0.86987","0.02834"
"54.67800","0.94505","0.04453"
"54.87800","1.01912","0.04728"
"55.07800","1.09283","0.05140"
"55.27800","1.16691","0.05440"
"55.47800","1.24079","0.05567"
"55.67800","1.31515","0.07025"
"55.87800","1.38914","0.06914"
"56.07800","1.46293","0.08730"
"56.27800","1.53721","0.09889"
"56.47800","1.61109","0.11858"
"56.67800","1.68521","0.14176"
"56.87800","1.75915","0.18786"
"57.07800","1.83292","0.26107"
"57.27800","1.90701","0.39705"
"57.47800","1.98096","0.63676"
"57.67800","2.05487","1.00326"
"57.86200","2.12300","1.46421"
"57.86400","2.12372","1.47036"
"58.06400","2.13391","1.41183"
"58.26400","2.13173","1.34652"
"58.46400","2.13143","1.31898"
"58.66400","2.13141","1.30727"
"58.86400","2.13141","1.29313"
"59.06400","2.13141","1.27546"
"59.26400","2.13133","1.26910"
"59.46400","2.13131","1.26199"
"59.66400","2.13137","1.25261"
"59.86400","2.13138","1.24725"
"60.06400","2.13138","1.24538"
"60.26400","2.13139","1.23784"
"60.46400","2.13141","1.22765"
"60.66400","2.13141","1.22546"
"60.86400","2.13141","1.22667"
"61.06400","2.13141","1.21870"
"61.26400","2.13141","1.21821"
"61.46400","2.13141","1.20338"
"61.66400","2.13141","1.20713"
"61.86400","2.13141","1.21177"
"62.06400","2.13141","1.19661"
"62.26400","2.13141","1.20121"
"62.46400","2.13141","1.19336"
"62.66400","2.13141","1.19351"
"62.86400","2.13141","1.19424"
"63.06400","2.13141","1.18551"
"63.26400","2.13141","1.19106"
"63.46400","2.13141","1.18562"
"63.66400","2.13141","1.18167"
"63.86400","2.13141","1.18243"
"64.06400","2.13141","1.17714"
"64.26400","2.13141","1.17418"
"64.46400","2.13141","1.17007"
"64.66400","2.13141","1.17743"
"64.86400","2.13141","1.16777"
"65.06400","2.13141","1.16805"
"65.26400","2.13141","1.16139"
"65.46400","2.13141","1.16197"
"65.66400","2.13141","1.15788"
"65.86400","2.13141","1.16545"
"66.06400","2.13141","1.16476"
"66.26400","2.13141","1.16335"
"66.46400","2.13141","1.16370"
"66.66400","2.13141","1.15101"
"66.86400","2.13141","1.15364"
"67.06400","2.13141","1.14625"
"67.26400","2.13141","1.15601"
"67.46400","2.13141","1.14938"
"67.66400","2.13141","1.15209"
"67.86400","2.13141","1.15184"
"68.06400","2.13141","1.14249"
"68.26400","2.13141","1.14803"
"68.46400","2.13141","1.13995"
"68.66400","2.13141","1.14491"
"68.86400","2.13141","1.14400"
"69.06400","2.13141","1.14215"
"69.26400","2.13141","1.14037"
"69.46400","2.13141","1.14500"
"69.66400","2.13141","1.14364"
"69.86400","2.13141","1.14145"
"70.06400","2.13141","1.14779"
"70.26400","2.13141","1.13705"
"70.46400","2.13141","1.13893"
"70.66400","2.13141","1.13758"
"70.86400","2.13141","1.13353"
"71.06400","2.13141","1.12623"
"71.26400","2.13141","1.12862"
"71.46400","2.13141","1.13195"
"71.66400","2.13141","1.12700"
"71.86400","2.13141","1.13004"
"72.06400","2.13141","1.12804"
"72.26400","2.13141","1.12301"
"72.46400","2.13141","1.11864"
"72.66400","2.13141","1.12076"
"72.86400","2.13141","1.12794"
"73.06400","2.13141","1.11994"
"73.26400","2.13141","1.12492"
"73.46400","2.13141","1.12781"
"73.66400","2.13141","1.12129"
"73.86400","2.13141","1.12687"
"74.06400","2.13141","1.11608"
"74.26400","2.13141","1.11978"
"74.46400","2.13141","1.12354"
"74.66400","2.13141","1.11672"
"74.86400","2.13141","1.11928"
"75.06400","2.13141","1.11345"
"75.26400","2.13141","1.11313"
"75.46400","2.13141","1.11050"
"75.66400","2.13141","1.10894"
"75.86400","2.13141","1.11294"
"76.06400","2.13141","1.12089"
"76.26400","2.13141","1.10653"
"76.46400","2.13141","1.10752"
"76.66400","2.13141","1.11136"
"76.86400","2.13141","1.10926"
"77.06400","2.13141","1.10384"
"77.26400","2.13141","1.10892"
"77.46400","2.13141","1.10623"
"77.66400","2.13141","1.10639"
"77.86300","2.13141","1.09966"
"77.88900","2.13141","1.10659"
"78.08900","2.07313","0.52508"
"78.28900","1.99877","0.27674"
"78.48900","1.92450","0.17059"
"78.68900","1.85047","0.12146"
"78.88900","1.77677","0.09596"
"79.08900","1.70260","0.08046"
"79.28900","1.62863","0.07146"
"79.48900","1.55452","0.06766"
"79.68900","1.48037","0.06282"
"79.88900","1.40660","0.05106"
"80.08900","1.33248","0.04593"
"80.28900","1.25841","0.04022"
"80.48900","1.18457","0.03601"
"80.68900","1.11043","0.03348"
"80.88900","1.03669","0.03120"
"81.08900","0.96247","0.03663"
"81.28900","0.88874","0.02799"
"81.43000","0.83637","0.02957"
"81.43200","0.83563","0.02995"
"81.63200","0.87836","0.03852"
"81.83200","0.95357","0.03600"
"82.03200","1.02770","0.03765"
"82.23200","1.10166","0.05336"
"82.43200","1.17572","0.05462"
"82.63200","1.24951","0.06938"
"82.83200","1.32386","0.06456"
"83.03200","1.39777","0.07296"
"83.23200","1.47162","0.08701"
"83.43200","1.54572","0.10006"
"83.63200","1.61947","0.11301"
"83.83200","1.69372","0.14405"
"84.03200","1.76764","0.17655"
"84.23200","1.84134","0.24068"
"84.43200","1.91548","0.36650"
"84.56400","1.96450","0.50071"
"84.56600","1.96525","0.50334"
"84.58600","1.97217","0.51532"
"84.60600","1.97642","0.54262"
"84.62600","1.98019","0.54253"
"84.64600","1.98323","0.56232"
"84.66600","1.98864","0.58785"
"84.68600","1.99728","0.62732"
"84.70600","2.00673","0.66798"
"84.72600","2.01545","0.70078"
"84.74600","2.02355","0.74069"
"84.76600","2.03139","0.77171"
"84.78600","2.03902","0.80390"
"84.80600","2.04647","0.84974"
"84.82600","2.05391","0.89020"
"84.84600","2.06156","0.93058"
"84.86600","2.06924","0.97982"
"84.88600","2.07669","1.01988"
"84.90600","2.08396","1.06596"
"84.92600","2.09125","1.11432"
"84.94600","2.09877","1.16512"
"84.96600","2.10634","1.21776"
"84.98600","2.11369","1.26944"
"85.00600","2.12089","1.32475"
"85.02600","2.12815","1.38712"
"85.04600","2.13566","1.44653"
"85.06600","2.14323","1.50553"
"85.08600","2.15059","1.56405"
"85.10600","2.15778","1.61485"
"85.12600","2.16505","1.68289"
"85.14600","2.17256","1.74437"
"85.16600","2.18011","1.80239"
"85.18600","2.18750","1.85502"
"85.20600","2.19478","1.89949"
"85.22600","2.20212","1.95130"
"85.24600","2.20960","2.00066"
"85.26600","2.21707","2.05283"
"85.28600","2.22441","2.08971"
"85.30600","2.23168","2.12218"
"85.32600","2.23911","2.15172"
"85.34600","2.24672","2.17862"
"85.36600","2.25429","2.20759"
"85.38600","2.26169","2.22769"
"85.40600","2.26900","2.25034"
"85.42600","2.27641","2.27093"
"85.44600","2.28390","2.29222"
"85.46600","2.29126","2.32060"
"85.48600","2.29852","2.33620"
"85.50600","2.30583","2.35659"
"85.52600","2.31336","2.37839"
"85.54600","2.32091","2.39526"
"85.56600","2.32824","2.41695"
"85.58600","2.33547","2.42909"
"85.60600","2.34278","2.45239"
"85.62600","2.35027","2.47967"
"85.64600","2.35780","2.50147"
"85.66600","2.36515","2.51842"
"85.68600","2.37237","2.53261"
"85.70600","2.37972","2.55014"
"85.72600","2.38723","2.57111"
"85.74600","2.39471","2.59250"
"85.76600","2.40206","2.61210"
"85.78600","2.40929","2.62872"
"85.80600","2.41664","2.65508"
"85.82600","2.42422","2.67863"
"85.84600","2.43183","2.70389"
"85.86600","2.43930","2.71230"
"85.88600","2.44663","2.71124"
"85.90600","2.45402","2.71732"
"85.92600","2.46149","2.73348"
"85.94600","2.46890","2.75012"
"85.96600","2.47623","2.75820"
"85.98600","2.48353","2.76233"
"86.00600","2.49094","2.77666"
"86.02600","2.49842","2.79333"
"86.04600","2.50586","2.80595"
"86.06600","2.51319","2.81513"
"86.08600","2.52052","2.82096"
"86.10600","2.52797","2.83061"
"86.12600","2.53540","2.85024"
"86.14600","2.54270","2.86734"
"86.16600","2.54995","2.87568"
"86.18600","2.55733","2.89299"
"86.20600","2.56487","2.91136"
"86.22600","2.57234","2.92326"
"86.24600","2.57965","2.93666"
"86.26600","2.58688","2.95109"
"86.28600","2.59427","2.96261"
"86.30600","2.60188","2.98043"
"86.32600","2.60940","3.00256"
"86.34600","2.61670","3.02553"
"86.36600","2.62397","3.03998"
"86.38600","2.63149","3.05217"
"86.40600","2.63916","3.06772"
"86.42600","2.64667","3.07322"
"86.44600","2.65390","3.08588"
"86.46600","2.66106","3.09455"
"86.48600","2.66845","3.10792"
"86.50600","2.67605","3.13530"
"86.52600","2.68358","3.15449"
"86.54600","2.69084","3.17129"
"86.56600","2.69802","3.18788"
"86.58600","2.70546","3.19930"
"86.60600","2.71303","3.21366"
"86.62600","2.72047","3.22582"
"86.64600","2.72772","3.24064"
"86.66600","2.73492","3.24578"
"86.68600","2.74231","3.25678"
"86.70600","2.74984","3.26644"
"86.72600","2.75731","3.27369"
"86.74600","2.76463","3.28238"
"86.76600","2.77196","3.29605"
"86.78600","2.77941","3.31456"
"86.80600","2.78688","3.33077"
"86.82600","2.79425","3.34440"
"86.84600","2.80157","3.35902"
"86.86600","2.80906","3.37747"
"86.88600","2.81669","3.40043"
"86.90600","2.82419","3.41275"
"86.92600","2.83145","3.42409"
"86.94600","2.83865","3.43907"
"86.96600","2.84608","3.45618"
"86.98600","2.85369","3.46855"
"87.00600","2.86115","3.48246"
"87.02600","2.86841","3.48990"
"87.04600","2.87564","3.50317"
"87.06600","2.88309","3.52068"
"87.08600","2.89068","3.53550"
"87.10600","2.89811","3.55394"
"87.12600","2.90532","3.55819"
"87.14600","2.91251","3.56212"
"87.16600","2.91997","3.57457"
"87.18600","2.92758","3.59000"
"87.20600","2.93507","3.59542"
"87.22600","2.94232","3.57582"
"87.24600","2.94950","3.56067"
"87.26600","2.95689","3.56730"
"87.28600","2.96441","3.57034"
"87.30600","2.97185","3.57576"
"87.32600","2.97914","3.59352"
"87.34600","2.98644","3.60746"
"87.36600","2.99397","3.62464"
"87.38600","3.00158","3.64618"
"87.40600","3.00908","3.66403"
"87.42600","3.01647","3.68595"
"87.44600","3.02386","3.70741"
"87.46600","3.03132","3.72149"
"87.48600","3.03872","3.73514"
"87.50600","3.04602","3.74841"
"87.52600","3.05332","3.76750"
"87.54600","3.06079","3.78747"
"87.56600","3.06830","3.80274"
"87.58600","3.07561","3.82241"
"87.60600","3.08284","3.83934"
"87.62600","3.09014","3.86191"
"87.64600","3.09765","3.88617"
"87.66600","3.10521","3.90634"
"87.68600","3.11258","3.92664"
"87.70600","3.11977","3.95094"
"87.72600","3.12707","3.97523"
"87.74600","3.13461","3.99999"
"87.76600","3.14218","4.02867"
"87.78600","3.14953","4.04917"
"87.80600","3.15672","4.06570"
"87.82600","3.16401","4.09595"
"87.84600","3.17156","4.12235"
"87.86600","3.17915","4.14081"
"87.88600","3.18666","4.15785"
"87.90600","3.19401","4.17351"
"87.92600","3.20135","4.19462"
"87.94600","3.20886","4.21604"
"87.96600","3.21636","4.23791"
"87.98600","3.22374","4.25956"
"88.00600","3.23097","4.27020"
"88.02600","3.23824","4.28745"
"88.04600","3.24570","4.31244"
"88.06600","3.25318","4.34273"
"88.08600","3.26058","4.36391"
"88.10600","3.26792","4.38517"
"88.12600","3.27532","4.41277"
"88.14600","3.28275","4.44264"
"88.16600","3.29009","4.46065"
"88.18600","3.29738","4.48175"
"88.20600","3.30473","4.50967"
"88.22600","3.31225","4.53488"
"88.24600","3.31976","4.56479"
"88.26600","3.32709","4.58862"
"88.28600","3.33432","4.61048"
"88.30600","3.34163","4.63893"
"88.32600","3.34922","4.67063"
"88.34600","3.35681","4.70164"
"88.36600","3.36417","4.73490"
"88.38600","3.37142","4.76849"
"88.40600","3.37884","4.80153"
"88.42600","3.38650","4.82503"
"88.44600","3.39408","4.85143"
"88.46600","3.40132","4.88184"
"88.48600","3.40843","4.91302"
"88.50600","3.41574","4.94522"
"88.52600","3.42336","4.98053"
"88.54600","3.43100","5.01084"
"88.56600","3.43838","5.04073"
"88.58400","3.44482","5.06619"
"88.58600","3.44553","5.06901"
"88.78600","3.40255","3.29783"
"88.98600","3.32780","2.18731"
"89.18600","3.25367","1.44967"
"89.38600","3.17950","0.95533"
"89.58600","3.10596","0.62156"
"89.78600","3.03178","0.38512"
"89.98600","2.95785","0.24318"
"90.18600","2.88387","0.16841"
"90.38600","2.80968","0.12071"
"90.58600","2.73584","0.10135"
"90.78600","2.66164","0.09044"
"90.98600","2.58759","0.07120"
"91.18600","2.51379","0.06821"
"91.38600","2.43961","0.05640"
"91.58600","2.36587","0.05948"
"91.78600","2.29136","0.05527"
"91.98600","2.21768","0.05246"
"92.18600","2.14393","0.04526"
"92.38600","2.06976","0.03715"
"92.58600","1.99589","0.03026"
"92.67100","1.96440","0.04059"
"92.77200","1.96557","0.04959"
"92.97200","2.04411","0.04612"
"93.17200","2.11859","0.04985"
"93.37200","2.19248","0.05701"
"93.57200","2.26660","0.06254"
"93.77200","2.34044","0.07786"
"93.97200","2.41430","0.08764"
"94.17200","2.48858","0.10328"
"94.37200","2.56240","0.11982"
"94.57200","2.63661","0.15371"
"94.77200","2.71062","0.19887"
"94.97200","2.78452","0.28984"
"95.17200","2.85878","0.47152"
"95.19800","2.86825","0.50171"
"95.20000","2.86897","0.50429"
"95.20200","2.86969","0.50767"
"95.20400","2.87043","0.51684"
"95.20600","2.87121","0.53716"
"95.20800","2.87212","0.56671"
"95.21000","2.87323","0.60271"
"95.21200","2.87466","0.64553"
"95.21400","2.87652","0.69527"
"95.21600","2.87895","0.75133"
"95.21800","2.88209","0.81374"
"95.22000","2.88607","0.88120"
"95.22200","2.89104","0.95459"
"95.22400","2.89713","1.03543"
"95.22600","2.90448","1.12473"
"95.22800","2.91321","1.22181"
"95.23000","2.92347","1.32640"
"95.23200","2.93535","1.43911"
"95.23400","2.94898","1.56182"
"95.23600","2.96445","1.69705"
"95.23800","2.98186","1.84765"
"95.24000","3.00130","2.01414"
"95.24200","3.02284","2.19980"
"95.24400","3.04655","2.40914"
"95.24600","3.07250","2.64525"
"95.24800","3.10073","2.91025"
"95.25000","3.13129","3.20406"
"95.25200","3.16421","3.52475"
"95.25400","3.19948","3.86912"
"95.25600","3.23711","4.23369"
"95.25800","3.27707","4.61501"
"95.26000","3.31935","5.00909"
"95.26200","3.36390","5.40822"
"95.26400","3.41070","5.81026"
"95.26600","3.45970","6.22013"
"95.26800","3.51084","6.64123"
"95.27000","3.56409","7.07403"
"95.27200","3.61939","7.52150"
"95.27400","3.67670","7.98737"
"95.27600","3.73598","8.46853"
"95.27800","3.79717","8.95958"
"95.28000","3.86023","9.45334"
"95.28200","3.92504","9.94166"
"95.28400","3.99149","10.42042"
"95.28600","4.05941","10.89048"
"95.28800","4.12862","11.35166"
"95.29000","4.19893","11.79929"
"95.29200","4.27015","12.23113"
"95.29400","4.34212","12.64717"
"95.29600","4.41468","13.04614"
"95.29800","4.48769","13.42634"
"95.30000","4.56104","13.78807"
"95.30200","4.63463","14.13182"
"95.30400","4.70839","14.45755"
"95.30600","4.78226","14.76717"
"95.30800","4.85621","15.06020"
"95.31000","4.93021","15.33245"
"95.31200","5.00426","15.58044"
"95.31400","5.07834","15.80556"
"95.31600","5.15246","16.00805"
"95.31800","5.22661","16.18597"
"95.32000","5.30081","16.33968"
"95.32200","5.37506","16.47129"
"95.32400","5.44936","16.58168"
"95.32600","5.52372","16.67234"
"95.32800","5.59814","16.74575"
"95.33000","5.67261","16.80311"
"95.33200","5.74715","16.84400"
"95.33400","5.82173","16.86895"
"95.33600","5.89637","16.87925"
"95.33800","5.97105","16.87733"
"95.34000","6.04576","16.86731"
"95.34200","6.12050","16.85099"
"95.34400","6.19525","16.82499"
"95.34600","6.27001","16.78791"
"95.34800","6.34477","16.73944"
"95.35000","6.41952","16.67916"
"95.35200","6.49426","16.60862"
"95.35400","6.56897","16.52987"
"95.35600","6.64366","16.44557"
"95.35800","6.71833","16.35825"
"95.36000","6.79296","16.26875"
"95.36200","6.86756","16.17844"
"95.36400","6.94212","16.08819"
"95.36600","7.01664","15.99908"
"95.36800","7.09112","15.91399"
"95.37000","7.16556","15.83189"
"95.37200","7.23997","15.74853"
"95.37400","7.31434","15.66433"
"95.37600","7.38868","15.58282"
"95.37800","7.46300","15.50411"
"95.38000","7.53729","15.42404"
"95.38200","7.61156","15.34327"
"95.38400","7.68582","15.26550"
"95.38600","7.76005","15.19159"
"95.38800","7.83427","15.11693"
"95.39000","7.90848","15.03847"
"95.39200","7.98268","14.95829"
"95.39400","8.05687","14.87909"
"95.39600","8.13105","14.80280"
"95.39800","8.20523","14.73208"
"95.40000","8.27940","14.66729"
"95.40200","8.35357","14.60751"
"95.40400","8.42773","14.55082"
"95.40600","8.50188","14.49476"
"95.40800","8.57603","14.43634"
"95.41000","8.65017","14.37515"
"95.41200","8.72430","14.31116"
"95.41400","8.79844","14.24243"
"95.41600","8.87256","14.16701"
"95.41800","8.94668","14.08519"
"95.42000","9.02080","13.99570"
"95.42200","9.09491","13.89608"
"95.42400","9.16902","13.78403"
"95.42600","9.24312","13.66144"
"95.42800","9.31721","13.53163"
"95.43000","9.39129","13.39558"
"95.43200","9.46536","13.25534"
"95.43400","9.53943","13.11283"
"95.43600","9.61349","12.96961"
"95.43800","9.68755","12.82539"
"95.44000","9.76160","12.67985"
"95.44200","9.83564","12.53061"
"95.44400","9.90967","12.37609"
"95.44600","9.98370","12.21817"
"95.44800","10.05772","12.05826"
"95.45000","10.13175","11.89598"
"95.45200","10.20577","11.73198"
"95.45400","10.27978","11.56741"
"95.45600","10.35380","11.40346"
"95.45800","10.42782","11.24165"
"95.46000","10.50184","11.08392"
"95.46200","10.57587","10.93086"
"95.46400","10.64989","10.78295"
"95.46600","10.72392","10.64105"
"95.46800","10.79794","10.50570"
"95.47000","10.87197","10.37609"
"95.47200","10.94599","10.25214"
"95.47400","11.02002","10.13533"
"95.47600","11.09404","10.02608"
"95.47800","11.16807","9.92163"
"95.48000","11.24209","9.81980"
"95.48200","11.31612","9.72018"
"95.48400","11.39014","9.62087"
"95.48600","11.46416","9.51869"
"95.48800","11.53817","9.41325"
"95.49000","11.61219","9.30864"
"95.49200","11.68620","9.20896"
"95.49400","11.76021","9.11284"
"95.49600","11.83423","9.01891"
"95.49800","11.90824","8.92904"
"95.50000","11.98226","8.84459"
"95.50200","12.05627","8.76267"
"95.50400","12.13029","8.68147"
"95.50600","12.20430","8.60055"
"95.50800","12.27831","8.51924"
"95.51000","12.35232","8.43645"
"95.51200","12.42632","8.35294"
"95.51400","12.50033","8.26974"
"95.51600","12.57433","8.18408"
"95.51800","12.64834","8.09385"
"95.52000","12.72234","8.00303"
"95.52200","12.79635","7.91501"
"95.52400","12.87036","7.82786"
"95.52600","12.94437","7.74185"
"95.52800","13.01837","7.66033"
"95.53000","13.09238","7.58299"
"95.53200","13.16639","7.50670"
"95.53400","13.24039","7.43116"
"95.53600","13.31440","7.35806"
"95.53800","13.38840","7.28726"
"95.54000","13.46241","7.21743"
"95.54200","13.53642","7.14877"
"95.54400","13.61043","7.07956"
"95.54600","13.68444","7.00773"
"95.54800","13.75844","6.93256"
"95.55000","13.83245","6.85544"
"95.55200","13.90645","6.77770"
"95.55400","13.98046","6.69963"
"95.55600","14.05446","6.61980"
"95.55800","14.12847","6.53813"
"95.56000","14.20248","6.45628"
"95.56200","14.27649","6.37606"
"95.56400","14.35050","6.29761"
"95.56600","14.42452","6.22111"
"95.56800","14.49853","6.14829"
"95.57000","14.57254","6.08063"
"95.57200","14.64656","6.01773"
"95.57400","14.72057","5.95945"
"95.57600","14.79458","5.90472"
"95.57800","14.86859","5.84964"
"95.58000","14.94259","5.79193"
"95.58200","15.01659","5.73602"
"95.58400","15.09060","5.68413"
"95.58600","15.16460","5.63176"
"95.58800","15.23860","5.57726"
"95.59000","15.31260","5.52354"
"95.59200","15.38660","5.47323"
"95.59400","15.46060","5.42531"
"95.59600","15.53460","5.37641"
"95.59800","15.60861","5.32639"
"95.60000","15.68262","5.27731"
"95.60200","15.75663","5.22969"
"95.60400","15.83064","5.18015"
"95.60600","15.90465","5.12558"
"95.60800","15.97866","5.06543"
"95.61000","16.05267","5.00071"
"95.61200","16.12668","4.93368"
"95.61400","16.20068","4.86460"
"95.61600","16.27469","4.79258"
"95.61800","16.34869","4.71892"
"95.62000","16.42269","4.64455"
"95.62200","16.49669","4.57075"
"95.62400","16.57068","4.49829"
"95.62600","16.64468","4.42687"
"95.62800","16.71867","4.35645"
"95.63000","16.79265","4.28658"
"95.63200","16.86664","4.21807"
"95.63400","16.94063","4.15344"
"95.63600","17.01461","4.09096"
"95.63800","17.08860","4.02815"
"95.64000","17.16260","3.96595"
"95.64200","17.23659","3.90473"
"95.64400","17.31058","3.84353"
"95.64600","17.38458","3.78315"
"95.64800","17.45857","3.72324"
"95.65000","17.53256","3.66177"
"95.65200","17.60656","3.59930"
"95.65400","17.68055","3.53833"
"95.65600","17.75455","3.47949"
"95.65800","17.82856","3.42330"
"95.66000","17.90256","3.36962"
"95.66200","17.97657","3.31748"
"95.66400","18.05058","3.26814"
"95.66600","18.12460","3.22277"
"95.66800","18.19861","3.18018"
"95.67000","18.27263","3.13857"
"95.67200","18.34665","3.09908"
"95.67400","18.42066","3.06311"
"95.67600","18.49468","3.02891"
"95.67800","18.56870","2.99431"
"95.68000","18.64272","2.96065"
"95.68200","18.71674","2.93065"
"95.68400","18.79076","2.90392"
"95.68600","18.86478","2.87701"
"95.68800","18.93880","2.84978"
"95.69000","19.01282","2.82534"
"95.69200","19.08683","2.80368"
"95.69400","19.16084","2.78265"
"95.69600","19.23485","2.76144"
"95.69800","19.30886","2.74166"
"95.70000","19.38288","2.72427"
"95.70200","19.45689","2.70768"
"95.70400","19.53090","2.69010"
"95.70600","19.60491","2.67203"
"95.70800","19.67892","2.65358"
"95.71000","19.75292","2.63430"
"95.71200","19.82692","2.61429"
"95.71400","19.90092","2.59175"
"95.71600","19.97491","2.56470"
"95.71800","20.04889","2.53213"
"95.72000","20.12287","2.49797"
"95.72200","20.19685","2.46335"
"95.72400","20.27083","2.42702"
"95.72600","20.34481","2.39058"
"95.72800","20.41879","2.35852"
"95.73000","20.49277","2.32985"
"95.73200","20.56675","2.30115"
"95.73400","20.64073","2.27403"
"95.73600","20.71471","2.25142"
"95.73800","20.78870","2.23152"
"95.74000","20.86269","2.21191"
"95.74200","20.93668","2.19392"
"95.74400","21.01067","2.17850"
"95.74600","21.08467","2.16403"
"95.74800","21.15866","2.14918"
"95.75000","21.23265","2.13388"
"95.75200","21.30665","2.11850"
"95.75400","21.38064","2.10352"