File: data/instron/Sample26_Control.is_tcyclic_RawData/Specimen_RawData_1.csv
Strain : Tensile strain (Extension) gauge length,100,mm,,,,
,,,,,,
Time,Extension,Load,,,,
(s),(mm),(N),Low Start,Low End,High Start,High End
0,0,0.40584,5,405,467,486
0.01,0,0.40794,,,,
0.02,0.00007,0.40864,,,,
0.03,0.00034,0.40662,,,,
0.04,0.00097,0.41115,,,,
0.05,0.00227,0.41224,,,,
0.06,0.00389,0.41054,,,,
0.07,0.00533,0.42006,,,,
0.08,0.00677,0.43931,,,,
0.09,0.00862,0.4527,,,,
0.1,0.01131,0.47131,,,,
0.11,0.01496,0.4953,,,,
0.12,0.01932,0.51697,,,,
0.13,0.024,0.53861,,,,
0.14,0.0287,0.5649,,,,
0.15,0.03326,0.59061,,,,
0.16,0.03765,0.61645,,,,
0.17,0.04191,0.64439,,,,
0.18,0.04603,0.67032,,,,
0.19,0.05001,0.69333,,,,
0.2,0.05381,0.71255,,,,
0.21,0.05749,0.73929,,,,
0.22,0.06108,0.76786,,,,
0.23,0.06463,0.79373,,,,
0.24,0.06819,0.81884,,,,
0.25,0.07182,0.8459,,,,
0.26,0.07552,0.87257,,,,
0.27,0.07928,0.9003,,,,
0.28,0.08305,0.933,,,,
0.29,0.08679,0.96772,,,,
0.3,0.09046,1.0025,,,,
0.31,0.09404,1.03462,,,,
0.32,0.09756,1.06478,,,,
0.33,0.10103,1.09328,,,,
0.34,0.10451,1.12587,,,,
0.35,0.10805,1.16245,,,,
0.36,0.11166,1.19708,,,,
0.37,0.11533,1.23271,,,,
0.38,0.11903,1.27014,,,,
0.39,0.12273,1.3096,,,,
0.4,0.1264,1.34758,,,,
0.41,0.13001,1.3829,,,,
0.42,0.13356,1.41972,,,,
0.43,0.13705,1.46101,,,,
0.44,0.14051,1.504,,,,
0.45,0.14401,1.54655,,,,
0.46,0.14758,1.59516,,,,
0.47,0.15121,1.64216,,,,
0.48,0.15486,1.68663,,,,
0.49,0.15852,1.73159,,,,
0.5,0.16216,1.77837,,,,
0.51,0.16577,1.82407,,,,
0.52,0.16934,1.87063,,,,
0.53,0.17288,1.91772,,,,
0.54,0.17642,1.96743,,,,
0.55,0.17996,2.02616,,,,
0.56,0.18353,2.08756,,,,
0.57,0.18713,2.14219,,,,
0.58,0.19076,2.19536,,,,
0.59,0.19439,2.25154,,,,
0.6,0.19801,2.31173,,,,
0.61,0.2016,2.36952,,,,
0.62,0.20516,2.42804,,,,
0.63,0.20869,2.48621,,,,
0.64,0.21223,2.54571,,,,
0.65,0.21581,2.60828,,,,
0.66,0.21945,2.67408,,,,
0.67,0.22311,2.74356,,,,
0.68,0.22678,2.81641,,,,
0.69,0.23041,2.88522,,,,
0.7,0.23401,2.9538,,,,
0.71,0.23758,3.02657,,,,
0.72,0.24111,3.09429,,,,
0.73,0.24463,3.15399,,,,
0.74,0.24818,3.2162,,,,
0.75,0.2518,3.29647,,,,
0.76,0.25549,3.39551,,,,
0.77,0.25923,3.47447,,,,
0.78,0.26296,3.54809,,,,
0.79,0.26665,3.63941,,,,
0.8,0.27026,3.72145,,,,
0.81,0.27382,3.78704,,,,
0.82,0.27732,3.86815,,,,
0.83,0.28079,3.95309,,,,
0.84,0.2843,4.03052,,,,
0.85,0.28787,4.1245,,,,
0.86,0.29151,4.22436,,,,
0.87,0.2952,4.31249,,,,
0.88,0.2989,4.40436,,,,
0.89,0.30255,4.50313,,,,
0.9,0.30614,4.59072,,,,
0.91,0.30968,4.6829,,,,
0.92,0.31316,4.78696,,,,
0.93,0.31663,4.88186,,,,
0.94,0.32013,4.97674,,,,
0.95,0.3237,5.082,,,,
0.96,0.32734,5.18313,,,,
0.97,0.33102,5.28461,,,,
0.98,0.33471,5.39049,,,,
0.99,0.33837,5.49787,,,,
1,0.34198,5.60179,,,,
1.01,0.34553,5.71166,,,,
1.02,0.34904,5.81944,,,,
1.03,0.35252,5.92164,,,,
1.04,0.35601,6.02978,,,,
1.05,0.35956,6.14272,,,,
1.06,0.36318,6.25801,,,,
1.07,0.36685,6.38096,,,,
1.08,0.37053,6.51026,,,,
1.09,0.37419,6.63588,,,,
1.1,0.37782,6.7586,,,,
1.11,0.3814,6.87897,,,,
1.12,0.38494,6.98993,,,,
1.13,0.38845,7.10055,,,,
1.14,0.39195,7.2228,,,,
1.15,0.39549,7.35601,,,,
1.16,0.39908,7.4891,,,,
1.17,0.40271,7.6259,,,,
1.18,0.40636,7.76369,,,,
1.19,0.41,7.90125,,,,
1.2,0.41362,8.03767,,,,
1.21,0.41721,8.17087,,,,
1.22,0.42077,8.30255,,,,
1.23,0.42431,8.43368,,,,
1.24,0.42785,8.57194,,,,
1.25,0.43143,8.71707,,,,
1.26,0.43506,8.8653,,,,
1.27,0.43874,9.02246,,,,
1.28,0.44244,9.17679,,,,
1.29,0.44611,9.32672,,,,
1.3,0.44974,9.4756,,,,
1.31,0.45334,9.62232,,,,
1.32,0.45691,9.76706,,,,
1.33,0.46046,9.91506,,,,
1.34,0.46403,10.07038,,,,
1.35,0.46764,10.22545,,,,
1.36,0.47127,10.38343,,,,
1.37,0.47492,10.54598,,,,
1.38,0.47856,10.7073,,,,
1.39,0.48216,10.86675,,,,
1.4,0.48573,11.03011,,,,
1.41,0.48926,11.19467,,,,
1.42,0.49277,11.3583,,,,
1.43,0.49629,11.51903,,,,
1.44,0.49984,11.68219,,,,
1.45,0.50347,11.85084,,,,
1.46,0.50714,12.02333,,,,
1.47,0.51083,12.20275,,,,
1.48,0.51447,12.3822,,,,
1.49,0.51805,12.56045,,,,
1.5,0.52158,12.73898,,,,
1.51,0.52508,12.91623,,,,
1.52,0.52857,13.08764,,,,
1.53,0.53209,13.26273,,,,
1.54,0.53565,13.44211,,,,
1.55,0.53927,13.62627,,,,
1.56,0.54294,13.81458,,,,
1.57,0.54662,14.0101,,,,
1.58,0.55028,14.20724,,,,
1.59,0.55388,14.40134,,,,
1.6,0.55743,14.59305,,,,
1.61,0.56095,14.78051,,,,
1.62,0.56445,14.96762,,,,
1.63,0.56796,15.15997,,,,
1.64,0.57152,15.35035,,,,
1.65,0.57514,15.54609,,,,
1.66,0.57881,15.74923,,,,
1.67,0.58249,15.95346,,,,
1.68,0.58617,16.15981,,,,
1.69,0.58981,16.36379,,,,
1.7,0.5934,16.55927,,,,
1.71,0.59693,16.7511,,,,
1.72,0.60043,16.94361,,,,
1.73,0.60393,17.14451,,,,
1.74,0.60748,17.35079,,,,
1.75,0.6111,17.56315,,,,
1.76,0.61478,17.7799,,,,
1.77,0.61848,18.00023,,,,
1.78,0.62219,18.22347,,,,
1.79,0.62587,18.44628,,,,
1.8,0.6295,18.66544,,,,
1.81,0.63307,18.87986,,,,
1.82,0.63659,19.09647,,,,
1.83,0.64009,19.31535,,,,
1.84,0.64361,19.53442,,,,
1.85,0.64719,19.75929,,,,
1.86,0.65084,19.99322,,,,
1.87,0.65451,20.22869,,,,
1.88,0.65819,20.45885,,,,
1.89,0.66185,20.68974,,,,
1.9,0.66547,20.91852,,,,
1.91,0.66907,21.14174,,,,
1.92,0.67262,21.37223,,,,
1.93,0.67613,21.60703,,,,
1.94,0.67966,21.8429,,,,
1.95,0.68321,22.08629,,,,
1.96,0.68681,22.33095,,,,
1.97,0.69043,22.56928,,,,
1.98,0.69406,22.80991,,,,
1.99,0.69768,23.05205,,,,
2,0.70128,23.29115,,,,
2.01,0.70485,23.52723,,,,
2.02,0.7084,23.76819,,,,
2.03,0.71195,24.01375,,,,
2.04,0.71552,24.25883,,,,
2.05,0.71911,24.51034,,,,
2.06,0.72272,24.76581,,,,
2.07,0.72632,25.02471,,,,
2.08,0.72991,25.28448,,,,
2.09,0.73348,25.54329,,,,
2.1,0.73703,25.79775,,,,
2.11,0.74056,26.0487,,,,
2.12,0.74409,26.29606,,,,
2.13,0.74765,26.55035,,,,
2.14,0.75127,26.81252,,,,
2.15,0.75493,27.08806,,,,
2.16,0.75861,27.37495,,,,
2.17,0.76228,27.66088,,,,
2.18,0.76592,27.94174,,,,
2.19,0.7695,28.21624,,,,
2.2,0.77304,28.48266,,,,
2.21,0.77656,28.74008,,,,
2.22,0.78006,29.00016,,,,
2.23,0.78361,29.26726,,,,
2.24,0.78722,29.5385,,,,
2.25,0.79091,29.81971,,,,
2.26,0.79463,30.11016,,,,
2.27,0.79832,30.39744,,,,
2.28,0.80195,30.68292,,,,
2.29,0.80551,30.9694,,,,
2.3,0.80903,31.24999,,,,
2.31,0.81254,31.52969,,,,
2.32,0.81606,31.81608,,,,
2.33,0.81962,32.11153,,,,
2.34,0.82326,32.41036,,,,
2.35,0.82697,32.71454,,,,
2.36,0.83073,33.01992,,,,
2.37,0.83446,33.32874,,,,
2.38,0.83813,33.62833,,,,
2.39,0.84171,33.91924,,,,
2.4,0.84523,34.21391,,,,
2.41,0.84871,34.50776,,,,
2.42,0.85216,34.79539,,,,
2.43,0.85564,35.08957,,,,
2.44,0.85919,35.39188,,,,
2.45,0.86282,35.69939,,,,
2.46,0.86651,36.01617,,,,
2.47,0.87024,36.33688,,,,
2.48,0.87395,36.64928,,,,
2.49,0.87759,36.95928,,,,
2.5,0.88116,37.26668,,,,
2.51,0.88466,37.56873,,,,
2.52,0.88813,37.87072,,,,
2.53,0.89162,38.18204,,,,
2.54,0.89516,38.50587,,,,
2.55,0.89878,38.83741,,,,
2.56,0.90244,39.17259,,,,
2.57,0.90611,39.50624,,,,
2.58,0.90975,39.82844,,,,
2.59,0.91337,40.14668,,,,
2.6,0.91695,40.46423,,,,
2.61,0.92047,40.77457,,,,
2.62,0.92396,41.08454,,,,
2.63,0.92744,41.40683,,,,
2.64,0.93096,41.74244,,,,
2.65,0.93455,42.09061,,,,
2.66,0.93818,42.44704,,,,
2.67,0.94184,42.80216,,,,
2.68,0.9455,43.15018,,,,
2.69,0.94913,43.48955,,,,
2.7,0.95272,43.82306,,,,
2.71,0.95628,44.14977,,,,
2.72,0.95981,44.47689,,,,
2.73,0.96335,44.81353,,,,
2.74,0.96692,45.16378,,,,
2.75,0.97052,45.52433,,,,
2.76,0.97415,45.8904,,,,
2.77,0.9778,46.26014,,,,
2.78,0.98143,46.62741,,,,
2.79,0.98503,46.98837,,,,
2.8,0.98861,47.33985,,,,
2.81,0.99218,47.68575,,,,
2.82,0.99576,48.03283,,,,
2.83,0.99939,48.38574,,,,
2.84,1.00307,48.74797,,,,
2.85,1.00677,49.12193,,,,
2.86,1.01048,49.50039,,,,
2.87,1.01414,49.87661,,,,
2.88,1.01775,50.24491,,,,
2.89,1.0213,50.60633,,,,
2.9,1.02481,50.96006,,,,
2.91,1.02829,51.30579,,,,
2.92,1.03179,51.65161,,,,
2.93,1.03534,52.00341,,,,
2.94,1.03898,52.3683,,,,
2.95,1.04268,52.74699,,,,
2.96,1.0464,53.1324,,,,
2.97,1.05009,53.51688,,,,
2.98,1.0537,53.89275,,,,
2.99,1.05724,54.26287,,,,
3,1.06074,54.62574,,,,
3.01,1.06421,54.98288,,,,
3.02,1.06768,55.3404,,,,
3.03,1.07119,55.70482,,,,
3.04,1.07478,56.0758,,,,
3.05,1.07845,56.45952,,,,
3.06,1.08216,56.85045,,,,
3.07,1.08587,57.24044,,,,
3.08,1.08954,57.62709,,,,
3.09,1.09314,58.00967,,,,
3.1,1.09667,58.387,,,,
3.11,1.10016,58.76347,,,,
3.12,1.10362,59.13681,,,,
3.13,1.10712,59.51399,,,,
3.14,1.11069,59.90005,,,,
3.15,1.11433,60.29636,,,,
3.16,1.11802,60.69474,,,,
3.17,1.12172,61.09753,,,,
3.18,1.12539,61.49598,,,,
3.19,1.12901,61.88663,,,,
3.2,1.13256,62.27015,,,,
3.21,1.13606,62.64919,,,,
3.22,1.13952,63.02687,,,,
3.23,1.14301,63.41031,,,,
3.24,1.14656,63.80614,,,,
3.25,1.15017,64.20831,,,,
3.26,1.15382,64.61522,,,,
3.27,1.15749,65.02258,,,,
3.28,1.16114,65.42236,,,,
3.29,1.16475,65.81828,,,,
3.3,1.16834,66.20809,,,,
3.31,1.17189,66.59659,,,,
3.32,1.17542,66.98847,,,,
3.33,1.17896,67.38932,,,,
3.34,1.18255,67.8044,,,,
3.35,1.1862,68.23003,,,,
3.36,1.18989,68.6588,,,,
3.37,1.19358,69.08575,,,,
3.38,1.19726,69.50207,,,,
3.39,1.2009,69.90813,,,,
3.4,1.20452,70.30217,,,,
3.41,1.20811,70.69204,,,,
3.42,1.21168,71.08263,,,,
3.43,1.21525,71.47753,,,,
3.44,1.21884,71.88409,,,,
3.45,1.22245,72.29993,,,,
3.46,1.22608,72.72278,,,,
3.47,1.22969,73.14097,,,,
3.48,1.23327,73.54488,,,,
3.49,1.23683,73.93953,,,,
3.5,1.24037,74.32381,,,,
3.51,1.2439,74.70777,,,,
3.52,1.24745,75.10011,,,,
3.53,1.25104,75.50454,,,,
3.54,1.25467,75.92475,,,,
3.55,1.25833,76.35168,,,,
3.56,1.26198,76.78155,,,,
3.57,1.26558,77.20419,,,,
3.58,1.26913,77.61728,,,,
3.59,1.27266,78.02245,,,,
3.6,1.27619,78.42065,,,,
3.61,1.27971,78.81642,,,,
3.62,1.28326,79.21651,,,,
3.63,1.28686,79.62144,,,,
3.64,1.29051,80.04077,,,,
3.65,1.29418,80.46664,,,,
3.66,1.29785,80.89616,,,,
3.67,1.30146,81.32403,,,,
3.68,1.30503,81.74641,,,,
3.69,1.30855,82.16058,,,,
3.7,1.31206,82.56956,,,,
3.71,1.31555,82.97287,,,,
3.72,1.31908,83.3768,,,,
3.73,1.32266,83.78964,,,,
3.74,1.32631,84.21451,,,,
3.75,1.33,84.64594,,,,
3.76,1.33369,85.07626,,,,
3.77,1.33735,85.50649,,,,
3.78,1.34095,85.93004,,,,
3.79,1.34449,86.34827,,,,
3.8,1.34799,86.75822,,,,
3.81,1.35147,87.16618,,,,
3.82,1.35499,87.58138,,,,
3.83,1.35857,88.00888,,,,
3.84,1.36222,88.44212,,,,
3.85,1.36594,88.87489,,,,
3.86,1.36967,89.3053,,,,
3.87,1.37339,89.73095,,,,
3.88,1.37706,90.1461,,,,
3.89,1.38067,90.55183,,,,
3.9,1.38422,90.95589,,,,
3.91,1.38773,91.35527,,,,
3.92,1.39125,91.76067,,,,
3.93,1.39481,92.17648,,,,
3.94,1.39841,92.59749,,,,
3.95,1.40206,93.01799,,,,
3.96,1.40571,93.43746,,,,
3.97,1.40936,93.85164,,,,
3.98,1.41299,94.25915,,,,
3.99,1.41659,94.66474,,,,
4,1.42015,95.06336,,,,
4.01,1.42366,95.45825,,,,
4.02,1.42718,95.86167,,,,
4.03,1.43072,96.28078,,,,
4.04,1.43431,96.71096,,,,
4.05,1.43794,97.14088,,,,
4.051,1.43831,97.18398,,,,
4.052,1.43867,97.22709,,,,
4.152,1.43692,94.38426,,,,
4.204,1.41606,89.28825,,,,
4.261,1.39398,84.2146,,,,
4.325,1.3704,79.21266,,,,
4.393,1.34606,74.2065,,,,
4.465,1.32001,69.16888,,,,
4.541,1.29286,64.13148,,,,
4.621,1.26411,59.08364,,,,
4.705,1.23359,54.04319,,,,
4.794,1.20147,49.02579,,,,
4.889,1.16735,44.01018,,,,
4.989,1.13175,39.134,,,,
5.089,1.09584,34.58554,,,,
5.189,1.05974,30.40602,,,,
5.289,1.02363,26.57524,,,,
5.389,0.98752,23.08712,,,,
5.489,0.95179,19.96787,,,,
5.589,0.91598,17.13913,,,,
5.689,0.88004,14.62185,,,,
5.789,0.84405,12.38344,,,,
5.889,0.80793,10.404,,,,
5.989,0.77214,8.69211,,,,
6.089,0.73619,7.18742,,,,
6.189,0.70022,5.87947,,,,
6.289,0.66426,4.75586,,,,
6.389,0.62834,3.79414,,,,
6.489,0.59259,3.00309,,,,
6.589,0.55663,2.32463,,,,
6.689,0.52073,1.78317,,,,
6.789,0.48452,1.34798,,,,
6.889,0.44859,1.00397,,,,
6.989,0.41268,0.74197,,,,
7.089,0.37706,0.54749,,,,
7.189,0.34105,0.40004,,,,
7.289,0.30499,0.28862,,,,
7.389,0.26899,0.21286,,,,
7.489,0.23288,0.15873,,,,
7.589,0.19716,0.12074,,,,
7.689,0.16126,0.09463,,,,
7.789,0.12528,0.0752,,,,
7.889,0.08932,0.06055,,,,
7.989,0.05339,0.05131,,,,
8.089,0.01762,0.04597,,,,
8.137,0.00024,0.03462,,,,
8.138,-0.00014,0.03487,,,,
8.139,-0.00051,0.03521,,,,
8.239,0.00056,0.0599,,,,
8.339,0.04037,0.06566,,,,
8.439,0.07731,0.0899,,,,
8.539,0.11342,0.11519,,,,
8.639,0.1494,0.1631,,,,
8.739,0.18535,0.21418,,,,
8.839,0.22132,0.29015,,,,
8.939,0.25737,0.40404,,,,
9.003,0.28046,0.50198,,,,
9.004,0.28081,0.50396,,,,
9.005,0.28116,0.50591,,,,
9.01,0.28292,0.52325,,,,
9.015,0.28508,0.59536,,,,
9.02,0.28891,0.71205,,,,
9.025,0.2963,0.87786,,,,
9.03,0.3094,1.1122,,,,
9.035,0.33035,1.47438,,,,
9.04,0.36111,2.06954,,,,
9.045,0.40336,3.09158,,,,
9.05,0.45846,4.84563,,,,
9.055,0.52747,7.77682,,,,
9.06,0.61115,12.48312,,,,
9.065,0.71,19.66951,,,,
9.07,0.8243,29.99109,,,,
9.075,0.95405,43.84218,,,,
9.08,1.09859,61.02299,,,,
9.085,1.2556,80.7543,,,,
9.09,1.42173,102.00037,,,,
9.095,1.59375,123.68425,,,,
9.1,1.76924,144.37949,,,,
9.105,1.94673,163.60515,,,,
9.11,2.12542,181.42586,,,,
9.115,2.305,197.7811,,,,
9.12,2.48534,212.58678,,,,
9.125,2.66639,225.79642,,,,
9.13,2.84805,237.51498,,,,
9.135,3.03015,247.9068,,,,
9.14,3.2125,257.0769,,,,
9.145,3.39492,264.90637,,,,
9.15,3.57723,268.79779,,,,
9.155,3.75931,253.79124,,,,
9.16,3.94112,223.91649,,,,
9.165,4.12268,187.02782,,,,
9.17,4.30401,148.59123,,,,
9.175,4.48514,112.24882,,,,
9.18,4.66605,80.08685,,,,
9.185,4.84676,53.11566,,,,
9.19,5.02726,31.63803,,,,
9.195,5.20755,15.36242,,,,
9.2,5.38765,3.70399,,,,
9.205,5.56762,-4.07771,,,,
9.21,5.7475,-8.73148,,,,
9.215,5.92732,-11.0125,,,,
9.22,6.1071,-11.59903,,,,
9.225,6.28686,-11.04799,,,,
9.23,6.46663,-9.82005,,,,
9.235,6.6464,-8.24146,,,,
9.24,6.82616,-6.57202,,,,
9.245,7.00591,-4.97452,,,,
9.25,7.18568,-3.55165,,,,
9.255,7.36545,-2.34864,,,,
9.26,7.5452,-1.38813,,,,
9.265,7.72493,-0.65653,,,,
9.27,7.90465,-0.13875,,,,
9.275,8.08438,0.20381,,,,
9.28,8.26412,0.42024,,,,
9.285,8.44387,0.52034,,,,
9.29,8.62366,0.5484,,,,
9.295,8.80347,0.52131,,,,
9.3,8.98328,0.47083,,,,
9.305,9.16308,0.4021,,,,
9.31,9.34288,0.33496,,,,
9.315,9.52267,0.26729,,,,
9.32,9.70245,0.20524,,,,
9.325,9.88221,0.16216,,,,
9.33,10.06195,0.12315,,,,
9.335,10.24166,0.09213,,,,
9.34,10.42134,0.0653,,,,
9.345,10.601,0.0507,,,,
9.35,10.78066,0.0351,,,,
9.355,10.96033,0.02863,,,,
9.36,11.14002,0.02319,,,,
9.365,11.31971,0.02307,,,,
9.37,11.4994,0.02524,,,,
9.375,11.6791,0.03023,,,,
9.38,11.85881,0.03674,,,,
9.385,12.03851,0.03746,,,,
9.39,12.21821,0.0455,,,,
9.395,12.39793,0.05082,,,,
9.4,12.57765,0.06089,,,,
9.405,12.75735,0.07359,,,,
9.41,12.93704,0.07806,,,,
9.415,13.11672,0.08015,,,,
9.42,13.29641,0.08596,,,,
9.425,13.47611,0.08847,,,,
9.43,13.6558,0.09472,,,,
9.435,13.83549,0.10466,,,,
9.44,14.01519,0.11617,,,,
9.445,14.1949,0.12699,,,,
9.45,14.3746,0.13506,,,,
9.455,14.5543,0.14097,,,,
9.46,14.73402,0.1465,,,,
9.465,14.91375,0.15744,,,,
9.47,15.09347,0.16882,,,,
9.475,15.27317,0.18886,,,,
9.48,15.45286,0.19641,,,,
9.485,15.63253,0.20991,,,,
9.49,15.8122,0.21528,,,,
9.495,15.99187,0.22849,,,,
9.5,16.17156,0.24043,,,,
9.505,16.35126,0.25527,,,,
9.51,16.53096,0.26904,,,,
9.515,16.71064,0.28458,,,,
9.52,16.89032,0.29849,,,,
9.525,17.06999,0.31597,,,,
9.53,17.24964,0.33458,,,,
9.535,17.4293,0.35365,,,,
9.54,17.60897,0.38074,,,,
9.545,17.78865,0.40929,,,,
9.55,17.96835,0.43041,,,,
9.555,18.14804,0.44765,,,,
9.558,18.25587,0.45896,,,,