File: data/instron/Sample27_Dynamic.is_tcyclic_RawData/Specimen_RawData_1.csv
Strain : Tensile strain (Extension) gauge length,"100.00000",mm

Time,Extension,Load
(s),(mm),(N)
"0.00000","0.00000","0.19831"
"0.20000","0.12879","1.12361"
"0.40000","0.29302","4.06162"
"0.60000","0.45628","9.27986"
"0.80000","0.61977","16.66124"
"1.00000","0.78338","26.07791"
"1.04400","0.81937","28.38477"
"1.14500","0.80396","25.05146"
"1.28200","0.68685","15.00747"
"1.48100","0.52380","6.16895"
"1.68100","0.36016","1.70251"
"1.88100","0.19640","0.25053"
"2.08100","0.03284","0.05640"
"2.12300","-0.00122","0.04194"
"2.22400","0.01330","0.06411"
"2.42400","0.18337","0.47232"
"2.62400","0.34718","2.71812"
"2.82400","0.51084","8.18764"
"3.02400","0.67437","16.97081"
"3.20100","0.81878","26.97106"
"3.20300","0.82043","27.09175"
"3.36400","0.75049","19.07011"
"3.54300","0.60241","9.07592"
"3.74300","0.43854","2.90652"
"3.94300","0.27506","0.51425"
"4.14300","0.11153","0.06531"
"4.28000","-0.00013","0.02847"
"4.28200","-0.00176","0.02860"
"4.48200","0.10097","0.12514"
"4.68200","0.26543","0.97003"
"4.88200","0.42889","4.39521"
"5.08200","0.59241","11.37447"
"5.27400","0.74975","21.20289"
"5.35800","0.81817","26.26871"
"5.36000","0.81981","26.39477"
"5.52200","0.74910","18.48455"
"5.70200","0.60021","8.58007"
"5.90200","0.43634","2.61095"
"6.10200","0.27285","0.41505"
"6.30200","0.10931","0.05962"
"6.43700","-0.00074","0.02488"
"6.43900","-0.00236","0.02471"
"6.63900","0.10036","0.09844"
"6.83900","0.26484","0.83136"
"7.03900","0.42830","4.03951"
"7.23900","0.59194","10.88956"
"7.43100","0.74916","20.70630"
"7.51600","0.81839","25.88088"
"7.51800","0.82004","26.00717"
"7.68000","0.74940","18.19331"
"7.86000","0.60049","8.33438"
"8.06000","0.43665","2.44990"
"8.26000","0.27315","0.37325"
"8.46000","0.10960","0.04956"
"8.59500","-0.00048","0.02129"
"8.59700","-0.00210","0.02107"
"8.79700","0.10063","0.09235"
"8.99700","0.26511","0.73736"
"9.19700","0.42857","3.81671"
"9.39700","0.59220","10.57912"
"9.58800","0.74861","20.33795"
"9.67400","0.81864","25.59772"
"9.67600","0.82029","25.72618"
"9.83800","0.74974","17.96216"
"10.01800","0.60083","8.14510"
"10.21800","0.43700","2.33883"
"10.41800","0.27347","0.33875"
"10.61800","0.10995","0.04588"
"10.75300","-0.00017","0.02280"
"10.75500","-0.00179","0.02251"
"10.95500","0.10092","0.07995"
"11.15500","0.26541","0.67242"
"11.35500","0.42884","3.63752"
"11.55500","0.59248","10.33393"
"11.74600","0.74888","20.08879"
"11.83100","0.81811","25.31654"
"11.83300","0.81975","25.44491"
"11.99500","0.74923","17.72676"
"12.17500","0.60032","7.95590"
"12.37500","0.43652","2.23517"
"12.57500","0.27296","0.30881"
"12.77500","0.10944","0.04084"
"12.91000","-0.00067","0.01665"
"12.91200","-0.00230","0.01707"
"13.11200","0.10039","0.07900"
"13.31200","0.26487","0.61494"
"13.51200","0.42832","3.47360"
"13.71200","0.59192","10.09393"
"13.90400","0.74916","19.89085"
"13.98900","0.81840","25.12628"
"13.99100","0.82005","25.25562"
"14.15300","0.74955","17.57429"
"14.33400","0.59982","7.79412"
"14.53400","0.43600","2.14771"
"14.73400","0.27244","0.27206"
"14.93400","0.10892","0.03597"
"15.06800","-0.00037","0.02349"
"15.07000","-0.00200","0.02311"
"15.27000","0.10067","0.07264"
"15.47000","0.26513","0.58343"
"15.67000","0.42859","3.36317"
"15.87000","0.59219","9.94115"
"16.06100","0.74859","19.67589"
"16.14700","0.81865","24.98586"
"16.14900","0.82029","25.11541"
"16.31100","0.74987","17.45518"
"16.49200","0.60012","7.69671"
"16.69200","0.43642","2.08906"
"16.89200","0.27274","0.26765"
"17.09200","0.10922","0.03675"
"17.22600","-0.00006","0.01430"
"17.22800","-0.00169","0.01300"
"17.42800","0.10091","0.07985"
"17.62800","0.26538","0.54372"
"17.82800","0.42882","3.27545"
"18.02800","0.59241","9.79339"
"18.21900","0.74884","19.54474"
"18.30400","0.81808","24.80207"
"18.30600","0.81972","24.93204"
"18.46800","0.74931","17.29773"
"18.64900","0.59953","7.56180"
"18.84900","0.43584","2.01591"
"19.04900","0.27216","0.24512"
"19.24900","0.10866","0.03893"
"19.38300","-0.00064","0.01623"
"19.38500","-0.00227","0.01614"
"19.58500","0.10033","0.06828"
"19.78500","0.26478","0.50958"
"19.98500","0.42826","3.16260"
"20.18500","0.59186","9.63599"
"20.37600","0.74827","19.36604"
"20.46200","0.81831","24.68915"
"20.46400","0.81995","24.81952"
"20.62600","0.74963","17.20839"
"20.80700","0.59984","7.48359"
"21.00700","0.43618","1.97164"
"21.20700","0.27249","0.24090"
"21.40700","0.10900","0.03583"
"21.54100","-0.00033","0.02071"
"21.54300","-0.00196","0.02045"
"21.74300","0.10063","0.06250"
"21.94300","0.26509","0.48953"
"22.14300","0.42856","3.09885"
"22.34300","0.59204","9.53707"
"22.53400","0.74856","19.25593"
"22.62000","0.81861","24.59871"
"22.62200","0.82026","24.72947"
"22.78400","0.74996","17.13045"
"22.96500","0.60016","7.42516"
"23.16500","0.43652","1.92645"
"23.36500","0.27283","0.22607"
"23.56500","0.10931","0.03709"
"23.69900","0.00000","0.01742"
"23.70100","-0.00163","0.01742"
"23.90100","0.10095","0.07233"
"24.10100","0.26543","0.47453"
"24.30100","0.42889","3.03805"
"24.50100","0.59227","9.43363"
"24.69200","0.74888","19.16306"
"24.77700","0.81810","24.43691"
"24.77900","0.81975","24.56856"
"24.94200","0.74865","16.93521"
"25.12400","0.59805","7.24082"
"25.32400","0.43444","1.84894"
"25.52400","0.27070","0.20837"
"25.72400","0.10718","0.02727"
"25.85600","-0.00049","0.01714"
"25.85800","-0.00212","0.01760"
"26.05800","0.10049","0.06411"
"26.25800","0.26495","0.44467"
"26.45800","0.42844","2.94888"
"26.65800","0.59180","9.29627"
"26.84900","0.74842","19.02315"
"26.93500","0.81844","24.36035"
"26.93700","0.82008","24.49133"
"27.09900","0.74988","16.93964"
"27.28000","0.60007","7.27048"
"27.48000","0.43649","1.83973"
"27.68000","0.27275","0.20888"
"27.88000","0.10925","0.03363"
"28.01400","-0.00008","0.01899"
"28.01600","-0.00171","0.01867"
"28.21600","0.10085","0.05810"
"28.41600","0.26530","0.44195"
"28.61600","0.42881","2.90338"
"28.81600","0.59226","9.24302"
"29.00700","0.74880","18.95306"
"29.09300","0.81879","24.30213"
"29.09500","0.82044","24.43397"
"29.25800","0.74941","16.81978"
"29.44000","0.59882","7.13922"
"29.64000","0.43525","1.78452"
"29.84000","0.27147","0.19341"
"30.04000","0.10797","0.03636"
"30.17300","-0.00051","0.01138"
"30.17500","-0.00215","0.01091"
"30.37500","0.10040","0.05495"
"30.57500","0.26483","0.42484"
"30.77500","0.42831","2.84024"
"30.97500","0.59192","9.14606"
"31.16600","0.74833","18.84165"
"31.25200","0.81833","24.19224"
"31.25400","0.81998","24.32488"
"31.41700","0.74888","16.71731"
"31.59900","0.59833","7.06356"
"31.79900","0.43476","1.74140"
"31.99900","0.27095","0.18841"
"32.19900","0.10748","0.02673"
"32.33100","-0.00019","0.00862"
"32.33300","-0.00183","0.00941"
"32.53300","0.10072","0.05642"
"32.73300","0.26515","0.41348"
"32.93300","0.42862","2.80673"
"33.13300","0.59230","9.09416"
"33.32400","0.74864","18.78485"
"33.41000","0.81864","24.14713"
"33.41200","0.82028","24.27859"
"33.57500","0.74929","16.68382"
"33.75700","0.59873","7.02853"
"33.95700","0.43513","1.72750"
"34.15700","0.27135","0.19025"
"34.35700","0.10787","0.02538"
"34.49000","-0.00062","0.01004"
"34.49200","-0.00226","0.01080"
"34.69200","0.10026","0.05879"
"34.89200","0.26467","0.40175"
"35.09200","0.42814","2.74726"
"35.29200","0.59179","9.00813"
"35.48300","0.74817","18.68062"
"35.56900","0.81818","24.04678"
"35.57100","0.81982","24.17903"
"35.73400","0.74876","16.58945"
"35.91600","0.59821","6.96270"
"36.11600","0.43464","1.68696"
"36.31600","0.27086","0.17472"
"36.51600","0.10737","0.03409"
"36.64800","-0.00031","0.00592"
"36.65000","-0.00195","0.00622"
"36.85000","0.10060","0.05137"
"37.05000","0.26499","0.38270"
"37.25000","0.42845","2.71634"
"37.45000","0.59208","8.94151"
"37.64100","0.74848","18.63494"
"37.72700","0.81852","23.99787"
"37.72900","0.82016","24.12873"
"37.89200","0.74915","16.54690"
"38.07400","0.59858","6.92706"
"38.27400","0.43500","1.67210"
"38.47400","0.27124","0.17313"
"38.67400","0.10774","0.02834"
"38.80700","-0.00075","0.01288"
"38.80900","-0.00239","0.01279"
"39.00900","0.10017","0.04629"
"39.20900","0.26456","0.36456"
"39.40900","0.42801","2.67024"
"39.60900","0.59162","8.86469"
"39.80000","0.74803","18.54097"
"39.88600","0.81809","23.90233"
"39.88800","0.81973","24.03386"
"40.05100","0.74864","16.46388"
"40.23300","0.59813","6.86485"
"40.43300","0.43454","1.63961"
"40.63300","0.27076","0.16540"
"40.83300","0.10727","0.02578"
"40.96500","-0.00040","0.01390"
"40.96700","-0.00204","0.01396"
"41.16700","0.10052","0.06004"
"41.36700","0.26491","0.36584"
"41.56700","0.42838","2.63979"
"41.76700","0.59197","8.82958"
"41.95800","0.74837","18.49644"
"42.04400","0.81845","23.87288"
"42.04600","0.82009","24.00543"
"42.20900","0.74906","16.43991"
"42.39100","0.59851","6.83570"
"42.59100","0.43491","1.61900"
"42.79100","0.27115","0.16384"
"42.99100","0.10765","0.02013"
"43.12300","-0.00003","0.00955"
"43.12500","-0.00166","0.00946"
"43.32500","0.10092","0.05605"
"43.52500","0.26529","0.35886"
"43.72500","0.42879","2.61449"
"43.92500","0.59237","8.79868"
"44.11600","0.74876","18.47419"
"44.20100","0.81800","23.78532"
"44.20300","0.81965","23.91814"
"44.36600","0.74855","16.35407"
"44.54900","0.59724","6.73405"
"44.74900","0.43362","1.57786"
"44.94900","0.26984","0.15744"
"45.14900","0.10631","0.02395"
"45.28000","-0.00048","0.01256"
"45.28200","-0.00212","0.01266"
"45.48200","0.10044","0.04712"
"45.68200","0.26483","0.34693"
"45.88200","0.42831","2.56503"
"46.08200","0.59191","8.71822"
"46.27400","0.74911","18.43334"
"46.35900","0.81837","23.76306"
"46.36100","0.82001","23.89539"
"46.52300","0.74983","16.40567"
"46.70500","0.59925","6.78858"
"46.90500","0.43564","1.59006"
"47.10500","0.27188","0.16518"
"47.30500","0.10841","0.02808"
"47.43800","-0.00010","0.01138"
"47.44000","-0.00174","0.01140"
"47.64000","0.10082","0.04737"
"47.84000","0.26522","0.33993"
"48.04000","0.42868","2.54632"
"48.24000","0.59229","8.69745"
"48.43100","0.74867","18.35845"
"48.51700","0.81875","23.74934"
"48.51900","0.82039","23.88181"
"48.68200","0.74932","16.31505"
"48.86500","0.59797","6.70263"
"49.06500","0.43433","1.55260"
"49.26500","0.27057","0.15623"
"49.46500","0.10719","0.02427"
"49.59700","-0.00055","0.01047"
"49.59900","-0.00219","0.01008"
"49.79900","0.10033","0.04799"
"49.99900","0.26475","0.33383"
"50.19900","0.42814","2.50353"
"50.39900","0.59184","8.62650"
"50.59100","0.74899","18.32973"
"50.67600","0.81828","23.66801"
"50.67800","0.81992","23.80115"
"50.84100","0.74883","16.24637"
"51.02400","0.59750","6.64590"
"51.22400","0.43386","1.52980"
"51.42400","0.27008","0.13847"
"51.62400","0.10678","0.02495"
"51.75500","-0.00020","0.00970"
"51.75700","-0.00184","0.00930"
"51.95700","0.10068","0.04780"
"52.15700","0.26511","0.32377"
"52.35700","0.42844","2.48575"
"52.55700","0.59219","8.60241"
"52.74800","0.74852","18.25672"
"52.83400","0.81863","23.65696"
"52.83600","0.82027","23.79071"
"52.99900","0.74913","16.22963"
"53.18200","0.59781","6.62709"
"53.38200","0.43416","1.50717"
"53.58200","0.27040","0.14984"
"53.78200","0.10710","0.02313"
"53.91400","-0.00081","0.01270"
"53.91600","-0.00244","0.01314"
"54.11600","0.10017","0.04928"
"54.31600","0.26461","0.31293"
"54.51600","0.42808","2.45749"
"54.71600","0.59169","8.53671"
"54.90700","0.74802","18.17787"
"54.99300","0.81813","23.57794"
"54.99500","0.81978","23.71093"
"55.15800","0.74862","16.15338"
"55.34100","0.59731","6.58022"
"55.54100","0.43367","1.49215"
"55.74100","0.26991","0.13921"
"55.94100","0.10649","0.03094"
"56.07200","-0.00048","0.01115"
"56.07400","-0.00212","0.01136"
"56.27400","0.10051","0.05175"
"56.47400","0.26494","0.31848"
"56.67400","0.42843","2.44154"
"56.87400","0.59202","8.51630"
"57.06500","0.74836","18.16686"
"57.15100","0.81847","23.56936"
"57.15300","0.82011","23.70169"
"57.31500","0.74986","16.21714"
"57.49700","0.59930","6.63369"
"57.69700","0.43564","1.50717"
"57.89700","0.27193","0.14271"
"58.09700","0.10849","0.02494"
"58.23000","-0.00012","0.01661"
"58.23200","-0.00177","0.01666"
"58.43200","0.10078","0.04545"
"58.63200","0.26523","0.30126"
"58.83200","0.42870","2.41316"
"59.03200","0.59231","8.48836"
"59.22300","0.74864","18.13259"
"59.30900","0.81875","23.54612"
"59.31100","0.82040","23.67895"
"59.47400","0.74925","16.12422"
"59.65700","0.59792","6.54456"
"59.85700","0.43424","1.46467"
"60.05700","0.27053","0.14178"
"60.25700","0.10709","0.02249"
"60.38900","-0.00058","0.00913"
"60.39100","-0.00222","0.00825"
"60.59100","0.10023","0.05097"
"60.79100","0.26468","0.30148"
"60.99100","0.42816","2.37244"
"61.19100","0.59175","8.41250"
"61.38200","0.74808","18.05071"
"61.46800","0.81810","23.44755"
"61.47000","0.81975","23.58081"
"61.63300","0.74884","16.05866"
"61.81600","0.59751","6.49851"
"62.01600","0.43382","1.44291"
"62.21600","0.27010","0.13686"
"62.41600","0.10674","0.02322"
"62.54700","-0.00029","0.00558"
"62.54900","-0.00192","0.00609"
"62.74900","0.10061","0.04909"
"62.94900","0.26506","0.29151"
"63.14900","0.42854","2.36800"
"63.34900","0.59213","8.39899"
"63.54000","0.74847","18.03142"
"63.62600","0.81844","23.44076"
"63.62800","0.82008","23.57452"
"63.79000","0.75010","16.11685"
"63.97200","0.59955","6.55575"
"64.17200","0.43583","1.45944"
"64.37200","0.27216","0.12870"
"64.57200","0.10843","0.01630"
"64.70600","-0.00068","0.00575"
"64.70800","-0.00231","0.00552"
"64.90800","0.10012","0.04343"
"65.10800","0.26460","0.28876"
"65.30800","0.42808","2.32679"
"65.50800","0.59167","8.34311"
"65.69900","0.74796","17.95949"
"65.78500","0.81804","23.36217"
"65.78700","0.81968","23.49563"
"65.95000","0.74886","16.00118"
"66.13300","0.59752","6.44324"
"66.33300","0.43381","1.41537"
"66.53300","0.27010","0.12582"
"66.73300","0.10646","0.02055"
"66.86400","-0.00045","0.00938"
"66.86600","-0.00207","0.00920"
"67.06600","0.10056","0.04313"
"67.26600","0.26500","0.28520"
"67.46600","0.42849","2.31484"
"67.66600","0.59210","8.32638"
"67.85700","0.74826","17.93985"
"67.94300","0.81847","23.36530"
"67.94500","0.82012","23.49858"
"68.10700","0.75022","16.07134"
"68.28900","0.59966","6.51484"
"68.48900","0.43589","1.43346"
"68.68900","0.27225","0.12931"
"68.88900","0.10866","0.02862"
"69.02300","-0.00079","0.01159"
"69.02500","-0.00242","0.01133"
"69.22500","0.10009","0.04041"
"69.42500","0.26456","0.27625"
"69.62500","0.42803","2.29417"
"69.82500","0.59168","8.27326"
"70.01700","0.74862","17.94019"
"70.10300","0.81881","23.36118"
"70.10500","0.82045","23.49370"
"70.26700","0.75066","16.07080"
"70.44900","0.60009","6.50690"
"70.64900","0.43629","1.42476"
"70.84900","0.27268","0.13300"
"71.04900","0.10933","0.02232"
"71.18300","-0.00041","0.00865"
"71.18500","-0.00205","0.00857"
"71.38500","0.10056","0.03714"
"71.58500","0.26499","0.27889"
"71.78500","0.42842","2.27994"
"71.98500","0.59213","8.26458"
"72.17600","0.74824","17.87171"
"72.26200","0.81838","23.28951"
"72.26400","0.82002","23.42296"
"72.42700","0.74945","15.95396"
"72.61000","0.59811","6.39255"
"72.81000","0.43431","1.38527"
"73.01000","0.27066","0.12417"
"73.21000","0.10762","0.02661"
"73.34200","-0.00062","0.01206"
"73.34400","-0.00229","0.01298"
"73.54400","0.10001","0.04438"
"73.74400","0.26446","0.27062"
"73.94400","0.42790","2.25115"
"74.14400","0.59161","8.19987"
"74.33500","0.74772","17.80924"
"74.42200","0.81868","23.28910"
"74.42400","0.82033","23.42365"
"74.58700","0.74978","15.94751"
"74.76900","0.59924","6.41877"
"74.96900","0.43541","1.39232"
"75.16900","0.27181","0.12604"
"75.36900","0.10883","0.02302"
"75.50200","0.00000","0.01131"
"75.50400","-0.00165","0.01129"
"75.70400","0.10021","0.04250"
"75.90400","0.26466","0.26519"
"76.10400","0.42807","2.23507"
"76.30400","0.59182","8.18046"
"76.49600","0.74869","17.83900"
"76.58100","0.81804","23.20209"
"76.58300","0.81969","23.33614"
"76.74600","0.74913","15.87579"
"76.92900","0.59779","6.32910"
"77.12900","0.43396","1.35165"
"77.32900","0.27033","0.12422"
"77.52900","0.10730","0.02230"
"77.66100","-0.00050","0.00686"
"77.66300","-0.00212","0.00692"
"77.86300","0.09943","0.04088"
"78.06300","0.26392","0.26487"
"78.26300","0.42734","2.19543"
"78.46300","0.59110","8.12110"
"78.65500","0.74794","17.75294"
"78.74100","0.81823","23.19716"
"78.74300","0.81989","23.33068"
"78.90600","0.74918","15.85296"
"79.08900","0.59783","6.31116"
"79.28900","0.43400","1.33839"
"79.48900","0.27036","0.12148"
"79.68900","0.10715","0.02570"
"79.82100","-0.00044","0.00873"
"79.82300","-0.00205","0.00905"
"80.02300","0.09943","0.04225"
"80.22300","0.26389","0.24996"
"80.42300","0.42733","2.17655"
"80.62300","0.59107","8.09645"
"80.81500","0.74797","17.72937"
"80.90100","0.81825","23.17510"
"80.90300","0.81991","23.31061"
"81.06600","0.74910","15.82243"
"81.24900","0.59777","6.28935"
"81.44900","0.43391","1.32931"
"81.64900","0.27026","0.11740"
"81.84900","0.10697","0.02766"
"81.98100","-0.00066","0.00309"
"81.98300","-0.00227","0.00239"
"82.18300","0.09928","0.03681"
"82.38300","0.26374","0.25389"
"82.58300","0.42717","2.16349"
"82.78300","0.59091","8.05969"
"82.97400","0.74706","17.64801"
"83.06100","0.81815","23.15096"
"83.06300","0.81980","23.28541"
"83.22500","0.74980","15.86048"
"83.40700","0.59921","6.34530"
"83.60700","0.43536","1.34823"
"83.80700","0.27172","0.11403"
"84.00700","0.10837","0.01844"
"84.14000","-0.00013","0.00771"
"84.14200","-0.00176","0.00652"
"84.34200","0.09994","0.04092"
"84.54200","0.26439","0.25571"
"84.74200","0.42784","2.16019"
"84.94200","0.59156","8.06178"
"85.13300","0.74779","17.67150"
"85.22000","0.81881","23.18892"
"85.22200","0.82047","23.32444"
"85.38400","0.75046","15.87279"
"85.56600","0.59986","6.33713"
"85.76600","0.43599","1.33904"
"85.96600","0.27236","0.12662"
"86.16600","0.10898","0.01507"
"86.30000","-0.00029","0.01403"
"86.30200","-0.00193","0.01458"
"86.50200","0.09977","0.03902"
"86.70200","0.26422","0.25270"
"86.90200","0.42767","2.13783"
"87.10200","0.59138","8.03168"
"87.29300","0.74757","17.62360"
"87.38000","0.81870","23.14678"
"87.38200","0.82036","23.28182"
"87.54400","0.75029","15.83572"
"87.72700","0.59887","6.27715"
"87.92700","0.43500","1.31875"
"88.12700","0.27136","0.11237"
"88.32700","0.10797","0.01677"
"88.46000","-0.00038","0.00614"
"88.46200","-0.00203","0.00607"
"88.66200","0.09965","0.03525"
"88.86200","0.26410","0.24301"
"89.06200","0.42754","2.12134"
"89.26200","0.59125","7.99751"
"89.45300","0.74743","17.59375"
"89.54000","0.81863","23.11360"
"89.54200","0.82029","23.24977"
"89.70500","0.74920","15.73075"
"89.88800","0.59784","6.21238"
"90.08800","0.43398","1.28792"
"90.28800","0.27035","0.10805"
"90.48800","0.10695","0.02086"
"90.62000","-0.00052","0.00791"
"90.62200","-0.00217","0.00690"
"90.82200","0.09948","0.03846"
"91.02200","0.26393","0.24610"
"91.22200","0.42739","2.10942"
"91.42200","0.59102","7.95858"
"91.61300","0.74728","17.54818"
"91.70000","0.81849","23.07992"
"91.70200","0.82014","23.21461"
"91.86500","0.74908","15.70404"
"92.04800","0.59771","6.19052"
"92.24800","0.43382","1.27711"
"92.44800","0.27022","0.10644"
"92.64800","0.10681","0.02131"
"92.78000","-0.00060","0.00842"
"92.78200","-0.00226","0.00814"
"92.98200","0.09934","0.03915"
"93.18200","0.26381","0.23906"
"93.38200","0.42726","2.09459"
"93.58200","0.59082","7.92465"
"93.77300","0.74718","17.51697"
"93.86000","0.81833","23.04448"
"93.86200","0.81998","23.17826"
"94.02500","0.74887","15.65796"
"94.20800","0.59751","6.15930"
"94.40800","0.43362","1.26192"
"94.60800","0.27005","0.10479"
"94.80800","0.10661","0.01984"
"94.94000","-0.00065","0.00838"
"94.94200","-0.00230","0.00823"
"95.14200","0.09912","0.03306"
"95.34200","0.26357","0.22711"
"95.54200","0.42705","2.07543"
"95.74200","0.59055","7.88956"
"95.93300","0.74697","17.47527"
"96.02000","0.81809","23.00993"
"96.02200","0.81973","23.14274"
"96.18500","0.74868","15.63089"
"96.36800","0.59730","6.12637"
"96.56800","0.43341","1.25349"
"96.76800","0.26986","0.10444"
"96.96800","0.10639","0.01230"
"97.10000","-0.00077","0.00652"
"97.10200","-0.00241","0.00627"
"97.30200","0.01876","0.01679"
"97.50200","0.08563","0.03240"
"97.70200","0.15104","0.06100"
"97.90200","0.21642","0.11980"
"98.10200","0.28192","0.31801"
"98.19500","0.31206","0.50438"
"98.20600","0.31565","0.52264"
"98.22600","0.32043","0.54761"
"98.24600","0.32377","0.56577"
"98.26600","0.32662","0.58549"
"98.28600","0.32970","0.62623"
"98.30600","0.33567","0.69371"
"98.32600","0.34372","0.77430"
"98.34600","0.35202","0.86707"
"98.36600","0.35986","0.95102"
"98.38600","0.36715","1.03790"
"98.40600","0.37399","1.13167"
"98.42600","0.38053","1.23057"
"98.44600","0.38708","1.33404"
"98.46600","0.39374","1.44017"
"98.48600","0.40044","1.55635"
"98.50600","0.40704","1.67684"
"98.52600","0.41350","1.79878"
"98.54600","0.42003","1.93183"
"98.56600","0.42664","2.07026"
"98.58600","0.43323","2.21554"
"98.60600","0.43972","2.36337"
"98.62600","0.44617","2.51280"
"98.64600","0.45271","2.68516"
"98.66600","0.45948","2.86536"
"98.68600","0.46627","3.05260"
"98.70600","0.47285","3.24165"
"98.72600","0.47924","3.43593"
"98.74600","0.48560","3.62785"
"98.76600","0.49214","3.83707"
"98.78600","0.49888","4.05292"
"98.80600","0.50555","4.27323"
"98.82600","0.51197","4.49725"
"98.84600","0.51828","4.73257"
"98.86600","0.52467","4.96993"
"98.88600","0.53135","5.22675"
"98.90600","0.53818","5.49236"
"98.92600","0.54484","5.75863"
"98.94600","0.55121","6.03169"
"98.96600","0.55747","6.29764"
"98.98600","0.56386","6.57920"
"99.00600","0.57051","6.87384"
"99.02600","0.57721","7.17310"
"99.04600","0.58379","7.47413"
"99.06600","0.59019","7.78221"
"99.08600","0.59655","8.08734"
"99.10600","0.60311","8.42227"
"99.12600","0.60981","8.76287"
"99.14600","0.61645","9.10997"
"99.16600","0.62300","9.45177"
"99.18600","0.62944","9.79601"
"99.20600","0.63594","10.15878"
"99.22600","0.64266","10.53825"
"99.24600","0.64943","10.92351"
"99.26600","0.65608","11.30106"
"99.28600","0.66256","11.67373"
"99.30600","0.66900","12.05271"
"99.32600","0.67554","12.45637"
"99.34600","0.68213","12.86829"
"99.36600","0.68862","13.27457"
"99.38600","0.69504","13.68118"
"99.40600","0.70145","14.08994"
"99.42600","0.70804","14.50874"
"99.44600","0.71473","14.95573"
"99.46600","0.72128","15.40256"
"99.48600","0.72775","15.84734"
"99.50600","0.73426","16.29387"
"99.52600","0.74086","16.75306"
"99.54600","0.74754","17.22281"
"99.56600","0.75416","17.69004"
"99.58600","0.76058","18.15367"
"99.60600","0.76690","18.61844"
"99.62600","0.77330","19.09159"
"99.64600","0.77993","19.59070"
"99.66600","0.78673","20.10991"
"99.68600","0.79345","20.62560"
"99.70600","0.79990","21.12796"
"99.72600","0.80618","21.61997"
"99.74600","0.81260","22.12380"
"99.76600","0.81929","22.65781"
"99.78600","0.82607","23.19035"
"99.80600","0.83272","23.71833"
"99.82600","0.83920","24.24453"
"99.84600","0.84561","24.76990"
"99.86600","0.85213","25.32073"
"99.88600","0.85876","25.87194"
"99.90600","0.86538","26.41275"
"99.92600","0.87195","26.95582"
"99.94600","0.87838","27.48502"
"99.96600","0.88479","28.02196"
"99.98600","0.89133","28.57277"
"100.00600","0.89793","29.13054"
"100.02600","0.90452","29.67905"
"100.04600","0.91102","30.20672"
"100.06600","0.91752","30.73987"
"100.08600","0.92409","31.29683"
"100.10600","0.93068","31.85870"
"100.12600","0.93720","32.41477"
"100.14600","0.94368","32.95085"
"100.16600","0.95013","33.47628"
"100.18600","0.95672","34.01370"
"100.20600","0.96339","34.57851"
"100.22600","0.96998","35.14264"
"100.24600","0.97643","35.68947"
"100.26600","0.98280","36.22839"
"100.28600","0.98927","36.76535"
"100.30600","0.99600","37.33534"
"100.32600","1.00274","37.91204"
"100.34600","1.00927","38.47380"
"100.36600","1.01565","39.02106"
"100.38600","1.02204","39.55979"
"100.40600","1.02863","40.11800"
"100.42600","1.03546","40.70141"
"100.44600","1.04220","41.27943"
"100.46600","1.04866","41.83795"
"100.48600","1.05498","42.39014"
"100.50600","1.06138","42.94837"
"100.52600","1.06803","43.53755"
"100.54600","1.07480","44.12710"
"100.56600","1.08145","44.69633"
"100.58600","1.08788","45.26158"
"100.60600","1.09419","45.81868"
"100.62600","1.10069","46.40563"
"100.64600","1.10740","47.01493"
"100.66600","1.11407","47.60203"
"100.68600","1.12060","48.17229"
"100.70600","1.12697","48.73215"
"100.72600","1.13330","49.29605"
"100.74600","1.13978","49.89051"
"100.76600","1.14641","50.49905"
"100.78600","1.15307","51.10365"
"100.80600","1.15961","51.68208"
"100.82600","1.16608","52.26549"
"100.84600","1.17263","52.86934"
"100.86600","1.17929","53.49585"
"100.88600","1.18593","54.11335"
"100.90600","1.19244","54.69323"
"100.92600","1.19888","55.24725"
"100.94600","1.20546","55.83172"
"100.96600","1.21219","56.44628"
"100.98600","1.21885","57.06932"
"101.00600","1.22535","57.66622"
"101.02600","1.23173","58.24497"
"101.04600","1.23812","58.82948"
"101.06600","1.24476","59.43389"
"101.08600","1.25155","60.06860"
"101.10600","1.25815","60.67696"
"101.12600","1.26452","61.26060"
"101.14600","1.27083","61.83482"
"101.16600","1.27732","62.43193"
"101.18600","1.28408","63.05194"
"101.20600","1.29086","63.67661"
"101.22600","1.29735","64.27781"
"101.24600","1.30365","64.86333"
"101.26600","1.30995","65.45211"
"101.28600","1.31654","66.07122"
"101.30600","1.32334","66.71334"
"101.32600","1.33005","67.33394"
"101.34600","1.33652","67.92343"
"101.36600","1.34279","68.49793"
"101.38600","1.34915","69.09693"
"101.40600","1.35579","69.73988"
"101.42600","1.36255","70.37566"
"101.44600","1.36920","70.97716"
"101.46600","1.37570","71.56610"
"101.48600","1.38210","72.15915"
"101.50600","1.38862","72.78091"
"101.52600","1.39531","73.42412"
"101.54600","1.40197","74.04642"
"101.56600","1.40853","74.63648"
"101.58600","1.41501","75.21429"
"101.60600","1.42153","75.81634"
"101.62600","1.42814","76.44781"
"101.64600","1.43472","77.06861"
"101.66600","1.44121","77.65341"
"101.68600","1.44765","78.22943"
"101.70600","1.45416","78.81679"
"101.72600","1.46084","79.43519"
"101.74600","1.46747","80.05677"
"101.76600","1.47391","80.65570"
"101.78600","1.48029","81.23017"
"101.80600","1.48671","81.80129"
"101.82600","1.49328","82.39426"
"101.84600","1.49999","83.01036"
"101.86600","1.50658","83.62261"
"101.88600","1.51300","84.20221"
"101.90600","1.51936","84.77760"
"101.92600","1.52585","85.36070"
"101.94600","1.53257","85.96667"
"101.96600","1.53933","86.57903"
"101.98600","1.54589","87.17161"
"102.00600","1.55222","87.73568"
"102.02600","1.55852","88.30016"
"102.04600","1.56508","88.89250"
"102.06600","1.57187","89.51215"
"102.08600","1.57865","90.12032"
"102.10600","1.58527","90.71240"
"102.12600","1.59171","91.28477"
"102.14600","1.59815","91.85542"
"102.16600","1.60473","92.44671"
"102.18600","1.61138","93.03802"
"102.20600","1.61796","93.59407"
"102.21500","1.62091","93.83740"
"102.31600","1.61988","91.75637"
"102.46500","1.56728","81.70696"
"102.64700","1.50788","71.67091"
"102.84500","1.44253","61.72097"
"103.04500","1.37723","52.62826"
"103.24500","1.31201","44.41573"
"103.44500","1.24646","36.97047"
"103.64500","1.18112","30.33165"
"103.84500","1.11563","24.49764"
"104.04500","1.05011","19.39702"
"104.24500","0.98449","15.02744"
"104.44500","0.91931","11.29310"
"104.64500","0.85377","8.13438"
"104.84500","0.78833","5.56800"
"105.04500","0.72305","3.55365"
"105.24500","0.65736","2.07957"
"105.44500","0.59214","1.10029"
"105.64500","0.52656","0.52406"
"105.84500","0.46119","0.22401"
"106.04500","0.39594","0.10328"
"106.24500","0.33035","0.06263"
"106.30300","0.31121","0.05205"
"106.40400","0.31157","0.07335"
"106.60400","0.38108","0.17451"
"106.80400","0.44675","0.44671"
"106.82800","0.45464","0.50327"
"106.83000","0.45532","0.50803"
"106.83200","0.45599","0.51358"
"106.83400","0.45668","0.52451"
"106.83600","0.45742","0.54529"
"106.83800","0.45827","0.57498"
"106.84000","0.45932","0.61247"
"106.84200","0.46067","0.65902"
"106.84400","0.46244","0.71613"
"106.84600","0.46476","0.78348"
"106.84800","0.46776","0.86153"
"106.85000","0.47159","0.95416"
"106.85200","0.47638","1.06525"
"106.85400","0.48228","1.19997"
"106.85600","0.48941","1.36477"
"106.85800","0.49792","1.56759"
"106.86000","0.50791","1.81840"
"106.86200","0.51952","2.13033"
"106.86400","0.53285","2.51766"
"106.86600","0.54800","2.99628"
"106.86800","0.56506","3.58546"
"106.87000","0.58413","4.30634"
"106.87200","0.60528","5.17959"
"106.87400","0.62858","6.22882"
"106.87600","0.65409","7.47967"
"106.87800","0.68187","8.95779"
"106.88000","0.71196","10.68979"
"106.88200","0.74441","12.70318"
"106.88400","0.77925","15.02764"
"106.88600","0.81650","17.68958"
"106.88800","0.85619","20.71139"
"106.89000","0.89832","24.11204"
"106.89200","0.94289","27.90683"
"106.89400","0.98984","32.09987"
"106.89600","1.03912","36.68092"
"106.89800","1.09061","41.63184"
"106.90000","1.14414","46.92882"
"106.90200","1.19955","52.53963"
"106.90400","1.25663","58.42169"
"106.90600","1.31518","64.52667"
"106.90800","1.37499","70.80725"
"106.91000","1.43588","77.21646"
"106.91200","1.49769","83.70539"
"106.91400","1.56025","90.22243"
"106.91600","1.62345","96.69940"
"106.91800","1.68716","103.06326"
"106.92000","1.75130","109.27905"
"106.92200","1.81579","115.32941"
"106.92400","1.88058","120.93127"
"106.92600","1.94562","125.42021"
"106.92800","2.01089","128.59885"
"106.93000","2.07634","130.63486"
"106.93200","2.14196","131.74438"
"106.93400","2.20774","132.09244"
"106.93600","2.27366","131.56078"
"106.93800","2.33970","129.59483"
"106.94000","2.40586","126.08184"
"106.94200","2.47213","121.28193"
"106.94400","2.53848","115.50250"
"106.94600","2.60492","108.99728"
"106.94800","2.67143","101.97921"
"106.95000","2.73800","94.63411"
"106.95200","2.80462","87.12454"
"106.95400","2.87126","79.58472"
"106.95600","2.93792","72.12704"
"106.95800","3.00459","64.84496"
"106.96000","3.07125","57.81360"
"106.96200","3.13789","51.09362"
"106.96400","3.20450","44.73085"
"106.96600","3.27106","38.75430"
"106.96800","3.33758","33.18586"
"106.97000","3.40404","28.04165"
"106.97200","3.47045","23.32967"
"106.97400","3.53680","19.04582"
"106.97600","3.60309","15.18016"
"106.97800","3.66931","11.71972"
"106.98000","3.73548","8.65259"
"106.98200","3.80158","5.96327"
"106.98400","3.86762","3.63077"
"106.98600","3.93360","1.62732"
"106.98800","3.99953","-0.07441"
"106.99000","4.06540","-1.49952"
"106.99200","4.13123","-2.67103"
"106.99400","4.19700","-3.61070"
"106.99600","4.26274","-4.34154"
"106.99800","4.32844","-4.88943"
"107.00000","4.39411","-5.27966"
"107.00200","4.45975","-5.53089"
"107.00400","4.52537","-5.65923"
"107.00600","4.59097","-5.68285"
"107.00800","4.65656","-5.62090"
"107.01000","4.72212","-5.48905"
"107.01200","4.78768","-5.29912"
"107.01400","4.85323","-5.06107"
"107.01600","4.91876","-4.78416"
"107.01800","4.98429","-4.48003"
"107.02000","5.04982","-4.16017"
"107.02200","5.11534","-3.83353"
"107.02400","5.18086","-3.50565"
"107.02600","5.24638","-3.17839"
"107.02800","5.31189","-2.85443"
"107.03000","5.37740","-2.53974"
"107.03200","5.44290","-2.24152"
"107.03400","5.50840","-1.96192"
"107.03600","5.57390","-1.70007"
"107.03800","5.63939","-1.45534"
"107.04000","5.70487","-1.22863"
"107.04200","5.77036","-1.02184"
"107.04400","5.83584","-0.83349"
"107.04600","5.90132","-0.66238"
"107.04800","5.96680","-0.50722"
"107.05000","6.03228","-0.36775"
"107.05200","6.09776","-0.24526"
"107.05400","6.16323","-0.14062"
"107.05600","6.22870","-0.05085"
"107.05800","6.29417","0.02762"
"107.06000","6.35964","0.09671"
"107.06200","6.42510","0.15490"
"107.06400","6.49057","0.19994"
"107.06600","6.55603","0.23156"
"107.06800","6.62149","0.25280"
"107.07000","6.68695","0.26747"
"107.07200","6.75240","0.27821"
"107.07400","6.81786","0.28460"
"107.07600","6.88331","0.28516"
"107.07800","6.94875","0.27992"
"107.08000","7.01419","0.27291"
"107.08200","7.07963","0.26619"
"107.08400","7.14507","0.25792"
"107.08600","7.21051","0.24609"
"107.08800","7.27595","0.23078"
"107.09000","7.34140","0.21646"
"107.09200","7.40685","0.20435"
"107.09400","7.47230","0.19267"
"107.09600","7.53776","0.18032"
"107.09800","7.60322","0.16643"
"107.10000","7.66868","0.15131"
"107.10200","7.73415","0.13678"
"107.10400","7.79961","0.12470"
"107.10600","7.86508","0.11422"
"107.10800","7.93054","0.10424"
"107.11000","7.99601","0.09443"
"107.11200","8.06148","0.08665"
"107.11400","8.12695","0.08140"
"107.11600","8.19243","0.07657"
"107.11800","8.25790","0.07252"
"107.12000","8.32337","0.06974"
"107.12200","8.38884","0.06626"
"107.12400","8.45430","0.06160"
"107.12600","8.51976","0.05881"
"107.12800","8.58522","0.05783"
"107.13000","8.65067","0.05417"
"107.13200","8.71612","0.04678"
"107.13400","8.78157","0.03966"
"107.13600","8.84702","0.03574"
"107.13800","8.91246","0.03388"
"107.14000","8.97791","0.03192"
"107.14200","9.04335","0.02944"
"107.14400","9.10879","0.02831"
"107.14600","9.17423","0.02942"
"107.14800","9.23966","0.03232"
"107.15000","9.30510","0.03637"
"107.15200","9.37053","0.04067"
"107.15400","9.43596","0.04224"
"107.15600","9.50139","0.04031"
"107.15800","9.56682","0.03919"
"107.16000","9.63225","0.04039"
"107.16200","9.69769","0.04043"
"107.16400","9.76313","0.03656"
"107.16600","9.82858","0.03187"
"107.16800","9.89403","0.02994"
"107.17000","9.95949","0.03082"
"107.17200","10.02495","0.03270"
"107.17400","10.09041","0.03222"
"107.17600","10.15588","0.02990"
"107.17800","10.22134","0.03013"
"107.18000","10.28682","0.03360"
"107.18200","10.35230","0.03784"
"107.18400","10.41778","0.03979"
"107.18600","10.48326","0.04024"
"107.18800","10.54875","0.04040"
"107.19000","10.61423","0.04165"
"107.19200","10.67972","0.04263"
"107.19400","10.74520","0.04159"
"107.19600","10.81067","0.03966"
"107.19800","10.87615","0.03938"
"107.20000","10.94162","0.03980"
"107.20200","11.00709","0.03829"
"107.20400","11.07256","0.03491"
"107.20600","11.13802","0.03197"
"107.20800","11.20348","0.03004"
"107.21000","11.26895","0.02876"
"107.21200","11.33440","0.02850"
"107.21400","11.39986","0.02975"
"107.21600","11.46531","0.03197"
"107.21800","11.53076","0.03421"
"107.22000","11.59620","0.03475"
"107.22200","11.66164","0.03499"
"107.22400","11.72708","0.03630"
"107.22600","11.79251","0.03652"
"107.22800","11.85794","0.03487"
"107.23000","11.92337","0.03301"
"107.23200","11.98880","0.03266"
"107.23400","12.05422","0.03256"
"107.23600","12.11964","0.03142"
"107.23800","12.18505","0.03033"
"107.24000","12.25047","0.03051"
"107.24200","12.31588","0.03150"
"107.24400","12.38129","0.03400"
"107.24600","12.44671","0.03872"
"107.24800","12.51213","0.04318"
"107.25000","12.57755","0.04534"
"107.25200","12.64297","0.04647"
"107.25400","12.70840","0.04817"
"107.25600","12.77384","0.04990"
"107.25800","12.83927","0.05049"
"107.26000","12.90471","0.05052"
"107.26200","12.97015","0.05046"
"107.26400","13.03559","0.05063"
"107.26600","13.10102","0.05085"
"107.26800","13.16646","0.05169"
"107.27000","13.23190","0.05274"
"107.27200","13.29734","0.05255"
"107.27400","13.36279","0.05214"
"107.27600","13.42823","0.05272"
"107.27800","13.49368","0.05421"
"107.28000","13.55912","0.05551"
"107.28200","13.62457","0.05556"
"107.28400","13.69001","0.05463"
"107.28600","13.75545","0.05355"
"107.28800","13.82089","0.05201"
"107.29000","13.88633","0.05039"
"107.29200","13.95177","0.04847"
"107.29400","14.01721","0.04635"
"107.29600","14.08266","0.04340"
"107.29800","14.14810","0.04014"
"107.30000","14.21355","0.03765"
"107.30200","14.27900","0.03561"
"107.30400","14.34444","0.03458"
"107.30600","14.40989","0.03453"
"107.30800","14.47533","0.03531"
"107.31000","14.54077","0.03558"
"107.31200","14.60620","0.03467"
"107.31400","14.67163","0.03463"
"107.31600","14.73707","0.03509"
"107.31800","14.80250","0.03412"
"107.32000","14.86794","0.03141"
"107.32200","14.93338","0.02884"
"107.32400","14.99882","0.02781"
"107.32600","15.06427","0.02656"
"107.32800","15.12971","0.02434"
"107.33000","15.19516","0.02314"
"107.33200","15.26060","0.02471"
"107.33400","15.32604","0.02678"
"107.33600","15.39149","0.02798"
"107.33800","15.45693","0.02887"
"107.34000","15.52237","0.03095"
"107.34200","15.58782","0.03277"
"107.34400","15.65326","0.03339"
"107.34600","15.71871","0.03525"
"107.34800","15.78415","0.03782"
"107.35000","15.84959","0.03843"
"107.35200","15.91503","0.03818"
"107.35400","15.98047","0.03967"
"107.35600","16.04590","0.04132"
"107.35800","16.11133","0.03998"
"107.36000","16.17677","0.03676"
"107.36200","16.24220","0.03436"
"107.36400","16.30763","0.03273"
"107.36600","16.37306","0.03105"
"107.36800","16.43850","0.02881"
"107.37000","16.50393","0.02746"
"107.37200","16.56937","0.02773"
"107.37400","16.63480","0.02877"
"107.37600","16.70024","0.02955"
"107.37800","16.76567","0.03052"
"107.38000","16.83110","0.03218"