File: data/instron/Sample13_Static.is_tcyclic_RawData/Specimen_RawData_1.csv
Strain : Tensile strain (Extension) gauge length,"100.00000",mm

Time,Extension,Load
(s),(mm),(N)
"0.00000","0.00000","0.27603"
"0.20000","0.04374","0.53858"
"0.40000","0.10276","0.93370"
"0.60000","0.16182","1.40059"
"0.80000","0.21984","1.91422"
"1.00000","0.27860","2.49407"
"1.20000","0.33737","3.14977"
"1.40000","0.39557","3.86734"
"1.60000","0.45433","4.70590"
"1.80000","0.51297","5.61858"
"2.00000","0.57143","6.61247"
"2.20000","0.62991","7.73016"
"2.40000","0.68863","8.94254"
"2.60000","0.74711","10.32094"
"2.80000","0.80564","11.92534"
"3.00000","0.86423","13.72576"
"3.20000","0.92272","15.76975"
"3.40000","0.98140","18.10987"
"3.54900","1.02497","20.00182"
"3.55100","1.02555","20.02698"
"3.75100","1.03381","19.19779"
"3.95100","1.03201","18.48861"
"4.15100","1.03162","18.06976"
"4.35100","1.03153","17.77056"
"4.55100","1.03153","17.53679"
"4.75100","1.03153","17.34166"
"4.95100","1.03153","17.16123"
"5.15100","1.03153","17.01661"
"5.35100","1.03153","16.88878"
"5.55100","1.03147","16.76156"
"5.75100","1.03144","16.65385"
"5.95100","1.03149","16.56184"
"6.15100","1.03150","16.46461"
"6.35100","1.03151","16.38282"
"6.55100","1.03151","16.30097"
"6.75100","1.03151","16.22750"
"6.95100","1.03151","16.15257"
"7.15100","1.03151","16.08982"
"7.35100","1.03151","16.02265"
"7.55100","1.03151","15.96569"
"7.75100","1.03151","15.90311"
"7.95100","1.03152","15.85054"
"8.15100","1.03153","15.79573"
"8.35100","1.03153","15.74175"
"8.55100","1.03153","15.69911"
"8.75100","1.03153","15.65690"
"8.95100","1.03153","15.60865"
"9.15100","1.03153","15.56228"
"9.35100","1.03153","15.53160"
"9.55100","1.03153","15.48474"
"9.75100","1.03153","15.45244"
"9.95100","1.03153","15.40997"
"10.15100","1.03153","15.36421"
"10.35100","1.03153","15.33951"
"10.55100","1.03153","15.30161"
"10.75100","1.03153","15.26064"
"10.95100","1.03153","15.23616"
"11.15100","1.03153","15.19747"
"11.35100","1.03153","15.16492"
"11.55100","1.03153","15.12824"
"11.75100","1.03153","15.10687"
"11.95100","1.03153","15.07840"
"12.15100","1.03153","15.05655"
"12.35100","1.03153","15.02744"
"12.55100","1.03153","15.00324"
"12.75100","1.03153","14.97732"
"12.95100","1.03153","14.95916"
"13.15100","1.03153","14.92721"
"13.35100","1.03153","14.90370"
"13.55100","1.03153","14.87645"
"13.75100","1.03153","14.84909"
"13.95100","1.03153","14.83126"
"14.15100","1.03153","14.80875"
"14.35100","1.03153","14.78298"
"14.55100","1.03153","14.75954"
"14.75100","1.03153","14.73419"
"14.95100","1.03153","14.71834"
"15.15100","1.03153","14.69485"
"15.35100","1.03153","14.67538"
"15.55100","1.03153","14.66179"
"15.75100","1.03153","14.63918"
"15.95100","1.03153","14.61483"
"16.15100","1.03153","14.60017"
"16.35100","1.03153","14.57335"
"16.55100","1.03153","14.56119"
"16.75100","1.03153","14.54025"
"16.95100","1.03153","14.52416"
"17.15100","1.03153","14.50842"
"17.35100","1.03153","14.49402"
"17.55100","1.03153","14.46993"
"17.75100","1.03153","14.44769"
"17.95100","1.03153","14.44026"
"18.15100","1.03153","14.43145"
"18.35100","1.03153","14.40816"
"18.55100","1.03153","14.39289"
"18.75100","1.03153","14.36968"
"18.95100","1.03153","14.35834"
"19.15100","1.03153","14.33561"
"19.35100","1.03153","14.31701"
"19.55100","1.03153","14.30825"
"19.75100","1.03153","14.28798"
"19.95100","1.03153","14.27355"
"20.15100","1.03153","14.25830"
"20.35100","1.03153","14.24180"
"20.55100","1.03153","14.22991"
"20.75100","1.03153","14.21383"
"20.95100","1.03153","14.20507"
"21.15100","1.03153","14.18127"
"21.35100","1.03153","14.16751"
"21.55100","1.03153","14.15444"
"21.75100","1.03153","14.14285"
"21.95100","1.03153","14.12734"
"22.15100","1.03153","14.11082"
"22.35100","1.03153","14.10557"
"22.55100","1.03153","14.09385"
"22.75100","1.03153","14.07921"
"22.95100","1.03153","14.06357"
"23.15100","1.03153","14.05671"
"23.35100","1.03153","14.05069"
"23.55000","1.03153","14.03716"
"23.58800","1.03153","14.03004"
"23.78800","0.98590","10.68409"
"23.98800","0.92670","7.55789"
"24.18800","0.86819","5.41318"
"24.38800","0.80958","3.88049"
"24.58800","0.75113","2.73215"
"24.78800","0.69244","1.90622"
"24.98800","0.63376","1.28043"
"25.18800","0.57547","0.84143"
"25.38800","0.51666","0.52173"
"25.58800","0.45827","0.30686"
"25.78800","0.39970","0.15025"
"25.98800","0.34109","0.06204"
"26.18800","0.28242","-0.01306"
"26.38800","0.22401","-0.04326"
"26.58800","0.16549","-0.06685"
"26.78800","0.10658","-0.08530"
"26.98800","0.04839","-0.08633"
"27.13100","0.00650","-0.09466"
"27.13300","0.00591","-0.09419"
"27.33300","0.03844","-0.08322"
"27.53300","0.09820","-0.05095"
"27.73300","0.15721","-0.01087"
"27.93300","0.21533","0.05174"
"28.13300","0.27411","0.16112"
"28.33300","0.33279","0.32913"
"28.53300","0.39108","0.58365"
"28.73300","0.44990","0.94114"
"28.93300","0.50839","1.42009"
"29.13300","0.56693","2.05877"
"29.33300","0.62551","2.86438"
"29.53300","0.68396","3.85613"
"29.73300","0.74280","5.10969"
"29.93300","0.80108","6.62574"
"30.13300","0.85954","8.47792"
"30.33300","0.91836","10.76327"
"30.53300","0.97675","13.48997"
"30.72000","1.03146","16.48701"
"30.72200","1.03203","16.51948"
"30.92200","1.04043","16.31888"
"31.12200","1.03867","15.87671"
"31.32200","1.03819","15.63927"
"31.52200","1.03819","15.47127"
"31.72200","1.03809","15.35857"
"31.92200","1.03809","15.24737"
"32.12200","1.03809","15.16342"
"32.32200","1.03809","15.09020"
"32.52200","1.03809","15.01149"
"32.72200","1.03809","14.95272"
"32.92200","1.03809","14.90122"
"33.12200","1.03809","14.85229"
"33.32200","1.03809","14.79294"
"33.52200","1.03809","14.75694"
"33.72200","1.03800","14.71431"
"33.92200","1.03806","14.67895"
"34.12200","1.03807","14.64071"
"34.32200","1.03809","14.60054"
"34.52200","1.03809","14.57930"
"34.72200","1.03809","14.55123"
"34.92200","1.03809","14.51715"
"35.12200","1.03809","14.48245"
"35.32200","1.03809","14.45980"
"35.52200","1.03809","14.43575"
"35.72200","1.03809","14.40273"
"35.92200","1.03809","14.38916"
"36.12200","1.03809","14.35580"
"36.32200","1.03809","14.33850"
"36.52200","1.03809","14.31265"
"36.72200","1.03809","14.29053"
"36.92200","1.03809","14.26738"
"37.12200","1.03809","14.25085"
"37.32200","1.03809","14.23792"
"37.52200","1.03809","14.21690"
"37.72200","1.03809","14.19530"
"37.92200","1.03809","14.17921"
"38.12200","1.03809","14.15916"
"38.32200","1.03809","14.14356"
"38.52200","1.03809","14.12532"
"38.72200","1.03809","14.10279"
"38.92200","1.03809","14.08977"
"39.12200","1.03809","14.07288"
"39.32200","1.03809","14.06445"
"39.52200","1.03809","14.04745"
"39.72200","1.03809","14.02372"
"39.92200","1.03809","14.01017"
"40.12200","1.03809","13.99766"
"40.32200","1.03809","13.98506"
"40.52200","1.03809","13.97337"
"40.72200","1.03809","13.95888"
"40.92200","1.03809","13.94574"
"41.12200","1.03809","13.93366"
"41.32200","1.03809","13.92233"
"41.52200","1.03809","13.89845"
"41.72200","1.03809","13.88900"
"41.92200","1.03809","13.87785"
"42.12200","1.03809","13.86569"
"42.32200","1.03809","13.85575"
"42.52200","1.03809","13.84005"
"42.72200","1.03809","13.83440"
"42.92200","1.03809","13.81582"
"43.12200","1.03809","13.81444"
"43.32200","1.03809","13.80249"
"43.52200","1.03809","13.79364"
"43.72200","1.03809","13.77854"
"43.92200","1.03809","13.76179"
"44.12200","1.03809","13.75548"
"44.32200","1.03809","13.75146"
"44.52200","1.03809","13.72770"
"44.72200","1.03809","13.71471"
"44.92200","1.03809","13.71750"
"45.12200","1.03809","13.70242"
"45.32200","1.03809","13.68605"
"45.52200","1.03809","13.68320"
"45.72200","1.03809","13.67650"
"45.92200","1.03809","13.65801"
"46.12200","1.03809","13.65575"
"46.32200","1.03809","13.63748"
"46.52200","1.03809","13.63585"
"46.72200","1.03809","13.62309"
"46.92200","1.03809","13.61324"
"47.12200","1.03809","13.61448"
"47.32200","1.03809","13.59921"
"47.52200","1.03809","13.58592"
"47.72200","1.03809","13.58843"
"47.92200","1.03809","13.57659"
"48.12200","1.03809","13.56198"
"48.32200","1.03809","13.54801"
"48.52200","1.03809","13.54736"
"48.72200","1.03809","13.53542"
"48.92200","1.03809","13.53701"
"49.12200","1.03809","13.50664"
"49.32200","1.03809","13.51610"
"49.52200","1.03809","13.50473"
"49.72200","1.03809","13.49327"
"49.92200","1.03809","13.48291"
"50.12200","1.03809","13.47514"
"50.32200","1.03809","13.47055"
"50.52200","1.03809","13.46025"
"50.72100","1.03809","13.45803"
"50.74500","1.03809","13.45827"
"50.94500","0.99237","10.08014"
"51.14500","0.93326","7.00096"
"51.34500","0.87477","4.90582"
"51.54500","0.81596","3.41553"
"51.74500","0.75768","2.35766"
"51.94500","0.69897","1.58072"
"52.14500","0.64004","1.02055"
"52.34500","0.58208","0.64266"
"52.54500","0.52319","0.37440"
"52.74500","0.46463","0.19451"
"52.94500","0.40633","0.07350"
"53.14500","0.34742","-0.00248"
"53.34500","0.28895","-0.03545"
"53.54500","0.23057","-0.06628"
"53.74500","0.17188","-0.08594"
"53.94500","0.11329","-0.08991"
"54.14500","0.05488","-0.10094"
"54.28800","0.01307","-0.10351"
"54.29000","0.01249","-0.10456"
"54.49000","0.04491","-0.09454"
"54.69000","0.10460","-0.06283"
"54.89000","0.16376","-0.03813"
"55.09000","0.22183","0.00233"
"55.29000","0.28051","0.07420"
"55.49000","0.33935","0.20097"
"55.69000","0.39756","0.39788"
"55.89000","0.45624","0.67653"
"56.09000","0.51496","1.09254"
"56.29000","0.57340","1.65963"
"56.49000","0.63185","2.38201"
"56.69000","0.69066","3.30725"
"56.89000","0.74903","4.47842"
"57.09000","0.80766","5.94771"
"57.29000","0.86631","7.76071"
"57.49000","0.92463","10.00554"
"57.69000","0.98340","12.75817"
"57.87800","1.03807","15.81118"
"57.88000","1.03865","15.84552"
"58.08000","1.04728","15.72812"
"58.28000","1.04541","15.30422"
"58.48000","1.04494","15.08713"
"58.68000","1.04486","14.95366"
"58.88000","1.04484","14.84406"
"59.08000","1.04484","14.75162"
"59.28000","1.04484","14.67636"
"59.48000","1.04484","14.60214"
"59.68000","1.04484","14.54491"
"59.88000","1.04484","14.48906"
"60.08000","1.04484","14.43855"
"60.28000","1.04484","14.40724"
"60.48000","1.04475","14.34896"
"60.68000","1.04481","14.31802"
"60.88000","1.04484","14.29131"
"61.08000","1.04484","14.24711"
"61.28000","1.04484","14.21938"
"61.48000","1.04484","14.18693"
"61.68000","1.04484","14.16257"
"61.88000","1.04484","14.13759"
"62.08000","1.04484","14.10331"
"62.28000","1.04484","14.07785"
"62.48000","1.04484","14.05464"
"62.68000","1.04484","14.03424"
"62.88000","1.04484","14.02174"
"63.08000","1.04484","13.99731"
"63.28000","1.04484","13.97937"
"63.48000","1.04484","13.96037"
"63.68000","1.04484","13.93452"
"63.88000","1.04484","13.91489"
"64.08000","1.04484","13.89781"
"64.28000","1.04484","13.88074"
"64.48000","1.04484","13.86293"
"64.68000","1.04484","13.85490"
"64.88000","1.04484","13.83595"
"65.08000","1.04484","13.82588"
"65.28000","1.04484","13.81234"
"65.48000","1.04484","13.78737"
"65.68000","1.04484","13.77739"
"65.88000","1.04484","13.76920"
"66.08000","1.04484","13.74447"
"66.28000","1.04484","13.73823"
"66.48000","1.04484","13.71901"
"66.68000","1.04484","13.71258"
"66.88000","1.04484","13.69405"
"67.08000","1.04484","13.69163"
"67.28000","1.04484","13.67484"
"67.48000","1.04484","13.66305"
"67.68000","1.04484","13.65100"
"67.88000","1.04484","13.64644"
"68.08000","1.04484","13.63278"
"68.28000","1.04484","13.61545"
"68.48000","1.04484","13.61118"
"68.68000","1.04484","13.59922"
"68.88000","1.04484","13.57770"
"69.08000","1.04484","13.56795"
"69.28000","1.04484","13.55875"
"69.48000","1.04484","13.54800"
"69.68000","1.04484","13.54235"
"69.88000","1.04484","13.53753"
"70.08000","1.04484","13.51676"
"70.28000","1.04484","13.50901"
"70.48000","1.04484","13.49998"
"70.68000","1.04484","13.49085"
"70.88000","1.04484","13.48149"
"71.08000","1.04484","13.46698"
"71.28000","1.04484","13.46305"
"71.48000","1.04484","13.44869"
"71.68000","1.04484","13.44132"
"71.88000","1.04484","13.43593"
"72.08000","1.04484","13.42926"
"72.28000","1.04484","13.42445"
"72.48000","1.04484","13.39955"
"72.68000","1.04484","13.39978"
"72.88000","1.04484","13.39231"
"73.08000","1.04484","13.38612"
"73.28000","1.04484","13.37086"
"73.48000","1.04484","13.37265"
"73.68000","1.04484","13.36703"
"73.88000","1.04484","13.35416"
"74.08000","1.04484","13.34327"
"74.28000","1.04484","13.34517"
"74.48000","1.04484","13.33197"
"74.68000","1.04484","13.31626"
"74.88000","1.04484","13.31965"
"75.08000","1.04484","13.30441"
"75.28000","1.04484","13.29573"
"75.48000","1.04484","13.28607"
"75.68000","1.04484","13.27921"
"75.88000","1.04484","13.27865"
"76.08000","1.04484","13.26962"
"76.28000","1.04484","13.26853"
"76.48000","1.04484","13.25883"
"76.68000","1.04484","13.25126"
"76.88000","1.04484","13.24448"
"77.08000","1.04484","13.24172"
"77.28000","1.04484","13.23244"
"77.48000","1.04484","13.22965"
"77.68000","1.04484","13.22254"
"77.87900","1.04484","13.21988"
"77.90800","1.04484","13.21591"
"78.10800","0.99900","9.79925"
"78.30800","0.94009","6.73400"
"78.50800","0.88130","4.65075"
"78.70800","0.82272","3.20241"
"78.90800","0.76423","2.16215"
"79.10800","0.70554","1.43269"
"79.30800","0.64681","0.90019"
"79.50800","0.58873","0.54199"
"79.70800","0.52984","0.30240"
"79.90800","0.47119","0.14316"
"80.10800","0.41300","0.04115"
"80.30800","0.35403","-0.01303"
"80.50800","0.29567","-0.04955"
"80.70800","0.23725","-0.07729"
"80.90800","0.17846","-0.08048"
"81.10800","0.12007","-0.09540"
"81.30800","0.06143","-0.10056"
"81.45000","0.02003","-0.10443"
"81.45200","0.01945","-0.10487"
"81.65200","0.05206","-0.09198"
"81.85200","0.11168","-0.07614"
"82.05200","0.17063","-0.04142"
"82.25200","0.22902","-0.01046"
"82.45200","0.28740","0.04618"
"82.65200","0.34633","0.14035"
"82.85200","0.40477","0.30890"
"83.00800","0.45054","0.50159"
"83.01000","0.45112","0.50496"
"83.03000","0.45683","0.53667"
"83.05000","0.46243","0.56202"
"83.07000","0.46630","0.57990"
"83.09000","0.46888","0.59850"
"83.11000","0.47371","0.61932"
"83.13000","0.48111","0.66529"
"83.15000","0.48892","0.71477"
"83.17000","0.49597","0.75860"
"83.19000","0.50239","0.79971"
"83.21000","0.50861","0.84537"
"83.23000","0.51477","0.88798"
"83.25000","0.52081","0.92639"
"83.27000","0.52673","0.97214"
"83.29000","0.53252","1.01490"
"83.31000","0.53829","1.07027"
"83.33000","0.54420","1.12480"
"83.35000","0.55018","1.17298"
"83.37000","0.55609","1.22322"
"83.39000","0.56193","1.27706"
"83.41000","0.56773","1.32899"
"83.43000","0.57357","1.39161"
"83.45000","0.57950","1.44879"
"83.47000","0.58540","1.51170"
"83.49000","0.59121","1.57858"
"83.51000","0.59695","1.63579"
"83.53000","0.60269","1.70147"
"83.55000","0.60854","1.76768"
"83.57000","0.61454","1.83573"
"83.59000","0.62050","1.90891"
"83.61000","0.62633","1.98175"
"83.63000","0.63208","2.05402"
"83.65000","0.63782","2.13755"
"83.67000","0.64364","2.21498"
"83.69000","0.64968","2.29981"
"83.71000","0.65579","2.38832"
"83.73000","0.66169","2.47275"
"83.75000","0.66739","2.56641"
"83.77000","0.67310","2.64553"
"83.79000","0.67889","2.73649"
"83.81000","0.68484","2.83174"
"83.83000","0.69089","2.93079"
"83.85000","0.69686","3.03441"
"83.87000","0.70263","3.13017"
"83.89000","0.70828","3.23061"
"83.91000","0.71398","3.34629"
"83.93000","0.71987","3.45676"
"83.95000","0.72594","3.57199"
"83.97000","0.73200","3.67868"
"83.99000","0.73789","3.79642"
"84.01000","0.74362","3.91297"
"84.03000","0.74925","4.03090"
"84.05000","0.75501","4.15843"
"84.07000","0.76097","4.29200"
"84.09000","0.76694","4.43073"
"84.11000","0.77280","4.56534"
"84.13000","0.77857","4.69477"
"84.15000","0.78429","4.82152"
"84.17000","0.79006","4.96895"
"84.19000","0.79599","5.12699"
"84.21000","0.80197","5.28384"
"84.23000","0.80790","5.43530"
"84.25000","0.81372","5.59166"
"84.27000","0.81946","5.74771"
"84.29000","0.82527","5.91855"
"84.31000","0.83118","6.09291"
"84.33000","0.83710","6.26290"
"84.35000","0.84294","6.44171"
"84.37000","0.84872","6.62073"
"84.39000","0.85451","6.80779"
"84.41000","0.86044","7.00016"
"84.43000","0.86655","7.19952"
"84.45000","0.87258","7.40346"
"84.47000","0.87841","7.59989"
"84.49000","0.88411","7.81157"
"84.51000","0.88979","8.01207"
"84.53000","0.89559","8.22077"
"84.55000","0.90162","8.44655"
"84.57000","0.90768","8.67984"
"84.59000","0.91351","8.90841"
"84.61000","0.91920","9.13587"
"84.63000","0.92486","9.37459"
"84.65000","0.93062","9.62339"
"84.67000","0.93661","9.87575"
"84.69000","0.94269","10.13549"
"84.71000","0.94864","10.40290"
"84.73000","0.95436","10.66305"
"84.75000","0.95997","10.92367"
"84.77000","0.96564","11.19735"
"84.79000","0.97156","11.48044"
"84.81000","0.97763","11.78071"
"84.83000","0.98362","12.08561"
"84.85000","0.98946","12.37810"
"84.87000","0.99518","12.68191"
"84.89000","1.00086","12.98872"
"84.91000","1.00669","13.30800"
"84.93000","1.01267","13.64152"
"84.95000","1.01864","13.97297"
"84.97000","1.02453","14.31112"
"84.99000","1.03032","14.64390"
"85.01000","1.03602","14.98126"
"85.03000","1.04182","15.33890"
"85.05000","1.04780","15.71029"
"85.07000","1.05383","16.08815"
"85.09000","1.05976","16.46197"
"85.11000","1.06559","16.82360"
"85.13000","1.07138","17.18956"
"85.15000","1.07726","17.57440"
"85.17000","1.08319","17.96895"
"85.19000","1.08911","18.36952"
"85.21000","1.09495","18.76360"
"85.23000","1.10071","19.14965"
"85.25000","1.10649","19.53306"
"85.27000","1.11242","19.93766"
"85.29000","1.11843","20.36067"
"85.31000","1.12427","20.76895"
"85.33000","1.12992","21.16237"
"85.35000","1.13560","21.56222"
"85.37000","1.14137","21.96292"
"85.39000","1.14726","22.36997"
"85.41000","1.15329","22.79217"
"85.43000","1.15927","23.22433"
"85.45000","1.16510","23.64366"
"85.47000","1.17081","24.05367"
"85.49000","1.17651","24.46260"
"85.51000","1.18240","24.88666"
"85.53000","1.18844","25.32663"
"85.55000","1.19445","25.75715"
"85.57000","1.20031","26.17235"
"85.59000","1.20599","26.58360"
"85.61000","1.21164","26.98660"
"85.63000","1.21745","27.41167"
"85.65000","1.22346","27.85787"
"85.67000","1.22954","28.29464"
"85.69000","1.23555","28.72487"
"85.71000","1.24143","29.14777"
"85.73000","1.24715","29.56346"
"85.75000","1.25289","29.98521"
"85.77000","1.25877","30.42582"
"85.79000","1.26471","30.86699"
"85.81000","1.27059","31.29224"
"85.83000","1.27645","31.71337"
"85.85000","1.28223","32.14177"
"85.87000","1.28797","32.57150"
"85.89000","1.29383","33.02022"
"85.91000","1.29978","33.48050"
"85.93000","1.30571","33.93035"
"85.95000","1.31156","34.36150"
"85.97000","1.31734","34.77488"
"85.99000","1.32315","35.20345"
"86.01000","1.32903","35.65308"
"86.03000","1.33493","36.11255"
"86.05000","1.34077","36.55829"
"86.07000","1.34654","36.97965"
"86.09000","1.35232","37.39820"
"86.11000","1.35814","37.82330"
"86.13000","1.36411","38.27106"
"86.15000","1.37009","38.74091"
"86.17000","1.37595","39.20369"
"86.19000","1.38169","39.64241"
"86.21000","1.38740","40.06934"
"86.23000","1.39319","40.51117"
"86.25000","1.39917","40.97304"
"86.27000","1.40524","41.44061"
"86.29000","1.41114","41.89596"
"86.31000","1.41685","42.33782"
"86.33000","1.42258","42.77753"
"86.35000","1.42841","43.23294"
"86.37000","1.43442","43.69415"
"86.39000","1.44055","44.16095"
"86.41000","1.44655","44.61077"
"86.43000","1.45228","45.03816"
"86.45000","1.45791","45.46389"
"86.47000","1.46357","45.90197"
"86.49000","1.46942","46.36786"
"86.51000","1.47547","46.84552"
"86.53000","1.48153","47.30401"
"86.55000","1.48742","47.72891"
"86.57000","1.49312","48.15067"
"86.59000","1.49871","48.56408"
"86.61000","1.50445","49.00078"
"86.63000","1.51043","49.47357"
"86.65000","1.51648","49.94204"
"86.67000","1.52241","50.38015"
"86.69000","1.52823","50.79666"
"86.71000","1.53393","51.21287"
"86.73000","1.53965","51.65162"
"86.75000","1.54553","52.12052"
"86.77000","1.55148","52.58405"
"86.79000","1.55738","53.02170"
"86.81000","1.56320","53.44621"
"86.83000","1.56897","53.86324"
"86.85000","1.57479","54.30187"
"86.87000","1.58069","54.76080"
"86.89000","1.58662","55.22892"
"86.91000","1.59248","55.66857"
"86.93000","1.59827","56.08007"
"86.95000","1.60407","56.48472"
"86.97000","1.61000","56.90168"
"86.99000","1.61607","57.36469"
"87.00900","1.62179","57.80601"
"87.01100","1.62238","57.85065"
"87.19100","1.59581","50.68384"
"87.38600","1.53762","41.05095"
"87.58600","1.47887","33.04994"
"87.78600","1.42008","26.30863"
"87.98600","1.36172","20.75023"
"88.18600","1.30318","16.11515"
"88.38600","1.24446","12.29657"
"88.58600","1.18602","9.27684"
"88.78600","1.12765","6.88342"
"88.98600","1.06864","5.01508"
"89.18600","1.01046","3.64291"
"89.38600","0.95196","2.58556"
"89.58600","0.89300","1.81190"
"89.78600","0.83481","1.23223"
"89.98600","0.77601","0.81314"
"90.18600","0.71739","0.50766"
"90.38600","0.65890","0.29601"
"90.58600","0.60029","0.13838"
"90.78600","0.54191","0.05030"
"90.98600","0.48307","-0.01595"
"91.09900","0.45040","-0.03642"
"91.10100","0.44982","-0.03581"
"91.30100","0.48226","0.04293"
"91.50100","0.54189","0.20548"
"91.70100","0.60047","0.45236"
"91.72800","0.60834","0.50196"
"91.73000","0.60893","0.50417"
"91.73200","0.60953","0.50673"
"91.73400","0.61014","0.51397"
"91.73600","0.61079","0.53145"
"91.73800","0.61155","0.55916"
"91.74000","0.61251","0.59418"
"91.74200","0.61375","0.63581"
"91.74400","0.61541","0.68661"
"91.74600","0.61762","0.74769"
"91.74800","0.62050","0.81586"
"91.75000","0.62420","0.89241"
"91.75200","0.62885","0.98072"
"91.75400","0.63460","1.08290"
"91.75600","0.64158","1.20027"
"91.75800","0.64993","1.33563"
"91.76000","0.65976","1.49301"
"91.76200","0.67120","1.67825"
"91.76400","0.68437","1.89803"
"91.76600","0.69935","2.16100"
"91.76800","0.71626","2.47916"
"91.77000","0.73517","2.86723"
"91.77200","0.75616","3.34270"
"91.77400","0.77931","3.92786"
"91.77600","0.80469","4.64855"
"91.77800","0.83233","5.53395"
"91.78000","0.86230","6.61783"
"91.78200","0.89463","7.93723"
"91.78400","0.92936","9.53040"
"91.78600","0.96651","11.43222"
"91.78800","1.00609","13.66516"
"91.79000","1.04804","16.24022"
"91.79200","1.09226","19.16261"
"91.79400","1.13858","22.42874"
"91.79600","1.18682","26.02324"
"91.79800","1.23676","29.91679"
"91.80000","1.28818","34.07412"
"91.80200","1.34088","38.45969"
"91.80400","1.39464","43.03409"
"91.80600","1.44930","47.75619"
"91.80800","1.50469","52.58766"
"91.81000","1.56069","57.49438"
"91.81200","1.61718","62.44426"
"91.81400","1.67408","67.40495"
"91.81600","1.73132","72.34611"
"91.81800","1.78884","77.24366"
"91.82000","1.84660","82.07950"
"91.82200","1.90458","86.83863"
"91.82400","1.96275","91.50776"
"91.82600","2.02110","96.07459"
"91.82800","2.07961","100.53069"
"91.83000","2.13827","104.87001"
"91.83200","2.19707","109.08677"
"91.83400","2.25601","113.17490"
"91.83600","2.31507","117.13280"
"91.83800","2.37424","120.96151"
"91.84000","2.43353","124.65966"
"91.84200","2.49291","128.22627"
"91.84400","2.55237","131.66431"
"91.84600","2.61190","134.97897"
"91.84800","2.67149","138.17557"
"91.85000","2.73112","141.25819"
"91.85200","2.79077","144.23198"
"91.85400","2.85044","147.10214"
"91.85600","2.91010","149.87436"
"91.85800","2.96975","152.55591"
"91.86000","3.02938","155.15408"
"91.86200","3.08898","157.67491"
"91.86400","3.14854","160.12640"
"91.86600","3.20806","162.51463"
"91.86800","3.26753","164.84558"
"91.87000","3.32695","167.12532"
"91.87200","3.38632","169.35999"
"91.87400","3.44564","171.55588"
"91.87600","3.50489","173.71782"
"91.87800","3.56410","175.84895"
"91.88000","3.62325","177.95175"
"91.88200","3.68235","180.02901"
"91.88400","3.74140","182.08255"
"91.88600","3.80040","184.11340"
"91.88800","3.85936","186.12453"
"91.89000","3.91829","188.12030"
"91.89200","3.97718","190.10127"
"91.89400","4.03604","192.06679"
"91.89600","4.09487","194.01744"
"91.89800","4.15368","195.95483"
"91.90000","4.21246","197.88078"
"91.90200","4.27123","199.79634"
"91.90400","4.32998","201.70346"
"91.90600","4.38871","203.60286"
"91.90800","4.44742","205.49614"
"91.91000","4.50612","207.38510"
"91.91200","4.56481","209.26622"
"91.91400","4.62349","211.13594"
"91.91600","4.68216","212.99225"
"91.91800","4.74083","214.83310"
"91.92000","4.79949","216.65559"
"91.92200","4.85815","218.45547"
"91.92400","4.91681","220.22929"
"91.92600","4.97546","221.97491"
"91.92800","5.03412","223.69026"
"91.93000","5.09277","225.37326"
"91.93200","5.15142","227.02266"
"91.93400","5.21007","228.63704"
"91.93600","5.26872","230.21162"
"91.93800","5.32736","231.74001"
"91.94000","5.38601","233.21817"
"91.94200","5.44465","234.64351"
"91.94400","5.50330","236.01231"
"91.94600","5.56194","237.32251"
"91.94800","5.62059","238.57323"
"91.95000","5.67923","239.76321"
"91.95200","5.73788","240.88875"
"91.95400","5.79652","241.94614"
"91.95600","5.85515","242.93179"
"91.95800","5.91379","243.84117"
"91.96000","5.97241","244.67113"
"91.96200","6.03104","245.41760"
"91.96400","6.08966","246.07297"
"91.96600","6.14828","246.62900"
"91.96800","6.20689","247.07935"
"91.97000","6.26550","247.41881"
"91.97200","6.32411","247.64255"
"91.97400","6.38272","247.74443"
"91.97600","6.44133","247.72116"
"91.97800","6.49994","247.57092"
"91.98000","6.55854","247.29187"
"91.98200","6.61715","246.88094"
"91.98400","6.67575","246.33749"
"91.98600","6.73435","245.66211"
"91.98800","6.79294","244.85858"
"91.99000","6.85154","243.93301"
"91.99200","6.91013","242.89450"
"91.99400","6.96873","241.75537"
"91.99600","7.02732","240.52930"
"91.99800","7.08591","239.22807"
"92.00000","7.14450","237.86226"
"92.00200","7.20309","236.44136"
"92.00400","7.26168","234.97101"
"92.00600","7.32026","233.45482"
"92.00800","7.37883","231.89566"
"92.01000","7.43740","230.29576"
"92.01200","7.49597","228.66060"
"92.01400","7.55453","226.99330"
"92.01600","7.61310","225.29704"
"92.01800","7.67166","223.57620"
"92.02000","7.73022","221.83752"
"92.02200","7.78879","220.09195"
"92.02400","7.84737","218.34833"
"92.02600","7.90594","216.61560"
"92.02800","7.96452","214.90358"
"92.03000","8.02310","213.22147"
"92.03200","8.08168","211.57697"
"92.03400","8.14027","209.97592"
"92.03600","8.19885","208.42291"
"92.03800","8.25743","206.92102"
"92.04000","8.31601","205.47090"
"92.04200","8.37459","204.07303"
"92.04400","8.43317","202.72597"
"92.04600","8.49175","201.42824"
"92.04800","8.55033","200.17741"
"92.05000","8.60891","198.96812"
"92.05200","8.66750","197.79436"
"92.05400","8.72608","196.65398"
"92.05600","8.78465","195.54480"
"92.05800","8.84323","194.46460"
"92.06000","8.90180","193.41347"
"92.06200","8.96037","192.39291"
"92.06400","9.01894","191.40326"
"92.06600","9.07750","190.44182"
"92.06800","9.13607","189.50461"
"92.07000","9.19463","188.58873"
"92.07200","9.25319","187.69070"
"92.07400","9.31176","186.80652"
"92.07600","9.37033","185.93390"
"92.07800","9.42890","185.07117"
"92.08000","9.48747","184.21654"
"92.08200","9.54605","183.36967"
"92.08400","9.60462","182.53049"
"92.08600","9.66319","181.69571"
"92.08800","9.72175","180.86339"
"92.09000","9.78032","180.03392"
"92.09200","9.83888","179.20624"
"92.09400","9.89745","178.37373"
"92.09600","9.95601","177.52940"
"92.09800","10.01457","176.67365"
"92.10000","10.07314","175.81010"
"92.10200","10.13171","174.93942"
"92.10400","10.19028","174.06253"
"92.10600","10.24885","173.18068"
"92.10800","10.30743","172.29703"
"92.11000","10.36601","171.41446"
"92.11200","10.42459","170.53560"
"92.11400","10.48316","169.66229"
"92.11600","10.54174","168.79425"
"92.11800","10.60032","167.92902"
"92.12000","10.65890","167.06430"
"92.12200","10.71748","166.19820"
"92.12400","10.77607","165.33040"
"92.12600","10.83465","164.46358"
"92.12800","10.89323","163.59761"
"92.13000","10.95182","162.73135"
"92.13200","11.01040","161.86310"
"92.13400","11.06898","160.99300"
"92.13600","11.12756","160.12283"
"92.13800","11.18614","159.25342"
"92.14000","11.24471","158.38411"
"92.14200","11.30328","157.51524"
"92.14400","11.36184","156.64445"
"92.14600","11.42040","155.76836"
"92.14800","11.47896","154.88319"
"92.15000","11.53752","153.98816"
"92.15200","11.59608","153.08075"
"92.15400","11.65464","152.15578"
"92.15600","11.71320","151.20880"
"92.15800","11.77176","150.23729"
"92.16000","11.83032","149.24118"
"92.16200","11.88888","148.22287"
"92.16400","11.94744","147.18468"
"92.16600","12.00599","146.12819"
"92.16800","12.06454","145.05141"
"92.17000","12.12310","143.95210"
"92.17200","12.18165","142.82732"
"92.17400","12.24020","141.67332"
"92.17600","12.29875","140.49217"
"92.17800","12.35730","139.28966"
"92.18000","12.41585","138.07356"
"92.18200","12.47440","136.85223"
"92.18400","12.53294","135.63213"
"92.18600","12.59149","134.41991"
"92.18800","12.65003","133.22382"
"92.19000","12.70857","132.04945"
"92.19200","12.76711","130.89993"
"92.19400","12.82565","129.77943"
"92.19600","12.88420","128.69112"
"92.19800","12.94274","127.63420"
"92.20000","13.00129","126.60580"
"92.20200","13.05984","125.60169"
"92.20400","13.11840","124.61442"
"92.20600","13.17696","123.63441"
"92.20800","13.23552","122.65189"
"92.21000","13.29408","121.65798"
"92.21200","13.35265","120.64840"
"92.21400","13.41122","119.62238"
"92.21600","13.46979","118.58229"
"92.21800","13.52835","117.53217"
"92.22000","13.58692","116.47793"
"92.22200","13.64549","115.42570"
"92.22400","13.70405","114.38141"
"92.22600","13.76262","113.35029"
"92.22800","13.82119","112.33492"
"92.23000","13.87976","111.33315"
"92.23200","13.93833","110.34213"
"92.23400","13.99690","109.35997"
"92.23600","14.05547","108.38726"
"92.23800","14.11404","107.42749"
"92.24000","14.17260","106.48495"
"92.24200","14.23116","105.56129"
"92.24400","14.28973","104.65530"
"92.24600","14.34829","103.76721"
"92.24800","14.40685","102.89531"
"92.25000","14.46541","102.03656"
"92.25200","14.52398","101.18642"
"92.25400","14.58255","100.34267"
"92.25600","14.64111","99.50534"
"92.25800","14.69968","98.67686"
"92.26000","14.75825","97.86117"
"92.26200","14.81682","97.06161"
"92.26400","14.87539","96.28062"
"92.26600","14.93395","95.51876"
"92.26800","14.99251","94.77346"
"92.27000","15.05107","94.04105"
"92.27200","15.10962","93.31816"
"92.27400","15.16818","92.60372"
"92.27600","15.22673","91.89307"
"92.27700","15.25601","91.53803"