File: data/instron/Sample18_Control.is_tcyclic_RawData/Specimen_RawData_1.csv
Strain : Tensile strain (Extension) gauge length,"100.00000",mm

Time,Extension,Load
(s),(mm),(N)
"0.00000","0.00000","0.23581"
"0.01000","0.00000","0.23727"
"0.02000","0.00008","0.24146"
"0.03000","0.00036","0.24508"
"0.04000","0.00108","0.25528"
"0.05000","0.00245","0.25473"
"0.06000","0.00383","0.26011"
"0.07000","0.00509","0.26842"
"0.08000","0.00645","0.28400"
"0.09000","0.00836","0.29888"
"0.10000","0.01119","0.31535"
"0.11000","0.01497","0.33798"
"0.12000","0.01947","0.36514"
"0.13000","0.02430","0.39461"
"0.14000","0.02913","0.42958"
"0.15000","0.03372","0.46241"
"0.16000","0.03799","0.49211"
"0.17000","0.04194","0.51963"
"0.18000","0.04565","0.54575"
"0.19000","0.04920","0.57094"
"0.20000","0.05269","0.59988"
"0.21000","0.05621","0.62933"
"0.22000","0.05977","0.65830"
"0.23000","0.06337","0.68930"
"0.24000","0.06697","0.72163"
"0.25000","0.07054","0.75193"
"0.26000","0.07404","0.78719"
"0.27000","0.07748","0.81879"
"0.28000","0.08088","0.84851"
"0.29000","0.08425","0.88382"
"0.30000","0.08763","0.91801"
"0.31000","0.09107","0.95462"
"0.32000","0.09458","0.98939"
"0.33000","0.09814","1.02656"
"0.34000","0.10171","1.06339"
"0.35000","0.10527","1.10146"
"0.36000","0.10877","1.14403"
"0.37000","0.11220","1.18565"
"0.38000","0.11559","1.22853"
"0.39000","0.11893","1.26908"
"0.40000","0.12228","1.30928"
"0.41000","0.12567","1.35004"
"0.42000","0.12913","1.39322"
"0.43000","0.13265","1.44191"
"0.44000","0.13619","1.49164"
"0.45000","0.13973","1.54439"
"0.46000","0.14324","1.59781"
"0.47000","0.14672","1.64944"
"0.48000","0.15017","1.69699"
"0.49000","0.15359","1.74363"
"0.50000","0.15699","1.79302"
"0.51000","0.16038","1.84370"
"0.52000","0.16381","1.89728"
"0.53000","0.16730","1.95489"
"0.54000","0.17082","2.01345"
"0.55000","0.17436","2.07539"
"0.56000","0.17787","2.13884"
"0.57000","0.18135","2.19753"
"0.58000","0.18480","2.25624"
"0.59000","0.18821","2.31763"
"0.60000","0.19160","2.38048"
"0.61000","0.19498","2.44619"
"0.62000","0.19839","2.51559"
"0.63000","0.20187","2.58279"
"0.64000","0.20540","2.65049"
"0.65000","0.20894","2.72043"
"0.66000","0.21248","2.79134"
"0.67000","0.21599","2.86415"
"0.68000","0.21948","2.93669"
"0.69000","0.22293","3.00807"
"0.70000","0.22637","3.08257"
"0.71000","0.22981","3.15584"
"0.72000","0.23328","3.22852"
"0.73000","0.23679","3.30884"
"0.74000","0.24032","3.39058"
"0.75000","0.24385","3.47189"
"0.76000","0.24735","3.55683"
"0.77000","0.25080","3.64678"
"0.78000","0.25421","3.73123"
"0.79000","0.25760","3.81535"
"0.80000","0.26098","3.90148"
"0.81000","0.26438","3.98454"
"0.82000","0.26782","4.07013"
"0.83000","0.27131","4.16163"
"0.84000","0.27485","4.25574"
"0.85000","0.27839","4.34972"
"0.86000","0.28190","4.44633"
"0.87000","0.28535","4.54405"
"0.88000","0.28874","4.63979"
"0.89000","0.29212","4.73518"
"0.90000","0.29550","4.83206"
"0.91000","0.29888","4.92541"
"0.92000","0.30230","5.02174"
"0.93000","0.30578","5.12563"
"0.94000","0.30931","5.23153"
"0.95000","0.31285","5.34011"
"0.96000","0.31637","5.45222"
"0.97000","0.31985","5.56398"
"0.98000","0.32327","5.67600"
"0.99000","0.32665","5.78779"
"1.00000","0.33001","5.90264"
"1.01000","0.33337","6.01825"
"1.02000","0.33676","6.13167"
"1.03000","0.34023","6.25174"
"1.04000","0.34376","6.37331"
"1.05000","0.34733","6.49496"
"1.06000","0.35092","6.61706"
"1.07000","0.35450","6.74222"
"1.08000","0.35801","6.86881"
"1.09000","0.36145","6.99505"
"1.10000","0.36482","7.11971"
"1.11000","0.36815","7.24451"
"1.12000","0.37148","7.37046"
"1.13000","0.37486","7.50158"
"1.14000","0.37832","7.63594"
"1.15000","0.38185","7.77181"
"1.16000","0.38542","7.91030"
"1.17000","0.38900","8.05219"
"1.18000","0.39256","8.19343"
"1.19000","0.39608","8.33329"
"1.20000","0.39956","8.47317"
"1.21000","0.40298","8.61002"
"1.22000","0.40637","8.74702"
"1.23000","0.40975","8.88887"
"1.24000","0.41318","9.03415"
"1.25000","0.41666","9.18670"
"1.26000","0.42018","9.33997"
"1.27000","0.42371","9.49363"
"1.28000","0.42723","9.64655"
"1.29000","0.43073","9.79652"
"1.30000","0.43420","9.94384"
"1.31000","0.43763","10.09384"
"1.32000","0.44102","10.24842"
"1.33000","0.44442","10.40640"
"1.34000","0.44784","10.56709"
"1.35000","0.45130","10.72806"
"1.36000","0.45478","10.89417"
"1.37000","0.45829","11.06233"
"1.38000","0.46180","11.23275"
"1.39000","0.46530","11.39862"
"1.40000","0.46879","11.55896"
"1.41000","0.47225","11.72026"
"1.42000","0.47567","11.88630"
"1.43000","0.47910","12.05546"
"1.44000","0.48254","12.22770"
"1.45000","0.48600","12.40403"
"1.46000","0.48948","12.58325"
"1.47000","0.49295","12.76188"
"1.48000","0.49641","12.94056"
"1.49000","0.49984","13.11796"
"1.50000","0.50325","13.29331"
"1.51000","0.50665","13.47077"
"1.52000","0.51005","13.64904"
"1.53000","0.51347","13.82713"
"1.54000","0.51693","14.00658"
"1.55000","0.52044","14.19411"
"1.56000","0.52398","14.38280"
"1.57000","0.52751","14.57099"
"1.58000","0.53101","14.76211"
"1.59000","0.53447","14.95285"
"1.60000","0.53789","15.14142"
"1.61000","0.54129","15.33131"
"1.62000","0.54467","15.51871"
"1.63000","0.54805","15.70107"
"1.64000","0.55147","15.88841"
"1.65000","0.55497","16.08714"
"1.66000","0.55854","16.29309"
"1.67000","0.56214","16.49776"
"1.68000","0.56571","16.70409"
"1.69000","0.56921","16.90502"
"1.70000","0.57264","17.10452"
"1.71000","0.57604","17.30414"
"1.72000","0.57943","17.50469"
"1.73000","0.58281","17.70570"
"1.74000","0.58622","17.90956"
"1.75000","0.58968","18.11835"
"1.76000","0.59321","18.33135"
"1.77000","0.59678","18.54989"
"1.78000","0.60036","18.76737"
"1.79000","0.60391","18.98364"
"1.80000","0.60740","19.19719"
"1.81000","0.61083","19.41119"
"1.82000","0.61421","19.62499"
"1.83000","0.61756","19.83901"
"1.84000","0.62090","20.05123"
"1.85000","0.62427","20.26891"
"1.86000","0.62772","20.48988"
"1.87000","0.63124","20.71723"
"1.88000","0.63481","20.95115"
"1.89000","0.63840","21.18765"
"1.90000","0.64197","21.41893"
"1.91000","0.64548","21.64727"
"1.92000","0.64892","21.87164"
"1.93000","0.65230","22.09481"
"1.94000","0.65563","22.31630"
"1.95000","0.65897","22.53968"
"1.96000","0.66234","22.76867"
"1.97000","0.66579","23.00507"
"1.98000","0.66930","23.24725"
"1.99000","0.67283","23.49076"
"2.00000","0.67635","23.73204"
"2.01000","0.67986","23.97126"
"2.02000","0.68334","24.21312"
"2.03000","0.68678","24.45344"
"2.04000","0.69019","24.68759"
"2.05000","0.69358","24.92586"
"2.06000","0.69697","25.16966"
"2.07000","0.70041","25.41911"
"2.08000","0.70390","25.67516"
"2.09000","0.70740","25.93431"
"2.10000","0.71090","26.19183"
"2.11000","0.71439","26.44663"
"2.12000","0.71786","26.69791"
"2.13000","0.72130","26.94499"
"2.14000","0.72471","27.18914"
"2.15000","0.72812","27.43479"
"2.16000","0.73155","27.68579"
"2.17000","0.73501","27.94425"
"2.18000","0.73850","28.20692"
"2.19000","0.74200","28.47091"
"2.20000","0.74550","28.73856"
"2.21000","0.74898","29.00902"
"2.22000","0.75242","29.26730"
"2.23000","0.75586","29.52182"
"2.24000","0.75928","29.77555"
"2.25000","0.76271","30.02548"
"2.26000","0.76617","30.27839"
"2.27000","0.76970","30.54554"
"2.28000","0.77330","30.82231"
"2.29000","0.77690","31.10906"
"2.30000","0.78048","31.39311"
"2.31000","0.78398","31.67007"
"2.32000","0.78742","31.93883"
"2.33000","0.79080","32.20946"
"2.34000","0.79415","32.47058"
"2.35000","0.79750","32.72501"
"2.36000","0.80089","32.98497"
"2.37000","0.80435","33.25759"
"2.38000","0.80788","33.53337"
"2.39000","0.81147","33.81796"
"2.40000","0.81504","34.10966"
"2.41000","0.81856","34.39498"
"2.42000","0.82201","34.67135"
"2.43000","0.82540","34.94889"
"2.44000","0.82877","35.22453"
"2.45000","0.83212","35.49697"
"2.46000","0.83549","35.77086"
"2.47000","0.83891","36.04550"
"2.48000","0.84240","36.32533"
"2.49000","0.84595","36.61349"
"2.50000","0.84953","36.90876"
"2.51000","0.85309","37.20397"
"2.52000","0.85660","37.49627"
"2.53000","0.86003","37.78267"
"2.54000","0.86340","38.06384"
"2.55000","0.86673","38.33966"
"2.56000","0.87005","38.61569"
"2.57000","0.87341","38.89345"
"2.58000","0.87683","39.17530"
"2.59000","0.88035","39.46487"
"2.60000","0.88392","39.75941"
"2.61000","0.88750","40.05313"
"2.62000","0.89106","40.34616"
"2.63000","0.89457","40.63859"
"2.64000","0.89803","40.92783"
"2.65000","0.90143","41.21768"
"2.66000","0.90478","41.50203"
"2.67000","0.90813","41.78857"
"2.68000","0.91150","42.08057"
"2.69000","0.91493","42.37701"
"2.70000","0.91842","42.67934"
"2.71000","0.92196","42.98535"
"2.72000","0.92549","43.28960"
"2.73000","0.92901","43.59081"
"2.74000","0.93249","43.88948"
"2.75000","0.93593","44.18242"
"2.76000","0.93934","44.47178"
"2.77000","0.94273","44.76958"
"2.78000","0.94614","45.07813"
"2.79000","0.94960","45.38681"
"2.80000","0.95312","45.69854"
"2.81000","0.95668","46.01773"
"2.82000","0.96024","46.33501"
"2.83000","0.96377","46.64552"
"2.84000","0.96727","46.95421"
"2.85000","0.97075","47.25658"
"2.86000","0.97420","47.55165"
"2.87000","0.97764","47.85394"
"2.88000","0.98108","48.15730"
"2.89000","0.98456","48.46508"
"2.90000","0.98806","48.78384"
"2.91000","0.99158","49.11146"
"2.92000","0.99509","49.42865"
"2.93000","0.99857","49.73904"
"2.94000","1.00200","50.04106"
"2.95000","1.00540","50.34045"
"2.96000","1.00879","50.63469"
"2.97000","1.01217","50.93060"
"2.98000","1.01557","51.23093"
"2.99000","1.01902","51.53768"
"3.00000","1.02252","51.85606"
"3.01000","1.02605","52.18082"
"3.02000","1.02955","52.50669"
"3.03000","1.03302","52.82914"
"3.04000","1.03645","53.14548"
"3.05000","1.03986","53.45805"
"3.06000","1.04326","53.76789"
"3.07000","1.04666","54.07291"
"3.08000","1.05008","54.37546"
"3.09000","1.05352","54.68283"
"3.10000","1.05702","54.99783"
"3.11000","1.06057","55.32053"
"3.12000","1.06412","55.64643"
"3.13000","1.06765","55.97150"
"3.14000","1.07111","56.29164"
"3.15000","1.07452","56.60517"
"3.16000","1.07789","56.91456"
"3.17000","1.08125","57.22410"
"3.18000","1.08462","57.53230"
"3.19000","1.08803","57.84611"
"3.20000","1.09151","58.16626"
"3.21000","1.09505","58.48861"
"3.22000","1.09862","58.81395"
"3.23000","1.10219","59.13621"
"3.24000","1.10573","59.46130"
"3.25000","1.10921","59.78363"
"3.26000","1.11262","60.09809"
"3.27000","1.11597","60.40462"
"3.28000","1.11930","60.70597"
"3.29000","1.12266","61.00999"
"3.30000","1.12610","61.32121"
"3.31000","1.12960","61.64293"
"3.32000","1.13316","61.96769"
"3.33000","1.13674","62.29304"
"3.34000","1.14032","62.61317"
"3.35000","1.14387","62.93332"
"3.36000","1.14738","63.25205"
"3.37000","1.15083","63.56590"
"3.38000","1.15422","63.87424"
"3.39000","1.15760","64.18622"
"3.40000","1.16100","64.50243"
"3.41000","1.16445","64.82117"
"3.42000","1.16794","65.14381"
"3.43000","1.17147","65.46852"
"3.44000","1.17500","65.78872"
"3.45000","1.17851","66.10856"
"3.46000","1.18201","66.42403"
"3.47000","1.18547","66.73829"
"3.48000","1.18888","67.04787"
"3.49000","1.19225","67.35802"
"3.50000","1.19562","67.67134"
"3.51000","1.19902","67.99002"
"3.52000","1.20247","68.31772"
"3.53000","1.20595","68.65305"
"3.54000","1.20945","68.98536"
"3.55000","1.21296","69.30684"
"3.56000","1.21646","69.63025"
"3.57000","1.21994","69.95026"
"3.58000","1.22340","70.26311"
"3.59000","1.22684","70.57200"
"3.60000","1.23028","70.88813"
"3.61000","1.23373","71.20784"
"3.62000","1.23720","71.53153"
"3.63000","1.24067","71.85908"
"3.64000","1.24414","72.18130"
"3.65000","1.24758","72.49915"
"3.66000","1.25100","72.81576"
"3.67000","1.25442","73.12656"
"3.68000","1.25783","73.43104"
"3.69000","1.26125","73.73316"
"3.70000","1.26469","74.03640"
"3.71000","1.26817","74.34564"
"3.72000","1.27171","74.66194"
"3.73000","1.27525","74.98466"
"3.74000","1.27877","75.30803"
"3.75000","1.28225","75.63029"
"3.76000","1.28568","75.94862"
"3.77000","1.28907","76.26322"
"3.78000","1.29245","76.57215"
"3.79000","1.29582","76.87481"
"3.80000","1.29922","77.18052"
"3.81000","1.30266","77.49259"
"3.82000","1.30618","77.81924"
"3.83000","1.30977","78.15444"
"3.84000","1.31337","78.48986"
"3.85000","1.31692","78.82130"
"3.86000","1.32040","79.14344"
"3.87000","1.32382","79.46507"
"3.88000","1.32721","79.78411"
"3.89000","1.33059","80.09839"
"3.90000","1.33398","80.40993"
"3.91000","1.33741","80.72198"
"3.92000","1.34092","81.04021"
"3.93000","1.34451","81.36820"
"3.94000","1.34813","81.69897"
"3.95000","1.35173","82.02831"
"3.96000","1.35528","82.35548"
"3.97000","1.35873","82.67701"
"3.98000","1.36212","82.98875"
"3.99000","1.36546","83.29266"
"4.00000","1.36878","83.60282"
"4.01000","1.37214","83.91807"
"4.02000","1.37554","84.23621"
"4.03000","1.37901","84.55890"
"4.04000","1.38254","84.88101"
"4.04700","1.38504","85.10606"
"4.04800","1.38540","85.13831"
"4.04900","1.38575","85.17058"
"4.14900","1.38397","83.89145"
"4.23600","1.35073","78.83888"
"4.33500","1.31566","73.83829"
"4.43500","1.28099","69.20659"
"4.53500","1.24628","64.71734"
"4.63500","1.21154","60.36562"
"4.73500","1.17678","56.16208"
"4.83500","1.14205","52.09782"
"4.93500","1.10775","48.23473"
"5.03500","1.07320","44.46391"
"5.13500","1.03848","40.83311"
"5.23500","1.00368","37.31499"
"5.33500","0.96887","33.95756"
"5.43500","0.93438","30.76912"
"5.53500","0.90003","27.74390"
"5.63500","0.86539","24.85328"
"5.73500","0.83058","22.12510"
"5.83500","0.79575","19.56906"
"5.93500","0.76098","17.19942"
"6.03500","0.72669","15.04153"
"6.13500","0.69220","13.04856"
"6.23500","0.65764","11.22145"
"6.33500","0.62281","9.56503"
"6.43500","0.58813","8.08002"
"6.53500","0.55342","6.76781"
"6.63500","0.51916","5.62287"
"6.73500","0.48463","4.59804"
"6.83500","0.44986","3.69195"
"6.93500","0.41512","2.91425"
"7.03500","0.38032","2.25136"
"7.13500","0.34609","1.71231"
"7.23500","0.31151","1.25999"
"7.33500","0.27689","0.90567"
"7.43500","0.24214","0.62464"
"7.53500","0.20736","0.40454"
"7.63500","0.17298","0.24333"
"7.73500","0.13833","0.13147"
"7.83500","0.10382","0.07032"
"7.93500","0.06908","0.03865"
"8.03500","0.03442","0.01666"
"8.13400","0.00004","0.01815"
"8.13500","-0.00029","0.01772"
"8.13600","-0.00062","0.01731"
"8.23600","0.00084","0.03524"
"8.33600","0.03960","0.05389"
"8.43600","0.07505","0.09865"
"8.53600","0.10981","0.17171"
"8.63600","0.14437","0.30504"
"8.73600","0.17900","0.48806"
"8.74200","0.18107","0.50136"
"8.74300","0.18142","0.50369"
"8.74400","0.18177","0.50606"
"8.74900","0.18351","0.52435"
"8.75400","0.18561","0.59406"
"8.75900","0.18930","0.71477"
"8.76400","0.19644","0.89540"
"8.76900","0.20917","1.16326"
"8.77400","0.22963","1.57568"
"8.77900","0.25980","2.25012"
"8.78400","0.30138","3.36978"
"8.78900","0.35576","5.21914"
"8.79400","0.42403","8.16001"
"8.79900","0.50690","12.59241"
"8.80400","0.60459","18.87008"
"8.80900","0.71679","27.21736"
"8.81400","0.84289","37.71754"
"8.81900","0.98202","50.28814"
"8.82400","1.13264","64.62376"
"8.82900","1.29218","80.30856"
"8.83400","1.45781","96.84029"
"8.83900","1.62718","113.73188"
"8.84400","1.79867","130.55353"
"8.84900","1.97134","145.17995"
"8.85400","2.14473","146.07014"
"8.85900","2.31871","134.96126"
"8.86400","2.49327","117.18364"
"8.86900","2.66835","96.53217"
"8.87400","2.84383","75.69035"
"8.87900","3.01955","56.39920"
"8.88400","3.19533","39.56578"
"8.88900","3.37101","25.63889"
"8.89400","3.54644","14.67858"
"8.89900","3.72155","6.49664"
"8.90400","3.89633","0.71151"
"8.90900","4.07078","-3.05952"
"8.91400","4.24495","-5.22441"
"8.91900","4.41888","-6.18742"
"8.92400","4.59261","-6.30665"
"8.92900","4.76620","-5.89530"
"8.93400","4.93971","-5.16435"
"8.93900","5.11315","-4.28135"
"8.94400","5.28654","-3.35750"
"8.94900","5.45991","-2.49908"
"8.95400","5.63326","-1.73531"
"8.95900","5.80659","-1.10881"
"8.96400","5.97988","-0.61786"
"8.96900","6.15315","-0.26297"
"8.97400","6.32640","-0.00916"
"8.97900","6.49963","0.15624"
"8.98400","6.67283","0.26398"
"8.98900","6.84600","0.31527"
"8.99400","7.01917","0.31956"
"8.99900","7.19230","0.29802"
"9.00400","7.36540","0.26154"
"9.00900","7.53849","0.22428"
"9.01400","7.71160","0.18624"
"9.01900","7.88472","0.16228"
"9.02400","8.05785","0.12934"
"9.02900","8.23100","0.10253"
"9.03400","8.40417","0.07702"
"9.03900","8.57735","0.06161"
"9.04400","8.75053","0.05000"
"9.04900","8.92370","0.04879"
"9.05400","9.09685","0.04497"
"9.05900","9.27002","0.03348"
"9.06400","9.44318","0.02751"
"9.06900","9.61633","0.02836"
"9.07400","9.78947","0.03009"
"9.07900","9.96260","0.03358"
"9.08400","10.13574","0.04108"
"9.08900","10.30889","0.04412"
"9.09400","10.48205","0.04478"
"9.09900","10.65522","0.04406"
"9.10400","10.82841","0.04539"
"9.10900","11.00160","0.04640"
"9.11400","11.17478","0.05168"
"9.11900","11.34795","0.04854"
"9.12400","11.52111","0.04227"
"9.12900","11.69425","0.03223"
"9.13400","11.86736","0.02751"
"9.13900","12.04046","0.02877"
"9.14400","12.21353","0.03362"
"9.14900","12.38658","0.03623"
"9.15400","12.55962","0.03150"
"9.15900","12.73265","0.03345"
"9.16400","12.90570","0.02840"
"9.16900","13.07877","0.03340"
"9.17400","13.25185","0.03852"
"9.17900","13.42495","0.04491"
"9.18400","13.59805","0.04699"
"9.18900","13.77116","0.04812"
"9.19400","13.94427","0.04696"
"9.19900","14.11737","0.03840"
"9.20400","14.29047","0.04301"
"9.20900","14.46358","0.04488"
"9.21400","14.63670","0.04695"
"9.21900","14.80980","0.04712"
"9.22400","14.98289","0.04172"
"9.22900","15.15597","0.03142"
"9.23400","15.32907","0.03072"
"9.23900","15.50217","0.02733"
"9.24400","15.67527","0.03071"
"9.24900","15.84836","0.03418"
"9.25400","16.02147","0.03435"
"9.25900","16.19457","0.03159"
"9.26400","16.36767","0.03505"
"9.26900","16.54075","0.03807"
"9.27400","16.71384","0.03696"
"9.27900","16.88693","0.03882"
"9.28400","17.06001","0.03757"
"9.28900","17.23308","0.03848"
"9.29400","17.40614","0.03843"
"9.29700","17.50997","0.03350"