File: data/static/S1/raw_data.csv
Strain : Tensile strain (Extension) gauge length,100,mm,,,,
,,,,,,
Time,Extension,Load,,,,
(s),(mm),(N),Low Start,Low End,High Start,High End
0,0,0.31088,854,1141,1309,1399
0.2,0.04464,0.46735,,,,
0.4,0.10771,0.75107,,,,
0.6,0.17022,1.15833,,,,
0.8,0.23274,1.76487,,,,
1,0.29453,2.58362,,,,
1.2,0.35712,3.69221,,,,
1.4,0.41922,5.1153,,,,
1.6,0.48167,6.9638,,,,
1.8,0.5439,9.21826,,,,
2,0.60616,11.91786,,,,
2.2,0.66823,15.12716,,,,
2.4,0.73109,18.83556,,,,
2.6,0.79284,22.98728,,,,
2.8,0.85507,27.58791,,,,
3,0.91767,32.65871,,,,
3.2,0.98002,38.06059,,,,
3.4,1.04183,43.70059,,,,
3.554,1.09019,48.37321,,,,
3.556,1.09082,48.43443,,,,
3.756,1.09845,47.50261,,,,
3.956,1.09743,46.33934,,,,
4.156,1.09715,45.5745,,,,
4.356,1.09706,44.99315,,,,
4.556,1.09706,44.54534,,,,
4.756,1.09706,44.14304,,,,
4.956,1.09706,43.8086,,,,
5.156,1.09706,43.51061,,,,
5.356,1.09706,43.23232,,,,
5.556,1.09706,42.99363,,,,
5.756,1.09703,42.77784,,,,
5.956,1.09697,42.55859,,,,
6.156,1.09697,42.36531,,,,
6.356,1.09697,42.18314,,,,
6.556,1.09697,42.02572,,,,
6.756,1.09697,41.86728,,,,
6.956,1.09697,41.72033,,,,
7.156,1.09697,41.57323,,,,
7.356,1.09697,41.43172,,,,
7.556,1.09697,41.31121,,,,
7.756,1.09697,41.1858,,,,
7.956,1.09697,41.07784,,,,
8.156,1.09697,40.95089,,,,
8.356,1.09697,40.84721,,,,
8.556,1.09697,40.73798,,,,
8.756,1.09697,40.63424,,,,
8.956,1.09697,40.54094,,,,
9.156,1.09697,40.44859,,,,
9.356,1.09697,40.36287,,,,
9.556,1.09697,40.27818,,,,
9.756,1.09697,40.18298,,,,
9.956,1.09697,40.09733,,,,
10.156,1.09697,40.02182,,,,
10.356,1.09697,39.94333,,,,
10.556,1.09697,39.86732,,,,
10.756,1.09697,39.79487,,,,
10.956,1.09697,39.73232,,,,
11.156,1.09697,39.65957,,,,
11.356,1.09697,39.58922,,,,
11.556,1.09697,39.5153,,,,
11.756,1.09697,39.45617,,,,
11.956,1.09697,39.38983,,,,
12.156,1.09697,39.33063,,,,
12.356,1.09697,39.26122,,,,
12.556,1.09697,39.20667,,,,
12.756,1.09697,39.14224,,,,
12.956,1.09697,39.08995,,,,
13.156,1.09697,39.03312,,,,
13.356,1.09697,38.98627,,,,
13.556,1.09697,38.93132,,,,
13.756,1.09697,38.86497,,,,
13.956,1.09697,38.81158,,,,
14.156,1.09697,38.75731,,,,
14.356,1.09697,38.7198,,,,
14.556,1.09697,38.67695,,,,
14.756,1.09697,38.62199,,,,
14.956,1.09697,38.56832,,,,
15.156,1.09697,38.52087,,,,
15.356,1.09697,38.47622,,,,
15.556,1.09697,38.42015,,,,
15.756,1.09697,38.37704,,,,
15.956,1.09697,38.32629,,,,
16.156,1.09697,38.28265,,,,
16.356,1.09697,38.2286,,,,
16.556,1.09697,38.19144,,,,
16.756,1.09697,38.15285,,,,
16.956,1.09697,38.10999,,,,
17.156,1.09697,38.06593,,,,
17.356,1.09697,38.03202,,,,
17.556,1.09697,37.98728,,,,
17.756,1.09697,37.95233,,,,
17.956,1.09697,37.90919,,,,
18.156,1.09697,37.87601,,,,
18.356,1.09697,37.83157,,,,
18.556,1.09697,37.79413,,,,
18.756,1.09697,37.7585,,,,
18.956,1.09697,37.71618,,,,
19.156,1.09697,37.68961,,,,
19.356,1.09697,37.64633,,,,
19.556,1.09697,37.61254,,,,
19.756,1.09697,37.58351,,,,
19.956,1.09697,37.54022,,,,
20.156,1.09697,37.49702,,,,
20.356,1.09697,37.48256,,,,
20.556,1.09697,37.44332,,,,
20.756,1.09697,37.41148,,,,
20.956,1.09697,37.37401,,,,
21.156,1.09697,37.34668,,,,
21.356,1.09697,37.31372,,,,
21.556,1.09697,37.27768,,,,
21.756,1.09697,37.252,,,,
21.956,1.09697,37.2255,,,,
22.156,1.09697,37.19029,,,,
22.356,1.09697,37.16137,,,,
22.556,1.09697,37.13508,,,,
22.756,1.09697,37.10464,,,,
22.956,1.09697,37.07815,,,,
23.156,1.09697,37.04796,,,,
23.356,1.09697,37.02197,,,,
23.555,1.09697,36.99242,,,,
23.586,1.09697,36.99356,,,,
23.783,1.04986,30.38811,,,,
23.983,0.98709,22.73158,,,,
24.183,0.92441,16.69875,,,,
24.383,0.86235,11.96934,,,,
24.583,0.79999,8.24357,,,,
24.783,0.73766,5.43502,,,,
24.983,0.67509,3.38004,,,,
25.183,0.61331,2.01582,,,,
25.383,0.55071,1.13975,,,,
25.583,0.48855,0.63127,,,,
25.783,0.4261,0.355,,,,
25.983,0.36413,0.22074,,,,
26.183,0.30164,0.15965,,,,
26.383,0.2396,0.11676,,,,
26.583,0.17692,0.09266,,,,
26.783,0.11502,0.07319,,,,
26.983,0.0526,0.06633,,,,
27.13,0.00682,0.04917,,,,
27.132,0.00619,0.04887,,,,
27.332,0.0408,0.07949,,,,
27.532,0.10426,0.10887,,,,
27.732,0.16694,0.14336,,,,
27.932,0.22929,0.20918,,,,
28.132,0.29106,0.30802,,,,
28.332,0.35373,0.48131,,,,
28.532,0.41592,0.78569,,,,
28.732,0.47826,1.36879,,,,
28.932,0.54048,2.33074,,,,
29.132,0.60281,3.80246,,,,
29.332,0.66497,5.93753,,,,
29.532,0.72764,8.83592,,,,
29.732,0.78943,12.46801,,,,
29.932,0.85173,16.94194,,,,
30.132,0.91441,22.26206,,,,
30.332,0.97653,28.23433,,,,
30.532,1.03845,34.80645,,,,
30.718,1.09672,41.53568,,,,
30.72,1.09733,41.60774,,,,
30.92,1.10593,41.58379,,,,
31.12,1.1041,40.81397,,,,
31.32,1.10372,40.40852,,,,
31.52,1.10363,40.11345,,,,
31.72,1.10363,39.87943,,,,
31.92,1.10363,39.68779,,,,
32.12,1.10353,39.52261,,,,
32.32,1.10353,39.37201,,,,
32.52,1.10358,39.24323,,,,
32.72,1.10359,39.1259,,,,
32.92,1.10359,39.01366,,,,
33.12,1.1036,38.9356,,,,
33.32,1.1036,38.83826,,,,
33.52,1.10362,38.7582,,,,
33.72,1.10363,38.68449,,,,
33.92,1.10363,38.60944,,,,
34.12,1.10363,38.51999,,,,
34.32,1.10363,38.45676,,,,
34.52,1.10363,38.38134,,,,
34.72,1.10363,38.32236,,,,
34.92,1.10363,38.26479,,,,
35.12,1.10363,38.20254,,,,
35.32,1.10363,38.15047,,,,
35.52,1.10363,38.09752,,,,
35.72,1.10363,38.0465,,,,
35.92,1.10363,37.99738,,,,
36.12,1.10363,37.94923,,,,
36.32,1.10363,37.8991,,,,
36.52,1.10363,37.84539,,,,
36.72,1.10363,37.80981,,,,
36.92,1.10363,37.76591,,,,
37.12,1.10363,37.72537,,,,
37.32,1.10363,37.67833,,,,
37.52,1.10363,37.65251,,,,
37.72,1.10363,37.60711,,,,
37.92,1.10363,37.56527,,,,
38.12,1.10363,37.53931,,,,
38.32,1.10363,37.50602,,,,
38.52,1.10363,37.46597,,,,
38.72,1.10363,37.43421,,,,
38.92,1.10363,37.41028,,,,
39.12,1.10363,37.37789,,,,
39.32,1.10363,37.33172,,,,
39.52,1.10363,37.3051,,,,
39.72,1.10363,37.27581,,,,
39.92,1.10363,37.24804,,,,
40.12,1.10363,37.21191,,,,
40.32,1.10363,37.18192,,,,
40.52,1.10363,37.1551,,,,
40.72,1.10363,37.1339,,,,
40.92,1.10363,37.10204,,,,
41.12,1.10363,37.07405,,,,
41.32,1.10363,37.04923,,,,
41.52,1.10363,37.03251,,,,
41.72,1.10363,37.00091,,,,
41.92,1.10363,36.97648,,,,
42.12,1.10363,36.9534,,,,
42.32,1.10363,36.92684,,,,
42.52,1.10363,36.89775,,,,
42.72,1.10363,36.87109,,,,
42.92,1.10363,36.84591,,,,
43.12,1.10363,36.83307,,,,
43.32,1.10363,36.8021,,,,
43.52,1.10363,36.78183,,,,
43.72,1.10363,36.75931,,,,
43.92,1.10363,36.73547,,,,
44.12,1.10363,36.71329,,,,
44.32,1.10363,36.68533,,,,
44.52,1.10363,36.66794,,,,
44.72,1.10363,36.65296,,,,
44.92,1.10363,36.62027,,,,
45.12,1.10363,36.60728,,,,
45.32,1.10363,36.58874,,,,
45.52,1.10363,36.5676,,,,
45.72,1.10363,36.53988,,,,
45.92,1.10363,36.53135,,,,
46.12,1.10363,36.51023,,,,
46.32,1.10363,36.49595,,,,
46.52,1.10363,36.47328,,,,
46.72,1.10363,36.44126,,,,
46.92,1.10363,36.42718,,,,
47.12,1.10363,36.40903,,,,
47.32,1.10363,36.38794,,,,
47.52,1.10363,36.37861,,,,
47.72,1.10363,36.35914,,,,
47.92,1.10363,36.34243,,,,
48.12,1.10363,36.32643,,,,
48.32,1.10363,36.30594,,,,
48.52,1.10363,36.28711,,,,
48.72,1.10363,36.26651,,,,
48.92,1.10363,36.24159,,,,
49.12,1.10363,36.21915,,,,
49.32,1.10363,36.21538,,,,
49.52,1.10363,36.19324,,,,
49.72,1.10363,36.17952,,,,
49.92,1.10363,36.15963,,,,
50.12,1.10363,36.15088,,,,
50.32,1.10363,36.13651,,,,
50.52,1.10363,36.11622,,,,
50.719,1.10363,36.10069,,,,
50.745,1.10363,36.0967,,,,
50.939,1.0566,29.35376,,,,
51.139,0.99377,21.69148,,,,
51.339,0.93141,15.70422,,,,
51.539,0.86921,11.02959,,,,
51.739,0.80684,7.42874,,,,
51.939,0.74444,4.73904,,,,
52.139,0.68209,2.86698,,,,
52.339,0.62016,1.66497,,,,
52.539,0.55759,0.92613,,,,
52.739,0.49527,0.52752,,,,
52.939,0.43318,0.33001,,,,
53.139,0.37097,0.24492,,,,
53.339,0.30844,0.18954,,,,
53.539,0.2464,0.16939,,,,
53.739,0.18406,0.15324,,,,
53.939,0.12177,0.12811,,,,
54.139,0.05945,0.1169,,,,
54.286,0.01372,0.10865,,,,
54.288,0.01309,0.10839,,,,
54.488,0.048,0.13257,,,,
54.688,0.11126,0.15985,,,,
54.888,0.17371,0.18963,,,,
55.088,0.23628,0.2327,,,,
55.288,0.29822,0.30533,,,,
55.488,0.36073,0.41281,,,,
55.688,0.42273,0.65949,,,,
55.888,0.4852,1.09082,,,,
56.088,0.54756,1.87211,,,,
56.288,0.60981,3.14242,,,,
56.488,0.67174,5.06768,,,,
56.688,0.73467,7.7759,,,,
56.888,0.79655,11.26114,,,,
57.088,0.8587,15.62161,,,,
57.288,0.92121,20.8769,,,,
57.488,0.98362,26.87185,,,,
57.688,1.04555,33.54888,,,,
57.874,1.10363,40.35988,,,,
57.876,1.10424,40.4314,,,,
58.076,1.11296,40.54115,,,,
58.276,1.11107,39.82782,,,,
58.476,1.11065,39.45315,,,,
58.676,1.11066,39.20045,,,,
58.876,1.11056,38.99167,,,,
59.076,1.11056,38.822,,,,
59.276,1.11056,38.67111,,,,
59.476,1.11056,38.54197,,,,
59.676,1.11056,38.44591,,,,
59.876,1.11056,38.336,,,,
60.076,1.11056,38.24817,,,,
60.276,1.11056,38.15282,,,,
60.476,1.11056,38.07576,,,,
60.676,1.11056,37.99256,,,,
60.876,1.11056,37.92833,,,,
61.076,1.11047,37.85956,,,,
61.276,1.11053,37.80699,,,,
61.476,1.11056,37.74702,,,,
61.676,1.11056,37.70066,,,,
61.876,1.11056,37.64715,,,,
62.076,1.11056,37.58727,,,,
62.276,1.11056,37.53078,,,,
62.476,1.11056,37.4898,,,,
62.676,1.11056,37.45884,,,,
62.876,1.11056,37.40992,,,,
63.076,1.11056,37.3779,,,,
63.276,1.11056,37.32812,,,,
63.476,1.11056,37.29042,,,,
63.676,1.11056,37.25061,,,,
63.876,1.11056,37.22898,,,,
64.076,1.11056,37.18344,,,,
64.276,1.11056,37.14976,,,,
64.476,1.11056,37.12075,,,,
64.676,1.11056,37.08854,,,,
64.876,1.11056,37.06815,,,,
65.076,1.11056,37.02595,,,,
65.276,1.11056,37.00031,,,,
65.476,1.11056,36.9663,,,,
65.676,1.11056,36.94395,,,,
65.876,1.11056,36.91508,,,,
66.076,1.11056,36.89271,,,,
66.276,1.11056,36.85556,,,,
66.476,1.11056,36.83893,,,,
66.676,1.11056,36.80989,,,,
66.876,1.11056,36.78212,,,,
67.076,1.11056,36.75723,,,,
67.276,1.11056,36.73286,,,,
67.476,1.11056,36.71194,,,,
67.676,1.11056,36.69254,,,,
67.876,1.11056,36.68045,,,,
68.076,1.11056,36.64582,,,,
68.276,1.11056,36.62428,,,,
68.476,1.11056,36.59925,,,,
68.676,1.11056,36.58053,,,,
68.876,1.11056,36.55564,,,,
69.076,1.11056,36.53423,,,,
69.276,1.11056,36.50985,,,,
69.476,1.11056,36.47911,,,,
69.676,1.11056,36.46777,,,,
69.876,1.11056,36.44721,,,,
70.076,1.11056,36.43936,,,,
70.276,1.11056,36.41382,,,,
70.476,1.11056,36.39006,,,,
70.676,1.11056,36.37467,,,,
70.876,1.11056,36.35929,,,,
71.076,1.11056,36.33884,,,,
71.276,1.11056,36.31471,,,,
71.476,1.11056,36.29296,,,,
71.676,1.11056,36.28685,,,,
71.876,1.11056,36.26624,,,,
72.076,1.11056,36.24314,,,,
72.276,1.11056,36.22325,,,,
72.476,1.11056,36.21544,,,,
72.676,1.11056,36.19666,,,,
72.876,1.11056,36.17556,,,,
73.076,1.11056,36.15678,,,,
73.276,1.11056,36.14425,,,,
73.476,1.11056,36.1366,,,,
73.676,1.11056,36.11161,,,,
73.876,1.11056,36.08577,,,,
74.076,1.11056,36.08395,,,,
74.276,1.11056,36.07725,,,,
74.476,1.11056,36.06334,,,,
74.676,1.11056,36.05361,,,,
74.876,1.11056,36.03644,,,,
75.076,1.11056,36.01533,,,,
75.276,1.11056,36.00732,,,,
75.476,1.11056,35.9958,,,,
75.676,1.11056,35.96616,,,,
75.876,1.11056,35.96478,,,,
76.076,1.11056,35.94829,,,,
76.276,1.11056,35.93604,,,,
76.476,1.11056,35.91686,,,,
76.676,1.11056,35.89582,,,,
76.876,1.11056,35.89027,,,,
77.076,1.11056,35.87931,,,,
77.276,1.11056,35.85789,,,,
77.476,1.11056,35.84137,,,,
77.676,1.11056,35.83501,,,,
77.875,1.11056,35.826,,,,
77.895,1.11056,35.8169,,,,
78.087,1.06377,29.03702,,,,
78.287,1.00117,21.36764,,,,
78.487,0.93887,15.35216,,,,
78.687,0.87636,10.65679,,,,
78.887,0.81421,7.08463,,,,
79.087,0.75183,4.44652,,,,
79.287,0.68962,2.63307,,,,
79.487,0.62738,1.47738,,,,
79.687,0.56499,0.80104,,,,
79.887,0.50257,0.44859,,,,
80.087,0.44076,0.29855,,,,
80.287,0.37815,0.19685,,,,
80.487,0.31574,0.16446,,,,
80.687,0.2538,0.15321,,,,
80.887,0.19152,0.12405,,,,
81.087,0.12884,0.12034,,,,
81.287,0.0669,0.10034,,,,
81.436,0.02051,0.09359,,,,
81.438,0.01988,0.09297,,,,
81.638,0.05512,0.11228,,,,
81.838,0.11825,0.13727,,,,
82.038,0.18066,0.1544,,,,
82.238,0.24299,0.19461,,,,
82.438,0.30532,0.24652,,,,
82.638,0.36778,0.35339,,,,
82.81,0.42101,0.50129,,,,
82.812,0.42162,0.50479,,,,
82.832,0.4272,0.52465,,,,
82.852,0.43046,0.55186,,,,
82.872,0.43354,0.55304,,,,
82.892,0.43593,0.56832,,,,
82.912,0.43986,0.59693,,,,
82.932,0.44671,0.62896,,,,
82.952,0.45465,0.67632,,,,
82.972,0.46225,0.7186,,,,
82.992,0.46944,0.76636,,,,
83.012,0.47631,0.81956,,,,
83.032,0.48282,0.86986,,,,
83.052,0.48901,0.91971,,,,
83.072,0.4951,0.97258,,,,
83.092,0.50135,1.02413,,,,
83.112,0.50785,1.08534,,,,
83.132,0.51439,1.14861,,,,
83.152,0.52079,1.21507,,,,
83.172,0.527,1.28243,,,,
83.192,0.53309,1.3572,,,,
83.212,0.53926,1.43658,,,,
83.232,0.54555,1.51964,,,,
83.252,0.55187,1.60859,,,,
83.272,0.55815,1.6986,,,,
83.292,0.56435,1.7952,,,,
83.312,0.57047,1.89062,,,,
83.332,0.57666,2.0052,,,,
83.352,0.58294,2.12521,,,,
83.372,0.58922,2.24223,,,,
83.392,0.59547,2.36691,,,,
83.412,0.60163,2.49491,,,,
83.432,0.60783,2.63633,,,,
83.452,0.61409,2.77965,,,,
83.472,0.6203,2.9258,,,,
83.492,0.62643,3.07191,,,,
83.512,0.63258,3.22554,,,,
83.532,0.63878,3.39105,,,,
83.552,0.6451,3.57618,,,,
83.572,0.65149,3.77206,,,,
83.592,0.65774,3.96359,,,,
83.612,0.66383,4.15569,,,,
83.632,0.66987,4.35199,,,,
83.652,0.67597,4.55668,,,,
83.672,0.68232,4.78548,,,,
83.692,0.68882,5.01785,,,,
83.712,0.69517,5.2517,,,,
83.732,0.70126,5.49985,,,,
83.752,0.70732,5.75194,,,,
83.772,0.71352,6.01525,,,,
83.792,0.71995,6.28483,,,,
83.812,0.72643,6.56938,,,,
83.832,0.73276,6.86253,,,,
83.852,0.73885,7.14802,,,,
83.872,0.74481,7.44512,,,,
83.892,0.75091,7.75012,,,,
83.912,0.75725,8.07449,,,,
83.932,0.76366,8.41529,,,,
83.952,0.76998,8.74939,,,,
83.972,0.77614,9.08467,,,,
83.992,0.78214,9.42667,,,,
84.012,0.78824,9.7908,,,,
84.032,0.79455,10.16957,,,,
84.052,0.80092,10.56132,,,,
84.072,0.80718,10.94837,,,,
84.092,0.81332,11.33324,,,,
84.112,0.81943,11.73429,,,,
84.132,0.82565,12.15562,,,,
84.152,0.83194,12.59601,,,,
84.172,0.83822,13.04402,,,,
84.192,0.84445,13.48596,,,,
84.212,0.85059,13.9204,,,,
84.232,0.85675,14.37056,,,,
84.252,0.86305,14.85063,,,,
84.272,0.86937,15.34166,,,,
84.292,0.87559,15.83207,,,,
84.312,0.88171,16.32575,,,,
84.332,0.88784,16.82012,,,,
84.352,0.89415,17.33701,,,,
84.372,0.90066,17.88153,,,,
84.392,0.90709,18.43329,,,,
84.412,0.91328,18.97022,,,,
84.432,0.91934,19.50187,,,,
84.452,0.92539,20.03985,,,,
84.472,0.93161,20.60512,,,,
84.492,0.938,21.18813,,,,
84.512,0.94434,21.7679,,,,
84.532,0.95049,22.34693,,,,
84.552,0.95654,22.92727,,,,
84.572,0.96261,23.51562,,,,
84.592,0.96889,24.14321,,,,
84.612,0.97532,24.79125,,,,
84.632,0.98168,25.41977,,,,
84.652,0.98784,26.02701,,,,
84.672,0.99387,26.63736,,,,
84.692,0.99991,27.26833,,,,
84.712,1.00617,27.94141,,,,
84.732,1.01255,28.63914,,,,
84.752,1.01886,29.314,,,,
84.772,1.02508,29.97122,,,,
84.792,1.0312,30.62706,,,,
84.812,1.03732,31.3106,,,,
84.832,1.04358,32.02188,,,,
84.852,1.04991,32.75595,,,,
84.872,1.05616,33.47523,,,,
84.892,1.06233,34.1847,,,,
84.912,1.06847,34.88193,,,,
84.932,1.07471,35.61005,,,,
84.952,1.08111,36.38348,,,,
84.972,1.08749,37.15884,,,,
84.992,1.09373,37.91587,,,,
85.012,1.0999,38.65371,,,,
85.032,1.10606,39.38483,,,,
85.052,1.11231,40.14359,,,,
85.072,1.1186,40.92477,,,,
85.092,1.12482,41.70073,,,,
85.112,1.13095,42.46888,,,,
85.132,1.13705,43.23917,,,,
85.152,1.14325,44.01287,,,,
85.172,1.14968,44.81669,,,,
85.192,1.15608,45.63074,,,,
85.212,1.16225,46.42447,,,,
85.232,1.16831,47.21007,,,,
85.252,1.17437,47.97573,,,,
85.272,1.18056,48.76943,,,,
85.292,1.18692,49.5824,,,,
85.312,1.19331,50.40209,,,,
85.332,1.19953,51.21354,,,,
85.352,1.20557,51.98919,,,,
85.372,1.21163,52.77058,,,,
85.392,1.2179,53.59211,,,,
85.412,1.22428,54.42662,,,,
85.432,1.23063,55.23935,,,,
85.452,1.23681,56.02534,,,,
85.472,1.24286,56.79218,,,,
85.492,1.24895,57.58263,,,,
85.512,1.25527,58.40724,,,,
85.532,1.26171,59.24242,,,,
85.552,1.26809,60.05267,,,,
85.572,1.27437,60.84079,,,,
85.592,1.28052,61.61667,,,,
85.612,1.28666,62.39389,,,,
85.632,1.29294,63.18361,,,,
85.652,1.29929,63.97688,,,,
85.672,1.30558,64.74911,,,,
85.692,1.31179,65.49529,,,,
85.712,1.31786,66.22653,,,,
85.732,1.32394,66.96424,,,,
85.752,1.33015,67.71951,,,,
85.772,1.33643,68.47309,,,,
85.792,1.34269,69.1991,,,,
85.812,1.3489,69.9173,,,,
85.832,1.35512,70.63941,,,,
85.852,1.36138,71.37774,,,,
85.872,1.36766,72.10773,,,,
85.892,1.37387,72.80911,,,,
85.912,1.38001,73.48727,,,,
85.932,1.38615,74.15154,,,,
85.952,1.39238,74.82677,,,,
85.972,1.39873,75.53936,,,,
85.992,1.40502,76.25642,,,,
86.012,1.4112,76.94613,,,,
86.032,1.41731,77.62118,,,,
86.052,1.42341,78.27909,,,,
86.072,1.42966,78.94514,,,,
86.092,1.43612,79.65152,,,,
86.112,1.4425,80.34878,,,,
86.132,1.44864,81.02597,,,,
86.152,1.45472,81.69592,,,,
86.172,1.46086,82.36913,,,,
86.192,1.46722,83.06872,,,,
86.212,1.47374,83.77221,,,,
86.232,1.48011,84.45317,,,,
86.252,1.4862,85.10185,,,,
86.272,1.49217,85.73759,,,,
86.292,1.49823,86.39979,,,,
86.312,1.50453,87.08696,,,,
86.332,1.51098,87.78837,,,,
86.352,1.51736,88.4642,,,,
86.372,1.52352,89.10188,,,,
86.392,1.52951,89.73267,,,,
86.412,1.53556,90.38116,,,,
86.432,1.54188,91.0797,,,,
86.452,1.5483,91.77955,,,,
86.472,1.55463,92.43901,,,,
86.492,1.56081,93.06514,,,,
86.512,1.56684,93.67502,,,,
86.532,1.57291,94.32079,,,,
86.552,1.57916,95.00169,,,,
86.572,1.58552,95.69127,,,,
86.592,1.59184,96.35486,,,,
86.612,1.59805,96.97588,,,,
86.632,1.60417,97.59013,,,,
86.652,1.61032,98.23632,,,,
86.672,1.61658,98.90999,,,,
86.692,1.62289,99.58299,,,,
86.712,1.6291,100.2142,,,,
86.732,1.63527,100.82719,,,,
86.752,1.64154,101.44671,,,,
86.772,1.64796,102.10104,,,,
86.792,1.65438,102.77549,,,,
86.812,1.66062,103.42332,,,,
86.832,1.66672,104.03279,,,,
86.834,1.66732,104.09146,,,,
86.997,1.64475,96.47581,,,,
87.146,1.5965,86.41866,,,,
87.316,1.54357,76.36887,,,,
87.5,1.48614,66.33337,,,,
87.698,1.42416,56.49861,,,,
87.898,1.36237,47.5259,,,,
88.098,1.29989,39.3313,,,,
88.298,1.23761,31.92953,,,,
88.498,1.17522,25.30756,,,,
88.698,1.1131,19.54292,,,,
88.898,1.05079,14.58879,,,,
89.098,0.98853,10.46376,,,,
89.298,0.92608,7.13637,,,,
89.498,0.86405,4.62486,,,,
89.698,0.80167,2.82944,,,,
89.898,0.73929,1.62159,,,,
90.098,0.67677,0.87601,,,,
90.298,0.61499,0.50277,,,,
90.498,0.55237,0.30238,,,,
90.698,0.49015,0.21683,,,,
90.898,0.42777,0.16551,,,,
90.921,0.42061,0.1703,,,,
91.022,0.42133,0.1925,,,,
91.222,0.48755,0.29872,,,,
91.406,0.54519,0.50159,,,,
91.408,0.54582,0.50471,,,,
91.41,0.54646,0.50757,,,,
91.412,0.5471,0.5126,,,,
91.414,0.54776,0.52591,,,,
91.416,0.5485,0.55076,,,,
91.418,0.54939,0.58431,,,,
91.42,0.55052,0.62456,,,,
91.422,0.55201,0.67233,,,,
91.424,0.55398,0.7286,,,,
91.426,0.55656,0.79421,,,,
91.428,0.5599,0.86909,,,,
91.43,0.56413,0.95602,,,,
91.432,0.5694,1.05883,,,,
91.434,0.57584,1.18231,,,,
91.436,0.58359,1.33238,,,,
91.438,0.59276,1.51831,,,,
91.44,0.6035,1.75183,,,,
91.442,0.6159,2.0469,,,,
91.444,0.63008,2.4216,,,,
91.446,0.64614,2.89889,,,,
91.448,0.66416,3.5046,,,,
91.45,0.68423,4.26887,,,,
91.452,0.70643,5.22537,,,,
91.454,0.73081,6.40999,,,,
91.456,0.75745,7.86071,,,,
91.458,0.78638,9.61727,,,,
91.46,0.81765,11.71907,,,,
91.462,0.8513,14.20256,,,,
91.464,0.88734,17.0996,,,,
91.466,0.92578,20.44033,,,,
91.468,0.96661,24.24859,,,,
91.47,1.00981,28.53656,,,,
91.472,1.05532,33.30483,,,,
91.474,1.10303,38.54573,,,,
91.476,1.15281,44.24182,,,,
91.478,1.2045,50.36074,,,,
91.48,1.2579,56.85461,,,,
91.482,1.31282,63.66941,,,,
91.484,1.36906,70.74969,,,,
91.486,1.42643,78.04084,,,,
91.488,1.48477,85.49084,,,,
91.49,1.54392,93.04972,,,,
91.492,1.60375,100.67385,,,,
91.494,1.66415,108.32549,,,,
91.496,1.72502,115.97025,,,,
91.498,1.78628,123.57855,,,,
91.5,1.84787,131.12305,,,,
91.502,1.90973,138.57898,,,,
91.504,1.97183,145.92395,,,,
91.506,2.03413,153.13936,,,,
91.508,2.0966,160.20775,,,,
91.51,2.15922,167.11241,,,,
91.512,2.22197,173.8376,,,,
91.514,2.28484,180.37004,,,,
91.516,2.34782,186.69818,,,,
91.518,2.4109,192.81091,,,,
91.52,2.47406,198.6918,,,,
91.522,2.53729,204.32108,,,,
91.524,2.60059,209.67982,,,,
91.526,2.66393,214.7719,,,,
91.528,2.7273,219.62242,,,,
91.53,2.7907,224.2569,,,,
91.532,2.85412,228.68506,,,,
91.534,2.91752,232.88643,,,,
91.536,2.98092,236.80737,,,,
91.538,3.0443,240.42798,,,,
91.54,3.10765,243.76932,,,,
91.542,3.17096,246.86523,,,,
91.544,3.23423,249.74684,,,,
91.546,3.29746,252.44391,,,,
91.548,3.36063,254.98158,,,,
91.55,3.42376,257.38098,,,,
91.552,3.48683,259.40366,,,,
91.554,3.54986,259.33719,,,,
91.556,3.61282,255.82474,,,,
91.558,3.67574,249.06635,,,,
91.56,3.73861,239.74698,,,,
91.562,3.80144,228.47168,,,,
91.564,3.86424,215.73289,,,,
91.566,3.927,201.94786,,,,
91.568,3.98974,187.48996,,,,
91.57,4.05245,172.68102,,,,
91.572,4.11515,157.79416,,,,
91.574,4.17783,143.05713,,,,
91.576,4.24049,128.65855,,,,
91.578,4.30313,114.75149,,,,
91.58,4.36576,101.45361,,,,
91.582,4.42836,88.85591,,,,
91.584,4.49095,77.02654,,,,
91.586,4.55351,66.01176,,,,
91.588,4.61606,55.83837,,,,
91.59,4.67858,46.51836,,,,
91.592,4.74108,38.0465,,,,
91.594,4.80357,30.40622,,,,
91.596,4.86603,23.57399,,,,
91.598,4.92847,17.51859,,,,
91.6,4.9909,12.19897,,,,
91.602,5.05331,7.5682,,,,
91.604,5.11569,3.57828,,,,
91.606,5.17807,0.18444,,,,
91.608,5.24042,-2.65964,,,,
91.61,5.30276,-4.99998,,,,
91.612,5.36509,-6.88375,,,,
91.614,5.42741,-8.35666,,,,
91.616,5.48972,-9.46413,,,,
91.618,5.55202,-10.25226,,,,
91.62,5.61431,-10.76121,,,,
91.622,5.6766,-11.02612,,,,
91.624,5.73888,-11.0821,,,,
91.626,5.80115,-10.9637,,,,
91.628,5.86342,-10.70384,,,,
91.63,5.92568,-10.3306,,,,
91.632,5.98793,-9.8647,,,,
91.634,6.05018,-9.32764,,,,
91.636,6.11243,-8.74265,,,,
91.638,6.17468,-8.12848,,,,
91.64,6.23693,-7.49654,,,,
91.642,6.29919,-6.85419,,,,
91.644,6.36145,-6.21305,,,,
91.646,6.42372,-5.5845,,,,
91.648,6.486,-4.97616,,,,
91.65,6.54827,-4.39229,,,,
91.652,6.61056,-3.83782,,,,
91.654,6.67284,-3.31582,,,,
91.656,6.73513,-2.82672,,,,
91.658,6.79742,-2.37174,,,,
91.66,6.85971,-1.95286,,,,
91.662,6.92201,-1.57189,,,,
91.664,6.98431,-1.22835,,,,
91.666,7.04661,-0.9206,,,,
91.668,7.10892,-0.64916,,,,
91.67,7.17123,-0.41364,,,,
91.672,7.23354,-0.21043,,,,
91.674,7.29585,-0.03536,,,,
91.676,7.35816,0.11397,,,,
91.678,7.42046,0.24051,,,,
91.68,7.48276,0.34606,,,,
91.682,7.54506,0.43145,,,,
91.684,7.60736,0.49759,,,,
91.686,7.66966,0.54844,,,,
91.688,7.73195,0.58719,,,,
91.69,7.79425,0.61335,,,,
91.692,7.85655,0.62757,,,,
91.694,7.91884,0.63313,,,,
91.696,7.98114,0.63222,,,,
91.698,8.04344,0.6248,,,,
91.7,8.10573,0.61133,,,,
91.702,8.16802,0.59298,,,,
91.704,8.23031,0.57135,,,,
91.706,8.29259,0.54863,,,,
91.708,8.35487,0.52528,,,,
91.71,8.41715,0.49921,,,,
91.712,8.47942,0.47046,,,,
91.714,8.5417,0.44223,,,,
91.716,8.60398,0.41483,,,,
91.718,8.66626,0.38759,,,,
91.72,8.72855,0.36168,,,,
91.722,8.79083,0.33932,,,,
91.724,8.85312,0.32116,,,,
91.726,8.91541,0.30439,,,,
91.728,8.97771,0.28772,,,,
91.73,9.04001,0.27101,,,,
91.732,9.10231,0.25348,,,,
91.734,9.16461,0.23556,,,,
91.736,9.22692,0.21821,,,,
91.738,9.28923,0.20231,,,,
91.74,9.35154,0.18792,,,,
91.742,9.41386,0.17549,,,,
91.744,9.47617,0.16489,,,,
91.746,9.53849,0.15537,,,,
91.748,9.6008,0.14759,,,,
91.75,9.66311,0.1425,,,,
91.752,9.72542,0.14034,,,,
91.754,9.78773,0.14063,,,,
91.756,9.85003,0.14145,,,,
91.758,9.91233,0.13984,,,,
91.76,9.97463,0.13534,,,,
91.762,10.03693,0.13067,,,,
91.764,10.09923,0.12725,,,,
91.766,10.16152,0.12498,,,,
91.768,10.22381,0.12346,,,,
91.77,10.2861,0.12248,,,,
91.772,10.34839,0.12188,,,,
91.774,10.41067,0.1217,,,,
91.776,10.47295,0.12245,,,,
91.778,10.53522,0.12441,,,,
91.78,10.5975,0.12563,,,,
91.782,10.65977,0.12787,,,,
91.784,10.72204,0.13231,,,,
91.786,10.78431,0.13822,,,,
91.788,10.84658,0.14454,,,,
91.79,10.90885,0.14999,,,,
91.792,10.97111,0.15357,,,,
91.794,11.03338,0.1539,,,,
91.796,11.09564,0.15307,,,,
91.798,11.1579,0.15385,,,,
91.8,11.22016,0.1543,,,,
91.802,11.28242,0.15309,,,,
91.804,11.34469,0.15254,,,,
91.806,11.40695,0.15389,,,,
91.808,11.46922,0.15386,,,,
91.81,11.53149,0.15142,,,,
91.812,11.59376,0.14891,,,,
91.814,11.65604,0.14877,,,,
91.816,11.71832,0.1516,,,,
91.818,11.7806,0.15387,,,,
91.82,11.84289,0.15456,,,,
91.822,11.90517,0.15363,,,,
91.824,11.96746,0.15209,,,,
91.826,12.02974,0.15067,,,,
91.828,12.09202,0.14934,,,,
91.83,12.15431,0.14764,,,,
91.832,12.21659,0.14576,,,,
91.834,12.27887,0.14277,,,,
91.836,12.34115,0.13887,,,,
91.838,12.40343,0.13504,,,,
91.84,12.46571,0.1331,,,,
91.842,12.52799,0.1326,,,,
91.844,12.59027,0.13214,,,,
91.846,12.65255,0.13146,,,,
91.848,12.71482,0.13157,,,,
91.85,12.7771,0.13236,,,,
91.852,12.83937,0.13394,,,,
91.854,12.90165,0.13505,,,,
91.856,12.96393,0.13593,,,,
91.858,13.02621,0.13732,,,,
91.86,13.08849,0.13964,,,,
91.862,13.15078,0.14163,,,,
91.864,13.21306,0.14206,,,,
91.866,13.27535,0.14103,,,,
91.868,13.33763,0.14054,,,,
91.87,13.39991,0.14176,,,,
91.872,13.46219,0.14438,,,,
91.874,13.52447,0.14676,,,,
91.876,13.58675,0.1479,,,,
91.878,13.64902,0.15008,,,,
91.88,13.71129,0.15283,,,,
91.882,13.77357,0.15323,,,,
91.884,13.83584,0.15187,,,,
91.886,13.89812,0.15014,,,,
91.888,13.9604,0.15063,,,,
91.89,14.02268,0.15116,,,,
91.892,14.08496,0.1511,,,,
91.894,14.14725,0.15057,,,,
91.896,14.20953,0.15031,,,,
91.898,14.27181,0.14947,,,,
91.9,14.33409,0.14688,,,,
91.902,14.39637,0.14394,,,,
91.904,14.45865,0.14255,,,,
91.906,14.52093,0.14191,,,,
91.908,14.58322,0.14007,,,,
91.91,14.6455,0.13815,,,,
91.912,14.70779,0.13769,,,,
91.914,14.77007,0.13671,,,,
91.916,14.83235,0.13496,,,,
91.918,14.89464,0.13494,,,,
91.92,14.95691,0.13581,,,,
91.922,15.01919,0.13546,,,,
91.924,15.08147,0.13375,,,,
91.926,15.14374,0.13311,,,,
91.928,15.20602,0.13323,,,,
91.93,15.26829,0.13073,,,,
91.932,15.33057,0.12654,,,,
91.934,15.39285,0.12367,,,,
91.936,15.45512,0.12319,,,,
91.938,15.5174,0.12417,,,,
91.94,15.57968,0.12652,,,,
91.942,15.64196,0.12907,,,,
91.944,15.70423,0.13085,,,,
91.946,15.7665,0.13241,,,,
91.948,15.82877,0.13503,,,,
91.95,15.89104,0.13872,,,,
91.952,15.95331,0.1439,,,,
91.954,16.01557,0.14857,,,,
91.956,16.07783,0.14978,,,,
91.958,16.14009,0.14803,,,,