File: data/instron/Sample14_Static.is_tcyclic_RawData/Specimen_RawData_1.csv
Strain : Tensile strain (Extension) gauge length,"100.00000",mm

Time,Extension,Load
(s),(mm),(N)
"0.00000","0.00000","0.31088"
"0.20000","0.04464","0.46735"
"0.40000","0.10771","0.75107"
"0.60000","0.17022","1.15833"
"0.80000","0.23274","1.76487"
"1.00000","0.29453","2.58362"
"1.20000","0.35712","3.69221"
"1.40000","0.41922","5.11530"
"1.60000","0.48167","6.96380"
"1.80000","0.54390","9.21826"
"2.00000","0.60616","11.91786"
"2.20000","0.66823","15.12716"
"2.40000","0.73109","18.83556"
"2.60000","0.79284","22.98728"
"2.80000","0.85507","27.58791"
"3.00000","0.91767","32.65871"
"3.20000","0.98002","38.06059"
"3.40000","1.04183","43.70059"
"3.55400","1.09019","48.37321"
"3.55600","1.09082","48.43443"
"3.75600","1.09845","47.50261"
"3.95600","1.09743","46.33934"
"4.15600","1.09715","45.57450"
"4.35600","1.09706","44.99315"
"4.55600","1.09706","44.54534"
"4.75600","1.09706","44.14304"
"4.95600","1.09706","43.80860"
"5.15600","1.09706","43.51061"
"5.35600","1.09706","43.23232"
"5.55600","1.09706","42.99363"
"5.75600","1.09703","42.77784"
"5.95600","1.09697","42.55859"
"6.15600","1.09697","42.36531"
"6.35600","1.09697","42.18314"
"6.55600","1.09697","42.02572"
"6.75600","1.09697","41.86728"
"6.95600","1.09697","41.72033"
"7.15600","1.09697","41.57323"
"7.35600","1.09697","41.43172"
"7.55600","1.09697","41.31121"
"7.75600","1.09697","41.18580"
"7.95600","1.09697","41.07784"
"8.15600","1.09697","40.95089"
"8.35600","1.09697","40.84721"
"8.55600","1.09697","40.73798"
"8.75600","1.09697","40.63424"
"8.95600","1.09697","40.54094"
"9.15600","1.09697","40.44859"
"9.35600","1.09697","40.36287"
"9.55600","1.09697","40.27818"
"9.75600","1.09697","40.18298"
"9.95600","1.09697","40.09733"
"10.15600","1.09697","40.02182"
"10.35600","1.09697","39.94333"
"10.55600","1.09697","39.86732"
"10.75600","1.09697","39.79487"
"10.95600","1.09697","39.73232"
"11.15600","1.09697","39.65957"
"11.35600","1.09697","39.58922"
"11.55600","1.09697","39.51530"
"11.75600","1.09697","39.45617"
"11.95600","1.09697","39.38983"
"12.15600","1.09697","39.33063"
"12.35600","1.09697","39.26122"
"12.55600","1.09697","39.20667"
"12.75600","1.09697","39.14224"
"12.95600","1.09697","39.08995"
"13.15600","1.09697","39.03312"
"13.35600","1.09697","38.98627"
"13.55600","1.09697","38.93132"
"13.75600","1.09697","38.86497"
"13.95600","1.09697","38.81158"
"14.15600","1.09697","38.75731"
"14.35600","1.09697","38.71980"
"14.55600","1.09697","38.67695"
"14.75600","1.09697","38.62199"
"14.95600","1.09697","38.56832"
"15.15600","1.09697","38.52087"
"15.35600","1.09697","38.47622"
"15.55600","1.09697","38.42015"
"15.75600","1.09697","38.37704"
"15.95600","1.09697","38.32629"
"16.15600","1.09697","38.28265"
"16.35600","1.09697","38.22860"
"16.55600","1.09697","38.19144"
"16.75600","1.09697","38.15285"
"16.95600","1.09697","38.10999"
"17.15600","1.09697","38.06593"
"17.35600","1.09697","38.03202"
"17.55600","1.09697","37.98728"
"17.75600","1.09697","37.95233"
"17.95600","1.09697","37.90919"
"18.15600","1.09697","37.87601"
"18.35600","1.09697","37.83157"
"18.55600","1.09697","37.79413"
"18.75600","1.09697","37.75850"
"18.95600","1.09697","37.71618"
"19.15600","1.09697","37.68961"
"19.35600","1.09697","37.64633"
"19.55600","1.09697","37.61254"
"19.75600","1.09697","37.58351"
"19.95600","1.09697","37.54022"
"20.15600","1.09697","37.49702"
"20.35600","1.09697","37.48256"
"20.55600","1.09697","37.44332"
"20.75600","1.09697","37.41148"
"20.95600","1.09697","37.37401"
"21.15600","1.09697","37.34668"
"21.35600","1.09697","37.31372"
"21.55600","1.09697","37.27768"
"21.75600","1.09697","37.25200"
"21.95600","1.09697","37.22550"
"22.15600","1.09697","37.19029"
"22.35600","1.09697","37.16137"
"22.55600","1.09697","37.13508"
"22.75600","1.09697","37.10464"
"22.95600","1.09697","37.07815"
"23.15600","1.09697","37.04796"
"23.35600","1.09697","37.02197"
"23.55500","1.09697","36.99242"
"23.58600","1.09697","36.99356"
"23.78300","1.04986","30.38811"
"23.98300","0.98709","22.73158"
"24.18300","0.92441","16.69875"
"24.38300","0.86235","11.96934"
"24.58300","0.79999","8.24357"
"24.78300","0.73766","5.43502"
"24.98300","0.67509","3.38004"
"25.18300","0.61331","2.01582"
"25.38300","0.55071","1.13975"
"25.58300","0.48855","0.63127"
"25.78300","0.42610","0.35500"
"25.98300","0.36413","0.22074"
"26.18300","0.30164","0.15965"
"26.38300","0.23960","0.11676"
"26.58300","0.17692","0.09266"
"26.78300","0.11502","0.07319"
"26.98300","0.05260","0.06633"
"27.13000","0.00682","0.04917"
"27.13200","0.00619","0.04887"
"27.33200","0.04080","0.07949"
"27.53200","0.10426","0.10887"
"27.73200","0.16694","0.14336"
"27.93200","0.22929","0.20918"
"28.13200","0.29106","0.30802"
"28.33200","0.35373","0.48131"
"28.53200","0.41592","0.78569"
"28.73200","0.47826","1.36879"
"28.93200","0.54048","2.33074"
"29.13200","0.60281","3.80246"
"29.33200","0.66497","5.93753"
"29.53200","0.72764","8.83592"
"29.73200","0.78943","12.46801"
"29.93200","0.85173","16.94194"
"30.13200","0.91441","22.26206"
"30.33200","0.97653","28.23433"
"30.53200","1.03845","34.80645"
"30.71800","1.09672","41.53568"
"30.72000","1.09733","41.60774"
"30.92000","1.10593","41.58379"
"31.12000","1.10410","40.81397"
"31.32000","1.10372","40.40852"
"31.52000","1.10363","40.11345"
"31.72000","1.10363","39.87943"
"31.92000","1.10363","39.68779"
"32.12000","1.10353","39.52261"
"32.32000","1.10353","39.37201"
"32.52000","1.10358","39.24323"
"32.72000","1.10359","39.12590"
"32.92000","1.10359","39.01366"
"33.12000","1.10360","38.93560"
"33.32000","1.10360","38.83826"
"33.52000","1.10362","38.75820"
"33.72000","1.10363","38.68449"
"33.92000","1.10363","38.60944"
"34.12000","1.10363","38.51999"
"34.32000","1.10363","38.45676"
"34.52000","1.10363","38.38134"
"34.72000","1.10363","38.32236"
"34.92000","1.10363","38.26479"
"35.12000","1.10363","38.20254"
"35.32000","1.10363","38.15047"
"35.52000","1.10363","38.09752"
"35.72000","1.10363","38.04650"
"35.92000","1.10363","37.99738"
"36.12000","1.10363","37.94923"
"36.32000","1.10363","37.89910"
"36.52000","1.10363","37.84539"
"36.72000","1.10363","37.80981"
"36.92000","1.10363","37.76591"
"37.12000","1.10363","37.72537"
"37.32000","1.10363","37.67833"
"37.52000","1.10363","37.65251"
"37.72000","1.10363","37.60711"
"37.92000","1.10363","37.56527"
"38.12000","1.10363","37.53931"
"38.32000","1.10363","37.50602"
"38.52000","1.10363","37.46597"
"38.72000","1.10363","37.43421"
"38.92000","1.10363","37.41028"
"39.12000","1.10363","37.37789"
"39.32000","1.10363","37.33172"
"39.52000","1.10363","37.30510"
"39.72000","1.10363","37.27581"
"39.92000","1.10363","37.24804"
"40.12000","1.10363","37.21191"
"40.32000","1.10363","37.18192"
"40.52000","1.10363","37.15510"
"40.72000","1.10363","37.13390"
"40.92000","1.10363","37.10204"
"41.12000","1.10363","37.07405"
"41.32000","1.10363","37.04923"
"41.52000","1.10363","37.03251"
"41.72000","1.10363","37.00091"
"41.92000","1.10363","36.97648"
"42.12000","1.10363","36.95340"
"42.32000","1.10363","36.92684"
"42.52000","1.10363","36.89775"
"42.72000","1.10363","36.87109"
"42.92000","1.10363","36.84591"
"43.12000","1.10363","36.83307"
"43.32000","1.10363","36.80210"
"43.52000","1.10363","36.78183"
"43.72000","1.10363","36.75931"
"43.92000","1.10363","36.73547"
"44.12000","1.10363","36.71329"
"44.32000","1.10363","36.68533"
"44.52000","1.10363","36.66794"
"44.72000","1.10363","36.65296"
"44.92000","1.10363","36.62027"
"45.12000","1.10363","36.60728"
"45.32000","1.10363","36.58874"
"45.52000","1.10363","36.56760"
"45.72000","1.10363","36.53988"
"45.92000","1.10363","36.53135"
"46.12000","1.10363","36.51023"
"46.32000","1.10363","36.49595"
"46.52000","1.10363","36.47328"
"46.72000","1.10363","36.44126"
"46.92000","1.10363","36.42718"
"47.12000","1.10363","36.40903"
"47.32000","1.10363","36.38794"
"47.52000","1.10363","36.37861"
"47.72000","1.10363","36.35914"
"47.92000","1.10363","36.34243"
"48.12000","1.10363","36.32643"
"48.32000","1.10363","36.30594"
"48.52000","1.10363","36.28711"
"48.72000","1.10363","36.26651"
"48.92000","1.10363","36.24159"
"49.12000","1.10363","36.21915"
"49.32000","1.10363","36.21538"
"49.52000","1.10363","36.19324"
"49.72000","1.10363","36.17952"
"49.92000","1.10363","36.15963"
"50.12000","1.10363","36.15088"
"50.32000","1.10363","36.13651"
"50.52000","1.10363","36.11622"
"50.71900","1.10363","36.10069"
"50.74500","1.10363","36.09670"
"50.93900","1.05660","29.35376"
"51.13900","0.99377","21.69148"
"51.33900","0.93141","15.70422"
"51.53900","0.86921","11.02959"
"51.73900","0.80684","7.42874"
"51.93900","0.74444","4.73904"
"52.13900","0.68209","2.86698"
"52.33900","0.62016","1.66497"
"52.53900","0.55759","0.92613"
"52.73900","0.49527","0.52752"
"52.93900","0.43318","0.33001"
"53.13900","0.37097","0.24492"
"53.33900","0.30844","0.18954"
"53.53900","0.24640","0.16939"
"53.73900","0.18406","0.15324"
"53.93900","0.12177","0.12811"
"54.13900","0.05945","0.11690"
"54.28600","0.01372","0.10865"
"54.28800","0.01309","0.10839"
"54.48800","0.04800","0.13257"
"54.68800","0.11126","0.15985"
"54.88800","0.17371","0.18963"
"55.08800","0.23628","0.23270"
"55.28800","0.29822","0.30533"
"55.48800","0.36073","0.41281"
"55.68800","0.42273","0.65949"
"55.88800","0.48520","1.09082"
"56.08800","0.54756","1.87211"
"56.28800","0.60981","3.14242"
"56.48800","0.67174","5.06768"
"56.68800","0.73467","7.77590"
"56.88800","0.79655","11.26114"
"57.08800","0.85870","15.62161"
"57.28800","0.92121","20.87690"
"57.48800","0.98362","26.87185"
"57.68800","1.04555","33.54888"
"57.87400","1.10363","40.35988"
"57.87600","1.10424","40.43140"
"58.07600","1.11296","40.54115"
"58.27600","1.11107","39.82782"
"58.47600","1.11065","39.45315"
"58.67600","1.11066","39.20045"
"58.87600","1.11056","38.99167"
"59.07600","1.11056","38.82200"
"59.27600","1.11056","38.67111"
"59.47600","1.11056","38.54197"
"59.67600","1.11056","38.44591"
"59.87600","1.11056","38.33600"
"60.07600","1.11056","38.24817"
"60.27600","1.11056","38.15282"
"60.47600","1.11056","38.07576"
"60.67600","1.11056","37.99256"
"60.87600","1.11056","37.92833"
"61.07600","1.11047","37.85956"
"61.27600","1.11053","37.80699"
"61.47600","1.11056","37.74702"
"61.67600","1.11056","37.70066"
"61.87600","1.11056","37.64715"
"62.07600","1.11056","37.58727"
"62.27600","1.11056","37.53078"
"62.47600","1.11056","37.48980"
"62.67600","1.11056","37.45884"
"62.87600","1.11056","37.40992"
"63.07600","1.11056","37.37790"
"63.27600","1.11056","37.32812"
"63.47600","1.11056","37.29042"
"63.67600","1.11056","37.25061"
"63.87600","1.11056","37.22898"
"64.07600","1.11056","37.18344"
"64.27600","1.11056","37.14976"
"64.47600","1.11056","37.12075"
"64.67600","1.11056","37.08854"
"64.87600","1.11056","37.06815"
"65.07600","1.11056","37.02595"
"65.27600","1.11056","37.00031"
"65.47600","1.11056","36.96630"
"65.67600","1.11056","36.94395"
"65.87600","1.11056","36.91508"
"66.07600","1.11056","36.89271"
"66.27600","1.11056","36.85556"
"66.47600","1.11056","36.83893"
"66.67600","1.11056","36.80989"
"66.87600","1.11056","36.78212"
"67.07600","1.11056","36.75723"
"67.27600","1.11056","36.73286"
"67.47600","1.11056","36.71194"
"67.67600","1.11056","36.69254"
"67.87600","1.11056","36.68045"
"68.07600","1.11056","36.64582"
"68.27600","1.11056","36.62428"
"68.47600","1.11056","36.59925"
"68.67600","1.11056","36.58053"
"68.87600","1.11056","36.55564"
"69.07600","1.11056","36.53423"
"69.27600","1.11056","36.50985"
"69.47600","1.11056","36.47911"
"69.67600","1.11056","36.46777"
"69.87600","1.11056","36.44721"
"70.07600","1.11056","36.43936"
"70.27600","1.11056","36.41382"
"70.47600","1.11056","36.39006"
"70.67600","1.11056","36.37467"
"70.87600","1.11056","36.35929"
"71.07600","1.11056","36.33884"
"71.27600","1.11056","36.31471"
"71.47600","1.11056","36.29296"
"71.67600","1.11056","36.28685"
"71.87600","1.11056","36.26624"
"72.07600","1.11056","36.24314"
"72.27600","1.11056","36.22325"
"72.47600","1.11056","36.21544"
"72.67600","1.11056","36.19666"
"72.87600","1.11056","36.17556"
"73.07600","1.11056","36.15678"
"73.27600","1.11056","36.14425"
"73.47600","1.11056","36.13660"
"73.67600","1.11056","36.11161"
"73.87600","1.11056","36.08577"
"74.07600","1.11056","36.08395"
"74.27600","1.11056","36.07725"
"74.47600","1.11056","36.06334"
"74.67600","1.11056","36.05361"
"74.87600","1.11056","36.03644"
"75.07600","1.11056","36.01533"
"75.27600","1.11056","36.00732"
"75.47600","1.11056","35.99580"
"75.67600","1.11056","35.96616"
"75.87600","1.11056","35.96478"
"76.07600","1.11056","35.94829"
"76.27600","1.11056","35.93604"
"76.47600","1.11056","35.91686"
"76.67600","1.11056","35.89582"
"76.87600","1.11056","35.89027"
"77.07600","1.11056","35.87931"
"77.27600","1.11056","35.85789"
"77.47600","1.11056","35.84137"
"77.67600","1.11056","35.83501"
"77.87500","1.11056","35.82600"
"77.89500","1.11056","35.81690"
"78.08700","1.06377","29.03702"
"78.28700","1.00117","21.36764"
"78.48700","0.93887","15.35216"
"78.68700","0.87636","10.65679"
"78.88700","0.81421","7.08463"
"79.08700","0.75183","4.44652"
"79.28700","0.68962","2.63307"
"79.48700","0.62738","1.47738"
"79.68700","0.56499","0.80104"
"79.88700","0.50257","0.44859"
"80.08700","0.44076","0.29855"
"80.28700","0.37815","0.19685"
"80.48700","0.31574","0.16446"
"80.68700","0.25380","0.15321"
"80.88700","0.19152","0.12405"
"81.08700","0.12884","0.12034"
"81.28700","0.06690","0.10034"
"81.43600","0.02051","0.09359"
"81.43800","0.01988","0.09297"
"81.63800","0.05512","0.11228"
"81.83800","0.11825","0.13727"
"82.03800","0.18066","0.15440"
"82.23800","0.24299","0.19461"
"82.43800","0.30532","0.24652"
"82.63800","0.36778","0.35339"
"82.81000","0.42101","0.50129"
"82.81200","0.42162","0.50479"
"82.83200","0.42720","0.52465"
"82.85200","0.43046","0.55186"
"82.87200","0.43354","0.55304"
"82.89200","0.43593","0.56832"
"82.91200","0.43986","0.59693"
"82.93200","0.44671","0.62896"
"82.95200","0.45465","0.67632"
"82.97200","0.46225","0.71860"
"82.99200","0.46944","0.76636"
"83.01200","0.47631","0.81956"
"83.03200","0.48282","0.86986"
"83.05200","0.48901","0.91971"
"83.07200","0.49510","0.97258"
"83.09200","0.50135","1.02413"
"83.11200","0.50785","1.08534"
"83.13200","0.51439","1.14861"
"83.15200","0.52079","1.21507"
"83.17200","0.52700","1.28243"
"83.19200","0.53309","1.35720"
"83.21200","0.53926","1.43658"
"83.23200","0.54555","1.51964"
"83.25200","0.55187","1.60859"
"83.27200","0.55815","1.69860"
"83.29200","0.56435","1.79520"
"83.31200","0.57047","1.89062"
"83.33200","0.57666","2.00520"
"83.35200","0.58294","2.12521"
"83.37200","0.58922","2.24223"
"83.39200","0.59547","2.36691"
"83.41200","0.60163","2.49491"
"83.43200","0.60783","2.63633"
"83.45200","0.61409","2.77965"
"83.47200","0.62030","2.92580"
"83.49200","0.62643","3.07191"
"83.51200","0.63258","3.22554"
"83.53200","0.63878","3.39105"
"83.55200","0.64510","3.57618"
"83.57200","0.65149","3.77206"
"83.59200","0.65774","3.96359"
"83.61200","0.66383","4.15569"
"83.63200","0.66987","4.35199"
"83.65200","0.67597","4.55668"
"83.67200","0.68232","4.78548"
"83.69200","0.68882","5.01785"
"83.71200","0.69517","5.25170"
"83.73200","0.70126","5.49985"
"83.75200","0.70732","5.75194"
"83.77200","0.71352","6.01525"
"83.79200","0.71995","6.28483"
"83.81200","0.72643","6.56938"
"83.83200","0.73276","6.86253"
"83.85200","0.73885","7.14802"
"83.87200","0.74481","7.44512"
"83.89200","0.75091","7.75012"
"83.91200","0.75725","8.07449"
"83.93200","0.76366","8.41529"
"83.95200","0.76998","8.74939"
"83.97200","0.77614","9.08467"
"83.99200","0.78214","9.42667"
"84.01200","0.78824","9.79080"
"84.03200","0.79455","10.16957"
"84.05200","0.80092","10.56132"
"84.07200","0.80718","10.94837"
"84.09200","0.81332","11.33324"
"84.11200","0.81943","11.73429"
"84.13200","0.82565","12.15562"
"84.15200","0.83194","12.59601"
"84.17200","0.83822","13.04402"
"84.19200","0.84445","13.48596"
"84.21200","0.85059","13.92040"
"84.23200","0.85675","14.37056"
"84.25200","0.86305","14.85063"
"84.27200","0.86937","15.34166"
"84.29200","0.87559","15.83207"
"84.31200","0.88171","16.32575"
"84.33200","0.88784","16.82012"
"84.35200","0.89415","17.33701"
"84.37200","0.90066","17.88153"
"84.39200","0.90709","18.43329"
"84.41200","0.91328","18.97022"
"84.43200","0.91934","19.50187"
"84.45200","0.92539","20.03985"
"84.47200","0.93161","20.60512"
"84.49200","0.93800","21.18813"
"84.51200","0.94434","21.76790"
"84.53200","0.95049","22.34693"
"84.55200","0.95654","22.92727"
"84.57200","0.96261","23.51562"
"84.59200","0.96889","24.14321"
"84.61200","0.97532","24.79125"
"84.63200","0.98168","25.41977"
"84.65200","0.98784","26.02701"
"84.67200","0.99387","26.63736"
"84.69200","0.99991","27.26833"
"84.71200","1.00617","27.94141"
"84.73200","1.01255","28.63914"
"84.75200","1.01886","29.31400"
"84.77200","1.02508","29.97122"
"84.79200","1.03120","30.62706"
"84.81200","1.03732","31.31060"
"84.83200","1.04358","32.02188"
"84.85200","1.04991","32.75595"
"84.87200","1.05616","33.47523"
"84.89200","1.06233","34.18470"
"84.91200","1.06847","34.88193"
"84.93200","1.07471","35.61005"
"84.95200","1.08111","36.38348"
"84.97200","1.08749","37.15884"
"84.99200","1.09373","37.91587"
"85.01200","1.09990","38.65371"
"85.03200","1.10606","39.38483"
"85.05200","1.11231","40.14359"
"85.07200","1.11860","40.92477"
"85.09200","1.12482","41.70073"
"85.11200","1.13095","42.46888"
"85.13200","1.13705","43.23917"
"85.15200","1.14325","44.01287"
"85.17200","1.14968","44.81669"
"85.19200","1.15608","45.63074"
"85.21200","1.16225","46.42447"
"85.23200","1.16831","47.21007"
"85.25200","1.17437","47.97573"
"85.27200","1.18056","48.76943"
"85.29200","1.18692","49.58240"
"85.31200","1.19331","50.40209"
"85.33200","1.19953","51.21354"
"85.35200","1.20557","51.98919"
"85.37200","1.21163","52.77058"
"85.39200","1.21790","53.59211"
"85.41200","1.22428","54.42662"
"85.43200","1.23063","55.23935"
"85.45200","1.23681","56.02534"
"85.47200","1.24286","56.79218"
"85.49200","1.24895","57.58263"
"85.51200","1.25527","58.40724"
"85.53200","1.26171","59.24242"
"85.55200","1.26809","60.05267"
"85.57200","1.27437","60.84079"
"85.59200","1.28052","61.61667"
"85.61200","1.28666","62.39389"
"85.63200","1.29294","63.18361"
"85.65200","1.29929","63.97688"
"85.67200","1.30558","64.74911"
"85.69200","1.31179","65.49529"
"85.71200","1.31786","66.22653"
"85.73200","1.32394","66.96424"
"85.75200","1.33015","67.71951"
"85.77200","1.33643","68.47309"
"85.79200","1.34269","69.19910"
"85.81200","1.34890","69.91730"
"85.83200","1.35512","70.63941"
"85.85200","1.36138","71.37774"
"85.87200","1.36766","72.10773"
"85.89200","1.37387","72.80911"
"85.91200","1.38001","73.48727"
"85.93200","1.38615","74.15154"
"85.95200","1.39238","74.82677"
"85.97200","1.39873","75.53936"
"85.99200","1.40502","76.25642"
"86.01200","1.41120","76.94613"
"86.03200","1.41731","77.62118"
"86.05200","1.42341","78.27909"
"86.07200","1.42966","78.94514"
"86.09200","1.43612","79.65152"
"86.11200","1.44250","80.34878"
"86.13200","1.44864","81.02597"
"86.15200","1.45472","81.69592"
"86.17200","1.46086","82.36913"
"86.19200","1.46722","83.06872"
"86.21200","1.47374","83.77221"
"86.23200","1.48011","84.45317"
"86.25200","1.48620","85.10185"
"86.27200","1.49217","85.73759"
"86.29200","1.49823","86.39979"
"86.31200","1.50453","87.08696"
"86.33200","1.51098","87.78837"
"86.35200","1.51736","88.46420"
"86.37200","1.52352","89.10188"
"86.39200","1.52951","89.73267"
"86.41200","1.53556","90.38116"
"86.43200","1.54188","91.07970"
"86.45200","1.54830","91.77955"
"86.47200","1.55463","92.43901"
"86.49200","1.56081","93.06514"
"86.51200","1.56684","93.67502"
"86.53200","1.57291","94.32079"
"86.55200","1.57916","95.00169"
"86.57200","1.58552","95.69127"
"86.59200","1.59184","96.35486"
"86.61200","1.59805","96.97588"
"86.63200","1.60417","97.59013"
"86.65200","1.61032","98.23632"
"86.67200","1.61658","98.90999"
"86.69200","1.62289","99.58299"
"86.71200","1.62910","100.21420"
"86.73200","1.63527","100.82719"
"86.75200","1.64154","101.44671"
"86.77200","1.64796","102.10104"
"86.79200","1.65438","102.77549"
"86.81200","1.66062","103.42332"
"86.83200","1.66672","104.03279"
"86.83400","1.66732","104.09146"
"86.99700","1.64475","96.47581"
"87.14600","1.59650","86.41866"
"87.31600","1.54357","76.36887"
"87.50000","1.48614","66.33337"
"87.69800","1.42416","56.49861"
"87.89800","1.36237","47.52590"
"88.09800","1.29989","39.33130"
"88.29800","1.23761","31.92953"
"88.49800","1.17522","25.30756"
"88.69800","1.11310","19.54292"
"88.89800","1.05079","14.58879"
"89.09800","0.98853","10.46376"
"89.29800","0.92608","7.13637"
"89.49800","0.86405","4.62486"
"89.69800","0.80167","2.82944"
"89.89800","0.73929","1.62159"
"90.09800","0.67677","0.87601"
"90.29800","0.61499","0.50277"
"90.49800","0.55237","0.30238"
"90.69800","0.49015","0.21683"
"90.89800","0.42777","0.16551"
"90.92100","0.42061","0.17030"
"91.02200","0.42133","0.19250"
"91.22200","0.48755","0.29872"
"91.40600","0.54519","0.50159"
"91.40800","0.54582","0.50471"
"91.41000","0.54646","0.50757"
"91.41200","0.54710","0.51260"
"91.41400","0.54776","0.52591"
"91.41600","0.54850","0.55076"
"91.41800","0.54939","0.58431"
"91.42000","0.55052","0.62456"
"91.42200","0.55201","0.67233"
"91.42400","0.55398","0.72860"
"91.42600","0.55656","0.79421"
"91.42800","0.55990","0.86909"
"91.43000","0.56413","0.95602"
"91.43200","0.56940","1.05883"
"91.43400","0.57584","1.18231"
"91.43600","0.58359","1.33238"
"91.43800","0.59276","1.51831"
"91.44000","0.60350","1.75183"
"91.44200","0.61590","2.04690"
"91.44400","0.63008","2.42160"
"91.44600","0.64614","2.89889"
"91.44800","0.66416","3.50460"
"91.45000","0.68423","4.26887"
"91.45200","0.70643","5.22537"
"91.45400","0.73081","6.40999"
"91.45600","0.75745","7.86071"
"91.45800","0.78638","9.61727"
"91.46000","0.81765","11.71907"
"91.46200","0.85130","14.20256"
"91.46400","0.88734","17.09960"
"91.46600","0.92578","20.44033"
"91.46800","0.96661","24.24859"
"91.47000","1.00981","28.53656"
"91.47200","1.05532","33.30483"
"91.47400","1.10303","38.54573"
"91.47600","1.15281","44.24182"
"91.47800","1.20450","50.36074"
"91.48000","1.25790","56.85461"
"91.48200","1.31282","63.66941"
"91.48400","1.36906","70.74969"
"91.48600","1.42643","78.04084"
"91.48800","1.48477","85.49084"
"91.49000","1.54392","93.04972"
"91.49200","1.60375","100.67385"
"91.49400","1.66415","108.32549"
"91.49600","1.72502","115.97025"
"91.49800","1.78628","123.57855"
"91.50000","1.84787","131.12305"
"91.50200","1.90973","138.57898"
"91.50400","1.97183","145.92395"
"91.50600","2.03413","153.13936"
"91.50800","2.09660","160.20775"
"91.51000","2.15922","167.11241"
"91.51200","2.22197","173.83760"
"91.51400","2.28484","180.37004"
"91.51600","2.34782","186.69818"
"91.51800","2.41090","192.81091"
"91.52000","2.47406","198.69180"
"91.52200","2.53729","204.32108"
"91.52400","2.60059","209.67982"
"91.52600","2.66393","214.77190"
"91.52800","2.72730","219.62242"
"91.53000","2.79070","224.25690"
"91.53200","2.85412","228.68506"
"91.53400","2.91752","232.88643"
"91.53600","2.98092","236.80737"
"91.53800","3.04430","240.42798"
"91.54000","3.10765","243.76932"
"91.54200","3.17096","246.86523"
"91.54400","3.23423","249.74684"
"91.54600","3.29746","252.44391"
"91.54800","3.36063","254.98158"
"91.55000","3.42376","257.38098"
"91.55200","3.48683","259.40366"
"91.55400","3.54986","259.33719"
"91.55600","3.61282","255.82474"
"91.55800","3.67574","249.06635"
"91.56000","3.73861","239.74698"
"91.56200","3.80144","228.47168"
"91.56400","3.86424","215.73289"
"91.56600","3.92700","201.94786"
"91.56800","3.98974","187.48996"
"91.57000","4.05245","172.68102"
"91.57200","4.11515","157.79416"
"91.57400","4.17783","143.05713"
"91.57600","4.24049","128.65855"
"91.57800","4.30313","114.75149"
"91.58000","4.36576","101.45361"
"91.58200","4.42836","88.85591"
"91.58400","4.49095","77.02654"
"91.58600","4.55351","66.01176"
"91.58800","4.61606","55.83837"
"91.59000","4.67858","46.51836"
"91.59200","4.74108","38.04650"
"91.59400","4.80357","30.40622"
"91.59600","4.86603","23.57399"
"91.59800","4.92847","17.51859"
"91.60000","4.99090","12.19897"
"91.60200","5.05331","7.56820"
"91.60400","5.11569","3.57828"
"91.60600","5.17807","0.18444"
"91.60800","5.24042","-2.65964"
"91.61000","5.30276","-4.99998"
"91.61200","5.36509","-6.88375"
"91.61400","5.42741","-8.35666"
"91.61600","5.48972","-9.46413"
"91.61800","5.55202","-10.25226"
"91.62000","5.61431","-10.76121"
"91.62200","5.67660","-11.02612"
"91.62400","5.73888","-11.08210"
"91.62600","5.80115","-10.96370"
"91.62800","5.86342","-10.70384"
"91.63000","5.92568","-10.33060"
"91.63200","5.98793","-9.86470"
"91.63400","6.05018","-9.32764"
"91.63600","6.11243","-8.74265"
"91.63800","6.17468","-8.12848"
"91.64000","6.23693","-7.49654"
"91.64200","6.29919","-6.85419"
"91.64400","6.36145","-6.21305"
"91.64600","6.42372","-5.58450"
"91.64800","6.48600","-4.97616"
"91.65000","6.54827","-4.39229"
"91.65200","6.61056","-3.83782"
"91.65400","6.67284","-3.31582"
"91.65600","6.73513","-2.82672"
"91.65800","6.79742","-2.37174"
"91.66000","6.85971","-1.95286"
"91.66200","6.92201","-1.57189"
"91.66400","6.98431","-1.22835"
"91.66600","7.04661","-0.92060"
"91.66800","7.10892","-0.64916"
"91.67000","7.17123","-0.41364"
"91.67200","7.23354","-0.21043"
"91.67400","7.29585","-0.03536"
"91.67600","7.35816","0.11397"
"91.67800","7.42046","0.24051"
"91.68000","7.48276","0.34606"
"91.68200","7.54506","0.43145"
"91.68400","7.60736","0.49759"
"91.68600","7.66966","0.54844"
"91.68800","7.73195","0.58719"
"91.69000","7.79425","0.61335"
"91.69200","7.85655","0.62757"
"91.69400","7.91884","0.63313"
"91.69600","7.98114","0.63222"
"91.69800","8.04344","0.62480"
"91.70000","8.10573","0.61133"
"91.70200","8.16802","0.59298"
"91.70400","8.23031","0.57135"
"91.70600","8.29259","0.54863"
"91.70800","8.35487","0.52528"
"91.71000","8.41715","0.49921"
"91.71200","8.47942","0.47046"
"91.71400","8.54170","0.44223"
"91.71600","8.60398","0.41483"
"91.71800","8.66626","0.38759"
"91.72000","8.72855","0.36168"
"91.72200","8.79083","0.33932"
"91.72400","8.85312","0.32116"
"91.72600","8.91541","0.30439"
"91.72800","8.97771","0.28772"
"91.73000","9.04001","0.27101"
"91.73200","9.10231","0.25348"
"91.73400","9.16461","0.23556"
"91.73600","9.22692","0.21821"
"91.73800","9.28923","0.20231"
"91.74000","9.35154","0.18792"
"91.74200","9.41386","0.17549"
"91.74400","9.47617","0.16489"
"91.74600","9.53849","0.15537"
"91.74800","9.60080","0.14759"
"91.75000","9.66311","0.14250"
"91.75200","9.72542","0.14034"
"91.75400","9.78773","0.14063"
"91.75600","9.85003","0.14145"
"91.75800","9.91233","0.13984"
"91.76000","9.97463","0.13534"
"91.76200","10.03693","0.13067"
"91.76400","10.09923","0.12725"
"91.76600","10.16152","0.12498"
"91.76800","10.22381","0.12346"
"91.77000","10.28610","0.12248"
"91.77200","10.34839","0.12188"
"91.77400","10.41067","0.12170"
"91.77600","10.47295","0.12245"
"91.77800","10.53522","0.12441"
"91.78000","10.59750","0.12563"
"91.78200","10.65977","0.12787"
"91.78400","10.72204","0.13231"
"91.78600","10.78431","0.13822"
"91.78800","10.84658","0.14454"
"91.79000","10.90885","0.14999"
"91.79200","10.97111","0.15357"
"91.79400","11.03338","0.15390"
"91.79600","11.09564","0.15307"
"91.79800","11.15790","0.15385"
"91.80000","11.22016","0.15430"
"91.80200","11.28242","0.15309"
"91.80400","11.34469","0.15254"
"91.80600","11.40695","0.15389"
"91.80800","11.46922","0.15386"
"91.81000","11.53149","0.15142"
"91.81200","11.59376","0.14891"
"91.81400","11.65604","0.14877"
"91.81600","11.71832","0.15160"
"91.81800","11.78060","0.15387"
"91.82000","11.84289","0.15456"
"91.82200","11.90517","0.15363"
"91.82400","11.96746","0.15209"
"91.82600","12.02974","0.15067"
"91.82800","12.09202","0.14934"
"91.83000","12.15431","0.14764"
"91.83200","12.21659","0.14576"
"91.83400","12.27887","0.14277"
"91.83600","12.34115","0.13887"
"91.83800","12.40343","0.13504"
"91.84000","12.46571","0.13310"
"91.84200","12.52799","0.13260"
"91.84400","12.59027","0.13214"
"91.84600","12.65255","0.13146"
"91.84800","12.71482","0.13157"
"91.85000","12.77710","0.13236"
"91.85200","12.83937","0.13394"
"91.85400","12.90165","0.13505"
"91.85600","12.96393","0.13593"
"91.85800","13.02621","0.13732"
"91.86000","13.08849","0.13964"
"91.86200","13.15078","0.14163"
"91.86400","13.21306","0.14206"
"91.86600","13.27535","0.14103"
"91.86800","13.33763","0.14054"
"91.87000","13.39991","0.14176"
"91.87200","13.46219","0.14438"
"91.87400","13.52447","0.14676"
"91.87600","13.58675","0.14790"
"91.87800","13.64902","0.15008"
"91.88000","13.71129","0.15283"
"91.88200","13.77357","0.15323"
"91.88400","13.83584","0.15187"
"91.88600","13.89812","0.15014"
"91.88800","13.96040","0.15063"
"91.89000","14.02268","0.15116"
"91.89200","14.08496","0.15110"
"91.89400","14.14725","0.15057"
"91.89600","14.20953","0.15031"
"91.89800","14.27181","0.14947"
"91.90000","14.33409","0.14688"
"91.90200","14.39637","0.14394"
"91.90400","14.45865","0.14255"
"91.90600","14.52093","0.14191"
"91.90800","14.58322","0.14007"
"91.91000","14.64550","0.13815"
"91.91200","14.70779","0.13769"
"91.91400","14.77007","0.13671"
"91.91600","14.83235","0.13496"
"91.91800","14.89464","0.13494"
"91.92000","14.95691","0.13581"
"91.92200","15.01919","0.13546"
"91.92400","15.08147","0.13375"
"91.92600","15.14374","0.13311"
"91.92800","15.20602","0.13323"
"91.93000","15.26829","0.13073"
"91.93200","15.33057","0.12654"
"91.93400","15.39285","0.12367"
"91.93600","15.45512","0.12319"
"91.93800","15.51740","0.12417"
"91.94000","15.57968","0.12652"
"91.94200","15.64196","0.12907"
"91.94400","15.70423","0.13085"
"91.94600","15.76650","0.13241"
"91.94800","15.82877","0.13503"
"91.95000","15.89104","0.13872"
"91.95200","15.95331","0.14390"
"91.95400","16.01557","0.14857"
"91.95600","16.07783","0.14978"
"91.95800","16.14009","0.14803"