File: data/instron/Sample25_Dynamic.is_tcyclic_RawData/Specimen_RawData_1.csv
Strain : Tensile strain (Extension) gauge length,100,mm,,,,
,,,,,,
Time,Extension,Load,,,,
(s),(mm),(N),Low Start,Low End,High Start,High End
0,0,0.15685,1279,1615,1740,1829
0.2,0.14651,0.74521,,,,
0.4,0.33268,3.05564,,,,
0.6,0.51811,8.66673,,,,
0.799,0.70271,17.88776,,,,
0.97,0.86108,27.95868,,,,
1.043,0.92889,32.75555,,,,
1.142,0.91177,27.69094,,,,
1.236,0.81915,17.56429,,,,
1.397,0.66921,7.52742,,,,
1.597,0.48366,1.96779,,,,
1.797,0.29801,0.37967,,,,
1.997,0.11263,0.07932,,,,
2.119,-0.00028,0.0409,,,,
2.121,-0.00212,0.0394,,,,
2.321,0.11533,0.1374,,,,
2.521,0.30169,0.80849,,,,
2.721,0.48728,3.72978,,,,
2.921,0.67264,11.55555,,,,
3.082,0.82173,21.61251,,,,
3.196,0.92777,30.46724,,,,
3.198,0.92961,30.62828,,,,
3.34,0.86681,20.97357,,,,
3.469,0.74557,10.86542,,,,
3.669,0.55979,3.06488,,,,
3.869,0.37424,0.59967,,,,
4.069,0.18881,0.11064,,,,
4.269,0.00335,0.03126,,,,
4.274,-0.00127,0.03239,,,,
4.375,0.01668,0.05269,,,,
4.575,0.20863,0.25605,,,,
4.775,0.39426,1.44908,,,,
4.975,0.57973,6.10145,,,,
5.163,0.75413,15.545,,,,
5.303,0.88413,25.59957,,,,
5.351,0.92857,29.53466,,,,
5.452,0.90953,25.21408,,,,
5.552,0.81155,15.12994,,,,
5.727,0.6485,5.50769,,,,
5.927,0.46297,1.21109,,,,
6.127,0.27744,0.20564,,,,
6.327,0.09198,0.04884,,,,
6.428,-0.00137,0.02777,,,,
6.529,0.01639,0.0491,,,,
6.729,0.20846,0.23241,,,,
6.929,0.39407,1.27173,,,,
7.129,0.57956,5.62955,,,,
7.318,0.75487,14.94777,,,,
7.458,0.88489,24.98742,,,,
7.506,0.92931,28.96321,,,,
7.607,0.91056,24.80475,,,,
7.707,0.81237,14.75288,,,,
7.884,0.64745,5.20237,,,,
8.084,0.46193,1.09823,,,,
8.284,0.27639,0.17851,,,,
8.484,0.09092,0.04396,,,,
8.584,-0.00146,0.024,,,,
8.685,0.01608,0.04368,,,,
8.885,0.20831,0.1923,,,,
9.085,0.3939,1.16417,,,,
9.285,0.57939,5.30414,,,,
9.475,0.75563,14.5249,,,,
9.615,0.88563,24.55356,,,,
9.662,0.92915,28.46748,,,,
9.763,0.91028,24.37398,,,,
9.865,0.81033,14.26596,,,,
10.043,0.64447,4.90667,,,,
10.243,0.45897,1.00577,,,,
10.443,0.27342,0.1698,,,,
10.643,0.08796,0.04651,,,,
10.74,-0.00163,0.01599,,,,
10.841,0.01598,0.04239,,,,
11.041,0.20809,0.17676,,,,
11.241,0.39369,1.0722,,,,
11.441,0.57917,5.06491,,,,
11.632,0.75633,14.22061,,,,
11.773,0.88726,24.30971,,,,
11.818,0.92894,28.07606,,,,
11.919,0.91015,24.05193,,,,
12.022,0.80922,13.93379,,,,
12.201,0.6424,4.67748,,,,
12.401,0.45692,0.92398,,,,
12.601,0.27135,0.15189,,,,
12.801,0.08593,0.03679,,,,
12.896,-0.00178,0.0215,,,,
12.997,0.01561,0.04723,,,,
13.197,0.20782,0.17843,,,,
13.397,0.39342,1.00568,,,,
13.597,0.57889,4.85779,,,,
13.789,0.75697,13.97702,,,,
13.93,0.88792,24.05499,,,,
13.974,0.92864,27.73733,,,,
14.075,0.91005,23.79586,,,,
14.178,0.80899,13.70223,,,,
14.358,0.64123,4.50179,,,,
14.558,0.45575,0.87667,,,,
14.758,0.27019,0.14163,,,,
14.958,0.08476,0.03695,,,,
15.051,-0.00111,0.02179,,,,
15.152,0.01619,0.0416,,,,
15.352,0.20847,0.16487,,,,
15.552,0.39408,0.95656,,,,
15.752,0.57954,4.72704,,,,
15.944,0.75763,13.77867,,,,
16.085,0.88861,23.86829,,,,
16.129,0.92931,27.54457,,,,
16.23,0.91076,23.63636,,,,
16.333,0.80968,13.55882,,,,
16.514,0.641,4.40672,,,,
16.714,0.45554,0.83832,,,,
16.914,0.26996,0.13337,,,,
17.114,0.08455,0.0345,,,,
17.207,-0.00134,0.02032,,,,
17.308,0.01613,0.03494,,,,
17.508,0.20827,0.15601,,,,
17.708,0.39386,0.91613,,,,
17.908,0.57933,4.57834,,,,
18.1,0.75742,13.55945,,,,
18.241,0.88838,23.61284,,,,
18.285,0.92908,27.2899,,,,
18.386,0.91058,23.41132,,,,
18.489,0.80951,13.39675,,,,
18.67,0.64082,4.29227,,,,
18.87,0.45536,0.80083,,,,
19.07,0.26977,0.13343,,,,
19.27,0.08432,0.03801,,,,
19.363,-0.00153,0.01741,,,,
19.464,0.01599,0.03637,,,,
19.664,0.20803,0.14675,,,,
19.864,0.39362,0.87648,,,,
20.064,0.57911,4.45505,,,,
20.257,0.75811,13.42175,,,,
20.398,0.88907,23.47074,,,,
20.441,0.92882,27.06203,,,,
20.542,0.91019,23.21154,,,,
20.647,0.80743,13.09567,,,,
20.83,0.63688,4.08225,,,,
21.03,0.4514,0.74926,,,,
21.23,0.26593,0.12326,,,,
21.43,0.08033,0.02967,,,,
21.519,-0.00176,0.01997,,,,
21.62,0.0153,0.03522,,,,
21.82,0.20773,0.14809,,,,
22.02,0.39333,0.84394,,,,
22.22,0.57881,4.34872,,,,
22.413,0.7578,13.249,,,,
22.554,0.88878,23.2688,,,,
22.597,0.92852,26.86061,,,,
22.698,0.90992,23.03215,,,,
22.803,0.80716,12.96169,,,,
22.986,0.6366,4.00632,,,,
23.186,0.45113,0.72175,,,,
23.386,0.26559,0.1114,,,,
23.586,0.08003,0.02761,,,,
23.674,-0.00111,0.01882,,,,
23.775,0.01597,0.03107,,,,
23.975,0.20838,0.1365,,,,
24.175,0.39398,0.81745,,,,
24.375,0.57949,4.27921,,,,
24.568,0.75845,13.14859,,,,
24.709,0.88944,23.1702,,,,
24.752,0.92916,26.76631,,,,
24.853,0.91072,22.95845,,,,
24.959,0.80693,12.80811,,,,
25.143,0.63544,3.8922,,,,
25.343,0.44997,0.69093,,,,
25.543,0.26439,0.10411,,,,
25.743,0.07886,0.03193,,,,
25.83,-0.00134,0.02013,,,,
25.931,0.01566,0.04187,,,,
26.131,0.2081,0.14107,,,,
26.331,0.39369,0.78604,,,,
26.531,0.5792,4.19114,,,,
26.725,0.7591,13.05595,,,,
26.866,0.89007,23.06643,,,,
26.908,0.92885,26.56921,,,,
27.009,0.91041,22.79216,,,,
27.115,0.80667,12.68997,,,,
27.299,0.63518,3.83003,,,,
27.499,0.4497,0.67812,,,,
27.699,0.26413,0.10448,,,,
27.899,0.07857,0.02428,,,,
27.986,-0.00161,0.01537,,,,
28.087,0.01546,0.03624,,,,
28.287,0.20785,0.1271,,,,
28.487,0.39343,0.76718,,,,
28.687,0.57894,4.09233,,,,
28.881,0.75886,12.90789,,,,
29.023,0.89074,22.98134,,,,
29.064,0.92861,26.41032,,,,
29.165,0.91013,22.63842,,,,
29.271,0.80641,12.55522,,,,
29.456,0.63399,3.72798,,,,
29.656,0.44852,0.65061,,,,
29.856,0.26295,0.09936,,,,
30.056,0.07739,0.02792,,,,
30.141,-0.00092,0.01532,,,,
30.242,0.01631,0.03902,,,,
30.442,0.20852,0.13201,,,,
30.642,0.3941,0.7499,,,,
30.842,0.57962,4.05046,,,,
31.036,0.75953,12.83396,,,,
31.178,0.89141,22.91253,,,,
31.219,0.92929,26.33154,,,,
31.32,0.91091,22.58788,,,,
31.426,0.8071,12.50082,,,,
31.611,0.6347,3.68452,,,,
31.811,0.44921,0.632,,,,
32.011,0.26366,0.10933,,,,
32.211,0.07809,0.02522,,,,
32.297,-0.00115,0.01225,,,,
32.398,0.0162,0.03605,,,,
32.598,0.20829,0.12932,,,,
32.798,0.39386,0.73288,,,,
32.998,0.57939,3.9832,,,,
33.193,0.76019,12.76783,,,,
33.335,0.89208,22.8388,,,,
33.375,0.92905,26.19818,,,,
33.476,0.91058,22.43803,,,,
33.582,0.80685,12.40792,,,,
33.767,0.63445,3.63797,,,,
33.967,0.44896,0.62053,,,,
34.167,0.26339,0.10246,,,,
34.367,0.0778,0.03025,,,,
34.453,-0.00138,0.0091,,,,
34.554,0.01581,0.03457,,,,
34.754,0.20796,0.12135,,,,
34.954,0.39354,0.71487,,,,
35.154,0.57905,3.9059,,,,
35.349,0.75988,12.65674,,,,
35.492,0.89267,22.77799,,,,
35.531,0.92874,26.04101,,,,
35.632,0.91038,22.31582,,,,
35.738,0.80654,12.29925,,,,
35.924,0.63323,3.55493,,,,
36.124,0.4477,0.60126,,,,
36.324,0.26215,0.09911,,,,
36.524,0.07657,0.02877,,,,
36.609,-0.00175,0.01967,,,,
36.71,0.01541,0.02681,,,,
36.91,0.20771,0.11667,,,,
37.11,0.3933,0.69282,,,,
37.31,0.5788,3.83631,,,,
37.505,0.75961,12.53869,,,,
37.648,0.89238,22.63714,,,,
37.687,0.92849,25.91785,,,,
37.788,0.90993,22.18121,,,,
37.895,0.8053,12.12085,,,,
38.082,0.63105,3.45095,,,,
38.282,0.44551,0.57328,,,,
38.482,0.25997,0.10099,,,,
38.682,0.07437,0.02868,,,,
38.764,-0.00113,0.01766,,,,
38.865,0.0162,0.03628,,,,
39.065,0.20834,0.12223,,,,
39.265,0.39391,0.68352,,,,
39.465,0.57942,3.79764,,,,
39.661,0.76113,12.55405,,,,
39.803,0.89299,22.60049,,,,
39.842,0.92912,25.86983,,,,
39.943,0.91097,22.18175,,,,
40.05,0.80596,12.09483,,,,
40.237,0.63171,3.42741,,,,
40.437,0.44616,0.57128,,,,
40.637,0.26061,0.08932,,,,
40.837,0.07501,0.02687,,,,
40.92,-0.0014,0.0137,,,,
41.021,0.0159,0.03365,,,,
41.221,0.20805,0.11583,,,,
41.421,0.39364,0.66443,,,,
41.621,0.57914,3.75017,,,,
41.817,0.76085,12.44475,,,,
41.96,0.89362,22.55712,,,,
41.998,0.92881,25.73941,,,,
42.099,0.91063,22.0652,,,,
42.206,0.80567,12.00595,,,,
42.393,0.63144,3.38974,,,,
42.593,0.44588,0.54983,,,,
42.793,0.26034,0.08945,,,,
42.993,0.07473,0.02305,,,,
43.076,-0.00168,0.01625,,,,
43.177,0.01566,0.03776,,,,
43.377,0.20777,0.1163,,,,
43.577,0.39335,0.65178,,,,
43.777,0.57885,3.68743,,,,
43.973,0.76056,12.34956,,,,
44.116,0.89329,22.42757,,,,
44.154,0.92853,25.62355,,,,
44.255,0.91021,21.93703,,,,
44.364,0.80358,11.78231,,,,
44.553,0.62749,3.2376,,,,
44.753,0.4419,0.52564,,,,
44.953,0.25637,0.08769,,,,
45.153,0.0708,0.02361,,,,
45.231,-0.00104,0.00996,,,,
45.332,0.01619,0.03095,,,,
45.532,0.20836,0.11107,,,,
45.732,0.39396,0.63985,,,,
45.932,0.57939,3.66178,,,,
46.128,0.76117,12.30475,,,,
46.271,0.89392,22.40321,,,,
46.309,0.92913,25.59533,,,,
46.41,0.91118,21.95728,,,,
46.517,0.80614,11.89122,,,,
46.705,0.63096,3.28997,,,,
46.905,0.4454,0.54325,,,,
47.105,0.25986,0.09181,,,,
47.305,0.07425,0.03099,,,,
47.387,-0.00132,0.01673,,,,
47.488,0.01597,0.02674,,,,
47.688,0.20811,0.11703,,,,
47.888,0.39374,0.62477,,,,
48.088,0.57919,3.60656,,,,
48.284,0.76092,12.21896,,,,
48.427,0.8937,22.29647,,,,
48.465,0.92892,25.48299,,,,
48.566,0.91052,21.81224,,,,
48.675,0.80397,11.6818,,,,
48.864,0.62792,3.17155,,,,
49.064,0.44232,0.51202,,,,
49.264,0.25678,0.08506,,,,
49.464,0.07116,0.0289,,,,
49.543,-0.00162,0.01442,,,,
49.644,0.01559,0.03275,,,,
49.844,0.2078,0.10162,,,,
50.044,0.39341,0.61449,,,,
50.244,0.57887,3.56434,,,,
50.441,0.76155,12.18408,,,,
50.584,0.89431,22.26524,,,,
50.621,0.92859,25.36633,,,,
50.722,0.91059,21.75072,,,,
50.829,0.80558,11.72545,,,,
51.018,0.6295,3.19171,,,,
51.218,0.4439,0.51848,,,,
51.418,0.25836,0.08912,,,,
51.618,0.07276,0.02845,,,,
51.698,-0.00097,0.02634,,,,
51.799,0.01625,0.03296,,,,
51.999,0.20844,0.10569,,,,
52.199,0.39406,0.61146,,,,
52.399,0.57953,3.53794,,,,
52.596,0.76219,12.15675,,,,
52.739,0.89497,22.24614,,,,
52.776,0.92926,25.35659,,,,
52.877,0.911,21.70391,,,,
52.986,0.80432,11.57956,,,,
53.176,0.62734,3.10245,,,,
53.376,0.44173,0.49086,,,,
53.576,0.2562,0.08094,,,,
53.776,0.07061,0.01816,,,,
53.854,-0.00127,0.01848,,,,
53.955,0.01594,0.03241,,,,
54.155,0.20811,0.11103,,,,
54.355,0.39376,0.59734,,,,
54.555,0.5792,3.48767,,,,
54.752,0.76187,12.06797,,,,
54.895,0.89465,22.14194,,,,
54.932,0.92893,25.24066,,,,
55.033,0.91059,21.5943,,,,
55.142,0.804,11.49792,,,,
55.332,0.62703,3.05516,,,,
55.532,0.44142,0.48156,,,,
55.732,0.25588,0.08585,,,,
55.932,0.07025,0.02632,,,,
56.01,-0.00159,0.01585,,,,
56.111,0.01551,0.0363,,,,
56.311,0.20777,0.09838,,,,
56.511,0.39343,0.5844,,,,
56.711,0.57886,3.45238,,,,
56.908,0.76155,11.9988,,,,
57.052,0.89523,22.12417,,,,
57.088,0.9286,25.13682,,,,
57.189,0.91025,21.50283,,,,
57.298,0.8037,11.4255,,,,
57.489,0.62579,3.00192,,,,
57.689,0.44017,0.4691,,,,
57.889,0.25462,0.06992,,,,
58.089,0.06904,0.02805,,,,
58.165,-0.00099,0.0131,,,,
58.266,0.01624,0.02791,,,,
58.466,0.2084,0.10308,,,,
58.666,0.39404,0.58016,,,,
58.866,0.57949,3.43391,,,,
59.063,0.76217,11.97326,,,,
59.207,0.89587,22.10497,,,,
59.243,0.92922,25.12886,,,,
59.344,0.91081,21.47997,,,,
59.453,0.80429,11.41087,,,,
59.644,0.62636,2.99189,,,,
59.844,0.44081,0.46381,,,,
60.044,0.25522,0.07896,,,,
60.244,0.06967,0.02414,,,,
60.321,-0.0013,0.01613,,,,
60.422,0.01583,0.03761,,,,
60.622,0.20807,0.10267,,,,
60.822,0.3937,0.56992,,,,
61.022,0.57915,3.3977,,,,
61.22,0.76276,11.95336,,,,
61.364,0.89647,22.09232,,,,
61.399,0.92888,25.03333,,,,
61.5,0.91053,21.39436,,,,
61.609,0.80397,11.34642,,,,
61.8,0.62605,2.95828,,,,
62,0.44049,0.45033,,,,
62.2,0.2549,0.08025,,,,
62.4,0.06934,0.02488,,,,
62.477,-0.00161,0.00963,,,,
62.578,0.01558,0.03302,,,,
62.778,0.20775,0.10155,,,,
62.978,0.39337,0.56673,,,,
63.178,0.57884,3.35843,,,,
63.376,0.76245,11.88825,,,,
63.52,0.89616,21.99776,,,,
63.555,0.92859,24.93373,,,,
63.656,0.91021,21.30938,,,,
63.766,0.80269,11.20537,,,,
63.958,0.62384,2.87734,,,,
64.158,0.43828,0.44199,,,,
64.358,0.25272,0.07824,,,,
64.558,0.06719,0.01969,,,,
64.632,-0.00105,0.01122,,,,
64.733,0.01607,0.02771,,,,
64.933,0.20831,0.09639,,,,
65.133,0.39388,0.56026,,,,
65.333,0.5794,3.33991,,,,
65.531,0.76301,11.86752,,,,
65.675,0.89675,21.98844,,,,
65.71,0.92916,24.92143,,,,
65.811,0.91073,21.28329,,,,
65.921,0.80328,11.19032,,,,
66.113,0.6244,2.86975,,,,
66.313,0.43884,0.43681,,,,
66.513,0.25328,0.07285,,,,
66.713,0.06784,0.0209,,,,
66.788,-0.00139,0.00357,,,,
66.889,0.01563,0.03109,,,,
67.089,0.20792,0.09813,,,,
67.289,0.3935,0.54833,,,,
67.489,0.57899,3.29556,,,,
67.687,0.76261,11.78498,,,,
67.831,0.89635,21.88973,,,,
67.866,0.92878,24.82011,,,,
67.967,0.91044,21.19881,,,,
68.077,0.80287,11.12279,,,,
68.27,0.62307,2.80279,,,,
68.47,0.43751,0.42982,,,,
68.67,0.25198,0.06653,,,,
68.87,0.06649,0.02234,,,,
68.944,-0.00178,0.01433,,,,
69.045,0.0151,0.03454,,,,
69.245,0.20749,0.0998,,,,
69.445,0.39308,0.54281,,,,
69.645,0.57855,3.24891,,,,
69.843,0.76218,11.708,,,,
69.987,0.89594,21.78805,,,,
70.023,0.92927,24.79747,,,,
70.124,0.91082,21.17001,,,,
70.234,0.80335,11.10343,,,,
70.426,0.62448,2.81931,,,,
70.626,0.43892,0.42561,,,,
70.826,0.25338,0.07686,,,,
71.026,0.06791,0.01783,,,,
71.101,-0.00132,0.01383,,,,
71.202,0.01554,0.03057,,,,
71.402,0.20795,0.09427,,,,
71.602,0.39353,0.53925,,,,
71.802,0.57902,3.236,,,,
72,0.76265,11.67887,,,,
72.144,0.89643,21.77314,,,,
72.179,0.92881,24.69132,,,,
72.28,0.91054,21.09471,,,,
72.39,0.80293,11.03241,,,,
72.583,0.62316,2.76671,,,,
72.783,0.43755,0.42821,,,,
72.983,0.25204,0.06554,,,,
73.183,0.06659,0.01919,,,,
73.257,-0.00174,0.02222,,,,
73.358,0.01513,0.03069,,,,
73.558,0.20752,0.10364,,,,
73.758,0.3931,0.5226,,,,
73.958,0.57856,3.2037,,,,
74.157,0.76312,11.66078,,,,
74.301,0.89692,21.75444,,,,
74.336,0.9293,24.67596,,,,
74.437,0.91095,21.07226,,,,
74.547,0.80339,11.01412,,,,
74.74,0.62362,2.75606,,,,
74.94,0.43803,0.40709,,,,
75.14,0.25249,0.07406,,,,
75.34,0.06709,0.01033,,,,
75.414,-0.00126,0.01501,,,,
75.515,0.01566,0.02602,,,,
75.715,0.20801,0.09454,,,,
75.915,0.3936,0.52405,,,,
76.115,0.57906,3.19555,,,,
76.314,0.7636,11.64161,,,,
76.458,0.89741,21.74811,,,,
76.492,0.92887,24.57619,,,,
76.593,0.91049,20.97695,,,,
76.704,0.80205,10.88639,,,,
76.898,0.62136,2.67651,,,,
77.098,0.43577,0.40133,,,,
77.298,0.25024,0.06977,,,,
77.498,0.0648,0.02554,,,,
77.57,-0.00168,0.01444,,,,
77.671,0.01511,0.03624,,,,
77.871,0.20759,0.08907,,,,
78.071,0.39318,0.5167,,,,
78.271,0.57864,3.16283,,,,
78.47,0.76318,11.57304,,,,
78.614,0.89698,21.63907,,,,
78.648,0.92844,24.47796,,,,
78.749,0.91025,20.911,,,,
78.859,0.80258,10.87891,,,,
79.053,0.62185,2.67832,,,,
79.253,0.43628,0.40178,,,,
79.453,0.25074,0.07021,,,,
79.653,0.06534,0.02436,,,,
79.725,-0.00117,0.01486,,,,
79.826,0.01558,0.03489,,,,
80.026,0.2081,0.09206,,,,
80.226,0.39367,0.51625,,,,
80.426,0.57914,3.1511,,,,
80.625,0.76369,11.56723,,,,
80.769,0.89746,21.63381,,,,
80.803,0.92893,24.47611,,,,
80.904,0.91059,20.87965,,,,
81.016,0.8012,10.74893,,,,
81.211,0.61958,2.59695,,,,
81.411,0.43398,0.38651,,,,
81.611,0.24847,0.06925,,,,
81.811,0.06305,0.02619,,,,
81.881,-0.00159,0.01637,,,,
81.982,0.01528,0.028,,,,
82.182,0.2077,0.09449,,,,
82.382,0.39325,0.50569,,,,
82.582,0.57875,3.11594,,,,
82.781,0.76327,11.49422,,,,
82.925,0.89703,21.5398,,,,
82.959,0.92848,24.37065,,,,
83.06,0.91012,20.79603,,,,
83.172,0.80077,10.68389,,,,
83.367,0.61914,2.57938,,,,
83.567,0.43354,0.37753,,,,
83.767,0.24801,0.06184,,,,
83.967,0.06253,0.02719,,,,
84.036,-0.00114,0.01582,,,,
84.137,0.01561,0.03332,,,,
84.337,0.20815,0.09216,,,,
84.537,0.39365,0.50206,,,,
84.737,0.57919,3.09726,,,,
84.936,0.76372,11.48362,,,,
85.081,0.89841,21.62072,,,,
85.114,0.92895,24.37199,,,,
85.215,0.91064,20.7939,,,,
85.327,0.80121,10.66754,,,,
85.523,0.61868,2.54218,,,,
85.723,0.43305,0.36962,,,,
85.923,0.24755,0.06498,,,,
86.123,0.06216,0.01934,,,,
86.192,-0.00161,0.0103,,,,
86.293,0.01507,0.03757,,,,
86.493,0.20766,0.09362,,,,
86.693,0.39317,0.49763,,,,
86.893,0.57868,3.06401,,,,
87.093,0.76414,11.46529,,,,
87.237,0.89791,21.52386,,,,
87.271,0.92933,24.34939,,,,
87.372,0.91118,20.79324,,,,
87.484,0.80165,10.65057,,,,
87.68,0.619,2.53528,,,,
87.88,0.43353,0.37427,,,,
88.08,0.24803,0.06311,,,,
88.28,0.06257,0.02429,,,,
88.349,-0.00119,0.01852,,,,
88.45,0.01555,0.02065,,,,
88.65,0.20811,0.09885,,,,
88.85,0.39358,0.48846,,,,
89.05,0.57912,3.05684,,,,
89.25,0.76459,11.44728,,,,
89.394,0.89834,21.51205,,,,
89.427,0.92885,24.24923,,,,
89.528,0.91068,20.69963,,,,
89.64,0.80114,10.57914,,,,
89.837,0.61757,2.48796,,,,
90.037,0.43208,0.35572,,,,
90.237,0.2466,0.0651,,,,
90.437,0.06114,0.02175,,,,
90.505,-0.00172,0.01343,,,,
90.606,0.01494,0.02539,,,,
90.806,0.20756,0.09398,,,,
91.006,0.39307,0.48123,,,,
91.206,0.57859,3.02303,,,,
91.406,0.76404,11.37608,,,,
91.551,0.89874,21.49257,,,,
91.584,0.92924,24.23728,,,,
91.685,0.91108,20.68792,,,,
91.797,0.80156,10.57018,,,,
91.994,0.61804,2.4684,,,,
92.194,0.43253,0.36281,,,,
92.394,0.24702,0.05434,,,,
92.594,0.0616,0.02524,,,,
92.662,-0.00128,0.01222,,,,
92.763,0.01548,0.03558,,,,
92.963,0.20799,0.08809,,,,
93.163,0.39352,0.48048,,,,
93.363,0.57902,3.01027,,,,
93.563,0.76447,11.36965,,,,
93.708,0.89918,21.48914,,,,
93.74,0.92875,24.13979,,,,
93.841,0.91058,20.61069,,,,
93.953,0.80108,10.50922,,,,
94.15,0.61758,2.45125,,,,
94.35,0.43205,0.35467,,,,
94.55,0.24654,0.063,,,,
94.75,0.06112,0.02084,,,,
94.818,-0.00178,0.01429,,,,
94.919,0.01483,0.03048,,,,
95.119,0.20747,0.08942,,,,
95.319,0.39302,0.47319,,,,
95.519,0.5785,2.98253,,,,
95.719,0.76395,11.29144,,,,
95.864,0.89858,21.37819,,,,
95.897,0.92919,24.14056,,,,
95.998,0.91106,20.59189,,,,
96.11,0.80154,10.4981,,,,
96.307,0.6181,2.447,,,,
96.507,0.43251,0.34904,,,,
96.707,0.247,0.05534,,,,
96.907,0.06164,0.02046,,,,
96.975,-0.00132,0.01509,,,,
97.076,-0.01844,0.01753,,,,
97.276,0.06105,0.0298,,,,
97.476,0.13592,0.05268,,,,
97.676,0.2099,0.08653,,,,
97.876,0.28427,0.16485,,,,
98.076,0.35844,0.33143,,,,
98.184,0.3981,0.50131,,,,
98.186,0.39884,0.50519,,,,
98.206,0.40572,0.52837,,,,
98.226,0.40998,0.56134,,,,
98.246,0.41371,0.56992,,,,
98.266,0.41675,0.60509,,,,
98.286,0.4222,0.64397,,,,
98.306,0.43069,0.70686,,,,
98.326,0.44015,0.78179,,,,
98.346,0.44927,0.84843,,,,
98.366,0.45756,0.92205,,,,
98.386,0.46525,1.00331,,,,
98.406,0.47281,1.08193,,,,
98.426,0.48056,1.16764,,,,
98.446,0.4883,1.26153,,,,
98.466,0.49574,1.36006,,,,
98.486,0.50298,1.45841,,,,
98.506,0.51032,1.56985,,,,
98.526,0.51791,1.69097,,,,
98.546,0.52558,1.81888,,,,
98.566,0.53303,1.94751,,,,
98.586,0.54021,2.08607,,,,
98.606,0.54748,2.23663,,,,
98.626,0.55497,2.39855,,,,
98.646,0.56247,2.57263,,,,
98.666,0.56989,2.74469,,,,
98.686,0.57717,2.92594,,,,
98.706,0.58452,3.12966,,,,
98.726,0.59203,3.33981,,,,
98.746,0.59956,3.55365,,,,
98.766,0.60697,3.77965,,,,
98.786,0.61429,4.01866,,,,
98.806,0.62167,4.27768,,,,
98.826,0.62915,4.54057,,,,
98.846,0.63659,4.80756,,,,
98.866,0.64391,5.08055,,,,
98.886,0.65134,5.36719,,,,
98.906,0.65898,5.68171,,,,
98.926,0.66657,6.00846,,,,
98.946,0.67397,6.33203,,,,
98.966,0.68121,6.6573,,,,
98.986,0.68854,6.99746,,,,
99.006,0.69614,7.35987,,,,
99.026,0.70369,7.74223,,,,
99.046,0.71101,8.11657,,,,
99.066,0.71819,8.4907,,,,
99.086,0.72555,8.88195,,,,
99.106,0.73316,9.29776,,,,
99.126,0.74071,9.72169,,,,
99.146,0.74799,10.14904,,,,
99.166,0.75516,10.57323,,,,
99.186,0.76252,11.0158,,,,
99.206,0.77013,11.48011,,,,
99.226,0.7777,11.9426,,,,
99.246,0.78506,12.41043,,,,
99.266,0.79224,12.87756,,,,
99.286,0.79954,13.36359,,,,
99.306,0.80707,13.87834,,,,
99.326,0.81461,14.39081,,,,
99.346,0.82201,14.89889,,,,
99.366,0.82928,15.41616,,,,
99.386,0.83673,15.96366,,,,
99.406,0.84438,16.54587,,,,
99.426,0.85196,17.12357,,,,
99.446,0.85938,17.68743,,,,
99.466,0.86677,18.26474,,,,
99.486,0.87424,18.86515,,,,
99.506,0.88171,19.47822,,,,
99.526,0.88906,20.07836,,,,
99.546,0.89637,20.67607,,,,
99.566,0.90381,21.29319,,,,
99.586,0.91136,21.94558,,,,
99.606,0.91879,22.60314,,,,
99.626,0.92606,23.25119,,,,
99.646,0.93333,23.90004,,,,
99.666,0.94076,24.56727,,,,
99.686,0.94833,25.26636,,,,
99.706,0.95578,25.96175,,,,
99.726,0.96304,26.6444,,,,
99.746,0.97028,27.32245,,,,
99.766,0.97776,28.01926,,,,
99.786,0.98539,28.72114,,,,
99.806,0.99286,29.41028,,,,
99.826,1.00008,30.07841,,,,
99.846,1.0073,30.74637,,,,
99.866,1.01479,31.43055,,,,
99.886,1.02249,32.12148,,,,
99.906,1.0301,32.80863,,,,
99.926,1.03749,33.47054,,,,
99.946,1.0448,34.1405,,,,
99.966,1.05225,34.82092,,,,
99.986,1.05976,35.48382,,,,
100.006,1.06721,36.13133,,,,
100.026,1.07453,36.77448,,,,
100.046,1.0818,37.4186,,,,
100.066,1.08922,38.08096,,,,
100.086,1.09672,38.73765,,,,
100.106,1.10421,39.37363,,,,
100.126,1.1116,40.00034,,,,
100.146,1.11897,40.63935,,,,
100.166,1.12642,41.29262,,,,
100.186,1.13384,41.93114,,,,
100.206,1.14117,42.54185,,,,
100.226,1.14849,43.14098,,,,
100.246,1.15595,43.76544,,,,
100.266,1.16347,44.40882,,,,
100.286,1.17089,45.03804,,,,
100.306,1.17817,45.64554,,,,
100.326,1.18549,46.23682,,,,
100.346,1.19307,46.86404,,,,
100.366,1.20073,47.50395,,,,
100.386,1.20813,48.11863,,,,
100.406,1.21537,48.71748,,,,
100.426,1.2227,49.32717,,,,
100.446,1.23028,49.95203,,,,
100.466,1.23793,50.58022,,,,
100.486,1.24532,51.18483,,,,
100.506,1.2525,51.77359,,,,
100.526,1.25978,52.38877,,,,
100.546,1.26736,53.01801,,,,
100.566,1.27501,53.64244,,,,
100.586,1.28248,54.2451,,,,
100.606,1.28967,54.83509,,,,
100.626,1.29693,55.44857,,,,
100.646,1.30443,56.08986,,,,
100.666,1.31196,56.7137,,,,
100.686,1.31936,57.30037,,,,
100.706,1.32663,57.88668,,,,
100.726,1.33393,58.49911,,,,
100.746,1.34138,59.14243,,,,
100.766,1.34891,59.7719,,,,
100.786,1.35633,60.36746,,,,
100.806,1.36366,60.95503,,,,
100.826,1.37106,61.57259,,,,
100.846,1.37853,62.20942,,,,
100.866,1.38595,62.82605,,,,
100.886,1.39332,63.41652,,,,
100.906,1.40076,64.01703,,,,
100.926,1.4084,64.66163,,,,
100.946,1.41603,65.31307,,,,
100.966,1.42342,65.92419,,,,
100.986,1.43064,66.50579,,,,
101.006,1.43796,67.09525,,,,
101.026,1.44553,67.71698,,,,
101.046,1.45309,68.34737,,,,
101.066,1.46042,68.95805,,,,
101.086,1.46762,69.54547,,,,
101.106,1.47497,70.15285,,,,
101.126,1.48254,70.78658,,,,
101.146,1.49012,71.4137,,,,
101.166,1.49748,72.01135,,,,
101.186,1.50467,72.57555,,,,
101.206,1.51198,73.1694,,,,
101.226,1.51954,73.79909,,,,
101.246,1.52707,74.41538,,,,
101.266,1.53442,75.00652,,,,
101.286,1.5417,75.58905,,,,
101.306,1.54909,76.18824,,,,
101.326,1.55663,76.80701,,,,
101.346,1.56412,77.4045,,,,
101.366,1.57145,77.98476,,,,
101.386,1.57873,78.56131,,,,
101.406,1.58621,79.17552,,,,
101.426,1.59383,79.81045,,,,
101.446,1.60137,80.42538,,,,
101.466,1.60877,81.01113,,,,
101.486,1.61616,81.60779,,,,
101.506,1.62366,82.23963,,,,
101.526,1.63112,82.84222,,,,
101.546,1.63845,83.41685,,,,
101.566,1.64575,83.98058,,,,
101.586,1.65316,84.56886,,,,
101.606,1.66076,85.20192,,,,
101.626,1.66825,85.81628,,,,
101.646,1.67553,86.39037,,,,
101.666,1.68275,86.95753,,,,
101.686,1.69014,87.55478,,,,
101.706,1.69772,88.19032,,,,
101.726,1.70524,88.81377,,,,
101.746,1.71254,89.39404,,,,
101.766,1.71974,89.95099,,,,
101.786,1.72714,90.54421,,,,
101.806,1.73471,91.1637,,,,
101.826,1.74219,91.74944,,,,
101.846,1.7495,92.30695,,,,
101.866,1.75675,92.86096,,,,
101.886,1.76422,93.4478,,,,
101.906,1.77186,94.05968,,,,
101.926,1.77946,94.65269,,,,
101.946,1.78689,95.21221,,,,
101.966,1.79424,95.76142,,,,
101.986,1.80168,96.31848,,,,
102.006,1.80916,96.86751,,,,
102.026,1.81657,97.38973,,,,
102.046,1.8239,97.89613,,,,
102.066,1.83126,98.4127,,,,
102.086,1.83873,98.94845,,,,
102.106,1.84622,99.46288,,,,
102.126,1.85364,99.94638,,,,
102.146,1.86097,100.40102,,,,
102.166,1.86833,100.8651,,,,
102.186,1.87579,101.32989,,,,
102.203,1.88211,101.7054,,,,
102.205,1.88284,101.74736,,,,
102.356,1.85911,92.71465,,,,
102.479,1.81117,82.63388,,,,
102.623,1.75738,72.56693,,,,
102.785,1.69771,62.4966,,,,
102.965,1.63057,52.42431,,,,
103.163,1.55724,42.71067,,,,
103.363,1.48316,34.21171,,,,
103.563,1.40878,27.04453,,,,
103.763,1.33475,20.76295,,,,
103.963,1.26021,15.36414,,,,
104.163,1.18602,10.92782,,,,
104.363,1.11189,7.35406,,,,
104.563,1.03769,4.65381,,,,
104.763,0.96356,2.7412,,,,
104.963,0.88917,1.50741,,,,
105.163,0.81501,0.78496,,,,
105.363,0.74114,0.39822,,,,
105.563,0.66677,0.20463,,,,
105.763,0.59268,0.11315,,,,
105.963,0.51832,0.0721,,,,
106.163,0.44406,0.06022,,,,
106.287,0.39805,0.05047,,,,
106.289,0.39729,0.05051,,,,
106.489,0.43992,0.07848,,,,
106.689,0.5153,0.12226,,,,
106.889,0.58949,0.231,,,,
107.089,0.66402,0.48189,,,,
107.1,0.66816,0.50232,,,,
107.102,0.6689,0.50631,,,,
107.104,0.66965,0.51121,,,,
107.106,0.67041,0.52167,,,,
107.108,0.67121,0.54218,,,,
107.11,0.67213,0.57164,,,,
107.112,0.67325,0.60915,,,,
107.114,0.67467,0.65526,,,,
107.116,0.67653,0.70943,,,,
107.118,0.67895,0.77127,,,,
107.12,0.68207,0.84289,,,,
107.122,0.68602,0.92584,,,,
107.124,0.69095,1.02353,,,,
107.126,0.697,1.14103,,,,
107.128,0.7043,1.28388,,,,
107.13,0.71298,1.45872,,,,
107.132,0.72317,1.67632,,,,
107.134,0.73498,1.94975,,,,
107.136,0.74852,2.29454,,,,
107.138,0.7639,2.73026,,,,
107.14,0.78121,3.27789,,,,
107.142,0.80052,3.95918,,,,
107.144,0.82193,4.79831,,,,
107.146,0.8455,5.82103,,,,
107.148,0.87128,7.05304,,,,
107.15,0.89935,8.52231,,,,
107.152,0.92973,10.25695,,,,
107.154,0.96248,12.28557,,,,
107.156,0.99763,14.63653,,,,
107.158,1.0352,17.33914,,,,
107.16,1.07521,20.42426,,,,
107.162,1.11769,23.91883,,,,
107.164,1.16263,27.84226,,,,
107.166,1.21002,32.20963,,,,
107.168,1.25982,37.02693,,,,
107.17,1.31201,42.27194,,,,
107.172,1.36656,47.87783,,,,
107.174,1.42341,53.74897,,,,
107.176,1.48251,59.83078,,,,
107.178,1.54376,66.11145,,,,
107.18,1.60701,72.57972,,,,
107.182,1.67209,79.2168,,,,
107.184,1.73879,85.9943,,,,
107.186,1.8069,92.87407,,,,
107.188,1.87622,99.81935,,,,
107.19,1.94654,106.80505,,,,
107.192,2.01769,113.81251,,,,
107.194,2.08951,120.82233,,,,
107.196,2.16186,127.8162,,,,
107.198,2.23465,134.77818,,,,
107.2,2.30777,141.69226,,,,
107.202,2.38117,148.54277,,,,
107.204,2.45477,155.31702,,,,
107.206,2.52856,162.00134,,,,
107.208,2.6025,168.58215,,,,
107.21,2.67657,175.04829,,,,
107.212,2.75076,181.38824,,,,
107.214,2.82507,187.58812,,,,
107.216,2.89949,193.63394,,,,
107.218,2.97402,199.50871,,,,
107.22,3.04866,205.11108,,,,
107.222,3.1234,209.1331,,,,
107.224,3.19824,209.9512,,,,
107.226,3.27317,207.48341,,,,
107.228,3.34818,202.31851,,,,
107.23,3.42327,195.04672,,,,
107.232,3.49843,186.13884,,,,
107.234,3.57366,175.99474,,,,
107.236,3.64893,164.97177,,,,
107.238,3.72424,153.36978,,,,
107.24,3.79957,141.44576,,,,
107.242,3.87493,129.41754,,,,
107.244,3.95027,117.4716,,,,
107.246,4.02561,105.7624,,,,
107.248,4.10092,94.42307,,,,
107.25,4.1762,83.56286,,,,
107.252,4.25144,73.259,,,,
107.254,4.32664,63.56909,,,,
107.256,4.40178,54.53875,,,,
107.258,4.47687,46.19532,,,,
107.26,4.55191,38.5472,,,,
107.262,4.62688,31.58787,,,,
107.264,4.7018,25.30443,,,,
107.266,4.77666,19.67748,,,,
107.268,4.85146,14.68125,,,,
107.27,4.9262,10.28874,,,,
107.272,5.00088,6.46589,,,,
107.274,5.07552,3.17203,,,,
107.276,5.15011,0.36796,,,,
107.278,5.22465,-1.98333,,,,
107.28,5.29916,-3.91854,,,,
107.282,5.37363,-5.47575,,,,
107.284,5.44806,-6.69688,,,,
107.286,5.52247,-7.62347,,,,
107.288,5.59684,-8.29019,,,,
107.29,5.67119,-8.72759,,,,
107.292,5.74552,-8.96486,,,,
107.294,5.81984,-9.03214,,,,
107.296,5.89414,-8.95775,,,,
107.298,5.96843,-8.7658,,,,
107.3,6.04272,-8.4773,,,,
107.302,6.11701,-8.1098,,,,
107.304,6.19129,-7.68057,,,,
107.306,6.26557,-7.20841,,,,
107.308,6.33985,-6.70979,,,,
107.31,6.41412,-6.19454,,,,
107.312,6.4884,-5.66959,,,,
107.314,6.56268,-5.14656,,,,
107.316,6.63696,-4.63541,,,,
107.318,6.71125,-4.14074,,,,
107.32,6.78554,-3.66612,,,,
107.322,6.85984,-3.21667,,,,
107.324,6.93415,-2.7946,,,,
107.326,7.00846,-2.39853,,,,
107.328,7.08278,-2.02947,,,,
107.33,7.15711,-1.69193,,,,
107.332,7.23143,-1.38784,,,,
107.334,7.30577,-1.11259,,,,
107.336,7.3801,-0.86152,,,,
107.338,7.45445,-0.63616,,,,
107.34,7.52879,-0.44001,,,,
107.342,7.60314,-0.27127,,,,
107.344,7.67748,-0.12642,,,,
107.346,7.75183,-0.00045,,,,
107.348,7.82617,0.10773,,,,
107.35,7.90051,0.19727,,,,
107.352,7.97484,0.26821,,,,
107.354,8.04917,0.32263,,,,
107.356,8.12349,0.36389,,,,
107.358,8.19781,0.39522,,,,
107.36,8.27212,0.41766,,,,
107.362,8.34642,0.4308,,,,
107.364,8.42072,0.43455,,,,
107.366,8.49501,0.43169,,,,
107.368,8.56929,0.42635,,,,
107.37,8.64357,0.42004,,,,
107.372,8.71784,0.40953,,,,
107.374,8.7921,0.39445,,,,
107.376,8.86635,0.37701,,,,
107.378,8.9406,0.35913,,,,
107.38,9.01483,0.34182,,,,
107.382,9.08906,0.32445,,,,
107.384,9.16329,0.3038,,,,
107.386,9.2375,0.27831,,,,
107.388,9.31171,0.25218,,,,
107.39,9.38591,0.22942,,,,
107.392,9.46011,0.20958,,,,
107.394,9.5343,0.19104,,,,
107.396,9.60849,0.17154,,,,
107.398,9.68268,0.15228,,,,
107.4,9.75687,0.13582,,,,
107.402,9.83107,0.12321,,,,
107.404,9.90526,0.11217,,,,
107.406,9.97945,0.09983,,,,
107.408,10.05365,0.08741,,,,
107.41,10.12784,0.07752,,,,
107.412,10.20203,0.07,,,,
107.414,10.27623,0.06353,,,,
107.416,10.35042,0.05651,,,,
107.418,10.42461,0.04945,,,,
107.42,10.49881,0.04276,,,,
107.422,10.573,0.03672,,,,
107.424,10.64719,0.03274,,,,
107.426,10.72139,0.03006,,,,
107.428,10.79557,0.02608,,,,
107.43,10.86976,0.01933,,,,
107.432,10.94395,0.01248,,,,
107.434,11.01813,0.01029,,,,
107.436,11.09232,0.01203,,,,
107.438,11.16651,0.01336,,,,
107.44,11.2407,0.01341,,,,
107.442,11.31489,0.01441,,,,
107.444,11.38908,0.01747,,,,
107.446,11.46328,0.02257,,,,
107.448,11.53747,0.02743,,,,
107.45,11.61166,0.02952,,,,
107.452,11.68585,0.02806,,,,
107.454,11.76004,0.02722,,,,
107.456,11.83422,0.03032,,,,
107.458,11.90841,0.03302,,,,
107.46,11.9826,0.03233,,,,
107.462,12.05679,0.03102,,,,
107.464,12.13099,0.03424,,,,
107.466,12.20518,0.03921,,,,
107.468,12.27938,0.04194,,,,
107.47,12.35358,0.04415,,,,
107.472,12.42777,0.04659,,,,
107.474,12.50197,0.0477,,,,
107.476,12.57617,0.04748,,,,
107.478,12.65037,0.04888,,,,
107.48,12.72457,0.05209,,,,
107.482,12.79877,0.05362,,,,
107.484,12.87297,0.05318,,,,
107.486,12.94718,0.052,,,,
107.488,13.02138,0.05084,,,,
107.49,13.09558,0.0497,,,,
107.492,13.16979,0.0485,,,,
107.494,13.24399,0.04649,,,,
107.496,13.31819,0.0439,,,,
107.498,13.3924,0.04148,,,,
107.5,13.46661,0.03941,,,,
107.502,13.54082,0.03769,,,,
107.504,13.61503,0.03594,,,,
107.506,13.68925,0.0347,,,,
107.508,13.76346,0.03348,,,,
107.51,13.83768,0.03298,,,,
107.512,13.91189,0.03397,,,,
107.514,13.9861,0.03498,,,,
107.516,14.06031,0.03565,,,,
107.518,14.13452,0.03714,,,,
107.52,14.20873,0.03718,,,,
107.522,14.28293,0.03427,,,,
107.524,14.35713,0.03203,,,,
107.526,14.43133,0.0326,,,,
107.528,14.50553,0.03193,,,,
107.53,14.57973,0.02938,,,,
107.532,14.65392,0.02877,,,,
107.534,14.72812,0.0312,,,,
107.536,14.80232,0.03377,,,,
107.538,14.87652,0.03335,,,,
107.54,14.95072,0.03099,,,,
107.542,15.02492,0.03033,,,,
107.544,15.09913,0.03314,,,,
107.546,15.17334,0.0363,,,,
107.548,15.24754,0.03706,,,,
107.55,15.32175,0.03554,,,,
107.552,15.39594,0.03389,,,,
107.554,15.47014,0.0342,,,,
107.556,15.54433,0.0356,,,,
107.558,15.61852,0.03609,,,,
107.56,15.69271,0.03501,,,,
107.562,15.76688,0.0339,,,,
107.564,15.84106,0.03393,,,,
107.566,15.91524,0.03531,,,,
107.568,15.9894,0.03628,,,,
107.57,16.06357,0.03598,,,,
107.572,16.13773,0.03433,,,,
107.574,16.21189,0.03311,,,,
107.576,16.28606,0.03461,,,,
107.578,16.36022,0.0367,,,,
107.58,16.43439,0.03653,,,,
107.582,16.50856,0.03618,,,,
107.584,16.58273,0.03643,,,,
107.586,16.65691,0.03699,,,,
107.588,16.73109,0.03747,,,,
107.59,16.80527,0.03775,,,,
107.592,16.87945,0.03606,,,,
107.594,16.95364,0.03327,,,,
107.596,17.02783,0.03161,,,,
107.598,17.10203,0.03115,,,,
107.6,17.17624,0.03109,,,,
107.602,17.25045,0.03082,,,,
107.604,17.32467,0.02892,,,,
107.606,17.39889,0.02789,,,,
107.608,17.47312,0.02932,,,,
107.61,17.54735,0.03096,,,,
107.612,17.62158,0.03108,,,,
107.614,17.69582,0.03055,,,,
107.616,17.77005,0.03119,,,,
107.618,17.84429,0.03236,,,,
107.62,17.91854,0.0317,,,,
107.622,17.99277,0.03098,,,,
107.624,18.06702,0.03209,,,,
107.626,18.14126,0.03444,,,,
107.628,18.2155,0.03632,,,,
107.63,18.28974,0.03746,,,,
107.632,18.36398,0.03887,,,,
107.634,18.43821,0.03985,,,,
107.636,18.51244,0.03861,,,,
107.638,18.58666,0.03571,,,,
107.64,18.66089,0.03448,,,,
107.642,18.73512,0.03617,,,,
107.644,18.80935,0.03876,,,,
107.646,18.88358,0.03967,,,,
107.648,18.9578,0.03916,,,,
107.65,19.03202,0.0383,,,,
107.652,19.10623,0.03762,,,,
107.654,19.18044,0.03844,,,,
107.656,19.25464,0.03943,,,,