File: data/instron/Sample21_Dynamic.is_tcyclic_RawData/Specimen_RawData_1.csv
Strain : Tensile strain (Extension) gauge length,100,mm,,,,
,,,,,,
Time,Extension,Load,,,,
(s),(mm),(N),Low Start,Low End,High Start,High End
0,0,0.22325,1189,1580,1648,1738
0.2,0.14932,0.79376,,,,
0.4,0.33745,2.09747,,,,
0.6,0.52485,4.20079,,,,
0.8,0.71213,7.36267,,,,
1,0.89956,12.05463,,,,
1.041,0.93811,13.2407,,,,
1.142,0.91879,10.69286,,,,
1.342,0.7256,3.88551,,,,
1.542,0.53806,1.31795,,,,
1.742,0.35063,0.39013,,,,
1.942,0.16312,0.09929,,,,
2.117,-0.00055,0.044,,,,
2.119,-0.00244,0.04382,,,,
2.319,0.1167,0.1396,,,,
2.519,0.30512,0.57494,,,,
2.719,0.49249,1.82542,,,,
2.919,0.67985,4.52525,,,,
3.119,0.8672,9.53063,,,,
3.195,0.93882,12.17665,,,,
3.296,0.91944,10.04545,,,,
3.496,0.72633,3.49665,,,,
3.696,0.53877,1.12485,,,,
3.896,0.35137,0.31057,,,,
4.096,0.16385,0.0924,,,,
4.272,-0.0008,0.03244,,,,
4.274,-0.00268,0.03223,,,,
4.474,0.11642,0.11013,,,,
4.674,0.30483,0.44963,,,,
4.874,0.4922,1.5428,,,,
5.074,0.67955,4.06048,,,,
5.274,0.8669,8.98084,,,,
5.35,0.93853,11.67563,,,,
5.451,0.91925,9.67791,,,,
5.651,0.72607,3.28139,,,,
5.851,0.53851,1.02177,,,,
6.051,0.35109,0.27908,,,,
6.251,0.1636,0.0717,,,,
6.426,-0.00011,0.02868,,,,
6.428,-0.002,0.02859,,,,
6.628,0.11703,0.10168,,,,
6.828,0.30543,0.39333,,,,
7.028,0.4928,1.40479,,,,
7.228,0.68014,3.81998,,,,
7.428,0.86752,8.68597,,,,
7.503,0.93822,11.36583,,,,
7.604,0.91891,9.43519,,,,
7.804,0.72576,3.14496,,,,
8.004,0.5382,0.96474,,,,
8.204,0.35081,0.24727,,,,
8.404,0.16329,0.07462,,,,
8.579,-0.00041,0.03514,,,,
8.581,-0.0023,0.03466,,,,
8.781,0.11662,0.09325,,,,
8.981,0.30502,0.36387,,,,
9.181,0.49244,1.30511,,,,
9.381,0.67975,3.63596,,,,
9.581,0.8671,8.43896,,,,
9.657,0.93876,11.16721,,,,
9.758,0.91964,9.29809,,,,
9.958,0.72638,3.04448,,,,
10.158,0.53881,0.91225,,,,
10.358,0.35144,0.23108,,,,
10.558,0.1639,0.06553,,,,
10.734,-0.00074,0.03073,,,,
10.736,-0.00263,0.03003,,,,
10.936,0.11621,0.08584,,,,
11.136,0.30465,0.32992,,,,
11.336,0.49207,1.22662,,,,
11.536,0.67939,3.50747,,,,
11.736,0.86672,8.25484,,,,
11.812,0.9384,10.97854,,,,
11.913,0.91926,9.13511,,,,
12.113,0.72601,2.96095,,,,
12.313,0.53845,0.8734,,,,
12.513,0.35105,0.21189,,,,
12.713,0.16352,0.06818,,,,
12.888,-0.00018,0.02888,,,,
12.89,-0.00207,0.02864,,,,
13.09,0.11679,0.09093,,,,
13.29,0.30521,0.31115,,,,
13.49,0.49262,1.17302,,,,
13.69,0.67995,3.41062,,,,
13.89,0.86729,8.13778,,,,
13.965,0.93801,10.82946,,,,
14.066,0.91889,9.00177,,,,
14.266,0.72564,2.88578,,,,
14.466,0.53809,0.83254,,,,
14.666,0.35068,0.2108,,,,
14.866,0.16317,0.06009,,,,
15.041,-0.00051,0.02865,,,,
15.043,-0.0024,0.02871,,,,
15.243,0.11639,0.08137,,,,
15.443,0.30481,0.29998,,,,
15.643,0.49223,1.12509,,,,
15.843,0.67955,3.31544,,,,
16.043,0.86688,8.00599,,,,
16.119,0.93853,10.72367,,,,
16.22,0.91948,8.92486,,,,
16.42,0.72621,2.83345,,,,
16.62,0.53865,0.80827,,,,
16.82,0.35122,0.20197,,,,
17.02,0.1637,0.06074,,,,
17.196,-0.00091,0.02633,,,,
17.198,-0.0028,0.02498,,,,
17.398,0.11594,0.07958,,,,
17.598,0.30434,0.28168,,,,
17.798,0.49176,1.08851,,,,
17.998,0.67909,3.23833,,,,
18.198,0.86642,7.89654,,,,
18.274,0.93808,10.60955,,,,
18.375,0.91898,8.82351,,,,
18.575,0.72575,2.7834,,,,
18.775,0.53818,0.79281,,,,
18.975,0.35079,0.19112,,,,
19.175,0.16326,0.0577,,,,
19.35,-0.00043,0.01585,,,,
19.352,-0.00231,0.01489,,,,
19.552,0.11641,0.06976,,,,
19.752,0.30481,0.26906,,,,
19.952,0.49223,1.04946,,,,
20.152,0.67957,3.18251,,,,
20.352,0.86689,7.82608,,,,
20.428,0.93855,10.53381,,,,
20.529,0.91942,8.76002,,,,
20.729,0.72622,2.74078,,,,
20.929,0.53866,0.77337,,,,
21.129,0.35124,0.18095,,,,
21.329,0.16371,0.05959,,,,
21.505,-0.0009,0.02538,,,,
21.507,-0.00279,0.02495,,,,
21.707,0.11595,0.06568,,,,
21.907,0.3043,0.26171,,,,
22.107,0.49175,1.02477,,,,
22.307,0.6791,3.12078,,,,
22.507,0.86642,7.72734,,,,
22.583,0.93808,10.43562,,,,
22.684,0.91903,8.67778,,,,
22.884,0.72573,2.69262,,,,
23.084,0.5382,0.74488,,,,
23.284,0.35079,0.18109,,,,
23.484,0.16324,0.05391,,,,
23.659,-0.00042,0.02067,,,,
23.661,-0.00231,0.02118,,,,
23.861,0.11643,0.06969,,,,
24.061,0.30474,0.2454,,,,
24.261,0.49221,0.99588,,,,
24.461,0.67954,3.07577,,,,
24.661,0.86687,7.67542,,,,
24.737,0.93853,10.38501,,,,
24.838,0.91946,8.62881,,,,
25.038,0.72621,2.66691,,,,
25.238,0.53868,0.73539,,,,
25.438,0.35126,0.18062,,,,
25.638,0.16376,0.0569,,,,
25.814,-0.00089,0.02165,,,,
25.816,-0.00278,0.0219,,,,
26.016,0.11593,0.07678,,,,
26.216,0.30425,0.24,,,,
26.416,0.49169,0.97104,,,,
26.616,0.67904,3.03123,,,,
26.816,0.86636,7.58879,,,,
26.892,0.93803,10.29473,,,,
26.993,0.91902,8.56028,,,,
27.193,0.72574,2.62587,,,,
27.393,0.53822,0.71775,,,,
27.593,0.35077,0.17265,,,,
27.793,0.16332,0.04789,,,,
27.968,-0.00041,0.02111,,,,
27.97,-0.0023,0.02056,,,,
28.17,0.11639,0.066,,,,
28.37,0.3047,0.22941,,,,
28.57,0.49213,0.9477,,,,
28.77,0.67948,2.98767,,,,
28.97,0.86682,7.55306,,,,
29.046,0.93847,10.25268,,,,
29.147,0.91952,8.51672,,,,
29.347,0.72621,2.60256,,,,
29.547,0.53868,0.71009,,,,
29.747,0.35124,0.16634,,,,
29.947,0.16378,0.05615,,,,
30.123,-0.00088,0.01885,,,,
30.125,-0.00277,0.01802,,,,
30.325,0.1159,0.06931,,,,
30.525,0.30423,0.23389,,,,
30.725,0.49164,0.93278,,,,
30.925,0.67897,2.93716,,,,
31.125,0.86631,7.47524,,,,
31.202,0.93886,10.20553,,,,
31.303,0.92007,8.49154,,,,
31.503,0.72667,2.57983,,,,
31.703,0.53914,0.69619,,,,
31.903,0.35171,0.16012,,,,
32.103,0.16424,0.05496,,,,
32.279,-0.00041,0.0249,,,,
32.281,-0.0023,0.02481,,,,
32.481,0.11637,0.06618,,,,
32.681,0.30469,0.22783,,,,
32.881,0.49211,0.91325,,,,
33.081,0.67945,2.90787,,,,
33.281,0.86679,7.42987,,,,
33.357,0.93837,10.12427,,,,
33.458,0.91939,8.42274,,,,
33.658,0.72617,2.54279,,,,
33.858,0.53865,0.68341,,,,
34.058,0.3512,0.1566,,,,
34.258,0.16377,0.05318,,,,
34.434,-0.00092,0.01978,,,,
34.436,-0.0028,0.01987,,,,
34.636,0.11581,0.06525,,,,
34.836,0.30414,0.21794,,,,
35.036,0.49156,0.89403,,,,
35.236,0.67891,2.86839,,,,
35.436,0.86628,7.37041,,,,
35.513,0.93872,10.08804,,,,
35.614,0.92004,8.38675,,,,
35.814,0.72663,2.517,,,,
36.014,0.53911,0.67053,,,,
36.214,0.35165,0.15536,,,,
36.414,0.16421,0.05061,,,,
36.59,-0.00046,0.02235,,,,
36.592,-0.00234,0.02149,,,,
36.792,0.11631,0.05599,,,,
36.992,0.30462,0.21598,,,,
37.192,0.49202,0.87546,,,,
37.392,0.67938,2.83581,,,,
37.592,0.86676,7.33118,,,,
37.668,0.93833,10.01637,,,,
37.769,0.91951,8.32839,,,,
37.969,0.72619,2.48424,,,,
38.169,0.53868,0.65489,,,,
38.369,0.35124,0.15118,,,,
38.569,0.16379,0.04705,,,,
38.745,-0.0009,0.02516,,,,
38.747,-0.00279,0.02495,,,,
38.947,0.1159,0.06214,,,,
39.147,0.30422,0.22004,,,,
39.347,0.4916,0.85835,,,,
39.547,0.67896,2.801,,,,
39.747,0.86631,7.2703,,,,
39.823,0.93796,9.9539,,,,
39.924,0.9191,8.26869,,,,
40.124,0.72573,2.45227,,,,
40.324,0.5382,0.64435,,,,
40.524,0.35076,0.15039,,,,
40.724,0.16333,0.04351,,,,
40.899,-0.00043,0.02278,,,,
40.901,-0.00232,0.02368,,,,
41.101,0.11637,0.06985,,,,
41.301,0.30469,0.20541,,,,
41.501,0.49207,0.84911,,,,
41.701,0.67943,2.78351,,,,
41.901,0.86676,7.2427,,,,
41.977,0.93844,9.93521,,,,
42.078,0.91956,8.24021,,,,
42.278,0.72619,2.43657,,,,
42.478,0.53867,0.63657,,,,
42.678,0.35123,0.14738,,,,
42.878,0.16379,0.05062,,,,
43.054,-0.00093,0.01445,,,,
43.056,-0.00281,0.01408,,,,
43.256,0.11584,0.0553,,,,
43.456,0.30415,0.19642,,,,
43.656,0.49155,0.82784,,,,
43.856,0.67891,2.74474,,,,
44.056,0.86626,7.18619,,,,
44.133,0.93885,9.90593,,,,
44.234,0.91997,8.22658,,,,
44.434,0.7266,2.42534,,,,
44.634,0.53907,0.6304,,,,
44.834,0.35164,0.14072,,,,
45.034,0.16419,0.04465,,,,
45.21,-0.00054,0.0177,,,,
45.212,-0.00242,0.01819,,,,
45.412,0.11627,0.0597,,,,
45.612,0.30458,0.19576,,,,
45.812,0.49198,0.82392,,,,
46.012,0.67935,2.72297,,,,
46.212,0.86671,7.16516,,,,
46.288,0.93832,9.84701,,,,
46.389,0.91952,8.17259,,,,
46.589,0.7261,2.39262,,,,
46.789,0.53857,0.62533,,,,
46.989,0.35115,0.14577,,,,
47.189,0.16367,0.0447,,,,
47.364,-0.0001,0.01472,,,,
47.366,-0.00198,0.01467,,,,
47.566,0.11671,0.06172,,,,
47.766,0.305,0.19712,,,,
47.966,0.4924,0.81286,,,,
48.166,0.67977,2.69816,,,,
48.366,0.86714,7.14891,,,,
48.442,0.93876,9.83419,,,,
48.543,0.92004,8.15404,,,,
48.743,0.72656,2.38009,,,,
48.943,0.53904,0.61141,,,,
49.143,0.35157,0.14507,,,,
49.343,0.16413,0.04499,,,,
49.519,-0.00057,0.01753,,,,
49.521,-0.00245,0.0169,,,,
49.721,0.1162,0.05751,,,,
49.921,0.30451,0.18842,,,,
50.121,0.49191,0.80065,,,,
50.321,0.67928,2.6805,,,,
50.521,0.86662,7.09754,,,,
50.597,0.93825,9.77299,,,,
50.698,0.91936,8.09805,,,,
50.898,0.72602,2.35481,,,,
51.098,0.53841,0.60676,,,,
51.298,0.35105,0.14096,,,,
51.498,0.16358,0.04331,,,,
51.673,-0.00011,0.02494,,,,
51.675,-0.002,0.02439,,,,
51.875,0.11666,0.06384,,,,
52.075,0.30498,0.1886,,,,
52.275,0.49236,0.79864,,,,
52.475,0.67973,2.65773,,,,
52.675,0.86708,7.08339,,,,
52.751,0.93868,9.7611,,,,
52.852,0.91985,8.08907,,,,
53.052,0.72648,2.34092,,,,
53.252,0.53894,0.59587,,,,
53.452,0.35153,0.13425,,,,
53.652,0.16406,0.04897,,,,
53.828,-0.00059,0.02116,,,,
53.83,-0.00248,0.02085,,,,
54.03,0.11612,0.06018,,,,
54.23,0.30444,0.18492,,,,
54.43,0.49185,0.78002,,,,
54.63,0.6792,2.63348,,,,
54.83,0.86656,7.02357,,,,
54.906,0.93818,9.71565,,,,
55.007,0.91932,8.03814,,,,
55.207,0.72595,2.32165,,,,
55.407,0.53847,0.58917,,,,
55.607,0.35098,0.13928,,,,
55.807,0.16351,0.04944,,,,
55.982,-0.00019,0.01542,,,,
55.984,-0.00207,0.0152,,,,
56.184,0.11656,0.05732,,,,
56.384,0.30487,0.18782,,,,
56.584,0.49229,0.77623,,,,
56.784,0.67962,2.62328,,,,
56.984,0.86699,7.01968,,,,
57.06,0.9386,9.69016,,,,
57.161,0.91972,8.02988,,,,
57.361,0.72638,2.31561,,,,
57.561,0.53892,0.58036,,,,
57.761,0.35143,0.1398,,,,
57.961,0.16397,0.04012,,,,
58.137,-0.00069,0.0174,,,,
58.139,-0.00258,0.01702,,,,
58.339,0.11603,0.06246,,,,
58.539,0.30435,0.18313,,,,
58.739,0.49177,0.76216,,,,
58.939,0.6791,2.59283,,,,
59.139,0.86646,6.97403,,,,
59.215,0.9381,9.64629,,,,
59.316,0.91939,7.98743,,,,
59.516,0.7259,2.28876,,,,
59.716,0.53845,0.57657,,,,
59.916,0.35096,0.13429,,,,
60.116,0.16346,0.04232,,,,
60.291,-0.00024,0.01355,,,,
60.293,-0.00212,0.01369,,,,
60.493,0.11646,0.05743,,,,
60.693,0.30477,0.16895,,,,
60.893,0.49221,0.7536,,,,
61.093,0.67954,2.57597,,,,
61.293,0.86692,6.96086,,,,
61.369,0.93854,9.63655,,,,
61.47,0.91958,7.96554,,,,
61.67,0.72629,2.28634,,,,
61.87,0.53886,0.57327,,,,
62.07,0.35135,0.13422,,,,
62.27,0.16386,0.04109,,,,
62.446,-0.00079,0.01823,,,,
62.448,-0.00268,0.01825,,,,
62.648,0.11591,0.05452,,,,
62.848,0.30423,0.17743,,,,
63.048,0.49167,0.74599,,,,
63.248,0.67899,2.55191,,,,
63.448,0.86637,6.91091,,,,
63.524,0.938,9.58171,,,,
63.625,0.91934,7.937,,,,
63.825,0.7258,2.26019,,,,
64.025,0.53835,0.56206,,,,
64.225,0.35082,0.12269,,,,
64.425,0.16335,0.03973,,,,
64.6,-0.00036,0.01866,,,,
64.602,-0.00225,0.01846,,,,
64.802,0.11635,0.05663,,,,
65.002,0.30466,0.17871,,,,
65.202,0.49212,0.7377,,,,
65.402,0.67944,2.54336,,,,
65.602,0.86682,6.91074,,,,
65.678,0.93844,9.5721,,,,
65.779,0.91953,7.92347,,,,
65.979,0.72619,2.25052,,,,
66.179,0.53876,0.55653,,,,
66.379,0.35124,0.1301,,,,
66.579,0.16378,0.03982,,,,
66.755,-0.00089,0.01148,,,,
66.757,-0.00278,0.01143,,,,
66.957,0.1158,0.05074,,,,
67.157,0.30413,0.1708,,,,
67.357,0.49155,0.72558,,,,
67.557,0.67889,2.52086,,,,
67.757,0.86625,6.85885,,,,
67.834,0.93882,9.56207,,,,
67.935,0.92016,7.92842,,,,
68.135,0.72663,2.2508,,,,
68.335,0.53917,0.56159,,,,
68.535,0.35165,0.13031,,,,
68.735,0.16419,0.04522,,,,
68.911,-0.00047,0.00995,,,,
68.913,-0.00236,0.01023,,,,
69.113,0.11624,0.05764,,,,
69.313,0.30456,0.17463,,,,
69.513,0.49199,0.71979,,,,
69.713,0.67935,2.50591,,,,
69.913,0.86667,6.84903,,,,
69.989,0.93832,9.51464,,,,
70.09,0.91959,7.88479,,,,
70.29,0.72614,2.22985,,,,
70.49,0.53866,0.55228,,,,
70.69,0.35114,0.12945,,,,
70.89,0.16368,0.04294,,,,
71.065,0,0.01562,,,,
71.067,-0.00189,0.01578,,,,
71.267,0.11662,0.05761,,,,
71.467,0.30498,0.16895,,,,
71.667,0.49239,0.72209,,,,
71.867,0.67978,2.49505,,,,
72.067,0.8671,6.8445,,,,
72.143,0.93873,9.51512,,,,
72.244,0.92006,7.88429,,,,
72.444,0.72655,2.22485,,,,
72.644,0.53905,0.54659,,,,
72.844,0.35154,0.12569,,,,
73.044,0.16413,0.04438,,,,
73.22,-0.00054,0.01181,,,,
73.222,-0.00243,0.01159,,,,
73.422,0.11606,0.05192,,,,
73.622,0.30443,0.16154,,,,
73.822,0.49182,0.70663,,,,
74.022,0.67919,2.48773,,,,
74.222,0.86653,6.79767,,,,
74.298,0.93817,9.46621,,,,
74.399,0.91955,7.8371,,,,
74.599,0.72599,2.20809,,,,
74.799,0.53847,0.53671,,,,
74.999,0.35096,0.12539,,,,
75.199,0.16359,0.04542,,,,
75.374,-0.00016,0.01056,,,,
75.376,-0.00205,0.01024,,,,
75.576,0.11644,0.05103,,,,
75.776,0.30481,0.16243,,,,
75.976,0.49219,0.70086,,,,
76.176,0.67957,2.47354,,,,
76.376,0.86691,6.79311,,,,
76.452,0.93855,9.46454,,,,
76.553,0.91988,7.83936,,,,
76.753,0.72638,2.19684,,,,
76.953,0.53883,0.5393,,,,
77.153,0.35132,0.12033,,,,
77.353,0.16397,0.0419,,,,
77.529,-0.00071,0.01903,,,,
77.531,-0.0026,0.01941,,,,
77.731,0.11589,0.05365,,,,
77.931,0.30425,0.17058,,,,
78.131,0.49164,0.69895,,,,
78.331,0.67902,2.44241,,,,
78.531,0.86636,6.75838,,,,
78.607,0.93798,9.41456,,,,
78.708,0.91929,7.79442,,,,
78.908,0.72581,2.17833,,,,
79.108,0.53827,0.52766,,,,
79.308,0.35075,0.12124,,,,
79.508,0.1634,0.03412,,,,
79.683,-0.00034,0.02158,,,,
79.685,-0.00223,0.02136,,,,
79.885,0.11627,0.04824,,,,
80.085,0.30463,0.16467,,,,
80.285,0.49202,0.68633,,,,
80.485,0.6794,2.43821,,,,
80.685,0.86672,6.74466,,,,
80.761,0.93834,9.41523,,,,
80.862,0.91947,7.78518,,,,
81.062,0.72618,2.17872,,,,
81.262,0.53865,0.52096,,,,
81.462,0.35112,0.12375,,,,
81.662,0.16376,0.03942,,,,
81.838,-0.00093,0.00703,,,,
81.84,-0.00282,0.00778,,,,
82.04,0.1157,0.05341,,,,
82.24,0.30405,0.15793,,,,
82.44,0.49144,0.67931,,,,
82.64,0.67883,2.41799,,,,
82.84,0.86616,6.71011,,,,
82.917,0.93869,9.40254,,,,
83.018,0.91997,7.77795,,,,
83.218,0.72657,2.16707,,,,
83.418,0.53905,0.51876,,,,
83.618,0.35157,0.11506,,,,
83.818,0.16416,0.03323,,,,
83.994,-0.00053,0.01346,,,,
83.996,-0.00242,0.01333,,,,
84.196,0.1161,0.05025,,,,
84.396,0.30445,0.15316,,,,
84.596,0.49183,0.67586,,,,
84.796,0.67923,2.41046,,,,
84.996,0.86656,6.6986,,,,
85.072,0.93818,9.36824,,,,
85.173,0.9197,7.75547,,,,
85.373,0.72607,2.14332,,,,
85.573,0.53851,0.52348,,,,
85.773,0.3511,0.11717,,,,
85.973,0.16367,0.03703,,,,
86.148,-0.00011,0.0161,,,,
86.15,-0.00199,0.01606,,,,
86.35,0.11654,0.05365,,,,
86.55,0.3049,0.15559,,,,
86.75,0.49226,0.67285,,,,
86.95,0.67965,2.40542,,,,
87.15,0.86699,6.68963,,,,
87.226,0.93861,9.36444,,,,
87.327,0.91976,7.73987,,,,
87.527,0.72645,2.14115,,,,
87.727,0.53892,0.51451,,,,
87.927,0.35153,0.11192,,,,
88.127,0.16404,0.04445,,,,
88.303,-0.00066,0.01018,,,,
88.305,-0.00255,0.0102,,,,
88.505,0.11598,0.05341,,,,
88.705,0.30432,0.15055,,,,
88.905,0.49169,0.66442,,,,
89.105,0.67909,2.38022,,,,
89.305,0.8664,6.65393,,,,
89.381,0.93805,9.31303,,,,
89.482,0.9192,7.69565,,,,
89.682,0.7259,2.12377,,,,
89.882,0.53837,0.51182,,,,
90.082,0.35098,0.11326,,,,
90.282,0.16349,0.03176,,,,
90.457,-0.00025,0.00777,,,,
90.459,-0.00214,0.00753,,,,
90.659,0.11634,0.04922,,,,
90.859,0.3047,0.16539,,,,
91.059,0.49204,0.66919,,,,
91.259,0.67944,2.3749,,,,
91.459,0.86678,6.65068,,,,
91.535,0.93841,9.31439,,,,
91.636,0.91994,7.70814,,,,
91.836,0.72632,2.12471,,,,
92.036,0.53878,0.51214,,,,
92.236,0.3514,0.11076,,,,
92.436,0.16396,0.03843,,,,
92.612,-0.00077,0.01314,,,,
92.614,-0.00266,0.01335,,,,
92.814,0.11578,0.04409,,,,
93.014,0.30414,0.15575,,,,
93.214,0.4915,0.65275,,,,
93.414,0.6789,2.3637,,,,
93.614,0.86624,6.60872,,,,
93.691,0.93881,9.30608,,,,
93.792,0.92038,7.71014,,,,
93.992,0.72672,2.12481,,,,
94.192,0.53919,0.50625,,,,
94.392,0.35181,0.11113,,,,
94.592,0.16436,0.03792,,,,
94.768,-0.00036,0.01512,,,,
94.77,-0.00225,0.01562,,,,
94.97,0.11616,0.04316,,,,
95.17,0.30452,0.14708,,,,
95.37,0.49193,0.64849,,,,
95.57,0.67927,2.34499,,,,
95.77,0.86664,6.60903,,,,
95.846,0.93828,9.2714,,,,
95.947,0.91984,7.66989,,,,
96.147,0.72617,2.10768,,,,
96.347,0.53864,0.50132,,,,
96.547,0.35127,0.1107,,,,
96.747,0.16379,0.04248,,,,
96.923,-0.00092,0.01088,,,,
96.925,-0.00281,0.01102,,,,
97.125,0.02401,0.02662,,,,
97.325,0.09976,0.04533,,,,
97.525,0.17489,0.06731,,,,
97.725,0.24964,0.10907,,,,
97.925,0.32459,0.18333,,,,
98.125,0.39954,0.3119,,,,
98.28,0.45777,0.50039,,,,
98.282,0.45852,0.50375,,,,
98.302,0.46589,0.52877,,,,
98.322,0.47109,0.54825,,,,
98.342,0.47492,0.56041,,,,
98.362,0.47799,0.57075,,,,
98.382,0.48203,0.59923,,,,
98.402,0.48957,0.63237,,,,
98.422,0.49903,0.67887,,,,
98.442,0.50846,0.72959,,,,
98.462,0.51728,0.777,,,,
98.482,0.52537,0.82319,,,,
98.502,0.53294,0.87505,,,,
98.522,0.54043,0.92238,,,,
98.542,0.54819,0.97541,,,,
98.562,0.55592,1.03384,,,,
98.582,0.56339,1.08582,,,,
98.602,0.5707,1.14179,,,,
98.622,0.57813,1.20375,,,,
98.642,0.58582,1.27427,,,,
98.662,0.5935,1.34358,,,,
98.682,0.60091,1.40246,,,,
98.702,0.60816,1.4741,,,,
98.722,0.61558,1.54947,,,,
98.742,0.62329,1.62869,,,,
98.762,0.63097,1.71427,,,,
98.782,0.63839,1.79598,,,,
98.802,0.64562,1.88193,,,,
98.822,0.65301,1.97663,,,,
98.842,0.66062,2.0758,,,,
98.862,0.66821,2.16387,,,,
98.882,0.67566,2.25769,,,,
98.902,0.68304,2.36377,,,,
98.922,0.69061,2.47844,,,,
98.942,0.69833,2.60192,,,,
98.962,0.70594,2.72514,,,,
98.982,0.71341,2.84551,,,,
99.002,0.72087,2.96979,,,,
99.022,0.72843,3.10186,,,,
99.042,0.73597,3.2402,,,,
99.062,0.7434,3.37555,,,,
99.082,0.75077,3.51674,,,,
99.102,0.75827,3.66103,,,,
99.122,0.76589,3.81546,,,,
99.142,0.77335,3.98115,,,,
99.162,0.78069,4.14638,,,,
99.182,0.78806,4.31709,,,,
99.202,0.79564,4.49494,,,,
99.222,0.80331,4.67451,,,,
99.242,0.81078,4.86569,,,,
99.262,0.81808,5.05922,,,,
99.282,0.82544,5.25347,,,,
99.302,0.83306,5.46312,,,,
99.322,0.84074,5.67266,,,,
99.342,0.84822,5.89246,,,,
99.362,0.85548,6.1074,,,,
99.382,0.86284,6.33339,,,,
99.402,0.8705,6.5811,,,,
99.422,0.87827,6.83367,,,,
99.442,0.8859,7.07955,,,,
99.462,0.89331,7.33443,,,,
99.482,0.90071,7.6057,,,,
99.502,0.90826,7.87769,,,,
99.522,0.91584,8.15232,,,,
99.542,0.92331,8.42965,,,,
99.562,0.93063,8.71211,,,,
99.582,0.93805,9.00793,,,,
99.602,0.94564,9.32187,,,,
99.622,0.95322,9.64162,,,,
99.642,0.96071,9.95546,,,,
99.662,0.96813,10.2703,,,,
99.682,0.97564,10.61012,,,,
99.702,0.98319,10.95692,,,,
99.722,0.99066,11.29418,,,,
99.742,0.99805,11.61941,,,,
99.762,1.00547,11.95515,,,,
99.782,1.01301,12.30264,,,,
99.802,1.02053,12.65726,,,,
99.822,1.02794,13.01069,,,,
99.842,1.03532,13.35826,,,,
99.862,1.04288,13.70795,,,,
99.882,1.05063,14.06697,,,,
99.902,1.05824,14.42302,,,,
99.922,1.0656,14.77888,,,,
99.942,1.07295,15.13359,,,,
99.962,1.08056,15.49381,,,,
99.982,1.08835,15.87044,,,,
100.002,1.0959,16.23112,,,,
100.022,1.10319,16.58485,,,,
100.042,1.11048,16.93985,,,,
100.062,1.11803,17.31808,,,,
100.082,1.12577,17.69844,,,,
100.102,1.13338,18.06486,,,,
100.122,1.14069,18.42084,,,,
100.142,1.14796,18.79071,,,,
100.162,1.15548,19.1801,,,,
100.182,1.1631,19.56376,,,,
100.202,1.17061,19.92571,,,,
100.222,1.17796,20.28884,,,,
100.242,1.18531,20.66311,,,,
100.262,1.19287,21.06096,,,,
100.282,1.20052,21.46195,,,,
100.302,1.20805,21.83641,,,,
100.322,1.21544,22.20552,,,,
100.342,1.22286,22.59197,,,,
100.362,1.23038,22.99141,,,,
100.382,1.23788,23.38616,,,,
100.402,1.24529,23.76961,,,,
100.422,1.25278,24.15589,,,,
100.442,1.2605,24.56937,,,,
100.462,1.26823,24.98791,,,,
100.482,1.27574,25.39097,,,,
100.502,1.28305,25.77305,,,,
100.522,1.29039,26.16009,,,,
100.542,1.29802,26.57883,,,,
100.562,1.30566,27.00219,,,,
100.582,1.31311,27.41203,,,,
100.602,1.3204,27.81076,,,,
100.622,1.32778,28.22223,,,,
100.642,1.33544,28.64977,,,,
100.662,1.34311,29.07372,,,,
100.682,1.3505,29.4833,,,,
100.702,1.35775,29.89215,,,,
100.722,1.36516,30.3126,,,,
100.742,1.37284,30.75607,,,,
100.762,1.38052,31.18098,,,,
100.782,1.38798,31.59179,,,,
100.802,1.39525,32.0034,,,,
100.822,1.40263,32.42999,,,,
100.842,1.41024,32.879,,,,
100.862,1.41785,33.31958,,,,
100.882,1.42534,33.74902,,,,
100.902,1.43274,34.17709,,,,
100.922,1.44027,34.63445,,,,
100.942,1.44794,35.10794,,,,
100.962,1.45553,35.55347,,,,
100.982,1.46298,35.98841,,,,
101.002,1.47044,36.43144,,,,
101.022,1.47802,36.90116,,,,
101.042,1.48558,37.35912,,,,
101.062,1.49299,37.79356,,,,
101.082,1.50033,38.2228,,,,
101.102,1.50784,38.67475,,,,
101.122,1.51549,39.15656,,,,
101.142,1.52297,39.62116,,,,
101.162,1.53029,40.06488,,,,
101.182,1.53763,40.51978,,,,
101.202,1.54518,40.99652,,,,
101.222,1.55286,41.48065,,,,
101.242,1.56036,41.95511,,,,
101.262,1.56767,42.40797,,,,
101.282,1.57505,42.8695,,,,
101.302,1.58265,43.35497,,,,
101.322,1.59033,43.84376,,,,
101.342,1.59784,44.31653,,,,
101.362,1.60512,44.77892,,,,
101.382,1.61246,45.25392,,,,
101.402,1.62008,45.74983,,,,
101.422,1.62783,46.21422,,,,
101.442,1.63547,46.68169,,,,
101.462,1.6429,47.15489,,,,
101.482,1.65031,47.64392,,,,
101.502,1.65787,48.1459,,,,
101.522,1.66544,48.63153,,,,
101.542,1.67292,49.11018,,,,
101.562,1.68026,49.58054,,,,
101.582,1.68768,50.07509,,,,
101.602,1.69526,50.59264,,,,
101.622,1.70285,51.10056,,,,
101.642,1.71034,51.56255,,,,
101.662,1.71775,52.03347,,,,
101.682,1.72521,52.53473,,,,
101.702,1.73274,53.04683,,,,
101.722,1.7402,53.54162,,,,
101.742,1.7476,54.01284,,,,
101.762,1.75507,54.49147,,,,
101.782,1.76269,55.01633,,,,
101.802,1.77027,55.53524,,,,
101.822,1.77768,56.03558,,,,
101.842,1.78499,56.51874,,,,
101.862,1.79247,57.01571,,,,
101.882,1.80019,57.5479,,,,
101.902,1.80781,58.07671,,,,
101.922,1.81521,58.58661,,,,
101.942,1.8226,59.09804,,,,
101.962,1.83023,59.63173,,,,
101.982,1.838,60.16585,,,,
102.002,1.84557,60.67389,,,,
102.022,1.85282,61.15833,,,,
102.042,1.86,61.63047,,,,
102.062,1.86749,62.14833,,,,
102.082,1.87523,62.69113,,,,
102.102,1.88289,63.21196,,,,
102.122,1.89028,63.70138,,,,
102.142,1.89755,64.18978,,,,
102.162,1.90504,64.72839,,,,
102.182,1.91267,65.26694,,,,
102.202,1.92021,65.7755,,,,
102.222,1.92758,66.2645,,,,
102.242,1.93494,66.773,,,,
102.262,1.94246,67.31133,,,,
102.282,1.95005,67.84357,,,,
102.301,1.95718,68.3202,,,,
102.303,1.95792,68.36905,,,,
102.469,1.92798,60.84365,,,,
102.637,1.86308,50.78131,,,,
102.837,1.78786,41.12743,,,,
103.037,1.71315,32.93798,,,,
103.237,1.63812,25.88717,,,,
103.437,1.56331,19.9585,,,,
103.637,1.48819,15.00953,,,,
103.837,1.41329,11.00044,,,,
104.037,1.33836,7.83387,,,,
104.237,1.26344,5.40285,,,,
104.437,1.1886,3.62437,,,,
104.637,1.11341,2.3358,,,,
104.837,1.0382,1.47254,,,,
105.037,0.96358,0.8965,,,,
105.237,0.88852,0.53189,,,,
105.437,0.81377,0.31543,,,,
105.637,0.73855,0.1812,,,,
105.837,0.66357,0.11285,,,,
106.037,0.58885,0.07359,,,,
106.237,0.5138,0.05218,,,,
106.386,0.45786,0.04722,,,,
106.388,0.45712,0.04725,,,,
106.588,0.50016,0.0738,,,,
106.788,0.57615,0.12195,,,,
106.988,0.651,0.21968,,,,
107.188,0.72638,0.40088,,,,
107.262,0.75394,0.50263,,,,
107.264,0.75469,0.50541,,,,
107.266,0.75545,0.50907,,,,
107.268,0.75622,0.51862,,,,
107.27,0.75705,0.5384,,,,
107.272,0.75799,0.56781,,,,
107.274,0.75915,0.60443,,,,
107.276,0.76062,0.6475,,,,
107.278,0.76253,0.69821,,,,
107.28,0.765,0.75588,,,,
107.282,0.76818,0.81948,,,,
107.284,0.7722,0.89065,,,,
107.286,0.7772,0.97126,,,,
107.288,0.78332,1.06273,,,,
107.29,0.7907,1.16739,,,,
107.292,0.79946,1.28839,,,,
107.294,0.80973,1.42992,,,,
107.296,0.82162,1.59768,,,,
107.298,0.83525,1.79847,,,,
107.3,0.85072,2.0423,,,,
107.302,0.86812,2.34027,,,,
107.304,0.88754,2.70495,,,,
107.306,0.90905,3.15288,,,,
107.308,0.93272,3.70211,,,,
107.31,0.95862,4.37234,,,,
107.312,0.98679,5.1884,,,,
107.314,1.01729,6.17684,,,,
107.316,1.05016,7.36352,,,,
107.318,1.08542,8.77654,,,,
107.32,1.1231,10.44622,,,,
107.322,1.16323,12.40094,,,,
107.324,1.20583,14.66779,,,,
107.326,1.25089,17.27277,,,,
107.328,1.29844,20.23748,,,,
107.33,1.34848,23.57865,,,,
107.332,1.401,27.30334,,,,
107.334,1.45599,31.40616,,,,
107.336,1.51339,35.86898,,,,
107.338,1.57313,40.66237,,,,
107.34,1.63505,45.75102,,,,
107.342,1.69897,51.09607,,,,
107.344,1.76468,56.65566,,,,
107.346,1.83196,62.38478,,,,
107.348,1.90061,68.23883,,,,
107.35,1.9704,74.17351,,,,
107.352,2.04116,80.14701,,,,
107.354,2.11271,86.12175,,,,
107.356,2.18493,92.06764,,,,
107.358,2.25768,97.9569,,,,
107.36,2.33087,103.76491,,,,
107.362,2.40443,109.47092,,,,
107.364,2.47829,115.05865,,,,
107.366,2.55241,120.51225,,,,
107.368,2.62676,125.81767,,,,
107.37,2.70132,130.96333,,,,
107.372,2.77607,135.93822,,,,
107.374,2.851,140.73468,,,,
107.376,2.92609,145.35352,,,,
107.378,3.00135,149.79979,,,,
107.38,3.07675,154.07993,,,,
107.382,3.15229,158.19672,,,,
107.384,3.22796,162.15097,,,,
107.386,3.30375,165.9393,,,,
107.388,3.37964,169.55418,,,,
107.39,3.45562,172.98936,,,,
107.392,3.53167,176.24649,,,,
107.394,3.60779,179.33112,,,,
107.396,3.68395,182.24806,,,,
107.398,3.76014,185.00139,,,,
107.4,3.83635,187.59875,,,,
107.402,3.91255,190.00995,,,,
107.404,3.98874,191.94254,,,,
107.406,4.06492,193.13911,,,,
107.408,4.14105,193.6338,,,,
107.41,4.21715,193.57088,,,,
107.412,4.2932,193.08908,,,,
107.414,4.3692,192.30409,,,,
107.416,4.44515,191.31122,,,,
107.418,4.52103,190.1907,,,,
107.42,4.59685,189.01097,,,,
107.422,4.6726,187.8307,,,,
107.424,4.74829,186.69955,,,,
107.426,4.82392,185.65456,,,,
107.428,4.8995,184.72232,,,,
107.43,4.97502,183.9234,,,,
107.432,5.05049,183.26814,,,,
107.434,5.12592,182.74817,,,,
107.436,5.2013,182.3441,,,,
107.438,5.27664,181.73126,,,,
107.44,5.35195,179.58981,,,,
107.442,5.42722,175.25453,,,,
107.444,5.50246,168.98299,,,,
107.446,5.57767,161.2552,,,,
107.448,5.65286,152.46158,,,,
107.45,5.72804,142.90906,,,,
107.452,5.8032,132.85593,,,,
107.454,5.87836,122.51787,,,,
107.456,5.95351,112.08327,,,,
107.458,6.02865,101.72163,,,,
107.46,6.10379,91.57308,,,,
107.462,6.17892,81.75527,,,,
107.464,6.25404,72.35764,,,,
107.466,6.32915,63.44246,,,,
107.468,6.40426,55.06297,,,,
107.47,6.47937,47.2559,,,,
107.472,6.55447,40.03946,,,,
107.474,6.62957,33.41932,,,,
107.476,6.70467,27.39108,,,,
107.478,6.77976,21.94487,,,,
107.48,6.85485,17.07015,,,,
107.482,6.92993,12.74683,,,,
107.484,7.005,8.94825,,,,
107.486,7.08007,5.64186,,,,
107.488,7.15514,2.78882,,,,
107.49,7.2302,0.35677,,,,
107.492,7.30526,-1.68113,,,,
107.494,7.38033,-3.35829,,,,
107.496,7.45539,-4.71321,,,,
107.498,7.53046,-5.78152,,,,
107.5,7.60553,-6.59159,,,,
107.502,7.6806,-7.16695,,,,
107.504,7.75567,-7.5389,,,,
107.506,7.83074,-7.74184,,,,
107.508,7.90582,-7.8022,,,,
107.51,7.98089,-7.74179,,,,
107.512,8.05597,-7.57707,,,,
107.514,8.13105,-7.32716,,,,
107.516,8.20612,-7.01105,,,,
107.518,8.2812,-6.64622,,,,
107.52,8.35627,-6.24647,,,,
107.522,8.43134,-5.82136,,,,
107.524,8.5064,-5.37835,,,,
107.526,8.58146,-4.9264,,,,
107.528,8.65652,-4.4755,,,,
107.53,8.73157,-4.03423,,,,
107.532,8.80662,-3.60665,,,,
107.534,8.88167,-3.1935,,,,
107.536,8.95671,-2.79806,,,,
107.538,9.03174,-2.42568,,,,
107.54,9.10677,-2.08048,,,,
107.542,9.1818,-1.76344,,,,
107.544,9.25681,-1.47196,,,,
107.546,9.33183,-1.20531,,,,
107.548,9.40683,-0.96242,,,,
107.55,9.48182,-0.74429,,,,
107.552,9.55682,-0.5528,,,,
107.554,9.6318,-0.38627,,,,
107.556,9.70677,-0.23938,,,,
107.558,9.78174,-0.11091,,,,
107.56,9.8567,-0.0013,,,,
107.562,9.93166,0.08976,,,,
107.564,10.00661,0.16406,,,,
107.566,10.08155,0.22542,,,,
107.568,10.1565,0.27752,,,,
107.57,10.23144,0.3187,,,,
107.572,10.30638,0.347,,,,
107.574,10.38132,0.36368,,,,
107.576,10.45627,0.37217,,,,
107.578,10.53122,0.37578,,,,
107.58,10.60616,0.3752,,,,
107.582,10.68111,0.37023,,,,
107.584,10.75606,0.36004,,,,
107.586,10.83101,0.34342,,,,
107.588,10.90595,0.32461,,,,
107.59,10.9809,0.30758,,,,
107.592,11.05585,0.29321,,,,
107.594,11.13081,0.27836,,,,
107.596,11.20576,0.2612,,,,
107.598,11.28071,0.24445,,,,
107.6,11.35567,0.22955,,,,
107.602,11.43062,0.21431,,,,
107.604,11.50556,0.19627,,,,
107.606,11.58051,0.17671,,,,
107.608,11.65546,0.15951,,,,
107.61,11.73041,0.14548,,,,
107.612,11.80536,0.13332,,,,
107.614,11.88031,0.12181,,,,
107.616,11.95527,0.10949,,,,
107.618,12.03022,0.09665,,,,
107.62,12.10517,0.0869,,,,
107.622,12.18011,0.08004,,,,
107.624,12.25506,0.07364,,,,
107.626,12.33,0.06587,,,,
107.628,12.40494,0.0595,,,,
107.63,12.47988,0.05296,,,,
107.632,12.55482,0.04576,,,,
107.634,12.62976,0.0399,,,,
107.636,12.70471,0.03823,,,,
107.638,12.77965,0.03721,,,,
107.64,12.8546,0.03254,,,,
107.642,12.92955,0.027,,,,
107.644,13.0045,0.0244,,,,
107.646,13.07945,0.02252,,,,
107.648,13.15441,0.01777,,,,
107.65,13.22936,0.01216,,,,
107.652,13.30431,0.00959,,,,
107.654,13.37927,0.0104,,,,
107.656,13.45423,0.01291,,,,
107.658,13.52919,0.01517,,,,
107.66,13.60415,0.01592,,,,
107.662,13.67911,0.0158,,,,
107.664,13.75407,0.01634,,,,
107.666,13.82902,0.0186,,,,
107.668,13.90398,0.02174,,,,
107.67,13.97894,0.0236,,,,
107.672,14.0539,0.02256,,,,
107.674,14.12886,0.02017,,,,
107.676,14.20382,0.01962,,,,
107.678,14.27879,0.02148,,,,
107.68,14.35375,0.02346,,,,
107.682,14.42872,0.02419,,,,
107.684,14.50368,0.02501,,,,
107.686,14.57865,0.02723,,,,
107.688,14.65361,0.03164,,,,
107.69,14.72857,0.03797,,,,
107.692,14.80353,0.04055,,,,
107.694,14.87848,0.03752,,,,
107.696,14.95344,0.03485,,,,
107.698,15.0284,0.03699,,,,
107.7,15.10335,0.03993,,,,
107.702,15.1783,0.03948,,,,
107.704,15.25326,0.03782,,,,
107.706,15.32821,0.03707,,,,
107.708,15.40317,0.03582,,,,
107.71,15.47813,0.03342,,,,
107.712,15.55309,0.03044,,,,
107.714,15.62805,0.0284,,,,
107.716,15.70301,0.02758,,,,
107.718,15.77798,0.02703,,,,
107.72,15.85294,0.02675,,,,
107.722,15.9279,0.02649,,,,
107.724,16.00286,0.02599,,,,
107.726,16.07781,0.02541,,,,
107.728,16.15276,0.02539,,,,
107.73,16.22771,0.02611,,,,
107.732,16.30265,0.0269,,,,
107.734,16.3776,0.02674,,,,
107.736,16.45254,0.02578,,,,
107.738,16.52747,0.0249,,,,
107.74,16.60241,0.02424,,,,
107.742,16.67734,0.02325,,,,
107.744,16.75227,0.0217,,,,
107.746,16.8272,0.02005,,,,
107.748,16.90213,0.01948,,,,
107.75,16.97707,0.01924,,,,
107.752,17.05201,0.01978,,,,
107.754,17.12695,0.02216,,,,
107.756,17.20189,0.02562,,,,
107.758,17.27684,0.02796,,,,
107.76,17.3518,0.02987,,,,
107.762,17.42675,0.03076,,,,
107.764,17.5017,0.03091,,,,
107.766,17.57666,0.0315,,,,
107.768,17.65162,0.03199,,,,
107.77,17.72659,0.03183,,,,
107.772,17.80156,0.0317,,,,
107.774,17.87654,0.03147,,,,
107.776,17.95152,0.03129,,,,
107.778,18.02651,0.03081,,,,
107.78,18.1015,0.03074,,,,
107.782,18.17649,0.02961,,,,
107.784,18.25148,0.02842,,,,
107.786,18.32648,0.02913,,,,
107.788,18.40148,0.03097,,,,
107.79,18.47647,0.03142,,,,
107.792,18.55147,0.02984,,,,
107.794,18.62648,0.02812,,,,
107.796,18.70148,0.02862,,,,
107.798,18.77648,0.02973,,,,
107.8,18.85148,0.02944,,,,
107.802,18.92648,0.02805,,,,
107.804,19.00148,0.02579,,,,
107.806,19.07647,0.02238,,,,
107.808,19.15146,0.01723,,,,
107.81,19.22644,0.01205,,,,
107.812,19.30143,0.00958,,,,
107.814,19.37642,0.00907,,,,
107.816,19.4514,0.00949,,,,
107.818,19.52638,0.01035,,,,